[2025-03-07 13:50:42,915] [INFO] Starting node at localhost:30087 | index= 88 | f=1, k=4 | Role: Replica
[2025-03-07 13:52:32,174] [INFO] Starting node at localhost:30087 | index= 88 | f=1, k=4 | Role: Replica
[2025-03-07 13:53:20,226] [INFO] Starting node at localhost:30087 | index= 88 | f=1, k=4 | Role: Replica
[2025-03-07 13:53:38,528] [INFO] [30087] Received PRE-PREPARE: id:1741323218379, from:Leader(30000), delay:0.0000s, distance:181.80m (Euclidean)
[2025-03-07 13:53:38,528] [INFO] [30087] Broadcasting PREPARE for REQUEST 1741323218379
[2025-03-07 13:53:39,290] [INFO] [30087] Received PREPARE: id:1741323218379, from:30054, delay:0.0000s, distance:94.48m (Euclidean)
[2025-03-07 13:53:39,346] [INFO] [30087] Received PREPARE: id:1741323218379, from:30097, delay:0.0000s, distance:27.82m (Euclidean)
[2025-03-07 13:53:39,348] [INFO] [30087] Broadcasting COMMIT for REQUEST 1741323218379
[2025-03-07 13:53:39,569] [INFO] [30087] Received PREPARE: id:1741323218379, from:30079, delay:0.0000s, distance:94.12m (Euclidean)
[2025-03-07 13:53:39,569] [INFO] [30087] Received COMMIT: id:1741323218379, from:30079, delay:0.0000s, distance:94.12m (Euclidean)
[2025-03-07 13:53:39,629] [INFO] [30087] Received PREPARE: id:1741323218379, from:30088, delay:0.0001s, distance:156.89m (Euclidean)
[2025-03-07 13:53:39,645] [INFO] [30087] Received PREPARE: id:1741323218379, from:30062, delay:0.0000s, distance:134.67m (Euclidean)
[2025-03-07 13:53:39,800] [INFO] [30087] Received PREPARE: id:1741323218379, from:30059, delay:0.0000s, distance:96.79m (Euclidean)
[2025-03-07 13:53:39,800] [INFO] [30087] Received COMMIT: id:1741323218379, from:30059, delay:0.0000s, distance:96.79m (Euclidean)
[2025-03-07 13:53:39,800] [INFO] [LEADER 30087] Sending REPLY for REQUEST 1741323218379 to CLIENT
[2025-03-07 13:53:39,832] [INFO] [30087] Received PREPARE: id:1741323218379, from:30090, delay:0.0000s, distance:64.31m (Euclidean)
[2025-03-07 13:53:39,832] [INFO] [30087] Received PREPARE: id:1741323218379, from:30048, delay:0.0001s, distance:154.76m (Euclidean)
[2025-03-07 13:53:39,863] [INFO] [30087] Received COMMIT: id:1741323218379, from:30026, delay:0.0000s, distance:32.07m (Euclidean)
[2025-03-07 13:53:39,863] [INFO] [30087] Received PREPARE: id:1741323218379, from:30026, delay:0.0000s, distance:32.07m (Euclidean)
[2025-03-07 13:53:39,927] [INFO] [30087] Received COMMIT: id:1741323218379, from:30062, delay:0.0000s, distance:134.67m (Euclidean)
[2025-03-07 13:53:39,990] [INFO] [30087] Received PREPARE: id:1741323218379, from:30020, delay:0.0001s, distance:189.56m (Euclidean)
[2025-03-07 13:53:39,990] [INFO] [30087] Received COMMIT: id:1741323218379, from:30020, delay:0.0001s, distance:189.56m (Euclidean)
[2025-03-07 13:53:39,990] [INFO] [30087] Received PREPARE: id:1741323218379, from:30070, delay:0.0000s, distance:129.26m (Euclidean)
[2025-03-07 13:53:39,990] [INFO] [30087] Received COMMIT: id:1741323218379, from:30070, delay:0.0000s, distance:129.26m (Euclidean)
[2025-03-07 13:53:40,059] [INFO] [30087] Received PREPARE: id:1741323218379, from:30011, delay:0.0001s, distance:168.36m (Euclidean)
[2025-03-07 13:53:40,112] [INFO] [30087] Received COMMIT: id:1741323218379, from:30054, delay:0.0000s, distance:94.48m (Euclidean)
[2025-03-07 13:53:40,148] [INFO] [30087] Received COMMIT: id:1741323218379, from:30011, delay:0.0001s, distance:168.36m (Euclidean)
[2025-03-07 13:53:40,302] [INFO] [30087] Received COMMIT: id:1741323218379, from:30090, delay:0.0000s, distance:64.31m (Euclidean)
[2025-03-07 13:53:40,339] [INFO] [30087] Received PREPARE: id:1741323218379, from:30005, delay:0.0001s, distance:161.37m (Euclidean)
[2025-03-07 13:53:40,371] [INFO] [30087] Received COMMIT: id:1741323218379, from:30005, delay:0.0001s, distance:161.37m (Euclidean)
[2025-03-07 13:53:40,402] [INFO] [30087] Received PREPARE: id:1741323218379, from:30021, delay:0.0002s, distance:251.63m (Euclidean)
[2025-03-07 13:53:40,402] [INFO] [30087] Received COMMIT: id:1741323218379, from:30021, delay:0.0002s, distance:251.63m (Euclidean)
[2025-03-07 13:53:40,450] [INFO] [30087] Received COMMIT: id:1741323218379, from:30097, delay:0.0000s, distance:27.82m (Euclidean)
[2025-03-07 13:53:40,482] [INFO] [30087] Received PREPARE: id:1741323218379, from:30040, delay:0.0000s, distance:88.64m (Euclidean)
[2025-03-07 13:53:40,482] [INFO] [30087] Received COMMIT: id:1741323218379, from:30040, delay:0.0000s, distance:88.64m (Euclidean)
[2025-03-07 13:53:40,497] [INFO] [30087] Received PREPARE: id:1741323218379, from:30046, delay:0.0001s, distance:217.61m (Euclidean)
[2025-03-07 13:53:40,497] [INFO] [30087] Received PREPARE: id:1741323218379, from:30053, delay:0.0000s, distance:114.18m (Euclidean)
[2025-03-07 13:53:40,545] [INFO] [30087] Received PREPARE: id:1741323218379, from:30016, delay:0.0001s, distance:177.59m (Euclidean)
[2025-03-07 13:53:40,561] [INFO] [30087] Received PREPARE: id:1741323218379, from:30081, delay:0.0001s, distance:219.70m (Euclidean)
[2025-03-07 13:53:40,561] [INFO] [30087] Received COMMIT: id:1741323218379, from:30081, delay:0.0001s, distance:219.70m (Euclidean)
[2025-03-07 13:53:40,656] [INFO] [30087] Received PREPARE: id:1741323218379, from:30049, delay:0.0000s, distance:88.61m (Euclidean)
[2025-03-07 13:53:40,696] [INFO] [30087] Received PREPARE: id:1741323218379, from:30045, delay:0.0001s, distance:211.20m (Euclidean)
[2025-03-07 13:53:40,696] [INFO] [30087] Received COMMIT: id:1741323218379, from:30045, delay:0.0001s, distance:211.20m (Euclidean)
[2025-03-07 13:53:40,766] [INFO] [30087] Received PREPARE: id:1741323218379, from:30083, delay:0.0000s, distance:127.47m (Euclidean)
[2025-03-07 13:53:40,782] [INFO] [30087] Received PREPARE: id:1741323218379, from:30057, delay:0.0000s, distance:121.16m (Euclidean)
[2025-03-07 13:53:40,782] [INFO] [30087] Received COMMIT: id:1741323218379, from:30057, delay:0.0000s, distance:121.16m (Euclidean)
[2025-03-07 13:53:40,845] [INFO] [30087] Received PREPARE: id:1741323218379, from:30052, delay:0.0002s, distance:288.72m (Euclidean)
[2025-03-07 13:53:40,899] [INFO] [30087] Received COMMIT: id:1741323218379, from:30053, delay:0.0000s, distance:114.18m (Euclidean)
[2025-03-07 13:53:40,925] [INFO] [30087] Received PREPARE: id:1741323218379, from:30051, delay:0.0000s, distance:102.79m (Euclidean)
[2025-03-07 13:53:40,925] [INFO] [30087] Received COMMIT: id:1741323218379, from:30083, delay:0.0000s, distance:127.47m (Euclidean)
[2025-03-07 13:53:40,925] [INFO] [30087] Received COMMIT: id:1741323218379, from:30051, delay:0.0000s, distance:102.79m (Euclidean)
[2025-03-07 13:53:41,073] [INFO] [30087] Received PREPARE: id:1741323218379, from:30058, delay:0.0000s, distance:75.12m (Euclidean)
[2025-03-07 13:53:41,073] [INFO] [30087] Received COMMIT: id:1741323218379, from:30058, delay:0.0000s, distance:75.12m (Euclidean)
[2025-03-07 13:53:41,171] [INFO] [30087] Received PREPARE: id:1741323218379, from:30002, delay:0.0000s, distance:143.25m (Euclidean)
[2025-03-07 13:53:41,171] [INFO] [30087] Received COMMIT: id:1741323218379, from:30002, delay:0.0000s, distance:143.25m (Euclidean)
[2025-03-07 13:53:41,294] [INFO] [30087] Received PREPARE: id:1741323218379, from:30013, delay:0.0001s, distance:191.18m (Euclidean)
[2025-03-07 13:53:41,295] [INFO] [30087] Received PREPARE: id:1741323218379, from:30028, delay:0.0000s, distance:149.08m (Euclidean)
[2025-03-07 13:53:41,295] [INFO] [30087] Received COMMIT: id:1741323218379, from:30028, delay:0.0000s, distance:149.08m (Euclidean)
[2025-03-07 13:53:41,295] [INFO] [30087] Received COMMIT: id:1741323218379, from:30013, delay:0.0001s, distance:191.18m (Euclidean)
[2025-03-07 13:53:41,298] [INFO] [30087] Received PREPARE: id:1741323218379, from:30078, delay:0.0002s, distance:262.00m (Euclidean)
[2025-03-07 13:53:41,298] [INFO] [30087] Received COMMIT: id:1741323218379, from:30078, delay:0.0002s, distance:262.00m (Euclidean)
[2025-03-07 13:53:41,415] [INFO] [30087] Received COMMIT: id:1741323218379, from:30052, delay:0.0002s, distance:288.72m (Euclidean)
[2025-03-07 13:53:41,415] [INFO] [30087] Received COMMIT: id:1741323218379, from:30046, delay:0.0001s, distance:217.61m (Euclidean)
[2025-03-07 13:53:41,557] [INFO] [30087] Received PREPARE: id:1741323218379, from:30099, delay:0.0001s, distance:224.27m (Euclidean)
[2025-03-07 13:53:41,557] [INFO] [30087] Received PREPARE: id:1741323218379, from:30056, delay:0.0001s, distance:231.14m (Euclidean)
[2025-03-07 13:53:41,557] [INFO] [30087] Received COMMIT: id:1741323218379, from:30099, delay:0.0001s, distance:224.27m (Euclidean)
[2025-03-07 13:53:41,557] [INFO] [30087] Received COMMIT: id:1741323218379, from:30056, delay:0.0001s, distance:231.14m (Euclidean)
[2025-03-07 13:53:41,668] [INFO] [30087] Received COMMIT: id:1741323218379, from:30048, delay:0.0001s, distance:154.76m (Euclidean)
[2025-03-07 13:53:41,673] [INFO] [30087] Received COMMIT: id:1741323218379, from:30084, delay:0.0002s, distance:253.36m (Euclidean)
[2025-03-07 13:53:41,673] [INFO] [30087] Received PREPARE: id:1741323218379, from:30084, delay:0.0002s, distance:253.36m (Euclidean)
[2025-03-07 13:53:41,794] [INFO] [30087] Received PREPARE: id:1741323218379, from:30006, delay:0.0001s, distance:164.33m (Euclidean)
[2025-03-07 13:53:41,826] [INFO] [30087] Received PREPARE: id:1741323218379, from:30069, delay:0.0001s, distance:155.11m (Euclidean)
[2025-03-07 13:53:41,826] [INFO] [30087] Received COMMIT: id:1741323218379, from:30069, delay:0.0001s, distance:155.11m (Euclidean)
[2025-03-07 13:53:42,143] [INFO] [30087] Received PREPARE: id:1741323218379, from:30055, delay:0.0000s, distance:142.73m (Euclidean)
[2025-03-07 13:53:42,241] [INFO] [30087] Received PREPARE: id:1741323218379, from:30031, delay:0.0001s, distance:223.40m (Euclidean)
[2025-03-07 13:53:42,241] [INFO] [30087] Received COMMIT: id:1741323218379, from:30031, delay:0.0001s, distance:223.40m (Euclidean)
[2025-03-07 13:53:42,241] [INFO] [30087] Received PREPARE: id:1741323218379, from:30019, delay:0.0002s, distance:250.52m (Euclidean)
[2025-03-07 13:53:42,241] [INFO] [30087] Received COMMIT: id:1741323218379, from:30019, delay:0.0002s, distance:250.52m (Euclidean)
[2025-03-07 13:53:42,285] [INFO] [30087] Received PREPARE: id:1741323218379, from:30104, delay:0.0001s, distance:227.61m (Euclidean)
[2025-03-07 13:53:42,326] [INFO] [30087] Received COMMIT: id:1741323218379, from:30104, delay:0.0001s, distance:227.61m (Euclidean)
[2025-03-07 13:53:42,348] [INFO] [30087] Received PREPARE: id:1741323218379, from:30077, delay:0.0002s, distance:252.47m (Euclidean)
[2025-03-07 13:53:42,348] [INFO] [30087] Received COMMIT: id:1741323218379, from:30077, delay:0.0002s, distance:252.47m (Euclidean)
[2025-03-07 13:53:42,363] [INFO] [30087] Received PREPARE: id:1741323218379, from:30092, delay:0.0001s, distance:242.18m (Euclidean)
[2025-03-07 13:53:42,411] [INFO] [30087] Received COMMIT: id:1741323218379, from:30092, delay:0.0001s, distance:242.18m (Euclidean)
[2025-03-07 13:53:42,474] [INFO] [30087] Received PREPARE: id:1741323218379, from:30047, delay:0.0002s, distance:251.18m (Euclidean)
[2025-03-07 13:53:42,474] [INFO] [30087] Received COMMIT: id:1741323218379, from:30047, delay:0.0002s, distance:251.18m (Euclidean)
[2025-03-07 13:53:42,664] [INFO] [30087] Received COMMIT: id:1741323218379, from:30088, delay:0.0001s, distance:156.89m (Euclidean)
[2025-03-07 13:53:42,664] [INFO] [30087] Received PREPARE: id:1741323218379, from:30074, delay:0.0001s, distance:227.98m (Euclidean)
[2025-03-07 13:53:42,664] [INFO] [30087] Received COMMIT: id:1741323218379, from:30055, delay:0.0000s, distance:142.73m (Euclidean)
[2025-03-07 13:53:42,732] [INFO] [30087] Received COMMIT: id:1741323218379, from:30074, delay:0.0001s, distance:227.98m (Euclidean)
[2025-03-07 13:53:42,732] [INFO] [30087] Received COMMIT: id:1741323218379, from:30016, delay:0.0001s, distance:177.59m (Euclidean)
[2025-03-07 13:53:42,774] [INFO] [30087] Received PREPARE: id:1741323218379, from:30089, delay:0.0001s, distance:238.52m (Euclidean)
[2025-03-07 13:53:42,774] [INFO] [30087] Received COMMIT: id:1741323218379, from:30089, delay:0.0001s, distance:238.52m (Euclidean)
[2025-03-07 13:53:42,963] [ERROR] [30087] Error sending to http://localhost:30124/prepare: Cannot connect to host localhost:30124 ssl:default [Connect call failed ('127.0.0.1', 30124)]
Traceback (most recent call last):
  File "D:\anaconda\envs\PBFT\lib\site-packages\aiohttp\connector.py", line 980, in _wrap_create_connection
    return await self._loop.create_connection(*args, **kwargs)  # type: ignore[return-value]  # noqa
  File "D:\anaconda\envs\PBFT\lib\asyncio\base_events.py", line 948, in create_connection
    raise exceptions[0]
  File "D:\anaconda\envs\PBFT\lib\asyncio\base_events.py", line 935, in create_connection
    await self.sock_connect(sock, address)
  File "D:\anaconda\envs\PBFT\lib\asyncio\selector_events.py", line 475, in sock_connect
    return await fut
  File "D:\anaconda\envs\PBFT\lib\asyncio\selector_events.py", line 505, in _sock_connect_cb
    raise OSError(err, f'Connect call failed {address}')
ConnectionRefusedError: [Errno 10061] Connect call failed ('127.0.0.1', 30124)

The above exception was the direct cause of the following exception:

Traceback (most recent call last):
  File "pbft.py", line 236, in send_message
    await send_with_delay(self.session, self.node_info, target, url, data, self.bandwidth_data)
  File "pbft.py", line 63, in send_with_delay
    async with session.post(url, json=data) as resp:
  File "D:\anaconda\envs\PBFT\lib\site-packages\aiohttp\client.py", line 1141, in __aenter__
    self._resp = await self._coro
  File "D:\anaconda\envs\PBFT\lib\site-packages\aiohttp\client.py", line 537, in _request
    req, traces=traces, timeout=real_timeout
  File "D:\anaconda\envs\PBFT\lib\site-packages\aiohttp\connector.py", line 540, in connect
    proto = await self._create_connection(req, traces, timeout)
  File "D:\anaconda\envs\PBFT\lib\site-packages\aiohttp\connector.py", line 901, in _create_connection
    _, proto = await self._create_direct_connection(req, traces, timeout)
  File "D:\anaconda\envs\PBFT\lib\site-packages\aiohttp\connector.py", line 1206, in _create_direct_connection
    raise last_exc
  File "D:\anaconda\envs\PBFT\lib\site-packages\aiohttp\connector.py", line 1187, in _create_direct_connection
    client_error=client_error,
  File "D:\anaconda\envs\PBFT\lib\site-packages\aiohttp\connector.py", line 988, in _wrap_create_connection
    raise client_error(req.connection_key, exc) from exc
aiohttp.client_exceptions.ClientConnectorError: Cannot connect to host localhost:30124 ssl:default [Connect call failed ('127.0.0.1', 30124)]
[2025-03-07 13:53:42,995] [INFO] [30087] Received PREPARE: id:1741323218379, from:30073, delay:0.0001s, distance:181.17m (Euclidean)
[2025-03-07 13:53:43,133] [INFO] [30087] Received COMMIT: id:1741323218379, from:30073, delay:0.0001s, distance:181.17m (Euclidean)
[2025-03-07 13:53:43,139] [ERROR] [30087] Error sending to http://localhost:30029/prepare: Cannot connect to host localhost:30029 ssl:default [Connect call failed ('127.0.0.1', 30029)]
Traceback (most recent call last):
  File "D:\anaconda\envs\PBFT\lib\site-packages\aiohttp\connector.py", line 980, in _wrap_create_connection
    return await self._loop.create_connection(*args, **kwargs)  # type: ignore[return-value]  # noqa
  File "D:\anaconda\envs\PBFT\lib\asyncio\base_events.py", line 948, in create_connection
    raise exceptions[0]
  File "D:\anaconda\envs\PBFT\lib\asyncio\base_events.py", line 935, in create_connection
    await self.sock_connect(sock, address)
  File "D:\anaconda\envs\PBFT\lib\asyncio\selector_events.py", line 475, in sock_connect
    return await fut
  File "D:\anaconda\envs\PBFT\lib\asyncio\selector_events.py", line 505, in _sock_connect_cb
    raise OSError(err, f'Connect call failed {address}')
ConnectionRefusedError: [Errno 10061] Connect call failed ('127.0.0.1', 30029)

The above exception was the direct cause of the following exception:

Traceback (most recent call last):
  File "pbft.py", line 236, in send_message
    await send_with_delay(self.session, self.node_info, target, url, data, self.bandwidth_data)
  File "pbft.py", line 63, in send_with_delay
    async with session.post(url, json=data) as resp:
  File "D:\anaconda\envs\PBFT\lib\site-packages\aiohttp\client.py", line 1141, in __aenter__
    self._resp = await self._coro
  File "D:\anaconda\envs\PBFT\lib\site-packages\aiohttp\client.py", line 537, in _request
    req, traces=traces, timeout=real_timeout
  File "D:\anaconda\envs\PBFT\lib\site-packages\aiohttp\connector.py", line 540, in connect
    proto = await self._create_connection(req, traces, timeout)
  File "D:\anaconda\envs\PBFT\lib\site-packages\aiohttp\connector.py", line 901, in _create_connection
    _, proto = await self._create_direct_connection(req, traces, timeout)
  File "D:\anaconda\envs\PBFT\lib\site-packages\aiohttp\connector.py", line 1206, in _create_direct_connection
    raise last_exc
  File "D:\anaconda\envs\PBFT\lib\site-packages\aiohttp\connector.py", line 1187, in _create_direct_connection
    client_error=client_error,
  File "D:\anaconda\envs\PBFT\lib\site-packages\aiohttp\connector.py", line 988, in _wrap_create_connection
    raise client_error(req.connection_key, exc) from exc
aiohttp.client_exceptions.ClientConnectorError: Cannot connect to host localhost:30029 ssl:default [Connect call failed ('127.0.0.1', 30029)]
[2025-03-07 13:53:43,139] [INFO] [30087] Received COMMIT: id:1741323218379, from:30004, delay:0.0001s, distance:246.04m (Euclidean)
[2025-03-07 13:53:43,139] [INFO] [30087] Received PREPARE: id:1741323218379, from:30004, delay:0.0001s, distance:246.04m (Euclidean)
[2025-03-07 13:53:43,189] [INFO] [30087] Received PREPARE: id:1741323218379, from:30014, delay:0.0001s, distance:184.46m (Euclidean)
[2025-03-07 13:53:43,191] [INFO] [30087] Received COMMIT: id:1741323218379, from:30014, delay:0.0001s, distance:184.46m (Euclidean)
[2025-03-07 13:53:43,210] [INFO] [30087] Received PREPARE: id:1741323218379, from:30001, delay:0.0001s, distance:211.84m (Euclidean)
[2025-03-07 13:53:43,212] [INFO] [30087] Received COMMIT: id:1741323218379, from:30001, delay:0.0001s, distance:211.84m (Euclidean)
[2025-03-07 13:53:43,248] [INFO] [30087] Received COMMIT: id:1741323218379, from:30006, delay:0.0001s, distance:164.33m (Euclidean)
[2025-03-07 13:53:43,454] [ERROR] [30087] Error sending to http://localhost:30025/prepare: Cannot connect to host localhost:30025 ssl:default [Connect call failed ('127.0.0.1', 30025)]
Traceback (most recent call last):
  File "D:\anaconda\envs\PBFT\lib\site-packages\aiohttp\connector.py", line 980, in _wrap_create_connection
    return await self._loop.create_connection(*args, **kwargs)  # type: ignore[return-value]  # noqa
  File "D:\anaconda\envs\PBFT\lib\asyncio\base_events.py", line 948, in create_connection
    raise exceptions[0]
  File "D:\anaconda\envs\PBFT\lib\asyncio\base_events.py", line 935, in create_connection
    await self.sock_connect(sock, address)
  File "D:\anaconda\envs\PBFT\lib\asyncio\selector_events.py", line 475, in sock_connect
    return await fut
  File "D:\anaconda\envs\PBFT\lib\asyncio\selector_events.py", line 505, in _sock_connect_cb
    raise OSError(err, f'Connect call failed {address}')
ConnectionRefusedError: [Errno 10061] Connect call failed ('127.0.0.1', 30025)

The above exception was the direct cause of the following exception:

Traceback (most recent call last):
  File "pbft.py", line 236, in send_message
    await send_with_delay(self.session, self.node_info, target, url, data, self.bandwidth_data)
  File "pbft.py", line 63, in send_with_delay
    async with session.post(url, json=data) as resp:
  File "D:\anaconda\envs\PBFT\lib\site-packages\aiohttp\client.py", line 1141, in __aenter__
    self._resp = await self._coro
  File "D:\anaconda\envs\PBFT\lib\site-packages\aiohttp\client.py", line 537, in _request
    req, traces=traces, timeout=real_timeout
  File "D:\anaconda\envs\PBFT\lib\site-packages\aiohttp\connector.py", line 540, in connect
    proto = await self._create_connection(req, traces, timeout)
  File "D:\anaconda\envs\PBFT\lib\site-packages\aiohttp\connector.py", line 901, in _create_connection
    _, proto = await self._create_direct_connection(req, traces, timeout)
  File "D:\anaconda\envs\PBFT\lib\site-packages\aiohttp\connector.py", line 1206, in _create_direct_connection
    raise last_exc
  File "D:\anaconda\envs\PBFT\lib\site-packages\aiohttp\connector.py", line 1187, in _create_direct_connection
    client_error=client_error,
  File "D:\anaconda\envs\PBFT\lib\site-packages\aiohttp\connector.py", line 988, in _wrap_create_connection
    raise client_error(req.connection_key, exc) from exc
aiohttp.client_exceptions.ClientConnectorError: Cannot connect to host localhost:30025 ssl:default [Connect call failed ('127.0.0.1', 30025)]
[2025-03-07 13:53:43,454] [ERROR] [30087] Error sending to http://localhost:30023/prepare: Cannot connect to host localhost:30023 ssl:default [Connect call failed ('127.0.0.1', 30023)]
Traceback (most recent call last):
  File "D:\anaconda\envs\PBFT\lib\site-packages\aiohttp\connector.py", line 980, in _wrap_create_connection
    return await self._loop.create_connection(*args, **kwargs)  # type: ignore[return-value]  # noqa
  File "D:\anaconda\envs\PBFT\lib\asyncio\base_events.py", line 948, in create_connection
    raise exceptions[0]
  File "D:\anaconda\envs\PBFT\lib\asyncio\base_events.py", line 935, in create_connection
    await self.sock_connect(sock, address)
  File "D:\anaconda\envs\PBFT\lib\asyncio\selector_events.py", line 475, in sock_connect
    return await fut
  File "D:\anaconda\envs\PBFT\lib\asyncio\selector_events.py", line 505, in _sock_connect_cb
    raise OSError(err, f'Connect call failed {address}')
ConnectionRefusedError: [Errno 10061] Connect call failed ('127.0.0.1', 30023)

The above exception was the direct cause of the following exception:

Traceback (most recent call last):
  File "pbft.py", line 236, in send_message
    await send_with_delay(self.session, self.node_info, target, url, data, self.bandwidth_data)
  File "pbft.py", line 63, in send_with_delay
    async with session.post(url, json=data) as resp:
  File "D:\anaconda\envs\PBFT\lib\site-packages\aiohttp\client.py", line 1141, in __aenter__
    self._resp = await self._coro
  File "D:\anaconda\envs\PBFT\lib\site-packages\aiohttp\client.py", line 537, in _request
    req, traces=traces, timeout=real_timeout
  File "D:\anaconda\envs\PBFT\lib\site-packages\aiohttp\connector.py", line 540, in connect
    proto = await self._create_connection(req, traces, timeout)
  File "D:\anaconda\envs\PBFT\lib\site-packages\aiohttp\connector.py", line 901, in _create_connection
    _, proto = await self._create_direct_connection(req, traces, timeout)
  File "D:\anaconda\envs\PBFT\lib\site-packages\aiohttp\connector.py", line 1206, in _create_direct_connection
    raise last_exc
  File "D:\anaconda\envs\PBFT\lib\site-packages\aiohttp\connector.py", line 1187, in _create_direct_connection
    client_error=client_error,
  File "D:\anaconda\envs\PBFT\lib\site-packages\aiohttp\connector.py", line 988, in _wrap_create_connection
    raise client_error(req.connection_key, exc) from exc
aiohttp.client_exceptions.ClientConnectorError: Cannot connect to host localhost:30023 ssl:default [Connect call failed ('127.0.0.1', 30023)]
[2025-03-07 13:53:43,502] [INFO] [30087] Received COMMIT: id:1741323218379, from:30049, delay:0.0000s, distance:88.61m (Euclidean)
[2025-03-07 13:53:43,502] [ERROR] [30087] Error sending to http://localhost:30027/prepare: Cannot connect to host localhost:30027 ssl:default [Connect call failed ('127.0.0.1', 30027)]
Traceback (most recent call last):
  File "D:\anaconda\envs\PBFT\lib\site-packages\aiohttp\connector.py", line 980, in _wrap_create_connection
    return await self._loop.create_connection(*args, **kwargs)  # type: ignore[return-value]  # noqa
  File "D:\anaconda\envs\PBFT\lib\asyncio\base_events.py", line 948, in create_connection
    raise exceptions[0]
  File "D:\anaconda\envs\PBFT\lib\asyncio\base_events.py", line 935, in create_connection
    await self.sock_connect(sock, address)
  File "D:\anaconda\envs\PBFT\lib\asyncio\selector_events.py", line 475, in sock_connect
    return await fut
  File "D:\anaconda\envs\PBFT\lib\asyncio\selector_events.py", line 505, in _sock_connect_cb
    raise OSError(err, f'Connect call failed {address}')
ConnectionRefusedError: [Errno 10061] Connect call failed ('127.0.0.1', 30027)

The above exception was the direct cause of the following exception:

Traceback (most recent call last):
  File "pbft.py", line 236, in send_message
    await send_with_delay(self.session, self.node_info, target, url, data, self.bandwidth_data)
  File "pbft.py", line 63, in send_with_delay
    async with session.post(url, json=data) as resp:
  File "D:\anaconda\envs\PBFT\lib\site-packages\aiohttp\client.py", line 1141, in __aenter__
    self._resp = await self._coro
  File "D:\anaconda\envs\PBFT\lib\site-packages\aiohttp\client.py", line 537, in _request
    req, traces=traces, timeout=real_timeout
  File "D:\anaconda\envs\PBFT\lib\site-packages\aiohttp\connector.py", line 540, in connect
    proto = await self._create_connection(req, traces, timeout)
  File "D:\anaconda\envs\PBFT\lib\site-packages\aiohttp\connector.py", line 901, in _create_connection
    _, proto = await self._create_direct_connection(req, traces, timeout)
  File "D:\anaconda\envs\PBFT\lib\site-packages\aiohttp\connector.py", line 1206, in _create_direct_connection
    raise last_exc
  File "D:\anaconda\envs\PBFT\lib\site-packages\aiohttp\connector.py", line 1187, in _create_direct_connection
    client_error=client_error,
  File "D:\anaconda\envs\PBFT\lib\site-packages\aiohttp\connector.py", line 988, in _wrap_create_connection
    raise client_error(req.connection_key, exc) from exc
aiohttp.client_exceptions.ClientConnectorError: Cannot connect to host localhost:30027 ssl:default [Connect call failed ('127.0.0.1', 30027)]
[2025-03-07 13:53:43,596] [INFO] [30087] Received PREPARE: id:1741323218379, from:30017, delay:0.0000s, distance:191.52m (Euclidean)
[2025-03-07 13:53:43,596] [INFO] [30087] Received COMMIT: id:1741323218379, from:30017, delay:0.0000s, distance:191.52m (Euclidean)
[2025-03-07 13:53:43,596] [INFO] [30087] Received PREPARE: id:1741323218379, from:30039, delay:0.0001s, distance:190.03m (Euclidean)
[2025-03-07 13:53:43,596] [INFO] [30087] Received COMMIT: id:1741323218379, from:30039, delay:0.0001s, distance:190.03m (Euclidean)
[2025-03-07 13:53:43,616] [INFO] [30087] Received PREPARE: id:1741323218379, from:30010, delay:0.0000s, distance:187.95m (Euclidean)
[2025-03-07 13:53:43,616] [INFO] [30087] Received PREPARE: id:1741323218379, from:30032, delay:0.0000s, distance:194.60m (Euclidean)
[2025-03-07 13:53:43,691] [ERROR] [30087] Error sending to http://localhost:30025/commit: Cannot connect to host localhost:30025 ssl:default [Connect call failed ('::1', 30025, 0, 0)]
Traceback (most recent call last):
  File "D:\anaconda\envs\PBFT\lib\site-packages\aiohttp\connector.py", line 980, in _wrap_create_connection
    return await self._loop.create_connection(*args, **kwargs)  # type: ignore[return-value]  # noqa
  File "D:\anaconda\envs\PBFT\lib\asyncio\base_events.py", line 948, in create_connection
    raise exceptions[0]
  File "D:\anaconda\envs\PBFT\lib\asyncio\base_events.py", line 935, in create_connection
    await self.sock_connect(sock, address)
  File "D:\anaconda\envs\PBFT\lib\asyncio\selector_events.py", line 475, in sock_connect
    return await fut
  File "D:\anaconda\envs\PBFT\lib\asyncio\selector_events.py", line 505, in _sock_connect_cb
    raise OSError(err, f'Connect call failed {address}')
ConnectionRefusedError: [Errno 10061] Connect call failed ('::1', 30025, 0, 0)

The above exception was the direct cause of the following exception:

Traceback (most recent call last):
  File "pbft.py", line 236, in send_message
    await send_with_delay(self.session, self.node_info, target, url, data, self.bandwidth_data)
  File "pbft.py", line 63, in send_with_delay
    async with session.post(url, json=data) as resp:
  File "D:\anaconda\envs\PBFT\lib\site-packages\aiohttp\client.py", line 1141, in __aenter__
    self._resp = await self._coro
  File "D:\anaconda\envs\PBFT\lib\site-packages\aiohttp\client.py", line 537, in _request
    req, traces=traces, timeout=real_timeout
  File "D:\anaconda\envs\PBFT\lib\site-packages\aiohttp\connector.py", line 540, in connect
    proto = await self._create_connection(req, traces, timeout)
  File "D:\anaconda\envs\PBFT\lib\site-packages\aiohttp\connector.py", line 901, in _create_connection
    _, proto = await self._create_direct_connection(req, traces, timeout)
  File "D:\anaconda\envs\PBFT\lib\site-packages\aiohttp\connector.py", line 1206, in _create_direct_connection
    raise last_exc
  File "D:\anaconda\envs\PBFT\lib\site-packages\aiohttp\connector.py", line 1187, in _create_direct_connection
    client_error=client_error,
  File "D:\anaconda\envs\PBFT\lib\site-packages\aiohttp\connector.py", line 988, in _wrap_create_connection
    raise client_error(req.connection_key, exc) from exc
aiohttp.client_exceptions.ClientConnectorError: Cannot connect to host localhost:30025 ssl:default [Connect call failed ('::1', 30025, 0, 0)]
[2025-03-07 13:53:43,723] [INFO] [30087] Received COMMIT: id:1741323218379, from:30032, delay:0.0000s, distance:194.60m (Euclidean)
[2025-03-07 13:53:43,853] [INFO] [30087] Received PREPARE: id:1741323218379, from:30117, delay:0.0002s, distance:260.61m (Euclidean)
[2025-03-07 13:53:43,853] [INFO] [30087] Received COMMIT: id:1741323218379, from:30117, delay:0.0002s, distance:260.61m (Euclidean)
[2025-03-07 13:53:43,928] [ERROR] [30087] Error sending to http://localhost:30029/commit: Cannot connect to host localhost:30029 ssl:default [Connect call failed ('::1', 30029, 0, 0)]
Traceback (most recent call last):
  File "D:\anaconda\envs\PBFT\lib\site-packages\aiohttp\connector.py", line 980, in _wrap_create_connection
    return await self._loop.create_connection(*args, **kwargs)  # type: ignore[return-value]  # noqa
  File "D:\anaconda\envs\PBFT\lib\asyncio\base_events.py", line 948, in create_connection
    raise exceptions[0]
  File "D:\anaconda\envs\PBFT\lib\asyncio\base_events.py", line 935, in create_connection
    await self.sock_connect(sock, address)
  File "D:\anaconda\envs\PBFT\lib\asyncio\selector_events.py", line 475, in sock_connect
    return await fut
  File "D:\anaconda\envs\PBFT\lib\asyncio\selector_events.py", line 505, in _sock_connect_cb
    raise OSError(err, f'Connect call failed {address}')
ConnectionRefusedError: [Errno 10061] Connect call failed ('::1', 30029, 0, 0)

The above exception was the direct cause of the following exception:

Traceback (most recent call last):
  File "pbft.py", line 236, in send_message
    await send_with_delay(self.session, self.node_info, target, url, data, self.bandwidth_data)
  File "pbft.py", line 63, in send_with_delay
    async with session.post(url, json=data) as resp:
  File "D:\anaconda\envs\PBFT\lib\site-packages\aiohttp\client.py", line 1141, in __aenter__
    self._resp = await self._coro
  File "D:\anaconda\envs\PBFT\lib\site-packages\aiohttp\client.py", line 537, in _request
    req, traces=traces, timeout=real_timeout
  File "D:\anaconda\envs\PBFT\lib\site-packages\aiohttp\connector.py", line 540, in connect
    proto = await self._create_connection(req, traces, timeout)
  File "D:\anaconda\envs\PBFT\lib\site-packages\aiohttp\connector.py", line 901, in _create_connection
    _, proto = await self._create_direct_connection(req, traces, timeout)
  File "D:\anaconda\envs\PBFT\lib\site-packages\aiohttp\connector.py", line 1206, in _create_direct_connection
    raise last_exc
  File "D:\anaconda\envs\PBFT\lib\site-packages\aiohttp\connector.py", line 1187, in _create_direct_connection
    client_error=client_error,
  File "D:\anaconda\envs\PBFT\lib\site-packages\aiohttp\connector.py", line 988, in _wrap_create_connection
    raise client_error(req.connection_key, exc) from exc
aiohttp.client_exceptions.ClientConnectorError: Cannot connect to host localhost:30029 ssl:default [Connect call failed ('::1', 30029, 0, 0)]
[2025-03-07 13:53:43,960] [ERROR] [30087] Error sending to http://localhost:30075/prepare: Cannot connect to host localhost:30075 ssl:default [Connect call failed ('127.0.0.1', 30075)]
Traceback (most recent call last):
  File "D:\anaconda\envs\PBFT\lib\site-packages\aiohttp\connector.py", line 980, in _wrap_create_connection
    return await self._loop.create_connection(*args, **kwargs)  # type: ignore[return-value]  # noqa
  File "D:\anaconda\envs\PBFT\lib\asyncio\base_events.py", line 948, in create_connection
    raise exceptions[0]
  File "D:\anaconda\envs\PBFT\lib\asyncio\base_events.py", line 935, in create_connection
    await self.sock_connect(sock, address)
  File "D:\anaconda\envs\PBFT\lib\asyncio\selector_events.py", line 475, in sock_connect
    return await fut
  File "D:\anaconda\envs\PBFT\lib\asyncio\selector_events.py", line 505, in _sock_connect_cb
    raise OSError(err, f'Connect call failed {address}')
ConnectionRefusedError: [Errno 10061] Connect call failed ('127.0.0.1', 30075)

The above exception was the direct cause of the following exception:

Traceback (most recent call last):
  File "pbft.py", line 236, in send_message
    await send_with_delay(self.session, self.node_info, target, url, data, self.bandwidth_data)
  File "pbft.py", line 63, in send_with_delay
    async with session.post(url, json=data) as resp:
  File "D:\anaconda\envs\PBFT\lib\site-packages\aiohttp\client.py", line 1141, in __aenter__
    self._resp = await self._coro
  File "D:\anaconda\envs\PBFT\lib\site-packages\aiohttp\client.py", line 537, in _request
    req, traces=traces, timeout=real_timeout
  File "D:\anaconda\envs\PBFT\lib\site-packages\aiohttp\connector.py", line 540, in connect
    proto = await self._create_connection(req, traces, timeout)
  File "D:\anaconda\envs\PBFT\lib\site-packages\aiohttp\connector.py", line 901, in _create_connection
    _, proto = await self._create_direct_connection(req, traces, timeout)
  File "D:\anaconda\envs\PBFT\lib\site-packages\aiohttp\connector.py", line 1206, in _create_direct_connection
    raise last_exc
  File "D:\anaconda\envs\PBFT\lib\site-packages\aiohttp\connector.py", line 1187, in _create_direct_connection
    client_error=client_error,
  File "D:\anaconda\envs\PBFT\lib\site-packages\aiohttp\connector.py", line 988, in _wrap_create_connection
    raise client_error(req.connection_key, exc) from exc
aiohttp.client_exceptions.ClientConnectorError: Cannot connect to host localhost:30075 ssl:default [Connect call failed ('127.0.0.1', 30075)]
[2025-03-07 13:53:43,960] [ERROR] [30087] Error sending to http://localhost:30071/commit: Cannot connect to host localhost:30071 ssl:default [Connect call failed ('::1', 30071, 0, 0)]
Traceback (most recent call last):
  File "D:\anaconda\envs\PBFT\lib\site-packages\aiohttp\connector.py", line 980, in _wrap_create_connection
    return await self._loop.create_connection(*args, **kwargs)  # type: ignore[return-value]  # noqa
  File "D:\anaconda\envs\PBFT\lib\asyncio\base_events.py", line 948, in create_connection
    raise exceptions[0]
  File "D:\anaconda\envs\PBFT\lib\asyncio\base_events.py", line 935, in create_connection
    await self.sock_connect(sock, address)
  File "D:\anaconda\envs\PBFT\lib\asyncio\selector_events.py", line 475, in sock_connect
    return await fut
  File "D:\anaconda\envs\PBFT\lib\asyncio\selector_events.py", line 505, in _sock_connect_cb
    raise OSError(err, f'Connect call failed {address}')
ConnectionRefusedError: [Errno 10061] Connect call failed ('::1', 30071, 0, 0)

The above exception was the direct cause of the following exception:

Traceback (most recent call last):
  File "pbft.py", line 236, in send_message
    await send_with_delay(self.session, self.node_info, target, url, data, self.bandwidth_data)
  File "pbft.py", line 63, in send_with_delay
    async with session.post(url, json=data) as resp:
  File "D:\anaconda\envs\PBFT\lib\site-packages\aiohttp\client.py", line 1141, in __aenter__
    self._resp = await self._coro
  File "D:\anaconda\envs\PBFT\lib\site-packages\aiohttp\client.py", line 537, in _request
    req, traces=traces, timeout=real_timeout
  File "D:\anaconda\envs\PBFT\lib\site-packages\aiohttp\connector.py", line 540, in connect
    proto = await self._create_connection(req, traces, timeout)
  File "D:\anaconda\envs\PBFT\lib\site-packages\aiohttp\connector.py", line 901, in _create_connection
    _, proto = await self._create_direct_connection(req, traces, timeout)
  File "D:\anaconda\envs\PBFT\lib\site-packages\aiohttp\connector.py", line 1206, in _create_direct_connection
    raise last_exc
  File "D:\anaconda\envs\PBFT\lib\site-packages\aiohttp\connector.py", line 1187, in _create_direct_connection
    client_error=client_error,
  File "D:\anaconda\envs\PBFT\lib\site-packages\aiohttp\connector.py", line 988, in _wrap_create_connection
    raise client_error(req.connection_key, exc) from exc
aiohttp.client_exceptions.ClientConnectorError: Cannot connect to host localhost:30071 ssl:default [Connect call failed ('::1', 30071, 0, 0)]
[2025-03-07 13:53:43,976] [ERROR] [30087] Error sending to http://localhost:30071/prepare: Cannot connect to host localhost:30071 ssl:default [Connect call failed ('127.0.0.1', 30071)]
Traceback (most recent call last):
  File "D:\anaconda\envs\PBFT\lib\site-packages\aiohttp\connector.py", line 980, in _wrap_create_connection
    return await self._loop.create_connection(*args, **kwargs)  # type: ignore[return-value]  # noqa
  File "D:\anaconda\envs\PBFT\lib\asyncio\base_events.py", line 948, in create_connection
    raise exceptions[0]
  File "D:\anaconda\envs\PBFT\lib\asyncio\base_events.py", line 935, in create_connection
    await self.sock_connect(sock, address)
  File "D:\anaconda\envs\PBFT\lib\asyncio\selector_events.py", line 475, in sock_connect
    return await fut
  File "D:\anaconda\envs\PBFT\lib\asyncio\selector_events.py", line 505, in _sock_connect_cb
    raise OSError(err, f'Connect call failed {address}')
ConnectionRefusedError: [Errno 10061] Connect call failed ('127.0.0.1', 30071)

The above exception was the direct cause of the following exception:

Traceback (most recent call last):
  File "pbft.py", line 236, in send_message
    await send_with_delay(self.session, self.node_info, target, url, data, self.bandwidth_data)
  File "pbft.py", line 63, in send_with_delay
    async with session.post(url, json=data) as resp:
  File "D:\anaconda\envs\PBFT\lib\site-packages\aiohttp\client.py", line 1141, in __aenter__
    self._resp = await self._coro
  File "D:\anaconda\envs\PBFT\lib\site-packages\aiohttp\client.py", line 537, in _request
    req, traces=traces, timeout=real_timeout
  File "D:\anaconda\envs\PBFT\lib\site-packages\aiohttp\connector.py", line 540, in connect
    proto = await self._create_connection(req, traces, timeout)
  File "D:\anaconda\envs\PBFT\lib\site-packages\aiohttp\connector.py", line 901, in _create_connection
    _, proto = await self._create_direct_connection(req, traces, timeout)
  File "D:\anaconda\envs\PBFT\lib\site-packages\aiohttp\connector.py", line 1206, in _create_direct_connection
    raise last_exc
  File "D:\anaconda\envs\PBFT\lib\site-packages\aiohttp\connector.py", line 1187, in _create_direct_connection
    client_error=client_error,
  File "D:\anaconda\envs\PBFT\lib\site-packages\aiohttp\connector.py", line 988, in _wrap_create_connection
    raise client_error(req.connection_key, exc) from exc
aiohttp.client_exceptions.ClientConnectorError: Cannot connect to host localhost:30071 ssl:default [Connect call failed ('127.0.0.1', 30071)]
[2025-03-07 13:53:44,011] [INFO] [30087] Received COMMIT: id:1741323218379, from:30010, delay:0.0000s, distance:187.95m (Euclidean)
[2025-03-07 13:53:44,167] [ERROR] [30087] Error sending to http://localhost:30063/prepare: Cannot connect to host localhost:30063 ssl:default [Connect call failed ('127.0.0.1', 30063)]
Traceback (most recent call last):
  File "D:\anaconda\envs\PBFT\lib\site-packages\aiohttp\connector.py", line 980, in _wrap_create_connection
    return await self._loop.create_connection(*args, **kwargs)  # type: ignore[return-value]  # noqa
  File "D:\anaconda\envs\PBFT\lib\asyncio\base_events.py", line 948, in create_connection
    raise exceptions[0]
  File "D:\anaconda\envs\PBFT\lib\asyncio\base_events.py", line 935, in create_connection
    await self.sock_connect(sock, address)
  File "D:\anaconda\envs\PBFT\lib\asyncio\selector_events.py", line 475, in sock_connect
    return await fut
  File "D:\anaconda\envs\PBFT\lib\asyncio\selector_events.py", line 505, in _sock_connect_cb
    raise OSError(err, f'Connect call failed {address}')
ConnectionRefusedError: [Errno 10061] Connect call failed ('127.0.0.1', 30063)

The above exception was the direct cause of the following exception:

Traceback (most recent call last):
  File "pbft.py", line 236, in send_message
    await send_with_delay(self.session, self.node_info, target, url, data, self.bandwidth_data)
  File "pbft.py", line 63, in send_with_delay
    async with session.post(url, json=data) as resp:
  File "D:\anaconda\envs\PBFT\lib\site-packages\aiohttp\client.py", line 1141, in __aenter__
    self._resp = await self._coro
  File "D:\anaconda\envs\PBFT\lib\site-packages\aiohttp\client.py", line 537, in _request
    req, traces=traces, timeout=real_timeout
  File "D:\anaconda\envs\PBFT\lib\site-packages\aiohttp\connector.py", line 540, in connect
    proto = await self._create_connection(req, traces, timeout)
  File "D:\anaconda\envs\PBFT\lib\site-packages\aiohttp\connector.py", line 901, in _create_connection
    _, proto = await self._create_direct_connection(req, traces, timeout)
  File "D:\anaconda\envs\PBFT\lib\site-packages\aiohttp\connector.py", line 1206, in _create_direct_connection
    raise last_exc
  File "D:\anaconda\envs\PBFT\lib\site-packages\aiohttp\connector.py", line 1187, in _create_direct_connection
    client_error=client_error,
  File "D:\anaconda\envs\PBFT\lib\site-packages\aiohttp\connector.py", line 988, in _wrap_create_connection
    raise client_error(req.connection_key, exc) from exc
aiohttp.client_exceptions.ClientConnectorError: Cannot connect to host localhost:30063 ssl:default [Connect call failed ('127.0.0.1', 30063)]
[2025-03-07 13:53:44,260] [INFO] [30087] Received PREPARE: id:1741323218379, from:30036, delay:0.0002s, distance:265.27m (Euclidean)
[2025-03-07 13:53:44,260] [INFO] [30087] Received COMMIT: id:1741323218379, from:30060, delay:0.0002s, distance:289.11m (Euclidean)
[2025-03-07 13:53:44,260] [INFO] [30087] Received COMMIT: id:1741323218379, from:30036, delay:0.0002s, distance:265.27m (Euclidean)
[2025-03-07 13:53:44,260] [ERROR] [30087] Error sending to http://localhost:30027/commit: Cannot connect to host localhost:30027 ssl:default [Connect call failed ('::1', 30027, 0, 0)]
Traceback (most recent call last):
  File "D:\anaconda\envs\PBFT\lib\site-packages\aiohttp\connector.py", line 980, in _wrap_create_connection
    return await self._loop.create_connection(*args, **kwargs)  # type: ignore[return-value]  # noqa
  File "D:\anaconda\envs\PBFT\lib\asyncio\base_events.py", line 948, in create_connection
    raise exceptions[0]
  File "D:\anaconda\envs\PBFT\lib\asyncio\base_events.py", line 935, in create_connection
    await self.sock_connect(sock, address)
  File "D:\anaconda\envs\PBFT\lib\asyncio\selector_events.py", line 475, in sock_connect
    return await fut
  File "D:\anaconda\envs\PBFT\lib\asyncio\selector_events.py", line 505, in _sock_connect_cb
    raise OSError(err, f'Connect call failed {address}')
ConnectionRefusedError: [Errno 10061] Connect call failed ('::1', 30027, 0, 0)

The above exception was the direct cause of the following exception:

Traceback (most recent call last):
  File "pbft.py", line 236, in send_message
    await send_with_delay(self.session, self.node_info, target, url, data, self.bandwidth_data)
  File "pbft.py", line 63, in send_with_delay
    async with session.post(url, json=data) as resp:
  File "D:\anaconda\envs\PBFT\lib\site-packages\aiohttp\client.py", line 1141, in __aenter__
    self._resp = await self._coro
  File "D:\anaconda\envs\PBFT\lib\site-packages\aiohttp\client.py", line 537, in _request
    req, traces=traces, timeout=real_timeout
  File "D:\anaconda\envs\PBFT\lib\site-packages\aiohttp\connector.py", line 540, in connect
    proto = await self._create_connection(req, traces, timeout)
  File "D:\anaconda\envs\PBFT\lib\site-packages\aiohttp\connector.py", line 901, in _create_connection
    _, proto = await self._create_direct_connection(req, traces, timeout)
  File "D:\anaconda\envs\PBFT\lib\site-packages\aiohttp\connector.py", line 1206, in _create_direct_connection
    raise last_exc
  File "D:\anaconda\envs\PBFT\lib\site-packages\aiohttp\connector.py", line 1187, in _create_direct_connection
    client_error=client_error,
  File "D:\anaconda\envs\PBFT\lib\site-packages\aiohttp\connector.py", line 988, in _wrap_create_connection
    raise client_error(req.connection_key, exc) from exc
aiohttp.client_exceptions.ClientConnectorError: Cannot connect to host localhost:30027 ssl:default [Connect call failed ('::1', 30027, 0, 0)]
[2025-03-07 13:53:44,276] [INFO] [30087] Received PREPARE: id:1741323218379, from:30060, delay:0.0002s, distance:289.11m (Euclidean)
[2025-03-07 13:53:44,276] [ERROR] [30087] Error sending to http://localhost:30093/prepare: Cannot connect to host localhost:30093 ssl:default [Connect call failed ('127.0.0.1', 30093)]
Traceback (most recent call last):
  File "D:\anaconda\envs\PBFT\lib\site-packages\aiohttp\connector.py", line 980, in _wrap_create_connection
    return await self._loop.create_connection(*args, **kwargs)  # type: ignore[return-value]  # noqa
  File "D:\anaconda\envs\PBFT\lib\asyncio\base_events.py", line 948, in create_connection
    raise exceptions[0]
  File "D:\anaconda\envs\PBFT\lib\asyncio\base_events.py", line 935, in create_connection
    await self.sock_connect(sock, address)
  File "D:\anaconda\envs\PBFT\lib\asyncio\selector_events.py", line 475, in sock_connect
    return await fut
  File "D:\anaconda\envs\PBFT\lib\asyncio\selector_events.py", line 505, in _sock_connect_cb
    raise OSError(err, f'Connect call failed {address}')
ConnectionRefusedError: [Errno 10061] Connect call failed ('127.0.0.1', 30093)

The above exception was the direct cause of the following exception:

Traceback (most recent call last):
  File "pbft.py", line 236, in send_message
    await send_with_delay(self.session, self.node_info, target, url, data, self.bandwidth_data)
  File "pbft.py", line 63, in send_with_delay
    async with session.post(url, json=data) as resp:
  File "D:\anaconda\envs\PBFT\lib\site-packages\aiohttp\client.py", line 1141, in __aenter__
    self._resp = await self._coro
  File "D:\anaconda\envs\PBFT\lib\site-packages\aiohttp\client.py", line 537, in _request
    req, traces=traces, timeout=real_timeout
  File "D:\anaconda\envs\PBFT\lib\site-packages\aiohttp\connector.py", line 540, in connect
    proto = await self._create_connection(req, traces, timeout)
  File "D:\anaconda\envs\PBFT\lib\site-packages\aiohttp\connector.py", line 901, in _create_connection
    _, proto = await self._create_direct_connection(req, traces, timeout)
  File "D:\anaconda\envs\PBFT\lib\site-packages\aiohttp\connector.py", line 1206, in _create_direct_connection
    raise last_exc
  File "D:\anaconda\envs\PBFT\lib\site-packages\aiohttp\connector.py", line 1187, in _create_direct_connection
    client_error=client_error,
  File "D:\anaconda\envs\PBFT\lib\site-packages\aiohttp\connector.py", line 988, in _wrap_create_connection
    raise client_error(req.connection_key, exc) from exc
aiohttp.client_exceptions.ClientConnectorError: Cannot connect to host localhost:30093 ssl:default [Connect call failed ('127.0.0.1', 30093)]
[2025-03-07 13:53:44,388] [INFO] [30087] Received PREPARE: id:1741323218379, from:30037, delay:0.0001s, distance:158.44m (Euclidean)
[2025-03-07 13:53:44,391] [INFO] [30087] Received COMMIT: id:1741323218379, from:30037, delay:0.0001s, distance:158.44m (Euclidean)
[2025-03-07 13:53:44,391] [ERROR] [30087] Error sending to http://localhost:30085/prepare: Cannot connect to host localhost:30085 ssl:default [Connect call failed ('127.0.0.1', 30085)]
Traceback (most recent call last):
  File "D:\anaconda\envs\PBFT\lib\site-packages\aiohttp\connector.py", line 980, in _wrap_create_connection
    return await self._loop.create_connection(*args, **kwargs)  # type: ignore[return-value]  # noqa
  File "D:\anaconda\envs\PBFT\lib\asyncio\base_events.py", line 948, in create_connection
    raise exceptions[0]
  File "D:\anaconda\envs\PBFT\lib\asyncio\base_events.py", line 935, in create_connection
    await self.sock_connect(sock, address)
  File "D:\anaconda\envs\PBFT\lib\asyncio\selector_events.py", line 475, in sock_connect
    return await fut
  File "D:\anaconda\envs\PBFT\lib\asyncio\selector_events.py", line 505, in _sock_connect_cb
    raise OSError(err, f'Connect call failed {address}')
ConnectionRefusedError: [Errno 10061] Connect call failed ('127.0.0.1', 30085)

The above exception was the direct cause of the following exception:

Traceback (most recent call last):
  File "pbft.py", line 236, in send_message
    await send_with_delay(self.session, self.node_info, target, url, data, self.bandwidth_data)
  File "pbft.py", line 63, in send_with_delay
    async with session.post(url, json=data) as resp:
  File "D:\anaconda\envs\PBFT\lib\site-packages\aiohttp\client.py", line 1141, in __aenter__
    self._resp = await self._coro
  File "D:\anaconda\envs\PBFT\lib\site-packages\aiohttp\client.py", line 537, in _request
    req, traces=traces, timeout=real_timeout
  File "D:\anaconda\envs\PBFT\lib\site-packages\aiohttp\connector.py", line 540, in connect
    proto = await self._create_connection(req, traces, timeout)
  File "D:\anaconda\envs\PBFT\lib\site-packages\aiohttp\connector.py", line 901, in _create_connection
    _, proto = await self._create_direct_connection(req, traces, timeout)
  File "D:\anaconda\envs\PBFT\lib\site-packages\aiohttp\connector.py", line 1206, in _create_direct_connection
    raise last_exc
  File "D:\anaconda\envs\PBFT\lib\site-packages\aiohttp\connector.py", line 1187, in _create_direct_connection
    client_error=client_error,
  File "D:\anaconda\envs\PBFT\lib\site-packages\aiohttp\connector.py", line 988, in _wrap_create_connection
    raise client_error(req.connection_key, exc) from exc
aiohttp.client_exceptions.ClientConnectorError: Cannot connect to host localhost:30085 ssl:default [Connect call failed ('127.0.0.1', 30085)]
[2025-03-07 13:53:44,496] [INFO] [30087] Received PREPARE: id:1741323218379, from:30024, delay:0.0002s, distance:272.53m (Euclidean)
[2025-03-07 13:53:44,497] [INFO] [30087] Received COMMIT: id:1741323218379, from:30024, delay:0.0002s, distance:272.53m (Euclidean)
[2025-03-07 13:53:44,499] [ERROR] [30087] Error sending to http://localhost:30076/prepare: Cannot connect to host localhost:30076 ssl:default [Connect call failed ('127.0.0.1', 30076)]
Traceback (most recent call last):
  File "D:\anaconda\envs\PBFT\lib\site-packages\aiohttp\connector.py", line 980, in _wrap_create_connection
    return await self._loop.create_connection(*args, **kwargs)  # type: ignore[return-value]  # noqa
  File "D:\anaconda\envs\PBFT\lib\asyncio\base_events.py", line 948, in create_connection
    raise exceptions[0]
  File "D:\anaconda\envs\PBFT\lib\asyncio\base_events.py", line 935, in create_connection
    await self.sock_connect(sock, address)
  File "D:\anaconda\envs\PBFT\lib\asyncio\selector_events.py", line 475, in sock_connect
    return await fut
  File "D:\anaconda\envs\PBFT\lib\asyncio\selector_events.py", line 505, in _sock_connect_cb
    raise OSError(err, f'Connect call failed {address}')
ConnectionRefusedError: [Errno 10061] Connect call failed ('127.0.0.1', 30076)

The above exception was the direct cause of the following exception:

Traceback (most recent call last):
  File "pbft.py", line 236, in send_message
    await send_with_delay(self.session, self.node_info, target, url, data, self.bandwidth_data)
  File "pbft.py", line 63, in send_with_delay
    async with session.post(url, json=data) as resp:
  File "D:\anaconda\envs\PBFT\lib\site-packages\aiohttp\client.py", line 1141, in __aenter__
    self._resp = await self._coro
  File "D:\anaconda\envs\PBFT\lib\site-packages\aiohttp\client.py", line 537, in _request
    req, traces=traces, timeout=real_timeout
  File "D:\anaconda\envs\PBFT\lib\site-packages\aiohttp\connector.py", line 540, in connect
    proto = await self._create_connection(req, traces, timeout)
  File "D:\anaconda\envs\PBFT\lib\site-packages\aiohttp\connector.py", line 901, in _create_connection
    _, proto = await self._create_direct_connection(req, traces, timeout)
  File "D:\anaconda\envs\PBFT\lib\site-packages\aiohttp\connector.py", line 1206, in _create_direct_connection
    raise last_exc
  File "D:\anaconda\envs\PBFT\lib\site-packages\aiohttp\connector.py", line 1187, in _create_direct_connection
    client_error=client_error,
  File "D:\anaconda\envs\PBFT\lib\site-packages\aiohttp\connector.py", line 988, in _wrap_create_connection
    raise client_error(req.connection_key, exc) from exc
aiohttp.client_exceptions.ClientConnectorError: Cannot connect to host localhost:30076 ssl:default [Connect call failed ('127.0.0.1', 30076)]
[2025-03-07 13:53:44,499] [ERROR] [30087] Error sending to http://localhost:30076/commit: Cannot connect to host localhost:30076 ssl:default [Connect call failed ('::1', 30076, 0, 0)]
Traceback (most recent call last):
  File "D:\anaconda\envs\PBFT\lib\site-packages\aiohttp\connector.py", line 980, in _wrap_create_connection
    return await self._loop.create_connection(*args, **kwargs)  # type: ignore[return-value]  # noqa
  File "D:\anaconda\envs\PBFT\lib\asyncio\base_events.py", line 948, in create_connection
    raise exceptions[0]
  File "D:\anaconda\envs\PBFT\lib\asyncio\base_events.py", line 935, in create_connection
    await self.sock_connect(sock, address)
  File "D:\anaconda\envs\PBFT\lib\asyncio\selector_events.py", line 475, in sock_connect
    return await fut
  File "D:\anaconda\envs\PBFT\lib\asyncio\selector_events.py", line 505, in _sock_connect_cb
    raise OSError(err, f'Connect call failed {address}')
ConnectionRefusedError: [Errno 10061] Connect call failed ('::1', 30076, 0, 0)

The above exception was the direct cause of the following exception:

Traceback (most recent call last):
  File "pbft.py", line 236, in send_message
    await send_with_delay(self.session, self.node_info, target, url, data, self.bandwidth_data)
  File "pbft.py", line 63, in send_with_delay
    async with session.post(url, json=data) as resp:
  File "D:\anaconda\envs\PBFT\lib\site-packages\aiohttp\client.py", line 1141, in __aenter__
    self._resp = await self._coro
  File "D:\anaconda\envs\PBFT\lib\site-packages\aiohttp\client.py", line 537, in _request
    req, traces=traces, timeout=real_timeout
  File "D:\anaconda\envs\PBFT\lib\site-packages\aiohttp\connector.py", line 540, in connect
    proto = await self._create_connection(req, traces, timeout)
  File "D:\anaconda\envs\PBFT\lib\site-packages\aiohttp\connector.py", line 901, in _create_connection
    _, proto = await self._create_direct_connection(req, traces, timeout)
  File "D:\anaconda\envs\PBFT\lib\site-packages\aiohttp\connector.py", line 1206, in _create_direct_connection
    raise last_exc
  File "D:\anaconda\envs\PBFT\lib\site-packages\aiohttp\connector.py", line 1187, in _create_direct_connection
    client_error=client_error,
  File "D:\anaconda\envs\PBFT\lib\site-packages\aiohttp\connector.py", line 988, in _wrap_create_connection
    raise client_error(req.connection_key, exc) from exc
aiohttp.client_exceptions.ClientConnectorError: Cannot connect to host localhost:30076 ssl:default [Connect call failed ('::1', 30076, 0, 0)]
[2025-03-07 13:53:44,499] [INFO] [30087] Received PREPARE: id:1741323218379, from:30086, delay:0.0001s, distance:199.75m (Euclidean)
[2025-03-07 13:53:44,499] [INFO] [30087] Received COMMIT: id:1741323218379, from:30086, delay:0.0001s, distance:199.75m (Euclidean)
[2025-03-07 13:53:44,608] [ERROR] [30087] Error sending to http://localhost:30137/prepare: Cannot connect to host localhost:30137 ssl:default [Connect call failed ('127.0.0.1', 30137)]
Traceback (most recent call last):
  File "D:\anaconda\envs\PBFT\lib\site-packages\aiohttp\connector.py", line 980, in _wrap_create_connection
    return await self._loop.create_connection(*args, **kwargs)  # type: ignore[return-value]  # noqa
  File "D:\anaconda\envs\PBFT\lib\asyncio\base_events.py", line 948, in create_connection
    raise exceptions[0]
  File "D:\anaconda\envs\PBFT\lib\asyncio\base_events.py", line 935, in create_connection
    await self.sock_connect(sock, address)
  File "D:\anaconda\envs\PBFT\lib\asyncio\selector_events.py", line 475, in sock_connect
    return await fut
  File "D:\anaconda\envs\PBFT\lib\asyncio\selector_events.py", line 505, in _sock_connect_cb
    raise OSError(err, f'Connect call failed {address}')
ConnectionRefusedError: [Errno 10061] Connect call failed ('127.0.0.1', 30137)

The above exception was the direct cause of the following exception:

Traceback (most recent call last):
  File "pbft.py", line 236, in send_message
    await send_with_delay(self.session, self.node_info, target, url, data, self.bandwidth_data)
  File "pbft.py", line 63, in send_with_delay
    async with session.post(url, json=data) as resp:
  File "D:\anaconda\envs\PBFT\lib\site-packages\aiohttp\client.py", line 1141, in __aenter__
    self._resp = await self._coro
  File "D:\anaconda\envs\PBFT\lib\site-packages\aiohttp\client.py", line 537, in _request
    req, traces=traces, timeout=real_timeout
  File "D:\anaconda\envs\PBFT\lib\site-packages\aiohttp\connector.py", line 540, in connect
    proto = await self._create_connection(req, traces, timeout)
  File "D:\anaconda\envs\PBFT\lib\site-packages\aiohttp\connector.py", line 901, in _create_connection
    _, proto = await self._create_direct_connection(req, traces, timeout)
  File "D:\anaconda\envs\PBFT\lib\site-packages\aiohttp\connector.py", line 1206, in _create_direct_connection
    raise last_exc
  File "D:\anaconda\envs\PBFT\lib\site-packages\aiohttp\connector.py", line 1187, in _create_direct_connection
    client_error=client_error,
  File "D:\anaconda\envs\PBFT\lib\site-packages\aiohttp\connector.py", line 988, in _wrap_create_connection
    raise client_error(req.connection_key, exc) from exc
aiohttp.client_exceptions.ClientConnectorError: Cannot connect to host localhost:30137 ssl:default [Connect call failed ('127.0.0.1', 30137)]
[2025-03-07 13:53:44,608] [ERROR] [30087] Error sending to http://localhost:30137/commit: Cannot connect to host localhost:30137 ssl:default [Connect call failed ('::1', 30137, 0, 0)]
Traceback (most recent call last):
  File "D:\anaconda\envs\PBFT\lib\site-packages\aiohttp\connector.py", line 980, in _wrap_create_connection
    return await self._loop.create_connection(*args, **kwargs)  # type: ignore[return-value]  # noqa
  File "D:\anaconda\envs\PBFT\lib\asyncio\base_events.py", line 948, in create_connection
    raise exceptions[0]
  File "D:\anaconda\envs\PBFT\lib\asyncio\base_events.py", line 935, in create_connection
    await self.sock_connect(sock, address)
  File "D:\anaconda\envs\PBFT\lib\asyncio\selector_events.py", line 475, in sock_connect
    return await fut
  File "D:\anaconda\envs\PBFT\lib\asyncio\selector_events.py", line 505, in _sock_connect_cb
    raise OSError(err, f'Connect call failed {address}')
ConnectionRefusedError: [Errno 10061] Connect call failed ('::1', 30137, 0, 0)

The above exception was the direct cause of the following exception:

Traceback (most recent call last):
  File "pbft.py", line 236, in send_message
    await send_with_delay(self.session, self.node_info, target, url, data, self.bandwidth_data)
  File "pbft.py", line 63, in send_with_delay
    async with session.post(url, json=data) as resp:
  File "D:\anaconda\envs\PBFT\lib\site-packages\aiohttp\client.py", line 1141, in __aenter__
    self._resp = await self._coro
  File "D:\anaconda\envs\PBFT\lib\site-packages\aiohttp\client.py", line 537, in _request
    req, traces=traces, timeout=real_timeout
  File "D:\anaconda\envs\PBFT\lib\site-packages\aiohttp\connector.py", line 540, in connect
    proto = await self._create_connection(req, traces, timeout)
  File "D:\anaconda\envs\PBFT\lib\site-packages\aiohttp\connector.py", line 901, in _create_connection
    _, proto = await self._create_direct_connection(req, traces, timeout)
  File "D:\anaconda\envs\PBFT\lib\site-packages\aiohttp\connector.py", line 1206, in _create_direct_connection
    raise last_exc
  File "D:\anaconda\envs\PBFT\lib\site-packages\aiohttp\connector.py", line 1187, in _create_direct_connection
    client_error=client_error,
  File "D:\anaconda\envs\PBFT\lib\site-packages\aiohttp\connector.py", line 988, in _wrap_create_connection
    raise client_error(req.connection_key, exc) from exc
aiohttp.client_exceptions.ClientConnectorError: Cannot connect to host localhost:30137 ssl:default [Connect call failed ('::1', 30137, 0, 0)]
[2025-03-07 13:53:44,608] [INFO] [30087] Received PREPARE: id:1741323218379, from:30154, delay:0.0000s, distance:47.96m (Euclidean)
[2025-03-07 13:53:44,619] [INFO] [30087] Received PREPARE: id:1741323218379, from:30035, delay:0.0001s, distance:160.33m (Euclidean)
[2025-03-07 13:53:44,619] [INFO] [30087] Received COMMIT: id:1741323218379, from:30035, delay:0.0001s, distance:160.33m (Euclidean)
[2025-03-07 13:53:44,672] [INFO] [30087] Received PREPARE: id:1741323218379, from:30096, delay:0.0002s, distance:293.51m (Euclidean)
[2025-03-07 13:53:44,672] [INFO] [30087] Received COMMIT: id:1741323218379, from:30096, delay:0.0002s, distance:293.51m (Euclidean)
[2025-03-07 13:53:44,703] [ERROR] [30087] Error sending to http://localhost:30063/commit: Cannot connect to host localhost:30063 ssl:default [Connect call failed ('::1', 30063, 0, 0)]
Traceback (most recent call last):
  File "D:\anaconda\envs\PBFT\lib\site-packages\aiohttp\connector.py", line 980, in _wrap_create_connection
    return await self._loop.create_connection(*args, **kwargs)  # type: ignore[return-value]  # noqa
  File "D:\anaconda\envs\PBFT\lib\asyncio\base_events.py", line 948, in create_connection
    raise exceptions[0]
  File "D:\anaconda\envs\PBFT\lib\asyncio\base_events.py", line 935, in create_connection
    await self.sock_connect(sock, address)
  File "D:\anaconda\envs\PBFT\lib\asyncio\selector_events.py", line 475, in sock_connect
    return await fut
  File "D:\anaconda\envs\PBFT\lib\asyncio\selector_events.py", line 505, in _sock_connect_cb
    raise OSError(err, f'Connect call failed {address}')
ConnectionRefusedError: [Errno 10061] Connect call failed ('::1', 30063, 0, 0)

The above exception was the direct cause of the following exception:

Traceback (most recent call last):
  File "pbft.py", line 236, in send_message
    await send_with_delay(self.session, self.node_info, target, url, data, self.bandwidth_data)
  File "pbft.py", line 63, in send_with_delay
    async with session.post(url, json=data) as resp:
  File "D:\anaconda\envs\PBFT\lib\site-packages\aiohttp\client.py", line 1141, in __aenter__
    self._resp = await self._coro
  File "D:\anaconda\envs\PBFT\lib\site-packages\aiohttp\client.py", line 537, in _request
    req, traces=traces, timeout=real_timeout
  File "D:\anaconda\envs\PBFT\lib\site-packages\aiohttp\connector.py", line 540, in connect
    proto = await self._create_connection(req, traces, timeout)
  File "D:\anaconda\envs\PBFT\lib\site-packages\aiohttp\connector.py", line 901, in _create_connection
    _, proto = await self._create_direct_connection(req, traces, timeout)
  File "D:\anaconda\envs\PBFT\lib\site-packages\aiohttp\connector.py", line 1206, in _create_direct_connection
    raise last_exc
  File "D:\anaconda\envs\PBFT\lib\site-packages\aiohttp\connector.py", line 1187, in _create_direct_connection
    client_error=client_error,
  File "D:\anaconda\envs\PBFT\lib\site-packages\aiohttp\connector.py", line 988, in _wrap_create_connection
    raise client_error(req.connection_key, exc) from exc
aiohttp.client_exceptions.ClientConnectorError: Cannot connect to host localhost:30063 ssl:default [Connect call failed ('::1', 30063, 0, 0)]
[2025-03-07 13:53:44,703] [ERROR] [30087] Error sending to http://localhost:30085/commit: Cannot connect to host localhost:30085 ssl:default [Connect call failed ('::1', 30085, 0, 0)]
Traceback (most recent call last):
  File "D:\anaconda\envs\PBFT\lib\site-packages\aiohttp\connector.py", line 980, in _wrap_create_connection
    return await self._loop.create_connection(*args, **kwargs)  # type: ignore[return-value]  # noqa
  File "D:\anaconda\envs\PBFT\lib\asyncio\base_events.py", line 948, in create_connection
    raise exceptions[0]
  File "D:\anaconda\envs\PBFT\lib\asyncio\base_events.py", line 935, in create_connection
    await self.sock_connect(sock, address)
  File "D:\anaconda\envs\PBFT\lib\asyncio\selector_events.py", line 475, in sock_connect
    return await fut
  File "D:\anaconda\envs\PBFT\lib\asyncio\selector_events.py", line 505, in _sock_connect_cb
    raise OSError(err, f'Connect call failed {address}')
ConnectionRefusedError: [Errno 10061] Connect call failed ('::1', 30085, 0, 0)

The above exception was the direct cause of the following exception:

Traceback (most recent call last):
  File "pbft.py", line 236, in send_message
    await send_with_delay(self.session, self.node_info, target, url, data, self.bandwidth_data)
  File "pbft.py", line 63, in send_with_delay
    async with session.post(url, json=data) as resp:
  File "D:\anaconda\envs\PBFT\lib\site-packages\aiohttp\client.py", line 1141, in __aenter__
    self._resp = await self._coro
  File "D:\anaconda\envs\PBFT\lib\site-packages\aiohttp\client.py", line 537, in _request
    req, traces=traces, timeout=real_timeout
  File "D:\anaconda\envs\PBFT\lib\site-packages\aiohttp\connector.py", line 540, in connect
    proto = await self._create_connection(req, traces, timeout)
  File "D:\anaconda\envs\PBFT\lib\site-packages\aiohttp\connector.py", line 901, in _create_connection
    _, proto = await self._create_direct_connection(req, traces, timeout)
  File "D:\anaconda\envs\PBFT\lib\site-packages\aiohttp\connector.py", line 1206, in _create_direct_connection
    raise last_exc
  File "D:\anaconda\envs\PBFT\lib\site-packages\aiohttp\connector.py", line 1187, in _create_direct_connection
    client_error=client_error,
  File "D:\anaconda\envs\PBFT\lib\site-packages\aiohttp\connector.py", line 988, in _wrap_create_connection
    raise client_error(req.connection_key, exc) from exc
aiohttp.client_exceptions.ClientConnectorError: Cannot connect to host localhost:30085 ssl:default [Connect call failed ('::1', 30085, 0, 0)]
[2025-03-07 13:53:44,703] [ERROR] [30087] Error sending to http://localhost:30065/prepare: Cannot connect to host localhost:30065 ssl:default [Connect call failed ('127.0.0.1', 30065)]
Traceback (most recent call last):
  File "D:\anaconda\envs\PBFT\lib\site-packages\aiohttp\connector.py", line 980, in _wrap_create_connection
    return await self._loop.create_connection(*args, **kwargs)  # type: ignore[return-value]  # noqa
  File "D:\anaconda\envs\PBFT\lib\asyncio\base_events.py", line 948, in create_connection
    raise exceptions[0]
  File "D:\anaconda\envs\PBFT\lib\asyncio\base_events.py", line 935, in create_connection
    await self.sock_connect(sock, address)
  File "D:\anaconda\envs\PBFT\lib\asyncio\selector_events.py", line 475, in sock_connect
    return await fut
  File "D:\anaconda\envs\PBFT\lib\asyncio\selector_events.py", line 505, in _sock_connect_cb
    raise OSError(err, f'Connect call failed {address}')
ConnectionRefusedError: [Errno 10061] Connect call failed ('127.0.0.1', 30065)

The above exception was the direct cause of the following exception:

Traceback (most recent call last):
  File "pbft.py", line 236, in send_message
    await send_with_delay(self.session, self.node_info, target, url, data, self.bandwidth_data)
  File "pbft.py", line 63, in send_with_delay
    async with session.post(url, json=data) as resp:
  File "D:\anaconda\envs\PBFT\lib\site-packages\aiohttp\client.py", line 1141, in __aenter__
    self._resp = await self._coro
  File "D:\anaconda\envs\PBFT\lib\site-packages\aiohttp\client.py", line 537, in _request
    req, traces=traces, timeout=real_timeout
  File "D:\anaconda\envs\PBFT\lib\site-packages\aiohttp\connector.py", line 540, in connect
    proto = await self._create_connection(req, traces, timeout)
  File "D:\anaconda\envs\PBFT\lib\site-packages\aiohttp\connector.py", line 901, in _create_connection
    _, proto = await self._create_direct_connection(req, traces, timeout)
  File "D:\anaconda\envs\PBFT\lib\site-packages\aiohttp\connector.py", line 1206, in _create_direct_connection
    raise last_exc
  File "D:\anaconda\envs\PBFT\lib\site-packages\aiohttp\connector.py", line 1187, in _create_direct_connection
    client_error=client_error,
  File "D:\anaconda\envs\PBFT\lib\site-packages\aiohttp\connector.py", line 988, in _wrap_create_connection
    raise client_error(req.connection_key, exc) from exc
aiohttp.client_exceptions.ClientConnectorError: Cannot connect to host localhost:30065 ssl:default [Connect call failed ('127.0.0.1', 30065)]
[2025-03-07 13:53:44,756] [INFO] [30087] Received PREPARE: id:1741323218379, from:30094, delay:0.0002s, distance:256.24m (Euclidean)
[2025-03-07 13:53:44,756] [INFO] [30087] Received COMMIT: id:1741323218379, from:30094, delay:0.0002s, distance:256.24m (Euclidean)
[2025-03-07 13:53:44,801] [INFO] [30087] Received PREPARE: id:1741323218379, from:30044, delay:0.0002s, distance:270.04m (Euclidean)
[2025-03-07 13:53:44,801] [INFO] [30087] Received COMMIT: id:1741323218379, from:30044, delay:0.0002s, distance:270.04m (Euclidean)
[2025-03-07 13:53:44,849] [ERROR] [30087] Error sending to http://localhost:30065/commit: Cannot connect to host localhost:30065 ssl:default [Connect call failed ('::1', 30065, 0, 0)]
Traceback (most recent call last):
  File "D:\anaconda\envs\PBFT\lib\site-packages\aiohttp\connector.py", line 980, in _wrap_create_connection
    return await self._loop.create_connection(*args, **kwargs)  # type: ignore[return-value]  # noqa
  File "D:\anaconda\envs\PBFT\lib\asyncio\base_events.py", line 948, in create_connection
    raise exceptions[0]
  File "D:\anaconda\envs\PBFT\lib\asyncio\base_events.py", line 935, in create_connection
    await self.sock_connect(sock, address)
  File "D:\anaconda\envs\PBFT\lib\asyncio\selector_events.py", line 475, in sock_connect
    return await fut
  File "D:\anaconda\envs\PBFT\lib\asyncio\selector_events.py", line 505, in _sock_connect_cb
    raise OSError(err, f'Connect call failed {address}')
ConnectionRefusedError: [Errno 10061] Connect call failed ('::1', 30065, 0, 0)

The above exception was the direct cause of the following exception:

Traceback (most recent call last):
  File "pbft.py", line 236, in send_message
    await send_with_delay(self.session, self.node_info, target, url, data, self.bandwidth_data)
  File "pbft.py", line 63, in send_with_delay
    async with session.post(url, json=data) as resp:
  File "D:\anaconda\envs\PBFT\lib\site-packages\aiohttp\client.py", line 1141, in __aenter__
    self._resp = await self._coro
  File "D:\anaconda\envs\PBFT\lib\site-packages\aiohttp\client.py", line 537, in _request
    req, traces=traces, timeout=real_timeout
  File "D:\anaconda\envs\PBFT\lib\site-packages\aiohttp\connector.py", line 540, in connect
    proto = await self._create_connection(req, traces, timeout)
  File "D:\anaconda\envs\PBFT\lib\site-packages\aiohttp\connector.py", line 901, in _create_connection
    _, proto = await self._create_direct_connection(req, traces, timeout)
  File "D:\anaconda\envs\PBFT\lib\site-packages\aiohttp\connector.py", line 1206, in _create_direct_connection
    raise last_exc
  File "D:\anaconda\envs\PBFT\lib\site-packages\aiohttp\connector.py", line 1187, in _create_direct_connection
    client_error=client_error,
  File "D:\anaconda\envs\PBFT\lib\site-packages\aiohttp\connector.py", line 988, in _wrap_create_connection
    raise client_error(req.connection_key, exc) from exc
aiohttp.client_exceptions.ClientConnectorError: Cannot connect to host localhost:30065 ssl:default [Connect call failed ('::1', 30065, 0, 0)]
[2025-03-07 13:53:44,892] [INFO] [30087] Received PREPARE: id:1741323218379, from:30072, delay:0.0001s, distance:230.59m (Euclidean)
[2025-03-07 13:53:44,892] [INFO] [30087] Received COMMIT: id:1741323218379, from:30072, delay:0.0001s, distance:230.59m (Euclidean)
[2025-03-07 13:53:44,914] [INFO] [30087] Received PREPARE: id:1741323218379, from:30042, delay:0.0002s, distance:255.12m (Euclidean)
[2025-03-07 13:53:44,956] [INFO] [30087] Received COMMIT: id:1741323218379, from:30042, delay:0.0002s, distance:255.12m (Euclidean)
[2025-03-07 13:53:45,130] [INFO] [30087] Received PREPARE: id:1741323218379, from:30034, delay:0.0002s, distance:250.16m (Euclidean)
[2025-03-07 13:53:45,130] [INFO] [30087] Received COMMIT: id:1741323218379, from:30034, delay:0.0002s, distance:250.16m (Euclidean)
[2025-03-07 13:53:45,146] [INFO] [30087] Received PREPARE: id:1741323218379, from:30091, delay:0.0001s, distance:182.23m (Euclidean)
[2025-03-07 13:53:45,209] [ERROR] [30087] Error sending to http://localhost:30093/commit: Cannot connect to host localhost:30093 ssl:default [Connect call failed ('::1', 30093, 0, 0)]
Traceback (most recent call last):
  File "D:\anaconda\envs\PBFT\lib\site-packages\aiohttp\connector.py", line 980, in _wrap_create_connection
    return await self._loop.create_connection(*args, **kwargs)  # type: ignore[return-value]  # noqa
  File "D:\anaconda\envs\PBFT\lib\asyncio\base_events.py", line 948, in create_connection
    raise exceptions[0]
  File "D:\anaconda\envs\PBFT\lib\asyncio\base_events.py", line 935, in create_connection
    await self.sock_connect(sock, address)
  File "D:\anaconda\envs\PBFT\lib\asyncio\selector_events.py", line 475, in sock_connect
    return await fut
  File "D:\anaconda\envs\PBFT\lib\asyncio\selector_events.py", line 505, in _sock_connect_cb
    raise OSError(err, f'Connect call failed {address}')
ConnectionRefusedError: [Errno 10061] Connect call failed ('::1', 30093, 0, 0)

The above exception was the direct cause of the following exception:

Traceback (most recent call last):
  File "pbft.py", line 236, in send_message
    await send_with_delay(self.session, self.node_info, target, url, data, self.bandwidth_data)
  File "pbft.py", line 63, in send_with_delay
    async with session.post(url, json=data) as resp:
  File "D:\anaconda\envs\PBFT\lib\site-packages\aiohttp\client.py", line 1141, in __aenter__
    self._resp = await self._coro
  File "D:\anaconda\envs\PBFT\lib\site-packages\aiohttp\client.py", line 537, in _request
    req, traces=traces, timeout=real_timeout
  File "D:\anaconda\envs\PBFT\lib\site-packages\aiohttp\connector.py", line 540, in connect
    proto = await self._create_connection(req, traces, timeout)
  File "D:\anaconda\envs\PBFT\lib\site-packages\aiohttp\connector.py", line 901, in _create_connection
    _, proto = await self._create_direct_connection(req, traces, timeout)
  File "D:\anaconda\envs\PBFT\lib\site-packages\aiohttp\connector.py", line 1206, in _create_direct_connection
    raise last_exc
  File "D:\anaconda\envs\PBFT\lib\site-packages\aiohttp\connector.py", line 1187, in _create_direct_connection
    client_error=client_error,
  File "D:\anaconda\envs\PBFT\lib\site-packages\aiohttp\connector.py", line 988, in _wrap_create_connection
    raise client_error(req.connection_key, exc) from exc
aiohttp.client_exceptions.ClientConnectorError: Cannot connect to host localhost:30093 ssl:default [Connect call failed ('::1', 30093, 0, 0)]
[2025-03-07 13:53:45,209] [INFO] [30087] Received COMMIT: id:1741323218379, from:30091, delay:0.0001s, distance:182.23m (Euclidean)
[2025-03-07 13:53:45,383] [ERROR] [30087] Error sending to http://localhost:30023/commit: Cannot connect to host localhost:30023 ssl:default [Connect call failed ('::1', 30023, 0, 0)]
Traceback (most recent call last):
  File "D:\anaconda\envs\PBFT\lib\site-packages\aiohttp\connector.py", line 980, in _wrap_create_connection
    return await self._loop.create_connection(*args, **kwargs)  # type: ignore[return-value]  # noqa
  File "D:\anaconda\envs\PBFT\lib\asyncio\base_events.py", line 948, in create_connection
    raise exceptions[0]
  File "D:\anaconda\envs\PBFT\lib\asyncio\base_events.py", line 935, in create_connection
    await self.sock_connect(sock, address)
  File "D:\anaconda\envs\PBFT\lib\asyncio\selector_events.py", line 475, in sock_connect
    return await fut
  File "D:\anaconda\envs\PBFT\lib\asyncio\selector_events.py", line 505, in _sock_connect_cb
    raise OSError(err, f'Connect call failed {address}')
ConnectionRefusedError: [Errno 10061] Connect call failed ('::1', 30023, 0, 0)

The above exception was the direct cause of the following exception:

Traceback (most recent call last):
  File "pbft.py", line 236, in send_message
    await send_with_delay(self.session, self.node_info, target, url, data, self.bandwidth_data)
  File "pbft.py", line 63, in send_with_delay
    async with session.post(url, json=data) as resp:
  File "D:\anaconda\envs\PBFT\lib\site-packages\aiohttp\client.py", line 1141, in __aenter__
    self._resp = await self._coro
  File "D:\anaconda\envs\PBFT\lib\site-packages\aiohttp\client.py", line 537, in _request
    req, traces=traces, timeout=real_timeout
  File "D:\anaconda\envs\PBFT\lib\site-packages\aiohttp\connector.py", line 540, in connect
    proto = await self._create_connection(req, traces, timeout)
  File "D:\anaconda\envs\PBFT\lib\site-packages\aiohttp\connector.py", line 901, in _create_connection
    _, proto = await self._create_direct_connection(req, traces, timeout)
  File "D:\anaconda\envs\PBFT\lib\site-packages\aiohttp\connector.py", line 1206, in _create_direct_connection
    raise last_exc
  File "D:\anaconda\envs\PBFT\lib\site-packages\aiohttp\connector.py", line 1187, in _create_direct_connection
    client_error=client_error,
  File "D:\anaconda\envs\PBFT\lib\site-packages\aiohttp\connector.py", line 988, in _wrap_create_connection
    raise client_error(req.connection_key, exc) from exc
aiohttp.client_exceptions.ClientConnectorError: Cannot connect to host localhost:30023 ssl:default [Connect call failed ('::1', 30023, 0, 0)]
[2025-03-07 13:53:45,477] [INFO] [30087] Received PREPARE: id:1741323218379, from:30033, delay:0.0001s, distance:187.42m (Euclidean)
[2025-03-07 13:53:45,477] [INFO] [30087] Received COMMIT: id:1741323218379, from:30033, delay:0.0001s, distance:187.42m (Euclidean)
[2025-03-07 13:53:45,493] [ERROR] [30087] Error sending to http://localhost:30066/prepare: Cannot connect to host localhost:30066 ssl:default [Connect call failed ('127.0.0.1', 30066)]
Traceback (most recent call last):
  File "D:\anaconda\envs\PBFT\lib\site-packages\aiohttp\connector.py", line 980, in _wrap_create_connection
    return await self._loop.create_connection(*args, **kwargs)  # type: ignore[return-value]  # noqa
  File "D:\anaconda\envs\PBFT\lib\asyncio\base_events.py", line 948, in create_connection
    raise exceptions[0]
  File "D:\anaconda\envs\PBFT\lib\asyncio\base_events.py", line 935, in create_connection
    await self.sock_connect(sock, address)
  File "D:\anaconda\envs\PBFT\lib\asyncio\selector_events.py", line 475, in sock_connect
    return await fut
  File "D:\anaconda\envs\PBFT\lib\asyncio\selector_events.py", line 505, in _sock_connect_cb
    raise OSError(err, f'Connect call failed {address}')
ConnectionRefusedError: [Errno 10061] Connect call failed ('127.0.0.1', 30066)

The above exception was the direct cause of the following exception:

Traceback (most recent call last):
  File "pbft.py", line 236, in send_message
    await send_with_delay(self.session, self.node_info, target, url, data, self.bandwidth_data)
  File "pbft.py", line 63, in send_with_delay
    async with session.post(url, json=data) as resp:
  File "D:\anaconda\envs\PBFT\lib\site-packages\aiohttp\client.py", line 1141, in __aenter__
    self._resp = await self._coro
  File "D:\anaconda\envs\PBFT\lib\site-packages\aiohttp\client.py", line 537, in _request
    req, traces=traces, timeout=real_timeout
  File "D:\anaconda\envs\PBFT\lib\site-packages\aiohttp\connector.py", line 540, in connect
    proto = await self._create_connection(req, traces, timeout)
  File "D:\anaconda\envs\PBFT\lib\site-packages\aiohttp\connector.py", line 901, in _create_connection
    _, proto = await self._create_direct_connection(req, traces, timeout)
  File "D:\anaconda\envs\PBFT\lib\site-packages\aiohttp\connector.py", line 1206, in _create_direct_connection
    raise last_exc
  File "D:\anaconda\envs\PBFT\lib\site-packages\aiohttp\connector.py", line 1187, in _create_direct_connection
    client_error=client_error,
  File "D:\anaconda\envs\PBFT\lib\site-packages\aiohttp\connector.py", line 988, in _wrap_create_connection
    raise client_error(req.connection_key, exc) from exc
aiohttp.client_exceptions.ClientConnectorError: Cannot connect to host localhost:30066 ssl:default [Connect call failed ('127.0.0.1', 30066)]
[2025-03-07 13:53:45,541] [ERROR] [30087] Error sending to http://localhost:30066/commit: Cannot connect to host localhost:30066 ssl:default [Connect call failed ('::1', 30066, 0, 0)]
Traceback (most recent call last):
  File "D:\anaconda\envs\PBFT\lib\site-packages\aiohttp\connector.py", line 980, in _wrap_create_connection
    return await self._loop.create_connection(*args, **kwargs)  # type: ignore[return-value]  # noqa
  File "D:\anaconda\envs\PBFT\lib\asyncio\base_events.py", line 948, in create_connection
    raise exceptions[0]
  File "D:\anaconda\envs\PBFT\lib\asyncio\base_events.py", line 935, in create_connection
    await self.sock_connect(sock, address)
  File "D:\anaconda\envs\PBFT\lib\asyncio\selector_events.py", line 475, in sock_connect
    return await fut
  File "D:\anaconda\envs\PBFT\lib\asyncio\selector_events.py", line 505, in _sock_connect_cb
    raise OSError(err, f'Connect call failed {address}')
ConnectionRefusedError: [Errno 10061] Connect call failed ('::1', 30066, 0, 0)

The above exception was the direct cause of the following exception:

Traceback (most recent call last):
  File "pbft.py", line 236, in send_message
    await send_with_delay(self.session, self.node_info, target, url, data, self.bandwidth_data)
  File "pbft.py", line 63, in send_with_delay
    async with session.post(url, json=data) as resp:
  File "D:\anaconda\envs\PBFT\lib\site-packages\aiohttp\client.py", line 1141, in __aenter__
    self._resp = await self._coro
  File "D:\anaconda\envs\PBFT\lib\site-packages\aiohttp\client.py", line 537, in _request
    req, traces=traces, timeout=real_timeout
  File "D:\anaconda\envs\PBFT\lib\site-packages\aiohttp\connector.py", line 540, in connect
    proto = await self._create_connection(req, traces, timeout)
  File "D:\anaconda\envs\PBFT\lib\site-packages\aiohttp\connector.py", line 901, in _create_connection
    _, proto = await self._create_direct_connection(req, traces, timeout)
  File "D:\anaconda\envs\PBFT\lib\site-packages\aiohttp\connector.py", line 1206, in _create_direct_connection
    raise last_exc
  File "D:\anaconda\envs\PBFT\lib\site-packages\aiohttp\connector.py", line 1187, in _create_direct_connection
    client_error=client_error,
  File "D:\anaconda\envs\PBFT\lib\site-packages\aiohttp\connector.py", line 988, in _wrap_create_connection
    raise client_error(req.connection_key, exc) from exc
aiohttp.client_exceptions.ClientConnectorError: Cannot connect to host localhost:30066 ssl:default [Connect call failed ('::1', 30066, 0, 0)]
[2025-03-07 13:53:45,541] [ERROR] [30087] Error sending to http://localhost:30075/commit: Cannot connect to host localhost:30075 ssl:default [Connect call failed ('::1', 30075, 0, 0)]
Traceback (most recent call last):
  File "D:\anaconda\envs\PBFT\lib\site-packages\aiohttp\connector.py", line 980, in _wrap_create_connection
    return await self._loop.create_connection(*args, **kwargs)  # type: ignore[return-value]  # noqa
  File "D:\anaconda\envs\PBFT\lib\asyncio\base_events.py", line 948, in create_connection
    raise exceptions[0]
  File "D:\anaconda\envs\PBFT\lib\asyncio\base_events.py", line 935, in create_connection
    await self.sock_connect(sock, address)
  File "D:\anaconda\envs\PBFT\lib\asyncio\selector_events.py", line 475, in sock_connect
    return await fut
  File "D:\anaconda\envs\PBFT\lib\asyncio\selector_events.py", line 505, in _sock_connect_cb
    raise OSError(err, f'Connect call failed {address}')
ConnectionRefusedError: [Errno 10061] Connect call failed ('::1', 30075, 0, 0)

The above exception was the direct cause of the following exception:

Traceback (most recent call last):
  File "pbft.py", line 236, in send_message
    await send_with_delay(self.session, self.node_info, target, url, data, self.bandwidth_data)
  File "pbft.py", line 63, in send_with_delay
    async with session.post(url, json=data) as resp:
  File "D:\anaconda\envs\PBFT\lib\site-packages\aiohttp\client.py", line 1141, in __aenter__
    self._resp = await self._coro
  File "D:\anaconda\envs\PBFT\lib\site-packages\aiohttp\client.py", line 537, in _request
    req, traces=traces, timeout=real_timeout
  File "D:\anaconda\envs\PBFT\lib\site-packages\aiohttp\connector.py", line 540, in connect
    proto = await self._create_connection(req, traces, timeout)
  File "D:\anaconda\envs\PBFT\lib\site-packages\aiohttp\connector.py", line 901, in _create_connection
    _, proto = await self._create_direct_connection(req, traces, timeout)
  File "D:\anaconda\envs\PBFT\lib\site-packages\aiohttp\connector.py", line 1206, in _create_direct_connection
    raise last_exc
  File "D:\anaconda\envs\PBFT\lib\site-packages\aiohttp\connector.py", line 1187, in _create_direct_connection
    client_error=client_error,
  File "D:\anaconda\envs\PBFT\lib\site-packages\aiohttp\connector.py", line 988, in _wrap_create_connection
    raise client_error(req.connection_key, exc) from exc
aiohttp.client_exceptions.ClientConnectorError: Cannot connect to host localhost:30075 ssl:default [Connect call failed ('::1', 30075, 0, 0)]
[2025-03-07 13:53:45,715] [INFO] [30087] Received PREPARE: id:1741323218379, from:30061, delay:0.0001s, distance:175.47m (Euclidean)
[2025-03-07 13:53:45,776] [INFO] [30087] Received COMMIT: id:1741323218379, from:30061, delay:0.0001s, distance:175.47m (Euclidean)
[2025-03-07 13:53:45,776] [ERROR] [30087] Error sending to http://localhost:30100/prepare: Cannot connect to host localhost:30100 ssl:default [Connect call failed ('127.0.0.1', 30100)]
Traceback (most recent call last):
  File "D:\anaconda\envs\PBFT\lib\site-packages\aiohttp\connector.py", line 980, in _wrap_create_connection
    return await self._loop.create_connection(*args, **kwargs)  # type: ignore[return-value]  # noqa
  File "D:\anaconda\envs\PBFT\lib\asyncio\base_events.py", line 948, in create_connection
    raise exceptions[0]
  File "D:\anaconda\envs\PBFT\lib\asyncio\base_events.py", line 935, in create_connection
    await self.sock_connect(sock, address)
  File "D:\anaconda\envs\PBFT\lib\asyncio\selector_events.py", line 475, in sock_connect
    return await fut
  File "D:\anaconda\envs\PBFT\lib\asyncio\selector_events.py", line 505, in _sock_connect_cb
    raise OSError(err, f'Connect call failed {address}')
ConnectionRefusedError: [Errno 10061] Connect call failed ('127.0.0.1', 30100)

The above exception was the direct cause of the following exception:

Traceback (most recent call last):
  File "pbft.py", line 236, in send_message
    await send_with_delay(self.session, self.node_info, target, url, data, self.bandwidth_data)
  File "pbft.py", line 63, in send_with_delay
    async with session.post(url, json=data) as resp:
  File "D:\anaconda\envs\PBFT\lib\site-packages\aiohttp\client.py", line 1141, in __aenter__
    self._resp = await self._coro
  File "D:\anaconda\envs\PBFT\lib\site-packages\aiohttp\client.py", line 537, in _request
    req, traces=traces, timeout=real_timeout
  File "D:\anaconda\envs\PBFT\lib\site-packages\aiohttp\connector.py", line 540, in connect
    proto = await self._create_connection(req, traces, timeout)
  File "D:\anaconda\envs\PBFT\lib\site-packages\aiohttp\connector.py", line 901, in _create_connection
    _, proto = await self._create_direct_connection(req, traces, timeout)
  File "D:\anaconda\envs\PBFT\lib\site-packages\aiohttp\connector.py", line 1206, in _create_direct_connection
    raise last_exc
  File "D:\anaconda\envs\PBFT\lib\site-packages\aiohttp\connector.py", line 1187, in _create_direct_connection
    client_error=client_error,
  File "D:\anaconda\envs\PBFT\lib\site-packages\aiohttp\connector.py", line 988, in _wrap_create_connection
    raise client_error(req.connection_key, exc) from exc
aiohttp.client_exceptions.ClientConnectorError: Cannot connect to host localhost:30100 ssl:default [Connect call failed ('127.0.0.1', 30100)]
[2025-03-07 13:53:45,776] [ERROR] [30087] Error sending to http://localhost:30100/commit: Cannot connect to host localhost:30100 ssl:default [Connect call failed ('::1', 30100, 0, 0)]
Traceback (most recent call last):
  File "D:\anaconda\envs\PBFT\lib\site-packages\aiohttp\connector.py", line 980, in _wrap_create_connection
    return await self._loop.create_connection(*args, **kwargs)  # type: ignore[return-value]  # noqa
  File "D:\anaconda\envs\PBFT\lib\asyncio\base_events.py", line 948, in create_connection
    raise exceptions[0]
  File "D:\anaconda\envs\PBFT\lib\asyncio\base_events.py", line 935, in create_connection
    await self.sock_connect(sock, address)
  File "D:\anaconda\envs\PBFT\lib\asyncio\selector_events.py", line 475, in sock_connect
    return await fut
  File "D:\anaconda\envs\PBFT\lib\asyncio\selector_events.py", line 505, in _sock_connect_cb
    raise OSError(err, f'Connect call failed {address}')
ConnectionRefusedError: [Errno 10061] Connect call failed ('::1', 30100, 0, 0)

The above exception was the direct cause of the following exception:

Traceback (most recent call last):
  File "pbft.py", line 236, in send_message
    await send_with_delay(self.session, self.node_info, target, url, data, self.bandwidth_data)
  File "pbft.py", line 63, in send_with_delay
    async with session.post(url, json=data) as resp:
  File "D:\anaconda\envs\PBFT\lib\site-packages\aiohttp\client.py", line 1141, in __aenter__
    self._resp = await self._coro
  File "D:\anaconda\envs\PBFT\lib\site-packages\aiohttp\client.py", line 537, in _request
    req, traces=traces, timeout=real_timeout
  File "D:\anaconda\envs\PBFT\lib\site-packages\aiohttp\connector.py", line 540, in connect
    proto = await self._create_connection(req, traces, timeout)
  File "D:\anaconda\envs\PBFT\lib\site-packages\aiohttp\connector.py", line 901, in _create_connection
    _, proto = await self._create_direct_connection(req, traces, timeout)
  File "D:\anaconda\envs\PBFT\lib\site-packages\aiohttp\connector.py", line 1206, in _create_direct_connection
    raise last_exc
  File "D:\anaconda\envs\PBFT\lib\site-packages\aiohttp\connector.py", line 1187, in _create_direct_connection
    client_error=client_error,
  File "D:\anaconda\envs\PBFT\lib\site-packages\aiohttp\connector.py", line 988, in _wrap_create_connection
    raise client_error(req.connection_key, exc) from exc
aiohttp.client_exceptions.ClientConnectorError: Cannot connect to host localhost:30100 ssl:default [Connect call failed ('::1', 30100, 0, 0)]
[2025-03-07 13:53:45,778] [INFO] [30087] Received COMMIT: id:1741323218379, from:30158, delay:0.0000s, distance:145.40m (Euclidean)
[2025-03-07 13:53:45,778] [INFO] [30087] Received PREPARE: id:1741323218379, from:30158, delay:0.0000s, distance:145.40m (Euclidean)
[2025-03-07 13:53:46,063] [INFO] [30087] Received PREPARE: id:1741323218379, from:30030, delay:0.0002s, distance:287.06m (Euclidean)
[2025-03-07 13:53:46,063] [INFO] [30087] Received COMMIT: id:1741323218379, from:30030, delay:0.0002s, distance:287.06m (Euclidean)
[2025-03-07 13:53:46,126] [INFO] [30087] Received PREPARE: id:1741323218379, from:30007, delay:0.0002s, distance:282.77m (Euclidean)
[2025-03-07 13:53:46,126] [INFO] [30087] Received COMMIT: id:1741323218379, from:30007, delay:0.0002s, distance:282.77m (Euclidean)
[2025-03-07 13:53:46,190] [ERROR] [30087] Error sending to http://localhost:30124/commit: Cannot connect to host localhost:30124 ssl:default [Connect call failed ('::1', 30124, 0, 0)]
Traceback (most recent call last):
  File "D:\anaconda\envs\PBFT\lib\site-packages\aiohttp\connector.py", line 980, in _wrap_create_connection
    return await self._loop.create_connection(*args, **kwargs)  # type: ignore[return-value]  # noqa
  File "D:\anaconda\envs\PBFT\lib\asyncio\base_events.py", line 948, in create_connection
    raise exceptions[0]
  File "D:\anaconda\envs\PBFT\lib\asyncio\base_events.py", line 935, in create_connection
    await self.sock_connect(sock, address)
  File "D:\anaconda\envs\PBFT\lib\asyncio\selector_events.py", line 475, in sock_connect
    return await fut
  File "D:\anaconda\envs\PBFT\lib\asyncio\selector_events.py", line 505, in _sock_connect_cb
    raise OSError(err, f'Connect call failed {address}')
ConnectionRefusedError: [Errno 10061] Connect call failed ('::1', 30124, 0, 0)

The above exception was the direct cause of the following exception:

Traceback (most recent call last):
  File "pbft.py", line 236, in send_message
    await send_with_delay(self.session, self.node_info, target, url, data, self.bandwidth_data)
  File "pbft.py", line 63, in send_with_delay
    async with session.post(url, json=data) as resp:
  File "D:\anaconda\envs\PBFT\lib\site-packages\aiohttp\client.py", line 1141, in __aenter__
    self._resp = await self._coro
  File "D:\anaconda\envs\PBFT\lib\site-packages\aiohttp\client.py", line 537, in _request
    req, traces=traces, timeout=real_timeout
  File "D:\anaconda\envs\PBFT\lib\site-packages\aiohttp\connector.py", line 540, in connect
    proto = await self._create_connection(req, traces, timeout)
  File "D:\anaconda\envs\PBFT\lib\site-packages\aiohttp\connector.py", line 901, in _create_connection
    _, proto = await self._create_direct_connection(req, traces, timeout)
  File "D:\anaconda\envs\PBFT\lib\site-packages\aiohttp\connector.py", line 1206, in _create_direct_connection
    raise last_exc
  File "D:\anaconda\envs\PBFT\lib\site-packages\aiohttp\connector.py", line 1187, in _create_direct_connection
    client_error=client_error,
  File "D:\anaconda\envs\PBFT\lib\site-packages\aiohttp\connector.py", line 988, in _wrap_create_connection
    raise client_error(req.connection_key, exc) from exc
aiohttp.client_exceptions.ClientConnectorError: Cannot connect to host localhost:30124 ssl:default [Connect call failed ('::1', 30124, 0, 0)]
[2025-03-07 13:53:46,380] [INFO] [30087] Received PREPARE: id:1741323218379, from:30003, delay:0.0001s, distance:209.84m (Euclidean)
[2025-03-07 13:53:46,386] [INFO] [30087] Received COMMIT: id:1741323218379, from:30003, delay:0.0001s, distance:209.84m (Euclidean)
[2025-03-07 13:53:46,507] [INFO] [30087] Received PREPARE: id:1741323218379, from:30095, delay:0.0001s, distance:233.29m (Euclidean)
[2025-03-07 13:53:46,507] [INFO] [30087] Received COMMIT: id:1741323218379, from:30095, delay:0.0001s, distance:233.29m (Euclidean)
[2025-03-07 13:53:46,586] [INFO] [30087] Received PREPARE: id:1741323218379, from:30043, delay:0.0002s, distance:298.34m (Euclidean)
[2025-03-07 13:53:46,586] [INFO] [30087] Received COMMIT: id:1741323218379, from:30043, delay:0.0002s, distance:298.34m (Euclidean)
[2025-03-07 13:53:46,586] [INFO] [30087] Received PREPARE: id:1741323218379, from:30102, delay:0.0001s, distance:234.33m (Euclidean)
[2025-03-07 13:53:46,586] [INFO] [30087] Received COMMIT: id:1741323218379, from:30102, delay:0.0001s, distance:234.33m (Euclidean)
[2025-03-07 13:53:46,697] [INFO] [30087] Received PREPARE: id:1741323218379, from:30041, delay:0.0001s, distance:250.07m (Euclidean)
[2025-03-07 13:53:46,697] [INFO] [30087] Received COMMIT: id:1741323218379, from:30041, delay:0.0001s, distance:250.07m (Euclidean)
[2025-03-07 13:53:46,871] [ERROR] [30087] Error sending to http://localhost:30101/commit: Cannot connect to host localhost:30101 ssl:default [Connect call failed ('::1', 30101, 0, 0)]
Traceback (most recent call last):
  File "D:\anaconda\envs\PBFT\lib\site-packages\aiohttp\connector.py", line 980, in _wrap_create_connection
    return await self._loop.create_connection(*args, **kwargs)  # type: ignore[return-value]  # noqa
  File "D:\anaconda\envs\PBFT\lib\asyncio\base_events.py", line 948, in create_connection
    raise exceptions[0]
  File "D:\anaconda\envs\PBFT\lib\asyncio\base_events.py", line 935, in create_connection
    await self.sock_connect(sock, address)
  File "D:\anaconda\envs\PBFT\lib\asyncio\selector_events.py", line 475, in sock_connect
    return await fut
  File "D:\anaconda\envs\PBFT\lib\asyncio\selector_events.py", line 505, in _sock_connect_cb
    raise OSError(err, f'Connect call failed {address}')
ConnectionRefusedError: [Errno 10061] Connect call failed ('::1', 30101, 0, 0)

The above exception was the direct cause of the following exception:

Traceback (most recent call last):
  File "pbft.py", line 236, in send_message
    await send_with_delay(self.session, self.node_info, target, url, data, self.bandwidth_data)
  File "pbft.py", line 63, in send_with_delay
    async with session.post(url, json=data) as resp:
  File "D:\anaconda\envs\PBFT\lib\site-packages\aiohttp\client.py", line 1141, in __aenter__
    self._resp = await self._coro
  File "D:\anaconda\envs\PBFT\lib\site-packages\aiohttp\client.py", line 537, in _request
    req, traces=traces, timeout=real_timeout
  File "D:\anaconda\envs\PBFT\lib\site-packages\aiohttp\connector.py", line 540, in connect
    proto = await self._create_connection(req, traces, timeout)
  File "D:\anaconda\envs\PBFT\lib\site-packages\aiohttp\connector.py", line 901, in _create_connection
    _, proto = await self._create_direct_connection(req, traces, timeout)
  File "D:\anaconda\envs\PBFT\lib\site-packages\aiohttp\connector.py", line 1206, in _create_direct_connection
    raise last_exc
  File "D:\anaconda\envs\PBFT\lib\site-packages\aiohttp\connector.py", line 1187, in _create_direct_connection
    client_error=client_error,
  File "D:\anaconda\envs\PBFT\lib\site-packages\aiohttp\connector.py", line 988, in _wrap_create_connection
    raise client_error(req.connection_key, exc) from exc
aiohttp.client_exceptions.ClientConnectorError: Cannot connect to host localhost:30101 ssl:default [Connect call failed ('::1', 30101, 0, 0)]
[2025-03-07 13:53:46,871] [ERROR] [30087] Error sending to http://localhost:30101/prepare: Cannot connect to host localhost:30101 ssl:default [Connect call failed ('127.0.0.1', 30101)]
Traceback (most recent call last):
  File "D:\anaconda\envs\PBFT\lib\site-packages\aiohttp\connector.py", line 980, in _wrap_create_connection
    return await self._loop.create_connection(*args, **kwargs)  # type: ignore[return-value]  # noqa
  File "D:\anaconda\envs\PBFT\lib\asyncio\base_events.py", line 948, in create_connection
    raise exceptions[0]
  File "D:\anaconda\envs\PBFT\lib\asyncio\base_events.py", line 935, in create_connection
    await self.sock_connect(sock, address)
  File "D:\anaconda\envs\PBFT\lib\asyncio\selector_events.py", line 475, in sock_connect
    return await fut
  File "D:\anaconda\envs\PBFT\lib\asyncio\selector_events.py", line 505, in _sock_connect_cb
    raise OSError(err, f'Connect call failed {address}')
ConnectionRefusedError: [Errno 10061] Connect call failed ('127.0.0.1', 30101)

The above exception was the direct cause of the following exception:

Traceback (most recent call last):
  File "pbft.py", line 236, in send_message
    await send_with_delay(self.session, self.node_info, target, url, data, self.bandwidth_data)
  File "pbft.py", line 63, in send_with_delay
    async with session.post(url, json=data) as resp:
  File "D:\anaconda\envs\PBFT\lib\site-packages\aiohttp\client.py", line 1141, in __aenter__
    self._resp = await self._coro
  File "D:\anaconda\envs\PBFT\lib\site-packages\aiohttp\client.py", line 537, in _request
    req, traces=traces, timeout=real_timeout
  File "D:\anaconda\envs\PBFT\lib\site-packages\aiohttp\connector.py", line 540, in connect
    proto = await self._create_connection(req, traces, timeout)
  File "D:\anaconda\envs\PBFT\lib\site-packages\aiohttp\connector.py", line 901, in _create_connection
    _, proto = await self._create_direct_connection(req, traces, timeout)
  File "D:\anaconda\envs\PBFT\lib\site-packages\aiohttp\connector.py", line 1206, in _create_direct_connection
    raise last_exc
  File "D:\anaconda\envs\PBFT\lib\site-packages\aiohttp\connector.py", line 1187, in _create_direct_connection
    client_error=client_error,
  File "D:\anaconda\envs\PBFT\lib\site-packages\aiohttp\connector.py", line 988, in _wrap_create_connection
    raise client_error(req.connection_key, exc) from exc
aiohttp.client_exceptions.ClientConnectorError: Cannot connect to host localhost:30101 ssl:default [Connect call failed ('127.0.0.1', 30101)]
[2025-03-07 13:53:46,871] [INFO] [30087] Received PREPARE: id:1741323218379, from:30135, delay:0.0000s, distance:147.65m (Euclidean)
[2025-03-07 13:53:46,871] [INFO] [30087] Received COMMIT: id:1741323218379, from:30135, delay:0.0000s, distance:147.65m (Euclidean)
[2025-03-07 13:53:46,902] [INFO] [30087] Received PREPARE: id:1741323218379, from:30147, delay:0.0000s, distance:187.81m (Euclidean)
[2025-03-07 13:53:46,902] [INFO] [30087] Received COMMIT: id:1741323218379, from:30147, delay:0.0000s, distance:187.81m (Euclidean)
[2025-03-07 13:53:47,109] [INFO] [30087] Received PREPARE: id:1741323218379, from:30136, delay:0.0001s, distance:156.48m (Euclidean)
[2025-03-07 13:53:47,109] [INFO] [30087] Received COMMIT: id:1741323218379, from:30136, delay:0.0001s, distance:156.48m (Euclidean)
[2025-03-07 13:53:47,204] [INFO] [30087] Received PREPARE: id:1741323218379, from:30122, delay:0.0002s, distance:298.26m (Euclidean)
[2025-03-07 13:53:47,204] [INFO] [30087] Received COMMIT: id:1741323218379, from:30122, delay:0.0002s, distance:298.26m (Euclidean)
[2025-03-07 13:53:47,330] [INFO] [30087] Received COMMIT: id:1741323218379, from:30154, delay:0.0000s, distance:47.96m (Euclidean)
[2025-03-07 13:53:47,391] [INFO] [30087] Received PREPARE: id:1741323218379, from:30134, delay:0.0001s, distance:167.34m (Euclidean)
[2025-03-07 13:53:47,391] [INFO] [30087] Received COMMIT: id:1741323218379, from:30110, delay:0.0001s, distance:186.54m (Euclidean)
[2025-03-07 13:53:47,391] [INFO] [30087] Received COMMIT: id:1741323218379, from:30134, delay:0.0001s, distance:167.34m (Euclidean)
[2025-03-07 13:53:47,391] [INFO] [30087] Received PREPARE: id:1741323218379, from:30105, delay:0.0001s, distance:225.97m (Euclidean)
[2025-03-07 13:53:47,391] [INFO] [30087] Received PREPARE: id:1741323218379, from:30110, delay:0.0001s, distance:186.54m (Euclidean)
[2025-03-07 13:53:47,391] [INFO] [30087] Received COMMIT: id:1741323218379, from:30105, delay:0.0001s, distance:225.97m (Euclidean)
[2025-03-07 13:53:47,439] [INFO] [30087] Received PREPARE: id:1741323218379, from:30153, delay:0.0001s, distance:212.40m (Euclidean)
[2025-03-07 13:53:47,453] [INFO] [30087] Received COMMIT: id:1741323218379, from:30153, delay:0.0001s, distance:212.40m (Euclidean)
[2025-03-07 13:53:47,826] [INFO] [30087] Received PREPARE: id:1741323218379, from:30157, delay:0.0000s, distance:85.50m (Euclidean)
[2025-03-07 13:53:47,929] [INFO] [30087] Received PREPARE: id:1741323218379, from:30107, delay:0.0000s, distance:147.78m (Euclidean)
[2025-03-07 13:53:48,210] [INFO] [30087] Received COMMIT: id:1741323218379, from:30157, delay:0.0000s, distance:85.50m (Euclidean)
[2025-03-07 13:53:48,325] [ERROR] [30087] Error sending to http://localhost:30125/commit: Cannot connect to host localhost:30125 ssl:default [Connect call failed ('::1', 30125, 0, 0)]
Traceback (most recent call last):
  File "D:\anaconda\envs\PBFT\lib\site-packages\aiohttp\connector.py", line 980, in _wrap_create_connection
    return await self._loop.create_connection(*args, **kwargs)  # type: ignore[return-value]  # noqa
  File "D:\anaconda\envs\PBFT\lib\asyncio\base_events.py", line 948, in create_connection
    raise exceptions[0]
  File "D:\anaconda\envs\PBFT\lib\asyncio\base_events.py", line 935, in create_connection
    await self.sock_connect(sock, address)
  File "D:\anaconda\envs\PBFT\lib\asyncio\selector_events.py", line 475, in sock_connect
    return await fut
  File "D:\anaconda\envs\PBFT\lib\asyncio\selector_events.py", line 505, in _sock_connect_cb
    raise OSError(err, f'Connect call failed {address}')
ConnectionRefusedError: [Errno 10061] Connect call failed ('::1', 30125, 0, 0)

The above exception was the direct cause of the following exception:

Traceback (most recent call last):
  File "pbft.py", line 236, in send_message
    await send_with_delay(self.session, self.node_info, target, url, data, self.bandwidth_data)
  File "pbft.py", line 63, in send_with_delay
    async with session.post(url, json=data) as resp:
  File "D:\anaconda\envs\PBFT\lib\site-packages\aiohttp\client.py", line 1141, in __aenter__
    self._resp = await self._coro
  File "D:\anaconda\envs\PBFT\lib\site-packages\aiohttp\client.py", line 537, in _request
    req, traces=traces, timeout=real_timeout
  File "D:\anaconda\envs\PBFT\lib\site-packages\aiohttp\connector.py", line 540, in connect
    proto = await self._create_connection(req, traces, timeout)
  File "D:\anaconda\envs\PBFT\lib\site-packages\aiohttp\connector.py", line 901, in _create_connection
    _, proto = await self._create_direct_connection(req, traces, timeout)
  File "D:\anaconda\envs\PBFT\lib\site-packages\aiohttp\connector.py", line 1206, in _create_direct_connection
    raise last_exc
  File "D:\anaconda\envs\PBFT\lib\site-packages\aiohttp\connector.py", line 1187, in _create_direct_connection
    client_error=client_error,
  File "D:\anaconda\envs\PBFT\lib\site-packages\aiohttp\connector.py", line 988, in _wrap_create_connection
    raise client_error(req.connection_key, exc) from exc
aiohttp.client_exceptions.ClientConnectorError: Cannot connect to host localhost:30125 ssl:default [Connect call failed ('::1', 30125, 0, 0)]
[2025-03-07 13:53:48,325] [INFO] [30087] Received PREPARE: id:1741323218379, from:30131, delay:0.0001s, distance:204.50m (Euclidean)
[2025-03-07 13:53:48,340] [ERROR] [30087] Error sending to http://localhost:30125/prepare: Cannot connect to host localhost:30125 ssl:default [Connect call failed ('127.0.0.1', 30125)]
Traceback (most recent call last):
  File "D:\anaconda\envs\PBFT\lib\site-packages\aiohttp\connector.py", line 980, in _wrap_create_connection
    return await self._loop.create_connection(*args, **kwargs)  # type: ignore[return-value]  # noqa
  File "D:\anaconda\envs\PBFT\lib\asyncio\base_events.py", line 948, in create_connection
    raise exceptions[0]
  File "D:\anaconda\envs\PBFT\lib\asyncio\base_events.py", line 935, in create_connection
    await self.sock_connect(sock, address)
  File "D:\anaconda\envs\PBFT\lib\asyncio\selector_events.py", line 475, in sock_connect
    return await fut
  File "D:\anaconda\envs\PBFT\lib\asyncio\selector_events.py", line 505, in _sock_connect_cb
    raise OSError(err, f'Connect call failed {address}')
ConnectionRefusedError: [Errno 10061] Connect call failed ('127.0.0.1', 30125)

The above exception was the direct cause of the following exception:

Traceback (most recent call last):
  File "pbft.py", line 236, in send_message
    await send_with_delay(self.session, self.node_info, target, url, data, self.bandwidth_data)
  File "pbft.py", line 63, in send_with_delay
    async with session.post(url, json=data) as resp:
  File "D:\anaconda\envs\PBFT\lib\site-packages\aiohttp\client.py", line 1141, in __aenter__
    self._resp = await self._coro
  File "D:\anaconda\envs\PBFT\lib\site-packages\aiohttp\client.py", line 537, in _request
    req, traces=traces, timeout=real_timeout
  File "D:\anaconda\envs\PBFT\lib\site-packages\aiohttp\connector.py", line 540, in connect
    proto = await self._create_connection(req, traces, timeout)
  File "D:\anaconda\envs\PBFT\lib\site-packages\aiohttp\connector.py", line 901, in _create_connection
    _, proto = await self._create_direct_connection(req, traces, timeout)
  File "D:\anaconda\envs\PBFT\lib\site-packages\aiohttp\connector.py", line 1206, in _create_direct_connection
    raise last_exc
  File "D:\anaconda\envs\PBFT\lib\site-packages\aiohttp\connector.py", line 1187, in _create_direct_connection
    client_error=client_error,
  File "D:\anaconda\envs\PBFT\lib\site-packages\aiohttp\connector.py", line 988, in _wrap_create_connection
    raise client_error(req.connection_key, exc) from exc
aiohttp.client_exceptions.ClientConnectorError: Cannot connect to host localhost:30125 ssl:default [Connect call failed ('127.0.0.1', 30125)]
[2025-03-07 13:53:48,342] [INFO] [30087] Received COMMIT: id:1741323218379, from:30107, delay:0.0000s, distance:147.78m (Euclidean)
[2025-03-07 13:53:48,427] [INFO] [30087] Received PREPARE: id:1741323218379, from:30128, delay:0.0000s, distance:59.90m (Euclidean)
[2025-03-07 13:53:48,427] [INFO] [30087] Received COMMIT: id:1741323218379, from:30128, delay:0.0000s, distance:59.90m (Euclidean)
[2025-03-07 13:53:48,483] [INFO] [30087] Received COMMIT: id:1741323218379, from:30131, delay:0.0001s, distance:204.50m (Euclidean)
[2025-03-07 13:53:48,574] [INFO] [30087] Received PREPARE: id:1741323218379, from:30139, delay:0.0001s, distance:231.77m (Euclidean)
[2025-03-07 13:53:48,574] [INFO] [30087] Received COMMIT: id:1741323218379, from:30139, delay:0.0001s, distance:231.77m (Euclidean)
[2025-03-07 13:53:48,577] [ERROR] [30087] Error sending to http://localhost:30138/prepare: Cannot connect to host localhost:30138 ssl:default [Connect call failed ('127.0.0.1', 30138)]
Traceback (most recent call last):
  File "D:\anaconda\envs\PBFT\lib\site-packages\aiohttp\connector.py", line 980, in _wrap_create_connection
    return await self._loop.create_connection(*args, **kwargs)  # type: ignore[return-value]  # noqa
  File "D:\anaconda\envs\PBFT\lib\asyncio\base_events.py", line 948, in create_connection
    raise exceptions[0]
  File "D:\anaconda\envs\PBFT\lib\asyncio\base_events.py", line 935, in create_connection
    await self.sock_connect(sock, address)
  File "D:\anaconda\envs\PBFT\lib\asyncio\selector_events.py", line 475, in sock_connect
    return await fut
  File "D:\anaconda\envs\PBFT\lib\asyncio\selector_events.py", line 505, in _sock_connect_cb
    raise OSError(err, f'Connect call failed {address}')
ConnectionRefusedError: [Errno 10061] Connect call failed ('127.0.0.1', 30138)

The above exception was the direct cause of the following exception:

Traceback (most recent call last):
  File "pbft.py", line 236, in send_message
    await send_with_delay(self.session, self.node_info, target, url, data, self.bandwidth_data)
  File "pbft.py", line 63, in send_with_delay
    async with session.post(url, json=data) as resp:
  File "D:\anaconda\envs\PBFT\lib\site-packages\aiohttp\client.py", line 1141, in __aenter__
    self._resp = await self._coro
  File "D:\anaconda\envs\PBFT\lib\site-packages\aiohttp\client.py", line 537, in _request
    req, traces=traces, timeout=real_timeout
  File "D:\anaconda\envs\PBFT\lib\site-packages\aiohttp\connector.py", line 540, in connect
    proto = await self._create_connection(req, traces, timeout)
  File "D:\anaconda\envs\PBFT\lib\site-packages\aiohttp\connector.py", line 901, in _create_connection
    _, proto = await self._create_direct_connection(req, traces, timeout)
  File "D:\anaconda\envs\PBFT\lib\site-packages\aiohttp\connector.py", line 1206, in _create_direct_connection
    raise last_exc
  File "D:\anaconda\envs\PBFT\lib\site-packages\aiohttp\connector.py", line 1187, in _create_direct_connection
    client_error=client_error,
  File "D:\anaconda\envs\PBFT\lib\site-packages\aiohttp\connector.py", line 988, in _wrap_create_connection
    raise client_error(req.connection_key, exc) from exc
aiohttp.client_exceptions.ClientConnectorError: Cannot connect to host localhost:30138 ssl:default [Connect call failed ('127.0.0.1', 30138)]
[2025-03-07 13:53:48,657] [ERROR] [30087] Error sending to http://localhost:30138/commit: Cannot connect to host localhost:30138 ssl:default [Connect call failed ('::1', 30138, 0, 0)]
Traceback (most recent call last):
  File "D:\anaconda\envs\PBFT\lib\site-packages\aiohttp\connector.py", line 980, in _wrap_create_connection
    return await self._loop.create_connection(*args, **kwargs)  # type: ignore[return-value]  # noqa
  File "D:\anaconda\envs\PBFT\lib\asyncio\base_events.py", line 948, in create_connection
    raise exceptions[0]
  File "D:\anaconda\envs\PBFT\lib\asyncio\base_events.py", line 935, in create_connection
    await self.sock_connect(sock, address)
  File "D:\anaconda\envs\PBFT\lib\asyncio\selector_events.py", line 475, in sock_connect
    return await fut
  File "D:\anaconda\envs\PBFT\lib\asyncio\selector_events.py", line 505, in _sock_connect_cb
    raise OSError(err, f'Connect call failed {address}')
ConnectionRefusedError: [Errno 10061] Connect call failed ('::1', 30138, 0, 0)

The above exception was the direct cause of the following exception:

Traceback (most recent call last):
  File "pbft.py", line 236, in send_message
    await send_with_delay(self.session, self.node_info, target, url, data, self.bandwidth_data)
  File "pbft.py", line 63, in send_with_delay
    async with session.post(url, json=data) as resp:
  File "D:\anaconda\envs\PBFT\lib\site-packages\aiohttp\client.py", line 1141, in __aenter__
    self._resp = await self._coro
  File "D:\anaconda\envs\PBFT\lib\site-packages\aiohttp\client.py", line 537, in _request
    req, traces=traces, timeout=real_timeout
  File "D:\anaconda\envs\PBFT\lib\site-packages\aiohttp\connector.py", line 540, in connect
    proto = await self._create_connection(req, traces, timeout)
  File "D:\anaconda\envs\PBFT\lib\site-packages\aiohttp\connector.py", line 901, in _create_connection
    _, proto = await self._create_direct_connection(req, traces, timeout)
  File "D:\anaconda\envs\PBFT\lib\site-packages\aiohttp\connector.py", line 1206, in _create_direct_connection
    raise last_exc
  File "D:\anaconda\envs\PBFT\lib\site-packages\aiohttp\connector.py", line 1187, in _create_direct_connection
    client_error=client_error,
  File "D:\anaconda\envs\PBFT\lib\site-packages\aiohttp\connector.py", line 988, in _wrap_create_connection
    raise client_error(req.connection_key, exc) from exc
aiohttp.client_exceptions.ClientConnectorError: Cannot connect to host localhost:30138 ssl:default [Connect call failed ('::1', 30138, 0, 0)]
[2025-03-07 13:53:48,735] [INFO] [30087] Received PREPARE: id:1741323218379, from:30109, delay:0.0002s, distance:270.23m (Euclidean)
[2025-03-07 13:53:48,735] [INFO] [30087] Received COMMIT: id:1741323218379, from:30109, delay:0.0002s, distance:270.23m (Euclidean)
[2025-03-07 13:53:48,929] [INFO] [30087] Received PREPARE: id:1741323218379, from:30133, delay:0.0002s, distance:264.13m (Euclidean)
[2025-03-07 13:53:48,929] [INFO] [30087] Received COMMIT: id:1741323218379, from:30133, delay:0.0002s, distance:264.13m (Euclidean)
[2025-03-07 13:53:49,067] [ERROR] [30087] Error sending to http://localhost:30143/prepare: Cannot connect to host localhost:30143 ssl:default [Connect call failed ('127.0.0.1', 30143)]
Traceback (most recent call last):
  File "D:\anaconda\envs\PBFT\lib\site-packages\aiohttp\connector.py", line 980, in _wrap_create_connection
    return await self._loop.create_connection(*args, **kwargs)  # type: ignore[return-value]  # noqa
  File "D:\anaconda\envs\PBFT\lib\asyncio\base_events.py", line 948, in create_connection
    raise exceptions[0]
  File "D:\anaconda\envs\PBFT\lib\asyncio\base_events.py", line 935, in create_connection
    await self.sock_connect(sock, address)
  File "D:\anaconda\envs\PBFT\lib\asyncio\selector_events.py", line 475, in sock_connect
    return await fut
  File "D:\anaconda\envs\PBFT\lib\asyncio\selector_events.py", line 505, in _sock_connect_cb
    raise OSError(err, f'Connect call failed {address}')
ConnectionRefusedError: [Errno 10061] Connect call failed ('127.0.0.1', 30143)

The above exception was the direct cause of the following exception:

Traceback (most recent call last):
  File "pbft.py", line 236, in send_message
    await send_with_delay(self.session, self.node_info, target, url, data, self.bandwidth_data)
  File "pbft.py", line 63, in send_with_delay
    async with session.post(url, json=data) as resp:
  File "D:\anaconda\envs\PBFT\lib\site-packages\aiohttp\client.py", line 1141, in __aenter__
    self._resp = await self._coro
  File "D:\anaconda\envs\PBFT\lib\site-packages\aiohttp\client.py", line 537, in _request
    req, traces=traces, timeout=real_timeout
  File "D:\anaconda\envs\PBFT\lib\site-packages\aiohttp\connector.py", line 540, in connect
    proto = await self._create_connection(req, traces, timeout)
  File "D:\anaconda\envs\PBFT\lib\site-packages\aiohttp\connector.py", line 901, in _create_connection
    _, proto = await self._create_direct_connection(req, traces, timeout)
  File "D:\anaconda\envs\PBFT\lib\site-packages\aiohttp\connector.py", line 1206, in _create_direct_connection
    raise last_exc
  File "D:\anaconda\envs\PBFT\lib\site-packages\aiohttp\connector.py", line 1187, in _create_direct_connection
    client_error=client_error,
  File "D:\anaconda\envs\PBFT\lib\site-packages\aiohttp\connector.py", line 988, in _wrap_create_connection
    raise client_error(req.connection_key, exc) from exc
aiohttp.client_exceptions.ClientConnectorError: Cannot connect to host localhost:30143 ssl:default [Connect call failed ('127.0.0.1', 30143)]
[2025-03-07 13:53:49,067] [INFO] [30087] Received PREPARE: id:1741323218379, from:30144, delay:0.0001s, distance:197.29m (Euclidean)
[2025-03-07 13:53:49,067] [INFO] [30087] Received COMMIT: id:1741323218379, from:30144, delay:0.0001s, distance:197.29m (Euclidean)
[2025-03-07 13:53:49,082] [ERROR] [30087] Error sending to http://localhost:30143/commit: Cannot connect to host localhost:30143 ssl:default [Connect call failed ('::1', 30143, 0, 0)]
Traceback (most recent call last):
  File "D:\anaconda\envs\PBFT\lib\site-packages\aiohttp\connector.py", line 980, in _wrap_create_connection
    return await self._loop.create_connection(*args, **kwargs)  # type: ignore[return-value]  # noqa
  File "D:\anaconda\envs\PBFT\lib\asyncio\base_events.py", line 948, in create_connection
    raise exceptions[0]
  File "D:\anaconda\envs\PBFT\lib\asyncio\base_events.py", line 935, in create_connection
    await self.sock_connect(sock, address)
  File "D:\anaconda\envs\PBFT\lib\asyncio\selector_events.py", line 475, in sock_connect
    return await fut
  File "D:\anaconda\envs\PBFT\lib\asyncio\selector_events.py", line 505, in _sock_connect_cb
    raise OSError(err, f'Connect call failed {address}')
ConnectionRefusedError: [Errno 10061] Connect call failed ('::1', 30143, 0, 0)

The above exception was the direct cause of the following exception:

Traceback (most recent call last):
  File "pbft.py", line 236, in send_message
    await send_with_delay(self.session, self.node_info, target, url, data, self.bandwidth_data)
  File "pbft.py", line 63, in send_with_delay
    async with session.post(url, json=data) as resp:
  File "D:\anaconda\envs\PBFT\lib\site-packages\aiohttp\client.py", line 1141, in __aenter__
    self._resp = await self._coro
  File "D:\anaconda\envs\PBFT\lib\site-packages\aiohttp\client.py", line 537, in _request
    req, traces=traces, timeout=real_timeout
  File "D:\anaconda\envs\PBFT\lib\site-packages\aiohttp\connector.py", line 540, in connect
    proto = await self._create_connection(req, traces, timeout)
  File "D:\anaconda\envs\PBFT\lib\site-packages\aiohttp\connector.py", line 901, in _create_connection
    _, proto = await self._create_direct_connection(req, traces, timeout)
  File "D:\anaconda\envs\PBFT\lib\site-packages\aiohttp\connector.py", line 1206, in _create_direct_connection
    raise last_exc
  File "D:\anaconda\envs\PBFT\lib\site-packages\aiohttp\connector.py", line 1187, in _create_direct_connection
    client_error=client_error,
  File "D:\anaconda\envs\PBFT\lib\site-packages\aiohttp\connector.py", line 988, in _wrap_create_connection
    raise client_error(req.connection_key, exc) from exc
aiohttp.client_exceptions.ClientConnectorError: Cannot connect to host localhost:30143 ssl:default [Connect call failed ('::1', 30143, 0, 0)]
[2025-03-07 13:53:49,193] [ERROR] [30087] Error sending to http://localhost:30140/prepare: Cannot connect to host localhost:30140 ssl:default [Connect call failed ('127.0.0.1', 30140)]
Traceback (most recent call last):
  File "D:\anaconda\envs\PBFT\lib\site-packages\aiohttp\connector.py", line 980, in _wrap_create_connection
    return await self._loop.create_connection(*args, **kwargs)  # type: ignore[return-value]  # noqa
  File "D:\anaconda\envs\PBFT\lib\asyncio\base_events.py", line 948, in create_connection
    raise exceptions[0]
  File "D:\anaconda\envs\PBFT\lib\asyncio\base_events.py", line 935, in create_connection
    await self.sock_connect(sock, address)
  File "D:\anaconda\envs\PBFT\lib\asyncio\selector_events.py", line 475, in sock_connect
    return await fut
  File "D:\anaconda\envs\PBFT\lib\asyncio\selector_events.py", line 505, in _sock_connect_cb
    raise OSError(err, f'Connect call failed {address}')
ConnectionRefusedError: [Errno 10061] Connect call failed ('127.0.0.1', 30140)

The above exception was the direct cause of the following exception:

Traceback (most recent call last):
  File "pbft.py", line 236, in send_message
    await send_with_delay(self.session, self.node_info, target, url, data, self.bandwidth_data)
  File "pbft.py", line 63, in send_with_delay
    async with session.post(url, json=data) as resp:
  File "D:\anaconda\envs\PBFT\lib\site-packages\aiohttp\client.py", line 1141, in __aenter__
    self._resp = await self._coro
  File "D:\anaconda\envs\PBFT\lib\site-packages\aiohttp\client.py", line 537, in _request
    req, traces=traces, timeout=real_timeout
  File "D:\anaconda\envs\PBFT\lib\site-packages\aiohttp\connector.py", line 540, in connect
    proto = await self._create_connection(req, traces, timeout)
  File "D:\anaconda\envs\PBFT\lib\site-packages\aiohttp\connector.py", line 901, in _create_connection
    _, proto = await self._create_direct_connection(req, traces, timeout)
  File "D:\anaconda\envs\PBFT\lib\site-packages\aiohttp\connector.py", line 1206, in _create_direct_connection
    raise last_exc
  File "D:\anaconda\envs\PBFT\lib\site-packages\aiohttp\connector.py", line 1187, in _create_direct_connection
    client_error=client_error,
  File "D:\anaconda\envs\PBFT\lib\site-packages\aiohttp\connector.py", line 988, in _wrap_create_connection
    raise client_error(req.connection_key, exc) from exc
aiohttp.client_exceptions.ClientConnectorError: Cannot connect to host localhost:30140 ssl:default [Connect call failed ('127.0.0.1', 30140)]
[2025-03-07 13:53:49,205] [INFO] [30087] Received PREPARE: id:1741323218379, from:30151, delay:0.0001s, distance:231.41m (Euclidean)
[2025-03-07 13:53:49,209] [ERROR] [30087] Error sending to http://localhost:30140/commit: Cannot connect to host localhost:30140 ssl:default [Connect call failed ('::1', 30140, 0, 0)]
Traceback (most recent call last):
  File "D:\anaconda\envs\PBFT\lib\site-packages\aiohttp\connector.py", line 980, in _wrap_create_connection
    return await self._loop.create_connection(*args, **kwargs)  # type: ignore[return-value]  # noqa
  File "D:\anaconda\envs\PBFT\lib\asyncio\base_events.py", line 948, in create_connection
    raise exceptions[0]
  File "D:\anaconda\envs\PBFT\lib\asyncio\base_events.py", line 935, in create_connection
    await self.sock_connect(sock, address)
  File "D:\anaconda\envs\PBFT\lib\asyncio\selector_events.py", line 475, in sock_connect
    return await fut
  File "D:\anaconda\envs\PBFT\lib\asyncio\selector_events.py", line 505, in _sock_connect_cb
    raise OSError(err, f'Connect call failed {address}')
ConnectionRefusedError: [Errno 10061] Connect call failed ('::1', 30140, 0, 0)

The above exception was the direct cause of the following exception:

Traceback (most recent call last):
  File "pbft.py", line 236, in send_message
    await send_with_delay(self.session, self.node_info, target, url, data, self.bandwidth_data)
  File "pbft.py", line 63, in send_with_delay
    async with session.post(url, json=data) as resp:
  File "D:\anaconda\envs\PBFT\lib\site-packages\aiohttp\client.py", line 1141, in __aenter__
    self._resp = await self._coro
  File "D:\anaconda\envs\PBFT\lib\site-packages\aiohttp\client.py", line 537, in _request
    req, traces=traces, timeout=real_timeout
  File "D:\anaconda\envs\PBFT\lib\site-packages\aiohttp\connector.py", line 540, in connect
    proto = await self._create_connection(req, traces, timeout)
  File "D:\anaconda\envs\PBFT\lib\site-packages\aiohttp\connector.py", line 901, in _create_connection
    _, proto = await self._create_direct_connection(req, traces, timeout)
  File "D:\anaconda\envs\PBFT\lib\site-packages\aiohttp\connector.py", line 1206, in _create_direct_connection
    raise last_exc
  File "D:\anaconda\envs\PBFT\lib\site-packages\aiohttp\connector.py", line 1187, in _create_direct_connection
    client_error=client_error,
  File "D:\anaconda\envs\PBFT\lib\site-packages\aiohttp\connector.py", line 988, in _wrap_create_connection
    raise client_error(req.connection_key, exc) from exc
aiohttp.client_exceptions.ClientConnectorError: Cannot connect to host localhost:30140 ssl:default [Connect call failed ('::1', 30140, 0, 0)]
[2025-03-07 13:53:49,240] [INFO] [30087] Received COMMIT: id:1741323218379, from:30151, delay:0.0001s, distance:231.41m (Euclidean)
[2025-03-07 13:53:49,367] [ERROR] [30087] Error sending to http://localhost:30141/commit: Cannot connect to host localhost:30141 ssl:default [Connect call failed ('::1', 30141, 0, 0)]
Traceback (most recent call last):
  File "D:\anaconda\envs\PBFT\lib\site-packages\aiohttp\connector.py", line 980, in _wrap_create_connection
    return await self._loop.create_connection(*args, **kwargs)  # type: ignore[return-value]  # noqa
  File "D:\anaconda\envs\PBFT\lib\asyncio\base_events.py", line 948, in create_connection
    raise exceptions[0]
  File "D:\anaconda\envs\PBFT\lib\asyncio\base_events.py", line 935, in create_connection
    await self.sock_connect(sock, address)
  File "D:\anaconda\envs\PBFT\lib\asyncio\selector_events.py", line 475, in sock_connect
    return await fut
  File "D:\anaconda\envs\PBFT\lib\asyncio\selector_events.py", line 505, in _sock_connect_cb
    raise OSError(err, f'Connect call failed {address}')
ConnectionRefusedError: [Errno 10061] Connect call failed ('::1', 30141, 0, 0)

The above exception was the direct cause of the following exception:

Traceback (most recent call last):
  File "pbft.py", line 236, in send_message
    await send_with_delay(self.session, self.node_info, target, url, data, self.bandwidth_data)
  File "pbft.py", line 63, in send_with_delay
    async with session.post(url, json=data) as resp:
  File "D:\anaconda\envs\PBFT\lib\site-packages\aiohttp\client.py", line 1141, in __aenter__
    self._resp = await self._coro
  File "D:\anaconda\envs\PBFT\lib\site-packages\aiohttp\client.py", line 537, in _request
    req, traces=traces, timeout=real_timeout
  File "D:\anaconda\envs\PBFT\lib\site-packages\aiohttp\connector.py", line 540, in connect
    proto = await self._create_connection(req, traces, timeout)
  File "D:\anaconda\envs\PBFT\lib\site-packages\aiohttp\connector.py", line 901, in _create_connection
    _, proto = await self._create_direct_connection(req, traces, timeout)
  File "D:\anaconda\envs\PBFT\lib\site-packages\aiohttp\connector.py", line 1206, in _create_direct_connection
    raise last_exc
  File "D:\anaconda\envs\PBFT\lib\site-packages\aiohttp\connector.py", line 1187, in _create_direct_connection
    client_error=client_error,
  File "D:\anaconda\envs\PBFT\lib\site-packages\aiohttp\connector.py", line 988, in _wrap_create_connection
    raise client_error(req.connection_key, exc) from exc
aiohttp.client_exceptions.ClientConnectorError: Cannot connect to host localhost:30141 ssl:default [Connect call failed ('::1', 30141, 0, 0)]
[2025-03-07 13:53:49,383] [ERROR] [30087] Error sending to http://localhost:30141/prepare: Cannot connect to host localhost:30141 ssl:default [Connect call failed ('127.0.0.1', 30141)]
Traceback (most recent call last):
  File "D:\anaconda\envs\PBFT\lib\site-packages\aiohttp\connector.py", line 980, in _wrap_create_connection
    return await self._loop.create_connection(*args, **kwargs)  # type: ignore[return-value]  # noqa
  File "D:\anaconda\envs\PBFT\lib\asyncio\base_events.py", line 948, in create_connection
    raise exceptions[0]
  File "D:\anaconda\envs\PBFT\lib\asyncio\base_events.py", line 935, in create_connection
    await self.sock_connect(sock, address)
  File "D:\anaconda\envs\PBFT\lib\asyncio\selector_events.py", line 475, in sock_connect
    return await fut
  File "D:\anaconda\envs\PBFT\lib\asyncio\selector_events.py", line 505, in _sock_connect_cb
    raise OSError(err, f'Connect call failed {address}')
ConnectionRefusedError: [Errno 10061] Connect call failed ('127.0.0.1', 30141)

The above exception was the direct cause of the following exception:

Traceback (most recent call last):
  File "pbft.py", line 236, in send_message
    await send_with_delay(self.session, self.node_info, target, url, data, self.bandwidth_data)
  File "pbft.py", line 63, in send_with_delay
    async with session.post(url, json=data) as resp:
  File "D:\anaconda\envs\PBFT\lib\site-packages\aiohttp\client.py", line 1141, in __aenter__
    self._resp = await self._coro
  File "D:\anaconda\envs\PBFT\lib\site-packages\aiohttp\client.py", line 537, in _request
    req, traces=traces, timeout=real_timeout
  File "D:\anaconda\envs\PBFT\lib\site-packages\aiohttp\connector.py", line 540, in connect
    proto = await self._create_connection(req, traces, timeout)
  File "D:\anaconda\envs\PBFT\lib\site-packages\aiohttp\connector.py", line 901, in _create_connection
    _, proto = await self._create_direct_connection(req, traces, timeout)
  File "D:\anaconda\envs\PBFT\lib\site-packages\aiohttp\connector.py", line 1206, in _create_direct_connection
    raise last_exc
  File "D:\anaconda\envs\PBFT\lib\site-packages\aiohttp\connector.py", line 1187, in _create_direct_connection
    client_error=client_error,
  File "D:\anaconda\envs\PBFT\lib\site-packages\aiohttp\connector.py", line 988, in _wrap_create_connection
    raise client_error(req.connection_key, exc) from exc
aiohttp.client_exceptions.ClientConnectorError: Cannot connect to host localhost:30141 ssl:default [Connect call failed ('127.0.0.1', 30141)]
[2025-03-07 13:53:49,431] [INFO] [30087] Received PREPARE: id:1741323218379, from:30112, delay:0.0001s, distance:212.58m (Euclidean)
[2025-03-07 13:53:49,447] [INFO] [30087] Received COMMIT: id:1741323218379, from:30112, delay:0.0001s, distance:212.58m (Euclidean)
[2025-03-07 13:53:49,578] [INFO] [30087] Received PREPARE: id:1741323218379, from:30067, delay:0.0000s, distance:119.10m (Euclidean)
[2025-03-07 13:53:49,578] [INFO] [30087] Received COMMIT: id:1741323218379, from:30067, delay:0.0000s, distance:119.10m (Euclidean)
[2025-03-07 13:53:49,657] [INFO] [30087] Received COMMIT: id:1741323218379, from:30000, delay:0.0000s, distance:181.80m (Euclidean)
[2025-03-07 13:53:50,316] [INFO] [30087] Received PREPARE: id:1741323218379, from:30123, delay:0.0000s, distance:45.05m (Euclidean)
[2025-03-07 13:53:50,598] [INFO] [30087] Received PREPARE: id:1741323218379, from:30116, delay:0.0002s, distance:269.49m (Euclidean)
[2025-03-07 13:53:50,598] [INFO] [30087] Received COMMIT: id:1741323218379, from:30116, delay:0.0002s, distance:269.49m (Euclidean)
[2025-03-07 13:53:50,641] [INFO] [30087] Received PREPARE: id:1741323218379, from:30126, delay:0.0002s, distance:276.27m (Euclidean)
[2025-03-07 13:53:50,641] [INFO] [30087] Received COMMIT: id:1741323218379, from:30126, delay:0.0002s, distance:276.27m (Euclidean)
[2025-03-07 13:53:50,688] [INFO] [30087] Received PREPARE: id:1741323218379, from:30068, delay:0.0000s, distance:121.00m (Euclidean)
[2025-03-07 13:53:50,696] [INFO] [30087] Received COMMIT: id:1741323218379, from:30068, delay:0.0000s, distance:121.00m (Euclidean)
[2025-03-07 13:53:50,873] [INFO] [30087] Received PREPARE: id:1741323218379, from:30149, delay:0.0001s, distance:177.73m (Euclidean)
[2025-03-07 13:53:50,905] [INFO] [30087] Received PREPARE: id:1741323218379, from:30119, delay:0.0001s, distance:224.99m (Euclidean)
[2025-03-07 13:53:50,918] [INFO] [30087] Received PREPARE: id:1741323218379, from:30130, delay:0.0001s, distance:190.43m (Euclidean)
[2025-03-07 13:53:50,918] [INFO] [30087] Received COMMIT: id:1741323218379, from:30130, delay:0.0001s, distance:190.43m (Euclidean)
[2025-03-07 13:53:50,934] [INFO] [30087] Received COMMIT: id:1741323218379, from:30119, delay:0.0001s, distance:224.99m (Euclidean)
[2025-03-07 13:53:51,298] [INFO] [30087] Received PREPARE: id:1741323218379, from:30111, delay:0.0000s, distance:78.03m (Euclidean)
[2025-03-07 13:53:51,345] [INFO] [30087] Received PREPARE: id:1741323218379, from:30121, delay:0.0001s, distance:171.06m (Euclidean)
[2025-03-07 13:53:51,345] [INFO] [30087] Received COMMIT: id:1741323218379, from:30121, delay:0.0001s, distance:171.06m (Euclidean)
[2025-03-07 13:53:51,393] [INFO] [30087] Received PREPARE: id:1741323218379, from:30015, delay:0.0002s, distance:277.64m (Euclidean)
[2025-03-07 13:53:51,393] [INFO] [30087] Received COMMIT: id:1741323218379, from:30015, delay:0.0002s, distance:277.64m (Euclidean)
[2025-03-07 13:53:51,588] [INFO] [30087] Received COMMIT: id:1741323218379, from:30149, delay:0.0001s, distance:177.73m (Euclidean)
[2025-03-07 13:53:51,645] [INFO] [30087] Received PREPARE: id:1741323218379, from:30129, delay:0.0001s, distance:239.47m (Euclidean)
[2025-03-07 13:53:51,645] [INFO] [30087] Received COMMIT: id:1741323218379, from:30129, delay:0.0001s, distance:239.47m (Euclidean)
[2025-03-07 13:53:51,823] [INFO] [30087] Received PREPARE: id:1741323218379, from:30113, delay:0.0000s, distance:174.36m (Euclidean)
[2025-03-07 13:53:52,024] [INFO] [30087] Received PREPARE: id:1741323218379, from:30127, delay:0.0000s, distance:142.43m (Euclidean)
[2025-03-07 13:53:52,637] [INFO] [30087] Received PREPARE: id:1741323218379, from:30022, delay:0.0001s, distance:237.30m (Euclidean)
[2025-03-07 13:53:52,963] [INFO] [30087] Received COMMIT: id:1741323218379, from:30123, delay:0.0000s, distance:45.05m (Euclidean)
[2025-03-07 13:53:53,038] [INFO] [30087] Received COMMIT: id:1741323218379, from:30113, delay:0.0000s, distance:174.36m (Euclidean)
[2025-03-07 13:53:53,084] [INFO] [30087] Received COMMIT: id:1741323218379, from:30111, delay:0.0000s, distance:78.03m (Euclidean)
[2025-03-07 13:53:53,163] [INFO] [30087] Received PREPARE: id:1741323218379, from:30150, delay:0.0001s, distance:152.93m (Euclidean)
[2025-03-07 13:53:53,163] [INFO] [30087] Received COMMIT: id:1741323218379, from:30150, delay:0.0001s, distance:152.93m (Euclidean)
[2025-03-07 13:53:53,180] [INFO] [30087] Received COMMIT: id:1741323218379, from:30022, delay:0.0001s, distance:237.30m (Euclidean)
[2025-03-07 13:53:53,327] [INFO] [30087] Received COMMIT: id:1741323218379, from:30127, delay:0.0000s, distance:142.43m (Euclidean)
[2025-03-07 13:53:53,543] [INFO] [30087] Received PREPARE: id:1741323218379, from:30118, delay:0.0000s, distance:159.07m (Euclidean)
[2025-03-07 13:53:53,543] [INFO] [30087] Received COMMIT: id:1741323218379, from:30118, delay:0.0000s, distance:159.07m (Euclidean)
[2025-03-07 13:53:53,642] [INFO] [30087] Received PREPARE: id:1741323218379, from:30108, delay:0.0001s, distance:232.56m (Euclidean)
[2025-03-07 13:53:53,812] [INFO] [30087] Received PREPARE: id:1741323218379, from:30146, delay:0.0001s, distance:166.70m (Euclidean)
[2025-03-07 13:53:53,812] [INFO] [30087] Received COMMIT: id:1741323218379, from:30146, delay:0.0001s, distance:166.70m (Euclidean)
[2025-03-07 13:53:53,860] [INFO] [30087] Received COMMIT: id:1741323218379, from:30108, delay:0.0001s, distance:232.56m (Euclidean)
[2025-03-07 13:53:54,271] [INFO] [30087] Received PREPARE: id:1741323218379, from:30142, delay:0.0002s, distance:259.90m (Euclidean)
[2025-03-07 13:53:54,282] [INFO] [30087] Received COMMIT: id:1741323218379, from:30142, delay:0.0002s, distance:259.90m (Euclidean)
[2025-03-07 13:53:54,418] [INFO] [30087] Received PREPARE: id:1741323218379, from:30156, delay:0.0002s, distance:254.86m (Euclidean)
[2025-03-07 13:53:54,438] [INFO] [30087] Received PREPARE: id:1741323218379, from:30106, delay:0.0001s, distance:210.36m (Euclidean)
[2025-03-07 13:53:54,444] [INFO] [30087] Received COMMIT: id:1741323218379, from:30106, delay:0.0001s, distance:210.36m (Euclidean)
[2025-03-07 13:53:54,453] [INFO] [30087] Received COMMIT: id:1741323218379, from:30156, delay:0.0002s, distance:254.86m (Euclidean)
[2025-03-07 13:53:54,528] [INFO] [30087] Received PREPARE: id:1741323218379, from:30120, delay:0.0002s, distance:285.63m (Euclidean)
[2025-03-07 13:53:54,530] [INFO] [30087] Received COMMIT: id:1741323218379, from:30120, delay:0.0002s, distance:285.63m (Euclidean)
[2025-03-07 13:53:54,533] [INFO] [30087] Received PREPARE: id:1741323218379, from:30115, delay:0.0001s, distance:243.46m (Euclidean)
[2025-03-07 13:53:54,585] [INFO] [30087] Received COMMIT: id:1741323218379, from:30115, delay:0.0001s, distance:243.46m (Euclidean)
[2025-03-07 13:53:54,598] [INFO] [30087] Received PREPARE: id:1741323218379, from:30152, delay:0.0001s, distance:220.36m (Euclidean)
[2025-03-07 13:53:54,598] [INFO] [30087] Received COMMIT: id:1741323218379, from:30152, delay:0.0001s, distance:220.36m (Euclidean)
[2025-03-07 13:57:31,674] [INFO] Starting node at localhost:30087 | index= 88 | f=1, k=4 | Role: Replica
[2025-03-07 13:58:34,073] [INFO] Starting node at localhost:30087 | index= 88 | f=1, k=4 | Role: Replica
[2025-03-07 13:59:03,153] [INFO] [30087] Received PREPARE: id:1741323542381, from:30112, delay:0.0000s, distance:107.57m (Euclidean)
[2025-03-07 13:59:03,153] [INFO] [30087] Missing PRE-PREPARE for REQUEST 1741323542381; ignoring PREPARE
[2025-03-07 13:59:03,726] [INFO] [30087] Received PREPARE: id:1741323542381, from:30169, delay:0.0000s, distance:70.05m (Euclidean)
[2025-03-07 13:59:03,726] [INFO] [30087] Missing PRE-PREPARE for REQUEST 1741323542381; ignoring PREPARE
[2025-03-07 13:59:03,825] [INFO] [30087] Received PREPARE: id:1741323542381, from:30157, delay:0.0002s, distance:261.73m (Euclidean)
[2025-03-07 13:59:03,825] [INFO] [30087] Missing PRE-PREPARE for REQUEST 1741323542381; ignoring PREPARE
[2025-03-07 13:59:03,869] [INFO] [30087] Received PREPARE: id:1741323542381, from:30176, delay:0.0001s, distance:235.47m (Euclidean)
[2025-03-07 13:59:03,869] [INFO] [30087] Missing PRE-PREPARE for REQUEST 1741323542381; ignoring PREPARE
[2025-03-07 13:59:03,897] [INFO] [30087] Received PREPARE: id:1741323542381, from:30121, delay:0.0001s, distance:196.62m (Euclidean)
[2025-03-07 13:59:03,897] [INFO] [30087] Missing PRE-PREPARE for REQUEST 1741323542381; ignoring PREPARE
[2025-03-07 13:59:03,983] [INFO] [30087] Received PREPARE: id:1741323542381, from:30196, delay:0.0001s, distance:237.19m (Euclidean)
[2025-03-07 13:59:03,984] [INFO] [30087] Missing PRE-PREPARE for REQUEST 1741323542381; ignoring PREPARE
[2025-03-07 13:59:04,017] [INFO] [30087] Received PREPARE: id:1741323542381, from:30118, delay:0.0001s, distance:179.01m (Euclidean)
[2025-03-07 13:59:04,018] [INFO] [30087] Missing PRE-PREPARE for REQUEST 1741323542381; ignoring PREPARE
[2025-03-07 13:59:04,050] [INFO] [30087] Received COMMIT: id:1741323542381, from:30118, delay:0.0001s, distance:179.01m (Euclidean)
[2025-03-07 13:59:04,057] [INFO] [30087] Received PREPARE: id:1741323542381, from:30023, delay:0.0001s, distance:197.94m (Euclidean)
[2025-03-07 13:59:04,057] [INFO] [30087] Missing PRE-PREPARE for REQUEST 1741323542381; ignoring PREPARE
[2025-03-07 13:59:04,074] [INFO] [30087] Received PREPARE: id:1741323542381, from:30195, delay:0.0002s, distance:266.99m (Euclidean)
[2025-03-07 13:59:04,074] [INFO] [30087] Missing PRE-PREPARE for REQUEST 1741323542381; ignoring PREPARE
[2025-03-07 13:59:04,103] [INFO] [30087] Received PREPARE: id:1741323542381, from:30154, delay:0.0001s, distance:292.97m (Euclidean)
[2025-03-07 13:59:04,243] [INFO] [30087] Missing PRE-PREPARE for REQUEST 1741323542381; ignoring PREPARE
[2025-03-07 13:59:04,273] [INFO] [30087] Received PREPARE: id:1741323542381, from:30130, delay:0.0001s, distance:229.54m (Euclidean)
[2025-03-07 13:59:04,273] [INFO] [30087] Missing PRE-PREPARE for REQUEST 1741323542381; ignoring PREPARE
[2025-03-07 13:59:04,276] [INFO] [30087] Received PREPARE: id:1741323542381, from:30046, delay:0.0001s, distance:239.49m (Euclidean)
[2025-03-07 13:59:04,276] [INFO] [30087] Missing PRE-PREPARE for REQUEST 1741323542381; ignoring PREPARE
[2025-03-07 13:59:04,281] [INFO] [30087] Received PREPARE: id:1741323542381, from:30108, delay:0.0001s, distance:223.98m (Euclidean)
[2025-03-07 13:59:04,281] [INFO] [30087] Missing PRE-PREPARE for REQUEST 1741323542381; ignoring PREPARE
[2025-03-07 13:59:04,281] [INFO] [30087] Received PREPARE: id:1741323542381, from:30095, delay:0.0001s, distance:179.62m (Euclidean)
[2025-03-07 13:59:04,281] [INFO] [30087] Missing PRE-PREPARE for REQUEST 1741323542381; ignoring PREPARE
[2025-03-07 13:59:04,281] [INFO] [30087] Received PREPARE: id:1741323542381, from:30189, delay:0.0002s, distance:297.63m (Euclidean)
[2025-03-07 13:59:04,281] [INFO] [30087] Missing PRE-PREPARE for REQUEST 1741323542381; ignoring PREPARE
[2025-03-07 13:59:04,281] [INFO] [30087] Received COMMIT: id:1741323542381, from:30189, delay:0.0002s, distance:297.63m (Euclidean)
[2025-03-07 13:59:04,333] [INFO] [30087] Received PREPARE: id:1741323542381, from:30025, delay:0.0001s, distance:218.43m (Euclidean)
[2025-03-07 13:59:04,333] [INFO] [30087] Missing PRE-PREPARE for REQUEST 1741323542381; ignoring PREPARE
[2025-03-07 13:59:04,531] [INFO] [30087] Received COMMIT: id:1741323542381, from:30157, delay:0.0002s, distance:261.73m (Euclidean)
[2025-03-07 13:59:04,564] [INFO] [30087] Received COMMIT: id:1741323542381, from:30043, delay:0.0001s, distance:260.56m (Euclidean)
[2025-03-07 13:59:04,566] [INFO] [30087] Received PREPARE: id:1741323542381, from:30043, delay:0.0001s, distance:260.56m (Euclidean)
[2025-03-07 13:59:04,566] [INFO] [30087] Missing PRE-PREPARE for REQUEST 1741323542381; ignoring PREPARE
[2025-03-07 13:59:04,566] [INFO] [30087] Received PREPARE: id:1741323542381, from:30106, delay:0.0001s, distance:164.55m (Euclidean)
[2025-03-07 13:59:04,566] [INFO] [30087] Missing PRE-PREPARE for REQUEST 1741323542381; ignoring PREPARE
[2025-03-07 13:59:04,637] [INFO] [30087] Received PREPARE: id:1741323542381, from:30127, delay:0.0001s, distance:159.32m (Euclidean)
[2025-03-07 13:59:04,673] [INFO] [30087] Missing PRE-PREPARE for REQUEST 1741323542381; ignoring PREPARE
[2025-03-07 13:59:04,673] [INFO] [30087] Received COMMIT: id:1741323542381, from:30127, delay:0.0001s, distance:159.32m (Euclidean)
[2025-03-07 13:59:04,697] [INFO] [30087] Received PREPARE: id:1741323542381, from:30027, delay:0.0002s, distance:254.62m (Euclidean)
[2025-03-07 13:59:04,697] [INFO] [30087] Missing PRE-PREPARE for REQUEST 1741323542381; ignoring PREPARE
[2025-03-07 13:59:04,718] [INFO] [30087] Received PREPARE: id:1741323542381, from:30070, delay:0.0002s, distance:259.59m (Euclidean)
[2025-03-07 13:59:04,718] [INFO] [30087] Missing PRE-PREPARE for REQUEST 1741323542381; ignoring PREPARE
[2025-03-07 13:59:04,782] [INFO] [30087] Received COMMIT: id:1741323542381, from:30095, delay:0.0001s, distance:179.62m (Euclidean)
[2025-03-07 13:59:04,870] [INFO] [30087] Received COMMIT: id:1741323542381, from:30195, delay:0.0002s, distance:266.99m (Euclidean)
[2025-03-07 13:59:05,069] [INFO] [30087] Received PREPARE: id:1741323542381, from:30103, delay:0.0001s, distance:280.91m (Euclidean)
[2025-03-07 13:59:05,069] [INFO] [30087] Missing PRE-PREPARE for REQUEST 1741323542381; ignoring PREPARE
[2025-03-07 13:59:05,082] [INFO] [30087] Received PREPARE: id:1741323542381, from:30021, delay:0.0001s, distance:247.40m (Euclidean)
[2025-03-07 13:59:05,082] [INFO] [30087] Missing PRE-PREPARE for REQUEST 1741323542381; ignoring PREPARE
[2025-03-07 13:59:05,127] [INFO] [30087] Received PREPARE: id:1741323542381, from:30126, delay:0.0001s, distance:223.87m (Euclidean)
[2025-03-07 13:59:05,127] [INFO] [30087] Missing PRE-PREPARE for REQUEST 1741323542381; ignoring PREPARE
[2025-03-07 13:59:05,127] [INFO] [30087] Received COMMIT: id:1741323542381, from:30126, delay:0.0001s, distance:223.87m (Euclidean)
[2025-03-07 13:59:05,131] [INFO] [30087] Received PREPARE: id:1741323542381, from:30057, delay:0.0000s, distance:120.05m (Euclidean)
[2025-03-07 13:59:05,133] [INFO] [30087] Missing PRE-PREPARE for REQUEST 1741323542381; ignoring PREPARE
[2025-03-07 13:59:05,174] [INFO] [30087] Received COMMIT: id:1741323542381, from:30025, delay:0.0001s, distance:218.43m (Euclidean)
[2025-03-07 13:59:05,208] [INFO] [30087] Received PREPARE: id:1741323542381, from:30048, delay:0.0001s, distance:290.71m (Euclidean)
[2025-03-07 13:59:05,208] [INFO] [30087] Missing PRE-PREPARE for REQUEST 1741323542381; ignoring PREPARE
[2025-03-07 13:59:05,224] [INFO] [30087] Received COMMIT: id:1741323542381, from:30057, delay:0.0000s, distance:120.05m (Euclidean)
[2025-03-07 13:59:05,259] [INFO] [30087] Received COMMIT: id:1741323542381, from:30176, delay:0.0001s, distance:235.47m (Euclidean)
[2025-03-07 13:59:05,382] [INFO] [30087] Received COMMIT: id:1741323542381, from:30027, delay:0.0002s, distance:254.62m (Euclidean)
[2025-03-07 13:59:05,382] [INFO] [30087] Received COMMIT: id:1741323542381, from:30048, delay:0.0001s, distance:290.71m (Euclidean)
[2025-03-07 13:59:05,403] [INFO] [30087] Received PREPARE: id:1741323542381, from:30049, delay:0.0001s, distance:226.45m (Euclidean)
[2025-03-07 13:59:05,403] [INFO] [30087] Missing PRE-PREPARE for REQUEST 1741323542381; ignoring PREPARE
[2025-03-07 13:59:05,435] [INFO] [30087] Received PREPARE: id:1741323542381, from:30171, delay:0.0001s, distance:243.12m (Euclidean)
[2025-03-07 13:59:05,435] [INFO] [30087] Missing PRE-PREPARE for REQUEST 1741323542381; ignoring PREPARE
[2025-03-07 13:59:05,451] [INFO] [30087] Received PREPARE: id:1741323542381, from:30090, delay:0.0001s, distance:280.02m (Euclidean)
[2025-03-07 13:59:05,451] [INFO] [30087] Missing PRE-PREPARE for REQUEST 1741323542381; ignoring PREPARE
[2025-03-07 13:59:05,458] [INFO] [30087] Received PREPARE: id:1741323542381, from:30092, delay:0.0002s, distance:280.54m (Euclidean)
[2025-03-07 13:59:05,458] [INFO] [30087] Missing PRE-PREPARE for REQUEST 1741323542381; ignoring PREPARE
[2025-03-07 13:59:05,464] [INFO] [30087] Received COMMIT: id:1741323542381, from:30046, delay:0.0001s, distance:239.49m (Euclidean)
[2025-03-07 13:59:05,505] [INFO] [30087] Received COMMIT: id:1741323542381, from:30090, delay:0.0001s, distance:280.02m (Euclidean)
[2025-03-07 13:59:05,516] [INFO] [30087] Received COMMIT: id:1741323542381, from:30103, delay:0.0001s, distance:280.91m (Euclidean)
[2025-03-07 13:59:05,532] [INFO] [30087] Received COMMIT: id:1741323542381, from:30154, delay:0.0001s, distance:292.97m (Euclidean)
[2025-03-07 13:59:05,619] [INFO] [30087] Received PREPARE: id:1741323542381, from:30059, delay:0.0001s, distance:168.65m (Euclidean)
[2025-03-07 13:59:05,619] [INFO] [30087] Missing PRE-PREPARE for REQUEST 1741323542381; ignoring PREPARE
[2025-03-07 13:59:05,656] [INFO] [30087] Received PREPARE: id:1741323542381, from:30115, delay:0.0002s, distance:257.62m (Euclidean)
[2025-03-07 13:59:05,656] [INFO] [30087] Missing PRE-PREPARE for REQUEST 1741323542381; ignoring PREPARE
[2025-03-07 13:59:05,661] [INFO] [30087] Received COMMIT: id:1741323542381, from:30171, delay:0.0001s, distance:243.12m (Euclidean)
[2025-03-07 13:59:05,776] [INFO] [30087] Received PREPARE: id:1741323542381, from:30129, delay:0.0001s, distance:209.96m (Euclidean)
[2025-03-07 13:59:05,776] [INFO] [30087] Missing PRE-PREPARE for REQUEST 1741323542381; ignoring PREPARE
[2025-03-07 13:59:05,797] [INFO] [30087] Received COMMIT: id:1741323542381, from:30196, delay:0.0001s, distance:237.19m (Euclidean)
[2025-03-07 13:59:05,843] [INFO] [30087] Received PREPARE: id:1741323542381, from:30065, delay:0.0002s, distance:296.19m (Euclidean)
[2025-03-07 13:59:05,843] [INFO] [30087] Missing PRE-PREPARE for REQUEST 1741323542381; ignoring PREPARE
[2025-03-07 13:59:05,883] [INFO] [30087] Received PREPARE: id:1741323542381, from:30089, delay:0.0001s, distance:172.02m (Euclidean)
[2025-03-07 13:59:05,883] [INFO] [30087] Missing PRE-PREPARE for REQUEST 1741323542381; ignoring PREPARE
[2025-03-07 13:59:05,909] [INFO] [30087] Received PREPARE: id:1741323542381, from:30063, delay:0.0001s, distance:243.53m (Euclidean)
[2025-03-07 13:59:05,911] [INFO] [30087] Missing PRE-PREPARE for REQUEST 1741323542381; ignoring PREPARE
[2025-03-07 13:59:05,928] [INFO] [30087] Received COMMIT: id:1741323542381, from:30115, delay:0.0002s, distance:257.62m (Euclidean)
[2025-03-07 13:59:05,928] [INFO] [30087] Received PREPARE: id:1741323542381, from:30060, delay:0.0001s, distance:185.08m (Euclidean)
[2025-03-07 13:59:05,928] [INFO] [30087] Missing PRE-PREPARE for REQUEST 1741323542381; ignoring PREPARE
[2025-03-07 13:59:05,964] [INFO] [30087] Received PREPARE: id:1741323542381, from:30053, delay:0.0001s, distance:207.22m (Euclidean)
[2025-03-07 13:59:05,964] [INFO] [30087] Missing PRE-PREPARE for REQUEST 1741323542381; ignoring PREPARE
[2025-03-07 13:59:06,040] [INFO] [30087] Received PREPARE: id:1741323542381, from:30041, delay:0.0001s, distance:246.79m (Euclidean)
[2025-03-07 13:59:06,040] [INFO] [30087] Missing PRE-PREPARE for REQUEST 1741323542381; ignoring PREPARE
[2025-03-07 13:59:06,112] [INFO] [30087] Received COMMIT: id:1741323542381, from:30130, delay:0.0001s, distance:229.54m (Euclidean)
[2025-03-07 13:59:06,117] [INFO] [30087] Received PREPARE: id:1741323542381, from:30093, delay:0.0001s, distance:224.29m (Euclidean)
[2025-03-07 13:59:06,117] [INFO] [30087] Missing PRE-PREPARE for REQUEST 1741323542381; ignoring PREPARE
[2025-03-07 13:59:06,329] [INFO] [30087] Received COMMIT: id:1741323542381, from:30121, delay:0.0001s, distance:196.62m (Euclidean)
[2025-03-07 13:59:06,333] [INFO] [30087] Received COMMIT: id:1741323542381, from:30060, delay:0.0001s, distance:185.08m (Euclidean)
[2025-03-07 13:59:06,381] [INFO] [30087] Received COMMIT: id:1741323542381, from:30041, delay:0.0001s, distance:246.79m (Euclidean)
[2025-03-07 13:59:06,383] [INFO] [30087] Received COMMIT: id:1741323542381, from:30021, delay:0.0001s, distance:247.40m (Euclidean)
[2025-03-07 13:59:06,383] [INFO] [30087] Received PREPARE: id:1741323542381, from:30123, delay:0.0001s, distance:202.01m (Euclidean)
[2025-03-07 13:59:06,383] [INFO] [30087] Missing PRE-PREPARE for REQUEST 1741323542381; ignoring PREPARE
[2025-03-07 13:59:06,452] [INFO] [30087] Received COMMIT: id:1741323542381, from:30129, delay:0.0001s, distance:209.96m (Euclidean)
[2025-03-07 13:59:06,499] [INFO] [30087] Received PREPARE: id:1741323542381, from:30051, delay:0.0001s, distance:240.03m (Euclidean)
[2025-03-07 13:59:06,499] [INFO] [30087] Missing PRE-PREPARE for REQUEST 1741323542381; ignoring PREPARE
[2025-03-07 13:59:06,531] [INFO] [30087] Received COMMIT: id:1741323542381, from:30063, delay:0.0001s, distance:243.53m (Euclidean)
[2025-03-07 13:59:06,560] [INFO] [30087] Received COMMIT: id:1741323542381, from:30049, delay:0.0001s, distance:226.45m (Euclidean)
[2025-03-07 13:59:06,578] [INFO] [30087] Received COMMIT: id:1741323542381, from:30093, delay:0.0001s, distance:224.29m (Euclidean)
[2025-03-07 13:59:06,580] [INFO] [30087] Received COMMIT: id:1741323542381, from:30112, delay:0.0000s, distance:107.57m (Euclidean)
[2025-03-07 13:59:06,594] [INFO] [30087] Received COMMIT: id:1741323542381, from:30053, delay:0.0001s, distance:207.22m (Euclidean)
[2025-03-07 13:59:06,627] [INFO] [30087] Received PREPARE: id:1741323542381, from:30098, delay:0.0001s, distance:206.41m (Euclidean)
[2025-03-07 13:59:06,627] [INFO] [30087] Missing PRE-PREPARE for REQUEST 1741323542381; ignoring PREPARE
[2025-03-07 13:59:06,664] [INFO] [30087] Received COMMIT: id:1741323542381, from:30108, delay:0.0001s, distance:223.98m (Euclidean)
[2025-03-07 13:59:06,688] [INFO] [30087] Received PREPARE: id:1741323542381, from:30102, delay:0.0001s, distance:273.71m (Euclidean)
[2025-03-07 13:59:06,688] [INFO] [30087] Missing PRE-PREPARE for REQUEST 1741323542381; ignoring PREPARE
[2025-03-07 13:59:06,702] [INFO] [30087] Received COMMIT: id:1741323542381, from:30106, delay:0.0001s, distance:164.55m (Euclidean)
[2025-03-07 13:59:06,772] [INFO] [30087] Received PREPARE: id:1741323542381, from:30190, delay:0.0002s, distance:293.19m (Euclidean)
[2025-03-07 13:59:06,772] [INFO] [30087] Missing PRE-PREPARE for REQUEST 1741323542381; ignoring PREPARE
[2025-03-07 13:59:06,862] [INFO] [30087] Received COMMIT: id:1741323542381, from:30059, delay:0.0001s, distance:168.65m (Euclidean)
[2025-03-07 13:59:07,019] [INFO] [30087] Received COMMIT: id:1741323542381, from:30092, delay:0.0002s, distance:280.54m (Euclidean)
[2025-03-07 13:59:07,043] [INFO] [30087] Received PREPARE: id:1741323542381, from:30181, delay:0.0001s, distance:214.81m (Euclidean)
[2025-03-07 13:59:07,043] [INFO] [30087] Missing PRE-PREPARE for REQUEST 1741323542381; ignoring PREPARE
[2025-03-07 13:59:07,096] [INFO] [30087] Received COMMIT: id:1741323542381, from:30102, delay:0.0001s, distance:273.71m (Euclidean)
[2025-03-07 13:59:07,109] [INFO] [30087] Received COMMIT: id:1741323542381, from:30098, delay:0.0001s, distance:206.41m (Euclidean)
[2025-03-07 13:59:07,130] [INFO] [30087] Received COMMIT: id:1741323542381, from:30065, delay:0.0002s, distance:296.19m (Euclidean)
[2025-03-07 13:59:07,151] [INFO] [30087] Received COMMIT: id:1741323542381, from:30181, delay:0.0001s, distance:214.81m (Euclidean)
[2025-03-07 13:59:07,158] [INFO] [30087] Received COMMIT: id:1741323542381, from:30190, delay:0.0002s, distance:293.19m (Euclidean)
[2025-03-07 13:59:07,189] [INFO] [30087] Received COMMIT: id:1741323542381, from:30070, delay:0.0002s, distance:259.59m (Euclidean)
[2025-03-07 13:59:07,216] [INFO] [30087] Received PREPARE: id:1741323542381, from:30054, delay:0.0001s, distance:224.66m (Euclidean)
[2025-03-07 13:59:07,216] [INFO] [30087] Missing PRE-PREPARE for REQUEST 1741323542381; ignoring PREPARE
[2025-03-07 13:59:07,216] [INFO] [30087] Received COMMIT: id:1741323542381, from:30054, delay:0.0001s, distance:224.66m (Euclidean)
[2025-03-07 13:59:07,237] [INFO] [30087] Received COMMIT: id:1741323542381, from:30051, delay:0.0001s, distance:240.03m (Euclidean)
[2025-03-07 13:59:07,242] [INFO] [30087] Received COMMIT: id:1741323542381, from:30089, delay:0.0001s, distance:172.02m (Euclidean)
[2025-03-07 13:59:07,305] [INFO] [30087] Received PREPARE: id:1741323542381, from:30150, delay:0.0001s, distance:254.52m (Euclidean)
[2025-03-07 13:59:07,305] [INFO] [30087] Missing PRE-PREPARE for REQUEST 1741323542381; ignoring PREPARE
[2025-03-07 13:59:07,447] [INFO] [30087] Received COMMIT: id:1741323542381, from:30123, delay:0.0001s, distance:202.01m (Euclidean)
[2025-03-07 13:59:07,479] [INFO] [30087] Received PREPARE: id:1741323542381, from:30040, delay:0.0002s, distance:273.43m (Euclidean)
[2025-03-07 13:59:07,479] [INFO] [30087] Missing PRE-PREPARE for REQUEST 1741323542381; ignoring PREPARE
[2025-03-07 13:59:07,549] [INFO] [30087] Received COMMIT: id:1741323542381, from:30150, delay:0.0001s, distance:254.52m (Euclidean)
[2025-03-07 13:59:07,752] [INFO] [30087] Received COMMIT: id:1741323542381, from:30169, delay:0.0000s, distance:70.05m (Euclidean)
[2025-03-07 13:59:07,760] [INFO] [30087] Received COMMIT: id:1741323542381, from:30040, delay:0.0002s, distance:273.43m (Euclidean)
[2025-03-07 13:59:07,813] [INFO] [30087] Received COMMIT: id:1741323542381, from:30023, delay:0.0001s, distance:197.94m (Euclidean)
[2025-03-07 13:59:08,313] [INFO] [30087] Received PREPARE: id:1741323542381, from:30161, delay:0.0001s, distance:242.05m (Euclidean)
[2025-03-07 13:59:08,315] [INFO] [30087] Missing PRE-PREPARE for REQUEST 1741323542381; ignoring PREPARE
[2025-03-07 13:59:08,329] [INFO] [30087] Received COMMIT: id:1741323542381, from:30161, delay:0.0001s, distance:242.05m (Euclidean)
[2025-03-07 13:59:08,347] [INFO] [30087] Received PREPARE: id:1741323542381, from:30168, delay:0.0002s, distance:271.80m (Euclidean)
[2025-03-07 13:59:08,347] [INFO] [30087] Missing PRE-PREPARE for REQUEST 1741323542381; ignoring PREPARE
[2025-03-07 13:59:08,560] [INFO] [30087] Received PREPARE: id:1741323542381, from:30149, delay:0.0001s, distance:223.17m (Euclidean)
[2025-03-07 13:59:08,560] [INFO] [30087] Missing PRE-PREPARE for REQUEST 1741323542381; ignoring PREPARE
[2025-03-07 13:59:08,593] [INFO] [30087] Received COMMIT: id:1741323542381, from:30149, delay:0.0001s, distance:223.17m (Euclidean)
[2025-03-07 13:59:08,593] [INFO] [30087] Received COMMIT: id:1741323542381, from:30168, delay:0.0002s, distance:271.80m (Euclidean)
[2025-03-07 13:59:08,645] [INFO] [30087] Received PREPARE: id:1741323542381, from:30110, delay:0.0001s, distance:258.33m (Euclidean)
[2025-03-07 13:59:08,647] [INFO] [30087] Missing PRE-PREPARE for REQUEST 1741323542381; ignoring PREPARE
[2025-03-07 13:59:08,647] [INFO] [30087] Received COMMIT: id:1741323542381, from:30110, delay:0.0001s, distance:258.33m (Euclidean)
[2025-03-07 13:59:08,793] [INFO] [30087] Received PREPARE: id:1741323542381, from:30178, delay:0.0001s, distance:277.94m (Euclidean)
[2025-03-07 13:59:08,793] [INFO] [30087] Missing PRE-PREPARE for REQUEST 1741323542381; ignoring PREPARE
[2025-03-07 13:59:08,875] [INFO] [30087] Received COMMIT: id:1741323542381, from:30178, delay:0.0001s, distance:277.94m (Euclidean)
[2025-03-07 13:59:08,964] [INFO] [30087] Received PREPARE: id:1741323542381, from:30120, delay:0.0001s, distance:247.38m (Euclidean)
[2025-03-07 13:59:08,964] [INFO] [30087] Missing PRE-PREPARE for REQUEST 1741323542381; ignoring PREPARE
[2025-03-07 13:59:09,033] [INFO] [30087] Received COMMIT: id:1741323542381, from:30120, delay:0.0001s, distance:247.38m (Euclidean)
[2025-03-07 13:59:09,404] [INFO] [30087] Received PREPARE: id:1741323542381, from:30015, delay:0.0001s, distance:273.42m (Euclidean)
[2025-03-07 13:59:09,404] [INFO] [30087] Missing PRE-PREPARE for REQUEST 1741323542381; ignoring PREPARE
[2025-03-07 13:59:09,405] [INFO] [30087] Received COMMIT: id:1741323542381, from:30015, delay:0.0001s, distance:273.42m (Euclidean)
[2025-03-07 13:59:09,710] [INFO] [30087] Received PREPARE: id:1741323542381, from:30170, delay:0.0001s, distance:231.68m (Euclidean)
[2025-03-07 13:59:09,710] [INFO] [30087] Missing PRE-PREPARE for REQUEST 1741323542381; ignoring PREPARE
[2025-03-07 13:59:09,710] [INFO] [30087] Received COMMIT: id:1741323542381, from:30170, delay:0.0001s, distance:231.68m (Euclidean)
[2025-03-07 13:59:10,202] [INFO] [30087] Received PREPARE: id:1741323542381, from:30111, delay:0.0001s, distance:226.77m (Euclidean)
[2025-03-07 13:59:10,209] [INFO] [30087] Missing PRE-PREPARE for REQUEST 1741323542381; ignoring PREPARE
[2025-03-07 13:59:10,209] [INFO] [30087] Received PREPARE: id:1741323542381, from:30175, delay:0.0001s, distance:210.84m (Euclidean)
[2025-03-07 13:59:10,209] [INFO] [30087] Missing PRE-PREPARE for REQUEST 1741323542381; ignoring PREPARE
[2025-03-07 13:59:10,209] [INFO] [30087] Received COMMIT: id:1741323542381, from:30175, delay:0.0001s, distance:210.84m (Euclidean)
[2025-03-07 13:59:10,209] [INFO] [30087] Received COMMIT: id:1741323542381, from:30111, delay:0.0001s, distance:226.77m (Euclidean)
[2025-03-07 13:59:10,489] [INFO] [30087] Received PREPARE: id:1741323542381, from:30013, delay:0.0001s, distance:196.33m (Euclidean)
[2025-03-07 13:59:10,489] [INFO] [30087] Missing PRE-PREPARE for REQUEST 1741323542381; ignoring PREPARE
[2025-03-07 13:59:10,489] [INFO] [30087] Received COMMIT: id:1741323542381, from:30013, delay:0.0001s, distance:196.33m (Euclidean)
[2025-03-07 13:59:11,066] [INFO] [30087] Received PREPARE: id:1741323542381, from:30174, delay:0.0002s, distance:298.53m (Euclidean)
[2025-03-07 13:59:11,066] [INFO] [30087] Missing PRE-PREPARE for REQUEST 1741323542381; ignoring PREPARE
[2025-03-07 13:59:11,208] [INFO] [30087] Received PREPARE: id:1741323542381, from:30124, delay:0.0002s, distance:254.47m (Euclidean)
[2025-03-07 13:59:11,208] [INFO] [30087] Missing PRE-PREPARE for REQUEST 1741323542381; ignoring PREPARE
[2025-03-07 13:59:11,210] [INFO] [30087] Received COMMIT: id:1741323542381, from:30124, delay:0.0002s, distance:254.47m (Euclidean)
[2025-03-07 13:59:11,212] [INFO] [30087] Received COMMIT: id:1741323542381, from:30174, delay:0.0002s, distance:298.53m (Euclidean)
[2025-03-07 13:59:11,280] [INFO] [30087] Received PREPARE: id:1741323542381, from:30116, delay:0.0000s, distance:164.69m (Euclidean)
[2025-03-07 13:59:11,280] [INFO] [30087] Missing PRE-PREPARE for REQUEST 1741323542381; ignoring PREPARE
[2025-03-07 13:59:11,282] [INFO] [30087] Received COMMIT: id:1741323542381, from:30116, delay:0.0000s, distance:164.69m (Euclidean)
[2025-03-07 13:59:11,314] [INFO] [30087] Received PREPARE: id:1741323542381, from:30011, delay:0.0001s, distance:242.76m (Euclidean)
[2025-03-07 13:59:11,314] [INFO] [30087] Missing PRE-PREPARE for REQUEST 1741323542381; ignoring PREPARE
[2025-03-07 13:59:11,320] [INFO] [30087] Received COMMIT: id:1741323542381, from:30011, delay:0.0001s, distance:242.76m (Euclidean)
[2025-03-07 13:59:11,419] [INFO] [30087] Received PREPARE: id:1741323542381, from:30056, delay:0.0001s, distance:242.51m (Euclidean)
[2025-03-07 13:59:11,419] [INFO] [30087] Missing PRE-PREPARE for REQUEST 1741323542381; ignoring PREPARE
[2025-03-07 13:59:11,419] [INFO] [30087] Received COMMIT: id:1741323542381, from:30056, delay:0.0001s, distance:242.51m (Euclidean)
[2025-03-07 13:59:11,524] [INFO] [30087] Received PREPARE: id:1741323542381, from:30113, delay:0.0001s, distance:277.75m (Euclidean)
[2025-03-07 13:59:11,526] [INFO] [30087] Missing PRE-PREPARE for REQUEST 1741323542381; ignoring PREPARE
[2025-03-07 13:59:11,526] [INFO] [30087] Received PREPARE: id:1741323542381, from:30004, delay:0.0000s, distance:174.89m (Euclidean)
[2025-03-07 13:59:11,526] [INFO] [30087] Missing PRE-PREPARE for REQUEST 1741323542381; ignoring PREPARE
[2025-03-07 13:59:11,526] [INFO] [30087] Received COMMIT: id:1741323542381, from:30113, delay:0.0001s, distance:277.75m (Euclidean)
[2025-03-07 13:59:11,526] [INFO] [30087] Received COMMIT: id:1741323542381, from:30004, delay:0.0000s, distance:174.89m (Euclidean)
[2025-03-07 13:59:11,585] [INFO] [30087] Received PREPARE: id:1741323542381, from:30035, delay:0.0002s, distance:288.02m (Euclidean)
[2025-03-07 13:59:11,585] [INFO] [30087] Missing PRE-PREPARE for REQUEST 1741323542381; ignoring PREPARE
[2025-03-07 13:59:11,585] [INFO] [30087] Received COMMIT: id:1741323542381, from:30035, delay:0.0002s, distance:288.02m (Euclidean)
[2025-03-07 13:59:11,648] [INFO] [30087] Received PREPARE: id:1741323542381, from:30007, delay:0.0001s, distance:240.39m (Euclidean)
[2025-03-07 13:59:11,648] [INFO] [30087] Missing PRE-PREPARE for REQUEST 1741323542381; ignoring PREPARE
[2025-03-07 13:59:11,648] [INFO] [30087] Received COMMIT: id:1741323542381, from:30007, delay:0.0001s, distance:240.39m (Euclidean)
[2025-03-07 13:59:12,005] [INFO] [30087] Received PREPARE: id:1741323542381, from:30085, delay:0.0000s, distance:175.89m (Euclidean)
[2025-03-07 13:59:12,005] [INFO] [30087] Missing PRE-PREPARE for REQUEST 1741323542381; ignoring PREPARE
[2025-03-07 13:59:12,007] [INFO] [30087] Received COMMIT: id:1741323542381, from:30085, delay:0.0000s, distance:175.89m (Euclidean)
[2025-03-07 13:59:12,167] [INFO] [30087] Received PREPARE: id:1741323542381, from:30066, delay:0.0001s, distance:206.24m (Euclidean)
[2025-03-07 13:59:12,167] [INFO] [30087] Missing PRE-PREPARE for REQUEST 1741323542381; ignoring PREPARE
[2025-03-07 13:59:12,167] [INFO] [30087] Received COMMIT: id:1741323542381, from:30066, delay:0.0001s, distance:206.24m (Euclidean)
[2025-03-07 13:59:12,352] [INFO] [30087] Received PREPARE: id:1741323542381, from:30096, delay:0.0001s, distance:226.63m (Euclidean)
[2025-03-07 13:59:12,352] [INFO] [30087] Missing PRE-PREPARE for REQUEST 1741323542381; ignoring PREPARE
[2025-03-07 13:59:12,352] [INFO] [30087] Received COMMIT: id:1741323542381, from:30096, delay:0.0001s, distance:226.63m (Euclidean)
[2025-03-07 13:59:12,448] [INFO] [30087] Received PREPARE: id:1741323542381, from:30061, delay:0.0000s, distance:140.61m (Euclidean)
[2025-03-07 13:59:12,448] [INFO] [30087] Missing PRE-PREPARE for REQUEST 1741323542381; ignoring PREPARE
[2025-03-07 13:59:12,725] [INFO] [30087] Received PREPARE: id:1741323542381, from:30156, delay:0.0000s, distance:200.78m (Euclidean)
[2025-03-07 13:59:12,725] [INFO] [30087] Missing PRE-PREPARE for REQUEST 1741323542381; ignoring PREPARE
[2025-03-07 13:59:12,750] [INFO] [30087] Received PRE-PREPARE: id:1741323542381, from:Leader(30000), delay:0.0001s, distance:286.36m (Euclidean)
[2025-03-07 13:59:12,750] [INFO] [30087] Broadcasting PREPARE for REQUEST 1741323542381
[2025-03-07 13:59:12,761] [INFO] [30087] Not broadcasting to fault node: 30077
[2025-03-07 13:59:12,773] [INFO] [30087] Not broadcasting to fault node: 30184
[2025-03-07 13:59:12,915] [INFO] [30087] Received PREPARE: id:1741323542381, from:30071, delay:0.0000s, distance:299.70m (Euclidean)
[2025-03-07 13:59:12,915] [INFO] [30087] Broadcasting COMMIT for REQUEST 1741323542381
[2025-03-07 13:59:12,926] [INFO] [30087] Not broadcasting to fault node: 30077
[2025-03-07 13:59:12,944] [INFO] [30087] Not broadcasting to fault node: 30184
[2025-03-07 13:59:13,037] [INFO] [30087] Received COMMIT: id:1741323542381, from:30031, delay:0.0001s, distance:180.74m (Euclidean)
[2025-03-07 13:59:13,037] [INFO] [30087] Received PREPARE: id:1741323542381, from:30067, delay:0.0001s, distance:248.08m (Euclidean)
[2025-03-07 13:59:13,037] [INFO] [30087] Received PREPARE: id:1741323542381, from:30031, delay:0.0001s, distance:180.74m (Euclidean)
[2025-03-07 13:59:13,037] [INFO] [30087] Received PREPARE: id:1741323542381, from:30006, delay:0.0001s, distance:199.69m (Euclidean)
[2025-03-07 13:59:13,075] [INFO] [30087] Received PREPARE: id:1741323542381, from:30165, delay:0.0000s, distance:43.18m (Euclidean)
[2025-03-07 13:59:13,075] [INFO] [30087] Received COMMIT: id:1741323542381, from:30165, delay:0.0000s, distance:43.18m (Euclidean)
[2025-03-07 13:59:13,412] [INFO] [30087] Received PREPARE: id:1741323542381, from:30143, delay:0.0000s, distance:68.70m (Euclidean)
[2025-03-07 13:59:13,418] [INFO] [30087] Received COMMIT: id:1741323542381, from:30143, delay:0.0000s, distance:68.70m (Euclidean)
[2025-03-07 13:59:13,421] [INFO] [30087] Received PREPARE: id:1741323542381, from:30122, delay:0.0000s, distance:31.60m (Euclidean)
[2025-03-07 13:59:13,833] [INFO] [30087] Received PREPARE: id:1741323542381, from:30014, delay:0.0000s, distance:107.70m (Euclidean)
[2025-03-07 13:59:13,954] [INFO] [30087] Received PREPARE: id:1741323542381, from:30132, delay:0.0000s, distance:103.10m (Euclidean)
[2025-03-07 13:59:14,122] [INFO] [30087] Received COMMIT: id:1741323542381, from:30067, delay:0.0001s, distance:248.08m (Euclidean)
[2025-03-07 13:59:14,415] [INFO] [30087] Received PREPARE: id:1741323542381, from:30052, delay:0.0000s, distance:98.51m (Euclidean)
[2025-03-07 13:59:14,415] [INFO] [30087] Received COMMIT: id:1741323542381, from:30052, delay:0.0000s, distance:98.51m (Euclidean)
[2025-03-07 13:59:14,463] [INFO] [30087] Received PREPARE: id:1741323542381, from:30105, delay:0.0000s, distance:142.59m (Euclidean)
[2025-03-07 13:59:14,815] [INFO] [30087] Received COMMIT: id:1741323542381, from:30137, delay:0.0001s, distance:182.60m (Euclidean)
[2025-03-07 13:59:14,815] [INFO] [30087] Received PREPARE: id:1741323542381, from:30137, delay:0.0001s, distance:182.60m (Euclidean)
[2025-03-07 13:59:14,823] [INFO] [30087] Received PREPARE: id:1741323542381, from:30001, delay:0.0000s, distance:91.31m (Euclidean)
[2025-03-07 13:59:14,823] [INFO] [30087] Received COMMIT: id:1741323542381, from:30001, delay:0.0000s, distance:91.31m (Euclidean)
[2025-03-07 13:59:14,843] [INFO] [30087] Received PREPARE: id:1741323542381, from:30187, delay:0.0000s, distance:90.26m (Euclidean)
[2025-03-07 13:59:14,871] [INFO] [30087] Received PREPARE: id:1741323542381, from:30036, delay:0.0000s, distance:90.37m (Euclidean)
[2025-03-07 13:59:14,964] [INFO] [30087] Received PREPARE: id:1741323542381, from:30135, delay:0.0002s, distance:256.34m (Euclidean)
[2025-03-07 13:59:14,967] [INFO] [30087] Received COMMIT: id:1741323542381, from:30135, delay:0.0002s, distance:256.34m (Euclidean)
[2025-03-07 13:59:14,984] [INFO] [30087] Received PREPARE: id:1741323542381, from:30114, delay:0.0000s, distance:31.09m (Euclidean)
[2025-03-07 13:59:15,003] [INFO] [30087] Received PREPARE: id:1741323542381, from:30042, delay:0.0000s, distance:126.73m (Euclidean)
[2025-03-07 13:59:15,032] [INFO] [30087] Received COMMIT: id:1741323542381, from:30132, delay:0.0000s, distance:103.10m (Euclidean)
[2025-03-07 13:59:15,090] [INFO] [30087] Received PREPARE: id:1741323542381, from:30050, delay:0.0002s, distance:275.02m (Euclidean)
[2025-03-07 13:59:15,153] [INFO] [30087] Received COMMIT: id:1741323542381, from:30014, delay:0.0000s, distance:107.70m (Euclidean)
[2025-03-07 13:59:15,590] [INFO] [30087] Received PREPARE: id:1741323542381, from:30142, delay:0.0000s, distance:89.16m (Euclidean)
[2025-03-07 13:59:15,677] [INFO] [30087] Received PREPARE: id:1741323542381, from:30079, delay:0.0000s, distance:67.13m (Euclidean)
[2025-03-07 13:59:15,677] [INFO] [30087] Received COMMIT: id:1741323542381, from:30079, delay:0.0000s, distance:67.13m (Euclidean)
[2025-03-07 13:59:15,729] [INFO] [30087] Received COMMIT: id:1741323542381, from:30061, delay:0.0000s, distance:140.61m (Euclidean)
[2025-03-07 13:59:15,746] [INFO] [30087] Received PREPARE: id:1741323542381, from:30145, delay:0.0001s, distance:190.04m (Euclidean)
[2025-03-07 13:59:15,842] [INFO] [30087] Received COMMIT: id:1741323542381, from:30071, delay:0.0000s, distance:299.70m (Euclidean)
[2025-03-07 13:59:15,937] [INFO] [30087] Received COMMIT: id:1741323542381, from:30036, delay:0.0000s, distance:90.37m (Euclidean)
[2025-03-07 13:59:15,973] [INFO] [30087] Received COMMIT: id:1741323542381, from:30050, delay:0.0002s, distance:275.02m (Euclidean)
[2025-03-07 13:59:16,095] [INFO] [30087] Received COMMIT: id:1741323542381, from:30114, delay:0.0000s, distance:31.09m (Euclidean)
[2025-03-07 13:59:16,137] [INFO] [30087] Received PREPARE: id:1741323542381, from:30194, delay:0.0002s, distance:292.88m (Euclidean)
[2025-03-07 13:59:16,215] [INFO] [30087] Received PREPARE: id:1741323542381, from:30198, delay:0.0002s, distance:294.19m (Euclidean)
[2025-03-07 13:59:16,215] [INFO] [30087] Received COMMIT: id:1741323542381, from:30198, delay:0.0002s, distance:294.19m (Euclidean)
[2025-03-07 13:59:16,274] [INFO] [30087] Received PREPARE: id:1741323542381, from:30081, delay:0.0002s, distance:274.11m (Euclidean)
[2025-03-07 13:59:16,274] [INFO] [30087] Received COMMIT: id:1741323542381, from:30081, delay:0.0002s, distance:274.11m (Euclidean)
[2025-03-07 13:59:16,419] [INFO] [30087] Received PREPARE: id:1741323542381, from:30104, delay:0.0001s, distance:153.21m (Euclidean)
[2025-03-07 13:59:16,419] [INFO] [30087] Received COMMIT: id:1741323542381, from:30104, delay:0.0001s, distance:153.21m (Euclidean)
[2025-03-07 13:59:16,692] [INFO] [30087] Received PREPARE: id:1741323542381, from:30032, delay:0.0002s, distance:295.55m (Euclidean)
[2025-03-07 13:59:16,692] [INFO] [30087] Received COMMIT: id:1741323542381, from:30032, delay:0.0002s, distance:295.55m (Euclidean)
[2025-03-07 13:59:16,865] [INFO] [30087] Received COMMIT: id:1741323542381, from:30042, delay:0.0000s, distance:126.73m (Euclidean)
[2025-03-07 13:59:16,964] [INFO] [30087] Received PREPARE: id:1741323542381, from:30173, delay:0.0001s, distance:160.81m (Euclidean)
[2025-03-07 13:59:16,964] [INFO] [30087] Received COMMIT: id:1741323542381, from:30173, delay:0.0001s, distance:160.81m (Euclidean)
[2025-03-07 13:59:17,059] [INFO] [30087] Received COMMIT: id:1741323542381, from:30122, delay:0.0000s, distance:31.60m (Euclidean)
[2025-03-07 13:59:17,111] [INFO] [30087] Received PREPARE: id:1741323542381, from:30084, delay:0.0001s, distance:239.67m (Euclidean)
[2025-03-07 13:59:17,190] [INFO] [30087] Received PREPARE: id:1741323542381, from:30064, delay:0.0002s, distance:296.24m (Euclidean)
[2025-03-07 13:59:17,296] [INFO] [30087] Received PREPARE: id:1741323542381, from:30091, delay:0.0001s, distance:222.71m (Euclidean)
[2025-03-07 13:59:17,299] [INFO] [30087] Received COMMIT: id:1741323542381, from:30091, delay:0.0001s, distance:222.71m (Euclidean)
[2025-03-07 13:59:17,544] [INFO] [30087] Received PREPARE: id:1741323542381, from:30058, delay:0.0001s, distance:201.02m (Euclidean)
[2025-03-07 13:59:17,545] [INFO] [30087] Received COMMIT: id:1741323542381, from:30058, delay:0.0001s, distance:201.02m (Euclidean)
[2025-03-07 13:59:17,677] [INFO] [30087] Received PREPARE: id:1741323542381, from:30069, delay:0.0002s, distance:296.02m (Euclidean)
[2025-03-07 13:59:17,679] [INFO] [30087] Received COMMIT: id:1741323542381, from:30069, delay:0.0002s, distance:296.02m (Euclidean)
[2025-03-07 13:59:17,734] [INFO] [30087] Received PREPARE: id:1741323542381, from:30010, delay:0.0001s, distance:232.66m (Euclidean)
[2025-03-07 13:59:17,734] [INFO] [30087] Received COMMIT: id:1741323542381, from:30010, delay:0.0001s, distance:232.66m (Euclidean)
[2025-03-07 13:59:17,753] [INFO] [30087] Received COMMIT: id:1741323542381, from:30194, delay:0.0002s, distance:292.88m (Euclidean)
[2025-03-07 13:59:17,826] [INFO] [30087] Received PREPARE: id:1741323542381, from:30083, delay:0.0002s, distance:293.38m (Euclidean)
[2025-03-07 13:59:17,828] [INFO] [30087] Received COMMIT: id:1741323542381, from:30083, delay:0.0002s, distance:293.38m (Euclidean)
[2025-03-07 13:59:18,091] [INFO] [30087] Received PREPARE: id:1741323542381, from:30038, delay:0.0000s, distance:144.37m (Euclidean)
[2025-03-07 13:59:18,091] [INFO] [30087] Received COMMIT: id:1741323542381, from:30038, delay:0.0000s, distance:144.37m (Euclidean)
[2025-03-07 13:59:18,216] [INFO] [30087] Received COMMIT: id:1741323542381, from:30105, delay:0.0000s, distance:142.59m (Euclidean)
[2025-03-07 13:59:18,286] [INFO] [30087] Received COMMIT: id:1741323542381, from:30006, delay:0.0001s, distance:199.69m (Euclidean)
[2025-03-07 13:59:18,627] [INFO] [30087] Received PREPARE: id:1741323542381, from:30008, delay:0.0000s, distance:165.07m (Euclidean)
[2025-03-07 13:59:18,629] [INFO] [30087] Received COMMIT: id:1741323542381, from:30008, delay:0.0000s, distance:165.07m (Euclidean)
[2025-03-07 13:59:18,634] [INFO] [30087] Received COMMIT: id:1741323542381, from:30142, delay:0.0000s, distance:89.16m (Euclidean)
[2025-03-07 13:59:18,729] [INFO] [30087] Received PREPARE: id:1741323542381, from:30039, delay:0.0000s, distance:133.18m (Euclidean)
[2025-03-07 13:59:18,731] [INFO] [30087] Received COMMIT: id:1741323542381, from:30039, delay:0.0000s, distance:133.18m (Euclidean)
[2025-03-07 13:59:18,802] [INFO] [30087] Received PREPARE: id:1741323542381, from:30186, delay:0.0001s, distance:212.89m (Euclidean)
[2025-03-07 13:59:18,802] [INFO] [30087] Received COMMIT: id:1741323542381, from:30186, delay:0.0001s, distance:212.89m (Euclidean)
[2025-03-07 13:59:18,921] [INFO] [30087] Received PREPARE: id:1741323542381, from:30148, delay:0.0000s, distance:299.09m (Euclidean)
[2025-03-07 13:59:18,921] [INFO] [30087] Received PREPARE: id:1741323542381, from:30188, delay:0.0001s, distance:238.28m (Euclidean)
[2025-03-07 13:59:18,931] [INFO] [30087] Received COMMIT: id:1741323542381, from:30188, delay:0.0001s, distance:238.28m (Euclidean)
[2025-03-07 13:59:19,023] [INFO] [30087] Received PREPARE: id:1741323542381, from:30016, delay:0.0001s, distance:205.76m (Euclidean)
[2025-03-07 13:59:19,024] [INFO] [30087] Received COMMIT: id:1741323542381, from:30016, delay:0.0001s, distance:205.76m (Euclidean)
[2025-03-07 13:59:19,035] [INFO] [30087] Received PREPARE: id:1741323542381, from:30160, delay:0.0002s, distance:275.06m (Euclidean)
[2025-03-07 13:59:19,036] [INFO] [30087] Received COMMIT: id:1741323542381, from:30160, delay:0.0002s, distance:275.06m (Euclidean)
[2025-03-07 13:59:19,176] [INFO] [30087] Received PREPARE: id:1741323542381, from:30034, delay:0.0001s, distance:207.97m (Euclidean)
[2025-03-07 13:59:19,176] [INFO] [30087] Received COMMIT: id:1741323542381, from:30034, delay:0.0001s, distance:207.97m (Euclidean)
[2025-03-07 13:59:19,325] [INFO] [30087] Received COMMIT: id:1741323542381, from:30145, delay:0.0001s, distance:190.04m (Euclidean)
[2025-03-07 13:59:19,791] [INFO] [30087] Received PREPARE: id:1741323542381, from:30101, delay:0.0002s, distance:291.15m (Euclidean)
[2025-03-07 13:59:19,809] [INFO] [30087] Received COMMIT: id:1741323542381, from:30101, delay:0.0002s, distance:291.15m (Euclidean)
[2025-03-07 13:59:19,838] [INFO] [30087] Received COMMIT: id:1741323542381, from:30156, delay:0.0000s, distance:200.78m (Euclidean)
[2025-03-07 13:59:19,983] [INFO] [30087] Received COMMIT: id:1741323542381, from:30064, delay:0.0002s, distance:296.24m (Euclidean)
[2025-03-07 13:59:20,204] [INFO] [30087] Received PREPARE: id:1741323542381, from:30193, delay:0.0001s, distance:235.91m (Euclidean)
[2025-03-07 13:59:21,494] [INFO] [30087] Received COMMIT: id:1741323542381, from:30193, delay:0.0001s, distance:235.91m (Euclidean)
[2025-03-07 13:59:22,083] [INFO] [30087] Received PREPARE: id:1741323542381, from:30099, delay:0.0002s, distance:281.19m (Euclidean)
[2025-03-07 13:59:22,084] [INFO] [30087] Received COMMIT: id:1741323542381, from:30151, delay:0.0000s, distance:168.90m (Euclidean)
[2025-03-07 13:59:22,084] [INFO] [30087] Received COMMIT: id:1741323542381, from:30099, delay:0.0002s, distance:281.19m (Euclidean)
[2025-03-07 13:59:22,084] [INFO] [30087] Received PREPARE: id:1741323542381, from:30139, delay:0.0000s, distance:130.91m (Euclidean)
[2025-03-07 13:59:22,084] [INFO] [30087] Received COMMIT: id:1741323542381, from:30073, delay:0.0001s, distance:198.72m (Euclidean)
[2025-03-07 13:59:22,084] [INFO] [30087] Received PREPARE: id:1741323542381, from:30073, delay:0.0001s, distance:198.72m (Euclidean)
[2025-03-07 13:59:22,084] [INFO] [30087] Received PREPARE: id:1741323542381, from:30185, delay:0.0000s, distance:100.18m (Euclidean)
[2025-03-07 13:59:22,128] [INFO] [30087] Received PREPARE: id:1741323542381, from:30151, delay:0.0000s, distance:168.90m (Euclidean)
[2025-03-07 13:59:22,169] [INFO] [30087] Received PREPARE: id:1741323542381, from:30094, delay:0.0000s, distance:130.60m (Euclidean)
[2025-03-07 13:59:22,169] [INFO] [30087] Received COMMIT: id:1741323542381, from:30094, delay:0.0000s, distance:130.60m (Euclidean)
[2025-03-07 13:59:22,216] [INFO] [30087] Received COMMIT: id:1741323542381, from:30075, delay:0.0001s, distance:186.15m (Euclidean)
[2025-03-07 13:59:22,216] [INFO] [30087] Received PREPARE: id:1741323542381, from:30075, delay:0.0001s, distance:186.15m (Euclidean)
[2025-03-07 13:59:22,216] [INFO] [30087] Received COMMIT: id:1741323542381, from:30185, delay:0.0000s, distance:100.18m (Euclidean)
[2025-03-07 13:59:22,230] [INFO] [30087] Received COMMIT: id:1741323542381, from:30084, delay:0.0001s, distance:239.67m (Euclidean)
[2025-03-07 13:59:22,813] [INFO] [30087] Received PREPARE: id:1741323542381, from:30138, delay:0.0000s, distance:109.41m (Euclidean)
[2025-03-07 13:59:22,813] [INFO] [30087] Received COMMIT: id:1741323542381, from:30138, delay:0.0000s, distance:109.41m (Euclidean)
[2025-03-07 13:59:23,503] [INFO] [30087] Received COMMIT: id:1741323542381, from:30187, delay:0.0000s, distance:90.26m (Euclidean)
[2025-03-07 13:59:23,583] [INFO] [30087] Received COMMIT: id:1741323542381, from:30139, delay:0.0000s, distance:130.91m (Euclidean)
[2025-03-07 13:59:24,115] [INFO] [30087] Received PREPARE: id:1741323542381, from:30152, delay:0.0002s, distance:278.04m (Euclidean)
[2025-03-07 13:59:24,115] [INFO] [30087] Received COMMIT: id:1741323542381, from:30152, delay:0.0002s, distance:278.04m (Euclidean)
[2025-03-07 13:59:24,154] [INFO] [30087] Received PREPARE: id:1741323542381, from:30088, delay:0.0001s, distance:218.56m (Euclidean)
[2025-03-07 13:59:24,154] [INFO] [30087] Received COMMIT: id:1741323542381, from:30088, delay:0.0001s, distance:218.56m (Euclidean)
[2025-03-07 13:59:24,162] [INFO] [30087] Received COMMIT: id:1741323542381, from:30148, delay:0.0000s, distance:299.09m (Euclidean)
[2025-03-07 13:59:24,703] [INFO] [30087] Received COMMIT: id:1741323542381, from:30000, delay:0.0001s, distance:286.36m (Euclidean)
[2025-03-07 13:59:24,786] [INFO] [30087] Received PREPARE: id:1741323542381, from:30131, delay:0.0001s, distance:199.78m (Euclidean)
[2025-03-07 13:59:24,786] [INFO] [30087] Received COMMIT: id:1741323542381, from:30131, delay:0.0001s, distance:199.78m (Euclidean)
[2025-03-07 13:59:25,111] [INFO] [30087] Received PREPARE: id:1741323542381, from:30082, delay:0.0000s, distance:92.90m (Euclidean)
[2025-03-07 13:59:25,204] [INFO] [30087] Received PREPARE: id:1741323542381, from:30045, delay:0.0002s, distance:252.28m (Euclidean)
[2025-03-07 13:59:25,207] [INFO] [30087] Received COMMIT: id:1741323542381, from:30045, delay:0.0002s, distance:252.28m (Euclidean)
[2025-03-07 13:59:25,290] [INFO] [30087] Received PREPARE: id:1741323542381, from:30055, delay:0.0001s, distance:238.36m (Euclidean)
[2025-03-07 13:59:25,290] [INFO] [30087] Received COMMIT: id:1741323542381, from:30055, delay:0.0001s, distance:238.36m (Euclidean)
[2025-03-07 13:59:26,050] [INFO] [30087] Received COMMIT: id:1741323542381, from:30082, delay:0.0000s, distance:92.90m (Euclidean)
[2025-03-07 13:59:26,344] [INFO] [30087] Received PREPARE: id:1741323542381, from:30072, delay:0.0001s, distance:225.48m (Euclidean)
[2025-03-07 13:59:26,361] [INFO] [30087] Received PREPARE: id:1741323542381, from:30009, delay:0.0002s, distance:293.49m (Euclidean)
[2025-03-07 13:59:26,361] [INFO] [30087] Received COMMIT: id:1741323542381, from:30009, delay:0.0002s, distance:293.49m (Euclidean)
[2025-03-07 13:59:26,735] [INFO] [30087] Received PREPARE: id:1741323542381, from:30192, delay:0.0001s, distance:226.11m (Euclidean)
[2025-03-07 13:59:26,735] [INFO] [30087] Received COMMIT: id:1741323542381, from:30192, delay:0.0001s, distance:226.11m (Euclidean)
[2025-03-07 13:59:26,840] [INFO] [30087] Received PREPARE: id:1741323542381, from:30166, delay:0.0001s, distance:166.97m (Euclidean)
[2025-03-07 13:59:26,847] [INFO] [30087] Received COMMIT: id:1741323542381, from:30166, delay:0.0001s, distance:166.97m (Euclidean)
[2025-03-07 13:59:27,395] [INFO] [30087] Received PREPARE: id:1741323542381, from:30047, delay:0.0000s, distance:88.28m (Euclidean)
[2025-03-07 13:59:27,395] [INFO] [30087] Received COMMIT: id:1741323542381, from:30047, delay:0.0000s, distance:88.28m (Euclidean)
[2025-03-07 13:59:27,623] [INFO] [30087] Received COMMIT: id:1741323542381, from:30072, delay:0.0001s, distance:225.48m (Euclidean)
[2025-03-07 13:59:27,634] [INFO] [30087] Received PREPARE: id:1741323542381, from:30162, delay:0.0002s, distance:284.35m (Euclidean)
[2025-03-07 13:59:27,634] [INFO] [30087] Received COMMIT: id:1741323542381, from:30162, delay:0.0002s, distance:284.35m (Euclidean)
[2025-03-07 13:59:27,795] [INFO] [30087] Received PREPARE: id:1741323542381, from:30164, delay:0.0001s, distance:239.64m (Euclidean)
[2025-03-07 13:59:27,814] [INFO] [30087] Received COMMIT: id:1741323542381, from:30164, delay:0.0001s, distance:239.64m (Euclidean)
[2025-03-07 13:59:28,037] [INFO] [30087] Received PREPARE: id:1741323542381, from:30097, delay:0.0002s, distance:257.69m (Euclidean)
[2025-03-07 13:59:28,037] [INFO] [30087] Received COMMIT: id:1741323542381, from:30097, delay:0.0002s, distance:257.69m (Euclidean)
[2025-03-07 13:59:28,049] [INFO] [30087] Received PREPARE: id:1741323542381, from:30012, delay:0.0001s, distance:192.78m (Euclidean)
[2025-03-07 13:59:28,057] [INFO] [30087] Received COMMIT: id:1741323542381, from:30012, delay:0.0001s, distance:192.78m (Euclidean)
[2025-03-07 13:59:28,322] [INFO] [30087] Received PREPARE: id:1741323542381, from:30044, delay:0.0000s, distance:130.43m (Euclidean)
[2025-03-07 13:59:28,322] [INFO] [30087] Received COMMIT: id:1741323542381, from:30044, delay:0.0000s, distance:130.43m (Euclidean)
[2025-03-07 13:59:28,379] [INFO] [30087] Received PREPARE: id:1741323542381, from:30002, delay:0.0002s, distance:283.17m (Euclidean)
[2025-03-07 13:59:28,379] [INFO] [30087] Received COMMIT: id:1741323542381, from:30002, delay:0.0002s, distance:283.17m (Euclidean)
[2025-03-07 13:59:28,660] [INFO] [30087] Received PREPARE: id:1741323542381, from:30018, delay:0.0000s, distance:151.19m (Euclidean)
[2025-03-07 13:59:28,691] [INFO] [30087] Received COMMIT: id:1741323542381, from:30018, delay:0.0000s, distance:151.19m (Euclidean)
[2025-03-07 13:59:28,919] [INFO] [30087] Received PREPARE: id:1741323542381, from:30172, delay:0.0001s, distance:203.15m (Euclidean)
[2025-03-07 13:59:29,005] [INFO] [30087] Received COMMIT: id:1741323542381, from:30172, delay:0.0001s, distance:203.15m (Euclidean)
[2025-03-07 13:59:37,453] [INFO] [30087] Received PREPARE: id:1741323542381, from:30078, delay:0.0001s, distance:229.49m (Euclidean)
[2025-03-07 13:59:38,072] [INFO] [30087] Received PREPARE: id:1741323542381, from:30030, delay:0.0002s, distance:286.61m (Euclidean)
[2025-03-07 13:59:38,418] [INFO] [30087] Received COMMIT: id:1741323542381, from:30030, delay:0.0002s, distance:286.61m (Euclidean)
[2025-03-07 13:59:38,525] [INFO] [30087] Received PREPARE: id:1741323542381, from:30183, delay:0.0002s, distance:265.10m (Euclidean)
[2025-03-07 13:59:38,531] [INFO] [30087] Received COMMIT: id:1741323542381, from:30183, delay:0.0002s, distance:265.10m (Euclidean)
[2025-03-07 13:59:38,599] [INFO] [30087] Received PREPARE: id:1741323542381, from:30163, delay:0.0001s, distance:165.84m (Euclidean)
[2025-03-07 13:59:38,748] [INFO] [30087] Received COMMIT: id:1741323542381, from:30163, delay:0.0001s, distance:165.84m (Euclidean)
