[2025-03-07 13:53:34,478] [INFO] Starting node at localhost:30158 | index=159 | f=1, k=4 | Role: Replica
[2025-03-07 13:53:39,075] [INFO] [30158] Received PREPARE: id:1741323218379, from:30018, delay:0.0000s, distance:299.97m (Euclidean)
[2025-03-07 13:53:39,075] [INFO] [30158] Missing PRE-PREPARE for REQUEST 1741323218379; ignoring PREPARE
[2025-03-07 13:53:39,302] [INFO] [30158] Received PREPARE: id:1741323218379, from:30048, delay:0.0000s, distance:100.23m (Euclidean)
[2025-03-07 13:53:39,302] [INFO] [30158] Missing PRE-PREPARE for REQUEST 1741323218379; ignoring PREPARE
[2025-03-07 13:53:39,440] [INFO] [30158] Received PREPARE: id:1741323218379, from:30028, delay:0.0000s, distance:150.73m (Euclidean)
[2025-03-07 13:53:39,440] [INFO] [30158] Missing PRE-PREPARE for REQUEST 1741323218379; ignoring PREPARE
[2025-03-07 13:53:39,578] [INFO] [30158] Received COMMIT: id:1741323218379, from:30028, delay:0.0000s, distance:150.73m (Euclidean)
[2025-03-07 13:53:39,639] [INFO] [30158] Received PREPARE: id:1741323218379, from:30005, delay:0.0000s, distance:70.54m (Euclidean)
[2025-03-07 13:53:39,639] [INFO] [30158] Missing PRE-PREPARE for REQUEST 1741323218379; ignoring PREPARE
[2025-03-07 13:53:39,785] [INFO] [30158] Received COMMIT: id:1741323218379, from:30005, delay:0.0000s, distance:70.54m (Euclidean)
[2025-03-07 13:53:40,021] [INFO] [30158] Received PREPARE: id:1741323218379, from:30086, delay:0.0000s, distance:112.86m (Euclidean)
[2025-03-07 13:53:40,021] [INFO] [30158] Missing PRE-PREPARE for REQUEST 1741323218379; ignoring PREPARE
[2025-03-07 13:53:40,766] [INFO] [30158] Received COMMIT: id:1741323218379, from:30018, delay:0.0000s, distance:299.97m (Euclidean)
[2025-03-07 13:53:40,766] [INFO] [30158] Received PREPARE: id:1741323218379, from:30073, delay:0.0000s, distance:51.79m (Euclidean)
[2025-03-07 13:53:40,766] [INFO] [30158] Missing PRE-PREPARE for REQUEST 1741323218379; ignoring PREPARE
[2025-03-07 13:53:40,818] [INFO] [30158] Received PREPARE: id:1741323218379, from:30021, delay:0.0002s, distance:297.19m (Euclidean)
[2025-03-07 13:53:40,818] [INFO] [30158] Missing PRE-PREPARE for REQUEST 1741323218379; ignoring PREPARE
[2025-03-07 13:53:40,818] [INFO] [30158] Received COMMIT: id:1741323218379, from:30021, delay:0.0002s, distance:297.19m (Euclidean)
[2025-03-07 13:53:40,877] [INFO] [30158] Received PREPARE: id:1741323218379, from:30049, delay:0.0000s, distance:99.44m (Euclidean)
[2025-03-07 13:53:40,877] [INFO] [30158] Missing PRE-PREPARE for REQUEST 1741323218379; ignoring PREPARE
[2025-03-07 13:53:40,877] [INFO] [30158] Received COMMIT: id:1741323218379, from:30049, delay:0.0000s, distance:99.44m (Euclidean)
[2025-03-07 13:53:41,257] [INFO] [30158] Received PREPARE: id:1741323218379, from:30061, delay:0.0000s, distance:108.51m (Euclidean)
[2025-03-07 13:53:41,257] [INFO] [30158] Missing PRE-PREPARE for REQUEST 1741323218379; ignoring PREPARE
[2025-03-07 13:53:41,861] [INFO] [30158] Received PREPARE: id:1741323218379, from:30020, delay:0.0002s, distance:296.05m (Euclidean)
[2025-03-07 13:53:41,861] [INFO] [30158] Missing PRE-PREPARE for REQUEST 1741323218379; ignoring PREPARE
[2025-03-07 13:53:41,861] [INFO] [30158] Received COMMIT: id:1741323218379, from:30020, delay:0.0002s, distance:296.05m (Euclidean)
[2025-03-07 13:53:41,921] [INFO] [30158] Received COMMIT: id:1741323218379, from:30073, delay:0.0000s, distance:51.79m (Euclidean)
[2025-03-07 13:53:41,952] [INFO] [30158] Received COMMIT: id:1741323218379, from:30086, delay:0.0000s, distance:112.86m (Euclidean)
[2025-03-07 13:53:42,143] [INFO] [30158] Received PREPARE: id:1741323218379, from:30033, delay:0.0001s, distance:193.98m (Euclidean)
[2025-03-07 13:53:42,143] [INFO] [30158] Missing PRE-PREPARE for REQUEST 1741323218379; ignoring PREPARE
[2025-03-07 13:53:42,143] [INFO] [30158] Received COMMIT: id:1741323218379, from:30033, delay:0.0001s, distance:193.98m (Euclidean)
[2025-03-07 13:53:42,143] [INFO] [30158] Received COMMIT: id:1741323218379, from:30048, delay:0.0000s, distance:100.23m (Euclidean)
[2025-03-07 13:53:42,163] [INFO] [30158] Received PREPARE: id:1741323218379, from:30047, delay:0.0001s, distance:215.30m (Euclidean)
[2025-03-07 13:53:42,163] [INFO] [30158] Missing PRE-PREPARE for REQUEST 1741323218379; ignoring PREPARE
[2025-03-07 13:53:42,163] [INFO] [30158] Received COMMIT: id:1741323218379, from:30047, delay:0.0001s, distance:215.30m (Euclidean)
[2025-03-07 13:53:42,269] [INFO] [30158] Received PREPARE: id:1741323218379, from:30096, delay:0.0002s, distance:264.86m (Euclidean)
[2025-03-07 13:53:42,269] [INFO] [30158] Missing PRE-PREPARE for REQUEST 1741323218379; ignoring PREPARE
[2025-03-07 13:53:42,269] [INFO] [30158] Received COMMIT: id:1741323218379, from:30096, delay:0.0002s, distance:264.86m (Euclidean)
[2025-03-07 13:53:42,285] [INFO] [30158] Received PREPARE: id:1741323218379, from:30062, delay:0.0001s, distance:192.12m (Euclidean)
[2025-03-07 13:53:42,285] [INFO] [30158] Missing PRE-PREPARE for REQUEST 1741323218379; ignoring PREPARE
[2025-03-07 13:53:42,285] [INFO] [30158] Received COMMIT: id:1741323218379, from:30062, delay:0.0001s, distance:192.12m (Euclidean)
[2025-03-07 13:53:42,405] [INFO] [30158] Received PREPARE: id:1741323218379, from:30052, delay:0.0001s, distance:228.76m (Euclidean)
[2025-03-07 13:53:42,405] [INFO] [30158] Missing PRE-PREPARE for REQUEST 1741323218379; ignoring PREPARE
[2025-03-07 13:53:42,411] [INFO] [30158] Received COMMIT: id:1741323218379, from:30052, delay:0.0001s, distance:228.76m (Euclidean)
[2025-03-07 13:53:42,411] [INFO] [30158] Received PREPARE: id:1741323218379, from:30046, delay:0.0001s, distance:171.65m (Euclidean)
[2025-03-07 13:53:42,411] [INFO] [30158] Missing PRE-PREPARE for REQUEST 1741323218379; ignoring PREPARE
[2025-03-07 13:53:42,411] [INFO] [30158] Received COMMIT: id:1741323218379, from:30046, delay:0.0001s, distance:171.65m (Euclidean)
[2025-03-07 13:53:42,711] [INFO] [30158] Received PREPARE: id:1741323218379, from:30060, delay:0.0001s, distance:234.89m (Euclidean)
[2025-03-07 13:53:42,711] [INFO] [30158] Missing PRE-PREPARE for REQUEST 1741323218379; ignoring PREPARE
[2025-03-07 13:53:42,711] [INFO] [30158] Received COMMIT: id:1741323218379, from:30060, delay:0.0001s, distance:234.89m (Euclidean)
[2025-03-07 13:53:42,789] [INFO] [30158] Received PREPARE: id:1741323218379, from:30002, delay:0.0000s, distance:103.60m (Euclidean)
[2025-03-07 13:53:42,789] [INFO] [30158] Missing PRE-PREPARE for REQUEST 1741323218379; ignoring PREPARE
[2025-03-07 13:53:42,805] [INFO] [30158] Received PRE-PREPARE: id:1741323218379, from:Leader(30000), delay:0.0000s, distance:197.70m (Euclidean)
[2025-03-07 13:53:42,805] [INFO] [30158] Broadcasting PREPARE for REQUEST 1741323218379
[2025-03-07 13:53:43,011] [INFO] [30158] Received PREPARE: id:1741323218379, from:30030, delay:0.0001s, distance:234.72m (Euclidean)
[2025-03-07 13:53:43,011] [INFO] [30158] Broadcasting COMMIT for REQUEST 1741323218379
[2025-03-07 13:53:43,053] [INFO] [30158] Received COMMIT: id:1741323218379, from:30030, delay:0.0001s, distance:234.72m (Euclidean)
[2025-03-07 13:53:43,094] [INFO] [30158] Received PREPARE: id:1741323218379, from:30135, delay:0.0000s, distance:249.49m (Euclidean)
[2025-03-07 13:53:43,264] [INFO] [30158] Received COMMIT: id:1741323218379, from:30061, delay:0.0000s, distance:108.51m (Euclidean)
[2025-03-07 13:53:43,276] [INFO] [30158] Received PREPARE: id:1741323218379, from:30088, delay:0.0000s, distance:145.99m (Euclidean)
[2025-03-07 13:53:43,285] [INFO] [30158] Received COMMIT: id:1741323218379, from:30088, delay:0.0000s, distance:145.99m (Euclidean)
[2025-03-07 13:53:43,298] [INFO] [30158] Received COMMIT: id:1741323218379, from:30002, delay:0.0000s, distance:103.60m (Euclidean)
[2025-03-07 13:53:43,298] [INFO] [30158] Received PREPARE: id:1741323218379, from:30011, delay:0.0001s, distance:165.95m (Euclidean)
[2025-03-07 13:53:43,308] [INFO] [30158] Received COMMIT: id:1741323218379, from:30011, delay:0.0001s, distance:165.95m (Euclidean)
[2025-03-07 13:53:43,314] [INFO] [30158] Received PREPARE: id:1741323218379, from:30081, delay:0.0002s, distance:279.10m (Euclidean)
[2025-03-07 13:53:43,314] [INFO] [30158] Received COMMIT: id:1741323218379, from:30081, delay:0.0002s, distance:279.10m (Euclidean)
[2025-03-07 13:53:43,314] [INFO] [30158] Received PREPARE: id:1741323218379, from:30090, delay:0.0000s, distance:99.03m (Euclidean)
[2025-03-07 13:53:43,328] [INFO] [30158] Received COMMIT: id:1741323218379, from:30090, delay:0.0000s, distance:99.03m (Euclidean)
[2025-03-07 13:53:43,549] [INFO] [30158] Received PREPARE: id:1741323218379, from:30055, delay:0.0000s, distance:131.93m (Euclidean)
[2025-03-07 13:53:43,580] [INFO] [30158] Received COMMIT: id:1741323218379, from:30055, delay:0.0000s, distance:131.93m (Euclidean)
[2025-03-07 13:53:43,628] [INFO] [30158] Received PREPARE: id:1741323218379, from:30053, delay:0.0001s, distance:216.80m (Euclidean)
[2025-03-07 13:53:43,648] [INFO] [30158] Received COMMIT: id:1741323218379, from:30053, delay:0.0001s, distance:216.80m (Euclidean)
[2025-03-07 13:53:43,738] [INFO] [30158] Received COMMIT: id:1741323218379, from:30135, delay:0.0000s, distance:249.49m (Euclidean)
[2025-03-07 13:53:43,738] [INFO] [30158] Received PREPARE: id:1741323218379, from:30097, delay:0.0001s, distance:167.66m (Euclidean)
[2025-03-07 13:53:43,738] [INFO] [30158] Received COMMIT: id:1741323218379, from:30097, delay:0.0001s, distance:167.66m (Euclidean)
[2025-03-07 13:53:43,824] [INFO] [30158] Received PREPARE: id:1741323218379, from:30010, delay:0.0000s, distance:160.99m (Euclidean)
[2025-03-07 13:53:43,944] [INFO] [30158] Received PREPARE: id:1741323218379, from:30034, delay:0.0002s, distance:293.52m (Euclidean)
[2025-03-07 13:53:43,947] [INFO] [30158] Received COMMIT: id:1741323218379, from:30034, delay:0.0002s, distance:293.52m (Euclidean)
[2025-03-07 13:53:44,054] [INFO] [30158] Received PREPARE: id:1741323218379, from:30040, delay:0.0001s, distance:196.61m (Euclidean)
[2025-03-07 13:53:44,054] [INFO] [30158] Received COMMIT: id:1741323218379, from:30040, delay:0.0001s, distance:196.61m (Euclidean)
[2025-03-07 13:53:44,177] [INFO] [30158] Received COMMIT: id:1741323218379, from:30010, delay:0.0000s, distance:160.99m (Euclidean)
[2025-03-07 13:53:44,188] [INFO] [30158] Received PREPARE: id:1741323218379, from:30117, delay:0.0001s, distance:230.62m (Euclidean)
[2025-03-07 13:53:44,188] [INFO] [30158] Received COMMIT: id:1741323218379, from:30117, delay:0.0001s, distance:230.62m (Euclidean)
[2025-03-07 13:53:44,418] [INFO] [30158] Received PREPARE: id:1741323218379, from:30102, delay:0.0002s, distance:269.71m (Euclidean)
[2025-03-07 13:53:44,418] [INFO] [30158] Received PREPARE: id:1741323218379, from:30014, delay:0.0002s, distance:274.37m (Euclidean)
[2025-03-07 13:53:44,434] [INFO] [30158] Received COMMIT: id:1741323218379, from:30014, delay:0.0002s, distance:274.37m (Euclidean)
[2025-03-07 13:53:44,434] [INFO] [30158] Received COMMIT: id:1741323218379, from:30039, delay:0.0001s, distance:237.71m (Euclidean)
[2025-03-07 13:53:44,434] [INFO] [30158] Received COMMIT: id:1741323218379, from:30102, delay:0.0002s, distance:269.71m (Euclidean)
[2025-03-07 13:53:44,434] [INFO] [30158] Received PREPARE: id:1741323218379, from:30039, delay:0.0001s, distance:237.71m (Euclidean)
[2025-03-07 13:53:44,434] [INFO] [30158] Received PREPARE: id:1741323218379, from:30026, delay:0.0000s, distance:134.97m (Euclidean)
[2025-03-07 13:53:44,434] [INFO] [30158] Received COMMIT: id:1741323218379, from:30026, delay:0.0000s, distance:134.97m (Euclidean)
[2025-03-07 13:53:44,592] [INFO] [30158] Received PREPARE: id:1741323218379, from:30041, delay:0.0001s, distance:236.49m (Euclidean)
[2025-03-07 13:53:44,600] [INFO] [30158] Received COMMIT: id:1741323218379, from:30041, delay:0.0001s, distance:236.49m (Euclidean)
[2025-03-07 13:53:44,600] [INFO] [30158] Received PREPARE: id:1741323218379, from:30037, delay:0.0001s, distance:233.13m (Euclidean)
[2025-03-07 13:53:44,600] [INFO] [30158] Received COMMIT: id:1741323218379, from:30037, delay:0.0001s, distance:233.13m (Euclidean)
[2025-03-07 13:53:44,604] [INFO] [30158] Received PREPARE: id:1741323218379, from:30004, delay:0.0002s, distance:268.61m (Euclidean)
[2025-03-07 13:53:44,604] [INFO] [30158] Received COMMIT: id:1741323218379, from:30004, delay:0.0002s, distance:268.61m (Euclidean)
[2025-03-07 13:53:44,703] [INFO] [30158] Received PREPARE: id:1741323218379, from:30087, delay:0.0000s, distance:145.40m (Euclidean)
[2025-03-07 13:53:44,703] [INFO] [30158] Received COMMIT: id:1741323218379, from:30087, delay:0.0000s, distance:145.40m (Euclidean)
[2025-03-07 13:53:44,797] [INFO] [30158] Received PREPARE: id:1741323218379, from:30013, delay:0.0001s, distance:234.99m (Euclidean)
[2025-03-07 13:53:44,801] [INFO] [30158] Received COMMIT: id:1741323218379, from:30013, delay:0.0001s, distance:234.99m (Euclidean)
[2025-03-07 13:53:44,993] [INFO] [30158] Received PREPARE: id:1741323218379, from:30016, delay:0.0001s, distance:203.32m (Euclidean)
[2025-03-07 13:53:44,993] [INFO] [30158] Received COMMIT: id:1741323218379, from:30016, delay:0.0001s, distance:203.32m (Euclidean)
[2025-03-07 13:53:45,003] [INFO] [30158] Received PREPARE: id:1741323218379, from:30006, delay:0.0002s, distance:264.23m (Euclidean)
[2025-03-07 13:53:45,003] [INFO] [30158] Received COMMIT: id:1741323218379, from:30006, delay:0.0002s, distance:264.23m (Euclidean)
[2025-03-07 13:53:45,056] [INFO] [30158] Received PREPARE: id:1741323218379, from:30091, delay:0.0000s, distance:130.39m (Euclidean)
[2025-03-07 13:53:45,130] [INFO] [30158] Received PREPARE: id:1741323218379, from:30094, delay:0.0002s, distance:295.36m (Euclidean)
[2025-03-07 13:53:45,130] [INFO] [30158] Received COMMIT: id:1741323218379, from:30094, delay:0.0002s, distance:295.36m (Euclidean)
[2025-03-07 13:53:45,146] [INFO] [30158] Received COMMIT: id:1741323218379, from:30091, delay:0.0000s, distance:130.39m (Euclidean)
[2025-03-07 13:53:45,225] [INFO] [30158] Received PREPARE: id:1741323218379, from:30083, delay:0.0000s, distance:18.20m (Euclidean)
[2025-03-07 13:53:45,225] [INFO] [30158] Received COMMIT: id:1741323218379, from:30083, delay:0.0000s, distance:18.20m (Euclidean)
[2025-03-07 13:53:45,636] [INFO] [30158] Received PREPARE: id:1741323218379, from:30058, delay:0.0001s, distance:210.08m (Euclidean)
[2025-03-07 13:53:45,636] [INFO] [30158] Received COMMIT: id:1741323218379, from:30058, delay:0.0001s, distance:210.08m (Euclidean)
[2025-03-07 13:53:45,636] [INFO] [30158] Received PREPARE: id:1741323218379, from:30001, delay:0.0001s, distance:198.20m (Euclidean)
[2025-03-07 13:53:45,636] [INFO] [30158] Received COMMIT: id:1741323218379, from:30001, delay:0.0001s, distance:198.20m (Euclidean)
[2025-03-07 13:53:45,826] [INFO] [30158] Received PREPARE: id:1741323218379, from:30089, delay:0.0001s, distance:243.94m (Euclidean)
[2025-03-07 13:53:45,846] [INFO] [30158] Received COMMIT: id:1741323218379, from:30089, delay:0.0001s, distance:243.94m (Euclidean)
[2025-03-07 13:53:45,873] [INFO] [30158] Received PREPARE: id:1741323218379, from:30031, delay:0.0002s, distance:298.56m (Euclidean)
[2025-03-07 13:53:45,873] [INFO] [30158] Received COMMIT: id:1741323218379, from:30031, delay:0.0002s, distance:298.56m (Euclidean)
[2025-03-07 13:53:46,063] [INFO] [30158] Received PREPARE: id:1741323218379, from:30043, delay:0.0002s, distance:290.29m (Euclidean)
[2025-03-07 13:53:46,063] [INFO] [30158] Received COMMIT: id:1741323218379, from:30043, delay:0.0002s, distance:290.29m (Euclidean)
[2025-03-07 13:53:46,063] [INFO] [30158] Received PREPARE: id:1741323218379, from:30104, delay:0.0001s, distance:165.43m (Euclidean)
[2025-03-07 13:53:46,063] [INFO] [30158] Received COMMIT: id:1741323218379, from:30104, delay:0.0001s, distance:165.43m (Euclidean)
[2025-03-07 13:53:46,142] [INFO] [30158] Received PREPARE: id:1741323218379, from:30024, delay:0.0001s, distance:244.70m (Euclidean)
[2025-03-07 13:53:46,143] [INFO] [30158] Received COMMIT: id:1741323218379, from:30024, delay:0.0001s, distance:244.70m (Euclidean)
[2025-03-07 13:53:46,143] [INFO] [30158] Received PREPARE: id:1741323218379, from:30017, delay:0.0001s, distance:201.22m (Euclidean)
[2025-03-07 13:53:46,143] [INFO] [30158] Received COMMIT: id:1741323218379, from:30017, delay:0.0001s, distance:201.22m (Euclidean)
[2025-03-07 13:53:46,174] [INFO] [30158] Received PREPARE: id:1741323218379, from:30072, delay:0.0002s, distance:297.20m (Euclidean)
[2025-03-07 13:53:46,174] [INFO] [30158] Received COMMIT: id:1741323218379, from:30072, delay:0.0002s, distance:297.20m (Euclidean)
[2025-03-07 13:53:46,301] [INFO] [30158] Received PREPARE: id:1741323218379, from:30099, delay:0.0001s, distance:235.49m (Euclidean)
[2025-03-07 13:53:46,301] [INFO] [30158] Received COMMIT: id:1741323218379, from:30099, delay:0.0001s, distance:235.49m (Euclidean)
[2025-03-07 13:53:46,507] [INFO] [30158] Received COMMIT: id:1741323218379, from:30070, delay:0.0000s, distance:113.78m (Euclidean)
[2025-03-07 13:53:46,507] [INFO] [30158] Received PREPARE: id:1741323218379, from:30070, delay:0.0000s, distance:113.78m (Euclidean)
[2025-03-07 13:53:46,554] [INFO] [30158] Received PREPARE: id:1741323218379, from:30095, delay:0.0001s, distance:168.28m (Euclidean)
[2025-03-07 13:53:46,554] [INFO] [30158] Received COMMIT: id:1741323218379, from:30095, delay:0.0001s, distance:168.28m (Euclidean)
[2025-03-07 13:53:46,574] [INFO] [30158] Received PREPARE: id:1741323218379, from:30035, delay:0.0001s, distance:165.96m (Euclidean)
[2025-03-07 13:53:46,574] [INFO] [30158] Received COMMIT: id:1741323218379, from:30035, delay:0.0001s, distance:165.96m (Euclidean)
[2025-03-07 13:53:46,633] [INFO] [30158] Received PREPARE: id:1741323218379, from:30036, delay:0.0002s, distance:295.05m (Euclidean)
[2025-03-07 13:53:46,649] [INFO] [30158] Received COMMIT: id:1741323218379, from:30036, delay:0.0002s, distance:295.05m (Euclidean)
[2025-03-07 13:53:46,776] [INFO] [30158] Received PREPARE: id:1741323218379, from:30110, delay:0.0000s, distance:41.79m (Euclidean)
[2025-03-07 13:53:46,776] [INFO] [30158] Received COMMIT: id:1741323218379, from:30110, delay:0.0000s, distance:41.79m (Euclidean)
[2025-03-07 13:53:46,854] [INFO] [30158] Received PREPARE: id:1741323218379, from:30032, delay:0.0000s, distance:147.58m (Euclidean)
[2025-03-07 13:53:46,854] [INFO] [30158] Received COMMIT: id:1741323218379, from:30032, delay:0.0000s, distance:147.58m (Euclidean)
[2025-03-07 13:53:46,902] [INFO] [30158] Received PREPARE: id:1741323218379, from:30003, delay:0.0000s, distance:141.21m (Euclidean)
[2025-03-07 13:53:46,902] [INFO] [30158] Received COMMIT: id:1741323218379, from:30003, delay:0.0000s, distance:141.21m (Euclidean)
[2025-03-07 13:53:47,013] [INFO] [30158] Received PREPARE: id:1741323218379, from:30134, delay:0.0000s, distance:76.01m (Euclidean)
[2025-03-07 13:53:47,028] [INFO] [30158] Received PREPARE: id:1741323218379, from:30131, delay:0.0000s, distance:200.68m (Euclidean)
[2025-03-07 13:53:47,424] [ERROR] [30158] Error sending to http://localhost:30100/prepare: Cannot connect to host localhost:30100 ssl:default [Connect call failed ('127.0.0.1', 30100)]
Traceback (most recent call last):
  File "D:\anaconda\envs\PBFT\lib\site-packages\aiohttp\connector.py", line 980, in _wrap_create_connection
    return await self._loop.create_connection(*args, **kwargs)  # type: ignore[return-value]  # noqa
  File "D:\anaconda\envs\PBFT\lib\asyncio\base_events.py", line 948, in create_connection
    raise exceptions[0]
  File "D:\anaconda\envs\PBFT\lib\asyncio\base_events.py", line 935, in create_connection
    await self.sock_connect(sock, address)
  File "D:\anaconda\envs\PBFT\lib\asyncio\selector_events.py", line 475, in sock_connect
    return await fut
  File "D:\anaconda\envs\PBFT\lib\asyncio\selector_events.py", line 505, in _sock_connect_cb
    raise OSError(err, f'Connect call failed {address}')
ConnectionRefusedError: [Errno 10061] Connect call failed ('127.0.0.1', 30100)

The above exception was the direct cause of the following exception:

Traceback (most recent call last):
  File "pbft.py", line 236, in send_message
    await send_with_delay(self.session, self.node_info, target, url, data, self.bandwidth_data)
  File "pbft.py", line 63, in send_with_delay
    async with session.post(url, json=data) as resp:
  File "D:\anaconda\envs\PBFT\lib\site-packages\aiohttp\client.py", line 1141, in __aenter__
    self._resp = await self._coro
  File "D:\anaconda\envs\PBFT\lib\site-packages\aiohttp\client.py", line 537, in _request
    req, traces=traces, timeout=real_timeout
  File "D:\anaconda\envs\PBFT\lib\site-packages\aiohttp\connector.py", line 540, in connect
    proto = await self._create_connection(req, traces, timeout)
  File "D:\anaconda\envs\PBFT\lib\site-packages\aiohttp\connector.py", line 901, in _create_connection
    _, proto = await self._create_direct_connection(req, traces, timeout)
  File "D:\anaconda\envs\PBFT\lib\site-packages\aiohttp\connector.py", line 1206, in _create_direct_connection
    raise last_exc
  File "D:\anaconda\envs\PBFT\lib\site-packages\aiohttp\connector.py", line 1187, in _create_direct_connection
    client_error=client_error,
  File "D:\anaconda\envs\PBFT\lib\site-packages\aiohttp\connector.py", line 988, in _wrap_create_connection
    raise client_error(req.connection_key, exc) from exc
aiohttp.client_exceptions.ClientConnectorError: Cannot connect to host localhost:30100 ssl:default [Connect call failed ('127.0.0.1', 30100)]
[2025-03-07 13:53:47,615] [INFO] [30158] Received PREPARE: id:1741323218379, from:30136, delay:0.0001s, distance:239.14m (Euclidean)
[2025-03-07 13:53:47,615] [INFO] [30158] Received COMMIT: id:1741323218379, from:30136, delay:0.0001s, distance:239.14m (Euclidean)
[2025-03-07 13:53:47,655] [INFO] [30158] Received COMMIT: id:1741323218379, from:30134, delay:0.0000s, distance:76.01m (Euclidean)
[2025-03-07 13:53:47,724] [INFO] [30158] Received PREPARE: id:1741323218379, from:30105, delay:0.0001s, distance:213.58m (Euclidean)
[2025-03-07 13:53:47,743] [INFO] [30158] Received COMMIT: id:1741323218379, from:30105, delay:0.0001s, distance:213.58m (Euclidean)
[2025-03-07 13:53:47,866] [INFO] [30158] Received PREPARE: id:1741323218379, from:30122, delay:0.0002s, distance:292.90m (Euclidean)
[2025-03-07 13:53:47,866] [INFO] [30158] Received COMMIT: id:1741323218379, from:30122, delay:0.0002s, distance:292.90m (Euclidean)
[2025-03-07 13:53:47,918] [INFO] [30158] Received PREPARE: id:1741323218379, from:30154, delay:0.0000s, distance:114.61m (Euclidean)
[2025-03-07 13:53:47,929] [INFO] [30158] Received COMMIT: id:1741323218379, from:30154, delay:0.0000s, distance:114.61m (Euclidean)
[2025-03-07 13:53:48,166] [INFO] [30158] Received PREPARE: id:1741323218379, from:30157, delay:0.0000s, distance:73.89m (Euclidean)
[2025-03-07 13:53:48,169] [INFO] [30158] Received COMMIT: id:1741323218379, from:30157, delay:0.0000s, distance:73.89m (Euclidean)
[2025-03-07 13:53:48,182] [INFO] [30158] Received PREPARE: id:1741323218379, from:30139, delay:0.0001s, distance:242.81m (Euclidean)
[2025-03-07 13:53:48,198] [INFO] [30158] Received COMMIT: id:1741323218379, from:30139, delay:0.0001s, distance:242.81m (Euclidean)
[2025-03-07 13:53:48,356] [INFO] [30158] Received COMMIT: id:1741323218379, from:30131, delay:0.0000s, distance:200.68m (Euclidean)
[2025-03-07 13:53:48,396] [INFO] [30158] Received PREPARE: id:1741323218379, from:30153, delay:0.0000s, distance:140.47m (Euclidean)
[2025-03-07 13:53:48,396] [INFO] [30158] Received COMMIT: id:1741323218379, from:30153, delay:0.0000s, distance:140.47m (Euclidean)
[2025-03-07 13:53:48,455] [INFO] [30158] Received PREPARE: id:1741323218379, from:30147, delay:0.0000s, distance:105.54m (Euclidean)
[2025-03-07 13:53:48,455] [INFO] [30158] Received PREPARE: id:1741323218379, from:30128, delay:0.0000s, distance:96.14m (Euclidean)
[2025-03-07 13:53:48,462] [INFO] [30158] Received COMMIT: id:1741323218379, from:30147, delay:0.0000s, distance:105.54m (Euclidean)
[2025-03-07 13:53:48,462] [INFO] [30158] Received PREPARE: id:1741323218379, from:30133, delay:0.0000s, distance:150.23m (Euclidean)
[2025-03-07 13:53:48,462] [INFO] [30158] Received COMMIT: id:1741323218379, from:30128, delay:0.0000s, distance:96.14m (Euclidean)
[2025-03-07 13:53:48,572] [ERROR] [30158] Error sending to http://localhost:30100/commit: Cannot connect to host localhost:30100 ssl:default [Connect call failed ('::1', 30100, 0, 0)]
Traceback (most recent call last):
  File "D:\anaconda\envs\PBFT\lib\site-packages\aiohttp\connector.py", line 980, in _wrap_create_connection
    return await self._loop.create_connection(*args, **kwargs)  # type: ignore[return-value]  # noqa
  File "D:\anaconda\envs\PBFT\lib\asyncio\base_events.py", line 948, in create_connection
    raise exceptions[0]
  File "D:\anaconda\envs\PBFT\lib\asyncio\base_events.py", line 935, in create_connection
    await self.sock_connect(sock, address)
  File "D:\anaconda\envs\PBFT\lib\asyncio\selector_events.py", line 475, in sock_connect
    return await fut
  File "D:\anaconda\envs\PBFT\lib\asyncio\selector_events.py", line 505, in _sock_connect_cb
    raise OSError(err, f'Connect call failed {address}')
ConnectionRefusedError: [Errno 10061] Connect call failed ('::1', 30100, 0, 0)

The above exception was the direct cause of the following exception:

Traceback (most recent call last):
  File "pbft.py", line 236, in send_message
    await send_with_delay(self.session, self.node_info, target, url, data, self.bandwidth_data)
  File "pbft.py", line 63, in send_with_delay
    async with session.post(url, json=data) as resp:
  File "D:\anaconda\envs\PBFT\lib\site-packages\aiohttp\client.py", line 1141, in __aenter__
    self._resp = await self._coro
  File "D:\anaconda\envs\PBFT\lib\site-packages\aiohttp\client.py", line 537, in _request
    req, traces=traces, timeout=real_timeout
  File "D:\anaconda\envs\PBFT\lib\site-packages\aiohttp\connector.py", line 540, in connect
    proto = await self._create_connection(req, traces, timeout)
  File "D:\anaconda\envs\PBFT\lib\site-packages\aiohttp\connector.py", line 901, in _create_connection
    _, proto = await self._create_direct_connection(req, traces, timeout)
  File "D:\anaconda\envs\PBFT\lib\site-packages\aiohttp\connector.py", line 1206, in _create_direct_connection
    raise last_exc
  File "D:\anaconda\envs\PBFT\lib\site-packages\aiohttp\connector.py", line 1187, in _create_direct_connection
    client_error=client_error,
  File "D:\anaconda\envs\PBFT\lib\site-packages\aiohttp\connector.py", line 988, in _wrap_create_connection
    raise client_error(req.connection_key, exc) from exc
aiohttp.client_exceptions.ClientConnectorError: Cannot connect to host localhost:30100 ssl:default [Connect call failed ('::1', 30100, 0, 0)]
[2025-03-07 13:53:48,877] [INFO] [30158] Received COMMIT: id:1741323218379, from:30133, delay:0.0000s, distance:150.23m (Euclidean)
[2025-03-07 13:53:48,893] [INFO] [30158] Received PREPARE: id:1741323218379, from:30109, delay:0.0001s, distance:244.07m (Euclidean)
[2025-03-07 13:53:48,893] [INFO] [30158] Received COMMIT: id:1741323218379, from:30109, delay:0.0001s, distance:244.07m (Euclidean)
[2025-03-07 13:53:48,909] [INFO] [30158] Received PREPARE: id:1741323218379, from:30144, delay:0.0000s, distance:60.91m (Euclidean)
[2025-03-07 13:53:49,110] [INFO] [30158] Received PREPARE: id:1741323218379, from:30107, delay:0.0001s, distance:239.45m (Euclidean)
[2025-03-07 13:53:49,110] [INFO] [30158] Received COMMIT: id:1741323218379, from:30107, delay:0.0001s, distance:239.45m (Euclidean)
[2025-03-07 13:53:49,134] [INFO] [30158] Received PREPARE: id:1741323218379, from:30112, delay:0.0000s, distance:98.23m (Euclidean)
[2025-03-07 13:53:49,154] [INFO] [30158] Received COMMIT: id:1741323218379, from:30112, delay:0.0000s, distance:98.23m (Euclidean)
[2025-03-07 13:53:49,193] [ERROR] [30158] Error sending to http://localhost:30076/prepare: Cannot connect to host localhost:30076 ssl:default [Connect call failed ('127.0.0.1', 30076)]
Traceback (most recent call last):
  File "D:\anaconda\envs\PBFT\lib\site-packages\aiohttp\connector.py", line 980, in _wrap_create_connection
    return await self._loop.create_connection(*args, **kwargs)  # type: ignore[return-value]  # noqa
  File "D:\anaconda\envs\PBFT\lib\asyncio\base_events.py", line 948, in create_connection
    raise exceptions[0]
  File "D:\anaconda\envs\PBFT\lib\asyncio\base_events.py", line 935, in create_connection
    await self.sock_connect(sock, address)
  File "D:\anaconda\envs\PBFT\lib\asyncio\selector_events.py", line 475, in sock_connect
    return await fut
  File "D:\anaconda\envs\PBFT\lib\asyncio\selector_events.py", line 505, in _sock_connect_cb
    raise OSError(err, f'Connect call failed {address}')
ConnectionRefusedError: [Errno 10061] Connect call failed ('127.0.0.1', 30076)

The above exception was the direct cause of the following exception:

Traceback (most recent call last):
  File "pbft.py", line 236, in send_message
    await send_with_delay(self.session, self.node_info, target, url, data, self.bandwidth_data)
  File "pbft.py", line 63, in send_with_delay
    async with session.post(url, json=data) as resp:
  File "D:\anaconda\envs\PBFT\lib\site-packages\aiohttp\client.py", line 1141, in __aenter__
    self._resp = await self._coro
  File "D:\anaconda\envs\PBFT\lib\site-packages\aiohttp\client.py", line 537, in _request
    req, traces=traces, timeout=real_timeout
  File "D:\anaconda\envs\PBFT\lib\site-packages\aiohttp\connector.py", line 540, in connect
    proto = await self._create_connection(req, traces, timeout)
  File "D:\anaconda\envs\PBFT\lib\site-packages\aiohttp\connector.py", line 901, in _create_connection
    _, proto = await self._create_direct_connection(req, traces, timeout)
  File "D:\anaconda\envs\PBFT\lib\site-packages\aiohttp\connector.py", line 1206, in _create_direct_connection
    raise last_exc
  File "D:\anaconda\envs\PBFT\lib\site-packages\aiohttp\connector.py", line 1187, in _create_direct_connection
    client_error=client_error,
  File "D:\anaconda\envs\PBFT\lib\site-packages\aiohttp\connector.py", line 988, in _wrap_create_connection
    raise client_error(req.connection_key, exc) from exc
aiohttp.client_exceptions.ClientConnectorError: Cannot connect to host localhost:30076 ssl:default [Connect call failed ('127.0.0.1', 30076)]
[2025-03-07 13:53:49,352] [INFO] [30158] Received PREPARE: id:1741323218379, from:30151, delay:0.0002s, distance:278.35m (Euclidean)
[2025-03-07 13:53:49,373] [INFO] [30158] Received COMMIT: id:1741323218379, from:30151, delay:0.0002s, distance:278.35m (Euclidean)
[2025-03-07 13:53:49,504] [INFO] [30158] Received COMMIT: id:1741323218379, from:30144, delay:0.0000s, distance:60.91m (Euclidean)
[2025-03-07 13:53:49,900] [INFO] [30158] Received PREPARE: id:1741323218379, from:30148, delay:0.0002s, distance:262.55m (Euclidean)
[2025-03-07 13:53:49,900] [INFO] [30158] Received COMMIT: id:1741323218379, from:30148, delay:0.0002s, distance:262.55m (Euclidean)
[2025-03-07 13:53:49,969] [ERROR] [30158] Error sending to http://localhost:30075/prepare: Cannot connect to host localhost:30075 ssl:default [Connect call failed ('127.0.0.1', 30075)]
Traceback (most recent call last):
  File "D:\anaconda\envs\PBFT\lib\site-packages\aiohttp\connector.py", line 980, in _wrap_create_connection
    return await self._loop.create_connection(*args, **kwargs)  # type: ignore[return-value]  # noqa
  File "D:\anaconda\envs\PBFT\lib\asyncio\base_events.py", line 948, in create_connection
    raise exceptions[0]
  File "D:\anaconda\envs\PBFT\lib\asyncio\base_events.py", line 935, in create_connection
    await self.sock_connect(sock, address)
  File "D:\anaconda\envs\PBFT\lib\asyncio\selector_events.py", line 475, in sock_connect
    return await fut
  File "D:\anaconda\envs\PBFT\lib\asyncio\selector_events.py", line 505, in _sock_connect_cb
    raise OSError(err, f'Connect call failed {address}')
ConnectionRefusedError: [Errno 10061] Connect call failed ('127.0.0.1', 30075)

The above exception was the direct cause of the following exception:

Traceback (most recent call last):
  File "pbft.py", line 236, in send_message
    await send_with_delay(self.session, self.node_info, target, url, data, self.bandwidth_data)
  File "pbft.py", line 63, in send_with_delay
    async with session.post(url, json=data) as resp:
  File "D:\anaconda\envs\PBFT\lib\site-packages\aiohttp\client.py", line 1141, in __aenter__
    self._resp = await self._coro
  File "D:\anaconda\envs\PBFT\lib\site-packages\aiohttp\client.py", line 537, in _request
    req, traces=traces, timeout=real_timeout
  File "D:\anaconda\envs\PBFT\lib\site-packages\aiohttp\connector.py", line 540, in connect
    proto = await self._create_connection(req, traces, timeout)
  File "D:\anaconda\envs\PBFT\lib\site-packages\aiohttp\connector.py", line 901, in _create_connection
    _, proto = await self._create_direct_connection(req, traces, timeout)
  File "D:\anaconda\envs\PBFT\lib\site-packages\aiohttp\connector.py", line 1206, in _create_direct_connection
    raise last_exc
  File "D:\anaconda\envs\PBFT\lib\site-packages\aiohttp\connector.py", line 1187, in _create_direct_connection
    client_error=client_error,
  File "D:\anaconda\envs\PBFT\lib\site-packages\aiohttp\connector.py", line 988, in _wrap_create_connection
    raise client_error(req.connection_key, exc) from exc
aiohttp.client_exceptions.ClientConnectorError: Cannot connect to host localhost:30075 ssl:default [Connect call failed ('127.0.0.1', 30075)]
[2025-03-07 13:53:50,070] [ERROR] [30158] Error sending to http://localhost:30071/prepare: Cannot connect to host localhost:30071 ssl:default [Connect call failed ('127.0.0.1', 30071)]
Traceback (most recent call last):
  File "D:\anaconda\envs\PBFT\lib\site-packages\aiohttp\connector.py", line 980, in _wrap_create_connection
    return await self._loop.create_connection(*args, **kwargs)  # type: ignore[return-value]  # noqa
  File "D:\anaconda\envs\PBFT\lib\asyncio\base_events.py", line 948, in create_connection
    raise exceptions[0]
  File "D:\anaconda\envs\PBFT\lib\asyncio\base_events.py", line 935, in create_connection
    await self.sock_connect(sock, address)
  File "D:\anaconda\envs\PBFT\lib\asyncio\selector_events.py", line 475, in sock_connect
    return await fut
  File "D:\anaconda\envs\PBFT\lib\asyncio\selector_events.py", line 505, in _sock_connect_cb
    raise OSError(err, f'Connect call failed {address}')
ConnectionRefusedError: [Errno 10061] Connect call failed ('127.0.0.1', 30071)

The above exception was the direct cause of the following exception:

Traceback (most recent call last):
  File "pbft.py", line 236, in send_message
    await send_with_delay(self.session, self.node_info, target, url, data, self.bandwidth_data)
  File "pbft.py", line 63, in send_with_delay
    async with session.post(url, json=data) as resp:
  File "D:\anaconda\envs\PBFT\lib\site-packages\aiohttp\client.py", line 1141, in __aenter__
    self._resp = await self._coro
  File "D:\anaconda\envs\PBFT\lib\site-packages\aiohttp\client.py", line 537, in _request
    req, traces=traces, timeout=real_timeout
  File "D:\anaconda\envs\PBFT\lib\site-packages\aiohttp\connector.py", line 540, in connect
    proto = await self._create_connection(req, traces, timeout)
  File "D:\anaconda\envs\PBFT\lib\site-packages\aiohttp\connector.py", line 901, in _create_connection
    _, proto = await self._create_direct_connection(req, traces, timeout)
  File "D:\anaconda\envs\PBFT\lib\site-packages\aiohttp\connector.py", line 1206, in _create_direct_connection
    raise last_exc
  File "D:\anaconda\envs\PBFT\lib\site-packages\aiohttp\connector.py", line 1187, in _create_direct_connection
    client_error=client_error,
  File "D:\anaconda\envs\PBFT\lib\site-packages\aiohttp\connector.py", line 988, in _wrap_create_connection
    raise client_error(req.connection_key, exc) from exc
aiohttp.client_exceptions.ClientConnectorError: Cannot connect to host localhost:30071 ssl:default [Connect call failed ('127.0.0.1', 30071)]
[2025-03-07 13:53:50,116] [INFO] [30158] Received COMMIT: id:1741323218379, from:30000, delay:0.0000s, distance:197.70m (Euclidean)
[2025-03-07 13:53:50,269] [INFO] [30158] Received PREPARE: id:1741323218379, from:30130, delay:0.0000s, distance:67.37m (Euclidean)
[2025-03-07 13:53:50,269] [INFO] [30158] Received COMMIT: id:1741323218379, from:30130, delay:0.0000s, distance:67.37m (Euclidean)
[2025-03-07 13:53:50,489] [INFO] [30158] Received PREPARE: id:1741323218379, from:30015, delay:0.0001s, distance:169.09m (Euclidean)
[2025-03-07 13:53:50,489] [INFO] [30158] Received COMMIT: id:1741323218379, from:30015, delay:0.0001s, distance:169.09m (Euclidean)
[2025-03-07 13:53:50,523] [ERROR] [30158] Error sending to http://localhost:30029/prepare: Cannot connect to host localhost:30029 ssl:default [Connect call failed ('127.0.0.1', 30029)]
Traceback (most recent call last):
  File "D:\anaconda\envs\PBFT\lib\site-packages\aiohttp\connector.py", line 980, in _wrap_create_connection
    return await self._loop.create_connection(*args, **kwargs)  # type: ignore[return-value]  # noqa
  File "D:\anaconda\envs\PBFT\lib\asyncio\base_events.py", line 948, in create_connection
    raise exceptions[0]
  File "D:\anaconda\envs\PBFT\lib\asyncio\base_events.py", line 935, in create_connection
    await self.sock_connect(sock, address)
  File "D:\anaconda\envs\PBFT\lib\asyncio\selector_events.py", line 475, in sock_connect
    return await fut
  File "D:\anaconda\envs\PBFT\lib\asyncio\selector_events.py", line 505, in _sock_connect_cb
    raise OSError(err, f'Connect call failed {address}')
ConnectionRefusedError: [Errno 10061] Connect call failed ('127.0.0.1', 30029)

The above exception was the direct cause of the following exception:

Traceback (most recent call last):
  File "pbft.py", line 236, in send_message
    await send_with_delay(self.session, self.node_info, target, url, data, self.bandwidth_data)
  File "pbft.py", line 63, in send_with_delay
    async with session.post(url, json=data) as resp:
  File "D:\anaconda\envs\PBFT\lib\site-packages\aiohttp\client.py", line 1141, in __aenter__
    self._resp = await self._coro
  File "D:\anaconda\envs\PBFT\lib\site-packages\aiohttp\client.py", line 537, in _request
    req, traces=traces, timeout=real_timeout
  File "D:\anaconda\envs\PBFT\lib\site-packages\aiohttp\connector.py", line 540, in connect
    proto = await self._create_connection(req, traces, timeout)
  File "D:\anaconda\envs\PBFT\lib\site-packages\aiohttp\connector.py", line 901, in _create_connection
    _, proto = await self._create_direct_connection(req, traces, timeout)
  File "D:\anaconda\envs\PBFT\lib\site-packages\aiohttp\connector.py", line 1206, in _create_direct_connection
    raise last_exc
  File "D:\anaconda\envs\PBFT\lib\site-packages\aiohttp\connector.py", line 1187, in _create_direct_connection
    client_error=client_error,
  File "D:\anaconda\envs\PBFT\lib\site-packages\aiohttp\connector.py", line 988, in _wrap_create_connection
    raise client_error(req.connection_key, exc) from exc
aiohttp.client_exceptions.ClientConnectorError: Cannot connect to host localhost:30029 ssl:default [Connect call failed ('127.0.0.1', 30029)]
[2025-03-07 13:53:50,602] [ERROR] [30158] Error sending to http://localhost:30093/prepare: Cannot connect to host localhost:30093 ssl:default [Connect call failed ('127.0.0.1', 30093)]
Traceback (most recent call last):
  File "D:\anaconda\envs\PBFT\lib\site-packages\aiohttp\connector.py", line 980, in _wrap_create_connection
    return await self._loop.create_connection(*args, **kwargs)  # type: ignore[return-value]  # noqa
  File "D:\anaconda\envs\PBFT\lib\asyncio\base_events.py", line 948, in create_connection
    raise exceptions[0]
  File "D:\anaconda\envs\PBFT\lib\asyncio\base_events.py", line 935, in create_connection
    await self.sock_connect(sock, address)
  File "D:\anaconda\envs\PBFT\lib\asyncio\selector_events.py", line 475, in sock_connect
    return await fut
  File "D:\anaconda\envs\PBFT\lib\asyncio\selector_events.py", line 505, in _sock_connect_cb
    raise OSError(err, f'Connect call failed {address}')
ConnectionRefusedError: [Errno 10061] Connect call failed ('127.0.0.1', 30093)

The above exception was the direct cause of the following exception:

Traceback (most recent call last):
  File "pbft.py", line 236, in send_message
    await send_with_delay(self.session, self.node_info, target, url, data, self.bandwidth_data)
  File "pbft.py", line 63, in send_with_delay
    async with session.post(url, json=data) as resp:
  File "D:\anaconda\envs\PBFT\lib\site-packages\aiohttp\client.py", line 1141, in __aenter__
    self._resp = await self._coro
  File "D:\anaconda\envs\PBFT\lib\site-packages\aiohttp\client.py", line 537, in _request
    req, traces=traces, timeout=real_timeout
  File "D:\anaconda\envs\PBFT\lib\site-packages\aiohttp\connector.py", line 540, in connect
    proto = await self._create_connection(req, traces, timeout)
  File "D:\anaconda\envs\PBFT\lib\site-packages\aiohttp\connector.py", line 901, in _create_connection
    _, proto = await self._create_direct_connection(req, traces, timeout)
  File "D:\anaconda\envs\PBFT\lib\site-packages\aiohttp\connector.py", line 1206, in _create_direct_connection
    raise last_exc
  File "D:\anaconda\envs\PBFT\lib\site-packages\aiohttp\connector.py", line 1187, in _create_direct_connection
    client_error=client_error,
  File "D:\anaconda\envs\PBFT\lib\site-packages\aiohttp\connector.py", line 988, in _wrap_create_connection
    raise client_error(req.connection_key, exc) from exc
aiohttp.client_exceptions.ClientConnectorError: Cannot connect to host localhost:30093 ssl:default [Connect call failed ('127.0.0.1', 30093)]
[2025-03-07 13:53:50,665] [ERROR] [30158] Error sending to http://localhost:30085/prepare: Cannot connect to host localhost:30085 ssl:default [Connect call failed ('127.0.0.1', 30085)]
Traceback (most recent call last):
  File "D:\anaconda\envs\PBFT\lib\site-packages\aiohttp\connector.py", line 980, in _wrap_create_connection
    return await self._loop.create_connection(*args, **kwargs)  # type: ignore[return-value]  # noqa
  File "D:\anaconda\envs\PBFT\lib\asyncio\base_events.py", line 948, in create_connection
    raise exceptions[0]
  File "D:\anaconda\envs\PBFT\lib\asyncio\base_events.py", line 935, in create_connection
    await self.sock_connect(sock, address)
  File "D:\anaconda\envs\PBFT\lib\asyncio\selector_events.py", line 475, in sock_connect
    return await fut
  File "D:\anaconda\envs\PBFT\lib\asyncio\selector_events.py", line 505, in _sock_connect_cb
    raise OSError(err, f'Connect call failed {address}')
ConnectionRefusedError: [Errno 10061] Connect call failed ('127.0.0.1', 30085)

The above exception was the direct cause of the following exception:

Traceback (most recent call last):
  File "pbft.py", line 236, in send_message
    await send_with_delay(self.session, self.node_info, target, url, data, self.bandwidth_data)
  File "pbft.py", line 63, in send_with_delay
    async with session.post(url, json=data) as resp:
  File "D:\anaconda\envs\PBFT\lib\site-packages\aiohttp\client.py", line 1141, in __aenter__
    self._resp = await self._coro
  File "D:\anaconda\envs\PBFT\lib\site-packages\aiohttp\client.py", line 537, in _request
    req, traces=traces, timeout=real_timeout
  File "D:\anaconda\envs\PBFT\lib\site-packages\aiohttp\connector.py", line 540, in connect
    proto = await self._create_connection(req, traces, timeout)
  File "D:\anaconda\envs\PBFT\lib\site-packages\aiohttp\connector.py", line 901, in _create_connection
    _, proto = await self._create_direct_connection(req, traces, timeout)
  File "D:\anaconda\envs\PBFT\lib\site-packages\aiohttp\connector.py", line 1206, in _create_direct_connection
    raise last_exc
  File "D:\anaconda\envs\PBFT\lib\site-packages\aiohttp\connector.py", line 1187, in _create_direct_connection
    client_error=client_error,
  File "D:\anaconda\envs\PBFT\lib\site-packages\aiohttp\connector.py", line 988, in _wrap_create_connection
    raise client_error(req.connection_key, exc) from exc
aiohttp.client_exceptions.ClientConnectorError: Cannot connect to host localhost:30085 ssl:default [Connect call failed ('127.0.0.1', 30085)]
[2025-03-07 13:53:50,712] [ERROR] [30158] Error sending to http://localhost:30023/commit: Cannot connect to host localhost:30023 ssl:default [Connect call failed ('::1', 30023, 0, 0)]
Traceback (most recent call last):
  File "D:\anaconda\envs\PBFT\lib\site-packages\aiohttp\connector.py", line 980, in _wrap_create_connection
    return await self._loop.create_connection(*args, **kwargs)  # type: ignore[return-value]  # noqa
  File "D:\anaconda\envs\PBFT\lib\asyncio\base_events.py", line 948, in create_connection
    raise exceptions[0]
  File "D:\anaconda\envs\PBFT\lib\asyncio\base_events.py", line 935, in create_connection
    await self.sock_connect(sock, address)
  File "D:\anaconda\envs\PBFT\lib\asyncio\selector_events.py", line 475, in sock_connect
    return await fut
  File "D:\anaconda\envs\PBFT\lib\asyncio\selector_events.py", line 505, in _sock_connect_cb
    raise OSError(err, f'Connect call failed {address}')
ConnectionRefusedError: [Errno 10061] Connect call failed ('::1', 30023, 0, 0)

The above exception was the direct cause of the following exception:

Traceback (most recent call last):
  File "pbft.py", line 236, in send_message
    await send_with_delay(self.session, self.node_info, target, url, data, self.bandwidth_data)
  File "pbft.py", line 63, in send_with_delay
    async with session.post(url, json=data) as resp:
  File "D:\anaconda\envs\PBFT\lib\site-packages\aiohttp\client.py", line 1141, in __aenter__
    self._resp = await self._coro
  File "D:\anaconda\envs\PBFT\lib\site-packages\aiohttp\client.py", line 537, in _request
    req, traces=traces, timeout=real_timeout
  File "D:\anaconda\envs\PBFT\lib\site-packages\aiohttp\connector.py", line 540, in connect
    proto = await self._create_connection(req, traces, timeout)
  File "D:\anaconda\envs\PBFT\lib\site-packages\aiohttp\connector.py", line 901, in _create_connection
    _, proto = await self._create_direct_connection(req, traces, timeout)
  File "D:\anaconda\envs\PBFT\lib\site-packages\aiohttp\connector.py", line 1206, in _create_direct_connection
    raise last_exc
  File "D:\anaconda\envs\PBFT\lib\site-packages\aiohttp\connector.py", line 1187, in _create_direct_connection
    client_error=client_error,
  File "D:\anaconda\envs\PBFT\lib\site-packages\aiohttp\connector.py", line 988, in _wrap_create_connection
    raise client_error(req.connection_key, exc) from exc
aiohttp.client_exceptions.ClientConnectorError: Cannot connect to host localhost:30023 ssl:default [Connect call failed ('::1', 30023, 0, 0)]
[2025-03-07 13:53:50,714] [ERROR] [30158] Error sending to http://localhost:30023/prepare: Cannot connect to host localhost:30023 ssl:default [Connect call failed ('127.0.0.1', 30023)]
Traceback (most recent call last):
  File "D:\anaconda\envs\PBFT\lib\site-packages\aiohttp\connector.py", line 980, in _wrap_create_connection
    return await self._loop.create_connection(*args, **kwargs)  # type: ignore[return-value]  # noqa
  File "D:\anaconda\envs\PBFT\lib\asyncio\base_events.py", line 948, in create_connection
    raise exceptions[0]
  File "D:\anaconda\envs\PBFT\lib\asyncio\base_events.py", line 935, in create_connection
    await self.sock_connect(sock, address)
  File "D:\anaconda\envs\PBFT\lib\asyncio\selector_events.py", line 475, in sock_connect
    return await fut
  File "D:\anaconda\envs\PBFT\lib\asyncio\selector_events.py", line 505, in _sock_connect_cb
    raise OSError(err, f'Connect call failed {address}')
ConnectionRefusedError: [Errno 10061] Connect call failed ('127.0.0.1', 30023)

The above exception was the direct cause of the following exception:

Traceback (most recent call last):
  File "pbft.py", line 236, in send_message
    await send_with_delay(self.session, self.node_info, target, url, data, self.bandwidth_data)
  File "pbft.py", line 63, in send_with_delay
    async with session.post(url, json=data) as resp:
  File "D:\anaconda\envs\PBFT\lib\site-packages\aiohttp\client.py", line 1141, in __aenter__
    self._resp = await self._coro
  File "D:\anaconda\envs\PBFT\lib\site-packages\aiohttp\client.py", line 537, in _request
    req, traces=traces, timeout=real_timeout
  File "D:\anaconda\envs\PBFT\lib\site-packages\aiohttp\connector.py", line 540, in connect
    proto = await self._create_connection(req, traces, timeout)
  File "D:\anaconda\envs\PBFT\lib\site-packages\aiohttp\connector.py", line 901, in _create_connection
    _, proto = await self._create_direct_connection(req, traces, timeout)
  File "D:\anaconda\envs\PBFT\lib\site-packages\aiohttp\connector.py", line 1206, in _create_direct_connection
    raise last_exc
  File "D:\anaconda\envs\PBFT\lib\site-packages\aiohttp\connector.py", line 1187, in _create_direct_connection
    client_error=client_error,
  File "D:\anaconda\envs\PBFT\lib\site-packages\aiohttp\connector.py", line 988, in _wrap_create_connection
    raise client_error(req.connection_key, exc) from exc
aiohttp.client_exceptions.ClientConnectorError: Cannot connect to host localhost:30023 ssl:default [Connect call failed ('127.0.0.1', 30023)]
[2025-03-07 13:53:50,743] [ERROR] [30158] Error sending to http://localhost:30066/prepare: Cannot connect to host localhost:30066 ssl:default [Connect call failed ('127.0.0.1', 30066)]
Traceback (most recent call last):
  File "D:\anaconda\envs\PBFT\lib\site-packages\aiohttp\connector.py", line 980, in _wrap_create_connection
    return await self._loop.create_connection(*args, **kwargs)  # type: ignore[return-value]  # noqa
  File "D:\anaconda\envs\PBFT\lib\asyncio\base_events.py", line 948, in create_connection
    raise exceptions[0]
  File "D:\anaconda\envs\PBFT\lib\asyncio\base_events.py", line 935, in create_connection
    await self.sock_connect(sock, address)
  File "D:\anaconda\envs\PBFT\lib\asyncio\selector_events.py", line 475, in sock_connect
    return await fut
  File "D:\anaconda\envs\PBFT\lib\asyncio\selector_events.py", line 505, in _sock_connect_cb
    raise OSError(err, f'Connect call failed {address}')
ConnectionRefusedError: [Errno 10061] Connect call failed ('127.0.0.1', 30066)

The above exception was the direct cause of the following exception:

Traceback (most recent call last):
  File "pbft.py", line 236, in send_message
    await send_with_delay(self.session, self.node_info, target, url, data, self.bandwidth_data)
  File "pbft.py", line 63, in send_with_delay
    async with session.post(url, json=data) as resp:
  File "D:\anaconda\envs\PBFT\lib\site-packages\aiohttp\client.py", line 1141, in __aenter__
    self._resp = await self._coro
  File "D:\anaconda\envs\PBFT\lib\site-packages\aiohttp\client.py", line 537, in _request
    req, traces=traces, timeout=real_timeout
  File "D:\anaconda\envs\PBFT\lib\site-packages\aiohttp\connector.py", line 540, in connect
    proto = await self._create_connection(req, traces, timeout)
  File "D:\anaconda\envs\PBFT\lib\site-packages\aiohttp\connector.py", line 901, in _create_connection
    _, proto = await self._create_direct_connection(req, traces, timeout)
  File "D:\anaconda\envs\PBFT\lib\site-packages\aiohttp\connector.py", line 1206, in _create_direct_connection
    raise last_exc
  File "D:\anaconda\envs\PBFT\lib\site-packages\aiohttp\connector.py", line 1187, in _create_direct_connection
    client_error=client_error,
  File "D:\anaconda\envs\PBFT\lib\site-packages\aiohttp\connector.py", line 988, in _wrap_create_connection
    raise client_error(req.connection_key, exc) from exc
aiohttp.client_exceptions.ClientConnectorError: Cannot connect to host localhost:30066 ssl:default [Connect call failed ('127.0.0.1', 30066)]
[2025-03-07 13:53:50,759] [ERROR] [30158] Error sending to http://localhost:30066/commit: Cannot connect to host localhost:30066 ssl:default [Connect call failed ('::1', 30066, 0, 0)]
Traceback (most recent call last):
  File "D:\anaconda\envs\PBFT\lib\site-packages\aiohttp\connector.py", line 980, in _wrap_create_connection
    return await self._loop.create_connection(*args, **kwargs)  # type: ignore[return-value]  # noqa
  File "D:\anaconda\envs\PBFT\lib\asyncio\base_events.py", line 948, in create_connection
    raise exceptions[0]
  File "D:\anaconda\envs\PBFT\lib\asyncio\base_events.py", line 935, in create_connection
    await self.sock_connect(sock, address)
  File "D:\anaconda\envs\PBFT\lib\asyncio\selector_events.py", line 475, in sock_connect
    return await fut
  File "D:\anaconda\envs\PBFT\lib\asyncio\selector_events.py", line 505, in _sock_connect_cb
    raise OSError(err, f'Connect call failed {address}')
ConnectionRefusedError: [Errno 10061] Connect call failed ('::1', 30066, 0, 0)

The above exception was the direct cause of the following exception:

Traceback (most recent call last):
  File "pbft.py", line 236, in send_message
    await send_with_delay(self.session, self.node_info, target, url, data, self.bandwidth_data)
  File "pbft.py", line 63, in send_with_delay
    async with session.post(url, json=data) as resp:
  File "D:\anaconda\envs\PBFT\lib\site-packages\aiohttp\client.py", line 1141, in __aenter__
    self._resp = await self._coro
  File "D:\anaconda\envs\PBFT\lib\site-packages\aiohttp\client.py", line 537, in _request
    req, traces=traces, timeout=real_timeout
  File "D:\anaconda\envs\PBFT\lib\site-packages\aiohttp\connector.py", line 540, in connect
    proto = await self._create_connection(req, traces, timeout)
  File "D:\anaconda\envs\PBFT\lib\site-packages\aiohttp\connector.py", line 901, in _create_connection
    _, proto = await self._create_direct_connection(req, traces, timeout)
  File "D:\anaconda\envs\PBFT\lib\site-packages\aiohttp\connector.py", line 1206, in _create_direct_connection
    raise last_exc
  File "D:\anaconda\envs\PBFT\lib\site-packages\aiohttp\connector.py", line 1187, in _create_direct_connection
    client_error=client_error,
  File "D:\anaconda\envs\PBFT\lib\site-packages\aiohttp\connector.py", line 988, in _wrap_create_connection
    raise client_error(req.connection_key, exc) from exc
aiohttp.client_exceptions.ClientConnectorError: Cannot connect to host localhost:30066 ssl:default [Connect call failed ('::1', 30066, 0, 0)]
[2025-03-07 13:53:50,854] [ERROR] [30158] Error sending to http://localhost:30093/commit: Cannot connect to host localhost:30093 ssl:default [Connect call failed ('::1', 30093, 0, 0)]
Traceback (most recent call last):
  File "D:\anaconda\envs\PBFT\lib\site-packages\aiohttp\connector.py", line 980, in _wrap_create_connection
    return await self._loop.create_connection(*args, **kwargs)  # type: ignore[return-value]  # noqa
  File "D:\anaconda\envs\PBFT\lib\asyncio\base_events.py", line 948, in create_connection
    raise exceptions[0]
  File "D:\anaconda\envs\PBFT\lib\asyncio\base_events.py", line 935, in create_connection
    await self.sock_connect(sock, address)
  File "D:\anaconda\envs\PBFT\lib\asyncio\selector_events.py", line 475, in sock_connect
    return await fut
  File "D:\anaconda\envs\PBFT\lib\asyncio\selector_events.py", line 505, in _sock_connect_cb
    raise OSError(err, f'Connect call failed {address}')
ConnectionRefusedError: [Errno 10061] Connect call failed ('::1', 30093, 0, 0)

The above exception was the direct cause of the following exception:

Traceback (most recent call last):
  File "pbft.py", line 236, in send_message
    await send_with_delay(self.session, self.node_info, target, url, data, self.bandwidth_data)
  File "pbft.py", line 63, in send_with_delay
    async with session.post(url, json=data) as resp:
  File "D:\anaconda\envs\PBFT\lib\site-packages\aiohttp\client.py", line 1141, in __aenter__
    self._resp = await self._coro
  File "D:\anaconda\envs\PBFT\lib\site-packages\aiohttp\client.py", line 537, in _request
    req, traces=traces, timeout=real_timeout
  File "D:\anaconda\envs\PBFT\lib\site-packages\aiohttp\connector.py", line 540, in connect
    proto = await self._create_connection(req, traces, timeout)
  File "D:\anaconda\envs\PBFT\lib\site-packages\aiohttp\connector.py", line 901, in _create_connection
    _, proto = await self._create_direct_connection(req, traces, timeout)
  File "D:\anaconda\envs\PBFT\lib\site-packages\aiohttp\connector.py", line 1206, in _create_direct_connection
    raise last_exc
  File "D:\anaconda\envs\PBFT\lib\site-packages\aiohttp\connector.py", line 1187, in _create_direct_connection
    client_error=client_error,
  File "D:\anaconda\envs\PBFT\lib\site-packages\aiohttp\connector.py", line 988, in _wrap_create_connection
    raise client_error(req.connection_key, exc) from exc
aiohttp.client_exceptions.ClientConnectorError: Cannot connect to host localhost:30093 ssl:default [Connect call failed ('::1', 30093, 0, 0)]
[2025-03-07 13:53:51,044] [ERROR] [30158] Error sending to http://localhost:30027/prepare: Cannot connect to host localhost:30027 ssl:default [Connect call failed ('127.0.0.1', 30027)]
Traceback (most recent call last):
  File "D:\anaconda\envs\PBFT\lib\site-packages\aiohttp\connector.py", line 980, in _wrap_create_connection
    return await self._loop.create_connection(*args, **kwargs)  # type: ignore[return-value]  # noqa
  File "D:\anaconda\envs\PBFT\lib\asyncio\base_events.py", line 948, in create_connection
    raise exceptions[0]
  File "D:\anaconda\envs\PBFT\lib\asyncio\base_events.py", line 935, in create_connection
    await self.sock_connect(sock, address)
  File "D:\anaconda\envs\PBFT\lib\asyncio\selector_events.py", line 475, in sock_connect
    return await fut
  File "D:\anaconda\envs\PBFT\lib\asyncio\selector_events.py", line 505, in _sock_connect_cb
    raise OSError(err, f'Connect call failed {address}')
ConnectionRefusedError: [Errno 10061] Connect call failed ('127.0.0.1', 30027)

The above exception was the direct cause of the following exception:

Traceback (most recent call last):
  File "pbft.py", line 236, in send_message
    await send_with_delay(self.session, self.node_info, target, url, data, self.bandwidth_data)
  File "pbft.py", line 63, in send_with_delay
    async with session.post(url, json=data) as resp:
  File "D:\anaconda\envs\PBFT\lib\site-packages\aiohttp\client.py", line 1141, in __aenter__
    self._resp = await self._coro
  File "D:\anaconda\envs\PBFT\lib\site-packages\aiohttp\client.py", line 537, in _request
    req, traces=traces, timeout=real_timeout
  File "D:\anaconda\envs\PBFT\lib\site-packages\aiohttp\connector.py", line 540, in connect
    proto = await self._create_connection(req, traces, timeout)
  File "D:\anaconda\envs\PBFT\lib\site-packages\aiohttp\connector.py", line 901, in _create_connection
    _, proto = await self._create_direct_connection(req, traces, timeout)
  File "D:\anaconda\envs\PBFT\lib\site-packages\aiohttp\connector.py", line 1206, in _create_direct_connection
    raise last_exc
  File "D:\anaconda\envs\PBFT\lib\site-packages\aiohttp\connector.py", line 1187, in _create_direct_connection
    client_error=client_error,
  File "D:\anaconda\envs\PBFT\lib\site-packages\aiohttp\connector.py", line 988, in _wrap_create_connection
    raise client_error(req.connection_key, exc) from exc
aiohttp.client_exceptions.ClientConnectorError: Cannot connect to host localhost:30027 ssl:default [Connect call failed ('127.0.0.1', 30027)]
[2025-03-07 13:53:51,076] [ERROR] [30158] Error sending to http://localhost:30025/prepare: Cannot connect to host localhost:30025 ssl:default [Connect call failed ('127.0.0.1', 30025)]
Traceback (most recent call last):
  File "D:\anaconda\envs\PBFT\lib\site-packages\aiohttp\connector.py", line 980, in _wrap_create_connection
    return await self._loop.create_connection(*args, **kwargs)  # type: ignore[return-value]  # noqa
  File "D:\anaconda\envs\PBFT\lib\asyncio\base_events.py", line 948, in create_connection
    raise exceptions[0]
  File "D:\anaconda\envs\PBFT\lib\asyncio\base_events.py", line 935, in create_connection
    await self.sock_connect(sock, address)
  File "D:\anaconda\envs\PBFT\lib\asyncio\selector_events.py", line 475, in sock_connect
    return await fut
  File "D:\anaconda\envs\PBFT\lib\asyncio\selector_events.py", line 505, in _sock_connect_cb
    raise OSError(err, f'Connect call failed {address}')
ConnectionRefusedError: [Errno 10061] Connect call failed ('127.0.0.1', 30025)

The above exception was the direct cause of the following exception:

Traceback (most recent call last):
  File "pbft.py", line 236, in send_message
    await send_with_delay(self.session, self.node_info, target, url, data, self.bandwidth_data)
  File "pbft.py", line 63, in send_with_delay
    async with session.post(url, json=data) as resp:
  File "D:\anaconda\envs\PBFT\lib\site-packages\aiohttp\client.py", line 1141, in __aenter__
    self._resp = await self._coro
  File "D:\anaconda\envs\PBFT\lib\site-packages\aiohttp\client.py", line 537, in _request
    req, traces=traces, timeout=real_timeout
  File "D:\anaconda\envs\PBFT\lib\site-packages\aiohttp\connector.py", line 540, in connect
    proto = await self._create_connection(req, traces, timeout)
  File "D:\anaconda\envs\PBFT\lib\site-packages\aiohttp\connector.py", line 901, in _create_connection
    _, proto = await self._create_direct_connection(req, traces, timeout)
  File "D:\anaconda\envs\PBFT\lib\site-packages\aiohttp\connector.py", line 1206, in _create_direct_connection
    raise last_exc
  File "D:\anaconda\envs\PBFT\lib\site-packages\aiohttp\connector.py", line 1187, in _create_direct_connection
    client_error=client_error,
  File "D:\anaconda\envs\PBFT\lib\site-packages\aiohttp\connector.py", line 988, in _wrap_create_connection
    raise client_error(req.connection_key, exc) from exc
aiohttp.client_exceptions.ClientConnectorError: Cannot connect to host localhost:30025 ssl:default [Connect call failed ('127.0.0.1', 30025)]
[2025-03-07 13:53:51,139] [ERROR] [30158] Error sending to http://localhost:30027/commit: Cannot connect to host localhost:30027 ssl:default [Connect call failed ('::1', 30027, 0, 0)]
Traceback (most recent call last):
  File "D:\anaconda\envs\PBFT\lib\site-packages\aiohttp\connector.py", line 980, in _wrap_create_connection
    return await self._loop.create_connection(*args, **kwargs)  # type: ignore[return-value]  # noqa
  File "D:\anaconda\envs\PBFT\lib\asyncio\base_events.py", line 948, in create_connection
    raise exceptions[0]
  File "D:\anaconda\envs\PBFT\lib\asyncio\base_events.py", line 935, in create_connection
    await self.sock_connect(sock, address)
  File "D:\anaconda\envs\PBFT\lib\asyncio\selector_events.py", line 475, in sock_connect
    return await fut
  File "D:\anaconda\envs\PBFT\lib\asyncio\selector_events.py", line 505, in _sock_connect_cb
    raise OSError(err, f'Connect call failed {address}')
ConnectionRefusedError: [Errno 10061] Connect call failed ('::1', 30027, 0, 0)

The above exception was the direct cause of the following exception:

Traceback (most recent call last):
  File "pbft.py", line 236, in send_message
    await send_with_delay(self.session, self.node_info, target, url, data, self.bandwidth_data)
  File "pbft.py", line 63, in send_with_delay
    async with session.post(url, json=data) as resp:
  File "D:\anaconda\envs\PBFT\lib\site-packages\aiohttp\client.py", line 1141, in __aenter__
    self._resp = await self._coro
  File "D:\anaconda\envs\PBFT\lib\site-packages\aiohttp\client.py", line 537, in _request
    req, traces=traces, timeout=real_timeout
  File "D:\anaconda\envs\PBFT\lib\site-packages\aiohttp\connector.py", line 540, in connect
    proto = await self._create_connection(req, traces, timeout)
  File "D:\anaconda\envs\PBFT\lib\site-packages\aiohttp\connector.py", line 901, in _create_connection
    _, proto = await self._create_direct_connection(req, traces, timeout)
  File "D:\anaconda\envs\PBFT\lib\site-packages\aiohttp\connector.py", line 1206, in _create_direct_connection
    raise last_exc
  File "D:\anaconda\envs\PBFT\lib\site-packages\aiohttp\connector.py", line 1187, in _create_direct_connection
    client_error=client_error,
  File "D:\anaconda\envs\PBFT\lib\site-packages\aiohttp\connector.py", line 988, in _wrap_create_connection
    raise client_error(req.connection_key, exc) from exc
aiohttp.client_exceptions.ClientConnectorError: Cannot connect to host localhost:30027 ssl:default [Connect call failed ('::1', 30027, 0, 0)]
[2025-03-07 13:53:51,145] [INFO] [30158] Received PREPARE: id:1741323218379, from:30126, delay:0.0001s, distance:230.04m (Euclidean)
[2025-03-07 13:53:51,145] [INFO] [30158] Received COMMIT: id:1741323218379, from:30126, delay:0.0001s, distance:230.04m (Euclidean)
[2025-03-07 13:53:51,171] [ERROR] [30158] Error sending to http://localhost:30025/commit: Cannot connect to host localhost:30025 ssl:default [Connect call failed ('::1', 30025, 0, 0)]
Traceback (most recent call last):
  File "D:\anaconda\envs\PBFT\lib\site-packages\aiohttp\connector.py", line 980, in _wrap_create_connection
    return await self._loop.create_connection(*args, **kwargs)  # type: ignore[return-value]  # noqa
  File "D:\anaconda\envs\PBFT\lib\asyncio\base_events.py", line 948, in create_connection
    raise exceptions[0]
  File "D:\anaconda\envs\PBFT\lib\asyncio\base_events.py", line 935, in create_connection
    await self.sock_connect(sock, address)
  File "D:\anaconda\envs\PBFT\lib\asyncio\selector_events.py", line 475, in sock_connect
    return await fut
  File "D:\anaconda\envs\PBFT\lib\asyncio\selector_events.py", line 505, in _sock_connect_cb
    raise OSError(err, f'Connect call failed {address}')
ConnectionRefusedError: [Errno 10061] Connect call failed ('::1', 30025, 0, 0)

The above exception was the direct cause of the following exception:

Traceback (most recent call last):
  File "pbft.py", line 236, in send_message
    await send_with_delay(self.session, self.node_info, target, url, data, self.bandwidth_data)
  File "pbft.py", line 63, in send_with_delay
    async with session.post(url, json=data) as resp:
  File "D:\anaconda\envs\PBFT\lib\site-packages\aiohttp\client.py", line 1141, in __aenter__
    self._resp = await self._coro
  File "D:\anaconda\envs\PBFT\lib\site-packages\aiohttp\client.py", line 537, in _request
    req, traces=traces, timeout=real_timeout
  File "D:\anaconda\envs\PBFT\lib\site-packages\aiohttp\connector.py", line 540, in connect
    proto = await self._create_connection(req, traces, timeout)
  File "D:\anaconda\envs\PBFT\lib\site-packages\aiohttp\connector.py", line 901, in _create_connection
    _, proto = await self._create_direct_connection(req, traces, timeout)
  File "D:\anaconda\envs\PBFT\lib\site-packages\aiohttp\connector.py", line 1206, in _create_direct_connection
    raise last_exc
  File "D:\anaconda\envs\PBFT\lib\site-packages\aiohttp\connector.py", line 1187, in _create_direct_connection
    client_error=client_error,
  File "D:\anaconda\envs\PBFT\lib\site-packages\aiohttp\connector.py", line 988, in _wrap_create_connection
    raise client_error(req.connection_key, exc) from exc
aiohttp.client_exceptions.ClientConnectorError: Cannot connect to host localhost:30025 ssl:default [Connect call failed ('::1', 30025, 0, 0)]
[2025-03-07 13:53:51,187] [ERROR] [30158] Error sending to http://localhost:30076/commit: Cannot connect to host localhost:30076 ssl:default [Connect call failed ('::1', 30076, 0, 0)]
Traceback (most recent call last):
  File "D:\anaconda\envs\PBFT\lib\site-packages\aiohttp\connector.py", line 980, in _wrap_create_connection
    return await self._loop.create_connection(*args, **kwargs)  # type: ignore[return-value]  # noqa
  File "D:\anaconda\envs\PBFT\lib\asyncio\base_events.py", line 948, in create_connection
    raise exceptions[0]
  File "D:\anaconda\envs\PBFT\lib\asyncio\base_events.py", line 935, in create_connection
    await self.sock_connect(sock, address)
  File "D:\anaconda\envs\PBFT\lib\asyncio\selector_events.py", line 475, in sock_connect
    return await fut
  File "D:\anaconda\envs\PBFT\lib\asyncio\selector_events.py", line 505, in _sock_connect_cb
    raise OSError(err, f'Connect call failed {address}')
ConnectionRefusedError: [Errno 10061] Connect call failed ('::1', 30076, 0, 0)

The above exception was the direct cause of the following exception:

Traceback (most recent call last):
  File "pbft.py", line 236, in send_message
    await send_with_delay(self.session, self.node_info, target, url, data, self.bandwidth_data)
  File "pbft.py", line 63, in send_with_delay
    async with session.post(url, json=data) as resp:
  File "D:\anaconda\envs\PBFT\lib\site-packages\aiohttp\client.py", line 1141, in __aenter__
    self._resp = await self._coro
  File "D:\anaconda\envs\PBFT\lib\site-packages\aiohttp\client.py", line 537, in _request
    req, traces=traces, timeout=real_timeout
  File "D:\anaconda\envs\PBFT\lib\site-packages\aiohttp\connector.py", line 540, in connect
    proto = await self._create_connection(req, traces, timeout)
  File "D:\anaconda\envs\PBFT\lib\site-packages\aiohttp\connector.py", line 901, in _create_connection
    _, proto = await self._create_direct_connection(req, traces, timeout)
  File "D:\anaconda\envs\PBFT\lib\site-packages\aiohttp\connector.py", line 1206, in _create_direct_connection
    raise last_exc
  File "D:\anaconda\envs\PBFT\lib\site-packages\aiohttp\connector.py", line 1187, in _create_direct_connection
    client_error=client_error,
  File "D:\anaconda\envs\PBFT\lib\site-packages\aiohttp\connector.py", line 988, in _wrap_create_connection
    raise client_error(req.connection_key, exc) from exc
aiohttp.client_exceptions.ClientConnectorError: Cannot connect to host localhost:30076 ssl:default [Connect call failed ('::1', 30076, 0, 0)]
[2025-03-07 13:53:51,187] [ERROR] [30158] Error sending to http://localhost:30075/commit: Cannot connect to host localhost:30075 ssl:default [Connect call failed ('::1', 30075, 0, 0)]
Traceback (most recent call last):
  File "D:\anaconda\envs\PBFT\lib\site-packages\aiohttp\connector.py", line 980, in _wrap_create_connection
    return await self._loop.create_connection(*args, **kwargs)  # type: ignore[return-value]  # noqa
  File "D:\anaconda\envs\PBFT\lib\asyncio\base_events.py", line 948, in create_connection
    raise exceptions[0]
  File "D:\anaconda\envs\PBFT\lib\asyncio\base_events.py", line 935, in create_connection
    await self.sock_connect(sock, address)
  File "D:\anaconda\envs\PBFT\lib\asyncio\selector_events.py", line 475, in sock_connect
    return await fut
  File "D:\anaconda\envs\PBFT\lib\asyncio\selector_events.py", line 505, in _sock_connect_cb
    raise OSError(err, f'Connect call failed {address}')
ConnectionRefusedError: [Errno 10061] Connect call failed ('::1', 30075, 0, 0)

The above exception was the direct cause of the following exception:

Traceback (most recent call last):
  File "pbft.py", line 236, in send_message
    await send_with_delay(self.session, self.node_info, target, url, data, self.bandwidth_data)
  File "pbft.py", line 63, in send_with_delay
    async with session.post(url, json=data) as resp:
  File "D:\anaconda\envs\PBFT\lib\site-packages\aiohttp\client.py", line 1141, in __aenter__
    self._resp = await self._coro
  File "D:\anaconda\envs\PBFT\lib\site-packages\aiohttp\client.py", line 537, in _request
    req, traces=traces, timeout=real_timeout
  File "D:\anaconda\envs\PBFT\lib\site-packages\aiohttp\connector.py", line 540, in connect
    proto = await self._create_connection(req, traces, timeout)
  File "D:\anaconda\envs\PBFT\lib\site-packages\aiohttp\connector.py", line 901, in _create_connection
    _, proto = await self._create_direct_connection(req, traces, timeout)
  File "D:\anaconda\envs\PBFT\lib\site-packages\aiohttp\connector.py", line 1206, in _create_direct_connection
    raise last_exc
  File "D:\anaconda\envs\PBFT\lib\site-packages\aiohttp\connector.py", line 1187, in _create_direct_connection
    client_error=client_error,
  File "D:\anaconda\envs\PBFT\lib\site-packages\aiohttp\connector.py", line 988, in _wrap_create_connection
    raise client_error(req.connection_key, exc) from exc
aiohttp.client_exceptions.ClientConnectorError: Cannot connect to host localhost:30075 ssl:default [Connect call failed ('::1', 30075, 0, 0)]
[2025-03-07 13:53:51,202] [ERROR] [30158] Error sending to http://localhost:30038/prepare: Cannot connect to host localhost:30038 ssl:default [Connect call failed ('127.0.0.1', 30038)]
Traceback (most recent call last):
  File "D:\anaconda\envs\PBFT\lib\site-packages\aiohttp\connector.py", line 980, in _wrap_create_connection
    return await self._loop.create_connection(*args, **kwargs)  # type: ignore[return-value]  # noqa
  File "D:\anaconda\envs\PBFT\lib\asyncio\base_events.py", line 948, in create_connection
    raise exceptions[0]
  File "D:\anaconda\envs\PBFT\lib\asyncio\base_events.py", line 935, in create_connection
    await self.sock_connect(sock, address)
  File "D:\anaconda\envs\PBFT\lib\asyncio\selector_events.py", line 475, in sock_connect
    return await fut
  File "D:\anaconda\envs\PBFT\lib\asyncio\selector_events.py", line 505, in _sock_connect_cb
    raise OSError(err, f'Connect call failed {address}')
ConnectionRefusedError: [Errno 10061] Connect call failed ('127.0.0.1', 30038)

The above exception was the direct cause of the following exception:

Traceback (most recent call last):
  File "pbft.py", line 236, in send_message
    await send_with_delay(self.session, self.node_info, target, url, data, self.bandwidth_data)
  File "pbft.py", line 63, in send_with_delay
    async with session.post(url, json=data) as resp:
  File "D:\anaconda\envs\PBFT\lib\site-packages\aiohttp\client.py", line 1141, in __aenter__
    self._resp = await self._coro
  File "D:\anaconda\envs\PBFT\lib\site-packages\aiohttp\client.py", line 537, in _request
    req, traces=traces, timeout=real_timeout
  File "D:\anaconda\envs\PBFT\lib\site-packages\aiohttp\connector.py", line 540, in connect
    proto = await self._create_connection(req, traces, timeout)
  File "D:\anaconda\envs\PBFT\lib\site-packages\aiohttp\connector.py", line 901, in _create_connection
    _, proto = await self._create_direct_connection(req, traces, timeout)
  File "D:\anaconda\envs\PBFT\lib\site-packages\aiohttp\connector.py", line 1206, in _create_direct_connection
    raise last_exc
  File "D:\anaconda\envs\PBFT\lib\site-packages\aiohttp\connector.py", line 1187, in _create_direct_connection
    client_error=client_error,
  File "D:\anaconda\envs\PBFT\lib\site-packages\aiohttp\connector.py", line 988, in _wrap_create_connection
    raise client_error(req.connection_key, exc) from exc
aiohttp.client_exceptions.ClientConnectorError: Cannot connect to host localhost:30038 ssl:default [Connect call failed ('127.0.0.1', 30038)]
[2025-03-07 13:53:51,361] [ERROR] [30158] Error sending to http://localhost:30085/commit: Cannot connect to host localhost:30085 ssl:default [Connect call failed ('::1', 30085, 0, 0)]
Traceback (most recent call last):
  File "D:\anaconda\envs\PBFT\lib\site-packages\aiohttp\connector.py", line 980, in _wrap_create_connection
    return await self._loop.create_connection(*args, **kwargs)  # type: ignore[return-value]  # noqa
  File "D:\anaconda\envs\PBFT\lib\asyncio\base_events.py", line 948, in create_connection
    raise exceptions[0]
  File "D:\anaconda\envs\PBFT\lib\asyncio\base_events.py", line 935, in create_connection
    await self.sock_connect(sock, address)
  File "D:\anaconda\envs\PBFT\lib\asyncio\selector_events.py", line 475, in sock_connect
    return await fut
  File "D:\anaconda\envs\PBFT\lib\asyncio\selector_events.py", line 505, in _sock_connect_cb
    raise OSError(err, f'Connect call failed {address}')
ConnectionRefusedError: [Errno 10061] Connect call failed ('::1', 30085, 0, 0)

The above exception was the direct cause of the following exception:

Traceback (most recent call last):
  File "pbft.py", line 236, in send_message
    await send_with_delay(self.session, self.node_info, target, url, data, self.bandwidth_data)
  File "pbft.py", line 63, in send_with_delay
    async with session.post(url, json=data) as resp:
  File "D:\anaconda\envs\PBFT\lib\site-packages\aiohttp\client.py", line 1141, in __aenter__
    self._resp = await self._coro
  File "D:\anaconda\envs\PBFT\lib\site-packages\aiohttp\client.py", line 537, in _request
    req, traces=traces, timeout=real_timeout
  File "D:\anaconda\envs\PBFT\lib\site-packages\aiohttp\connector.py", line 540, in connect
    proto = await self._create_connection(req, traces, timeout)
  File "D:\anaconda\envs\PBFT\lib\site-packages\aiohttp\connector.py", line 901, in _create_connection
    _, proto = await self._create_direct_connection(req, traces, timeout)
  File "D:\anaconda\envs\PBFT\lib\site-packages\aiohttp\connector.py", line 1206, in _create_direct_connection
    raise last_exc
  File "D:\anaconda\envs\PBFT\lib\site-packages\aiohttp\connector.py", line 1187, in _create_direct_connection
    client_error=client_error,
  File "D:\anaconda\envs\PBFT\lib\site-packages\aiohttp\connector.py", line 988, in _wrap_create_connection
    raise client_error(req.connection_key, exc) from exc
aiohttp.client_exceptions.ClientConnectorError: Cannot connect to host localhost:30085 ssl:default [Connect call failed ('::1', 30085, 0, 0)]
[2025-03-07 13:53:51,393] [ERROR] [30158] Error sending to http://localhost:30065/commit: Cannot connect to host localhost:30065 ssl:default [Connect call failed ('::1', 30065, 0, 0)]
Traceback (most recent call last):
  File "D:\anaconda\envs\PBFT\lib\site-packages\aiohttp\connector.py", line 980, in _wrap_create_connection
    return await self._loop.create_connection(*args, **kwargs)  # type: ignore[return-value]  # noqa
  File "D:\anaconda\envs\PBFT\lib\asyncio\base_events.py", line 948, in create_connection
    raise exceptions[0]
  File "D:\anaconda\envs\PBFT\lib\asyncio\base_events.py", line 935, in create_connection
    await self.sock_connect(sock, address)
  File "D:\anaconda\envs\PBFT\lib\asyncio\selector_events.py", line 475, in sock_connect
    return await fut
  File "D:\anaconda\envs\PBFT\lib\asyncio\selector_events.py", line 505, in _sock_connect_cb
    raise OSError(err, f'Connect call failed {address}')
ConnectionRefusedError: [Errno 10061] Connect call failed ('::1', 30065, 0, 0)

The above exception was the direct cause of the following exception:

Traceback (most recent call last):
  File "pbft.py", line 236, in send_message
    await send_with_delay(self.session, self.node_info, target, url, data, self.bandwidth_data)
  File "pbft.py", line 63, in send_with_delay
    async with session.post(url, json=data) as resp:
  File "D:\anaconda\envs\PBFT\lib\site-packages\aiohttp\client.py", line 1141, in __aenter__
    self._resp = await self._coro
  File "D:\anaconda\envs\PBFT\lib\site-packages\aiohttp\client.py", line 537, in _request
    req, traces=traces, timeout=real_timeout
  File "D:\anaconda\envs\PBFT\lib\site-packages\aiohttp\connector.py", line 540, in connect
    proto = await self._create_connection(req, traces, timeout)
  File "D:\anaconda\envs\PBFT\lib\site-packages\aiohttp\connector.py", line 901, in _create_connection
    _, proto = await self._create_direct_connection(req, traces, timeout)
  File "D:\anaconda\envs\PBFT\lib\site-packages\aiohttp\connector.py", line 1206, in _create_direct_connection
    raise last_exc
  File "D:\anaconda\envs\PBFT\lib\site-packages\aiohttp\connector.py", line 1187, in _create_direct_connection
    client_error=client_error,
  File "D:\anaconda\envs\PBFT\lib\site-packages\aiohttp\connector.py", line 988, in _wrap_create_connection
    raise client_error(req.connection_key, exc) from exc
aiohttp.client_exceptions.ClientConnectorError: Cannot connect to host localhost:30065 ssl:default [Connect call failed ('::1', 30065, 0, 0)]
[2025-03-07 13:53:51,393] [ERROR] [30158] Error sending to http://localhost:30065/prepare: Cannot connect to host localhost:30065 ssl:default [Connect call failed ('127.0.0.1', 30065)]
Traceback (most recent call last):
  File "D:\anaconda\envs\PBFT\lib\site-packages\aiohttp\connector.py", line 980, in _wrap_create_connection
    return await self._loop.create_connection(*args, **kwargs)  # type: ignore[return-value]  # noqa
  File "D:\anaconda\envs\PBFT\lib\asyncio\base_events.py", line 948, in create_connection
    raise exceptions[0]
  File "D:\anaconda\envs\PBFT\lib\asyncio\base_events.py", line 935, in create_connection
    await self.sock_connect(sock, address)
  File "D:\anaconda\envs\PBFT\lib\asyncio\selector_events.py", line 475, in sock_connect
    return await fut
  File "D:\anaconda\envs\PBFT\lib\asyncio\selector_events.py", line 505, in _sock_connect_cb
    raise OSError(err, f'Connect call failed {address}')
ConnectionRefusedError: [Errno 10061] Connect call failed ('127.0.0.1', 30065)

The above exception was the direct cause of the following exception:

Traceback (most recent call last):
  File "pbft.py", line 236, in send_message
    await send_with_delay(self.session, self.node_info, target, url, data, self.bandwidth_data)
  File "pbft.py", line 63, in send_with_delay
    async with session.post(url, json=data) as resp:
  File "D:\anaconda\envs\PBFT\lib\site-packages\aiohttp\client.py", line 1141, in __aenter__
    self._resp = await self._coro
  File "D:\anaconda\envs\PBFT\lib\site-packages\aiohttp\client.py", line 537, in _request
    req, traces=traces, timeout=real_timeout
  File "D:\anaconda\envs\PBFT\lib\site-packages\aiohttp\connector.py", line 540, in connect
    proto = await self._create_connection(req, traces, timeout)
  File "D:\anaconda\envs\PBFT\lib\site-packages\aiohttp\connector.py", line 901, in _create_connection
    _, proto = await self._create_direct_connection(req, traces, timeout)
  File "D:\anaconda\envs\PBFT\lib\site-packages\aiohttp\connector.py", line 1206, in _create_direct_connection
    raise last_exc
  File "D:\anaconda\envs\PBFT\lib\site-packages\aiohttp\connector.py", line 1187, in _create_direct_connection
    client_error=client_error,
  File "D:\anaconda\envs\PBFT\lib\site-packages\aiohttp\connector.py", line 988, in _wrap_create_connection
    raise client_error(req.connection_key, exc) from exc
aiohttp.client_exceptions.ClientConnectorError: Cannot connect to host localhost:30065 ssl:default [Connect call failed ('127.0.0.1', 30065)]
[2025-03-07 13:53:51,408] [ERROR] [30158] Error sending to http://localhost:30063/prepare: Cannot connect to host localhost:30063 ssl:default [Connect call failed ('127.0.0.1', 30063)]
Traceback (most recent call last):
  File "D:\anaconda\envs\PBFT\lib\site-packages\aiohttp\connector.py", line 980, in _wrap_create_connection
    return await self._loop.create_connection(*args, **kwargs)  # type: ignore[return-value]  # noqa
  File "D:\anaconda\envs\PBFT\lib\asyncio\base_events.py", line 948, in create_connection
    raise exceptions[0]
  File "D:\anaconda\envs\PBFT\lib\asyncio\base_events.py", line 935, in create_connection
    await self.sock_connect(sock, address)
  File "D:\anaconda\envs\PBFT\lib\asyncio\selector_events.py", line 475, in sock_connect
    return await fut
  File "D:\anaconda\envs\PBFT\lib\asyncio\selector_events.py", line 505, in _sock_connect_cb
    raise OSError(err, f'Connect call failed {address}')
ConnectionRefusedError: [Errno 10061] Connect call failed ('127.0.0.1', 30063)

The above exception was the direct cause of the following exception:

Traceback (most recent call last):
  File "pbft.py", line 236, in send_message
    await send_with_delay(self.session, self.node_info, target, url, data, self.bandwidth_data)
  File "pbft.py", line 63, in send_with_delay
    async with session.post(url, json=data) as resp:
  File "D:\anaconda\envs\PBFT\lib\site-packages\aiohttp\client.py", line 1141, in __aenter__
    self._resp = await self._coro
  File "D:\anaconda\envs\PBFT\lib\site-packages\aiohttp\client.py", line 537, in _request
    req, traces=traces, timeout=real_timeout
  File "D:\anaconda\envs\PBFT\lib\site-packages\aiohttp\connector.py", line 540, in connect
    proto = await self._create_connection(req, traces, timeout)
  File "D:\anaconda\envs\PBFT\lib\site-packages\aiohttp\connector.py", line 901, in _create_connection
    _, proto = await self._create_direct_connection(req, traces, timeout)
  File "D:\anaconda\envs\PBFT\lib\site-packages\aiohttp\connector.py", line 1206, in _create_direct_connection
    raise last_exc
  File "D:\anaconda\envs\PBFT\lib\site-packages\aiohttp\connector.py", line 1187, in _create_direct_connection
    client_error=client_error,
  File "D:\anaconda\envs\PBFT\lib\site-packages\aiohttp\connector.py", line 988, in _wrap_create_connection
    raise client_error(req.connection_key, exc) from exc
aiohttp.client_exceptions.ClientConnectorError: Cannot connect to host localhost:30063 ssl:default [Connect call failed ('127.0.0.1', 30063)]
[2025-03-07 13:53:51,472] [ERROR] [30158] Error sending to http://localhost:30140/prepare: Cannot connect to host localhost:30140 ssl:default [Connect call failed ('127.0.0.1', 30140)]
Traceback (most recent call last):
  File "D:\anaconda\envs\PBFT\lib\site-packages\aiohttp\connector.py", line 980, in _wrap_create_connection
    return await self._loop.create_connection(*args, **kwargs)  # type: ignore[return-value]  # noqa
  File "D:\anaconda\envs\PBFT\lib\asyncio\base_events.py", line 948, in create_connection
    raise exceptions[0]
  File "D:\anaconda\envs\PBFT\lib\asyncio\base_events.py", line 935, in create_connection
    await self.sock_connect(sock, address)
  File "D:\anaconda\envs\PBFT\lib\asyncio\selector_events.py", line 475, in sock_connect
    return await fut
  File "D:\anaconda\envs\PBFT\lib\asyncio\selector_events.py", line 505, in _sock_connect_cb
    raise OSError(err, f'Connect call failed {address}')
ConnectionRefusedError: [Errno 10061] Connect call failed ('127.0.0.1', 30140)

The above exception was the direct cause of the following exception:

Traceback (most recent call last):
  File "pbft.py", line 236, in send_message
    await send_with_delay(self.session, self.node_info, target, url, data, self.bandwidth_data)
  File "pbft.py", line 63, in send_with_delay
    async with session.post(url, json=data) as resp:
  File "D:\anaconda\envs\PBFT\lib\site-packages\aiohttp\client.py", line 1141, in __aenter__
    self._resp = await self._coro
  File "D:\anaconda\envs\PBFT\lib\site-packages\aiohttp\client.py", line 537, in _request
    req, traces=traces, timeout=real_timeout
  File "D:\anaconda\envs\PBFT\lib\site-packages\aiohttp\connector.py", line 540, in connect
    proto = await self._create_connection(req, traces, timeout)
  File "D:\anaconda\envs\PBFT\lib\site-packages\aiohttp\connector.py", line 901, in _create_connection
    _, proto = await self._create_direct_connection(req, traces, timeout)
  File "D:\anaconda\envs\PBFT\lib\site-packages\aiohttp\connector.py", line 1206, in _create_direct_connection
    raise last_exc
  File "D:\anaconda\envs\PBFT\lib\site-packages\aiohttp\connector.py", line 1187, in _create_direct_connection
    client_error=client_error,
  File "D:\anaconda\envs\PBFT\lib\site-packages\aiohttp\connector.py", line 988, in _wrap_create_connection
    raise client_error(req.connection_key, exc) from exc
aiohttp.client_exceptions.ClientConnectorError: Cannot connect to host localhost:30140 ssl:default [Connect call failed ('127.0.0.1', 30140)]
[2025-03-07 13:53:51,472] [ERROR] [30158] Error sending to http://localhost:30140/commit: Cannot connect to host localhost:30140 ssl:default [Connect call failed ('::1', 30140, 0, 0)]
Traceback (most recent call last):
  File "D:\anaconda\envs\PBFT\lib\site-packages\aiohttp\connector.py", line 980, in _wrap_create_connection
    return await self._loop.create_connection(*args, **kwargs)  # type: ignore[return-value]  # noqa
  File "D:\anaconda\envs\PBFT\lib\asyncio\base_events.py", line 948, in create_connection
    raise exceptions[0]
  File "D:\anaconda\envs\PBFT\lib\asyncio\base_events.py", line 935, in create_connection
    await self.sock_connect(sock, address)
  File "D:\anaconda\envs\PBFT\lib\asyncio\selector_events.py", line 475, in sock_connect
    return await fut
  File "D:\anaconda\envs\PBFT\lib\asyncio\selector_events.py", line 505, in _sock_connect_cb
    raise OSError(err, f'Connect call failed {address}')
ConnectionRefusedError: [Errno 10061] Connect call failed ('::1', 30140, 0, 0)

The above exception was the direct cause of the following exception:

Traceback (most recent call last):
  File "pbft.py", line 236, in send_message
    await send_with_delay(self.session, self.node_info, target, url, data, self.bandwidth_data)
  File "pbft.py", line 63, in send_with_delay
    async with session.post(url, json=data) as resp:
  File "D:\anaconda\envs\PBFT\lib\site-packages\aiohttp\client.py", line 1141, in __aenter__
    self._resp = await self._coro
  File "D:\anaconda\envs\PBFT\lib\site-packages\aiohttp\client.py", line 537, in _request
    req, traces=traces, timeout=real_timeout
  File "D:\anaconda\envs\PBFT\lib\site-packages\aiohttp\connector.py", line 540, in connect
    proto = await self._create_connection(req, traces, timeout)
  File "D:\anaconda\envs\PBFT\lib\site-packages\aiohttp\connector.py", line 901, in _create_connection
    _, proto = await self._create_direct_connection(req, traces, timeout)
  File "D:\anaconda\envs\PBFT\lib\site-packages\aiohttp\connector.py", line 1206, in _create_direct_connection
    raise last_exc
  File "D:\anaconda\envs\PBFT\lib\site-packages\aiohttp\connector.py", line 1187, in _create_direct_connection
    client_error=client_error,
  File "D:\anaconda\envs\PBFT\lib\site-packages\aiohttp\connector.py", line 988, in _wrap_create_connection
    raise client_error(req.connection_key, exc) from exc
aiohttp.client_exceptions.ClientConnectorError: Cannot connect to host localhost:30140 ssl:default [Connect call failed ('::1', 30140, 0, 0)]
[2025-03-07 13:53:51,566] [ERROR] [30158] Error sending to http://localhost:30063/commit: Cannot connect to host localhost:30063 ssl:default [Connect call failed ('::1', 30063, 0, 0)]
Traceback (most recent call last):
  File "D:\anaconda\envs\PBFT\lib\site-packages\aiohttp\connector.py", line 980, in _wrap_create_connection
    return await self._loop.create_connection(*args, **kwargs)  # type: ignore[return-value]  # noqa
  File "D:\anaconda\envs\PBFT\lib\asyncio\base_events.py", line 948, in create_connection
    raise exceptions[0]
  File "D:\anaconda\envs\PBFT\lib\asyncio\base_events.py", line 935, in create_connection
    await self.sock_connect(sock, address)
  File "D:\anaconda\envs\PBFT\lib\asyncio\selector_events.py", line 475, in sock_connect
    return await fut
  File "D:\anaconda\envs\PBFT\lib\asyncio\selector_events.py", line 505, in _sock_connect_cb
    raise OSError(err, f'Connect call failed {address}')
ConnectionRefusedError: [Errno 10061] Connect call failed ('::1', 30063, 0, 0)

The above exception was the direct cause of the following exception:

Traceback (most recent call last):
  File "pbft.py", line 236, in send_message
    await send_with_delay(self.session, self.node_info, target, url, data, self.bandwidth_data)
  File "pbft.py", line 63, in send_with_delay
    async with session.post(url, json=data) as resp:
  File "D:\anaconda\envs\PBFT\lib\site-packages\aiohttp\client.py", line 1141, in __aenter__
    self._resp = await self._coro
  File "D:\anaconda\envs\PBFT\lib\site-packages\aiohttp\client.py", line 537, in _request
    req, traces=traces, timeout=real_timeout
  File "D:\anaconda\envs\PBFT\lib\site-packages\aiohttp\connector.py", line 540, in connect
    proto = await self._create_connection(req, traces, timeout)
  File "D:\anaconda\envs\PBFT\lib\site-packages\aiohttp\connector.py", line 901, in _create_connection
    _, proto = await self._create_direct_connection(req, traces, timeout)
  File "D:\anaconda\envs\PBFT\lib\site-packages\aiohttp\connector.py", line 1206, in _create_direct_connection
    raise last_exc
  File "D:\anaconda\envs\PBFT\lib\site-packages\aiohttp\connector.py", line 1187, in _create_direct_connection
    client_error=client_error,
  File "D:\anaconda\envs\PBFT\lib\site-packages\aiohttp\connector.py", line 988, in _wrap_create_connection
    raise client_error(req.connection_key, exc) from exc
aiohttp.client_exceptions.ClientConnectorError: Cannot connect to host localhost:30063 ssl:default [Connect call failed ('::1', 30063, 0, 0)]
[2025-03-07 13:53:51,584] [ERROR] [30158] Error sending to http://localhost:30071/commit: Cannot connect to host localhost:30071 ssl:default [Connect call failed ('::1', 30071, 0, 0)]
Traceback (most recent call last):
  File "D:\anaconda\envs\PBFT\lib\site-packages\aiohttp\connector.py", line 980, in _wrap_create_connection
    return await self._loop.create_connection(*args, **kwargs)  # type: ignore[return-value]  # noqa
  File "D:\anaconda\envs\PBFT\lib\asyncio\base_events.py", line 948, in create_connection
    raise exceptions[0]
  File "D:\anaconda\envs\PBFT\lib\asyncio\base_events.py", line 935, in create_connection
    await self.sock_connect(sock, address)
  File "D:\anaconda\envs\PBFT\lib\asyncio\selector_events.py", line 475, in sock_connect
    return await fut
  File "D:\anaconda\envs\PBFT\lib\asyncio\selector_events.py", line 505, in _sock_connect_cb
    raise OSError(err, f'Connect call failed {address}')
ConnectionRefusedError: [Errno 10061] Connect call failed ('::1', 30071, 0, 0)

The above exception was the direct cause of the following exception:

Traceback (most recent call last):
  File "pbft.py", line 236, in send_message
    await send_with_delay(self.session, self.node_info, target, url, data, self.bandwidth_data)
  File "pbft.py", line 63, in send_with_delay
    async with session.post(url, json=data) as resp:
  File "D:\anaconda\envs\PBFT\lib\site-packages\aiohttp\client.py", line 1141, in __aenter__
    self._resp = await self._coro
  File "D:\anaconda\envs\PBFT\lib\site-packages\aiohttp\client.py", line 537, in _request
    req, traces=traces, timeout=real_timeout
  File "D:\anaconda\envs\PBFT\lib\site-packages\aiohttp\connector.py", line 540, in connect
    proto = await self._create_connection(req, traces, timeout)
  File "D:\anaconda\envs\PBFT\lib\site-packages\aiohttp\connector.py", line 901, in _create_connection
    _, proto = await self._create_direct_connection(req, traces, timeout)
  File "D:\anaconda\envs\PBFT\lib\site-packages\aiohttp\connector.py", line 1206, in _create_direct_connection
    raise last_exc
  File "D:\anaconda\envs\PBFT\lib\site-packages\aiohttp\connector.py", line 1187, in _create_direct_connection
    client_error=client_error,
  File "D:\anaconda\envs\PBFT\lib\site-packages\aiohttp\connector.py", line 988, in _wrap_create_connection
    raise client_error(req.connection_key, exc) from exc
aiohttp.client_exceptions.ClientConnectorError: Cannot connect to host localhost:30071 ssl:default [Connect call failed ('::1', 30071, 0, 0)]
[2025-03-07 13:53:51,678] [ERROR] [30158] Error sending to http://localhost:30038/commit: Cannot connect to host localhost:30038 ssl:default [Connect call failed ('::1', 30038, 0, 0)]
Traceback (most recent call last):
  File "D:\anaconda\envs\PBFT\lib\site-packages\aiohttp\connector.py", line 980, in _wrap_create_connection
    return await self._loop.create_connection(*args, **kwargs)  # type: ignore[return-value]  # noqa
  File "D:\anaconda\envs\PBFT\lib\asyncio\base_events.py", line 948, in create_connection
    raise exceptions[0]
  File "D:\anaconda\envs\PBFT\lib\asyncio\base_events.py", line 935, in create_connection
    await self.sock_connect(sock, address)
  File "D:\anaconda\envs\PBFT\lib\asyncio\selector_events.py", line 475, in sock_connect
    return await fut
  File "D:\anaconda\envs\PBFT\lib\asyncio\selector_events.py", line 505, in _sock_connect_cb
    raise OSError(err, f'Connect call failed {address}')
ConnectionRefusedError: [Errno 10061] Connect call failed ('::1', 30038, 0, 0)

The above exception was the direct cause of the following exception:

Traceback (most recent call last):
  File "pbft.py", line 236, in send_message
    await send_with_delay(self.session, self.node_info, target, url, data, self.bandwidth_data)
  File "pbft.py", line 63, in send_with_delay
    async with session.post(url, json=data) as resp:
  File "D:\anaconda\envs\PBFT\lib\site-packages\aiohttp\client.py", line 1141, in __aenter__
    self._resp = await self._coro
  File "D:\anaconda\envs\PBFT\lib\site-packages\aiohttp\client.py", line 537, in _request
    req, traces=traces, timeout=real_timeout
  File "D:\anaconda\envs\PBFT\lib\site-packages\aiohttp\connector.py", line 540, in connect
    proto = await self._create_connection(req, traces, timeout)
  File "D:\anaconda\envs\PBFT\lib\site-packages\aiohttp\connector.py", line 901, in _create_connection
    _, proto = await self._create_direct_connection(req, traces, timeout)
  File "D:\anaconda\envs\PBFT\lib\site-packages\aiohttp\connector.py", line 1206, in _create_direct_connection
    raise last_exc
  File "D:\anaconda\envs\PBFT\lib\site-packages\aiohttp\connector.py", line 1187, in _create_direct_connection
    client_error=client_error,
  File "D:\anaconda\envs\PBFT\lib\site-packages\aiohttp\connector.py", line 988, in _wrap_create_connection
    raise client_error(req.connection_key, exc) from exc
aiohttp.client_exceptions.ClientConnectorError: Cannot connect to host localhost:30038 ssl:default [Connect call failed ('::1', 30038, 0, 0)]
[2025-03-07 13:53:51,709] [ERROR] [30158] Error sending to http://localhost:30029/commit: Cannot connect to host localhost:30029 ssl:default [Connect call failed ('::1', 30029, 0, 0)]
Traceback (most recent call last):
  File "D:\anaconda\envs\PBFT\lib\site-packages\aiohttp\connector.py", line 980, in _wrap_create_connection
    return await self._loop.create_connection(*args, **kwargs)  # type: ignore[return-value]  # noqa
  File "D:\anaconda\envs\PBFT\lib\asyncio\base_events.py", line 948, in create_connection
    raise exceptions[0]
  File "D:\anaconda\envs\PBFT\lib\asyncio\base_events.py", line 935, in create_connection
    await self.sock_connect(sock, address)
  File "D:\anaconda\envs\PBFT\lib\asyncio\selector_events.py", line 475, in sock_connect
    return await fut
  File "D:\anaconda\envs\PBFT\lib\asyncio\selector_events.py", line 505, in _sock_connect_cb
    raise OSError(err, f'Connect call failed {address}')
ConnectionRefusedError: [Errno 10061] Connect call failed ('::1', 30029, 0, 0)

The above exception was the direct cause of the following exception:

Traceback (most recent call last):
  File "pbft.py", line 236, in send_message
    await send_with_delay(self.session, self.node_info, target, url, data, self.bandwidth_data)
  File "pbft.py", line 63, in send_with_delay
    async with session.post(url, json=data) as resp:
  File "D:\anaconda\envs\PBFT\lib\site-packages\aiohttp\client.py", line 1141, in __aenter__
    self._resp = await self._coro
  File "D:\anaconda\envs\PBFT\lib\site-packages\aiohttp\client.py", line 537, in _request
    req, traces=traces, timeout=real_timeout
  File "D:\anaconda\envs\PBFT\lib\site-packages\aiohttp\connector.py", line 540, in connect
    proto = await self._create_connection(req, traces, timeout)
  File "D:\anaconda\envs\PBFT\lib\site-packages\aiohttp\connector.py", line 901, in _create_connection
    _, proto = await self._create_direct_connection(req, traces, timeout)
  File "D:\anaconda\envs\PBFT\lib\site-packages\aiohttp\connector.py", line 1206, in _create_direct_connection
    raise last_exc
  File "D:\anaconda\envs\PBFT\lib\site-packages\aiohttp\connector.py", line 1187, in _create_direct_connection
    client_error=client_error,
  File "D:\anaconda\envs\PBFT\lib\site-packages\aiohttp\connector.py", line 988, in _wrap_create_connection
    raise client_error(req.connection_key, exc) from exc
aiohttp.client_exceptions.ClientConnectorError: Cannot connect to host localhost:30029 ssl:default [Connect call failed ('::1', 30029, 0, 0)]
[2025-03-07 13:53:51,756] [ERROR] [30158] Error sending to http://localhost:30141/prepare: Cannot connect to host localhost:30141 ssl:default [Connect call failed ('127.0.0.1', 30141)]
Traceback (most recent call last):
  File "D:\anaconda\envs\PBFT\lib\site-packages\aiohttp\connector.py", line 980, in _wrap_create_connection
    return await self._loop.create_connection(*args, **kwargs)  # type: ignore[return-value]  # noqa
  File "D:\anaconda\envs\PBFT\lib\asyncio\base_events.py", line 948, in create_connection
    raise exceptions[0]
  File "D:\anaconda\envs\PBFT\lib\asyncio\base_events.py", line 935, in create_connection
    await self.sock_connect(sock, address)
  File "D:\anaconda\envs\PBFT\lib\asyncio\selector_events.py", line 475, in sock_connect
    return await fut
  File "D:\anaconda\envs\PBFT\lib\asyncio\selector_events.py", line 505, in _sock_connect_cb
    raise OSError(err, f'Connect call failed {address}')
ConnectionRefusedError: [Errno 10061] Connect call failed ('127.0.0.1', 30141)

The above exception was the direct cause of the following exception:

Traceback (most recent call last):
  File "pbft.py", line 236, in send_message
    await send_with_delay(self.session, self.node_info, target, url, data, self.bandwidth_data)
  File "pbft.py", line 63, in send_with_delay
    async with session.post(url, json=data) as resp:
  File "D:\anaconda\envs\PBFT\lib\site-packages\aiohttp\client.py", line 1141, in __aenter__
    self._resp = await self._coro
  File "D:\anaconda\envs\PBFT\lib\site-packages\aiohttp\client.py", line 537, in _request
    req, traces=traces, timeout=real_timeout
  File "D:\anaconda\envs\PBFT\lib\site-packages\aiohttp\connector.py", line 540, in connect
    proto = await self._create_connection(req, traces, timeout)
  File "D:\anaconda\envs\PBFT\lib\site-packages\aiohttp\connector.py", line 901, in _create_connection
    _, proto = await self._create_direct_connection(req, traces, timeout)
  File "D:\anaconda\envs\PBFT\lib\site-packages\aiohttp\connector.py", line 1206, in _create_direct_connection
    raise last_exc
  File "D:\anaconda\envs\PBFT\lib\site-packages\aiohttp\connector.py", line 1187, in _create_direct_connection
    client_error=client_error,
  File "D:\anaconda\envs\PBFT\lib\site-packages\aiohttp\connector.py", line 988, in _wrap_create_connection
    raise client_error(req.connection_key, exc) from exc
aiohttp.client_exceptions.ClientConnectorError: Cannot connect to host localhost:30141 ssl:default [Connect call failed ('127.0.0.1', 30141)]
[2025-03-07 13:53:51,772] [ERROR] [30158] Error sending to http://localhost:30141/commit: Cannot connect to host localhost:30141 ssl:default [Connect call failed ('::1', 30141, 0, 0)]
Traceback (most recent call last):
  File "D:\anaconda\envs\PBFT\lib\site-packages\aiohttp\connector.py", line 980, in _wrap_create_connection
    return await self._loop.create_connection(*args, **kwargs)  # type: ignore[return-value]  # noqa
  File "D:\anaconda\envs\PBFT\lib\asyncio\base_events.py", line 948, in create_connection
    raise exceptions[0]
  File "D:\anaconda\envs\PBFT\lib\asyncio\base_events.py", line 935, in create_connection
    await self.sock_connect(sock, address)
  File "D:\anaconda\envs\PBFT\lib\asyncio\selector_events.py", line 475, in sock_connect
    return await fut
  File "D:\anaconda\envs\PBFT\lib\asyncio\selector_events.py", line 505, in _sock_connect_cb
    raise OSError(err, f'Connect call failed {address}')
ConnectionRefusedError: [Errno 10061] Connect call failed ('::1', 30141, 0, 0)

The above exception was the direct cause of the following exception:

Traceback (most recent call last):
  File "pbft.py", line 236, in send_message
    await send_with_delay(self.session, self.node_info, target, url, data, self.bandwidth_data)
  File "pbft.py", line 63, in send_with_delay
    async with session.post(url, json=data) as resp:
  File "D:\anaconda\envs\PBFT\lib\site-packages\aiohttp\client.py", line 1141, in __aenter__
    self._resp = await self._coro
  File "D:\anaconda\envs\PBFT\lib\site-packages\aiohttp\client.py", line 537, in _request
    req, traces=traces, timeout=real_timeout
  File "D:\anaconda\envs\PBFT\lib\site-packages\aiohttp\connector.py", line 540, in connect
    proto = await self._create_connection(req, traces, timeout)
  File "D:\anaconda\envs\PBFT\lib\site-packages\aiohttp\connector.py", line 901, in _create_connection
    _, proto = await self._create_direct_connection(req, traces, timeout)
  File "D:\anaconda\envs\PBFT\lib\site-packages\aiohttp\connector.py", line 1206, in _create_direct_connection
    raise last_exc
  File "D:\anaconda\envs\PBFT\lib\site-packages\aiohttp\connector.py", line 1187, in _create_direct_connection
    client_error=client_error,
  File "D:\anaconda\envs\PBFT\lib\site-packages\aiohttp\connector.py", line 988, in _wrap_create_connection
    raise client_error(req.connection_key, exc) from exc
aiohttp.client_exceptions.ClientConnectorError: Cannot connect to host localhost:30141 ssl:default [Connect call failed ('::1', 30141, 0, 0)]
[2025-03-07 13:53:51,835] [ERROR] [30158] Error sending to http://localhost:30124/commit: Cannot connect to host localhost:30124 ssl:default [Connect call failed ('::1', 30124, 0, 0)]
Traceback (most recent call last):
  File "D:\anaconda\envs\PBFT\lib\site-packages\aiohttp\connector.py", line 980, in _wrap_create_connection
    return await self._loop.create_connection(*args, **kwargs)  # type: ignore[return-value]  # noqa
  File "D:\anaconda\envs\PBFT\lib\asyncio\base_events.py", line 948, in create_connection
    raise exceptions[0]
  File "D:\anaconda\envs\PBFT\lib\asyncio\base_events.py", line 935, in create_connection
    await self.sock_connect(sock, address)
  File "D:\anaconda\envs\PBFT\lib\asyncio\selector_events.py", line 475, in sock_connect
    return await fut
  File "D:\anaconda\envs\PBFT\lib\asyncio\selector_events.py", line 505, in _sock_connect_cb
    raise OSError(err, f'Connect call failed {address}')
ConnectionRefusedError: [Errno 10061] Connect call failed ('::1', 30124, 0, 0)

The above exception was the direct cause of the following exception:

Traceback (most recent call last):
  File "pbft.py", line 236, in send_message
    await send_with_delay(self.session, self.node_info, target, url, data, self.bandwidth_data)
  File "pbft.py", line 63, in send_with_delay
    async with session.post(url, json=data) as resp:
  File "D:\anaconda\envs\PBFT\lib\site-packages\aiohttp\client.py", line 1141, in __aenter__
    self._resp = await self._coro
  File "D:\anaconda\envs\PBFT\lib\site-packages\aiohttp\client.py", line 537, in _request
    req, traces=traces, timeout=real_timeout
  File "D:\anaconda\envs\PBFT\lib\site-packages\aiohttp\connector.py", line 540, in connect
    proto = await self._create_connection(req, traces, timeout)
  File "D:\anaconda\envs\PBFT\lib\site-packages\aiohttp\connector.py", line 901, in _create_connection
    _, proto = await self._create_direct_connection(req, traces, timeout)
  File "D:\anaconda\envs\PBFT\lib\site-packages\aiohttp\connector.py", line 1206, in _create_direct_connection
    raise last_exc
  File "D:\anaconda\envs\PBFT\lib\site-packages\aiohttp\connector.py", line 1187, in _create_direct_connection
    client_error=client_error,
  File "D:\anaconda\envs\PBFT\lib\site-packages\aiohttp\connector.py", line 988, in _wrap_create_connection
    raise client_error(req.connection_key, exc) from exc
aiohttp.client_exceptions.ClientConnectorError: Cannot connect to host localhost:30124 ssl:default [Connect call failed ('::1', 30124, 0, 0)]
[2025-03-07 13:53:51,837] [ERROR] [30158] Error sending to http://localhost:30124/prepare: Cannot connect to host localhost:30124 ssl:default [Connect call failed ('127.0.0.1', 30124)]
Traceback (most recent call last):
  File "D:\anaconda\envs\PBFT\lib\site-packages\aiohttp\connector.py", line 980, in _wrap_create_connection
    return await self._loop.create_connection(*args, **kwargs)  # type: ignore[return-value]  # noqa
  File "D:\anaconda\envs\PBFT\lib\asyncio\base_events.py", line 948, in create_connection
    raise exceptions[0]
  File "D:\anaconda\envs\PBFT\lib\asyncio\base_events.py", line 935, in create_connection
    await self.sock_connect(sock, address)
  File "D:\anaconda\envs\PBFT\lib\asyncio\selector_events.py", line 475, in sock_connect
    return await fut
  File "D:\anaconda\envs\PBFT\lib\asyncio\selector_events.py", line 505, in _sock_connect_cb
    raise OSError(err, f'Connect call failed {address}')
ConnectionRefusedError: [Errno 10061] Connect call failed ('127.0.0.1', 30124)

The above exception was the direct cause of the following exception:

Traceback (most recent call last):
  File "pbft.py", line 236, in send_message
    await send_with_delay(self.session, self.node_info, target, url, data, self.bandwidth_data)
  File "pbft.py", line 63, in send_with_delay
    async with session.post(url, json=data) as resp:
  File "D:\anaconda\envs\PBFT\lib\site-packages\aiohttp\client.py", line 1141, in __aenter__
    self._resp = await self._coro
  File "D:\anaconda\envs\PBFT\lib\site-packages\aiohttp\client.py", line 537, in _request
    req, traces=traces, timeout=real_timeout
  File "D:\anaconda\envs\PBFT\lib\site-packages\aiohttp\connector.py", line 540, in connect
    proto = await self._create_connection(req, traces, timeout)
  File "D:\anaconda\envs\PBFT\lib\site-packages\aiohttp\connector.py", line 901, in _create_connection
    _, proto = await self._create_direct_connection(req, traces, timeout)
  File "D:\anaconda\envs\PBFT\lib\site-packages\aiohttp\connector.py", line 1206, in _create_direct_connection
    raise last_exc
  File "D:\anaconda\envs\PBFT\lib\site-packages\aiohttp\connector.py", line 1187, in _create_direct_connection
    client_error=client_error,
  File "D:\anaconda\envs\PBFT\lib\site-packages\aiohttp\connector.py", line 988, in _wrap_create_connection
    raise client_error(req.connection_key, exc) from exc
aiohttp.client_exceptions.ClientConnectorError: Cannot connect to host localhost:30124 ssl:default [Connect call failed ('127.0.0.1', 30124)]
[2025-03-07 13:53:51,882] [ERROR] [30158] Error sending to http://localhost:30138/prepare: Cannot connect to host localhost:30138 ssl:default [Connect call failed ('127.0.0.1', 30138)]
Traceback (most recent call last):
  File "D:\anaconda\envs\PBFT\lib\site-packages\aiohttp\connector.py", line 980, in _wrap_create_connection
    return await self._loop.create_connection(*args, **kwargs)  # type: ignore[return-value]  # noqa
  File "D:\anaconda\envs\PBFT\lib\asyncio\base_events.py", line 948, in create_connection
    raise exceptions[0]
  File "D:\anaconda\envs\PBFT\lib\asyncio\base_events.py", line 935, in create_connection
    await self.sock_connect(sock, address)
  File "D:\anaconda\envs\PBFT\lib\asyncio\selector_events.py", line 475, in sock_connect
    return await fut
  File "D:\anaconda\envs\PBFT\lib\asyncio\selector_events.py", line 505, in _sock_connect_cb
    raise OSError(err, f'Connect call failed {address}')
ConnectionRefusedError: [Errno 10061] Connect call failed ('127.0.0.1', 30138)

The above exception was the direct cause of the following exception:

Traceback (most recent call last):
  File "pbft.py", line 236, in send_message
    await send_with_delay(self.session, self.node_info, target, url, data, self.bandwidth_data)
  File "pbft.py", line 63, in send_with_delay
    async with session.post(url, json=data) as resp:
  File "D:\anaconda\envs\PBFT\lib\site-packages\aiohttp\client.py", line 1141, in __aenter__
    self._resp = await self._coro
  File "D:\anaconda\envs\PBFT\lib\site-packages\aiohttp\client.py", line 537, in _request
    req, traces=traces, timeout=real_timeout
  File "D:\anaconda\envs\PBFT\lib\site-packages\aiohttp\connector.py", line 540, in connect
    proto = await self._create_connection(req, traces, timeout)
  File "D:\anaconda\envs\PBFT\lib\site-packages\aiohttp\connector.py", line 901, in _create_connection
    _, proto = await self._create_direct_connection(req, traces, timeout)
  File "D:\anaconda\envs\PBFT\lib\site-packages\aiohttp\connector.py", line 1206, in _create_direct_connection
    raise last_exc
  File "D:\anaconda\envs\PBFT\lib\site-packages\aiohttp\connector.py", line 1187, in _create_direct_connection
    client_error=client_error,
  File "D:\anaconda\envs\PBFT\lib\site-packages\aiohttp\connector.py", line 988, in _wrap_create_connection
    raise client_error(req.connection_key, exc) from exc
aiohttp.client_exceptions.ClientConnectorError: Cannot connect to host localhost:30138 ssl:default [Connect call failed ('127.0.0.1', 30138)]
[2025-03-07 13:53:51,882] [INFO] [30158] Received PREPARE: id:1741323218379, from:30118, delay:0.0001s, distance:210.02m (Euclidean)
[2025-03-07 13:53:51,898] [ERROR] [30158] Error sending to http://localhost:30138/commit: Cannot connect to host localhost:30138 ssl:default [Connect call failed ('::1', 30138, 0, 0)]
Traceback (most recent call last):
  File "D:\anaconda\envs\PBFT\lib\site-packages\aiohttp\connector.py", line 980, in _wrap_create_connection
    return await self._loop.create_connection(*args, **kwargs)  # type: ignore[return-value]  # noqa
  File "D:\anaconda\envs\PBFT\lib\asyncio\base_events.py", line 948, in create_connection
    raise exceptions[0]
  File "D:\anaconda\envs\PBFT\lib\asyncio\base_events.py", line 935, in create_connection
    await self.sock_connect(sock, address)
  File "D:\anaconda\envs\PBFT\lib\asyncio\selector_events.py", line 475, in sock_connect
    return await fut
  File "D:\anaconda\envs\PBFT\lib\asyncio\selector_events.py", line 505, in _sock_connect_cb
    raise OSError(err, f'Connect call failed {address}')
ConnectionRefusedError: [Errno 10061] Connect call failed ('::1', 30138, 0, 0)

The above exception was the direct cause of the following exception:

Traceback (most recent call last):
  File "pbft.py", line 236, in send_message
    await send_with_delay(self.session, self.node_info, target, url, data, self.bandwidth_data)
  File "pbft.py", line 63, in send_with_delay
    async with session.post(url, json=data) as resp:
  File "D:\anaconda\envs\PBFT\lib\site-packages\aiohttp\client.py", line 1141, in __aenter__
    self._resp = await self._coro
  File "D:\anaconda\envs\PBFT\lib\site-packages\aiohttp\client.py", line 537, in _request
    req, traces=traces, timeout=real_timeout
  File "D:\anaconda\envs\PBFT\lib\site-packages\aiohttp\connector.py", line 540, in connect
    proto = await self._create_connection(req, traces, timeout)
  File "D:\anaconda\envs\PBFT\lib\site-packages\aiohttp\connector.py", line 901, in _create_connection
    _, proto = await self._create_direct_connection(req, traces, timeout)
  File "D:\anaconda\envs\PBFT\lib\site-packages\aiohttp\connector.py", line 1206, in _create_direct_connection
    raise last_exc
  File "D:\anaconda\envs\PBFT\lib\site-packages\aiohttp\connector.py", line 1187, in _create_direct_connection
    client_error=client_error,
  File "D:\anaconda\envs\PBFT\lib\site-packages\aiohttp\connector.py", line 988, in _wrap_create_connection
    raise client_error(req.connection_key, exc) from exc
aiohttp.client_exceptions.ClientConnectorError: Cannot connect to host localhost:30138 ssl:default [Connect call failed ('::1', 30138, 0, 0)]
[2025-03-07 13:53:52,236] [ERROR] [30158] Error sending to http://localhost:30103/commit: Cannot connect to host localhost:30103 ssl:default [Connect call failed ('::1', 30103, 0, 0)]
Traceback (most recent call last):
  File "D:\anaconda\envs\PBFT\lib\site-packages\aiohttp\connector.py", line 980, in _wrap_create_connection
    return await self._loop.create_connection(*args, **kwargs)  # type: ignore[return-value]  # noqa
  File "D:\anaconda\envs\PBFT\lib\asyncio\base_events.py", line 948, in create_connection
    raise exceptions[0]
  File "D:\anaconda\envs\PBFT\lib\asyncio\base_events.py", line 935, in create_connection
    await self.sock_connect(sock, address)
  File "D:\anaconda\envs\PBFT\lib\asyncio\selector_events.py", line 475, in sock_connect
    return await fut
  File "D:\anaconda\envs\PBFT\lib\asyncio\selector_events.py", line 505, in _sock_connect_cb
    raise OSError(err, f'Connect call failed {address}')
ConnectionRefusedError: [Errno 10061] Connect call failed ('::1', 30103, 0, 0)

The above exception was the direct cause of the following exception:

Traceback (most recent call last):
  File "pbft.py", line 236, in send_message
    await send_with_delay(self.session, self.node_info, target, url, data, self.bandwidth_data)
  File "pbft.py", line 63, in send_with_delay
    async with session.post(url, json=data) as resp:
  File "D:\anaconda\envs\PBFT\lib\site-packages\aiohttp\client.py", line 1141, in __aenter__
    self._resp = await self._coro
  File "D:\anaconda\envs\PBFT\lib\site-packages\aiohttp\client.py", line 537, in _request
    req, traces=traces, timeout=real_timeout
  File "D:\anaconda\envs\PBFT\lib\site-packages\aiohttp\connector.py", line 540, in connect
    proto = await self._create_connection(req, traces, timeout)
  File "D:\anaconda\envs\PBFT\lib\site-packages\aiohttp\connector.py", line 901, in _create_connection
    _, proto = await self._create_direct_connection(req, traces, timeout)
  File "D:\anaconda\envs\PBFT\lib\site-packages\aiohttp\connector.py", line 1206, in _create_direct_connection
    raise last_exc
  File "D:\anaconda\envs\PBFT\lib\site-packages\aiohttp\connector.py", line 1187, in _create_direct_connection
    client_error=client_error,
  File "D:\anaconda\envs\PBFT\lib\site-packages\aiohttp\connector.py", line 988, in _wrap_create_connection
    raise client_error(req.connection_key, exc) from exc
aiohttp.client_exceptions.ClientConnectorError: Cannot connect to host localhost:30103 ssl:default [Connect call failed ('::1', 30103, 0, 0)]
[2025-03-07 13:53:52,236] [ERROR] [30158] Error sending to http://localhost:30103/prepare: Cannot connect to host localhost:30103 ssl:default [Connect call failed ('127.0.0.1', 30103)]
Traceback (most recent call last):
  File "D:\anaconda\envs\PBFT\lib\site-packages\aiohttp\connector.py", line 980, in _wrap_create_connection
    return await self._loop.create_connection(*args, **kwargs)  # type: ignore[return-value]  # noqa
  File "D:\anaconda\envs\PBFT\lib\asyncio\base_events.py", line 948, in create_connection
    raise exceptions[0]
  File "D:\anaconda\envs\PBFT\lib\asyncio\base_events.py", line 935, in create_connection
    await self.sock_connect(sock, address)
  File "D:\anaconda\envs\PBFT\lib\asyncio\selector_events.py", line 475, in sock_connect
    return await fut
  File "D:\anaconda\envs\PBFT\lib\asyncio\selector_events.py", line 505, in _sock_connect_cb
    raise OSError(err, f'Connect call failed {address}')
ConnectionRefusedError: [Errno 10061] Connect call failed ('127.0.0.1', 30103)

The above exception was the direct cause of the following exception:

Traceback (most recent call last):
  File "pbft.py", line 236, in send_message
    await send_with_delay(self.session, self.node_info, target, url, data, self.bandwidth_data)
  File "pbft.py", line 63, in send_with_delay
    async with session.post(url, json=data) as resp:
  File "D:\anaconda\envs\PBFT\lib\site-packages\aiohttp\client.py", line 1141, in __aenter__
    self._resp = await self._coro
  File "D:\anaconda\envs\PBFT\lib\site-packages\aiohttp\client.py", line 537, in _request
    req, traces=traces, timeout=real_timeout
  File "D:\anaconda\envs\PBFT\lib\site-packages\aiohttp\connector.py", line 540, in connect
    proto = await self._create_connection(req, traces, timeout)
  File "D:\anaconda\envs\PBFT\lib\site-packages\aiohttp\connector.py", line 901, in _create_connection
    _, proto = await self._create_direct_connection(req, traces, timeout)
  File "D:\anaconda\envs\PBFT\lib\site-packages\aiohttp\connector.py", line 1206, in _create_direct_connection
    raise last_exc
  File "D:\anaconda\envs\PBFT\lib\site-packages\aiohttp\connector.py", line 1187, in _create_direct_connection
    client_error=client_error,
  File "D:\anaconda\envs\PBFT\lib\site-packages\aiohttp\connector.py", line 988, in _wrap_create_connection
    raise client_error(req.connection_key, exc) from exc
aiohttp.client_exceptions.ClientConnectorError: Cannot connect to host localhost:30103 ssl:default [Connect call failed ('127.0.0.1', 30103)]
[2025-03-07 13:53:52,242] [ERROR] [30158] Error sending to http://localhost:30101/prepare: Cannot connect to host localhost:30101 ssl:default [Connect call failed ('127.0.0.1', 30101)]
Traceback (most recent call last):
  File "D:\anaconda\envs\PBFT\lib\site-packages\aiohttp\connector.py", line 980, in _wrap_create_connection
    return await self._loop.create_connection(*args, **kwargs)  # type: ignore[return-value]  # noqa
  File "D:\anaconda\envs\PBFT\lib\asyncio\base_events.py", line 948, in create_connection
    raise exceptions[0]
  File "D:\anaconda\envs\PBFT\lib\asyncio\base_events.py", line 935, in create_connection
    await self.sock_connect(sock, address)
  File "D:\anaconda\envs\PBFT\lib\asyncio\selector_events.py", line 475, in sock_connect
    return await fut
  File "D:\anaconda\envs\PBFT\lib\asyncio\selector_events.py", line 505, in _sock_connect_cb
    raise OSError(err, f'Connect call failed {address}')
ConnectionRefusedError: [Errno 10061] Connect call failed ('127.0.0.1', 30101)

The above exception was the direct cause of the following exception:

Traceback (most recent call last):
  File "pbft.py", line 236, in send_message
    await send_with_delay(self.session, self.node_info, target, url, data, self.bandwidth_data)
  File "pbft.py", line 63, in send_with_delay
    async with session.post(url, json=data) as resp:
  File "D:\anaconda\envs\PBFT\lib\site-packages\aiohttp\client.py", line 1141, in __aenter__
    self._resp = await self._coro
  File "D:\anaconda\envs\PBFT\lib\site-packages\aiohttp\client.py", line 537, in _request
    req, traces=traces, timeout=real_timeout
  File "D:\anaconda\envs\PBFT\lib\site-packages\aiohttp\connector.py", line 540, in connect
    proto = await self._create_connection(req, traces, timeout)
  File "D:\anaconda\envs\PBFT\lib\site-packages\aiohttp\connector.py", line 901, in _create_connection
    _, proto = await self._create_direct_connection(req, traces, timeout)
  File "D:\anaconda\envs\PBFT\lib\site-packages\aiohttp\connector.py", line 1206, in _create_direct_connection
    raise last_exc
  File "D:\anaconda\envs\PBFT\lib\site-packages\aiohttp\connector.py", line 1187, in _create_direct_connection
    client_error=client_error,
  File "D:\anaconda\envs\PBFT\lib\site-packages\aiohttp\connector.py", line 988, in _wrap_create_connection
    raise client_error(req.connection_key, exc) from exc
aiohttp.client_exceptions.ClientConnectorError: Cannot connect to host localhost:30101 ssl:default [Connect call failed ('127.0.0.1', 30101)]
[2025-03-07 13:53:52,244] [ERROR] [30158] Error sending to http://localhost:30101/commit: Cannot connect to host localhost:30101 ssl:default [Connect call failed ('::1', 30101, 0, 0)]
Traceback (most recent call last):
  File "D:\anaconda\envs\PBFT\lib\site-packages\aiohttp\connector.py", line 980, in _wrap_create_connection
    return await self._loop.create_connection(*args, **kwargs)  # type: ignore[return-value]  # noqa
  File "D:\anaconda\envs\PBFT\lib\asyncio\base_events.py", line 948, in create_connection
    raise exceptions[0]
  File "D:\anaconda\envs\PBFT\lib\asyncio\base_events.py", line 935, in create_connection
    await self.sock_connect(sock, address)
  File "D:\anaconda\envs\PBFT\lib\asyncio\selector_events.py", line 475, in sock_connect
    return await fut
  File "D:\anaconda\envs\PBFT\lib\asyncio\selector_events.py", line 505, in _sock_connect_cb
    raise OSError(err, f'Connect call failed {address}')
ConnectionRefusedError: [Errno 10061] Connect call failed ('::1', 30101, 0, 0)

The above exception was the direct cause of the following exception:

Traceback (most recent call last):
  File "pbft.py", line 236, in send_message
    await send_with_delay(self.session, self.node_info, target, url, data, self.bandwidth_data)
  File "pbft.py", line 63, in send_with_delay
    async with session.post(url, json=data) as resp:
  File "D:\anaconda\envs\PBFT\lib\site-packages\aiohttp\client.py", line 1141, in __aenter__
    self._resp = await self._coro
  File "D:\anaconda\envs\PBFT\lib\site-packages\aiohttp\client.py", line 537, in _request
    req, traces=traces, timeout=real_timeout
  File "D:\anaconda\envs\PBFT\lib\site-packages\aiohttp\connector.py", line 540, in connect
    proto = await self._create_connection(req, traces, timeout)
  File "D:\anaconda\envs\PBFT\lib\site-packages\aiohttp\connector.py", line 901, in _create_connection
    _, proto = await self._create_direct_connection(req, traces, timeout)
  File "D:\anaconda\envs\PBFT\lib\site-packages\aiohttp\connector.py", line 1206, in _create_direct_connection
    raise last_exc
  File "D:\anaconda\envs\PBFT\lib\site-packages\aiohttp\connector.py", line 1187, in _create_direct_connection
    client_error=client_error,
  File "D:\anaconda\envs\PBFT\lib\site-packages\aiohttp\connector.py", line 988, in _wrap_create_connection
    raise client_error(req.connection_key, exc) from exc
aiohttp.client_exceptions.ClientConnectorError: Cannot connect to host localhost:30101 ssl:default [Connect call failed ('::1', 30101, 0, 0)]
[2025-03-07 13:53:52,323] [ERROR] [30158] Error sending to http://localhost:30137/prepare: Cannot connect to host localhost:30137 ssl:default [Connect call failed ('127.0.0.1', 30137)]
Traceback (most recent call last):
  File "D:\anaconda\envs\PBFT\lib\site-packages\aiohttp\connector.py", line 980, in _wrap_create_connection
    return await self._loop.create_connection(*args, **kwargs)  # type: ignore[return-value]  # noqa
  File "D:\anaconda\envs\PBFT\lib\asyncio\base_events.py", line 948, in create_connection
    raise exceptions[0]
  File "D:\anaconda\envs\PBFT\lib\asyncio\base_events.py", line 935, in create_connection
    await self.sock_connect(sock, address)
  File "D:\anaconda\envs\PBFT\lib\asyncio\selector_events.py", line 475, in sock_connect
    return await fut
  File "D:\anaconda\envs\PBFT\lib\asyncio\selector_events.py", line 505, in _sock_connect_cb
    raise OSError(err, f'Connect call failed {address}')
ConnectionRefusedError: [Errno 10061] Connect call failed ('127.0.0.1', 30137)

The above exception was the direct cause of the following exception:

Traceback (most recent call last):
  File "pbft.py", line 236, in send_message
    await send_with_delay(self.session, self.node_info, target, url, data, self.bandwidth_data)
  File "pbft.py", line 63, in send_with_delay
    async with session.post(url, json=data) as resp:
  File "D:\anaconda\envs\PBFT\lib\site-packages\aiohttp\client.py", line 1141, in __aenter__
    self._resp = await self._coro
  File "D:\anaconda\envs\PBFT\lib\site-packages\aiohttp\client.py", line 537, in _request
    req, traces=traces, timeout=real_timeout
  File "D:\anaconda\envs\PBFT\lib\site-packages\aiohttp\connector.py", line 540, in connect
    proto = await self._create_connection(req, traces, timeout)
  File "D:\anaconda\envs\PBFT\lib\site-packages\aiohttp\connector.py", line 901, in _create_connection
    _, proto = await self._create_direct_connection(req, traces, timeout)
  File "D:\anaconda\envs\PBFT\lib\site-packages\aiohttp\connector.py", line 1206, in _create_direct_connection
    raise last_exc
  File "D:\anaconda\envs\PBFT\lib\site-packages\aiohttp\connector.py", line 1187, in _create_direct_connection
    client_error=client_error,
  File "D:\anaconda\envs\PBFT\lib\site-packages\aiohttp\connector.py", line 988, in _wrap_create_connection
    raise client_error(req.connection_key, exc) from exc
aiohttp.client_exceptions.ClientConnectorError: Cannot connect to host localhost:30137 ssl:default [Connect call failed ('127.0.0.1', 30137)]
[2025-03-07 13:53:52,323] [ERROR] [30158] Error sending to http://localhost:30137/commit: Cannot connect to host localhost:30137 ssl:default [Connect call failed ('::1', 30137, 0, 0)]
Traceback (most recent call last):
  File "D:\anaconda\envs\PBFT\lib\site-packages\aiohttp\connector.py", line 980, in _wrap_create_connection
    return await self._loop.create_connection(*args, **kwargs)  # type: ignore[return-value]  # noqa
  File "D:\anaconda\envs\PBFT\lib\asyncio\base_events.py", line 948, in create_connection
    raise exceptions[0]
  File "D:\anaconda\envs\PBFT\lib\asyncio\base_events.py", line 935, in create_connection
    await self.sock_connect(sock, address)
  File "D:\anaconda\envs\PBFT\lib\asyncio\selector_events.py", line 475, in sock_connect
    return await fut
  File "D:\anaconda\envs\PBFT\lib\asyncio\selector_events.py", line 505, in _sock_connect_cb
    raise OSError(err, f'Connect call failed {address}')
ConnectionRefusedError: [Errno 10061] Connect call failed ('::1', 30137, 0, 0)

The above exception was the direct cause of the following exception:

Traceback (most recent call last):
  File "pbft.py", line 236, in send_message
    await send_with_delay(self.session, self.node_info, target, url, data, self.bandwidth_data)
  File "pbft.py", line 63, in send_with_delay
    async with session.post(url, json=data) as resp:
  File "D:\anaconda\envs\PBFT\lib\site-packages\aiohttp\client.py", line 1141, in __aenter__
    self._resp = await self._coro
  File "D:\anaconda\envs\PBFT\lib\site-packages\aiohttp\client.py", line 537, in _request
    req, traces=traces, timeout=real_timeout
  File "D:\anaconda\envs\PBFT\lib\site-packages\aiohttp\connector.py", line 540, in connect
    proto = await self._create_connection(req, traces, timeout)
  File "D:\anaconda\envs\PBFT\lib\site-packages\aiohttp\connector.py", line 901, in _create_connection
    _, proto = await self._create_direct_connection(req, traces, timeout)
  File "D:\anaconda\envs\PBFT\lib\site-packages\aiohttp\connector.py", line 1206, in _create_direct_connection
    raise last_exc
  File "D:\anaconda\envs\PBFT\lib\site-packages\aiohttp\connector.py", line 1187, in _create_direct_connection
    client_error=client_error,
  File "D:\anaconda\envs\PBFT\lib\site-packages\aiohttp\connector.py", line 988, in _wrap_create_connection
    raise client_error(req.connection_key, exc) from exc
aiohttp.client_exceptions.ClientConnectorError: Cannot connect to host localhost:30137 ssl:default [Connect call failed ('::1', 30137, 0, 0)]
[2025-03-07 13:53:52,338] [ERROR] [30158] Error sending to http://localhost:30125/prepare: Cannot connect to host localhost:30125 ssl:default [Connect call failed ('127.0.0.1', 30125)]
Traceback (most recent call last):
  File "D:\anaconda\envs\PBFT\lib\site-packages\aiohttp\connector.py", line 980, in _wrap_create_connection
    return await self._loop.create_connection(*args, **kwargs)  # type: ignore[return-value]  # noqa
  File "D:\anaconda\envs\PBFT\lib\asyncio\base_events.py", line 948, in create_connection
    raise exceptions[0]
  File "D:\anaconda\envs\PBFT\lib\asyncio\base_events.py", line 935, in create_connection
    await self.sock_connect(sock, address)
  File "D:\anaconda\envs\PBFT\lib\asyncio\selector_events.py", line 475, in sock_connect
    return await fut
  File "D:\anaconda\envs\PBFT\lib\asyncio\selector_events.py", line 505, in _sock_connect_cb
    raise OSError(err, f'Connect call failed {address}')
ConnectionRefusedError: [Errno 10061] Connect call failed ('127.0.0.1', 30125)

The above exception was the direct cause of the following exception:

Traceback (most recent call last):
  File "pbft.py", line 236, in send_message
    await send_with_delay(self.session, self.node_info, target, url, data, self.bandwidth_data)
  File "pbft.py", line 63, in send_with_delay
    async with session.post(url, json=data) as resp:
  File "D:\anaconda\envs\PBFT\lib\site-packages\aiohttp\client.py", line 1141, in __aenter__
    self._resp = await self._coro
  File "D:\anaconda\envs\PBFT\lib\site-packages\aiohttp\client.py", line 537, in _request
    req, traces=traces, timeout=real_timeout
  File "D:\anaconda\envs\PBFT\lib\site-packages\aiohttp\connector.py", line 540, in connect
    proto = await self._create_connection(req, traces, timeout)
  File "D:\anaconda\envs\PBFT\lib\site-packages\aiohttp\connector.py", line 901, in _create_connection
    _, proto = await self._create_direct_connection(req, traces, timeout)
  File "D:\anaconda\envs\PBFT\lib\site-packages\aiohttp\connector.py", line 1206, in _create_direct_connection
    raise last_exc
  File "D:\anaconda\envs\PBFT\lib\site-packages\aiohttp\connector.py", line 1187, in _create_direct_connection
    client_error=client_error,
  File "D:\anaconda\envs\PBFT\lib\site-packages\aiohttp\connector.py", line 988, in _wrap_create_connection
    raise client_error(req.connection_key, exc) from exc
aiohttp.client_exceptions.ClientConnectorError: Cannot connect to host localhost:30125 ssl:default [Connect call failed ('127.0.0.1', 30125)]
[2025-03-07 13:53:52,338] [ERROR] [30158] Error sending to http://localhost:30125/commit: Cannot connect to host localhost:30125 ssl:default [Connect call failed ('::1', 30125, 0, 0)]
Traceback (most recent call last):
  File "D:\anaconda\envs\PBFT\lib\site-packages\aiohttp\connector.py", line 980, in _wrap_create_connection
    return await self._loop.create_connection(*args, **kwargs)  # type: ignore[return-value]  # noqa
  File "D:\anaconda\envs\PBFT\lib\asyncio\base_events.py", line 948, in create_connection
    raise exceptions[0]
  File "D:\anaconda\envs\PBFT\lib\asyncio\base_events.py", line 935, in create_connection
    await self.sock_connect(sock, address)
  File "D:\anaconda\envs\PBFT\lib\asyncio\selector_events.py", line 475, in sock_connect
    return await fut
  File "D:\anaconda\envs\PBFT\lib\asyncio\selector_events.py", line 505, in _sock_connect_cb
    raise OSError(err, f'Connect call failed {address}')
ConnectionRefusedError: [Errno 10061] Connect call failed ('::1', 30125, 0, 0)

The above exception was the direct cause of the following exception:

Traceback (most recent call last):
  File "pbft.py", line 236, in send_message
    await send_with_delay(self.session, self.node_info, target, url, data, self.bandwidth_data)
  File "pbft.py", line 63, in send_with_delay
    async with session.post(url, json=data) as resp:
  File "D:\anaconda\envs\PBFT\lib\site-packages\aiohttp\client.py", line 1141, in __aenter__
    self._resp = await self._coro
  File "D:\anaconda\envs\PBFT\lib\site-packages\aiohttp\client.py", line 537, in _request
    req, traces=traces, timeout=real_timeout
  File "D:\anaconda\envs\PBFT\lib\site-packages\aiohttp\connector.py", line 540, in connect
    proto = await self._create_connection(req, traces, timeout)
  File "D:\anaconda\envs\PBFT\lib\site-packages\aiohttp\connector.py", line 901, in _create_connection
    _, proto = await self._create_direct_connection(req, traces, timeout)
  File "D:\anaconda\envs\PBFT\lib\site-packages\aiohttp\connector.py", line 1206, in _create_direct_connection
    raise last_exc
  File "D:\anaconda\envs\PBFT\lib\site-packages\aiohttp\connector.py", line 1187, in _create_direct_connection
    client_error=client_error,
  File "D:\anaconda\envs\PBFT\lib\site-packages\aiohttp\connector.py", line 988, in _wrap_create_connection
    raise client_error(req.connection_key, exc) from exc
aiohttp.client_exceptions.ClientConnectorError: Cannot connect to host localhost:30125 ssl:default [Connect call failed ('::1', 30125, 0, 0)]
[2025-03-07 13:53:52,597] [INFO] [30158] Received COMMIT: id:1741323218379, from:30118, delay:0.0001s, distance:210.02m (Euclidean)
[2025-03-07 13:53:52,648] [INFO] [30158] Received PREPARE: id:1741323218379, from:30121, delay:0.0001s, distance:192.45m (Euclidean)
[2025-03-07 13:53:52,648] [INFO] [30158] Received COMMIT: id:1741323218379, from:30121, delay:0.0001s, distance:192.45m (Euclidean)
[2025-03-07 13:53:52,909] [INFO] [30158] Received PREPARE: id:1741323218379, from:30129, delay:0.0001s, distance:201.08m (Euclidean)
[2025-03-07 13:53:52,909] [INFO] [30158] Received COMMIT: id:1741323218379, from:30129, delay:0.0001s, distance:201.08m (Euclidean)
[2025-03-07 13:53:53,196] [INFO] [30158] Received PREPARE: id:1741323218379, from:30123, delay:0.0000s, distance:140.88m (Euclidean)
[2025-03-07 13:53:53,208] [INFO] [30158] Received COMMIT: id:1741323218379, from:30123, delay:0.0000s, distance:140.88m (Euclidean)
[2025-03-07 13:53:53,242] [INFO] [30158] Received PREPARE: id:1741323218379, from:30113, delay:0.0000s, distance:127.33m (Euclidean)
[2025-03-07 13:53:53,242] [INFO] [30158] Received COMMIT: id:1741323218379, from:30113, delay:0.0000s, distance:127.33m (Euclidean)
[2025-03-07 13:53:53,687] [INFO] [30158] Received PREPARE: id:1741323218379, from:30149, delay:0.0000s, distance:141.44m (Euclidean)
[2025-03-07 13:53:53,687] [INFO] [30158] Received COMMIT: id:1741323218379, from:30149, delay:0.0000s, distance:141.44m (Euclidean)
[2025-03-07 13:53:53,944] [INFO] [30158] Received PREPARE: id:1741323218379, from:30127, delay:0.0002s, distance:266.60m (Euclidean)
[2025-03-07 13:53:53,944] [INFO] [30158] Received COMMIT: id:1741323218379, from:30127, delay:0.0002s, distance:266.60m (Euclidean)
[2025-03-07 13:53:54,018] [INFO] [30158] Received PREPARE: id:1741323218379, from:30142, delay:0.0001s, distance:175.45m (Euclidean)
[2025-03-07 13:53:54,034] [INFO] [30158] Received COMMIT: id:1741323218379, from:30142, delay:0.0001s, distance:175.45m (Euclidean)
[2025-03-07 13:53:54,217] [INFO] [30158] Received PREPARE: id:1741323218379, from:30111, delay:0.0000s, distance:146.79m (Euclidean)
[2025-03-07 13:53:54,217] [INFO] [30158] Received COMMIT: id:1741323218379, from:30111, delay:0.0000s, distance:146.79m (Euclidean)
[2025-03-07 13:53:54,224] [INFO] [30158] Received PREPARE: id:1741323218379, from:30132, delay:0.0002s, distance:292.26m (Euclidean)
[2025-03-07 13:53:54,224] [INFO] [30158] Received COMMIT: id:1741323218379, from:30132, delay:0.0002s, distance:292.26m (Euclidean)
[2025-03-07 13:53:54,224] [INFO] [30158] Received PREPARE: id:1741323218379, from:30106, delay:0.0002s, distance:276.15m (Euclidean)
[2025-03-07 13:53:54,224] [INFO] [30158] Received COMMIT: id:1741323218379, from:30106, delay:0.0002s, distance:276.15m (Euclidean)
[2025-03-07 13:53:54,239] [INFO] [30158] Received PREPARE: id:1741323218379, from:30156, delay:0.0002s, distance:256.86m (Euclidean)
[2025-03-07 13:53:54,246] [INFO] [30158] Received COMMIT: id:1741323218379, from:30156, delay:0.0002s, distance:256.86m (Euclidean)
[2025-03-07 13:53:54,397] [INFO] [30158] Received PREPARE: id:1741323218379, from:30145, delay:0.0002s, distance:288.96m (Euclidean)
[2025-03-07 13:53:54,403] [INFO] [30158] Received PREPARE: id:1741323218379, from:30150, delay:0.0002s, distance:275.99m (Euclidean)
[2025-03-07 13:53:54,405] [INFO] [30158] Received COMMIT: id:1741323218379, from:30150, delay:0.0002s, distance:275.99m (Euclidean)
[2025-03-07 13:53:54,405] [INFO] [30158] Received COMMIT: id:1741323218379, from:30145, delay:0.0002s, distance:288.96m (Euclidean)
[2025-03-07 13:53:54,487] [INFO] [30158] Received PREPARE: id:1741323218379, from:30152, delay:0.0002s, distance:264.30m (Euclidean)
[2025-03-07 13:53:54,491] [INFO] [30158] Received PREPARE: id:1741323218379, from:30146, delay:0.0001s, distance:218.02m (Euclidean)
[2025-03-07 13:53:54,499] [INFO] [30158] Received PREPARE: id:1741323218379, from:30120, delay:0.0001s, distance:206.89m (Euclidean)
[2025-03-07 13:53:54,511] [INFO] [30158] Received COMMIT: id:1741323218379, from:30152, delay:0.0002s, distance:264.30m (Euclidean)
[2025-03-07 13:53:54,511] [INFO] [30158] Received PREPARE: id:1741323218379, from:30108, delay:0.0002s, distance:255.57m (Euclidean)
[2025-03-07 13:53:54,524] [INFO] [30158] Received COMMIT: id:1741323218379, from:30146, delay:0.0001s, distance:218.02m (Euclidean)
[2025-03-07 13:53:54,528] [INFO] [30158] Received COMMIT: id:1741323218379, from:30108, delay:0.0002s, distance:255.57m (Euclidean)
[2025-03-07 13:53:54,532] [INFO] [30158] Received COMMIT: id:1741323218379, from:30120, delay:0.0001s, distance:206.89m (Euclidean)
[2025-03-07 13:53:54,533] [INFO] [30158] Received PREPARE: id:1741323218379, from:30115, delay:0.0001s, distance:226.55m (Euclidean)
[2025-03-07 13:53:54,596] [INFO] [30158] Received COMMIT: id:1741323218379, from:30115, delay:0.0001s, distance:226.55m (Euclidean)
[2025-03-07 13:53:55,658] [INFO] [30158] Received PREPARE: id:1741323218379, from:30022, delay:0.0002s, distance:284.00m (Euclidean)
[2025-03-07 13:53:55,669] [INFO] [30158] Received COMMIT: id:1741323218379, from:30022, delay:0.0002s, distance:284.00m (Euclidean)
[2025-03-07 13:53:55,692] [INFO] [30158] Received PREPARE: id:1741323218379, from:30155, delay:0.0002s, distance:272.64m (Euclidean)
[2025-03-07 13:53:55,692] [INFO] [30158] Received COMMIT: id:1741323218379, from:30155, delay:0.0002s, distance:272.64m (Euclidean)
[2025-03-07 13:54:59,489] [INFO] Starting node at localhost:30158 | index=159 | f=1, k=4 | Role: Replica
[2025-03-07 13:57:45,927] [INFO] Starting node at localhost:30158 | index=159 | f=1, k=4 | Role: Replica
[2025-03-07 13:58:48,352] [INFO] Starting node at localhost:30158 | index=159 | f=1, k=4 | Role: Replica
[2025-03-07 13:59:02,579] [INFO] [30158] Received PRE-PREPARE: id:1741323542381, from:Leader(30000), delay:0.0000s, distance:140.01m (Euclidean)
[2025-03-07 13:59:02,579] [INFO] [30158] Broadcasting PREPARE for REQUEST 1741323542381
[2025-03-07 13:59:02,591] [INFO] [30158] Not broadcasting to fault node: 30077
[2025-03-07 13:59:02,607] [INFO] [30158] Not broadcasting to fault node: 30184
[2025-03-07 13:59:03,120] [INFO] [30158] Received PREPARE: id:1741323542381, from:30133, delay:0.0000s, distance:200.52m (Euclidean)
[2025-03-07 13:59:03,581] [INFO] [30158] Received PREPARE: id:1741323542381, from:30005, delay:0.0000s, distance:200.53m (Euclidean)
[2025-03-07 13:59:03,581] [INFO] [30158] Broadcasting COMMIT for REQUEST 1741323542381
[2025-03-07 13:59:03,596] [INFO] [30158] Not broadcasting to fault node: 30077
[2025-03-07 13:59:03,613] [INFO] [30158] Not broadcasting to fault node: 30184
[2025-03-07 13:59:03,669] [INFO] [30158] Received PREPARE: id:1741323542381, from:30110, delay:0.0000s, distance:46.94m (Euclidean)
[2025-03-07 13:59:03,754] [INFO] [30158] Received PREPARE: id:1741323542381, from:30155, delay:0.0000s, distance:141.84m (Euclidean)
[2025-03-07 13:59:03,849] [INFO] [30158] Received COMMIT: id:1741323542381, from:30155, delay:0.0000s, distance:141.84m (Euclidean)
[2025-03-07 13:59:03,926] [INFO] [30158] Received PREPARE: id:1741323542381, from:30126, delay:0.0000s, distance:95.83m (Euclidean)
[2025-03-07 13:59:04,225] [INFO] [30158] Received COMMIT: id:1741323542381, from:30005, delay:0.0000s, distance:200.53m (Euclidean)
[2025-03-07 13:59:04,225] [INFO] [LEADER 30158] Sending REPLY for REQUEST 1741323542381 to CLIENT
[2025-03-07 13:59:04,249] [INFO] [30158] Received COMMIT: id:1741323542381, from:30133, delay:0.0000s, distance:200.52m (Euclidean)
[2025-03-07 13:59:04,318] [INFO] [30158] Received COMMIT: id:1741323542381, from:30110, delay:0.0000s, distance:46.94m (Euclidean)
[2025-03-07 13:59:04,348] [INFO] [30158] Received PREPARE: id:1741323542381, from:30147, delay:0.0000s, distance:95.30m (Euclidean)
[2025-03-07 13:59:04,433] [INFO] [30158] Received PREPARE: id:1741323542381, from:30119, delay:0.0001s, distance:192.78m (Euclidean)
[2025-03-07 13:59:04,820] [INFO] [30158] Received PREPARE: id:1741323542381, from:30128, delay:0.0000s, distance:75.86m (Euclidean)
[2025-03-07 13:59:04,820] [INFO] [30158] Received COMMIT: id:1741323542381, from:30147, delay:0.0000s, distance:95.30m (Euclidean)
[2025-03-07 13:59:04,820] [INFO] [30158] Received PREPARE: id:1741323542381, from:30157, delay:0.0001s, distance:213.34m (Euclidean)
[2025-03-07 13:59:04,834] [INFO] [30158] Received COMMIT: id:1741323542381, from:30128, delay:0.0000s, distance:75.86m (Euclidean)
[2025-03-07 13:59:04,878] [INFO] [30158] Received PREPARE: id:1741323542381, from:30144, delay:0.0000s, distance:128.77m (Euclidean)
[2025-03-07 13:59:04,947] [INFO] [30158] Received COMMIT: id:1741323542381, from:30144, delay:0.0000s, distance:128.77m (Euclidean)
[2025-03-07 13:59:04,976] [INFO] [30158] Received PREPARE: id:1741323542381, from:30195, delay:0.0001s, distance:187.22m (Euclidean)
[2025-03-07 13:59:04,976] [INFO] [30158] Received COMMIT: id:1741323542381, from:30195, delay:0.0001s, distance:187.22m (Euclidean)
[2025-03-07 13:59:05,378] [INFO] [30158] Received COMMIT: id:1741323542381, from:30190, delay:0.0000s, distance:149.35m (Euclidean)
[2025-03-07 13:59:05,378] [INFO] [30158] Received PREPARE: id:1741323542381, from:30029, delay:0.0001s, distance:194.86m (Euclidean)
[2025-03-07 13:59:05,378] [INFO] [30158] Received PREPARE: id:1741323542381, from:30190, delay:0.0000s, distance:149.35m (Euclidean)
[2025-03-07 13:59:05,852] [INFO] [30158] Received PREPARE: id:1741323542381, from:30116, delay:0.0000s, distance:143.42m (Euclidean)
[2025-03-07 13:59:05,852] [INFO] [30158] Received COMMIT: id:1741323542381, from:30029, delay:0.0001s, distance:194.86m (Euclidean)
[2025-03-07 13:59:05,946] [INFO] [30158] Received PREPARE: id:1741323542381, from:30108, delay:0.0001s, distance:207.13m (Euclidean)
[2025-03-07 13:59:06,082] [INFO] [30158] Received PREPARE: id:1741323542381, from:30189, delay:0.0001s, distance:248.35m (Euclidean)
[2025-03-07 13:59:06,082] [INFO] [30158] Received COMMIT: id:1741323542381, from:30157, delay:0.0001s, distance:213.34m (Euclidean)
[2025-03-07 13:59:06,082] [INFO] [30158] Received COMMIT: id:1741323542381, from:30126, delay:0.0000s, distance:95.83m (Euclidean)
[2025-03-07 13:59:06,082] [INFO] [30158] Received PREPARE: id:1741323542381, from:30199, delay:0.0001s, distance:156.82m (Euclidean)
[2025-03-07 13:59:07,371] [INFO] [30158] Received PREPARE: id:1741323542381, from:30176, delay:0.0000s, distance:192.72m (Euclidean)
[2025-03-07 13:59:07,398] [INFO] [30158] Received PREPARE: id:1741323542381, from:30021, delay:0.0000s, distance:78.42m (Euclidean)
[2025-03-07 13:59:07,400] [INFO] [30158] Received PREPARE: id:1741323542381, from:30115, delay:0.0001s, distance:207.88m (Euclidean)
[2025-03-07 13:59:07,400] [INFO] [30158] Received PREPARE: id:1741323542381, from:30053, delay:0.0000s, distance:190.30m (Euclidean)
[2025-03-07 13:59:07,400] [INFO] [30158] Received COMMIT: id:1741323542381, from:30176, delay:0.0000s, distance:192.72m (Euclidean)
[2025-03-07 13:59:07,400] [INFO] [30158] Received PREPARE: id:1741323542381, from:30130, delay:0.0001s, distance:239.93m (Euclidean)
[2025-03-07 13:59:07,400] [INFO] [30158] Received PREPARE: id:1741323542381, from:30179, delay:0.0000s, distance:149.46m (Euclidean)
[2025-03-07 13:59:07,857] [INFO] [30158] Received COMMIT: id:1741323542381, from:30179, delay:0.0000s, distance:149.46m (Euclidean)
[2025-03-07 13:59:07,857] [INFO] [30158] Received PREPARE: id:1741323542381, from:30049, delay:0.0000s, distance:187.06m (Euclidean)
[2025-03-07 13:59:07,857] [INFO] [30158] Received PREPARE: id:1741323542381, from:30127, delay:0.0001s, distance:239.87m (Euclidean)
[2025-03-07 13:59:07,857] [INFO] [30158] Received PREPARE: id:1741323542381, from:30174, delay:0.0001s, distance:222.64m (Euclidean)
[2025-03-07 13:59:07,857] [INFO] [30158] Received PREPARE: id:1741323542381, from:30098, delay:0.0000s, distance:103.21m (Euclidean)
[2025-03-07 13:59:07,857] [INFO] [30158] Received PREPARE: id:1741323542381, from:30170, delay:0.0000s, distance:80.40m (Euclidean)
[2025-03-07 13:59:07,857] [INFO] [30158] Received PREPARE: id:1741323542381, from:30054, delay:0.0001s, distance:232.19m (Euclidean)
[2025-03-07 13:59:07,857] [INFO] [30158] Received PREPARE: id:1741323542381, from:30015, delay:0.0000s, distance:155.97m (Euclidean)
[2025-03-07 13:59:07,868] [INFO] [30158] Received COMMIT: id:1741323542381, from:30116, delay:0.0000s, distance:143.42m (Euclidean)
[2025-03-07 13:59:07,868] [INFO] [30158] Received PREPARE: id:1741323542381, from:30056, delay:0.0000s, distance:80.98m (Euclidean)
[2025-03-07 13:59:07,868] [INFO] [30158] Received PREPARE: id:1741323542381, from:30060, delay:0.0001s, distance:234.92m (Euclidean)
[2025-03-07 13:59:07,870] [INFO] [30158] Received COMMIT: id:1741323542381, from:30115, delay:0.0001s, distance:207.88m (Euclidean)
[2025-03-07 13:59:07,870] [INFO] [30158] Received COMMIT: id:1741323542381, from:30130, delay:0.0001s, distance:239.93m (Euclidean)
[2025-03-07 13:59:07,870] [INFO] [30158] Received PREPARE: id:1741323542381, from:30180, delay:0.0000s, distance:130.17m (Euclidean)
[2025-03-07 13:59:07,870] [INFO] [30158] Received COMMIT: id:1741323542381, from:30199, delay:0.0001s, distance:156.82m (Euclidean)
[2025-03-07 13:59:08,321] [INFO] [30158] Received COMMIT: id:1741323542381, from:30060, delay:0.0001s, distance:234.92m (Euclidean)
[2025-03-07 13:59:08,323] [INFO] [30158] Received COMMIT: id:1741323542381, from:30127, delay:0.0001s, distance:239.87m (Euclidean)
[2025-03-07 13:59:08,323] [INFO] [30158] Received COMMIT: id:1741323542381, from:30108, delay:0.0001s, distance:207.13m (Euclidean)
[2025-03-07 13:59:08,427] [INFO] [30158] Received PREPARE: id:1741323542381, from:30041, delay:0.0000s, distance:178.18m (Euclidean)
[2025-03-07 13:59:08,427] [INFO] [30158] Received PREPARE: id:1741323542381, from:30136, delay:0.0000s, distance:103.34m (Euclidean)
[2025-03-07 13:59:08,427] [INFO] [30158] Received PREPARE: id:1741323542381, from:30129, delay:0.0000s, distance:191.14m (Euclidean)
[2025-03-07 13:59:08,427] [INFO] [30158] Received PREPARE: id:1741323542381, from:30027, delay:0.0002s, distance:271.09m (Euclidean)
[2025-03-07 13:59:08,427] [INFO] [30158] Received PREPARE: id:1741323542381, from:30074, delay:0.0000s, distance:127.99m (Euclidean)
[2025-03-07 13:59:08,429] [INFO] [30158] Received PREPARE: id:1741323542381, from:30121, delay:0.0001s, distance:173.36m (Euclidean)
[2025-03-07 13:59:08,429] [INFO] [30158] Received PREPARE: id:1741323542381, from:30102, delay:0.0000s, distance:91.44m (Euclidean)
[2025-03-07 13:59:08,429] [INFO] [30158] Received PREPARE: id:1741323542381, from:30177, delay:0.0001s, distance:182.40m (Euclidean)
[2025-03-07 13:59:08,429] [INFO] [30158] Received PREPARE: id:1741323542381, from:30113, delay:0.0000s, distance:145.72m (Euclidean)
[2025-03-07 13:59:08,429] [INFO] [30158] Received PREPARE: id:1741323542381, from:30169, delay:0.0001s, distance:241.02m (Euclidean)
[2025-03-07 13:59:08,429] [INFO] [30158] Received PREPARE: id:1741323542381, from:30191, delay:0.0001s, distance:185.91m (Euclidean)
[2025-03-07 13:59:08,429] [INFO] [30158] Received PREPARE: id:1741323542381, from:30161, delay:0.0000s, distance:141.26m (Euclidean)
[2025-03-07 13:59:08,429] [INFO] [30158] Received PREPARE: id:1741323542381, from:30062, delay:0.0000s, distance:136.50m (Euclidean)
[2025-03-07 13:59:08,429] [INFO] [30158] Received PREPARE: id:1741323542381, from:30111, delay:0.0000s, distance:110.71m (Euclidean)
[2025-03-07 13:59:08,577] [INFO] [30158] Received PREPARE: id:1741323542381, from:30168, delay:0.0002s, distance:263.47m (Euclidean)
[2025-03-07 13:59:08,577] [INFO] [30158] Received COMMIT: id:1741323542381, from:30095, delay:0.0000s, distance:135.99m (Euclidean)
[2025-03-07 13:59:08,577] [INFO] [30158] Received COMMIT: id:1741323542381, from:30062, delay:0.0000s, distance:136.50m (Euclidean)
[2025-03-07 13:59:08,577] [INFO] [30158] Received COMMIT: id:1741323542381, from:30136, delay:0.0000s, distance:103.34m (Euclidean)
[2025-03-07 13:59:08,577] [INFO] [30158] Received COMMIT: id:1741323542381, from:30041, delay:0.0000s, distance:178.18m (Euclidean)
[2025-03-07 13:59:08,577] [INFO] [30158] Received COMMIT: id:1741323542381, from:30057, delay:0.0001s, distance:236.60m (Euclidean)
[2025-03-07 13:59:08,577] [INFO] [30158] Received COMMIT: id:1741323542381, from:30074, delay:0.0000s, distance:127.99m (Euclidean)
[2025-03-07 13:59:08,583] [INFO] [30158] Received COMMIT: id:1741323542381, from:30170, delay:0.0000s, distance:80.40m (Euclidean)
[2025-03-07 13:59:08,583] [INFO] [30158] Received COMMIT: id:1741323542381, from:30119, delay:0.0001s, distance:192.78m (Euclidean)
[2025-03-07 13:59:08,583] [INFO] [30158] Received COMMIT: id:1741323542381, from:30043, delay:0.0000s, distance:172.43m (Euclidean)
[2025-03-07 13:59:08,583] [INFO] [30158] Received COMMIT: id:1741323542381, from:30013, delay:0.0001s, distance:184.96m (Euclidean)
[2025-03-07 13:59:08,584] [INFO] [30158] Received COMMIT: id:1741323542381, from:30098, delay:0.0000s, distance:103.21m (Euclidean)
[2025-03-07 13:59:08,584] [INFO] [30158] Received COMMIT: id:1741323542381, from:30021, delay:0.0000s, distance:78.42m (Euclidean)
[2025-03-07 13:59:08,584] [INFO] [30158] Received COMMIT: id:1741323542381, from:30053, delay:0.0000s, distance:190.30m (Euclidean)
[2025-03-07 13:59:08,584] [INFO] [30158] Received COMMIT: id:1741323542381, from:30121, delay:0.0001s, distance:173.36m (Euclidean)
[2025-03-07 13:59:08,584] [INFO] [30158] Received COMMIT: id:1741323542381, from:30027, delay:0.0002s, distance:271.09m (Euclidean)
[2025-03-07 13:59:08,586] [INFO] [30158] Received COMMIT: id:1741323542381, from:30049, delay:0.0000s, distance:187.06m (Euclidean)
[2025-03-07 13:59:08,586] [INFO] [30158] Received COMMIT: id:1741323542381, from:30180, delay:0.0000s, distance:130.17m (Euclidean)
[2025-03-07 13:59:08,586] [INFO] [30158] Received COMMIT: id:1741323542381, from:30056, delay:0.0000s, distance:80.98m (Euclidean)
[2025-03-07 13:59:08,586] [INFO] [30158] Received COMMIT: id:1741323542381, from:30113, delay:0.0000s, distance:145.72m (Euclidean)
[2025-03-07 13:59:08,586] [INFO] [30158] Received COMMIT: id:1741323542381, from:30054, delay:0.0001s, distance:232.19m (Euclidean)
[2025-03-07 13:59:08,588] [INFO] [30158] Received COMMIT: id:1741323542381, from:30015, delay:0.0000s, distance:155.97m (Euclidean)
[2025-03-07 13:59:08,683] [INFO] [30158] Received PREPARE: id:1741323542381, from:30123, delay:0.0001s, distance:236.39m (Euclidean)
[2025-03-07 13:59:08,683] [INFO] [30158] Received PREPARE: id:1741323542381, from:30043, delay:0.0000s, distance:172.43m (Euclidean)
[2025-03-07 13:59:08,683] [INFO] [30158] Received PREPARE: id:1741323542381, from:30107, delay:0.0000s, distance:125.56m (Euclidean)
[2025-03-07 13:59:08,683] [INFO] [30158] Received PREPARE: id:1741323542381, from:30181, delay:0.0001s, distance:238.80m (Euclidean)
[2025-03-07 13:59:08,683] [INFO] [30158] Received PREPARE: id:1741323542381, from:30057, delay:0.0001s, distance:236.60m (Euclidean)
[2025-03-07 13:59:08,683] [INFO] [30158] Received PREPARE: id:1741323542381, from:30004, delay:0.0000s, distance:148.34m (Euclidean)
[2025-03-07 13:59:08,683] [INFO] [30158] Received PREPARE: id:1741323542381, from:30013, delay:0.0001s, distance:184.96m (Euclidean)
[2025-03-07 13:59:08,683] [INFO] [30158] Received PREPARE: id:1741323542381, from:30095, delay:0.0000s, distance:135.99m (Euclidean)
[2025-03-07 13:59:08,683] [INFO] [30158] Received PREPARE: id:1741323542381, from:30196, delay:0.0001s, distance:166.46m (Euclidean)
[2025-03-07 13:59:08,683] [INFO] [30158] Received PREPARE: id:1741323542381, from:30037, delay:0.0000s, distance:123.99m (Euclidean)
[2025-03-07 13:59:08,683] [INFO] [30158] Received PREPARE: id:1741323542381, from:30109, delay:0.0000s, distance:70.28m (Euclidean)
[2025-03-07 13:59:08,683] [INFO] [30158] Received PREPARE: id:1741323542381, from:30085, delay:0.0000s, distance:139.76m (Euclidean)
[2025-03-07 13:59:08,683] [INFO] [30158] Received PREPARE: id:1741323542381, from:30154, delay:0.0000s, distance:146.30m (Euclidean)
[2025-03-07 13:59:08,683] [INFO] [30158] Received PREPARE: id:1741323542381, from:30066, delay:0.0000s, distance:120.01m (Euclidean)
[2025-03-07 13:59:08,798] [INFO] [30158] Received COMMIT: id:1741323542381, from:30168, delay:0.0002s, distance:263.47m (Euclidean)
[2025-03-07 13:59:08,798] [INFO] [30158] Received COMMIT: id:1741323542381, from:30102, delay:0.0000s, distance:91.44m (Euclidean)
[2025-03-07 13:59:08,798] [INFO] [30158] Received COMMIT: id:1741323542381, from:30037, delay:0.0000s, distance:123.99m (Euclidean)
[2025-03-07 13:59:08,798] [INFO] [30158] Received COMMIT: id:1741323542381, from:30196, delay:0.0001s, distance:166.46m (Euclidean)
[2025-03-07 13:59:08,798] [INFO] [30158] Received COMMIT: id:1741323542381, from:30177, delay:0.0001s, distance:182.40m (Euclidean)
[2025-03-07 13:59:08,798] [INFO] [30158] Received COMMIT: id:1741323542381, from:30129, delay:0.0000s, distance:191.14m (Euclidean)
[2025-03-07 13:59:08,798] [INFO] [30158] Received COMMIT: id:1741323542381, from:30066, delay:0.0000s, distance:120.01m (Euclidean)
[2025-03-07 13:59:08,798] [INFO] [30158] Received COMMIT: id:1741323542381, from:30080, delay:0.0000s, distance:136.01m (Euclidean)
[2025-03-07 13:59:08,798] [INFO] [30158] Received COMMIT: id:1741323542381, from:30111, delay:0.0000s, distance:110.71m (Euclidean)
[2025-03-07 13:59:08,806] [INFO] [30158] Received COMMIT: id:1741323542381, from:30154, delay:0.0000s, distance:146.30m (Euclidean)
[2025-03-07 13:59:08,806] [INFO] [30158] Received COMMIT: id:1741323542381, from:30107, delay:0.0000s, distance:125.56m (Euclidean)
[2025-03-07 13:59:08,806] [INFO] [30158] Received COMMIT: id:1741323542381, from:30109, delay:0.0000s, distance:70.28m (Euclidean)
[2025-03-07 13:59:08,806] [INFO] [30158] Received COMMIT: id:1741323542381, from:30085, delay:0.0000s, distance:139.76m (Euclidean)
[2025-03-07 13:59:08,806] [INFO] [30158] Received COMMIT: id:1741323542381, from:30004, delay:0.0000s, distance:148.34m (Euclidean)
[2025-03-07 13:59:08,806] [INFO] [30158] Received COMMIT: id:1741323542381, from:30161, delay:0.0000s, distance:141.26m (Euclidean)
[2025-03-07 13:59:08,806] [INFO] [30158] Received COMMIT: id:1741323542381, from:30169, delay:0.0001s, distance:241.02m (Euclidean)
[2025-03-07 13:59:08,808] [INFO] [30158] Received COMMIT: id:1741323542381, from:30090, delay:0.0000s, distance:51.98m (Euclidean)
[2025-03-07 13:59:08,808] [INFO] [30158] Received COMMIT: id:1741323542381, from:30181, delay:0.0001s, distance:238.80m (Euclidean)
[2025-03-07 13:59:08,808] [INFO] [30158] Received COMMIT: id:1741323542381, from:30174, delay:0.0001s, distance:222.64m (Euclidean)
[2025-03-07 13:59:08,922] [INFO] [30158] Received PREPARE: id:1741323542381, from:30093, delay:0.0001s, distance:191.46m (Euclidean)
[2025-03-07 13:59:08,922] [INFO] [30158] Received PREPARE: id:1741323542381, from:30080, delay:0.0000s, distance:136.01m (Euclidean)
[2025-03-07 13:59:08,922] [INFO] [30158] Received PREPARE: id:1741323542381, from:30120, delay:0.0001s, distance:179.98m (Euclidean)
[2025-03-07 13:59:08,922] [INFO] [30158] Received PREPARE: id:1741323542381, from:30090, delay:0.0000s, distance:51.98m (Euclidean)
[2025-03-07 13:59:08,922] [INFO] [30158] Received PREPARE: id:1741323542381, from:30089, delay:0.0001s, distance:245.24m (Euclidean)
[2025-03-07 13:59:08,922] [INFO] [30158] Received PREPARE: id:1741323542381, from:30112, delay:0.0001s, distance:229.23m (Euclidean)
[2025-03-07 13:59:08,995] [INFO] [30158] Received COMMIT: id:1741323542381, from:30093, delay:0.0001s, distance:191.46m (Euclidean)
[2025-03-07 13:59:08,995] [INFO] [30158] Received COMMIT: id:1741323542381, from:30089, delay:0.0001s, distance:245.24m (Euclidean)
[2025-03-07 13:59:09,058] [INFO] [30158] Received COMMIT: id:1741323542381, from:30191, delay:0.0001s, distance:185.91m (Euclidean)
[2025-03-07 13:59:09,136] [INFO] [30158] Received COMMIT: id:1741323542381, from:30112, delay:0.0001s, distance:229.23m (Euclidean)
[2025-03-07 13:59:09,136] [INFO] [30158] Received COMMIT: id:1741323542381, from:30000, delay:0.0000s, distance:140.01m (Euclidean)
[2025-03-07 13:59:09,136] [INFO] [30158] Received COMMIT: id:1741323542381, from:30092, delay:0.0001s, distance:187.25m (Euclidean)
[2025-03-07 13:59:09,138] [INFO] [30158] Received COMMIT: id:1741323542381, from:30123, delay:0.0001s, distance:236.39m (Euclidean)
[2025-03-07 13:59:09,209] [INFO] [30158] Received PREPARE: id:1741323542381, from:30092, delay:0.0001s, distance:187.25m (Euclidean)
[2025-03-07 13:59:09,209] [INFO] [30158] Received PREPARE: id:1741323542381, from:30178, delay:0.0000s, distance:128.18m (Euclidean)
[2025-03-07 13:59:09,328] [INFO] [30158] Received COMMIT: id:1741323542381, from:30120, delay:0.0001s, distance:179.98m (Euclidean)
[2025-03-07 13:59:09,328] [INFO] [30158] Received COMMIT: id:1741323542381, from:30178, delay:0.0000s, distance:128.18m (Euclidean)
[2025-03-07 13:59:09,448] [INFO] [30158] Received PREPARE: id:1741323542381, from:30150, delay:0.0000s, distance:64.50m (Euclidean)
[2025-03-07 13:59:09,455] [INFO] [30158] Received COMMIT: id:1741323542381, from:30150, delay:0.0000s, distance:64.50m (Euclidean)
[2025-03-07 13:59:09,506] [INFO] [30158] Received COMMIT: id:1741323542381, from:30189, delay:0.0001s, distance:248.35m (Euclidean)
[2025-03-07 13:59:09,537] [INFO] [30158] Received COMMIT: id:1741323542381, from:30025, delay:0.0001s, distance:166.95m (Euclidean)
[2025-03-07 13:59:09,537] [INFO] [30158] Received PREPARE: id:1741323542381, from:30025, delay:0.0001s, distance:166.95m (Euclidean)
[2025-03-07 13:59:09,573] [INFO] [30158] Received PREPARE: id:1741323542381, from:30007, delay:0.0000s, distance:156.52m (Euclidean)
[2025-03-07 13:59:09,614] [INFO] [30158] Received COMMIT: id:1741323542381, from:30007, delay:0.0000s, distance:156.52m (Euclidean)
[2025-03-07 13:59:09,728] [INFO] [30158] Received COMMIT: id:1741323542381, from:30182, delay:0.0001s, distance:175.74m (Euclidean)
[2025-03-07 13:59:09,728] [INFO] [30158] Received PREPARE: id:1741323542381, from:30182, delay:0.0001s, distance:175.74m (Euclidean)
[2025-03-07 13:59:09,819] [INFO] [30158] Received PREPARE: id:1741323542381, from:30023, delay:0.0001s, distance:243.92m (Euclidean)
[2025-03-07 13:59:09,819] [INFO] [30158] Received COMMIT: id:1741323542381, from:30023, delay:0.0001s, distance:243.92m (Euclidean)
[2025-03-07 13:59:09,963] [INFO] [30158] Received PREPARE: id:1741323542381, from:30048, delay:0.0000s, distance:82.08m (Euclidean)
[2025-03-07 13:59:09,963] [INFO] [30158] Received COMMIT: id:1741323542381, from:30048, delay:0.0000s, distance:82.08m (Euclidean)
[2025-03-07 13:59:10,218] [INFO] [30158] Received PREPARE: id:1741323542381, from:30124, delay:0.0000s, distance:55.27m (Euclidean)
[2025-03-07 13:59:10,218] [INFO] [30158] Received PREPARE: id:1741323542381, from:30020, delay:0.0000s, distance:135.49m (Euclidean)
[2025-03-07 13:59:10,218] [INFO] [30158] Received PREPARE: id:1741323542381, from:30103, delay:0.0000s, distance:95.54m (Euclidean)
[2025-03-07 13:59:10,245] [INFO] [30158] Received COMMIT: id:1741323542381, from:30051, delay:0.0001s, distance:246.98m (Euclidean)
[2025-03-07 13:59:10,245] [INFO] [30158] Received COMMIT: id:1741323542381, from:30124, delay:0.0000s, distance:55.27m (Euclidean)
[2025-03-07 13:59:10,245] [INFO] [30158] Received COMMIT: id:1741323542381, from:30103, delay:0.0000s, distance:95.54m (Euclidean)
[2025-03-07 13:59:10,245] [INFO] [30158] Received COMMIT: id:1741323542381, from:30020, delay:0.0000s, distance:135.49m (Euclidean)
[2025-03-07 13:59:10,247] [INFO] [30158] Received PREPARE: id:1741323542381, from:30028, delay:0.0001s, distance:246.96m (Euclidean)
[2025-03-07 13:59:10,247] [INFO] [30158] Received PREPARE: id:1741323542381, from:30051, delay:0.0001s, distance:246.98m (Euclidean)
[2025-03-07 13:59:10,247] [INFO] [30158] Received PREPARE: id:1741323542381, from:30100, delay:0.0000s, distance:80.38m (Euclidean)
[2025-03-07 13:59:10,270] [INFO] [30158] Received COMMIT: id:1741323542381, from:30100, delay:0.0000s, distance:80.38m (Euclidean)
[2025-03-07 13:59:10,270] [INFO] [30158] Received COMMIT: id:1741323542381, from:30028, delay:0.0001s, distance:246.96m (Euclidean)
[2025-03-07 13:59:10,398] [INFO] [30158] Received PREPARE: id:1741323542381, from:30106, delay:0.0002s, distance:260.08m (Euclidean)
[2025-03-07 13:59:10,398] [INFO] [30158] Received PREPARE: id:1741323542381, from:30011, delay:0.0000s, distance:85.00m (Euclidean)
[2025-03-07 13:59:10,423] [INFO] [30158] Received COMMIT: id:1741323542381, from:30106, delay:0.0002s, distance:260.08m (Euclidean)
[2025-03-07 13:59:10,423] [INFO] [30158] Received COMMIT: id:1741323542381, from:30011, delay:0.0000s, distance:85.00m (Euclidean)
[2025-03-07 13:59:10,528] [INFO] [30158] Received COMMIT: id:1741323542381, from:30167, delay:0.0000s, distance:143.29m (Euclidean)
[2025-03-07 13:59:10,540] [INFO] [30158] Received PREPARE: id:1741323542381, from:30167, delay:0.0000s, distance:143.29m (Euclidean)
[2025-03-07 13:59:10,542] [INFO] [30158] Received PREPARE: id:1741323542381, from:30096, delay:0.0000s, distance:81.92m (Euclidean)
[2025-03-07 13:59:10,567] [INFO] [30158] Received PREPARE: id:1741323542381, from:30070, delay:0.0001s, distance:206.22m (Euclidean)
[2025-03-07 13:59:10,569] [INFO] [30158] Received COMMIT: id:1741323542381, from:30070, delay:0.0001s, distance:206.22m (Euclidean)
[2025-03-07 13:59:10,583] [INFO] [30158] Received COMMIT: id:1741323542381, from:30096, delay:0.0000s, distance:81.92m (Euclidean)
[2025-03-07 13:59:10,668] [INFO] [30158] Received PREPARE: id:1741323542381, from:30065, delay:0.0001s, distance:201.83m (Euclidean)
[2025-03-07 13:59:10,686] [INFO] [30158] Received COMMIT: id:1741323542381, from:30065, delay:0.0001s, distance:201.83m (Euclidean)
[2025-03-07 13:59:10,984] [INFO] [30158] Received PREPARE: id:1741323542381, from:30046, delay:0.0001s, distance:211.73m (Euclidean)
[2025-03-07 13:59:10,984] [INFO] [30158] Received PREPARE: id:1741323542381, from:30059, delay:0.0000s, distance:140.78m (Euclidean)
[2025-03-07 13:59:11,005] [INFO] [30158] Received COMMIT: id:1741323542381, from:30059, delay:0.0000s, distance:140.78m (Euclidean)
[2025-03-07 13:59:11,005] [INFO] [30158] Received COMMIT: id:1741323542381, from:30046, delay:0.0001s, distance:211.73m (Euclidean)
[2025-03-07 13:59:11,009] [INFO] [30158] Received PREPARE: id:1741323542381, from:30171, delay:0.0001s, distance:204.00m (Euclidean)
[2025-03-07 13:59:11,037] [INFO] [30158] Received COMMIT: id:1741323542381, from:30171, delay:0.0001s, distance:204.00m (Euclidean)
[2025-03-07 13:59:11,101] [INFO] [30158] Received PREPARE: id:1741323542381, from:30149, delay:0.0000s, distance:175.48m (Euclidean)
[2025-03-07 13:59:11,101] [INFO] [30158] Received PREPARE: id:1741323542381, from:30118, delay:0.0001s, distance:195.62m (Euclidean)
[2025-03-07 13:59:11,109] [INFO] [30158] Received COMMIT: id:1741323542381, from:30149, delay:0.0000s, distance:175.48m (Euclidean)
[2025-03-07 13:59:11,109] [INFO] [30158] Received COMMIT: id:1741323542381, from:30118, delay:0.0001s, distance:195.62m (Euclidean)
[2025-03-07 13:59:11,267] [INFO] [30158] Received PREPARE: id:1741323542381, from:30076, delay:0.0001s, distance:235.53m (Euclidean)
[2025-03-07 13:59:11,314] [INFO] [30158] Received COMMIT: id:1741323542381, from:30076, delay:0.0001s, distance:235.53m (Euclidean)
[2025-03-07 13:59:11,314] [INFO] [30158] Received PREPARE: id:1741323542381, from:30024, delay:0.0001s, distance:223.35m (Euclidean)
[2025-03-07 13:59:11,327] [INFO] [30158] Received COMMIT: id:1741323542381, from:30024, delay:0.0001s, distance:223.35m (Euclidean)
[2025-03-07 13:59:12,094] [INFO] [30158] Received PREPARE: id:1741323542381, from:30063, delay:0.0000s, distance:132.67m (Euclidean)
[2025-03-07 13:59:12,094] [INFO] [30158] Received COMMIT: id:1741323542381, from:30063, delay:0.0000s, distance:132.67m (Euclidean)
[2025-03-07 13:59:12,170] [INFO] [30158] Received PREPARE: id:1741323542381, from:30035, delay:0.0001s, distance:161.01m (Euclidean)
[2025-03-07 13:59:12,170] [INFO] [30158] Received COMMIT: id:1741323542381, from:30035, delay:0.0001s, distance:161.01m (Euclidean)
[2025-03-07 13:59:12,230] [INFO] [30158] Received PREPARE: id:1741323542381, from:30040, delay:0.0001s, distance:238.99m (Euclidean)
[2025-03-07 13:59:12,247] [INFO] [30158] Received COMMIT: id:1741323542381, from:30040, delay:0.0001s, distance:238.99m (Euclidean)
[2025-03-07 13:59:12,314] [INFO] [30158] Received PREPARE: id:1741323542381, from:30175, delay:0.0000s, distance:109.81m (Euclidean)
[2025-03-07 13:59:12,314] [INFO] [30158] Received COMMIT: id:1741323542381, from:30175, delay:0.0000s, distance:109.81m (Euclidean)
[2025-03-07 13:59:12,926] [INFO] [30158] Received PREPARE: id:1741323542381, from:30086, delay:0.0001s, distance:153.49m (Euclidean)
[2025-03-07 13:59:12,926] [INFO] [30158] Received COMMIT: id:1741323542381, from:30086, delay:0.0001s, distance:153.49m (Euclidean)
[2025-03-07 13:59:13,275] [INFO] [30158] Received PREPARE: id:1741323542381, from:30073, delay:0.0000s, distance:150.42m (Euclidean)
[2025-03-07 13:59:13,559] [INFO] [30158] Received COMMIT: id:1741323542381, from:30073, delay:0.0000s, distance:150.42m (Euclidean)
[2025-03-07 13:59:13,717] [INFO] [30158] Received PREPARE: id:1741323542381, from:30146, delay:0.0001s, distance:153.10m (Euclidean)
[2025-03-07 13:59:13,717] [INFO] [30158] Received COMMIT: id:1741323542381, from:30146, delay:0.0001s, distance:153.10m (Euclidean)
[2025-03-07 13:59:14,122] [INFO] [30158] Received PREPARE: id:1741323542381, from:30125, delay:0.0000s, distance:98.14m (Euclidean)
[2025-03-07 13:59:14,185] [INFO] [30158] Received COMMIT: id:1741323542381, from:30125, delay:0.0000s, distance:98.14m (Euclidean)
[2025-03-07 13:59:14,497] [INFO] [30158] Received PREPARE: id:1741323542381, from:30026, delay:0.0002s, distance:279.19m (Euclidean)
[2025-03-07 13:59:14,497] [INFO] [30158] Received COMMIT: id:1741323542381, from:30026, delay:0.0002s, distance:279.19m (Euclidean)
[2025-03-07 13:59:14,497] [INFO] [30158] Received PREPARE: id:1741323542381, from:30153, delay:0.0000s, distance:108.07m (Euclidean)
[2025-03-07 13:59:14,671] [INFO] [30158] Received PREPARE: id:1741323542381, from:30034, delay:0.0000s, distance:176.45m (Euclidean)
[2025-03-07 13:59:14,680] [INFO] [30158] Received COMMIT: id:1741323542381, from:30034, delay:0.0000s, distance:176.45m (Euclidean)
[2025-03-07 13:59:14,952] [INFO] [30158] Received COMMIT: id:1741323542381, from:30153, delay:0.0000s, distance:108.07m (Euclidean)
[2025-03-07 13:59:15,048] [INFO] [30158] Received PREPARE: id:1741323542381, from:30033, delay:0.0000s, distance:138.92m (Euclidean)
[2025-03-07 13:59:15,217] [INFO] [30158] Received PREPARE: id:1741323542381, from:30003, delay:0.0000s, distance:126.47m (Euclidean)
[2025-03-07 13:59:15,217] [INFO] [30158] Received COMMIT: id:1741323542381, from:30003, delay:0.0000s, distance:126.47m (Euclidean)
[2025-03-07 13:59:15,292] [INFO] [30158] Received PREPARE: id:1741323542381, from:30165, delay:0.0002s, distance:267.11m (Euclidean)
[2025-03-07 13:59:15,292] [INFO] [30158] Received COMMIT: id:1741323542381, from:30165, delay:0.0002s, distance:267.11m (Euclidean)
[2025-03-07 13:59:15,977] [INFO] [30158] Received PREPARE: id:1741323542381, from:30010, delay:0.0002s, distance:269.73m (Euclidean)
[2025-03-07 13:59:15,977] [INFO] [30158] Received COMMIT: id:1741323542381, from:30010, delay:0.0002s, distance:269.73m (Euclidean)
[2025-03-07 13:59:16,199] [INFO] [30158] Received PREPARE: id:1741323542381, from:30140, delay:0.0000s, distance:70.21m (Euclidean)
[2025-03-07 13:59:16,215] [INFO] [30158] Received COMMIT: id:1741323542381, from:30140, delay:0.0000s, distance:70.21m (Euclidean)
[2025-03-07 13:59:16,215] [INFO] [30158] Received PREPARE: id:1741323542381, from:30067, delay:0.0001s, distance:180.07m (Euclidean)
[2025-03-07 13:59:16,215] [INFO] [30158] Received COMMIT: id:1741323542381, from:30067, delay:0.0001s, distance:180.07m (Euclidean)
[2025-03-07 13:59:16,343] [INFO] [30158] Received PREPARE: id:1741323542381, from:30135, delay:0.0001s, distance:161.21m (Euclidean)
[2025-03-07 13:59:16,343] [INFO] [30158] Received COMMIT: id:1741323542381, from:30135, delay:0.0001s, distance:161.21m (Euclidean)
[2025-03-07 13:59:16,692] [INFO] [30158] Received PREPARE: id:1741323542381, from:30031, delay:0.0002s, distance:283.66m (Euclidean)
[2025-03-07 13:59:16,692] [INFO] [30158] Received COMMIT: id:1741323542381, from:30031, delay:0.0002s, distance:283.66m (Euclidean)
[2025-03-07 13:59:16,780] [INFO] [30158] Received PREPARE: id:1741323542381, from:30052, delay:0.0001s, distance:207.08m (Euclidean)
[2025-03-07 13:59:16,780] [INFO] [30158] Received COMMIT: id:1741323542381, from:30052, delay:0.0001s, distance:207.08m (Euclidean)
[2025-03-07 13:59:16,854] [INFO] [30158] Received PREPARE: id:1741323542381, from:30019, delay:0.0000s, distance:110.58m (Euclidean)
[2025-03-07 13:59:16,854] [INFO] [30158] Received COMMIT: id:1741323542381, from:30019, delay:0.0000s, distance:110.58m (Euclidean)
[2025-03-07 13:59:16,964] [INFO] [30158] Received PREPARE: id:1741323542381, from:30006, delay:0.0001s, distance:159.85m (Euclidean)
[2025-03-07 13:59:17,101] [INFO] [30158] Received PREPARE: id:1741323542381, from:30079, delay:0.0001s, distance:246.30m (Euclidean)
[2025-03-07 13:59:17,101] [INFO] [30158] Received COMMIT: id:1741323542381, from:30079, delay:0.0001s, distance:246.30m (Euclidean)
[2025-03-07 13:59:17,205] [INFO] [30158] Received PREPARE: id:1741323542381, from:30152, delay:0.0000s, distance:76.29m (Euclidean)
[2025-03-07 13:59:17,205] [INFO] [30158] Received COMMIT: id:1741323542381, from:30152, delay:0.0000s, distance:76.29m (Euclidean)
[2025-03-07 13:59:17,271] [INFO] [30158] Received PREPARE: id:1741323542381, from:30188, delay:0.0000s, distance:107.41m (Euclidean)
[2025-03-07 13:59:17,271] [INFO] [30158] Received COMMIT: id:1741323542381, from:30188, delay:0.0000s, distance:107.41m (Euclidean)
[2025-03-07 13:59:17,456] [INFO] [30158] Received PREPARE: id:1741323542381, from:30081, delay:0.0001s, distance:231.11m (Euclidean)
[2025-03-07 13:59:17,456] [INFO] [30158] Received COMMIT: id:1741323542381, from:30081, delay:0.0001s, distance:231.11m (Euclidean)
[2025-03-07 13:59:17,763] [INFO] [30158] Received PREPARE: id:1741323542381, from:30071, delay:0.0001s, distance:177.82m (Euclidean)
[2025-03-07 13:59:17,769] [INFO] [30158] Received COMMIT: id:1741323542381, from:30071, delay:0.0001s, distance:177.82m (Euclidean)
[2025-03-07 13:59:17,875] [INFO] [30158] Received PREPARE: id:1741323542381, from:30151, delay:0.0000s, distance:138.14m (Euclidean)
[2025-03-07 13:59:17,973] [INFO] [30158] Received PREPARE: id:1741323542381, from:30137, delay:0.0002s, distance:261.18m (Euclidean)
[2025-03-07 13:59:18,084] [INFO] [30158] Received COMMIT: id:1741323542381, from:30033, delay:0.0000s, distance:138.92m (Euclidean)
[2025-03-07 13:59:18,292] [INFO] [30158] Received COMMIT: id:1741323542381, from:30006, delay:0.0001s, distance:159.85m (Euclidean)
[2025-03-07 13:59:18,641] [INFO] [30158] Received COMMIT: id:1741323542381, from:30137, delay:0.0002s, distance:261.18m (Euclidean)
[2025-03-07 13:59:18,670] [INFO] [30158] Received COMMIT: id:1741323542381, from:30151, delay:0.0000s, distance:138.14m (Euclidean)
[2025-03-07 13:59:18,771] [INFO] [30158] Received PREPARE: id:1741323542381, from:30193, delay:0.0001s, distance:151.32m (Euclidean)
[2025-03-07 13:59:18,772] [INFO] [30158] Received COMMIT: id:1741323542381, from:30193, delay:0.0001s, distance:151.32m (Euclidean)
[2025-03-07 13:59:18,942] [INFO] [30158] Received PREPARE: id:1741323542381, from:30058, delay:0.0002s, distance:251.14m (Euclidean)
[2025-03-07 13:59:18,942] [INFO] [30158] Received PREPARE: id:1741323542381, from:30068, delay:0.0000s, distance:89.19m (Euclidean)
[2025-03-07 13:59:18,942] [INFO] [30158] Received COMMIT: id:1741323542381, from:30058, delay:0.0002s, distance:251.14m (Euclidean)
[2025-03-07 13:59:18,942] [INFO] [30158] Received COMMIT: id:1741323542381, from:30068, delay:0.0000s, distance:89.19m (Euclidean)
[2025-03-07 13:59:18,948] [INFO] [30158] Received PREPARE: id:1741323542381, from:30156, delay:0.0001s, distance:204.50m (Euclidean)
[2025-03-07 13:59:19,007] [INFO] [30158] Received PREPARE: id:1741323542381, from:30050, delay:0.0001s, distance:248.48m (Euclidean)
[2025-03-07 13:59:19,007] [INFO] [30158] Received COMMIT: id:1741323542381, from:30050, delay:0.0001s, distance:248.48m (Euclidean)
[2025-03-07 13:59:19,176] [INFO] [30158] Received PREPARE: id:1741323542381, from:30117, delay:0.0001s, distance:213.14m (Euclidean)
[2025-03-07 13:59:19,176] [INFO] [30158] Received COMMIT: id:1741323542381, from:30117, delay:0.0001s, distance:213.14m (Euclidean)
[2025-03-07 13:59:19,710] [INFO] [30158] Received PREPARE: id:1741323542381, from:30145, delay:0.0001s, distance:194.63m (Euclidean)
[2025-03-07 13:59:19,730] [INFO] [30158] Received COMMIT: id:1741323542381, from:30145, delay:0.0001s, distance:194.63m (Euclidean)
[2025-03-07 13:59:20,074] [INFO] [30158] Received PREPARE: id:1741323542381, from:30132, delay:0.0002s, distance:264.95m (Euclidean)
[2025-03-07 13:59:20,076] [INFO] [30158] Received COMMIT: id:1741323542381, from:30132, delay:0.0002s, distance:264.95m (Euclidean)
[2025-03-07 13:59:20,092] [INFO] [30158] Received PREPARE: id:1741323542381, from:30162, delay:0.0000s, distance:48.33m (Euclidean)
[2025-03-07 13:59:20,137] [INFO] [30158] Received PREPARE: id:1741323542381, from:30061, delay:0.0002s, distance:261.51m (Euclidean)
[2025-03-07 13:59:20,139] [INFO] [30158] Received COMMIT: id:1741323542381, from:30061, delay:0.0002s, distance:261.51m (Euclidean)
[2025-03-07 13:59:20,163] [INFO] [30158] Received PREPARE: id:1741323542381, from:30141, delay:0.0001s, distance:210.94m (Euclidean)
[2025-03-07 13:59:20,163] [INFO] [30158] Received COMMIT: id:1741323542381, from:30141, delay:0.0001s, distance:210.94m (Euclidean)
[2025-03-07 13:59:20,167] [INFO] [30158] Received PREPARE: id:1741323542381, from:30084, delay:0.0000s, distance:130.45m (Euclidean)
[2025-03-07 13:59:20,445] [INFO] [30158] Received PREPARE: id:1741323542381, from:30166, delay:0.0001s, distance:182.48m (Euclidean)
[2025-03-07 13:59:20,459] [INFO] [30158] Received COMMIT: id:1741323542381, from:30166, delay:0.0001s, distance:182.48m (Euclidean)
[2025-03-07 13:59:20,532] [INFO] [30158] Received PREPARE: id:1741323542381, from:30173, delay:0.0001s, distance:209.73m (Euclidean)
[2025-03-07 13:59:20,543] [INFO] [30158] Received COMMIT: id:1741323542381, from:30173, delay:0.0001s, distance:209.73m (Euclidean)
[2025-03-07 13:59:21,266] [INFO] [30158] Received PREPARE: id:1741323542381, from:30114, delay:0.0002s, distance:286.69m (Euclidean)
[2025-03-07 13:59:21,307] [INFO] [30158] Received COMMIT: id:1741323542381, from:30114, delay:0.0002s, distance:286.69m (Euclidean)
[2025-03-07 13:59:21,492] [INFO] [30158] Received PREPARE: id:1741323542381, from:30055, delay:0.0001s, distance:240.02m (Euclidean)
[2025-03-07 13:59:21,494] [INFO] [30158] Received COMMIT: id:1741323542381, from:30055, delay:0.0001s, distance:240.02m (Euclidean)
[2025-03-07 13:59:21,587] [INFO] [30158] Received COMMIT: id:1741323542381, from:30156, delay:0.0001s, distance:204.50m (Euclidean)
[2025-03-07 13:59:21,706] [INFO] [30158] Received PREPARE: id:1741323542381, from:30139, delay:0.0001s, distance:206.79m (Euclidean)
[2025-03-07 13:59:21,709] [INFO] [30158] Received COMMIT: id:1741323542381, from:30139, delay:0.0001s, distance:206.79m (Euclidean)
[2025-03-07 13:59:21,740] [INFO] [30158] Received PREPARE: id:1741323542381, from:30088, delay:0.0000s, distance:141.77m (Euclidean)
[2025-03-07 13:59:21,765] [INFO] [30158] Received COMMIT: id:1741323542381, from:30088, delay:0.0000s, distance:141.77m (Euclidean)
[2025-03-07 13:59:21,765] [INFO] [30158] Received PREPARE: id:1741323542381, from:30064, delay:0.0001s, distance:220.71m (Euclidean)
[2025-03-07 13:59:21,767] [INFO] [30158] Received COMMIT: id:1741323542381, from:30064, delay:0.0001s, distance:220.71m (Euclidean)
[2025-03-07 13:59:21,869] [INFO] [30158] Received PREPARE: id:1741323542381, from:30022, delay:0.0000s, distance:120.27m (Euclidean)
[2025-03-07 13:59:21,869] [INFO] [30158] Received COMMIT: id:1741323542381, from:30022, delay:0.0000s, distance:120.27m (Euclidean)
[2025-03-07 13:59:22,120] [INFO] [30158] Received PREPARE: id:1741323542381, from:30134, delay:0.0001s, distance:233.72m (Euclidean)
[2025-03-07 13:59:22,122] [INFO] [30158] Received COMMIT: id:1741323542381, from:30134, delay:0.0001s, distance:233.72m (Euclidean)
[2025-03-07 13:59:22,124] [INFO] [30158] Received PREPARE: id:1741323542381, from:30038, delay:0.0002s, distance:269.75m (Euclidean)
[2025-03-07 13:59:22,130] [INFO] [30158] Received COMMIT: id:1741323542381, from:30038, delay:0.0002s, distance:269.75m (Euclidean)
[2025-03-07 13:59:22,145] [INFO] [30158] Received COMMIT: id:1741323542381, from:30162, delay:0.0000s, distance:48.33m (Euclidean)
[2025-03-07 13:59:22,179] [INFO] [30158] Received PREPARE: id:1741323542381, from:30198, delay:0.0002s, distance:293.72m (Euclidean)
[2025-03-07 13:59:22,179] [INFO] [30158] Received COMMIT: id:1741323542381, from:30198, delay:0.0002s, distance:293.72m (Euclidean)
[2025-03-07 13:59:22,179] [INFO] [30158] Received COMMIT: id:1741323542381, from:30084, delay:0.0000s, distance:130.45m (Euclidean)
[2025-03-07 13:59:22,273] [INFO] [30158] Received PREPARE: id:1741323542381, from:30197, delay:0.0000s, distance:137.18m (Euclidean)
[2025-03-07 13:59:22,275] [INFO] [30158] Received COMMIT: id:1741323542381, from:30197, delay:0.0000s, distance:137.18m (Euclidean)
[2025-03-07 13:59:22,317] [INFO] [30158] Received PREPARE: id:1741323542381, from:30016, delay:0.0002s, distance:273.76m (Euclidean)
[2025-03-07 13:59:22,317] [INFO] [30158] Received COMMIT: id:1741323542381, from:30016, delay:0.0002s, distance:273.76m (Euclidean)
[2025-03-07 13:59:22,334] [INFO] [30158] Received PREPARE: id:1741323542381, from:30104, delay:0.0002s, distance:283.05m (Euclidean)
[2025-03-07 13:59:22,334] [INFO] [30158] Received COMMIT: id:1741323542381, from:30104, delay:0.0002s, distance:283.05m (Euclidean)
[2025-03-07 13:59:22,506] [INFO] [30158] Received PREPARE: id:1741323542381, from:30105, delay:0.0002s, distance:295.60m (Euclidean)
[2025-03-07 13:59:22,508] [INFO] [30158] Received COMMIT: id:1741323542381, from:30105, delay:0.0002s, distance:295.60m (Euclidean)
[2025-03-07 13:59:22,700] [INFO] [30158] Received PREPARE: id:1741323542381, from:30042, delay:0.0000s, distance:185.86m (Euclidean)
[2025-03-07 13:59:22,700] [INFO] [30158] Received COMMIT: id:1741323542381, from:30042, delay:0.0000s, distance:185.86m (Euclidean)
[2025-03-07 13:59:22,965] [INFO] [30158] Received PREPARE: id:1741323542381, from:30142, delay:0.0001s, distance:239.67m (Euclidean)
[2025-03-07 13:59:22,967] [INFO] [30158] Received COMMIT: id:1741323542381, from:30142, delay:0.0001s, distance:239.67m (Euclidean)
[2025-03-07 13:59:23,041] [INFO] [30158] Received PREPARE: id:1741323542381, from:30045, delay:0.0001s, distance:241.14m (Euclidean)
[2025-03-07 13:59:23,083] [INFO] [30158] Received PREPARE: id:1741323542381, from:30194, delay:0.0001s, distance:155.70m (Euclidean)
[2025-03-07 13:59:23,083] [INFO] [30158] Received COMMIT: id:1741323542381, from:30194, delay:0.0001s, distance:155.70m (Euclidean)
[2025-03-07 13:59:23,340] [INFO] [30158] Received PREPARE: id:1741323542381, from:30032, delay:0.0001s, distance:158.55m (Euclidean)
[2025-03-07 13:59:23,340] [INFO] [30158] Received PREPARE: id:1741323542381, from:30159, delay:0.0001s, distance:167.05m (Euclidean)
[2025-03-07 13:59:23,342] [INFO] [30158] Received COMMIT: id:1741323542381, from:30159, delay:0.0001s, distance:167.05m (Euclidean)
[2025-03-07 13:59:23,342] [INFO] [30158] Received COMMIT: id:1741323542381, from:30032, delay:0.0001s, distance:158.55m (Euclidean)
[2025-03-07 13:59:23,487] [INFO] [30158] Received PREPARE: id:1741323542381, from:30094, delay:0.0001s, distance:173.26m (Euclidean)
[2025-03-07 13:59:23,489] [INFO] [30158] Received COMMIT: id:1741323542381, from:30094, delay:0.0001s, distance:173.26m (Euclidean)
[2025-03-07 13:59:23,499] [INFO] [30158] Received PREPARE: id:1741323542381, from:30039, delay:0.0001s, distance:219.30m (Euclidean)
[2025-03-07 13:59:23,499] [INFO] [30158] Received COMMIT: id:1741323542381, from:30039, delay:0.0001s, distance:219.30m (Euclidean)
[2025-03-07 13:59:23,642] [INFO] [30158] Received PREPARE: id:1741323542381, from:30101, delay:0.0002s, distance:257.84m (Euclidean)
[2025-03-07 13:59:23,644] [INFO] [30158] Received COMMIT: id:1741323542381, from:30101, delay:0.0002s, distance:257.84m (Euclidean)
[2025-03-07 13:59:23,665] [INFO] [30158] Received PREPARE: id:1741323542381, from:30143, delay:0.0002s, distance:258.32m (Euclidean)
[2025-03-07 13:59:23,665] [INFO] [30158] Received PREPARE: id:1741323542381, from:30160, delay:0.0001s, distance:197.20m (Euclidean)
[2025-03-07 13:59:23,665] [INFO] [30158] Received COMMIT: id:1741323542381, from:30160, delay:0.0001s, distance:197.20m (Euclidean)
[2025-03-07 13:59:23,665] [INFO] [30158] Received COMMIT: id:1741323542381, from:30143, delay:0.0002s, distance:258.32m (Euclidean)
[2025-03-07 13:59:23,765] [INFO] [30158] Received PREPARE: id:1741323542381, from:30091, delay:0.0000s, distance:112.82m (Euclidean)
[2025-03-07 13:59:23,768] [INFO] [30158] Received COMMIT: id:1741323542381, from:30091, delay:0.0000s, distance:112.82m (Euclidean)
[2025-03-07 13:59:23,824] [INFO] [30158] Received PREPARE: id:1741323542381, from:30187, delay:0.0001s, distance:248.61m (Euclidean)
[2025-03-07 13:59:23,825] [INFO] [30158] Received COMMIT: id:1741323542381, from:30187, delay:0.0001s, distance:248.61m (Euclidean)
[2025-03-07 13:59:23,953] [INFO] [30158] Received PREPARE: id:1741323542381, from:30075, delay:0.0001s, distance:154.52m (Euclidean)
[2025-03-07 13:59:23,953] [INFO] [30158] Received COMMIT: id:1741323542381, from:30075, delay:0.0001s, distance:154.52m (Euclidean)
[2025-03-07 13:59:24,003] [INFO] [30158] Received COMMIT: id:1741323542381, from:30045, delay:0.0001s, distance:241.14m (Euclidean)
[2025-03-07 13:59:24,104] [INFO] [30158] Received PREPARE: id:1741323542381, from:30138, delay:0.0001s, distance:196.88m (Euclidean)
[2025-03-07 13:59:24,104] [INFO] [30158] Received COMMIT: id:1741323542381, from:30138, delay:0.0001s, distance:196.88m (Euclidean)
[2025-03-07 13:59:24,211] [INFO] [30158] Received PREPARE: id:1741323542381, from:30083, delay:0.0002s, distance:278.96m (Euclidean)
[2025-03-07 13:59:24,213] [INFO] [30158] Received COMMIT: id:1741323542381, from:30083, delay:0.0002s, distance:278.96m (Euclidean)
[2025-03-07 13:59:24,561] [INFO] [30158] Received PREPARE: id:1741323542381, from:30099, delay:0.0001s, distance:225.92m (Euclidean)
[2025-03-07 13:59:24,561] [INFO] [30158] Received COMMIT: id:1741323542381, from:30099, delay:0.0001s, distance:225.92m (Euclidean)
[2025-03-07 13:59:24,592] [INFO] [30158] Received PREPARE: id:1741323542381, from:30069, delay:0.0001s, distance:234.48m (Euclidean)
[2025-03-07 13:59:24,592] [INFO] [30158] Received COMMIT: id:1741323542381, from:30069, delay:0.0001s, distance:234.48m (Euclidean)
[2025-03-07 13:59:24,848] [INFO] [30158] Received PREPARE: id:1741323542381, from:30131, delay:0.0000s, distance:119.24m (Euclidean)
[2025-03-07 13:59:24,848] [INFO] [30158] Received COMMIT: id:1741323542381, from:30131, delay:0.0000s, distance:119.24m (Euclidean)
[2025-03-07 13:59:24,893] [INFO] [30158] Received PREPARE: id:1741323542381, from:30001, delay:0.0001s, distance:227.95m (Euclidean)
[2025-03-07 13:59:24,893] [INFO] [30158] Received COMMIT: id:1741323542381, from:30001, delay:0.0001s, distance:227.95m (Euclidean)
[2025-03-07 13:59:25,079] [INFO] [30158] Received PREPARE: id:1741323542381, from:30186, delay:0.0000s, distance:193.06m (Euclidean)
[2025-03-07 13:59:25,079] [INFO] [30158] Received COMMIT: id:1741323542381, from:30186, delay:0.0000s, distance:193.06m (Euclidean)
[2025-03-07 13:59:25,523] [INFO] [30158] Received PREPARE: id:1741323542381, from:30017, delay:0.0000s, distance:25.60m (Euclidean)
[2025-03-07 13:59:25,533] [INFO] [30158] Received COMMIT: id:1741323542381, from:30017, delay:0.0000s, distance:25.60m (Euclidean)
[2025-03-07 13:59:25,793] [INFO] [30158] Received PREPARE: id:1741323542381, from:30014, delay:0.0001s, distance:230.99m (Euclidean)
[2025-03-07 13:59:25,793] [INFO] [30158] Received COMMIT: id:1741323542381, from:30014, delay:0.0001s, distance:230.99m (Euclidean)
[2025-03-07 13:59:26,128] [INFO] [30158] Received PREPARE: id:1741323542381, from:30148, delay:0.0001s, distance:154.86m (Euclidean)
[2025-03-07 13:59:26,139] [INFO] [30158] Received COMMIT: id:1741323542381, from:30148, delay:0.0001s, distance:154.86m (Euclidean)
[2025-03-07 13:59:26,139] [INFO] [30158] Received PREPARE: id:1741323542381, from:30122, delay:0.0002s, distance:272.85m (Euclidean)
[2025-03-07 13:59:26,139] [INFO] [30158] Received COMMIT: id:1741323542381, from:30122, delay:0.0002s, distance:272.85m (Euclidean)
[2025-03-07 13:59:26,615] [INFO] [30158] Received PREPARE: id:1741323542381, from:30008, delay:0.0000s, distance:194.12m (Euclidean)
[2025-03-07 13:59:26,615] [INFO] [30158] Received COMMIT: id:1741323542381, from:30008, delay:0.0000s, distance:194.12m (Euclidean)
[2025-03-07 13:59:26,695] [INFO] [30158] Received PREPARE: id:1741323542381, from:30172, delay:0.0000s, distance:134.88m (Euclidean)
[2025-03-07 13:59:28,247] [INFO] [30158] Received PREPARE: id:1741323542381, from:30072, delay:0.0001s, distance:204.99m (Euclidean)
[2025-03-07 13:59:28,247] [INFO] [30158] Received COMMIT: id:1741323542381, from:30072, delay:0.0001s, distance:204.99m (Euclidean)
[2025-03-07 13:59:28,589] [INFO] [30158] Received COMMIT: id:1741323542381, from:30172, delay:0.0000s, distance:134.88m (Euclidean)
[2025-03-07 13:59:28,830] [INFO] [30158] Received PREPARE: id:1741323542381, from:30183, delay:0.0000s, distance:60.58m (Euclidean)
[2025-03-07 13:59:28,848] [INFO] [30158] Received COMMIT: id:1741323542381, from:30183, delay:0.0000s, distance:60.58m (Euclidean)
[2025-03-07 13:59:37,586] [INFO] [30158] Received PREPARE: id:1741323542381, from:30012, delay:0.0001s, distance:213.68m (Euclidean)
[2025-03-07 13:59:37,588] [INFO] [30158] Received COMMIT: id:1741323542381, from:30012, delay:0.0001s, distance:213.68m (Euclidean)
[2025-03-07 13:59:37,965] [INFO] [30158] Received PREPARE: id:1741323542381, from:30018, delay:0.0000s, distance:153.76m (Euclidean)
[2025-03-07 13:59:38,015] [INFO] [30158] Received COMMIT: id:1741323542381, from:30018, delay:0.0000s, distance:153.76m (Euclidean)
[2025-03-07 13:59:38,113] [INFO] [30158] Received PREPARE: id:1741323542381, from:30047, delay:0.0001s, distance:231.49m (Euclidean)
[2025-03-07 13:59:38,180] [INFO] [30158] Received PREPARE: id:1741323542381, from:30002, delay:0.0001s, distance:246.94m (Euclidean)
[2025-03-07 13:59:38,180] [INFO] [30158] Received COMMIT: id:1741323542381, from:30047, delay:0.0001s, distance:231.49m (Euclidean)
[2025-03-07 13:59:38,180] [INFO] [30158] Received COMMIT: id:1741323542381, from:30002, delay:0.0001s, distance:246.94m (Euclidean)
[2025-03-07 13:59:38,192] [INFO] [30158] Received PREPARE: id:1741323542381, from:30082, delay:0.0002s, distance:258.16m (Euclidean)
[2025-03-07 13:59:38,202] [INFO] [30158] Received COMMIT: id:1741323542381, from:30082, delay:0.0002s, distance:258.16m (Euclidean)
[2025-03-07 13:59:38,266] [INFO] [30158] Received PREPARE: id:1741323542381, from:30185, delay:0.0002s, distance:251.23m (Euclidean)
[2025-03-07 13:59:38,268] [INFO] [30158] Received COMMIT: id:1741323542381, from:30185, delay:0.0002s, distance:251.23m (Euclidean)
[2025-03-07 13:59:38,303] [INFO] [30158] Received PREPARE: id:1741323542381, from:30044, delay:0.0002s, distance:272.21m (Euclidean)
[2025-03-07 13:59:38,324] [INFO] [30158] Received COMMIT: id:1741323542381, from:30044, delay:0.0002s, distance:272.21m (Euclidean)
[2025-03-07 13:59:38,339] [INFO] [30158] Received PREPARE: id:1741323542381, from:30078, delay:0.0000s, distance:109.61m (Euclidean)
[2025-03-07 13:59:38,355] [INFO] [30158] Received PREPARE: id:1741323542381, from:30097, delay:0.0001s, distance:236.95m (Euclidean)
[2025-03-07 13:59:38,424] [INFO] [30158] Received PREPARE: id:1741323542381, from:30030, delay:0.0001s, distance:216.60m (Euclidean)
[2025-03-07 13:59:38,440] [INFO] [30158] Received COMMIT: id:1741323542381, from:30030, delay:0.0001s, distance:216.60m (Euclidean)
[2025-03-07 13:59:38,460] [INFO] [30158] Received COMMIT: id:1741323542381, from:30078, delay:0.0000s, distance:109.61m (Euclidean)
[2025-03-07 13:59:38,515] [INFO] [30158] Received COMMIT: id:1741323542381, from:30097, delay:0.0001s, distance:236.95m (Euclidean)
[2025-03-07 13:59:38,531] [INFO] [30158] Received PREPARE: id:1741323542381, from:30192, delay:0.0001s, distance:223.45m (Euclidean)
[2025-03-07 13:59:38,538] [INFO] [30158] Received PREPARE: id:1741323542381, from:30164, delay:0.0000s, distance:118.55m (Euclidean)
[2025-03-07 13:59:38,675] [INFO] [30158] Received COMMIT: id:1741323542381, from:30164, delay:0.0000s, distance:118.55m (Euclidean)
[2025-03-07 13:59:38,690] [INFO] [30158] Received COMMIT: id:1741323542381, from:30192, delay:0.0001s, distance:223.45m (Euclidean)
[2025-03-07 13:59:38,809] [INFO] [30158] Received PREPARE: id:1741323542381, from:30163, delay:0.0001s, distance:243.42m (Euclidean)
[2025-03-07 13:59:38,844] [INFO] [30158] Received COMMIT: id:1741323542381, from:30163, delay:0.0001s, distance:243.42m (Euclidean)
