[2025-03-07 13:50:46,527] [INFO] Starting node at localhost:30105 | index=106 | f=1, k=4 | Role: Replica
[2025-03-07 13:51:30,237] [INFO] Starting node at localhost:30105 | index=106 | f=1, k=4 | Role: Replica
[2025-03-07 13:51:30,241] [ERROR] Unexpected error in main loop:
Traceback (most recent call last):
  File "pbft.py", line 440, in main
    runner = await serve_app(app, node_addr['host'], node_addr['port'], logger)
  File "pbft.py", line 388, in serve_app
    await site.start()
  File "D:\anaconda\envs\PBFT\lib\site-packages\aiohttp\web_runner.py", line 128, in start
    reuse_port=self._reuse_port,
  File "D:\anaconda\envs\PBFT\lib\asyncio\base_events.py", line 1386, in create_server
    server._start_serving()
  File "D:\anaconda\envs\PBFT\lib\asyncio\base_events.py", line 276, in _start_serving
    sock.listen(self._backlog)
OSError: [WinError 10014] 호출에 대한 포인터 인수를 사용하려는 동안 시스템에서 잘못된 포인터 주소를 감지했습니다
[2025-03-07 13:51:30,241] [ERROR] Error during cleanup.
Traceback (most recent call last):
  File "pbft.py", line 453, in main
    await runner.cleanup()
UnboundLocalError: local variable 'runner' referenced before assignment
[2025-03-07 13:52:35,791] [INFO] Starting node at localhost:30105 | index=106 | f=1, k=4 | Role: Replica
[2025-03-07 13:53:23,837] [INFO] Starting node at localhost:30105 | index=106 | f=1, k=4 | Role: Replica
[2025-03-07 13:53:39,362] [INFO] [30105] Received PREPARE: id:1741323218379, from:30021, delay:0.0000s, distance:116.50m (Euclidean)
[2025-03-07 13:53:39,362] [INFO] [30105] Missing PRE-PREPARE for REQUEST 1741323218379; ignoring PREPARE
[2025-03-07 13:53:39,424] [INFO] [30105] Received PREPARE: id:1741323218379, from:30048, delay:0.0000s, distance:122.53m (Euclidean)
[2025-03-07 13:53:39,424] [INFO] [30105] Missing PRE-PREPARE for REQUEST 1741323218379; ignoring PREPARE
[2025-03-07 13:53:39,438] [INFO] [30105] Received PREPARE: id:1741323218379, from:30052, delay:0.0000s, distance:111.42m (Euclidean)
[2025-03-07 13:53:39,438] [INFO] [30105] Missing PRE-PREPARE for REQUEST 1741323218379; ignoring PREPARE
[2025-03-07 13:53:39,450] [INFO] [30105] Received PREPARE: id:1741323218379, from:30079, delay:0.0000s, distance:77.28m (Euclidean)
[2025-03-07 13:53:39,450] [INFO] [30105] Missing PRE-PREPARE for REQUEST 1741323218379; ignoring PREPARE
[2025-03-07 13:53:39,747] [INFO] [30105] Received PREPARE: id:1741323218379, from:30060, delay:0.0000s, distance:86.01m (Euclidean)
[2025-03-07 13:53:39,747] [INFO] [30105] Missing PRE-PREPARE for REQUEST 1741323218379; ignoring PREPARE
[2025-03-07 13:53:39,747] [INFO] [30105] Received PREPARE: id:1741323218379, from:30033, delay:0.0000s, distance:43.11m (Euclidean)
[2025-03-07 13:53:39,747] [INFO] [30105] Missing PRE-PREPARE for REQUEST 1741323218379; ignoring PREPARE
[2025-03-07 13:53:39,943] [INFO] [30105] Received COMMIT: id:1741323218379, from:30021, delay:0.0000s, distance:116.50m (Euclidean)
[2025-03-07 13:53:40,180] [INFO] [30105] Received PREPARE: id:1741323218379, from:30010, delay:0.0000s, distance:134.85m (Euclidean)
[2025-03-07 13:53:40,180] [INFO] [30105] Missing PRE-PREPARE for REQUEST 1741323218379; ignoring PREPARE
[2025-03-07 13:53:40,196] [INFO] [30105] Received COMMIT: id:1741323218379, from:30010, delay:0.0000s, distance:134.85m (Euclidean)
[2025-03-07 13:53:40,339] [INFO] [30105] Received PREPARE: id:1741323218379, from:30084, delay:0.0001s, distance:204.76m (Euclidean)
[2025-03-07 13:53:40,339] [INFO] [30105] Missing PRE-PREPARE for REQUEST 1741323218379; ignoring PREPARE
[2025-03-07 13:53:40,339] [INFO] [30105] Received COMMIT: id:1741323218379, from:30084, delay:0.0001s, distance:204.76m (Euclidean)
[2025-03-07 13:53:40,371] [INFO] [30105] Received PREPARE: id:1741323218379, from:30039, delay:0.0000s, distance:104.41m (Euclidean)
[2025-03-07 13:53:40,371] [INFO] [30105] Missing PRE-PREPARE for REQUEST 1741323218379; ignoring PREPARE
[2025-03-07 13:53:40,371] [INFO] [30105] Received COMMIT: id:1741323218379, from:30039, delay:0.0000s, distance:104.41m (Euclidean)
[2025-03-07 13:53:40,434] [INFO] [30105] Received PREPARE: id:1741323218379, from:30089, delay:0.0000s, distance:80.01m (Euclidean)
[2025-03-07 13:53:40,434] [INFO] [30105] Missing PRE-PREPARE for REQUEST 1741323218379; ignoring PREPARE
[2025-03-07 13:53:40,434] [INFO] [30105] Received COMMIT: id:1741323218379, from:30089, delay:0.0000s, distance:80.01m (Euclidean)
[2025-03-07 13:53:40,497] [INFO] [30105] Received COMMIT: id:1741323218379, from:30079, delay:0.0000s, distance:77.28m (Euclidean)
[2025-03-07 13:53:40,561] [INFO] [30105] Received COMMIT: id:1741323218379, from:30059, delay:0.0001s, distance:192.78m (Euclidean)
[2025-03-07 13:53:40,561] [INFO] [30105] Received PREPARE: id:1741323218379, from:30059, delay:0.0001s, distance:192.78m (Euclidean)
[2025-03-07 13:53:40,561] [INFO] [30105] Missing PRE-PREPARE for REQUEST 1741323218379; ignoring PREPARE
[2025-03-07 13:53:40,608] [INFO] [30105] Received PREPARE: id:1741323218379, from:30040, delay:0.0001s, distance:198.93m (Euclidean)
[2025-03-07 13:53:40,608] [INFO] [30105] Missing PRE-PREPARE for REQUEST 1741323218379; ignoring PREPARE
[2025-03-07 13:53:40,627] [INFO] [30105] Received PREPARE: id:1741323218379, from:30117, delay:0.0000s, distance:45.38m (Euclidean)
[2025-03-07 13:53:40,628] [INFO] [30105] Missing PRE-PREPARE for REQUEST 1741323218379; ignoring PREPARE
[2025-03-07 13:53:40,671] [INFO] [30105] Received PREPARE: id:1741323218379, from:30094, delay:0.0000s, distance:143.43m (Euclidean)
[2025-03-07 13:53:40,671] [INFO] [30105] Missing PRE-PREPARE for REQUEST 1741323218379; ignoring PREPARE
[2025-03-07 13:53:40,671] [INFO] [30105] Received PREPARE: id:1741323218379, from:30053, delay:0.0001s, distance:194.39m (Euclidean)
[2025-03-07 13:53:40,671] [INFO] [30105] Missing PRE-PREPARE for REQUEST 1741323218379; ignoring PREPARE
[2025-03-07 13:53:40,671] [INFO] [30105] Received COMMIT: id:1741323218379, from:30053, delay:0.0001s, distance:194.39m (Euclidean)
[2025-03-07 13:53:40,671] [INFO] [30105] Received COMMIT: id:1741323218379, from:30094, delay:0.0000s, distance:143.43m (Euclidean)
[2025-03-07 13:53:40,671] [INFO] [30105] Received PREPARE: id:1741323218379, from:30051, delay:0.0000s, distance:106.28m (Euclidean)
[2025-03-07 13:53:40,671] [INFO] [30105] Missing PRE-PREPARE for REQUEST 1741323218379; ignoring PREPARE
[2025-03-07 13:53:40,671] [INFO] [30105] Received COMMIT: id:1741323218379, from:30051, delay:0.0000s, distance:106.28m (Euclidean)
[2025-03-07 13:53:40,703] [INFO] [30105] Received PREPARE: id:1741323218379, from:30034, delay:0.0001s, distance:176.78m (Euclidean)
[2025-03-07 13:53:40,703] [INFO] [30105] Missing PRE-PREPARE for REQUEST 1741323218379; ignoring PREPARE
[2025-03-07 13:53:40,703] [INFO] [30105] Received COMMIT: id:1741323218379, from:30034, delay:0.0001s, distance:176.78m (Euclidean)
[2025-03-07 13:53:40,735] [INFO] [30105] Received PREPARE: id:1741323218379, from:30044, delay:0.0001s, distance:246.93m (Euclidean)
[2025-03-07 13:53:40,735] [INFO] [30105] Missing PRE-PREPARE for REQUEST 1741323218379; ignoring PREPARE
[2025-03-07 13:53:40,845] [INFO] [30105] Received PREPARE: id:1741323218379, from:30090, delay:0.0001s, distance:179.75m (Euclidean)
[2025-03-07 13:53:40,845] [INFO] [30105] Missing PRE-PREPARE for REQUEST 1741323218379; ignoring PREPARE
[2025-03-07 13:53:40,845] [INFO] [30105] Received PREPARE: id:1741323218379, from:30097, delay:0.0001s, distance:233.61m (Euclidean)
[2025-03-07 13:53:40,845] [INFO] [30105] Missing PRE-PREPARE for REQUEST 1741323218379; ignoring PREPARE
[2025-03-07 13:53:40,856] [INFO] [30105] Received COMMIT: id:1741323218379, from:30097, delay:0.0001s, distance:233.61m (Euclidean)
[2025-03-07 13:53:40,893] [INFO] [30105] Received COMMIT: id:1741323218379, from:30090, delay:0.0001s, distance:179.75m (Euclidean)
[2025-03-07 13:53:41,146] [INFO] [30105] Received PREPARE: id:1741323218379, from:30087, delay:0.0001s, distance:225.97m (Euclidean)
[2025-03-07 13:53:41,146] [INFO] [30105] Missing PRE-PREPARE for REQUEST 1741323218379; ignoring PREPARE
[2025-03-07 13:53:41,150] [INFO] [30105] Received COMMIT: id:1741323218379, from:30087, delay:0.0001s, distance:225.97m (Euclidean)
[2025-03-07 13:53:41,225] [INFO] [30105] Received COMMIT: id:1741323218379, from:30044, delay:0.0001s, distance:246.93m (Euclidean)
[2025-03-07 13:53:41,241] [INFO] [30105] Received PREPARE: id:1741323218379, from:30062, delay:0.0002s, distance:259.72m (Euclidean)
[2025-03-07 13:53:41,241] [INFO] [30105] Missing PRE-PREPARE for REQUEST 1741323218379; ignoring PREPARE
[2025-03-07 13:53:41,241] [INFO] [30105] Received COMMIT: id:1741323218379, from:30062, delay:0.0002s, distance:259.72m (Euclidean)
[2025-03-07 13:53:41,304] [INFO] [30105] Received COMMIT: id:1741323218379, from:30052, delay:0.0000s, distance:111.42m (Euclidean)
[2025-03-07 13:53:41,399] [INFO] [30105] Received COMMIT: id:1741323218379, from:30060, delay:0.0000s, distance:86.01m (Euclidean)
[2025-03-07 13:53:41,399] [INFO] [30105] Received PREPARE: id:1741323218379, from:30050, delay:0.0002s, distance:291.06m (Euclidean)
[2025-03-07 13:53:41,399] [INFO] [30105] Missing PRE-PREPARE for REQUEST 1741323218379; ignoring PREPARE
[2025-03-07 13:53:41,399] [INFO] [30105] Received COMMIT: id:1741323218379, from:30050, delay:0.0002s, distance:291.06m (Euclidean)
[2025-03-07 13:53:41,478] [INFO] [30105] Received COMMIT: id:1741323218379, from:30117, delay:0.0000s, distance:45.38m (Euclidean)
[2025-03-07 13:53:41,636] [INFO] [30105] Received PREPARE: id:1741323218379, from:30018, delay:0.0002s, distance:282.79m (Euclidean)
[2025-03-07 13:53:41,636] [INFO] [30105] Missing PRE-PREPARE for REQUEST 1741323218379; ignoring PREPARE
[2025-03-07 13:53:41,636] [INFO] [30105] Received COMMIT: id:1741323218379, from:30018, delay:0.0002s, distance:282.79m (Euclidean)
[2025-03-07 13:53:41,673] [INFO] [30105] Received PREPARE: id:1741323218379, from:30046, delay:0.0000s, distance:88.31m (Euclidean)
[2025-03-07 13:53:41,673] [INFO] [30105] Missing PRE-PREPARE for REQUEST 1741323218379; ignoring PREPARE
[2025-03-07 13:53:41,673] [INFO] [30105] Received COMMIT: id:1741323218379, from:30046, delay:0.0000s, distance:88.31m (Euclidean)
[2025-03-07 13:53:41,826] [INFO] [30105] Received PREPARE: id:1741323218379, from:30012, delay:0.0001s, distance:211.02m (Euclidean)
[2025-03-07 13:53:41,826] [INFO] [30105] Missing PRE-PREPARE for REQUEST 1741323218379; ignoring PREPARE
[2025-03-07 13:53:41,826] [INFO] [30105] Received COMMIT: id:1741323218379, from:30012, delay:0.0001s, distance:211.02m (Euclidean)
[2025-03-07 13:53:41,826] [INFO] [30105] Received PREPARE: id:1741323218379, from:30030, delay:0.0001s, distance:165.05m (Euclidean)
[2025-03-07 13:53:41,826] [INFO] [30105] Missing PRE-PREPARE for REQUEST 1741323218379; ignoring PREPARE
[2025-03-07 13:53:41,842] [INFO] [30105] Received COMMIT: id:1741323218379, from:30074, delay:0.0001s, distance:222.75m (Euclidean)
[2025-03-07 13:53:41,842] [INFO] [30105] Received COMMIT: id:1741323218379, from:30030, delay:0.0001s, distance:165.05m (Euclidean)
[2025-03-07 13:53:41,842] [INFO] [30105] Received PREPARE: id:1741323218379, from:30074, delay:0.0001s, distance:222.75m (Euclidean)
[2025-03-07 13:53:41,842] [INFO] [30105] Missing PRE-PREPARE for REQUEST 1741323218379; ignoring PREPARE
[2025-03-07 13:53:41,873] [INFO] [30105] Received COMMIT: id:1741323218379, from:30040, delay:0.0001s, distance:198.93m (Euclidean)
[2025-03-07 13:53:41,967] [INFO] [30105] Received COMMIT: id:1741323218379, from:30033, delay:0.0000s, distance:43.11m (Euclidean)
[2025-03-07 13:53:42,064] [INFO] [30105] Received PREPARE: id:1741323218379, from:30032, delay:0.0000s, distance:140.06m (Euclidean)
[2025-03-07 13:53:42,080] [INFO] [30105] Missing PRE-PREPARE for REQUEST 1741323218379; ignoring PREPARE
[2025-03-07 13:53:42,177] [INFO] [30105] Received PREPARE: id:1741323218379, from:30057, delay:0.0000s, distance:161.18m (Euclidean)
[2025-03-07 13:53:42,177] [INFO] [30105] Missing PRE-PREPARE for REQUEST 1741323218379; ignoring PREPARE
[2025-03-07 13:53:42,177] [INFO] [30105] Received COMMIT: id:1741323218379, from:30057, delay:0.0000s, distance:161.18m (Euclidean)
[2025-03-07 13:53:42,222] [INFO] [30105] Received PREPARE: id:1741323218379, from:30043, delay:0.0001s, distance:206.66m (Euclidean)
[2025-03-07 13:53:42,222] [INFO] [30105] Missing PRE-PREPARE for REQUEST 1741323218379; ignoring PREPARE
[2025-03-07 13:53:42,222] [INFO] [30105] Received COMMIT: id:1741323218379, from:30043, delay:0.0001s, distance:206.66m (Euclidean)
[2025-03-07 13:53:42,269] [INFO] [30105] Received PREPARE: id:1741323218379, from:30098, delay:0.0001s, distance:226.94m (Euclidean)
[2025-03-07 13:53:42,269] [INFO] [30105] Missing PRE-PREPARE for REQUEST 1741323218379; ignoring PREPARE
[2025-03-07 13:53:42,269] [INFO] [30105] Received COMMIT: id:1741323218379, from:30098, delay:0.0001s, distance:226.94m (Euclidean)
[2025-03-07 13:53:42,320] [INFO] [30105] Received PREPARE: id:1741323218379, from:30056, delay:0.0001s, distance:266.46m (Euclidean)
[2025-03-07 13:53:42,320] [INFO] [30105] Missing PRE-PREPARE for REQUEST 1741323218379; ignoring PREPARE
[2025-03-07 13:53:42,405] [INFO] [30105] Received COMMIT: id:1741323218379, from:30056, delay:0.0001s, distance:266.46m (Euclidean)
[2025-03-07 13:53:42,411] [INFO] [30105] Received PREPARE: id:1741323218379, from:30080, delay:0.0002s, distance:274.98m (Euclidean)
[2025-03-07 13:53:42,411] [INFO] [30105] Missing PRE-PREPARE for REQUEST 1741323218379; ignoring PREPARE
[2025-03-07 13:53:42,411] [INFO] [30105] Received PREPARE: id:1741323218379, from:30026, delay:0.0001s, distance:229.94m (Euclidean)
[2025-03-07 13:53:42,411] [INFO] [30105] Missing PRE-PREPARE for REQUEST 1741323218379; ignoring PREPARE
[2025-03-07 13:53:42,411] [INFO] [30105] Received COMMIT: id:1741323218379, from:30026, delay:0.0001s, distance:229.94m (Euclidean)
[2025-03-07 13:53:42,429] [INFO] [30105] Received PREPARE: id:1741323218379, from:30002, delay:0.0002s, distance:257.15m (Euclidean)
[2025-03-07 13:53:42,429] [INFO] [30105] Missing PRE-PREPARE for REQUEST 1741323218379; ignoring PREPARE
[2025-03-07 13:53:42,429] [INFO] [30105] Received COMMIT: id:1741323218379, from:30002, delay:0.0002s, distance:257.15m (Euclidean)
[2025-03-07 13:53:42,446] [INFO] [30105] Received COMMIT: id:1741323218379, from:30080, delay:0.0002s, distance:274.98m (Euclidean)
[2025-03-07 13:53:42,498] [INFO] [30105] Received COMMIT: id:1741323218379, from:30048, delay:0.0000s, distance:122.53m (Euclidean)
[2025-03-07 13:53:42,522] [INFO] [30105] Received PREPARE: id:1741323218379, from:30104, delay:0.0001s, distance:213.20m (Euclidean)
[2025-03-07 13:53:42,522] [INFO] [30105] Missing PRE-PREPARE for REQUEST 1741323218379; ignoring PREPARE
[2025-03-07 13:53:42,522] [INFO] [30105] Received COMMIT: id:1741323218379, from:30104, delay:0.0001s, distance:213.20m (Euclidean)
[2025-03-07 13:53:42,524] [INFO] [30105] Received PREPARE: id:1741323218379, from:30005, delay:0.0002s, distance:265.63m (Euclidean)
[2025-03-07 13:53:42,524] [INFO] [30105] Missing PRE-PREPARE for REQUEST 1741323218379; ignoring PREPARE
[2025-03-07 13:53:42,524] [INFO] [30105] Received COMMIT: id:1741323218379, from:30005, delay:0.0002s, distance:265.63m (Euclidean)
[2025-03-07 13:53:42,526] [INFO] [30105] Received PREPARE: id:1741323218379, from:30054, delay:0.0001s, distance:184.78m (Euclidean)
[2025-03-07 13:53:42,526] [INFO] [30105] Missing PRE-PREPARE for REQUEST 1741323218379; ignoring PREPARE
[2025-03-07 13:53:42,540] [INFO] [30105] Received COMMIT: id:1741323218379, from:30054, delay:0.0001s, distance:184.78m (Euclidean)
[2025-03-07 13:53:42,664] [INFO] [30105] Received PREPARE: id:1741323218379, from:30045, delay:0.0002s, distance:250.04m (Euclidean)
[2025-03-07 13:53:42,664] [INFO] [30105] Missing PRE-PREPARE for REQUEST 1741323218379; ignoring PREPARE
[2025-03-07 13:53:42,664] [INFO] [30105] Received COMMIT: id:1741323218379, from:30045, delay:0.0002s, distance:250.04m (Euclidean)
[2025-03-07 13:53:42,932] [INFO] [30105] Received PREPARE: id:1741323218379, from:30095, delay:0.0000s, distance:110.51m (Euclidean)
[2025-03-07 13:53:42,932] [INFO] [30105] Missing PRE-PREPARE for REQUEST 1741323218379; ignoring PREPARE
[2025-03-07 13:53:43,017] [INFO] [30105] Received PREPARE: id:1741323218379, from:30078, delay:0.0002s, distance:253.13m (Euclidean)
[2025-03-07 13:53:43,017] [INFO] [30105] Missing PRE-PREPARE for REQUEST 1741323218379; ignoring PREPARE
[2025-03-07 13:53:43,017] [INFO] [30105] Received COMMIT: id:1741323218379, from:30078, delay:0.0002s, distance:253.13m (Euclidean)
[2025-03-07 13:53:43,077] [INFO] [30105] Received PREPARE: id:1741323218379, from:30017, delay:0.0000s, distance:183.71m (Euclidean)
[2025-03-07 13:53:43,077] [INFO] [30105] Missing PRE-PREPARE for REQUEST 1741323218379; ignoring PREPARE
[2025-03-07 13:53:43,077] [INFO] [30105] Received PREPARE: id:1741323218379, from:30073, delay:0.0001s, distance:186.04m (Euclidean)
[2025-03-07 13:53:43,077] [INFO] [30105] Missing PRE-PREPARE for REQUEST 1741323218379; ignoring PREPARE
[2025-03-07 13:53:43,077] [INFO] [30105] Received COMMIT: id:1741323218379, from:30017, delay:0.0000s, distance:183.71m (Euclidean)
[2025-03-07 13:53:43,110] [INFO] [30105] Received COMMIT: id:1741323218379, from:30073, delay:0.0001s, distance:186.04m (Euclidean)
[2025-03-07 13:53:43,160] [INFO] [30105] Received PRE-PREPARE: id:1741323218379, from:Leader(30000), delay:0.0000s, distance:194.11m (Euclidean)
[2025-03-07 13:53:43,160] [INFO] [30105] Broadcasting PREPARE for REQUEST 1741323218379
[2025-03-07 13:53:43,314] [INFO] [30105] Received COMMIT: id:1741323218379, from:30061, delay:0.0002s, distance:264.44m (Euclidean)
[2025-03-07 13:53:43,314] [INFO] [30105] Received PREPARE: id:1741323218379, from:30061, delay:0.0002s, distance:264.44m (Euclidean)
[2025-03-07 13:53:43,314] [INFO] [30105] Broadcasting COMMIT for REQUEST 1741323218379
[2025-03-07 13:53:43,470] [INFO] [30105] Received PREPARE: id:1741323218379, from:30037, delay:0.0002s, distance:276.29m (Euclidean)
[2025-03-07 13:53:43,470] [INFO] [30105] Received COMMIT: id:1741323218379, from:30037, delay:0.0002s, distance:276.29m (Euclidean)
[2025-03-07 13:53:43,470] [INFO] [30105] Received COMMIT: id:1741323218379, from:30009, delay:0.0002s, distance:252.21m (Euclidean)
[2025-03-07 13:53:43,470] [INFO] [30105] Received PREPARE: id:1741323218379, from:30009, delay:0.0002s, distance:252.21m (Euclidean)
[2025-03-07 13:53:43,571] [INFO] [30105] Received PREPARE: id:1741323218379, from:30004, delay:0.0001s, distance:221.15m (Euclidean)
[2025-03-07 13:53:43,580] [INFO] [30105] Received PREPARE: id:1741323218379, from:30069, delay:0.0001s, distance:231.94m (Euclidean)
[2025-03-07 13:53:43,580] [INFO] [30105] Received COMMIT: id:1741323218379, from:30004, delay:0.0001s, distance:221.15m (Euclidean)
[2025-03-07 13:53:43,580] [INFO] [30105] Received COMMIT: id:1741323218379, from:30069, delay:0.0001s, distance:231.94m (Euclidean)
[2025-03-07 13:53:43,580] [INFO] [30105] Received PREPARE: id:1741323218379, from:30099, delay:0.0000s, distance:162.40m (Euclidean)
[2025-03-07 13:53:43,580] [INFO] [30105] Received COMMIT: id:1741323218379, from:30099, delay:0.0000s, distance:162.40m (Euclidean)
[2025-03-07 13:53:43,723] [INFO] [30105] Received COMMIT: id:1741323218379, from:30032, delay:0.0000s, distance:140.06m (Euclidean)
[2025-03-07 13:53:43,735] [INFO] [30105] Received PREPARE: id:1741323218379, from:30036, delay:0.0002s, distance:255.27m (Euclidean)
[2025-03-07 13:53:43,738] [INFO] [30105] Received COMMIT: id:1741323218379, from:30036, delay:0.0002s, distance:255.27m (Euclidean)
[2025-03-07 13:53:43,833] [INFO] [30105] Received PREPARE: id:1741323218379, from:30042, delay:0.0002s, distance:278.72m (Euclidean)
[2025-03-07 13:53:43,833] [INFO] [30105] Received COMMIT: id:1741323218379, from:30042, delay:0.0002s, distance:278.72m (Euclidean)
[2025-03-07 13:53:44,307] [INFO] [30105] Received PREPARE: id:1741323218379, from:30055, delay:0.0002s, distance:255.83m (Euclidean)
[2025-03-07 13:53:44,307] [INFO] [30105] Received COMMIT: id:1741323218379, from:30055, delay:0.0002s, distance:255.83m (Euclidean)
[2025-03-07 13:53:44,339] [INFO] [30105] Received PREPARE: id:1741323218379, from:30041, delay:0.0000s, distance:175.41m (Euclidean)
[2025-03-07 13:53:44,339] [INFO] [30105] Received COMMIT: id:1741323218379, from:30041, delay:0.0000s, distance:175.41m (Euclidean)
[2025-03-07 13:53:44,371] [INFO] [30105] Received PREPARE: id:1741323218379, from:30019, delay:0.0002s, distance:271.61m (Euclidean)
[2025-03-07 13:53:44,371] [INFO] [30105] Received COMMIT: id:1741323218379, from:30019, delay:0.0002s, distance:271.61m (Euclidean)
[2025-03-07 13:53:44,473] [INFO] [30105] Received PREPARE: id:1741323218379, from:30072, delay:0.0002s, distance:274.27m (Euclidean)
[2025-03-07 13:53:44,473] [INFO] [30105] Received COMMIT: id:1741323218379, from:30088, delay:0.0002s, distance:267.09m (Euclidean)
[2025-03-07 13:53:44,473] [INFO] [30105] Received COMMIT: id:1741323218379, from:30072, delay:0.0002s, distance:274.27m (Euclidean)
[2025-03-07 13:53:44,473] [INFO] [30105] Received PREPARE: id:1741323218379, from:30088, delay:0.0002s, distance:267.09m (Euclidean)
[2025-03-07 13:53:44,734] [INFO] [30105] Received PREPARE: id:1741323218379, from:30058, delay:0.0001s, distance:235.44m (Euclidean)
[2025-03-07 13:53:44,740] [INFO] [30105] Received COMMIT: id:1741323218379, from:30058, delay:0.0001s, distance:235.44m (Euclidean)
[2025-03-07 13:53:44,914] [INFO] [30105] Received PREPARE: id:1741323218379, from:30028, delay:0.0002s, distance:267.92m (Euclidean)
[2025-03-07 13:53:44,914] [INFO] [30105] Received COMMIT: id:1741323218379, from:30028, delay:0.0002s, distance:267.92m (Euclidean)
[2025-03-07 13:53:45,035] [INFO] [30105] Received PREPARE: id:1741323218379, from:30001, delay:0.0002s, distance:295.01m (Euclidean)
[2025-03-07 13:53:45,035] [INFO] [30105] Received COMMIT: id:1741323218379, from:30001, delay:0.0002s, distance:295.01m (Euclidean)
[2025-03-07 13:53:45,056] [INFO] [30105] Received PREPARE: id:1741323218379, from:30091, delay:0.0001s, distance:211.36m (Euclidean)
[2025-03-07 13:53:45,114] [INFO] [30105] Received PREPARE: id:1741323218379, from:30086, delay:0.0001s, distance:213.37m (Euclidean)
[2025-03-07 13:53:45,114] [INFO] [30105] Received COMMIT: id:1741323218379, from:30086, delay:0.0001s, distance:213.37m (Euclidean)
[2025-03-07 13:53:45,146] [INFO] [30105] Received COMMIT: id:1741323218379, from:30091, delay:0.0001s, distance:211.36m (Euclidean)
[2025-03-07 13:53:45,344] [INFO] [30105] Received PREPARE: id:1741323218379, from:30096, delay:0.0002s, distance:258.99m (Euclidean)
[2025-03-07 13:53:45,344] [INFO] [30105] Received COMMIT: id:1741323218379, from:30096, delay:0.0002s, distance:258.99m (Euclidean)
[2025-03-07 13:53:45,385] [INFO] [30105] Received COMMIT: id:1741323218379, from:30095, delay:0.0000s, distance:110.51m (Euclidean)
[2025-03-07 13:53:45,400] [INFO] [30105] Received PREPARE: id:1741323218379, from:30102, delay:0.0001s, distance:216.54m (Euclidean)
[2025-03-07 13:53:45,434] [INFO] [30105] Received COMMIT: id:1741323218379, from:30102, delay:0.0001s, distance:216.54m (Euclidean)
[2025-03-07 13:53:45,446] [INFO] [30105] Received COMMIT: id:1741323218379, from:30070, delay:0.0002s, distance:257.39m (Euclidean)
[2025-03-07 13:53:45,449] [INFO] [30105] Received PREPARE: id:1741323218379, from:30070, delay:0.0002s, distance:257.39m (Euclidean)
[2025-03-07 13:53:45,797] [INFO] [30105] Received PREPARE: id:1741323218379, from:30006, delay:0.0002s, distance:290.15m (Euclidean)
[2025-03-07 13:53:45,810] [INFO] [30105] Received COMMIT: id:1741323218379, from:30006, delay:0.0002s, distance:290.15m (Euclidean)
[2025-03-07 13:53:45,961] [INFO] [30105] Received PREPARE: id:1741323218379, from:30153, delay:0.0000s, distance:123.90m (Euclidean)
[2025-03-07 13:53:45,984] [INFO] [30105] Received PREPARE: id:1741323218379, from:30049, delay:0.0001s, distance:219.01m (Euclidean)
[2025-03-07 13:53:45,984] [INFO] [30105] Received COMMIT: id:1741323218379, from:30049, delay:0.0001s, distance:219.01m (Euclidean)
[2025-03-07 13:53:46,032] [INFO] [30105] Received PREPARE: id:1741323218379, from:30083, delay:0.0001s, distance:210.14m (Euclidean)
[2025-03-07 13:53:46,037] [INFO] [30105] Received COMMIT: id:1741323218379, from:30083, delay:0.0001s, distance:210.14m (Euclidean)
[2025-03-07 13:53:46,037] [INFO] [30105] Received PREPARE: id:1741323218379, from:30031, delay:0.0002s, distance:254.21m (Euclidean)
[2025-03-07 13:53:46,047] [INFO] [30105] Received COMMIT: id:1741323218379, from:30031, delay:0.0002s, distance:254.21m (Euclidean)
[2025-03-07 13:53:46,174] [INFO] [30105] Received PREPARE: id:1741323218379, from:30035, delay:0.0002s, distance:261.29m (Euclidean)
[2025-03-07 13:53:46,174] [INFO] [30105] Received COMMIT: id:1741323218379, from:30035, delay:0.0002s, distance:261.29m (Euclidean)
[2025-03-07 13:53:46,574] [INFO] [30105] Received PREPARE: id:1741323218379, from:30014, delay:0.0001s, distance:248.55m (Euclidean)
[2025-03-07 13:53:46,574] [INFO] [30105] Received COMMIT: id:1741323218379, from:30014, delay:0.0001s, distance:248.55m (Euclidean)
[2025-03-07 13:53:46,629] [INFO] [30105] Received PREPARE: id:1741323218379, from:30016, delay:0.0002s, distance:275.06m (Euclidean)
[2025-03-07 13:53:46,629] [INFO] [30105] Received COMMIT: id:1741323218379, from:30016, delay:0.0002s, distance:275.06m (Euclidean)
[2025-03-07 13:53:46,854] [INFO] [30105] Received PREPARE: id:1741323218379, from:30003, delay:0.0000s, distance:159.55m (Euclidean)
[2025-03-07 13:53:46,854] [INFO] [30105] Received COMMIT: id:1741323218379, from:30003, delay:0.0000s, distance:159.55m (Euclidean)
[2025-03-07 13:53:46,896] [INFO] [30105] Received PREPARE: id:1741323218379, from:30154, delay:0.0001s, distance:184.81m (Euclidean)
[2025-03-07 13:53:46,900] [INFO] [30105] Received PREPARE: id:1741323218379, from:30007, delay:0.0000s, distance:122.87m (Euclidean)
[2025-03-07 13:53:46,900] [INFO] [30105] Received COMMIT: id:1741323218379, from:30007, delay:0.0000s, distance:122.87m (Euclidean)
[2025-03-07 13:53:47,265] [INFO] [30105] Received COMMIT: id:1741323218379, from:30153, delay:0.0000s, distance:123.90m (Euclidean)
[2025-03-07 13:53:47,316] [INFO] [30105] Received PREPARE: id:1741323218379, from:30134, delay:0.0000s, distance:142.92m (Euclidean)
[2025-03-07 13:53:47,316] [INFO] [30105] Received COMMIT: id:1741323218379, from:30134, delay:0.0000s, distance:142.92m (Euclidean)
[2025-03-07 13:53:47,409] [INFO] [30105] Received PREPARE: id:1741323218379, from:30136, delay:0.0001s, distance:217.11m (Euclidean)
[2025-03-07 13:53:47,615] [INFO] [30105] Received PREPARE: id:1741323218379, from:30147, delay:0.0001s, distance:157.58m (Euclidean)
[2025-03-07 13:53:47,615] [INFO] [30105] Received COMMIT: id:1741323218379, from:30147, delay:0.0001s, distance:157.58m (Euclidean)
[2025-03-07 13:53:47,645] [ERROR] [30105] Error sending to http://localhost:30029/prepare: Cannot connect to host localhost:30029 ssl:default [Connect call failed ('127.0.0.1', 30029)]
Traceback (most recent call last):
  File "D:\anaconda\envs\PBFT\lib\site-packages\aiohttp\connector.py", line 980, in _wrap_create_connection
    return await self._loop.create_connection(*args, **kwargs)  # type: ignore[return-value]  # noqa
  File "D:\anaconda\envs\PBFT\lib\asyncio\base_events.py", line 948, in create_connection
    raise exceptions[0]
  File "D:\anaconda\envs\PBFT\lib\asyncio\base_events.py", line 935, in create_connection
    await self.sock_connect(sock, address)
  File "D:\anaconda\envs\PBFT\lib\asyncio\selector_events.py", line 475, in sock_connect
    return await fut
  File "D:\anaconda\envs\PBFT\lib\asyncio\selector_events.py", line 505, in _sock_connect_cb
    raise OSError(err, f'Connect call failed {address}')
ConnectionRefusedError: [Errno 10061] Connect call failed ('127.0.0.1', 30029)

The above exception was the direct cause of the following exception:

Traceback (most recent call last):
  File "pbft.py", line 236, in send_message
    await send_with_delay(self.session, self.node_info, target, url, data, self.bandwidth_data)
  File "pbft.py", line 63, in send_with_delay
    async with session.post(url, json=data) as resp:
  File "D:\anaconda\envs\PBFT\lib\site-packages\aiohttp\client.py", line 1141, in __aenter__
    self._resp = await self._coro
  File "D:\anaconda\envs\PBFT\lib\site-packages\aiohttp\client.py", line 537, in _request
    req, traces=traces, timeout=real_timeout
  File "D:\anaconda\envs\PBFT\lib\site-packages\aiohttp\connector.py", line 540, in connect
    proto = await self._create_connection(req, traces, timeout)
  File "D:\anaconda\envs\PBFT\lib\site-packages\aiohttp\connector.py", line 901, in _create_connection
    _, proto = await self._create_direct_connection(req, traces, timeout)
  File "D:\anaconda\envs\PBFT\lib\site-packages\aiohttp\connector.py", line 1206, in _create_direct_connection
    raise last_exc
  File "D:\anaconda\envs\PBFT\lib\site-packages\aiohttp\connector.py", line 1187, in _create_direct_connection
    client_error=client_error,
  File "D:\anaconda\envs\PBFT\lib\site-packages\aiohttp\connector.py", line 988, in _wrap_create_connection
    raise client_error(req.connection_key, exc) from exc
aiohttp.client_exceptions.ClientConnectorError: Cannot connect to host localhost:30029 ssl:default [Connect call failed ('127.0.0.1', 30029)]
[2025-03-07 13:53:47,693] [INFO] [30105] Received PREPARE: id:1741323218379, from:30139, delay:0.0000s, distance:41.35m (Euclidean)
[2025-03-07 13:53:47,693] [INFO] [30105] Received PREPARE: id:1741323218379, from:30122, delay:0.0002s, distance:257.34m (Euclidean)
[2025-03-07 13:53:47,693] [INFO] [30105] Received COMMIT: id:1741323218379, from:30122, delay:0.0002s, distance:257.34m (Euclidean)
[2025-03-07 13:53:47,743] [INFO] [30105] Received PREPARE: id:1741323218379, from:30110, delay:0.0001s, distance:220.05m (Euclidean)
[2025-03-07 13:53:47,743] [INFO] [30105] Received COMMIT: id:1741323218379, from:30110, delay:0.0001s, distance:220.05m (Euclidean)
[2025-03-07 13:53:47,803] [INFO] [30105] Received COMMIT: id:1741323218379, from:30154, delay:0.0001s, distance:184.81m (Euclidean)
[2025-03-07 13:53:47,866] [INFO] [30105] Received COMMIT: id:1741323218379, from:30136, delay:0.0001s, distance:217.11m (Euclidean)
[2025-03-07 13:53:47,976] [INFO] [30105] Received PREPARE: id:1741323218379, from:30109, delay:0.0000s, distance:101.60m (Euclidean)
[2025-03-07 13:53:48,198] [INFO] [30105] Received PREPARE: id:1741323218379, from:30135, delay:0.0001s, distance:237.03m (Euclidean)
[2025-03-07 13:53:48,198] [INFO] [30105] Received COMMIT: id:1741323218379, from:30135, delay:0.0001s, distance:237.03m (Euclidean)
[2025-03-07 13:53:48,198] [INFO] [30105] Received PREPARE: id:1741323218379, from:30158, delay:0.0001s, distance:213.58m (Euclidean)
[2025-03-07 13:53:48,198] [INFO] [30105] Received COMMIT: id:1741323218379, from:30158, delay:0.0001s, distance:213.58m (Euclidean)
[2025-03-07 13:53:48,231] [INFO] [30105] Received COMMIT: id:1741323218379, from:30139, delay:0.0000s, distance:41.35m (Euclidean)
[2025-03-07 13:53:48,261] [INFO] [30105] Received COMMIT: id:1741323218379, from:30109, delay:0.0000s, distance:101.60m (Euclidean)
[2025-03-07 13:53:48,372] [ERROR] [30105] Error sending to http://localhost:30023/prepare: Cannot connect to host localhost:30023 ssl:default [Connect call failed ('127.0.0.1', 30023)]
Traceback (most recent call last):
  File "D:\anaconda\envs\PBFT\lib\site-packages\aiohttp\connector.py", line 980, in _wrap_create_connection
    return await self._loop.create_connection(*args, **kwargs)  # type: ignore[return-value]  # noqa
  File "D:\anaconda\envs\PBFT\lib\asyncio\base_events.py", line 948, in create_connection
    raise exceptions[0]
  File "D:\anaconda\envs\PBFT\lib\asyncio\base_events.py", line 935, in create_connection
    await self.sock_connect(sock, address)
  File "D:\anaconda\envs\PBFT\lib\asyncio\selector_events.py", line 475, in sock_connect
    return await fut
  File "D:\anaconda\envs\PBFT\lib\asyncio\selector_events.py", line 505, in _sock_connect_cb
    raise OSError(err, f'Connect call failed {address}')
ConnectionRefusedError: [Errno 10061] Connect call failed ('127.0.0.1', 30023)

The above exception was the direct cause of the following exception:

Traceback (most recent call last):
  File "pbft.py", line 236, in send_message
    await send_with_delay(self.session, self.node_info, target, url, data, self.bandwidth_data)
  File "pbft.py", line 63, in send_with_delay
    async with session.post(url, json=data) as resp:
  File "D:\anaconda\envs\PBFT\lib\site-packages\aiohttp\client.py", line 1141, in __aenter__
    self._resp = await self._coro
  File "D:\anaconda\envs\PBFT\lib\site-packages\aiohttp\client.py", line 537, in _request
    req, traces=traces, timeout=real_timeout
  File "D:\anaconda\envs\PBFT\lib\site-packages\aiohttp\connector.py", line 540, in connect
    proto = await self._create_connection(req, traces, timeout)
  File "D:\anaconda\envs\PBFT\lib\site-packages\aiohttp\connector.py", line 901, in _create_connection
    _, proto = await self._create_direct_connection(req, traces, timeout)
  File "D:\anaconda\envs\PBFT\lib\site-packages\aiohttp\connector.py", line 1206, in _create_direct_connection
    raise last_exc
  File "D:\anaconda\envs\PBFT\lib\site-packages\aiohttp\connector.py", line 1187, in _create_direct_connection
    client_error=client_error,
  File "D:\anaconda\envs\PBFT\lib\site-packages\aiohttp\connector.py", line 988, in _wrap_create_connection
    raise client_error(req.connection_key, exc) from exc
aiohttp.client_exceptions.ClientConnectorError: Cannot connect to host localhost:30023 ssl:default [Connect call failed ('127.0.0.1', 30023)]
[2025-03-07 13:53:48,546] [INFO] [30105] Received PREPARE: id:1741323218379, from:30157, delay:0.0001s, distance:194.63m (Euclidean)
[2025-03-07 13:53:48,548] [INFO] [30105] Received COMMIT: id:1741323218379, from:30157, delay:0.0001s, distance:194.63m (Euclidean)
[2025-03-07 13:53:48,627] [INFO] [30105] Received PREPARE: id:1741323218379, from:30128, delay:0.0001s, distance:183.27m (Euclidean)
[2025-03-07 13:53:48,641] [INFO] [30105] Received COMMIT: id:1741323218379, from:30128, delay:0.0001s, distance:183.27m (Euclidean)
[2025-03-07 13:53:48,717] [INFO] [30105] Received PREPARE: id:1741323218379, from:30131, delay:0.0000s, distance:197.32m (Euclidean)
[2025-03-07 13:53:48,717] [INFO] [30105] Received COMMIT: id:1741323218379, from:30131, delay:0.0000s, distance:197.32m (Euclidean)
[2025-03-07 13:53:48,877] [INFO] [30105] Received PREPARE: id:1741323218379, from:30107, delay:0.0001s, distance:157.18m (Euclidean)
[2025-03-07 13:53:48,877] [INFO] [30105] Received COMMIT: id:1741323218379, from:30107, delay:0.0001s, distance:157.18m (Euclidean)
[2025-03-07 13:53:48,947] [INFO] [30105] Received PREPARE: id:1741323218379, from:30151, delay:0.0000s, distance:103.94m (Euclidean)
[2025-03-07 13:53:49,035] [ERROR] [30105] Error sending to http://localhost:30008/prepare: Cannot connect to host localhost:30008 ssl:default [Connect call failed ('127.0.0.1', 30008)]
Traceback (most recent call last):
  File "D:\anaconda\envs\PBFT\lib\site-packages\aiohttp\connector.py", line 980, in _wrap_create_connection
    return await self._loop.create_connection(*args, **kwargs)  # type: ignore[return-value]  # noqa
  File "D:\anaconda\envs\PBFT\lib\asyncio\base_events.py", line 948, in create_connection
    raise exceptions[0]
  File "D:\anaconda\envs\PBFT\lib\asyncio\base_events.py", line 935, in create_connection
    await self.sock_connect(sock, address)
  File "D:\anaconda\envs\PBFT\lib\asyncio\selector_events.py", line 475, in sock_connect
    return await fut
  File "D:\anaconda\envs\PBFT\lib\asyncio\selector_events.py", line 505, in _sock_connect_cb
    raise OSError(err, f'Connect call failed {address}')
ConnectionRefusedError: [Errno 10061] Connect call failed ('127.0.0.1', 30008)

The above exception was the direct cause of the following exception:

Traceback (most recent call last):
  File "pbft.py", line 236, in send_message
    await send_with_delay(self.session, self.node_info, target, url, data, self.bandwidth_data)
  File "pbft.py", line 63, in send_with_delay
    async with session.post(url, json=data) as resp:
  File "D:\anaconda\envs\PBFT\lib\site-packages\aiohttp\client.py", line 1141, in __aenter__
    self._resp = await self._coro
  File "D:\anaconda\envs\PBFT\lib\site-packages\aiohttp\client.py", line 537, in _request
    req, traces=traces, timeout=real_timeout
  File "D:\anaconda\envs\PBFT\lib\site-packages\aiohttp\connector.py", line 540, in connect
    proto = await self._create_connection(req, traces, timeout)
  File "D:\anaconda\envs\PBFT\lib\site-packages\aiohttp\connector.py", line 901, in _create_connection
    _, proto = await self._create_direct_connection(req, traces, timeout)
  File "D:\anaconda\envs\PBFT\lib\site-packages\aiohttp\connector.py", line 1206, in _create_direct_connection
    raise last_exc
  File "D:\anaconda\envs\PBFT\lib\site-packages\aiohttp\connector.py", line 1187, in _create_direct_connection
    client_error=client_error,
  File "D:\anaconda\envs\PBFT\lib\site-packages\aiohttp\connector.py", line 988, in _wrap_create_connection
    raise client_error(req.connection_key, exc) from exc
aiohttp.client_exceptions.ClientConnectorError: Cannot connect to host localhost:30008 ssl:default [Connect call failed ('127.0.0.1', 30008)]
[2025-03-07 13:53:49,146] [ERROR] [30105] Error sending to http://localhost:30027/prepare: Cannot connect to host localhost:30027 ssl:default [Connect call failed ('127.0.0.1', 30027)]
Traceback (most recent call last):
  File "D:\anaconda\envs\PBFT\lib\site-packages\aiohttp\connector.py", line 980, in _wrap_create_connection
    return await self._loop.create_connection(*args, **kwargs)  # type: ignore[return-value]  # noqa
  File "D:\anaconda\envs\PBFT\lib\asyncio\base_events.py", line 948, in create_connection
    raise exceptions[0]
  File "D:\anaconda\envs\PBFT\lib\asyncio\base_events.py", line 935, in create_connection
    await self.sock_connect(sock, address)
  File "D:\anaconda\envs\PBFT\lib\asyncio\selector_events.py", line 475, in sock_connect
    return await fut
  File "D:\anaconda\envs\PBFT\lib\asyncio\selector_events.py", line 505, in _sock_connect_cb
    raise OSError(err, f'Connect call failed {address}')
ConnectionRefusedError: [Errno 10061] Connect call failed ('127.0.0.1', 30027)

The above exception was the direct cause of the following exception:

Traceback (most recent call last):
  File "pbft.py", line 236, in send_message
    await send_with_delay(self.session, self.node_info, target, url, data, self.bandwidth_data)
  File "pbft.py", line 63, in send_with_delay
    async with session.post(url, json=data) as resp:
  File "D:\anaconda\envs\PBFT\lib\site-packages\aiohttp\client.py", line 1141, in __aenter__
    self._resp = await self._coro
  File "D:\anaconda\envs\PBFT\lib\site-packages\aiohttp\client.py", line 537, in _request
    req, traces=traces, timeout=real_timeout
  File "D:\anaconda\envs\PBFT\lib\site-packages\aiohttp\connector.py", line 540, in connect
    proto = await self._create_connection(req, traces, timeout)
  File "D:\anaconda\envs\PBFT\lib\site-packages\aiohttp\connector.py", line 901, in _create_connection
    _, proto = await self._create_direct_connection(req, traces, timeout)
  File "D:\anaconda\envs\PBFT\lib\site-packages\aiohttp\connector.py", line 1206, in _create_direct_connection
    raise last_exc
  File "D:\anaconda\envs\PBFT\lib\site-packages\aiohttp\connector.py", line 1187, in _create_direct_connection
    client_error=client_error,
  File "D:\anaconda\envs\PBFT\lib\site-packages\aiohttp\connector.py", line 988, in _wrap_create_connection
    raise client_error(req.connection_key, exc) from exc
aiohttp.client_exceptions.ClientConnectorError: Cannot connect to host localhost:30027 ssl:default [Connect call failed ('127.0.0.1', 30027)]
[2025-03-07 13:53:49,180] [INFO] [30105] Received COMMIT: id:1741323218379, from:30151, delay:0.0000s, distance:103.94m (Euclidean)
[2025-03-07 13:53:49,240] [INFO] [30105] Received PREPARE: id:1741323218379, from:30144, delay:0.0001s, distance:219.77m (Euclidean)
[2025-03-07 13:53:49,256] [INFO] [30105] Received COMMIT: id:1741323218379, from:30144, delay:0.0001s, distance:219.77m (Euclidean)
[2025-03-07 13:53:49,260] [INFO] [30105] Received PREPARE: id:1741323218379, from:30133, delay:0.0001s, distance:172.94m (Euclidean)
[2025-03-07 13:53:49,277] [INFO] [30105] Received COMMIT: id:1741323218379, from:30133, delay:0.0001s, distance:172.94m (Euclidean)
[2025-03-07 13:53:49,285] [INFO] [30105] Received PREPARE: id:1741323218379, from:30112, delay:0.0001s, distance:160.57m (Euclidean)
[2025-03-07 13:53:49,288] [INFO] [30105] Received COMMIT: id:1741323218379, from:30112, delay:0.0001s, distance:160.57m (Euclidean)
[2025-03-07 13:53:49,717] [INFO] [30105] Received PREPARE: id:1741323218379, from:30067, delay:0.0000s, distance:158.43m (Euclidean)
[2025-03-07 13:53:49,717] [INFO] [30105] Received COMMIT: id:1741323218379, from:30067, delay:0.0000s, distance:158.43m (Euclidean)
[2025-03-07 13:53:49,860] [ERROR] [30105] Error sending to http://localhost:30025/prepare: Cannot connect to host localhost:30025 ssl:default [Connect call failed ('127.0.0.1', 30025)]
Traceback (most recent call last):
  File "D:\anaconda\envs\PBFT\lib\site-packages\aiohttp\connector.py", line 980, in _wrap_create_connection
    return await self._loop.create_connection(*args, **kwargs)  # type: ignore[return-value]  # noqa
  File "D:\anaconda\envs\PBFT\lib\asyncio\base_events.py", line 948, in create_connection
    raise exceptions[0]
  File "D:\anaconda\envs\PBFT\lib\asyncio\base_events.py", line 935, in create_connection
    await self.sock_connect(sock, address)
  File "D:\anaconda\envs\PBFT\lib\asyncio\selector_events.py", line 475, in sock_connect
    return await fut
  File "D:\anaconda\envs\PBFT\lib\asyncio\selector_events.py", line 505, in _sock_connect_cb
    raise OSError(err, f'Connect call failed {address}')
ConnectionRefusedError: [Errno 10061] Connect call failed ('127.0.0.1', 30025)

The above exception was the direct cause of the following exception:

Traceback (most recent call last):
  File "pbft.py", line 236, in send_message
    await send_with_delay(self.session, self.node_info, target, url, data, self.bandwidth_data)
  File "pbft.py", line 63, in send_with_delay
    async with session.post(url, json=data) as resp:
  File "D:\anaconda\envs\PBFT\lib\site-packages\aiohttp\client.py", line 1141, in __aenter__
    self._resp = await self._coro
  File "D:\anaconda\envs\PBFT\lib\site-packages\aiohttp\client.py", line 537, in _request
    req, traces=traces, timeout=real_timeout
  File "D:\anaconda\envs\PBFT\lib\site-packages\aiohttp\connector.py", line 540, in connect
    proto = await self._create_connection(req, traces, timeout)
  File "D:\anaconda\envs\PBFT\lib\site-packages\aiohttp\connector.py", line 901, in _create_connection
    _, proto = await self._create_direct_connection(req, traces, timeout)
  File "D:\anaconda\envs\PBFT\lib\site-packages\aiohttp\connector.py", line 1206, in _create_direct_connection
    raise last_exc
  File "D:\anaconda\envs\PBFT\lib\site-packages\aiohttp\connector.py", line 1187, in _create_direct_connection
    client_error=client_error,
  File "D:\anaconda\envs\PBFT\lib\site-packages\aiohttp\connector.py", line 988, in _wrap_create_connection
    raise client_error(req.connection_key, exc) from exc
aiohttp.client_exceptions.ClientConnectorError: Cannot connect to host localhost:30025 ssl:default [Connect call failed ('127.0.0.1', 30025)]
[2025-03-07 13:53:49,861] [ERROR] [30105] Error sending to http://localhost:30025/commit: Cannot connect to host localhost:30025 ssl:default [Connect call failed ('::1', 30025, 0, 0)]
Traceback (most recent call last):
  File "D:\anaconda\envs\PBFT\lib\site-packages\aiohttp\connector.py", line 980, in _wrap_create_connection
    return await self._loop.create_connection(*args, **kwargs)  # type: ignore[return-value]  # noqa
  File "D:\anaconda\envs\PBFT\lib\asyncio\base_events.py", line 948, in create_connection
    raise exceptions[0]
  File "D:\anaconda\envs\PBFT\lib\asyncio\base_events.py", line 935, in create_connection
    await self.sock_connect(sock, address)
  File "D:\anaconda\envs\PBFT\lib\asyncio\selector_events.py", line 475, in sock_connect
    return await fut
  File "D:\anaconda\envs\PBFT\lib\asyncio\selector_events.py", line 505, in _sock_connect_cb
    raise OSError(err, f'Connect call failed {address}')
ConnectionRefusedError: [Errno 10061] Connect call failed ('::1', 30025, 0, 0)

The above exception was the direct cause of the following exception:

Traceback (most recent call last):
  File "pbft.py", line 236, in send_message
    await send_with_delay(self.session, self.node_info, target, url, data, self.bandwidth_data)
  File "pbft.py", line 63, in send_with_delay
    async with session.post(url, json=data) as resp:
  File "D:\anaconda\envs\PBFT\lib\site-packages\aiohttp\client.py", line 1141, in __aenter__
    self._resp = await self._coro
  File "D:\anaconda\envs\PBFT\lib\site-packages\aiohttp\client.py", line 537, in _request
    req, traces=traces, timeout=real_timeout
  File "D:\anaconda\envs\PBFT\lib\site-packages\aiohttp\connector.py", line 540, in connect
    proto = await self._create_connection(req, traces, timeout)
  File "D:\anaconda\envs\PBFT\lib\site-packages\aiohttp\connector.py", line 901, in _create_connection
    _, proto = await self._create_direct_connection(req, traces, timeout)
  File "D:\anaconda\envs\PBFT\lib\site-packages\aiohttp\connector.py", line 1206, in _create_direct_connection
    raise last_exc
  File "D:\anaconda\envs\PBFT\lib\site-packages\aiohttp\connector.py", line 1187, in _create_direct_connection
    client_error=client_error,
  File "D:\anaconda\envs\PBFT\lib\site-packages\aiohttp\connector.py", line 988, in _wrap_create_connection
    raise client_error(req.connection_key, exc) from exc
aiohttp.client_exceptions.ClientConnectorError: Cannot connect to host localhost:30025 ssl:default [Connect call failed ('::1', 30025, 0, 0)]
[2025-03-07 13:53:49,921] [INFO] [30105] Received PREPARE: id:1741323218379, from:30114, delay:0.0001s, distance:234.26m (Euclidean)
[2025-03-07 13:53:49,923] [INFO] [30105] Received COMMIT: id:1741323218379, from:30114, delay:0.0001s, distance:234.26m (Euclidean)
[2025-03-07 13:53:50,269] [INFO] [30105] Received PREPARE: id:1741323218379, from:30149, delay:0.0000s, distance:74.36m (Euclidean)
[2025-03-07 13:53:50,301] [ERROR] [30105] Error sending to http://localhost:30101/prepare: Cannot connect to host localhost:30101 ssl:default [Connect call failed ('127.0.0.1', 30101)]
Traceback (most recent call last):
  File "D:\anaconda\envs\PBFT\lib\site-packages\aiohttp\connector.py", line 980, in _wrap_create_connection
    return await self._loop.create_connection(*args, **kwargs)  # type: ignore[return-value]  # noqa
  File "D:\anaconda\envs\PBFT\lib\asyncio\base_events.py", line 948, in create_connection
    raise exceptions[0]
  File "D:\anaconda\envs\PBFT\lib\asyncio\base_events.py", line 935, in create_connection
    await self.sock_connect(sock, address)
  File "D:\anaconda\envs\PBFT\lib\asyncio\selector_events.py", line 475, in sock_connect
    return await fut
  File "D:\anaconda\envs\PBFT\lib\asyncio\selector_events.py", line 505, in _sock_connect_cb
    raise OSError(err, f'Connect call failed {address}')
ConnectionRefusedError: [Errno 10061] Connect call failed ('127.0.0.1', 30101)

The above exception was the direct cause of the following exception:

Traceback (most recent call last):
  File "pbft.py", line 236, in send_message
    await send_with_delay(self.session, self.node_info, target, url, data, self.bandwidth_data)
  File "pbft.py", line 63, in send_with_delay
    async with session.post(url, json=data) as resp:
  File "D:\anaconda\envs\PBFT\lib\site-packages\aiohttp\client.py", line 1141, in __aenter__
    self._resp = await self._coro
  File "D:\anaconda\envs\PBFT\lib\site-packages\aiohttp\client.py", line 537, in _request
    req, traces=traces, timeout=real_timeout
  File "D:\anaconda\envs\PBFT\lib\site-packages\aiohttp\connector.py", line 540, in connect
    proto = await self._create_connection(req, traces, timeout)
  File "D:\anaconda\envs\PBFT\lib\site-packages\aiohttp\connector.py", line 901, in _create_connection
    _, proto = await self._create_direct_connection(req, traces, timeout)
  File "D:\anaconda\envs\PBFT\lib\site-packages\aiohttp\connector.py", line 1206, in _create_direct_connection
    raise last_exc
  File "D:\anaconda\envs\PBFT\lib\site-packages\aiohttp\connector.py", line 1187, in _create_direct_connection
    client_error=client_error,
  File "D:\anaconda\envs\PBFT\lib\site-packages\aiohttp\connector.py", line 988, in _wrap_create_connection
    raise client_error(req.connection_key, exc) from exc
aiohttp.client_exceptions.ClientConnectorError: Cannot connect to host localhost:30101 ssl:default [Connect call failed ('127.0.0.1', 30101)]
[2025-03-07 13:53:50,444] [INFO] [30105] Received PREPARE: id:1741323218379, from:30121, delay:0.0000s, distance:69.20m (Euclidean)
[2025-03-07 13:53:50,444] [INFO] [30105] Received COMMIT: id:1741323218379, from:30121, delay:0.0000s, distance:69.20m (Euclidean)
[2025-03-07 13:53:50,507] [INFO] [30105] Received COMMIT: id:1741323218379, from:30000, delay:0.0000s, distance:194.11m (Euclidean)
[2025-03-07 13:53:50,554] [INFO] [30105] Received PREPARE: id:1741323218379, from:30015, delay:0.0001s, distance:162.14m (Euclidean)
[2025-03-07 13:53:50,554] [INFO] [30105] Received COMMIT: id:1741323218379, from:30015, delay:0.0001s, distance:162.14m (Euclidean)
[2025-03-07 13:53:50,588] [INFO] [30105] Received PREPARE: id:1741323218379, from:30130, delay:0.0001s, distance:175.29m (Euclidean)
[2025-03-07 13:53:50,588] [INFO] [30105] Received COMMIT: id:1741323218379, from:30130, delay:0.0001s, distance:175.29m (Euclidean)
[2025-03-07 13:53:50,775] [ERROR] [30105] Error sending to http://localhost:30027/commit: Cannot connect to host localhost:30027 ssl:default [Connect call failed ('::1', 30027, 0, 0)]
Traceback (most recent call last):
  File "D:\anaconda\envs\PBFT\lib\site-packages\aiohttp\connector.py", line 980, in _wrap_create_connection
    return await self._loop.create_connection(*args, **kwargs)  # type: ignore[return-value]  # noqa
  File "D:\anaconda\envs\PBFT\lib\asyncio\base_events.py", line 948, in create_connection
    raise exceptions[0]
  File "D:\anaconda\envs\PBFT\lib\asyncio\base_events.py", line 935, in create_connection
    await self.sock_connect(sock, address)
  File "D:\anaconda\envs\PBFT\lib\asyncio\selector_events.py", line 475, in sock_connect
    return await fut
  File "D:\anaconda\envs\PBFT\lib\asyncio\selector_events.py", line 505, in _sock_connect_cb
    raise OSError(err, f'Connect call failed {address}')
ConnectionRefusedError: [Errno 10061] Connect call failed ('::1', 30027, 0, 0)

The above exception was the direct cause of the following exception:

Traceback (most recent call last):
  File "pbft.py", line 236, in send_message
    await send_with_delay(self.session, self.node_info, target, url, data, self.bandwidth_data)
  File "pbft.py", line 63, in send_with_delay
    async with session.post(url, json=data) as resp:
  File "D:\anaconda\envs\PBFT\lib\site-packages\aiohttp\client.py", line 1141, in __aenter__
    self._resp = await self._coro
  File "D:\anaconda\envs\PBFT\lib\site-packages\aiohttp\client.py", line 537, in _request
    req, traces=traces, timeout=real_timeout
  File "D:\anaconda\envs\PBFT\lib\site-packages\aiohttp\connector.py", line 540, in connect
    proto = await self._create_connection(req, traces, timeout)
  File "D:\anaconda\envs\PBFT\lib\site-packages\aiohttp\connector.py", line 901, in _create_connection
    _, proto = await self._create_direct_connection(req, traces, timeout)
  File "D:\anaconda\envs\PBFT\lib\site-packages\aiohttp\connector.py", line 1206, in _create_direct_connection
    raise last_exc
  File "D:\anaconda\envs\PBFT\lib\site-packages\aiohttp\connector.py", line 1187, in _create_direct_connection
    client_error=client_error,
  File "D:\anaconda\envs\PBFT\lib\site-packages\aiohttp\connector.py", line 988, in _wrap_create_connection
    raise client_error(req.connection_key, exc) from exc
aiohttp.client_exceptions.ClientConnectorError: Cannot connect to host localhost:30027 ssl:default [Connect call failed ('::1', 30027, 0, 0)]
[2025-03-07 13:53:50,775] [INFO] [30105] Received PREPARE: id:1741323218379, from:30126, delay:0.0002s, distance:292.73m (Euclidean)
[2025-03-07 13:53:50,775] [INFO] [30105] Received COMMIT: id:1741323218379, from:30126, delay:0.0002s, distance:292.73m (Euclidean)
[2025-03-07 13:53:50,838] [ERROR] [30105] Error sending to http://localhost:30071/commit: Cannot connect to host localhost:30071 ssl:default [Connect call failed ('::1', 30071, 0, 0)]
Traceback (most recent call last):
  File "D:\anaconda\envs\PBFT\lib\site-packages\aiohttp\connector.py", line 980, in _wrap_create_connection
    return await self._loop.create_connection(*args, **kwargs)  # type: ignore[return-value]  # noqa
  File "D:\anaconda\envs\PBFT\lib\asyncio\base_events.py", line 948, in create_connection
    raise exceptions[0]
  File "D:\anaconda\envs\PBFT\lib\asyncio\base_events.py", line 935, in create_connection
    await self.sock_connect(sock, address)
  File "D:\anaconda\envs\PBFT\lib\asyncio\selector_events.py", line 475, in sock_connect
    return await fut
  File "D:\anaconda\envs\PBFT\lib\asyncio\selector_events.py", line 505, in _sock_connect_cb
    raise OSError(err, f'Connect call failed {address}')
ConnectionRefusedError: [Errno 10061] Connect call failed ('::1', 30071, 0, 0)

The above exception was the direct cause of the following exception:

Traceback (most recent call last):
  File "pbft.py", line 236, in send_message
    await send_with_delay(self.session, self.node_info, target, url, data, self.bandwidth_data)
  File "pbft.py", line 63, in send_with_delay
    async with session.post(url, json=data) as resp:
  File "D:\anaconda\envs\PBFT\lib\site-packages\aiohttp\client.py", line 1141, in __aenter__
    self._resp = await self._coro
  File "D:\anaconda\envs\PBFT\lib\site-packages\aiohttp\client.py", line 537, in _request
    req, traces=traces, timeout=real_timeout
  File "D:\anaconda\envs\PBFT\lib\site-packages\aiohttp\connector.py", line 540, in connect
    proto = await self._create_connection(req, traces, timeout)
  File "D:\anaconda\envs\PBFT\lib\site-packages\aiohttp\connector.py", line 901, in _create_connection
    _, proto = await self._create_direct_connection(req, traces, timeout)
  File "D:\anaconda\envs\PBFT\lib\site-packages\aiohttp\connector.py", line 1206, in _create_direct_connection
    raise last_exc
  File "D:\anaconda\envs\PBFT\lib\site-packages\aiohttp\connector.py", line 1187, in _create_direct_connection
    client_error=client_error,
  File "D:\anaconda\envs\PBFT\lib\site-packages\aiohttp\connector.py", line 988, in _wrap_create_connection
    raise client_error(req.connection_key, exc) from exc
aiohttp.client_exceptions.ClientConnectorError: Cannot connect to host localhost:30071 ssl:default [Connect call failed ('::1', 30071, 0, 0)]
[2025-03-07 13:53:50,854] [ERROR] [30105] Error sending to http://localhost:30071/prepare: Cannot connect to host localhost:30071 ssl:default [Connect call failed ('127.0.0.1', 30071)]
Traceback (most recent call last):
  File "D:\anaconda\envs\PBFT\lib\site-packages\aiohttp\connector.py", line 980, in _wrap_create_connection
    return await self._loop.create_connection(*args, **kwargs)  # type: ignore[return-value]  # noqa
  File "D:\anaconda\envs\PBFT\lib\asyncio\base_events.py", line 948, in create_connection
    raise exceptions[0]
  File "D:\anaconda\envs\PBFT\lib\asyncio\base_events.py", line 935, in create_connection
    await self.sock_connect(sock, address)
  File "D:\anaconda\envs\PBFT\lib\asyncio\selector_events.py", line 475, in sock_connect
    return await fut
  File "D:\anaconda\envs\PBFT\lib\asyncio\selector_events.py", line 505, in _sock_connect_cb
    raise OSError(err, f'Connect call failed {address}')
ConnectionRefusedError: [Errno 10061] Connect call failed ('127.0.0.1', 30071)

The above exception was the direct cause of the following exception:

Traceback (most recent call last):
  File "pbft.py", line 236, in send_message
    await send_with_delay(self.session, self.node_info, target, url, data, self.bandwidth_data)
  File "pbft.py", line 63, in send_with_delay
    async with session.post(url, json=data) as resp:
  File "D:\anaconda\envs\PBFT\lib\site-packages\aiohttp\client.py", line 1141, in __aenter__
    self._resp = await self._coro
  File "D:\anaconda\envs\PBFT\lib\site-packages\aiohttp\client.py", line 537, in _request
    req, traces=traces, timeout=real_timeout
  File "D:\anaconda\envs\PBFT\lib\site-packages\aiohttp\connector.py", line 540, in connect
    proto = await self._create_connection(req, traces, timeout)
  File "D:\anaconda\envs\PBFT\lib\site-packages\aiohttp\connector.py", line 901, in _create_connection
    _, proto = await self._create_direct_connection(req, traces, timeout)
  File "D:\anaconda\envs\PBFT\lib\site-packages\aiohttp\connector.py", line 1206, in _create_direct_connection
    raise last_exc
  File "D:\anaconda\envs\PBFT\lib\site-packages\aiohttp\connector.py", line 1187, in _create_direct_connection
    client_error=client_error,
  File "D:\anaconda\envs\PBFT\lib\site-packages\aiohttp\connector.py", line 988, in _wrap_create_connection
    raise client_error(req.connection_key, exc) from exc
aiohttp.client_exceptions.ClientConnectorError: Cannot connect to host localhost:30071 ssl:default [Connect call failed ('127.0.0.1', 30071)]
[2025-03-07 13:53:50,870] [ERROR] [30105] Error sending to http://localhost:30076/prepare: Cannot connect to host localhost:30076 ssl:default [Connect call failed ('127.0.0.1', 30076)]
Traceback (most recent call last):
  File "D:\anaconda\envs\PBFT\lib\site-packages\aiohttp\connector.py", line 980, in _wrap_create_connection
    return await self._loop.create_connection(*args, **kwargs)  # type: ignore[return-value]  # noqa
  File "D:\anaconda\envs\PBFT\lib\asyncio\base_events.py", line 948, in create_connection
    raise exceptions[0]
  File "D:\anaconda\envs\PBFT\lib\asyncio\base_events.py", line 935, in create_connection
    await self.sock_connect(sock, address)
  File "D:\anaconda\envs\PBFT\lib\asyncio\selector_events.py", line 475, in sock_connect
    return await fut
  File "D:\anaconda\envs\PBFT\lib\asyncio\selector_events.py", line 505, in _sock_connect_cb
    raise OSError(err, f'Connect call failed {address}')
ConnectionRefusedError: [Errno 10061] Connect call failed ('127.0.0.1', 30076)

The above exception was the direct cause of the following exception:

Traceback (most recent call last):
  File "pbft.py", line 236, in send_message
    await send_with_delay(self.session, self.node_info, target, url, data, self.bandwidth_data)
  File "pbft.py", line 63, in send_with_delay
    async with session.post(url, json=data) as resp:
  File "D:\anaconda\envs\PBFT\lib\site-packages\aiohttp\client.py", line 1141, in __aenter__
    self._resp = await self._coro
  File "D:\anaconda\envs\PBFT\lib\site-packages\aiohttp\client.py", line 537, in _request
    req, traces=traces, timeout=real_timeout
  File "D:\anaconda\envs\PBFT\lib\site-packages\aiohttp\connector.py", line 540, in connect
    proto = await self._create_connection(req, traces, timeout)
  File "D:\anaconda\envs\PBFT\lib\site-packages\aiohttp\connector.py", line 901, in _create_connection
    _, proto = await self._create_direct_connection(req, traces, timeout)
  File "D:\anaconda\envs\PBFT\lib\site-packages\aiohttp\connector.py", line 1206, in _create_direct_connection
    raise last_exc
  File "D:\anaconda\envs\PBFT\lib\site-packages\aiohttp\connector.py", line 1187, in _create_direct_connection
    client_error=client_error,
  File "D:\anaconda\envs\PBFT\lib\site-packages\aiohttp\connector.py", line 988, in _wrap_create_connection
    raise client_error(req.connection_key, exc) from exc
aiohttp.client_exceptions.ClientConnectorError: Cannot connect to host localhost:30076 ssl:default [Connect call failed ('127.0.0.1', 30076)]
[2025-03-07 13:53:50,903] [ERROR] [30105] Error sending to http://localhost:30066/prepare: Cannot connect to host localhost:30066 ssl:default [Connect call failed ('127.0.0.1', 30066)]
Traceback (most recent call last):
  File "D:\anaconda\envs\PBFT\lib\site-packages\aiohttp\connector.py", line 980, in _wrap_create_connection
    return await self._loop.create_connection(*args, **kwargs)  # type: ignore[return-value]  # noqa
  File "D:\anaconda\envs\PBFT\lib\asyncio\base_events.py", line 948, in create_connection
    raise exceptions[0]
  File "D:\anaconda\envs\PBFT\lib\asyncio\base_events.py", line 935, in create_connection
    await self.sock_connect(sock, address)
  File "D:\anaconda\envs\PBFT\lib\asyncio\selector_events.py", line 475, in sock_connect
    return await fut
  File "D:\anaconda\envs\PBFT\lib\asyncio\selector_events.py", line 505, in _sock_connect_cb
    raise OSError(err, f'Connect call failed {address}')
ConnectionRefusedError: [Errno 10061] Connect call failed ('127.0.0.1', 30066)

The above exception was the direct cause of the following exception:

Traceback (most recent call last):
  File "pbft.py", line 236, in send_message
    await send_with_delay(self.session, self.node_info, target, url, data, self.bandwidth_data)
  File "pbft.py", line 63, in send_with_delay
    async with session.post(url, json=data) as resp:
  File "D:\anaconda\envs\PBFT\lib\site-packages\aiohttp\client.py", line 1141, in __aenter__
    self._resp = await self._coro
  File "D:\anaconda\envs\PBFT\lib\site-packages\aiohttp\client.py", line 537, in _request
    req, traces=traces, timeout=real_timeout
  File "D:\anaconda\envs\PBFT\lib\site-packages\aiohttp\connector.py", line 540, in connect
    proto = await self._create_connection(req, traces, timeout)
  File "D:\anaconda\envs\PBFT\lib\site-packages\aiohttp\connector.py", line 901, in _create_connection
    _, proto = await self._create_direct_connection(req, traces, timeout)
  File "D:\anaconda\envs\PBFT\lib\site-packages\aiohttp\connector.py", line 1206, in _create_direct_connection
    raise last_exc
  File "D:\anaconda\envs\PBFT\lib\site-packages\aiohttp\connector.py", line 1187, in _create_direct_connection
    client_error=client_error,
  File "D:\anaconda\envs\PBFT\lib\site-packages\aiohttp\connector.py", line 988, in _wrap_create_connection
    raise client_error(req.connection_key, exc) from exc
aiohttp.client_exceptions.ClientConnectorError: Cannot connect to host localhost:30066 ssl:default [Connect call failed ('127.0.0.1', 30066)]
[2025-03-07 13:53:50,905] [INFO] [30105] Received COMMIT: id:1741323218379, from:30149, delay:0.0000s, distance:74.36m (Euclidean)
[2025-03-07 13:53:50,918] [ERROR] [30105] Error sending to http://localhost:30066/commit: Cannot connect to host localhost:30066 ssl:default [Connect call failed ('::1', 30066, 0, 0)]
Traceback (most recent call last):
  File "D:\anaconda\envs\PBFT\lib\site-packages\aiohttp\connector.py", line 980, in _wrap_create_connection
    return await self._loop.create_connection(*args, **kwargs)  # type: ignore[return-value]  # noqa
  File "D:\anaconda\envs\PBFT\lib\asyncio\base_events.py", line 948, in create_connection
    raise exceptions[0]
  File "D:\anaconda\envs\PBFT\lib\asyncio\base_events.py", line 935, in create_connection
    await self.sock_connect(sock, address)
  File "D:\anaconda\envs\PBFT\lib\asyncio\selector_events.py", line 475, in sock_connect
    return await fut
  File "D:\anaconda\envs\PBFT\lib\asyncio\selector_events.py", line 505, in _sock_connect_cb
    raise OSError(err, f'Connect call failed {address}')
ConnectionRefusedError: [Errno 10061] Connect call failed ('::1', 30066, 0, 0)

The above exception was the direct cause of the following exception:

Traceback (most recent call last):
  File "pbft.py", line 236, in send_message
    await send_with_delay(self.session, self.node_info, target, url, data, self.bandwidth_data)
  File "pbft.py", line 63, in send_with_delay
    async with session.post(url, json=data) as resp:
  File "D:\anaconda\envs\PBFT\lib\site-packages\aiohttp\client.py", line 1141, in __aenter__
    self._resp = await self._coro
  File "D:\anaconda\envs\PBFT\lib\site-packages\aiohttp\client.py", line 537, in _request
    req, traces=traces, timeout=real_timeout
  File "D:\anaconda\envs\PBFT\lib\site-packages\aiohttp\connector.py", line 540, in connect
    proto = await self._create_connection(req, traces, timeout)
  File "D:\anaconda\envs\PBFT\lib\site-packages\aiohttp\connector.py", line 901, in _create_connection
    _, proto = await self._create_direct_connection(req, traces, timeout)
  File "D:\anaconda\envs\PBFT\lib\site-packages\aiohttp\connector.py", line 1206, in _create_direct_connection
    raise last_exc
  File "D:\anaconda\envs\PBFT\lib\site-packages\aiohttp\connector.py", line 1187, in _create_direct_connection
    client_error=client_error,
  File "D:\anaconda\envs\PBFT\lib\site-packages\aiohttp\connector.py", line 988, in _wrap_create_connection
    raise client_error(req.connection_key, exc) from exc
aiohttp.client_exceptions.ClientConnectorError: Cannot connect to host localhost:30066 ssl:default [Connect call failed ('::1', 30066, 0, 0)]
[2025-03-07 13:53:50,934] [INFO] [30105] Received PREPARE: id:1741323218379, from:30113, delay:0.0000s, distance:126.65m (Euclidean)
[2025-03-07 13:53:51,107] [ERROR] [30105] Error sending to http://localhost:30023/commit: Cannot connect to host localhost:30023 ssl:default [Connect call failed ('::1', 30023, 0, 0)]
Traceback (most recent call last):
  File "D:\anaconda\envs\PBFT\lib\site-packages\aiohttp\connector.py", line 980, in _wrap_create_connection
    return await self._loop.create_connection(*args, **kwargs)  # type: ignore[return-value]  # noqa
  File "D:\anaconda\envs\PBFT\lib\asyncio\base_events.py", line 948, in create_connection
    raise exceptions[0]
  File "D:\anaconda\envs\PBFT\lib\asyncio\base_events.py", line 935, in create_connection
    await self.sock_connect(sock, address)
  File "D:\anaconda\envs\PBFT\lib\asyncio\selector_events.py", line 475, in sock_connect
    return await fut
  File "D:\anaconda\envs\PBFT\lib\asyncio\selector_events.py", line 505, in _sock_connect_cb
    raise OSError(err, f'Connect call failed {address}')
ConnectionRefusedError: [Errno 10061] Connect call failed ('::1', 30023, 0, 0)

The above exception was the direct cause of the following exception:

Traceback (most recent call last):
  File "pbft.py", line 236, in send_message
    await send_with_delay(self.session, self.node_info, target, url, data, self.bandwidth_data)
  File "pbft.py", line 63, in send_with_delay
    async with session.post(url, json=data) as resp:
  File "D:\anaconda\envs\PBFT\lib\site-packages\aiohttp\client.py", line 1141, in __aenter__
    self._resp = await self._coro
  File "D:\anaconda\envs\PBFT\lib\site-packages\aiohttp\client.py", line 537, in _request
    req, traces=traces, timeout=real_timeout
  File "D:\anaconda\envs\PBFT\lib\site-packages\aiohttp\connector.py", line 540, in connect
    proto = await self._create_connection(req, traces, timeout)
  File "D:\anaconda\envs\PBFT\lib\site-packages\aiohttp\connector.py", line 901, in _create_connection
    _, proto = await self._create_direct_connection(req, traces, timeout)
  File "D:\anaconda\envs\PBFT\lib\site-packages\aiohttp\connector.py", line 1206, in _create_direct_connection
    raise last_exc
  File "D:\anaconda\envs\PBFT\lib\site-packages\aiohttp\connector.py", line 1187, in _create_direct_connection
    client_error=client_error,
  File "D:\anaconda\envs\PBFT\lib\site-packages\aiohttp\connector.py", line 988, in _wrap_create_connection
    raise client_error(req.connection_key, exc) from exc
aiohttp.client_exceptions.ClientConnectorError: Cannot connect to host localhost:30023 ssl:default [Connect call failed ('::1', 30023, 0, 0)]
[2025-03-07 13:53:51,155] [ERROR] [30105] Error sending to http://localhost:30075/prepare: Cannot connect to host localhost:30075 ssl:default [Connect call failed ('127.0.0.1', 30075)]
Traceback (most recent call last):
  File "D:\anaconda\envs\PBFT\lib\site-packages\aiohttp\connector.py", line 980, in _wrap_create_connection
    return await self._loop.create_connection(*args, **kwargs)  # type: ignore[return-value]  # noqa
  File "D:\anaconda\envs\PBFT\lib\asyncio\base_events.py", line 948, in create_connection
    raise exceptions[0]
  File "D:\anaconda\envs\PBFT\lib\asyncio\base_events.py", line 935, in create_connection
    await self.sock_connect(sock, address)
  File "D:\anaconda\envs\PBFT\lib\asyncio\selector_events.py", line 475, in sock_connect
    return await fut
  File "D:\anaconda\envs\PBFT\lib\asyncio\selector_events.py", line 505, in _sock_connect_cb
    raise OSError(err, f'Connect call failed {address}')
ConnectionRefusedError: [Errno 10061] Connect call failed ('127.0.0.1', 30075)

The above exception was the direct cause of the following exception:

Traceback (most recent call last):
  File "pbft.py", line 236, in send_message
    await send_with_delay(self.session, self.node_info, target, url, data, self.bandwidth_data)
  File "pbft.py", line 63, in send_with_delay
    async with session.post(url, json=data) as resp:
  File "D:\anaconda\envs\PBFT\lib\site-packages\aiohttp\client.py", line 1141, in __aenter__
    self._resp = await self._coro
  File "D:\anaconda\envs\PBFT\lib\site-packages\aiohttp\client.py", line 537, in _request
    req, traces=traces, timeout=real_timeout
  File "D:\anaconda\envs\PBFT\lib\site-packages\aiohttp\connector.py", line 540, in connect
    proto = await self._create_connection(req, traces, timeout)
  File "D:\anaconda\envs\PBFT\lib\site-packages\aiohttp\connector.py", line 901, in _create_connection
    _, proto = await self._create_direct_connection(req, traces, timeout)
  File "D:\anaconda\envs\PBFT\lib\site-packages\aiohttp\connector.py", line 1206, in _create_direct_connection
    raise last_exc
  File "D:\anaconda\envs\PBFT\lib\site-packages\aiohttp\connector.py", line 1187, in _create_direct_connection
    client_error=client_error,
  File "D:\anaconda\envs\PBFT\lib\site-packages\aiohttp\connector.py", line 988, in _wrap_create_connection
    raise client_error(req.connection_key, exc) from exc
aiohttp.client_exceptions.ClientConnectorError: Cannot connect to host localhost:30075 ssl:default [Connect call failed ('127.0.0.1', 30075)]
[2025-03-07 13:53:51,187] [ERROR] [30105] Error sending to http://localhost:30075/commit: Cannot connect to host localhost:30075 ssl:default [Connect call failed ('::1', 30075, 0, 0)]
Traceback (most recent call last):
  File "D:\anaconda\envs\PBFT\lib\site-packages\aiohttp\connector.py", line 980, in _wrap_create_connection
    return await self._loop.create_connection(*args, **kwargs)  # type: ignore[return-value]  # noqa
  File "D:\anaconda\envs\PBFT\lib\asyncio\base_events.py", line 948, in create_connection
    raise exceptions[0]
  File "D:\anaconda\envs\PBFT\lib\asyncio\base_events.py", line 935, in create_connection
    await self.sock_connect(sock, address)
  File "D:\anaconda\envs\PBFT\lib\asyncio\selector_events.py", line 475, in sock_connect
    return await fut
  File "D:\anaconda\envs\PBFT\lib\asyncio\selector_events.py", line 505, in _sock_connect_cb
    raise OSError(err, f'Connect call failed {address}')
ConnectionRefusedError: [Errno 10061] Connect call failed ('::1', 30075, 0, 0)

The above exception was the direct cause of the following exception:

Traceback (most recent call last):
  File "pbft.py", line 236, in send_message
    await send_with_delay(self.session, self.node_info, target, url, data, self.bandwidth_data)
  File "pbft.py", line 63, in send_with_delay
    async with session.post(url, json=data) as resp:
  File "D:\anaconda\envs\PBFT\lib\site-packages\aiohttp\client.py", line 1141, in __aenter__
    self._resp = await self._coro
  File "D:\anaconda\envs\PBFT\lib\site-packages\aiohttp\client.py", line 537, in _request
    req, traces=traces, timeout=real_timeout
  File "D:\anaconda\envs\PBFT\lib\site-packages\aiohttp\connector.py", line 540, in connect
    proto = await self._create_connection(req, traces, timeout)
  File "D:\anaconda\envs\PBFT\lib\site-packages\aiohttp\connector.py", line 901, in _create_connection
    _, proto = await self._create_direct_connection(req, traces, timeout)
  File "D:\anaconda\envs\PBFT\lib\site-packages\aiohttp\connector.py", line 1206, in _create_direct_connection
    raise last_exc
  File "D:\anaconda\envs\PBFT\lib\site-packages\aiohttp\connector.py", line 1187, in _create_direct_connection
    client_error=client_error,
  File "D:\anaconda\envs\PBFT\lib\site-packages\aiohttp\connector.py", line 988, in _wrap_create_connection
    raise client_error(req.connection_key, exc) from exc
aiohttp.client_exceptions.ClientConnectorError: Cannot connect to host localhost:30075 ssl:default [Connect call failed ('::1', 30075, 0, 0)]
[2025-03-07 13:53:51,250] [ERROR] [30105] Error sending to http://localhost:30008/commit: Cannot connect to host localhost:30008 ssl:default [Connect call failed ('::1', 30008, 0, 0)]
Traceback (most recent call last):
  File "D:\anaconda\envs\PBFT\lib\site-packages\aiohttp\connector.py", line 980, in _wrap_create_connection
    return await self._loop.create_connection(*args, **kwargs)  # type: ignore[return-value]  # noqa
  File "D:\anaconda\envs\PBFT\lib\asyncio\base_events.py", line 948, in create_connection
    raise exceptions[0]
  File "D:\anaconda\envs\PBFT\lib\asyncio\base_events.py", line 935, in create_connection
    await self.sock_connect(sock, address)
  File "D:\anaconda\envs\PBFT\lib\asyncio\selector_events.py", line 475, in sock_connect
    return await fut
  File "D:\anaconda\envs\PBFT\lib\asyncio\selector_events.py", line 505, in _sock_connect_cb
    raise OSError(err, f'Connect call failed {address}')
ConnectionRefusedError: [Errno 10061] Connect call failed ('::1', 30008, 0, 0)

The above exception was the direct cause of the following exception:

Traceback (most recent call last):
  File "pbft.py", line 236, in send_message
    await send_with_delay(self.session, self.node_info, target, url, data, self.bandwidth_data)
  File "pbft.py", line 63, in send_with_delay
    async with session.post(url, json=data) as resp:
  File "D:\anaconda\envs\PBFT\lib\site-packages\aiohttp\client.py", line 1141, in __aenter__
    self._resp = await self._coro
  File "D:\anaconda\envs\PBFT\lib\site-packages\aiohttp\client.py", line 537, in _request
    req, traces=traces, timeout=real_timeout
  File "D:\anaconda\envs\PBFT\lib\site-packages\aiohttp\connector.py", line 540, in connect
    proto = await self._create_connection(req, traces, timeout)
  File "D:\anaconda\envs\PBFT\lib\site-packages\aiohttp\connector.py", line 901, in _create_connection
    _, proto = await self._create_direct_connection(req, traces, timeout)
  File "D:\anaconda\envs\PBFT\lib\site-packages\aiohttp\connector.py", line 1206, in _create_direct_connection
    raise last_exc
  File "D:\anaconda\envs\PBFT\lib\site-packages\aiohttp\connector.py", line 1187, in _create_direct_connection
    client_error=client_error,
  File "D:\anaconda\envs\PBFT\lib\site-packages\aiohttp\connector.py", line 988, in _wrap_create_connection
    raise client_error(req.connection_key, exc) from exc
aiohttp.client_exceptions.ClientConnectorError: Cannot connect to host localhost:30008 ssl:default [Connect call failed ('::1', 30008, 0, 0)]
[2025-03-07 13:53:51,250] [ERROR] [30105] Error sending to http://localhost:30076/commit: Cannot connect to host localhost:30076 ssl:default [Connect call failed ('::1', 30076, 0, 0)]
Traceback (most recent call last):
  File "D:\anaconda\envs\PBFT\lib\site-packages\aiohttp\connector.py", line 980, in _wrap_create_connection
    return await self._loop.create_connection(*args, **kwargs)  # type: ignore[return-value]  # noqa
  File "D:\anaconda\envs\PBFT\lib\asyncio\base_events.py", line 948, in create_connection
    raise exceptions[0]
  File "D:\anaconda\envs\PBFT\lib\asyncio\base_events.py", line 935, in create_connection
    await self.sock_connect(sock, address)
  File "D:\anaconda\envs\PBFT\lib\asyncio\selector_events.py", line 475, in sock_connect
    return await fut
  File "D:\anaconda\envs\PBFT\lib\asyncio\selector_events.py", line 505, in _sock_connect_cb
    raise OSError(err, f'Connect call failed {address}')
ConnectionRefusedError: [Errno 10061] Connect call failed ('::1', 30076, 0, 0)

The above exception was the direct cause of the following exception:

Traceback (most recent call last):
  File "pbft.py", line 236, in send_message
    await send_with_delay(self.session, self.node_info, target, url, data, self.bandwidth_data)
  File "pbft.py", line 63, in send_with_delay
    async with session.post(url, json=data) as resp:
  File "D:\anaconda\envs\PBFT\lib\site-packages\aiohttp\client.py", line 1141, in __aenter__
    self._resp = await self._coro
  File "D:\anaconda\envs\PBFT\lib\site-packages\aiohttp\client.py", line 537, in _request
    req, traces=traces, timeout=real_timeout
  File "D:\anaconda\envs\PBFT\lib\site-packages\aiohttp\connector.py", line 540, in connect
    proto = await self._create_connection(req, traces, timeout)
  File "D:\anaconda\envs\PBFT\lib\site-packages\aiohttp\connector.py", line 901, in _create_connection
    _, proto = await self._create_direct_connection(req, traces, timeout)
  File "D:\anaconda\envs\PBFT\lib\site-packages\aiohttp\connector.py", line 1206, in _create_direct_connection
    raise last_exc
  File "D:\anaconda\envs\PBFT\lib\site-packages\aiohttp\connector.py", line 1187, in _create_direct_connection
    client_error=client_error,
  File "D:\anaconda\envs\PBFT\lib\site-packages\aiohttp\connector.py", line 988, in _wrap_create_connection
    raise client_error(req.connection_key, exc) from exc
aiohttp.client_exceptions.ClientConnectorError: Cannot connect to host localhost:30076 ssl:default [Connect call failed ('::1', 30076, 0, 0)]
[2025-03-07 13:53:51,298] [ERROR] [30105] Error sending to http://localhost:30038/commit: Cannot connect to host localhost:30038 ssl:default [Connect call failed ('::1', 30038, 0, 0)]
Traceback (most recent call last):
  File "D:\anaconda\envs\PBFT\lib\site-packages\aiohttp\connector.py", line 980, in _wrap_create_connection
    return await self._loop.create_connection(*args, **kwargs)  # type: ignore[return-value]  # noqa
  File "D:\anaconda\envs\PBFT\lib\asyncio\base_events.py", line 948, in create_connection
    raise exceptions[0]
  File "D:\anaconda\envs\PBFT\lib\asyncio\base_events.py", line 935, in create_connection
    await self.sock_connect(sock, address)
  File "D:\anaconda\envs\PBFT\lib\asyncio\selector_events.py", line 475, in sock_connect
    return await fut
  File "D:\anaconda\envs\PBFT\lib\asyncio\selector_events.py", line 505, in _sock_connect_cb
    raise OSError(err, f'Connect call failed {address}')
ConnectionRefusedError: [Errno 10061] Connect call failed ('::1', 30038, 0, 0)

The above exception was the direct cause of the following exception:

Traceback (most recent call last):
  File "pbft.py", line 236, in send_message
    await send_with_delay(self.session, self.node_info, target, url, data, self.bandwidth_data)
  File "pbft.py", line 63, in send_with_delay
    async with session.post(url, json=data) as resp:
  File "D:\anaconda\envs\PBFT\lib\site-packages\aiohttp\client.py", line 1141, in __aenter__
    self._resp = await self._coro
  File "D:\anaconda\envs\PBFT\lib\site-packages\aiohttp\client.py", line 537, in _request
    req, traces=traces, timeout=real_timeout
  File "D:\anaconda\envs\PBFT\lib\site-packages\aiohttp\connector.py", line 540, in connect
    proto = await self._create_connection(req, traces, timeout)
  File "D:\anaconda\envs\PBFT\lib\site-packages\aiohttp\connector.py", line 901, in _create_connection
    _, proto = await self._create_direct_connection(req, traces, timeout)
  File "D:\anaconda\envs\PBFT\lib\site-packages\aiohttp\connector.py", line 1206, in _create_direct_connection
    raise last_exc
  File "D:\anaconda\envs\PBFT\lib\site-packages\aiohttp\connector.py", line 1187, in _create_direct_connection
    client_error=client_error,
  File "D:\anaconda\envs\PBFT\lib\site-packages\aiohttp\connector.py", line 988, in _wrap_create_connection
    raise client_error(req.connection_key, exc) from exc
aiohttp.client_exceptions.ClientConnectorError: Cannot connect to host localhost:30038 ssl:default [Connect call failed ('::1', 30038, 0, 0)]
[2025-03-07 13:53:51,298] [ERROR] [30105] Error sending to http://localhost:30038/prepare: Cannot connect to host localhost:30038 ssl:default [Connect call failed ('127.0.0.1', 30038)]
Traceback (most recent call last):
  File "D:\anaconda\envs\PBFT\lib\site-packages\aiohttp\connector.py", line 980, in _wrap_create_connection
    return await self._loop.create_connection(*args, **kwargs)  # type: ignore[return-value]  # noqa
  File "D:\anaconda\envs\PBFT\lib\asyncio\base_events.py", line 948, in create_connection
    raise exceptions[0]
  File "D:\anaconda\envs\PBFT\lib\asyncio\base_events.py", line 935, in create_connection
    await self.sock_connect(sock, address)
  File "D:\anaconda\envs\PBFT\lib\asyncio\selector_events.py", line 475, in sock_connect
    return await fut
  File "D:\anaconda\envs\PBFT\lib\asyncio\selector_events.py", line 505, in _sock_connect_cb
    raise OSError(err, f'Connect call failed {address}')
ConnectionRefusedError: [Errno 10061] Connect call failed ('127.0.0.1', 30038)

The above exception was the direct cause of the following exception:

Traceback (most recent call last):
  File "pbft.py", line 236, in send_message
    await send_with_delay(self.session, self.node_info, target, url, data, self.bandwidth_data)
  File "pbft.py", line 63, in send_with_delay
    async with session.post(url, json=data) as resp:
  File "D:\anaconda\envs\PBFT\lib\site-packages\aiohttp\client.py", line 1141, in __aenter__
    self._resp = await self._coro
  File "D:\anaconda\envs\PBFT\lib\site-packages\aiohttp\client.py", line 537, in _request
    req, traces=traces, timeout=real_timeout
  File "D:\anaconda\envs\PBFT\lib\site-packages\aiohttp\connector.py", line 540, in connect
    proto = await self._create_connection(req, traces, timeout)
  File "D:\anaconda\envs\PBFT\lib\site-packages\aiohttp\connector.py", line 901, in _create_connection
    _, proto = await self._create_direct_connection(req, traces, timeout)
  File "D:\anaconda\envs\PBFT\lib\site-packages\aiohttp\connector.py", line 1206, in _create_direct_connection
    raise last_exc
  File "D:\anaconda\envs\PBFT\lib\site-packages\aiohttp\connector.py", line 1187, in _create_direct_connection
    client_error=client_error,
  File "D:\anaconda\envs\PBFT\lib\site-packages\aiohttp\connector.py", line 988, in _wrap_create_connection
    raise client_error(req.connection_key, exc) from exc
aiohttp.client_exceptions.ClientConnectorError: Cannot connect to host localhost:30038 ssl:default [Connect call failed ('127.0.0.1', 30038)]
[2025-03-07 13:53:51,377] [INFO] [30105] Received PREPARE: id:1741323218379, from:30022, delay:0.0000s, distance:115.52m (Euclidean)
[2025-03-07 13:53:51,408] [INFO] [30105] Received PREPARE: id:1741323218379, from:30116, delay:0.0001s, distance:224.87m (Euclidean)
[2025-03-07 13:53:51,408] [INFO] [30105] Received COMMIT: id:1741323218379, from:30116, delay:0.0001s, distance:224.87m (Euclidean)
[2025-03-07 13:53:51,488] [ERROR] [30105] Error sending to http://localhost:30063/prepare: Cannot connect to host localhost:30063 ssl:default [Connect call failed ('127.0.0.1', 30063)]
Traceback (most recent call last):
  File "D:\anaconda\envs\PBFT\lib\site-packages\aiohttp\connector.py", line 980, in _wrap_create_connection
    return await self._loop.create_connection(*args, **kwargs)  # type: ignore[return-value]  # noqa
  File "D:\anaconda\envs\PBFT\lib\asyncio\base_events.py", line 948, in create_connection
    raise exceptions[0]
  File "D:\anaconda\envs\PBFT\lib\asyncio\base_events.py", line 935, in create_connection
    await self.sock_connect(sock, address)
  File "D:\anaconda\envs\PBFT\lib\asyncio\selector_events.py", line 475, in sock_connect
    return await fut
  File "D:\anaconda\envs\PBFT\lib\asyncio\selector_events.py", line 505, in _sock_connect_cb
    raise OSError(err, f'Connect call failed {address}')
ConnectionRefusedError: [Errno 10061] Connect call failed ('127.0.0.1', 30063)

The above exception was the direct cause of the following exception:

Traceback (most recent call last):
  File "pbft.py", line 236, in send_message
    await send_with_delay(self.session, self.node_info, target, url, data, self.bandwidth_data)
  File "pbft.py", line 63, in send_with_delay
    async with session.post(url, json=data) as resp:
  File "D:\anaconda\envs\PBFT\lib\site-packages\aiohttp\client.py", line 1141, in __aenter__
    self._resp = await self._coro
  File "D:\anaconda\envs\PBFT\lib\site-packages\aiohttp\client.py", line 537, in _request
    req, traces=traces, timeout=real_timeout
  File "D:\anaconda\envs\PBFT\lib\site-packages\aiohttp\connector.py", line 540, in connect
    proto = await self._create_connection(req, traces, timeout)
  File "D:\anaconda\envs\PBFT\lib\site-packages\aiohttp\connector.py", line 901, in _create_connection
    _, proto = await self._create_direct_connection(req, traces, timeout)
  File "D:\anaconda\envs\PBFT\lib\site-packages\aiohttp\connector.py", line 1206, in _create_direct_connection
    raise last_exc
  File "D:\anaconda\envs\PBFT\lib\site-packages\aiohttp\connector.py", line 1187, in _create_direct_connection
    client_error=client_error,
  File "D:\anaconda\envs\PBFT\lib\site-packages\aiohttp\connector.py", line 988, in _wrap_create_connection
    raise client_error(req.connection_key, exc) from exc
aiohttp.client_exceptions.ClientConnectorError: Cannot connect to host localhost:30063 ssl:default [Connect call failed ('127.0.0.1', 30063)]
[2025-03-07 13:53:51,503] [ERROR] [30105] Error sending to http://localhost:30063/commit: Cannot connect to host localhost:30063 ssl:default [Connect call failed ('::1', 30063, 0, 0)]
Traceback (most recent call last):
  File "D:\anaconda\envs\PBFT\lib\site-packages\aiohttp\connector.py", line 980, in _wrap_create_connection
    return await self._loop.create_connection(*args, **kwargs)  # type: ignore[return-value]  # noqa
  File "D:\anaconda\envs\PBFT\lib\asyncio\base_events.py", line 948, in create_connection
    raise exceptions[0]
  File "D:\anaconda\envs\PBFT\lib\asyncio\base_events.py", line 935, in create_connection
    await self.sock_connect(sock, address)
  File "D:\anaconda\envs\PBFT\lib\asyncio\selector_events.py", line 475, in sock_connect
    return await fut
  File "D:\anaconda\envs\PBFT\lib\asyncio\selector_events.py", line 505, in _sock_connect_cb
    raise OSError(err, f'Connect call failed {address}')
ConnectionRefusedError: [Errno 10061] Connect call failed ('::1', 30063, 0, 0)

The above exception was the direct cause of the following exception:

Traceback (most recent call last):
  File "pbft.py", line 236, in send_message
    await send_with_delay(self.session, self.node_info, target, url, data, self.bandwidth_data)
  File "pbft.py", line 63, in send_with_delay
    async with session.post(url, json=data) as resp:
  File "D:\anaconda\envs\PBFT\lib\site-packages\aiohttp\client.py", line 1141, in __aenter__
    self._resp = await self._coro
  File "D:\anaconda\envs\PBFT\lib\site-packages\aiohttp\client.py", line 537, in _request
    req, traces=traces, timeout=real_timeout
  File "D:\anaconda\envs\PBFT\lib\site-packages\aiohttp\connector.py", line 540, in connect
    proto = await self._create_connection(req, traces, timeout)
  File "D:\anaconda\envs\PBFT\lib\site-packages\aiohttp\connector.py", line 901, in _create_connection
    _, proto = await self._create_direct_connection(req, traces, timeout)
  File "D:\anaconda\envs\PBFT\lib\site-packages\aiohttp\connector.py", line 1206, in _create_direct_connection
    raise last_exc
  File "D:\anaconda\envs\PBFT\lib\site-packages\aiohttp\connector.py", line 1187, in _create_direct_connection
    client_error=client_error,
  File "D:\anaconda\envs\PBFT\lib\site-packages\aiohttp\connector.py", line 988, in _wrap_create_connection
    raise client_error(req.connection_key, exc) from exc
aiohttp.client_exceptions.ClientConnectorError: Cannot connect to host localhost:30063 ssl:default [Connect call failed ('::1', 30063, 0, 0)]
[2025-03-07 13:53:51,535] [ERROR] [30105] Error sending to http://localhost:30101/commit: Cannot connect to host localhost:30101 ssl:default [Connect call failed ('::1', 30101, 0, 0)]
Traceback (most recent call last):
  File "D:\anaconda\envs\PBFT\lib\site-packages\aiohttp\connector.py", line 980, in _wrap_create_connection
    return await self._loop.create_connection(*args, **kwargs)  # type: ignore[return-value]  # noqa
  File "D:\anaconda\envs\PBFT\lib\asyncio\base_events.py", line 948, in create_connection
    raise exceptions[0]
  File "D:\anaconda\envs\PBFT\lib\asyncio\base_events.py", line 935, in create_connection
    await self.sock_connect(sock, address)
  File "D:\anaconda\envs\PBFT\lib\asyncio\selector_events.py", line 475, in sock_connect
    return await fut
  File "D:\anaconda\envs\PBFT\lib\asyncio\selector_events.py", line 505, in _sock_connect_cb
    raise OSError(err, f'Connect call failed {address}')
ConnectionRefusedError: [Errno 10061] Connect call failed ('::1', 30101, 0, 0)

The above exception was the direct cause of the following exception:

Traceback (most recent call last):
  File "pbft.py", line 236, in send_message
    await send_with_delay(self.session, self.node_info, target, url, data, self.bandwidth_data)
  File "pbft.py", line 63, in send_with_delay
    async with session.post(url, json=data) as resp:
  File "D:\anaconda\envs\PBFT\lib\site-packages\aiohttp\client.py", line 1141, in __aenter__
    self._resp = await self._coro
  File "D:\anaconda\envs\PBFT\lib\site-packages\aiohttp\client.py", line 537, in _request
    req, traces=traces, timeout=real_timeout
  File "D:\anaconda\envs\PBFT\lib\site-packages\aiohttp\connector.py", line 540, in connect
    proto = await self._create_connection(req, traces, timeout)
  File "D:\anaconda\envs\PBFT\lib\site-packages\aiohttp\connector.py", line 901, in _create_connection
    _, proto = await self._create_direct_connection(req, traces, timeout)
  File "D:\anaconda\envs\PBFT\lib\site-packages\aiohttp\connector.py", line 1206, in _create_direct_connection
    raise last_exc
  File "D:\anaconda\envs\PBFT\lib\site-packages\aiohttp\connector.py", line 1187, in _create_direct_connection
    client_error=client_error,
  File "D:\anaconda\envs\PBFT\lib\site-packages\aiohttp\connector.py", line 988, in _wrap_create_connection
    raise client_error(req.connection_key, exc) from exc
aiohttp.client_exceptions.ClientConnectorError: Cannot connect to host localhost:30101 ssl:default [Connect call failed ('::1', 30101, 0, 0)]
[2025-03-07 13:53:51,598] [ERROR] [30105] Error sending to http://localhost:30103/commit: Cannot connect to host localhost:30103 ssl:default [Connect call failed ('::1', 30103, 0, 0)]
Traceback (most recent call last):
  File "D:\anaconda\envs\PBFT\lib\site-packages\aiohttp\connector.py", line 980, in _wrap_create_connection
    return await self._loop.create_connection(*args, **kwargs)  # type: ignore[return-value]  # noqa
  File "D:\anaconda\envs\PBFT\lib\asyncio\base_events.py", line 948, in create_connection
    raise exceptions[0]
  File "D:\anaconda\envs\PBFT\lib\asyncio\base_events.py", line 935, in create_connection
    await self.sock_connect(sock, address)
  File "D:\anaconda\envs\PBFT\lib\asyncio\selector_events.py", line 475, in sock_connect
    return await fut
  File "D:\anaconda\envs\PBFT\lib\asyncio\selector_events.py", line 505, in _sock_connect_cb
    raise OSError(err, f'Connect call failed {address}')
ConnectionRefusedError: [Errno 10061] Connect call failed ('::1', 30103, 0, 0)

The above exception was the direct cause of the following exception:

Traceback (most recent call last):
  File "pbft.py", line 236, in send_message
    await send_with_delay(self.session, self.node_info, target, url, data, self.bandwidth_data)
  File "pbft.py", line 63, in send_with_delay
    async with session.post(url, json=data) as resp:
  File "D:\anaconda\envs\PBFT\lib\site-packages\aiohttp\client.py", line 1141, in __aenter__
    self._resp = await self._coro
  File "D:\anaconda\envs\PBFT\lib\site-packages\aiohttp\client.py", line 537, in _request
    req, traces=traces, timeout=real_timeout
  File "D:\anaconda\envs\PBFT\lib\site-packages\aiohttp\connector.py", line 540, in connect
    proto = await self._create_connection(req, traces, timeout)
  File "D:\anaconda\envs\PBFT\lib\site-packages\aiohttp\connector.py", line 901, in _create_connection
    _, proto = await self._create_direct_connection(req, traces, timeout)
  File "D:\anaconda\envs\PBFT\lib\site-packages\aiohttp\connector.py", line 1206, in _create_direct_connection
    raise last_exc
  File "D:\anaconda\envs\PBFT\lib\site-packages\aiohttp\connector.py", line 1187, in _create_direct_connection
    client_error=client_error,
  File "D:\anaconda\envs\PBFT\lib\site-packages\aiohttp\connector.py", line 988, in _wrap_create_connection
    raise client_error(req.connection_key, exc) from exc
aiohttp.client_exceptions.ClientConnectorError: Cannot connect to host localhost:30103 ssl:default [Connect call failed ('::1', 30103, 0, 0)]
[2025-03-07 13:53:51,614] [ERROR] [30105] Error sending to http://localhost:30103/prepare: Cannot connect to host localhost:30103 ssl:default [Connect call failed ('127.0.0.1', 30103)]
Traceback (most recent call last):
  File "D:\anaconda\envs\PBFT\lib\site-packages\aiohttp\connector.py", line 980, in _wrap_create_connection
    return await self._loop.create_connection(*args, **kwargs)  # type: ignore[return-value]  # noqa
  File "D:\anaconda\envs\PBFT\lib\asyncio\base_events.py", line 948, in create_connection
    raise exceptions[0]
  File "D:\anaconda\envs\PBFT\lib\asyncio\base_events.py", line 935, in create_connection
    await self.sock_connect(sock, address)
  File "D:\anaconda\envs\PBFT\lib\asyncio\selector_events.py", line 475, in sock_connect
    return await fut
  File "D:\anaconda\envs\PBFT\lib\asyncio\selector_events.py", line 505, in _sock_connect_cb
    raise OSError(err, f'Connect call failed {address}')
ConnectionRefusedError: [Errno 10061] Connect call failed ('127.0.0.1', 30103)

The above exception was the direct cause of the following exception:

Traceback (most recent call last):
  File "pbft.py", line 236, in send_message
    await send_with_delay(self.session, self.node_info, target, url, data, self.bandwidth_data)
  File "pbft.py", line 63, in send_with_delay
    async with session.post(url, json=data) as resp:
  File "D:\anaconda\envs\PBFT\lib\site-packages\aiohttp\client.py", line 1141, in __aenter__
    self._resp = await self._coro
  File "D:\anaconda\envs\PBFT\lib\site-packages\aiohttp\client.py", line 537, in _request
    req, traces=traces, timeout=real_timeout
  File "D:\anaconda\envs\PBFT\lib\site-packages\aiohttp\connector.py", line 540, in connect
    proto = await self._create_connection(req, traces, timeout)
  File "D:\anaconda\envs\PBFT\lib\site-packages\aiohttp\connector.py", line 901, in _create_connection
    _, proto = await self._create_direct_connection(req, traces, timeout)
  File "D:\anaconda\envs\PBFT\lib\site-packages\aiohttp\connector.py", line 1206, in _create_direct_connection
    raise last_exc
  File "D:\anaconda\envs\PBFT\lib\site-packages\aiohttp\connector.py", line 1187, in _create_direct_connection
    client_error=client_error,
  File "D:\anaconda\envs\PBFT\lib\site-packages\aiohttp\connector.py", line 988, in _wrap_create_connection
    raise client_error(req.connection_key, exc) from exc
aiohttp.client_exceptions.ClientConnectorError: Cannot connect to host localhost:30103 ssl:default [Connect call failed ('127.0.0.1', 30103)]
[2025-03-07 13:53:51,630] [ERROR] [30105] Error sending to http://localhost:30093/prepare: Cannot connect to host localhost:30093 ssl:default [Connect call failed ('127.0.0.1', 30093)]
Traceback (most recent call last):
  File "D:\anaconda\envs\PBFT\lib\site-packages\aiohttp\connector.py", line 980, in _wrap_create_connection
    return await self._loop.create_connection(*args, **kwargs)  # type: ignore[return-value]  # noqa
  File "D:\anaconda\envs\PBFT\lib\asyncio\base_events.py", line 948, in create_connection
    raise exceptions[0]
  File "D:\anaconda\envs\PBFT\lib\asyncio\base_events.py", line 935, in create_connection
    await self.sock_connect(sock, address)
  File "D:\anaconda\envs\PBFT\lib\asyncio\selector_events.py", line 475, in sock_connect
    return await fut
  File "D:\anaconda\envs\PBFT\lib\asyncio\selector_events.py", line 505, in _sock_connect_cb
    raise OSError(err, f'Connect call failed {address}')
ConnectionRefusedError: [Errno 10061] Connect call failed ('127.0.0.1', 30093)

The above exception was the direct cause of the following exception:

Traceback (most recent call last):
  File "pbft.py", line 236, in send_message
    await send_with_delay(self.session, self.node_info, target, url, data, self.bandwidth_data)
  File "pbft.py", line 63, in send_with_delay
    async with session.post(url, json=data) as resp:
  File "D:\anaconda\envs\PBFT\lib\site-packages\aiohttp\client.py", line 1141, in __aenter__
    self._resp = await self._coro
  File "D:\anaconda\envs\PBFT\lib\site-packages\aiohttp\client.py", line 537, in _request
    req, traces=traces, timeout=real_timeout
  File "D:\anaconda\envs\PBFT\lib\site-packages\aiohttp\connector.py", line 540, in connect
    proto = await self._create_connection(req, traces, timeout)
  File "D:\anaconda\envs\PBFT\lib\site-packages\aiohttp\connector.py", line 901, in _create_connection
    _, proto = await self._create_direct_connection(req, traces, timeout)
  File "D:\anaconda\envs\PBFT\lib\site-packages\aiohttp\connector.py", line 1206, in _create_direct_connection
    raise last_exc
  File "D:\anaconda\envs\PBFT\lib\site-packages\aiohttp\connector.py", line 1187, in _create_direct_connection
    client_error=client_error,
  File "D:\anaconda\envs\PBFT\lib\site-packages\aiohttp\connector.py", line 988, in _wrap_create_connection
    raise client_error(req.connection_key, exc) from exc
aiohttp.client_exceptions.ClientConnectorError: Cannot connect to host localhost:30093 ssl:default [Connect call failed ('127.0.0.1', 30093)]
[2025-03-07 13:53:51,645] [ERROR] [30105] Error sending to http://localhost:30093/commit: Cannot connect to host localhost:30093 ssl:default [Connect call failed ('::1', 30093, 0, 0)]
Traceback (most recent call last):
  File "D:\anaconda\envs\PBFT\lib\site-packages\aiohttp\connector.py", line 980, in _wrap_create_connection
    return await self._loop.create_connection(*args, **kwargs)  # type: ignore[return-value]  # noqa
  File "D:\anaconda\envs\PBFT\lib\asyncio\base_events.py", line 948, in create_connection
    raise exceptions[0]
  File "D:\anaconda\envs\PBFT\lib\asyncio\base_events.py", line 935, in create_connection
    await self.sock_connect(sock, address)
  File "D:\anaconda\envs\PBFT\lib\asyncio\selector_events.py", line 475, in sock_connect
    return await fut
  File "D:\anaconda\envs\PBFT\lib\asyncio\selector_events.py", line 505, in _sock_connect_cb
    raise OSError(err, f'Connect call failed {address}')
ConnectionRefusedError: [Errno 10061] Connect call failed ('::1', 30093, 0, 0)

The above exception was the direct cause of the following exception:

Traceback (most recent call last):
  File "pbft.py", line 236, in send_message
    await send_with_delay(self.session, self.node_info, target, url, data, self.bandwidth_data)
  File "pbft.py", line 63, in send_with_delay
    async with session.post(url, json=data) as resp:
  File "D:\anaconda\envs\PBFT\lib\site-packages\aiohttp\client.py", line 1141, in __aenter__
    self._resp = await self._coro
  File "D:\anaconda\envs\PBFT\lib\site-packages\aiohttp\client.py", line 537, in _request
    req, traces=traces, timeout=real_timeout
  File "D:\anaconda\envs\PBFT\lib\site-packages\aiohttp\connector.py", line 540, in connect
    proto = await self._create_connection(req, traces, timeout)
  File "D:\anaconda\envs\PBFT\lib\site-packages\aiohttp\connector.py", line 901, in _create_connection
    _, proto = await self._create_direct_connection(req, traces, timeout)
  File "D:\anaconda\envs\PBFT\lib\site-packages\aiohttp\connector.py", line 1206, in _create_direct_connection
    raise last_exc
  File "D:\anaconda\envs\PBFT\lib\site-packages\aiohttp\connector.py", line 1187, in _create_direct_connection
    client_error=client_error,
  File "D:\anaconda\envs\PBFT\lib\site-packages\aiohttp\connector.py", line 988, in _wrap_create_connection
    raise client_error(req.connection_key, exc) from exc
aiohttp.client_exceptions.ClientConnectorError: Cannot connect to host localhost:30093 ssl:default [Connect call failed ('::1', 30093, 0, 0)]
[2025-03-07 13:53:51,669] [INFO] [30105] Received PREPARE: id:1741323218379, from:30068, delay:0.0001s, distance:215.99m (Euclidean)
[2025-03-07 13:53:51,673] [INFO] [30105] Received COMMIT: id:1741323218379, from:30068, delay:0.0001s, distance:215.99m (Euclidean)
[2025-03-07 13:53:51,690] [INFO] [30105] Received PREPARE: id:1741323218379, from:30106, delay:0.0000s, distance:139.75m (Euclidean)
[2025-03-07 13:53:51,787] [ERROR] [30105] Error sending to http://localhost:30140/commit: Cannot connect to host localhost:30140 ssl:default [Connect call failed ('::1', 30140, 0, 0)]
Traceback (most recent call last):
  File "D:\anaconda\envs\PBFT\lib\site-packages\aiohttp\connector.py", line 980, in _wrap_create_connection
    return await self._loop.create_connection(*args, **kwargs)  # type: ignore[return-value]  # noqa
  File "D:\anaconda\envs\PBFT\lib\asyncio\base_events.py", line 948, in create_connection
    raise exceptions[0]
  File "D:\anaconda\envs\PBFT\lib\asyncio\base_events.py", line 935, in create_connection
    await self.sock_connect(sock, address)
  File "D:\anaconda\envs\PBFT\lib\asyncio\selector_events.py", line 475, in sock_connect
    return await fut
  File "D:\anaconda\envs\PBFT\lib\asyncio\selector_events.py", line 505, in _sock_connect_cb
    raise OSError(err, f'Connect call failed {address}')
ConnectionRefusedError: [Errno 10061] Connect call failed ('::1', 30140, 0, 0)

The above exception was the direct cause of the following exception:

Traceback (most recent call last):
  File "pbft.py", line 236, in send_message
    await send_with_delay(self.session, self.node_info, target, url, data, self.bandwidth_data)
  File "pbft.py", line 63, in send_with_delay
    async with session.post(url, json=data) as resp:
  File "D:\anaconda\envs\PBFT\lib\site-packages\aiohttp\client.py", line 1141, in __aenter__
    self._resp = await self._coro
  File "D:\anaconda\envs\PBFT\lib\site-packages\aiohttp\client.py", line 537, in _request
    req, traces=traces, timeout=real_timeout
  File "D:\anaconda\envs\PBFT\lib\site-packages\aiohttp\connector.py", line 540, in connect
    proto = await self._create_connection(req, traces, timeout)
  File "D:\anaconda\envs\PBFT\lib\site-packages\aiohttp\connector.py", line 901, in _create_connection
    _, proto = await self._create_direct_connection(req, traces, timeout)
  File "D:\anaconda\envs\PBFT\lib\site-packages\aiohttp\connector.py", line 1206, in _create_direct_connection
    raise last_exc
  File "D:\anaconda\envs\PBFT\lib\site-packages\aiohttp\connector.py", line 1187, in _create_direct_connection
    client_error=client_error,
  File "D:\anaconda\envs\PBFT\lib\site-packages\aiohttp\connector.py", line 988, in _wrap_create_connection
    raise client_error(req.connection_key, exc) from exc
aiohttp.client_exceptions.ClientConnectorError: Cannot connect to host localhost:30140 ssl:default [Connect call failed ('::1', 30140, 0, 0)]
[2025-03-07 13:53:51,787] [ERROR] [30105] Error sending to http://localhost:30125/commit: Cannot connect to host localhost:30125 ssl:default [Connect call failed ('::1', 30125, 0, 0)]
Traceback (most recent call last):
  File "D:\anaconda\envs\PBFT\lib\site-packages\aiohttp\connector.py", line 980, in _wrap_create_connection
    return await self._loop.create_connection(*args, **kwargs)  # type: ignore[return-value]  # noqa
  File "D:\anaconda\envs\PBFT\lib\asyncio\base_events.py", line 948, in create_connection
    raise exceptions[0]
  File "D:\anaconda\envs\PBFT\lib\asyncio\base_events.py", line 935, in create_connection
    await self.sock_connect(sock, address)
  File "D:\anaconda\envs\PBFT\lib\asyncio\selector_events.py", line 475, in sock_connect
    return await fut
  File "D:\anaconda\envs\PBFT\lib\asyncio\selector_events.py", line 505, in _sock_connect_cb
    raise OSError(err, f'Connect call failed {address}')
ConnectionRefusedError: [Errno 10061] Connect call failed ('::1', 30125, 0, 0)

The above exception was the direct cause of the following exception:

Traceback (most recent call last):
  File "pbft.py", line 236, in send_message
    await send_with_delay(self.session, self.node_info, target, url, data, self.bandwidth_data)
  File "pbft.py", line 63, in send_with_delay
    async with session.post(url, json=data) as resp:
  File "D:\anaconda\envs\PBFT\lib\site-packages\aiohttp\client.py", line 1141, in __aenter__
    self._resp = await self._coro
  File "D:\anaconda\envs\PBFT\lib\site-packages\aiohttp\client.py", line 537, in _request
    req, traces=traces, timeout=real_timeout
  File "D:\anaconda\envs\PBFT\lib\site-packages\aiohttp\connector.py", line 540, in connect
    proto = await self._create_connection(req, traces, timeout)
  File "D:\anaconda\envs\PBFT\lib\site-packages\aiohttp\connector.py", line 901, in _create_connection
    _, proto = await self._create_direct_connection(req, traces, timeout)
  File "D:\anaconda\envs\PBFT\lib\site-packages\aiohttp\connector.py", line 1206, in _create_direct_connection
    raise last_exc
  File "D:\anaconda\envs\PBFT\lib\site-packages\aiohttp\connector.py", line 1187, in _create_direct_connection
    client_error=client_error,
  File "D:\anaconda\envs\PBFT\lib\site-packages\aiohttp\connector.py", line 988, in _wrap_create_connection
    raise client_error(req.connection_key, exc) from exc
aiohttp.client_exceptions.ClientConnectorError: Cannot connect to host localhost:30125 ssl:default [Connect call failed ('::1', 30125, 0, 0)]
[2025-03-07 13:53:51,787] [ERROR] [30105] Error sending to http://localhost:30140/prepare: Cannot connect to host localhost:30140 ssl:default [Connect call failed ('127.0.0.1', 30140)]
Traceback (most recent call last):
  File "D:\anaconda\envs\PBFT\lib\site-packages\aiohttp\connector.py", line 980, in _wrap_create_connection
    return await self._loop.create_connection(*args, **kwargs)  # type: ignore[return-value]  # noqa
  File "D:\anaconda\envs\PBFT\lib\asyncio\base_events.py", line 948, in create_connection
    raise exceptions[0]
  File "D:\anaconda\envs\PBFT\lib\asyncio\base_events.py", line 935, in create_connection
    await self.sock_connect(sock, address)
  File "D:\anaconda\envs\PBFT\lib\asyncio\selector_events.py", line 475, in sock_connect
    return await fut
  File "D:\anaconda\envs\PBFT\lib\asyncio\selector_events.py", line 505, in _sock_connect_cb
    raise OSError(err, f'Connect call failed {address}')
ConnectionRefusedError: [Errno 10061] Connect call failed ('127.0.0.1', 30140)

The above exception was the direct cause of the following exception:

Traceback (most recent call last):
  File "pbft.py", line 236, in send_message
    await send_with_delay(self.session, self.node_info, target, url, data, self.bandwidth_data)
  File "pbft.py", line 63, in send_with_delay
    async with session.post(url, json=data) as resp:
  File "D:\anaconda\envs\PBFT\lib\site-packages\aiohttp\client.py", line 1141, in __aenter__
    self._resp = await self._coro
  File "D:\anaconda\envs\PBFT\lib\site-packages\aiohttp\client.py", line 537, in _request
    req, traces=traces, timeout=real_timeout
  File "D:\anaconda\envs\PBFT\lib\site-packages\aiohttp\connector.py", line 540, in connect
    proto = await self._create_connection(req, traces, timeout)
  File "D:\anaconda\envs\PBFT\lib\site-packages\aiohttp\connector.py", line 901, in _create_connection
    _, proto = await self._create_direct_connection(req, traces, timeout)
  File "D:\anaconda\envs\PBFT\lib\site-packages\aiohttp\connector.py", line 1206, in _create_direct_connection
    raise last_exc
  File "D:\anaconda\envs\PBFT\lib\site-packages\aiohttp\connector.py", line 1187, in _create_direct_connection
    client_error=client_error,
  File "D:\anaconda\envs\PBFT\lib\site-packages\aiohttp\connector.py", line 988, in _wrap_create_connection
    raise client_error(req.connection_key, exc) from exc
aiohttp.client_exceptions.ClientConnectorError: Cannot connect to host localhost:30140 ssl:default [Connect call failed ('127.0.0.1', 30140)]
[2025-03-07 13:53:51,787] [ERROR] [30105] Error sending to http://localhost:30137/prepare: Cannot connect to host localhost:30137 ssl:default [Connect call failed ('127.0.0.1', 30137)]
Traceback (most recent call last):
  File "D:\anaconda\envs\PBFT\lib\site-packages\aiohttp\connector.py", line 980, in _wrap_create_connection
    return await self._loop.create_connection(*args, **kwargs)  # type: ignore[return-value]  # noqa
  File "D:\anaconda\envs\PBFT\lib\asyncio\base_events.py", line 948, in create_connection
    raise exceptions[0]
  File "D:\anaconda\envs\PBFT\lib\asyncio\base_events.py", line 935, in create_connection
    await self.sock_connect(sock, address)
  File "D:\anaconda\envs\PBFT\lib\asyncio\selector_events.py", line 475, in sock_connect
    return await fut
  File "D:\anaconda\envs\PBFT\lib\asyncio\selector_events.py", line 505, in _sock_connect_cb
    raise OSError(err, f'Connect call failed {address}')
ConnectionRefusedError: [Errno 10061] Connect call failed ('127.0.0.1', 30137)

The above exception was the direct cause of the following exception:

Traceback (most recent call last):
  File "pbft.py", line 236, in send_message
    await send_with_delay(self.session, self.node_info, target, url, data, self.bandwidth_data)
  File "pbft.py", line 63, in send_with_delay
    async with session.post(url, json=data) as resp:
  File "D:\anaconda\envs\PBFT\lib\site-packages\aiohttp\client.py", line 1141, in __aenter__
    self._resp = await self._coro
  File "D:\anaconda\envs\PBFT\lib\site-packages\aiohttp\client.py", line 537, in _request
    req, traces=traces, timeout=real_timeout
  File "D:\anaconda\envs\PBFT\lib\site-packages\aiohttp\connector.py", line 540, in connect
    proto = await self._create_connection(req, traces, timeout)
  File "D:\anaconda\envs\PBFT\lib\site-packages\aiohttp\connector.py", line 901, in _create_connection
    _, proto = await self._create_direct_connection(req, traces, timeout)
  File "D:\anaconda\envs\PBFT\lib\site-packages\aiohttp\connector.py", line 1206, in _create_direct_connection
    raise last_exc
  File "D:\anaconda\envs\PBFT\lib\site-packages\aiohttp\connector.py", line 1187, in _create_direct_connection
    client_error=client_error,
  File "D:\anaconda\envs\PBFT\lib\site-packages\aiohttp\connector.py", line 988, in _wrap_create_connection
    raise client_error(req.connection_key, exc) from exc
aiohttp.client_exceptions.ClientConnectorError: Cannot connect to host localhost:30137 ssl:default [Connect call failed ('127.0.0.1', 30137)]
[2025-03-07 13:53:51,787] [ERROR] [30105] Error sending to http://localhost:30137/commit: Cannot connect to host localhost:30137 ssl:default [Connect call failed ('::1', 30137, 0, 0)]
Traceback (most recent call last):
  File "D:\anaconda\envs\PBFT\lib\site-packages\aiohttp\connector.py", line 980, in _wrap_create_connection
    return await self._loop.create_connection(*args, **kwargs)  # type: ignore[return-value]  # noqa
  File "D:\anaconda\envs\PBFT\lib\asyncio\base_events.py", line 948, in create_connection
    raise exceptions[0]
  File "D:\anaconda\envs\PBFT\lib\asyncio\base_events.py", line 935, in create_connection
    await self.sock_connect(sock, address)
  File "D:\anaconda\envs\PBFT\lib\asyncio\selector_events.py", line 475, in sock_connect
    return await fut
  File "D:\anaconda\envs\PBFT\lib\asyncio\selector_events.py", line 505, in _sock_connect_cb
    raise OSError(err, f'Connect call failed {address}')
ConnectionRefusedError: [Errno 10061] Connect call failed ('::1', 30137, 0, 0)

The above exception was the direct cause of the following exception:

Traceback (most recent call last):
  File "pbft.py", line 236, in send_message
    await send_with_delay(self.session, self.node_info, target, url, data, self.bandwidth_data)
  File "pbft.py", line 63, in send_with_delay
    async with session.post(url, json=data) as resp:
  File "D:\anaconda\envs\PBFT\lib\site-packages\aiohttp\client.py", line 1141, in __aenter__
    self._resp = await self._coro
  File "D:\anaconda\envs\PBFT\lib\site-packages\aiohttp\client.py", line 537, in _request
    req, traces=traces, timeout=real_timeout
  File "D:\anaconda\envs\PBFT\lib\site-packages\aiohttp\connector.py", line 540, in connect
    proto = await self._create_connection(req, traces, timeout)
  File "D:\anaconda\envs\PBFT\lib\site-packages\aiohttp\connector.py", line 901, in _create_connection
    _, proto = await self._create_direct_connection(req, traces, timeout)
  File "D:\anaconda\envs\PBFT\lib\site-packages\aiohttp\connector.py", line 1206, in _create_direct_connection
    raise last_exc
  File "D:\anaconda\envs\PBFT\lib\site-packages\aiohttp\connector.py", line 1187, in _create_direct_connection
    client_error=client_error,
  File "D:\anaconda\envs\PBFT\lib\site-packages\aiohttp\connector.py", line 988, in _wrap_create_connection
    raise client_error(req.connection_key, exc) from exc
aiohttp.client_exceptions.ClientConnectorError: Cannot connect to host localhost:30137 ssl:default [Connect call failed ('::1', 30137, 0, 0)]
[2025-03-07 13:53:51,787] [ERROR] [30105] Error sending to http://localhost:30125/prepare: Cannot connect to host localhost:30125 ssl:default [Connect call failed ('127.0.0.1', 30125)]
Traceback (most recent call last):
  File "D:\anaconda\envs\PBFT\lib\site-packages\aiohttp\connector.py", line 980, in _wrap_create_connection
    return await self._loop.create_connection(*args, **kwargs)  # type: ignore[return-value]  # noqa
  File "D:\anaconda\envs\PBFT\lib\asyncio\base_events.py", line 948, in create_connection
    raise exceptions[0]
  File "D:\anaconda\envs\PBFT\lib\asyncio\base_events.py", line 935, in create_connection
    await self.sock_connect(sock, address)
  File "D:\anaconda\envs\PBFT\lib\asyncio\selector_events.py", line 475, in sock_connect
    return await fut
  File "D:\anaconda\envs\PBFT\lib\asyncio\selector_events.py", line 505, in _sock_connect_cb
    raise OSError(err, f'Connect call failed {address}')
ConnectionRefusedError: [Errno 10061] Connect call failed ('127.0.0.1', 30125)

The above exception was the direct cause of the following exception:

Traceback (most recent call last):
  File "pbft.py", line 236, in send_message
    await send_with_delay(self.session, self.node_info, target, url, data, self.bandwidth_data)
  File "pbft.py", line 63, in send_with_delay
    async with session.post(url, json=data) as resp:
  File "D:\anaconda\envs\PBFT\lib\site-packages\aiohttp\client.py", line 1141, in __aenter__
    self._resp = await self._coro
  File "D:\anaconda\envs\PBFT\lib\site-packages\aiohttp\client.py", line 537, in _request
    req, traces=traces, timeout=real_timeout
  File "D:\anaconda\envs\PBFT\lib\site-packages\aiohttp\connector.py", line 540, in connect
    proto = await self._create_connection(req, traces, timeout)
  File "D:\anaconda\envs\PBFT\lib\site-packages\aiohttp\connector.py", line 901, in _create_connection
    _, proto = await self._create_direct_connection(req, traces, timeout)
  File "D:\anaconda\envs\PBFT\lib\site-packages\aiohttp\connector.py", line 1206, in _create_direct_connection
    raise last_exc
  File "D:\anaconda\envs\PBFT\lib\site-packages\aiohttp\connector.py", line 1187, in _create_direct_connection
    client_error=client_error,
  File "D:\anaconda\envs\PBFT\lib\site-packages\aiohttp\connector.py", line 988, in _wrap_create_connection
    raise client_error(req.connection_key, exc) from exc
aiohttp.client_exceptions.ClientConnectorError: Cannot connect to host localhost:30125 ssl:default [Connect call failed ('127.0.0.1', 30125)]
[2025-03-07 13:53:51,787] [ERROR] [30105] Error sending to http://localhost:30029/commit: Cannot connect to host localhost:30029 ssl:default [Connect call failed ('::1', 30029, 0, 0)]
Traceback (most recent call last):
  File "D:\anaconda\envs\PBFT\lib\site-packages\aiohttp\connector.py", line 980, in _wrap_create_connection
    return await self._loop.create_connection(*args, **kwargs)  # type: ignore[return-value]  # noqa
  File "D:\anaconda\envs\PBFT\lib\asyncio\base_events.py", line 948, in create_connection
    raise exceptions[0]
  File "D:\anaconda\envs\PBFT\lib\asyncio\base_events.py", line 935, in create_connection
    await self.sock_connect(sock, address)
  File "D:\anaconda\envs\PBFT\lib\asyncio\selector_events.py", line 475, in sock_connect
    return await fut
  File "D:\anaconda\envs\PBFT\lib\asyncio\selector_events.py", line 505, in _sock_connect_cb
    raise OSError(err, f'Connect call failed {address}')
ConnectionRefusedError: [Errno 10061] Connect call failed ('::1', 30029, 0, 0)

The above exception was the direct cause of the following exception:

Traceback (most recent call last):
  File "pbft.py", line 236, in send_message
    await send_with_delay(self.session, self.node_info, target, url, data, self.bandwidth_data)
  File "pbft.py", line 63, in send_with_delay
    async with session.post(url, json=data) as resp:
  File "D:\anaconda\envs\PBFT\lib\site-packages\aiohttp\client.py", line 1141, in __aenter__
    self._resp = await self._coro
  File "D:\anaconda\envs\PBFT\lib\site-packages\aiohttp\client.py", line 537, in _request
    req, traces=traces, timeout=real_timeout
  File "D:\anaconda\envs\PBFT\lib\site-packages\aiohttp\connector.py", line 540, in connect
    proto = await self._create_connection(req, traces, timeout)
  File "D:\anaconda\envs\PBFT\lib\site-packages\aiohttp\connector.py", line 901, in _create_connection
    _, proto = await self._create_direct_connection(req, traces, timeout)
  File "D:\anaconda\envs\PBFT\lib\site-packages\aiohttp\connector.py", line 1206, in _create_direct_connection
    raise last_exc
  File "D:\anaconda\envs\PBFT\lib\site-packages\aiohttp\connector.py", line 1187, in _create_direct_connection
    client_error=client_error,
  File "D:\anaconda\envs\PBFT\lib\site-packages\aiohttp\connector.py", line 988, in _wrap_create_connection
    raise client_error(req.connection_key, exc) from exc
aiohttp.client_exceptions.ClientConnectorError: Cannot connect to host localhost:30029 ssl:default [Connect call failed ('::1', 30029, 0, 0)]
[2025-03-07 13:53:52,041] [INFO] [30105] Received PREPARE: id:1741323218379, from:30123, delay:0.0001s, distance:242.38m (Euclidean)
[2025-03-07 13:53:52,042] [INFO] [30105] Received COMMIT: id:1741323218379, from:30123, delay:0.0001s, distance:242.38m (Euclidean)
[2025-03-07 13:53:52,236] [ERROR] [30105] Error sending to http://localhost:30064/prepare: Cannot connect to host localhost:30064 ssl:default [Connect call failed ('127.0.0.1', 30064)]
Traceback (most recent call last):
  File "D:\anaconda\envs\PBFT\lib\site-packages\aiohttp\connector.py", line 980, in _wrap_create_connection
    return await self._loop.create_connection(*args, **kwargs)  # type: ignore[return-value]  # noqa
  File "D:\anaconda\envs\PBFT\lib\asyncio\base_events.py", line 948, in create_connection
    raise exceptions[0]
  File "D:\anaconda\envs\PBFT\lib\asyncio\base_events.py", line 935, in create_connection
    await self.sock_connect(sock, address)
  File "D:\anaconda\envs\PBFT\lib\asyncio\selector_events.py", line 475, in sock_connect
    return await fut
  File "D:\anaconda\envs\PBFT\lib\asyncio\selector_events.py", line 505, in _sock_connect_cb
    raise OSError(err, f'Connect call failed {address}')
ConnectionRefusedError: [Errno 10061] Connect call failed ('127.0.0.1', 30064)

The above exception was the direct cause of the following exception:

Traceback (most recent call last):
  File "pbft.py", line 236, in send_message
    await send_with_delay(self.session, self.node_info, target, url, data, self.bandwidth_data)
  File "pbft.py", line 63, in send_with_delay
    async with session.post(url, json=data) as resp:
  File "D:\anaconda\envs\PBFT\lib\site-packages\aiohttp\client.py", line 1141, in __aenter__
    self._resp = await self._coro
  File "D:\anaconda\envs\PBFT\lib\site-packages\aiohttp\client.py", line 537, in _request
    req, traces=traces, timeout=real_timeout
  File "D:\anaconda\envs\PBFT\lib\site-packages\aiohttp\connector.py", line 540, in connect
    proto = await self._create_connection(req, traces, timeout)
  File "D:\anaconda\envs\PBFT\lib\site-packages\aiohttp\connector.py", line 901, in _create_connection
    _, proto = await self._create_direct_connection(req, traces, timeout)
  File "D:\anaconda\envs\PBFT\lib\site-packages\aiohttp\connector.py", line 1206, in _create_direct_connection
    raise last_exc
  File "D:\anaconda\envs\PBFT\lib\site-packages\aiohttp\connector.py", line 1187, in _create_direct_connection
    client_error=client_error,
  File "D:\anaconda\envs\PBFT\lib\site-packages\aiohttp\connector.py", line 988, in _wrap_create_connection
    raise client_error(req.connection_key, exc) from exc
aiohttp.client_exceptions.ClientConnectorError: Cannot connect to host localhost:30064 ssl:default [Connect call failed ('127.0.0.1', 30064)]
[2025-03-07 13:53:52,236] [ERROR] [30105] Error sending to http://localhost:30064/commit: Cannot connect to host localhost:30064 ssl:default [Connect call failed ('::1', 30064, 0, 0)]
Traceback (most recent call last):
  File "D:\anaconda\envs\PBFT\lib\site-packages\aiohttp\connector.py", line 980, in _wrap_create_connection
    return await self._loop.create_connection(*args, **kwargs)  # type: ignore[return-value]  # noqa
  File "D:\anaconda\envs\PBFT\lib\asyncio\base_events.py", line 948, in create_connection
    raise exceptions[0]
  File "D:\anaconda\envs\PBFT\lib\asyncio\base_events.py", line 935, in create_connection
    await self.sock_connect(sock, address)
  File "D:\anaconda\envs\PBFT\lib\asyncio\selector_events.py", line 475, in sock_connect
    return await fut
  File "D:\anaconda\envs\PBFT\lib\asyncio\selector_events.py", line 505, in _sock_connect_cb
    raise OSError(err, f'Connect call failed {address}')
ConnectionRefusedError: [Errno 10061] Connect call failed ('::1', 30064, 0, 0)

The above exception was the direct cause of the following exception:

Traceback (most recent call last):
  File "pbft.py", line 236, in send_message
    await send_with_delay(self.session, self.node_info, target, url, data, self.bandwidth_data)
  File "pbft.py", line 63, in send_with_delay
    async with session.post(url, json=data) as resp:
  File "D:\anaconda\envs\PBFT\lib\site-packages\aiohttp\client.py", line 1141, in __aenter__
    self._resp = await self._coro
  File "D:\anaconda\envs\PBFT\lib\site-packages\aiohttp\client.py", line 537, in _request
    req, traces=traces, timeout=real_timeout
  File "D:\anaconda\envs\PBFT\lib\site-packages\aiohttp\connector.py", line 540, in connect
    proto = await self._create_connection(req, traces, timeout)
  File "D:\anaconda\envs\PBFT\lib\site-packages\aiohttp\connector.py", line 901, in _create_connection
    _, proto = await self._create_direct_connection(req, traces, timeout)
  File "D:\anaconda\envs\PBFT\lib\site-packages\aiohttp\connector.py", line 1206, in _create_direct_connection
    raise last_exc
  File "D:\anaconda\envs\PBFT\lib\site-packages\aiohttp\connector.py", line 1187, in _create_direct_connection
    client_error=client_error,
  File "D:\anaconda\envs\PBFT\lib\site-packages\aiohttp\connector.py", line 988, in _wrap_create_connection
    raise client_error(req.connection_key, exc) from exc
aiohttp.client_exceptions.ClientConnectorError: Cannot connect to host localhost:30064 ssl:default [Connect call failed ('::1', 30064, 0, 0)]
[2025-03-07 13:53:52,242] [ERROR] [30105] Error sending to http://localhost:30138/commit: Cannot connect to host localhost:30138 ssl:default [Connect call failed ('::1', 30138, 0, 0)]
Traceback (most recent call last):
  File "D:\anaconda\envs\PBFT\lib\site-packages\aiohttp\connector.py", line 980, in _wrap_create_connection
    return await self._loop.create_connection(*args, **kwargs)  # type: ignore[return-value]  # noqa
  File "D:\anaconda\envs\PBFT\lib\asyncio\base_events.py", line 948, in create_connection
    raise exceptions[0]
  File "D:\anaconda\envs\PBFT\lib\asyncio\base_events.py", line 935, in create_connection
    await self.sock_connect(sock, address)
  File "D:\anaconda\envs\PBFT\lib\asyncio\selector_events.py", line 475, in sock_connect
    return await fut
  File "D:\anaconda\envs\PBFT\lib\asyncio\selector_events.py", line 505, in _sock_connect_cb
    raise OSError(err, f'Connect call failed {address}')
ConnectionRefusedError: [Errno 10061] Connect call failed ('::1', 30138, 0, 0)

The above exception was the direct cause of the following exception:

Traceback (most recent call last):
  File "pbft.py", line 236, in send_message
    await send_with_delay(self.session, self.node_info, target, url, data, self.bandwidth_data)
  File "pbft.py", line 63, in send_with_delay
    async with session.post(url, json=data) as resp:
  File "D:\anaconda\envs\PBFT\lib\site-packages\aiohttp\client.py", line 1141, in __aenter__
    self._resp = await self._coro
  File "D:\anaconda\envs\PBFT\lib\site-packages\aiohttp\client.py", line 537, in _request
    req, traces=traces, timeout=real_timeout
  File "D:\anaconda\envs\PBFT\lib\site-packages\aiohttp\connector.py", line 540, in connect
    proto = await self._create_connection(req, traces, timeout)
  File "D:\anaconda\envs\PBFT\lib\site-packages\aiohttp\connector.py", line 901, in _create_connection
    _, proto = await self._create_direct_connection(req, traces, timeout)
  File "D:\anaconda\envs\PBFT\lib\site-packages\aiohttp\connector.py", line 1206, in _create_direct_connection
    raise last_exc
  File "D:\anaconda\envs\PBFT\lib\site-packages\aiohttp\connector.py", line 1187, in _create_direct_connection
    client_error=client_error,
  File "D:\anaconda\envs\PBFT\lib\site-packages\aiohttp\connector.py", line 988, in _wrap_create_connection
    raise client_error(req.connection_key, exc) from exc
aiohttp.client_exceptions.ClientConnectorError: Cannot connect to host localhost:30138 ssl:default [Connect call failed ('::1', 30138, 0, 0)]
[2025-03-07 13:53:52,244] [ERROR] [30105] Error sending to http://localhost:30124/prepare: Cannot connect to host localhost:30124 ssl:default [Connect call failed ('127.0.0.1', 30124)]
Traceback (most recent call last):
  File "D:\anaconda\envs\PBFT\lib\site-packages\aiohttp\connector.py", line 980, in _wrap_create_connection
    return await self._loop.create_connection(*args, **kwargs)  # type: ignore[return-value]  # noqa
  File "D:\anaconda\envs\PBFT\lib\asyncio\base_events.py", line 948, in create_connection
    raise exceptions[0]
  File "D:\anaconda\envs\PBFT\lib\asyncio\base_events.py", line 935, in create_connection
    await self.sock_connect(sock, address)
  File "D:\anaconda\envs\PBFT\lib\asyncio\selector_events.py", line 475, in sock_connect
    return await fut
  File "D:\anaconda\envs\PBFT\lib\asyncio\selector_events.py", line 505, in _sock_connect_cb
    raise OSError(err, f'Connect call failed {address}')
ConnectionRefusedError: [Errno 10061] Connect call failed ('127.0.0.1', 30124)

The above exception was the direct cause of the following exception:

Traceback (most recent call last):
  File "pbft.py", line 236, in send_message
    await send_with_delay(self.session, self.node_info, target, url, data, self.bandwidth_data)
  File "pbft.py", line 63, in send_with_delay
    async with session.post(url, json=data) as resp:
  File "D:\anaconda\envs\PBFT\lib\site-packages\aiohttp\client.py", line 1141, in __aenter__
    self._resp = await self._coro
  File "D:\anaconda\envs\PBFT\lib\site-packages\aiohttp\client.py", line 537, in _request
    req, traces=traces, timeout=real_timeout
  File "D:\anaconda\envs\PBFT\lib\site-packages\aiohttp\connector.py", line 540, in connect
    proto = await self._create_connection(req, traces, timeout)
  File "D:\anaconda\envs\PBFT\lib\site-packages\aiohttp\connector.py", line 901, in _create_connection
    _, proto = await self._create_direct_connection(req, traces, timeout)
  File "D:\anaconda\envs\PBFT\lib\site-packages\aiohttp\connector.py", line 1206, in _create_direct_connection
    raise last_exc
  File "D:\anaconda\envs\PBFT\lib\site-packages\aiohttp\connector.py", line 1187, in _create_direct_connection
    client_error=client_error,
  File "D:\anaconda\envs\PBFT\lib\site-packages\aiohttp\connector.py", line 988, in _wrap_create_connection
    raise client_error(req.connection_key, exc) from exc
aiohttp.client_exceptions.ClientConnectorError: Cannot connect to host localhost:30124 ssl:default [Connect call failed ('127.0.0.1', 30124)]
[2025-03-07 13:53:52,244] [ERROR] [30105] Error sending to http://localhost:30124/commit: Cannot connect to host localhost:30124 ssl:default [Connect call failed ('::1', 30124, 0, 0)]
Traceback (most recent call last):
  File "D:\anaconda\envs\PBFT\lib\site-packages\aiohttp\connector.py", line 980, in _wrap_create_connection
    return await self._loop.create_connection(*args, **kwargs)  # type: ignore[return-value]  # noqa
  File "D:\anaconda\envs\PBFT\lib\asyncio\base_events.py", line 948, in create_connection
    raise exceptions[0]
  File "D:\anaconda\envs\PBFT\lib\asyncio\base_events.py", line 935, in create_connection
    await self.sock_connect(sock, address)
  File "D:\anaconda\envs\PBFT\lib\asyncio\selector_events.py", line 475, in sock_connect
    return await fut
  File "D:\anaconda\envs\PBFT\lib\asyncio\selector_events.py", line 505, in _sock_connect_cb
    raise OSError(err, f'Connect call failed {address}')
ConnectionRefusedError: [Errno 10061] Connect call failed ('::1', 30124, 0, 0)

The above exception was the direct cause of the following exception:

Traceback (most recent call last):
  File "pbft.py", line 236, in send_message
    await send_with_delay(self.session, self.node_info, target, url, data, self.bandwidth_data)
  File "pbft.py", line 63, in send_with_delay
    async with session.post(url, json=data) as resp:
  File "D:\anaconda\envs\PBFT\lib\site-packages\aiohttp\client.py", line 1141, in __aenter__
    self._resp = await self._coro
  File "D:\anaconda\envs\PBFT\lib\site-packages\aiohttp\client.py", line 537, in _request
    req, traces=traces, timeout=real_timeout
  File "D:\anaconda\envs\PBFT\lib\site-packages\aiohttp\connector.py", line 540, in connect
    proto = await self._create_connection(req, traces, timeout)
  File "D:\anaconda\envs\PBFT\lib\site-packages\aiohttp\connector.py", line 901, in _create_connection
    _, proto = await self._create_direct_connection(req, traces, timeout)
  File "D:\anaconda\envs\PBFT\lib\site-packages\aiohttp\connector.py", line 1206, in _create_direct_connection
    raise last_exc
  File "D:\anaconda\envs\PBFT\lib\site-packages\aiohttp\connector.py", line 1187, in _create_direct_connection
    client_error=client_error,
  File "D:\anaconda\envs\PBFT\lib\site-packages\aiohttp\connector.py", line 988, in _wrap_create_connection
    raise client_error(req.connection_key, exc) from exc
aiohttp.client_exceptions.ClientConnectorError: Cannot connect to host localhost:30124 ssl:default [Connect call failed ('::1', 30124, 0, 0)]
[2025-03-07 13:53:52,244] [ERROR] [30105] Error sending to http://localhost:30138/prepare: Cannot connect to host localhost:30138 ssl:default [Connect call failed ('127.0.0.1', 30138)]
Traceback (most recent call last):
  File "D:\anaconda\envs\PBFT\lib\site-packages\aiohttp\connector.py", line 980, in _wrap_create_connection
    return await self._loop.create_connection(*args, **kwargs)  # type: ignore[return-value]  # noqa
  File "D:\anaconda\envs\PBFT\lib\asyncio\base_events.py", line 948, in create_connection
    raise exceptions[0]
  File "D:\anaconda\envs\PBFT\lib\asyncio\base_events.py", line 935, in create_connection
    await self.sock_connect(sock, address)
  File "D:\anaconda\envs\PBFT\lib\asyncio\selector_events.py", line 475, in sock_connect
    return await fut
  File "D:\anaconda\envs\PBFT\lib\asyncio\selector_events.py", line 505, in _sock_connect_cb
    raise OSError(err, f'Connect call failed {address}')
ConnectionRefusedError: [Errno 10061] Connect call failed ('127.0.0.1', 30138)

The above exception was the direct cause of the following exception:

Traceback (most recent call last):
  File "pbft.py", line 236, in send_message
    await send_with_delay(self.session, self.node_info, target, url, data, self.bandwidth_data)
  File "pbft.py", line 63, in send_with_delay
    async with session.post(url, json=data) as resp:
  File "D:\anaconda\envs\PBFT\lib\site-packages\aiohttp\client.py", line 1141, in __aenter__
    self._resp = await self._coro
  File "D:\anaconda\envs\PBFT\lib\site-packages\aiohttp\client.py", line 537, in _request
    req, traces=traces, timeout=real_timeout
  File "D:\anaconda\envs\PBFT\lib\site-packages\aiohttp\connector.py", line 540, in connect
    proto = await self._create_connection(req, traces, timeout)
  File "D:\anaconda\envs\PBFT\lib\site-packages\aiohttp\connector.py", line 901, in _create_connection
    _, proto = await self._create_direct_connection(req, traces, timeout)
  File "D:\anaconda\envs\PBFT\lib\site-packages\aiohttp\connector.py", line 1206, in _create_direct_connection
    raise last_exc
  File "D:\anaconda\envs\PBFT\lib\site-packages\aiohttp\connector.py", line 1187, in _create_direct_connection
    client_error=client_error,
  File "D:\anaconda\envs\PBFT\lib\site-packages\aiohttp\connector.py", line 988, in _wrap_create_connection
    raise client_error(req.connection_key, exc) from exc
aiohttp.client_exceptions.ClientConnectorError: Cannot connect to host localhost:30138 ssl:default [Connect call failed ('127.0.0.1', 30138)]
[2025-03-07 13:53:52,291] [INFO] [30105] Received COMMIT: id:1741323218379, from:30022, delay:0.0000s, distance:115.52m (Euclidean)
[2025-03-07 13:53:52,307] [INFO] [30105] Received PREPARE: id:1741323218379, from:30129, delay:0.0000s, distance:180.34m (Euclidean)
[2025-03-07 13:53:52,307] [INFO] [30105] Received COMMIT: id:1741323218379, from:30129, delay:0.0000s, distance:180.34m (Euclidean)
[2025-03-07 13:53:52,343] [INFO] [30105] Received PREPARE: id:1741323218379, from:30118, delay:0.0000s, distance:171.87m (Euclidean)
[2025-03-07 13:53:52,343] [INFO] [30105] Received COMMIT: id:1741323218379, from:30118, delay:0.0000s, distance:171.87m (Euclidean)
[2025-03-07 13:53:52,878] [INFO] [30105] Received COMMIT: id:1741323218379, from:30113, delay:0.0000s, distance:126.65m (Euclidean)
[2025-03-07 13:53:52,925] [INFO] [30105] Received PREPARE: id:1741323218379, from:30155, delay:0.0002s, distance:272.66m (Euclidean)
[2025-03-07 13:53:53,182] [INFO] [30105] Received PREPARE: id:1741323218379, from:30111, delay:0.0000s, distance:172.13m (Euclidean)
[2025-03-07 13:53:53,268] [INFO] [30105] Received PREPARE: id:1741323218379, from:30145, delay:0.0002s, distance:276.97m (Euclidean)
[2025-03-07 13:53:53,276] [INFO] [30105] Received PREPARE: id:1741323218379, from:30132, delay:0.0001s, distance:228.39m (Euclidean)
[2025-03-07 13:53:53,284] [INFO] [30105] Received COMMIT: id:1741323218379, from:30132, delay:0.0001s, distance:228.39m (Euclidean)
[2025-03-07 13:53:53,496] [INFO] [30105] Received PREPARE: id:1741323218379, from:30127, delay:0.0002s, distance:296.67m (Euclidean)
[2025-03-07 13:53:53,496] [INFO] [30105] Received COMMIT: id:1741323218379, from:30127, delay:0.0002s, distance:296.67m (Euclidean)
[2025-03-07 13:53:53,565] [INFO] [30105] Received COMMIT: id:1741323218379, from:30111, delay:0.0000s, distance:172.13m (Euclidean)
[2025-03-07 13:53:53,574] [INFO] [30105] Received COMMIT: id:1741323218379, from:30155, delay:0.0002s, distance:272.66m (Euclidean)
[2025-03-07 13:53:53,640] [INFO] [30105] Received PREPARE: id:1741323218379, from:30142, delay:0.0001s, distance:161.70m (Euclidean)
[2025-03-07 13:53:53,642] [INFO] [30105] Received COMMIT: id:1741323218379, from:30142, delay:0.0001s, distance:161.70m (Euclidean)
[2025-03-07 13:53:53,705] [INFO] [30105] Received PREPARE: id:1741323218379, from:30159, delay:0.0002s, distance:253.89m (Euclidean)
[2025-03-07 13:53:53,711] [INFO] [30105] Received COMMIT: id:1741323218379, from:30159, delay:0.0002s, distance:253.89m (Euclidean)
[2025-03-07 13:53:53,717] [INFO] [30105] Received PREPARE: id:1741323218379, from:30120, delay:0.0001s, distance:189.44m (Euclidean)
[2025-03-07 13:53:53,717] [INFO] [30105] Received COMMIT: id:1741323218379, from:30120, delay:0.0001s, distance:189.44m (Euclidean)
[2025-03-07 13:53:53,717] [INFO] [30105] Received COMMIT: id:1741323218379, from:30145, delay:0.0002s, distance:276.97m (Euclidean)
[2025-03-07 13:53:53,768] [INFO] [30105] Received COMMIT: id:1741323218379, from:30106, delay:0.0000s, distance:139.75m (Euclidean)
[2025-03-07 13:53:54,224] [INFO] [30105] Received PREPARE: id:1741323218379, from:30152, delay:0.0001s, distance:218.94m (Euclidean)
[2025-03-07 13:53:54,239] [INFO] [30105] Received PREPARE: id:1741323218379, from:30115, delay:0.0000s, distance:149.41m (Euclidean)
[2025-03-07 13:53:54,239] [INFO] [30105] Received COMMIT: id:1741323218379, from:30115, delay:0.0000s, distance:149.41m (Euclidean)
[2025-03-07 13:53:54,246] [INFO] [30105] Received COMMIT: id:1741323218379, from:30152, delay:0.0001s, distance:218.94m (Euclidean)
[2025-03-07 13:53:54,246] [INFO] [30105] Received PREPARE: id:1741323218379, from:30156, delay:0.0001s, distance:198.16m (Euclidean)
[2025-03-07 13:53:54,311] [INFO] [30105] Received PREPARE: id:1741323218379, from:30146, delay:0.0002s, distance:292.23m (Euclidean)
[2025-03-07 13:53:54,318] [INFO] [30105] Received COMMIT: id:1741323218379, from:30146, delay:0.0002s, distance:292.23m (Euclidean)
[2025-03-07 13:53:54,530] [INFO] [30105] Received COMMIT: id:1741323218379, from:30156, delay:0.0001s, distance:198.16m (Euclidean)
[2025-03-07 13:57:35,284] [INFO] Starting node at localhost:30105 | index=106 | f=1, k=4 | Role: Replica
[2025-03-07 13:58:37,703] [INFO] Starting node at localhost:30105 | index=106 | f=1, k=4 | Role: Replica
[2025-03-07 13:59:03,059] [INFO] [30105] Received PREPARE: id:1741323542381, from:30106, delay:0.0000s, distance:50.90m (Euclidean)
[2025-03-07 13:59:03,059] [INFO] [30105] Missing PRE-PREPARE for REQUEST 1741323542381; ignoring PREPARE
[2025-03-07 13:59:03,534] [INFO] [30105] Received PREPARE: id:1741323542381, from:30118, delay:0.0000s, distance:131.80m (Euclidean)
[2025-03-07 13:59:03,534] [INFO] [30105] Missing PRE-PREPARE for REQUEST 1741323542381; ignoring PREPARE
[2025-03-07 13:59:03,548] [INFO] [30105] Received PREPARE: id:1741323542381, from:30189, delay:0.0001s, distance:182.62m (Euclidean)
[2025-03-07 13:59:03,548] [INFO] [30105] Missing PRE-PREPARE for REQUEST 1741323542381; ignoring PREPARE
[2025-03-07 13:59:03,554] [INFO] [30105] Received PREPARE: id:1741323542381, from:30157, delay:0.0001s, distance:164.06m (Euclidean)
[2025-03-07 13:59:03,554] [INFO] [30105] Missing PRE-PREPARE for REQUEST 1741323542381; ignoring PREPARE
[2025-03-07 13:59:03,578] [INFO] [30105] Received PREPARE: id:1741323542381, from:30196, delay:0.0001s, distance:196.49m (Euclidean)
[2025-03-07 13:59:03,578] [INFO] [30105] Missing PRE-PREPARE for REQUEST 1741323542381; ignoring PREPARE
[2025-03-07 13:59:03,594] [INFO] [30105] Received PREPARE: id:1741323542381, from:30108, delay:0.0000s, distance:125.28m (Euclidean)
[2025-03-07 13:59:03,595] [INFO] [30105] Missing PRE-PREPARE for REQUEST 1741323542381; ignoring PREPARE
[2025-03-07 13:59:03,821] [INFO] [30105] Received PREPARE: id:1741323542381, from:30168, delay:0.0000s, distance:145.07m (Euclidean)
[2025-03-07 13:59:03,821] [INFO] [30105] Missing PRE-PREPARE for REQUEST 1741323542381; ignoring PREPARE
[2025-03-07 13:59:03,968] [INFO] [30105] Received PREPARE: id:1741323542381, from:30065, delay:0.0001s, distance:197.35m (Euclidean)
[2025-03-07 13:59:03,969] [INFO] [30105] Missing PRE-PREPARE for REQUEST 1741323542381; ignoring PREPARE
[2025-03-07 13:59:04,030] [INFO] [30105] Received PREPARE: id:1741323542381, from:30089, delay:0.0000s, distance:67.41m (Euclidean)
[2025-03-07 13:59:04,030] [INFO] [30105] Missing PRE-PREPARE for REQUEST 1741323542381; ignoring PREPARE
[2025-03-07 13:59:04,042] [INFO] [30105] Received PREPARE: id:1741323542381, from:30133, delay:0.0001s, distance:224.37m (Euclidean)
[2025-03-07 13:59:04,042] [INFO] [30105] Missing PRE-PREPARE for REQUEST 1741323542381; ignoring PREPARE
[2025-03-07 13:59:04,083] [INFO] [30105] Received PREPARE: id:1741323542381, from:30095, delay:0.0001s, distance:194.30m (Euclidean)
[2025-03-07 13:59:04,083] [INFO] [30105] Missing PRE-PREPARE for REQUEST 1741323542381; ignoring PREPARE
[2025-03-07 13:59:04,119] [INFO] [30105] Received PREPARE: id:1741323542381, from:30127, delay:0.0000s, distance:58.86m (Euclidean)
[2025-03-07 13:59:04,119] [INFO] [30105] Missing PRE-PREPARE for REQUEST 1741323542381; ignoring PREPARE
[2025-03-07 13:59:04,135] [INFO] [30105] Received PREPARE: id:1741323542381, from:30123, delay:0.0000s, distance:148.29m (Euclidean)
[2025-03-07 13:59:04,135] [INFO] [30105] Missing PRE-PREPARE for REQUEST 1741323542381; ignoring PREPARE
[2025-03-07 13:59:04,151] [INFO] [30105] Received PREPARE: id:1741323542381, from:30169, delay:0.0001s, distance:165.00m (Euclidean)
[2025-03-07 13:59:04,151] [INFO] [30105] Missing PRE-PREPARE for REQUEST 1741323542381; ignoring PREPARE
[2025-03-07 13:59:04,170] [INFO] [30105] Received PREPARE: id:1741323542381, from:30027, delay:0.0000s, distance:149.87m (Euclidean)
[2025-03-07 13:59:04,170] [INFO] [30105] Missing PRE-PREPARE for REQUEST 1741323542381; ignoring PREPARE
[2025-03-07 13:59:04,182] [INFO] [30105] Received PREPARE: id:1741323542381, from:30115, delay:0.0001s, distance:153.79m (Euclidean)
[2025-03-07 13:59:04,182] [INFO] [30105] Missing PRE-PREPARE for REQUEST 1741323542381; ignoring PREPARE
[2025-03-07 13:59:04,184] [INFO] [30105] Received PREPARE: id:1741323542381, from:30112, delay:0.0000s, distance:92.21m (Euclidean)
[2025-03-07 13:59:04,184] [INFO] [30105] Missing PRE-PREPARE for REQUEST 1741323542381; ignoring PREPARE
[2025-03-07 13:59:04,190] [INFO] [30105] Received PREPARE: id:1741323542381, from:30147, delay:0.0002s, distance:294.92m (Euclidean)
[2025-03-07 13:59:04,190] [INFO] [30105] Missing PRE-PREPARE for REQUEST 1741323542381; ignoring PREPARE
[2025-03-07 13:59:04,197] [INFO] [30105] Received COMMIT: id:1741323542381, from:30169, delay:0.0001s, distance:165.00m (Euclidean)
[2025-03-07 13:59:04,217] [INFO] [30105] Received PREPARE: id:1741323542381, from:30025, delay:0.0001s, distance:183.47m (Euclidean)
[2025-03-07 13:59:04,217] [INFO] [30105] Missing PRE-PREPARE for REQUEST 1741323542381; ignoring PREPARE
[2025-03-07 13:59:04,229] [INFO] [30105] Received PREPARE: id:1741323542381, from:30007, delay:0.0000s, distance:170.12m (Euclidean)
[2025-03-07 13:59:04,229] [INFO] [30105] Missing PRE-PREPARE for REQUEST 1741323542381; ignoring PREPARE
[2025-03-07 13:59:04,277] [INFO] [30105] Received COMMIT: id:1741323542381, from:30127, delay:0.0000s, distance:58.86m (Euclidean)
[2025-03-07 13:59:04,331] [INFO] [30105] Received PREPARE: id:1741323542381, from:30015, delay:0.0000s, distance:194.24m (Euclidean)
[2025-03-07 13:59:04,331] [INFO] [30105] Missing PRE-PREPARE for REQUEST 1741323542381; ignoring PREPARE
[2025-03-07 13:59:04,360] [INFO] [30105] Received COMMIT: id:1741323542381, from:30112, delay:0.0000s, distance:92.21m (Euclidean)
[2025-03-07 13:59:04,372] [INFO] [30105] Received PREPARE: id:1741323542381, from:30057, delay:0.0000s, distance:65.09m (Euclidean)
[2025-03-07 13:59:04,372] [INFO] [30105] Missing PRE-PREPARE for REQUEST 1741323542381; ignoring PREPARE
[2025-03-07 13:59:04,392] [INFO] [30105] Received PREPARE: id:1741323542381, from:30149, delay:0.0000s, distance:172.00m (Euclidean)
[2025-03-07 13:59:04,392] [INFO] [30105] Missing PRE-PREPARE for REQUEST 1741323542381; ignoring PREPARE
[2025-03-07 13:59:04,459] [INFO] [30105] Received PREPARE: id:1741323542381, from:30028, delay:0.0002s, distance:258.79m (Euclidean)
[2025-03-07 13:59:04,459] [INFO] [30105] Missing PRE-PREPARE for REQUEST 1741323542381; ignoring PREPARE
[2025-03-07 13:59:04,477] [INFO] [30105] Received COMMIT: id:1741323542381, from:30157, delay:0.0001s, distance:164.06m (Euclidean)
[2025-03-07 13:59:04,485] [INFO] [30105] Received COMMIT: id:1741323542381, from:30189, delay:0.0001s, distance:182.62m (Euclidean)
[2025-03-07 13:59:04,551] [INFO] [30105] Received COMMIT: id:1741323542381, from:30027, delay:0.0000s, distance:149.87m (Euclidean)
[2025-03-07 13:59:04,584] [INFO] [30105] Received COMMIT: id:1741323542381, from:30007, delay:0.0000s, distance:170.12m (Euclidean)
[2025-03-07 13:59:04,715] [INFO] [30105] Received PREPARE: id:1741323542381, from:30110, delay:0.0001s, distance:258.19m (Euclidean)
[2025-03-07 13:59:04,715] [INFO] [30105] Missing PRE-PREPARE for REQUEST 1741323542381; ignoring PREPARE
[2025-03-07 13:59:04,736] [INFO] [30105] Received COMMIT: id:1741323542381, from:30065, delay:0.0001s, distance:197.35m (Euclidean)
[2025-03-07 13:59:04,753] [INFO] [30105] Received PREPARE: id:1741323542381, from:30176, delay:0.0000s, distance:144.87m (Euclidean)
[2025-03-07 13:59:04,753] [INFO] [30105] Missing PRE-PREPARE for REQUEST 1741323542381; ignoring PREPARE
[2025-03-07 13:59:04,753] [INFO] [30105] Received COMMIT: id:1741323542381, from:30176, delay:0.0000s, distance:144.87m (Euclidean)
[2025-03-07 13:59:04,801] [INFO] [30105] Received PREPARE: id:1741323542381, from:30004, delay:0.0000s, distance:166.37m (Euclidean)
[2025-03-07 13:59:04,801] [INFO] [30105] Missing PRE-PREPARE for REQUEST 1741323542381; ignoring PREPARE
[2025-03-07 13:59:04,810] [INFO] [30105] Received PREPARE: id:1741323542381, from:30053, delay:0.0000s, distance:139.75m (Euclidean)
[2025-03-07 13:59:04,810] [INFO] [30105] Missing PRE-PREPARE for REQUEST 1741323542381; ignoring PREPARE
[2025-03-07 13:59:04,833] [INFO] [30105] Received PREPARE: id:1741323542381, from:30150, delay:0.0001s, distance:233.84m (Euclidean)
[2025-03-07 13:59:04,833] [INFO] [30105] Missing PRE-PREPARE for REQUEST 1741323542381; ignoring PREPARE
[2025-03-07 13:59:04,834] [INFO] [30105] Received COMMIT: id:1741323542381, from:30150, delay:0.0001s, distance:233.84m (Euclidean)
[2025-03-07 13:59:04,944] [INFO] [30105] Received PREPARE: id:1741323542381, from:30161, delay:0.0000s, distance:176.54m (Euclidean)
[2025-03-07 13:59:04,944] [INFO] [30105] Missing PRE-PREPARE for REQUEST 1741323542381; ignoring PREPARE
[2025-03-07 13:59:04,948] [INFO] [30105] Received COMMIT: id:1741323542381, from:30095, delay:0.0001s, distance:194.30m (Euclidean)
[2025-03-07 13:59:04,961] [INFO] [30105] Received PREPARE: id:1741323542381, from:30158, delay:0.0002s, distance:295.60m (Euclidean)
[2025-03-07 13:59:04,961] [INFO] [30105] Missing PRE-PREPARE for REQUEST 1741323542381; ignoring PREPARE
[2025-03-07 13:59:04,965] [INFO] [30105] Received COMMIT: id:1741323542381, from:30158, delay:0.0002s, distance:295.60m (Euclidean)
[2025-03-07 13:59:05,046] [INFO] [30105] Received COMMIT: id:1741323542381, from:30004, delay:0.0000s, distance:166.37m (Euclidean)
[2025-03-07 13:59:05,056] [INFO] [30105] Received PREPARE: id:1741323542381, from:30170, delay:0.0001s, distance:229.47m (Euclidean)
[2025-03-07 13:59:05,056] [INFO] [30105] Missing PRE-PREPARE for REQUEST 1741323542381; ignoring PREPARE
[2025-03-07 13:59:05,076] [INFO] [30105] Received PREPARE: id:1741323542381, from:30060, delay:0.0000s, distance:95.86m (Euclidean)
[2025-03-07 13:59:05,076] [INFO] [30105] Missing PRE-PREPARE for REQUEST 1741323542381; ignoring PREPARE
[2025-03-07 13:59:05,156] [INFO] [30105] Received PREPARE: id:1741323542381, from:30181, delay:0.0000s, distance:107.68m (Euclidean)
[2025-03-07 13:59:05,156] [INFO] [30105] Missing PRE-PREPARE for REQUEST 1741323542381; ignoring PREPARE
[2025-03-07 13:59:05,178] [INFO] [30105] Received COMMIT: id:1741323542381, from:30025, delay:0.0001s, distance:183.47m (Euclidean)
[2025-03-07 13:59:05,186] [INFO] [30105] Received PREPARE: id:1741323542381, from:30126, delay:0.0002s, distance:255.95m (Euclidean)
[2025-03-07 13:59:05,186] [INFO] [30105] Missing PRE-PREPARE for REQUEST 1741323542381; ignoring PREPARE
[2025-03-07 13:59:05,186] [INFO] [30105] Received COMMIT: id:1741323542381, from:30126, delay:0.0002s, distance:255.95m (Euclidean)
[2025-03-07 13:59:05,268] [INFO] [30105] Received PREPARE: id:1741323542381, from:30066, delay:0.0000s, distance:188.89m (Euclidean)
[2025-03-07 13:59:05,268] [INFO] [30105] Missing PRE-PREPARE for REQUEST 1741323542381; ignoring PREPARE
[2025-03-07 13:59:05,290] [INFO] [30105] Received PREPARE: id:1741323542381, from:30013, delay:0.0001s, distance:185.71m (Euclidean)
[2025-03-07 13:59:05,290] [INFO] [30105] Missing PRE-PREPARE for REQUEST 1741323542381; ignoring PREPARE
[2025-03-07 13:59:05,302] [INFO] [30105] Received PREPARE: id:1741323542381, from:30195, delay:0.0001s, distance:186.95m (Euclidean)
[2025-03-07 13:59:05,302] [INFO] [30105] Missing PRE-PREPARE for REQUEST 1741323542381; ignoring PREPARE
[2025-03-07 13:59:05,304] [INFO] [30105] Received COMMIT: id:1741323542381, from:30195, delay:0.0001s, distance:186.95m (Euclidean)
[2025-03-07 13:59:05,376] [INFO] [30105] Received PREPARE: id:1741323542381, from:30174, delay:0.0001s, distance:204.83m (Euclidean)
[2025-03-07 13:59:05,376] [INFO] [30105] Missing PRE-PREPARE for REQUEST 1741323542381; ignoring PREPARE
[2025-03-07 13:59:05,413] [INFO] [30105] Received COMMIT: id:1741323542381, from:30106, delay:0.0000s, distance:50.90m (Euclidean)
[2025-03-07 13:59:05,431] [INFO] [30105] Received COMMIT: id:1741323542381, from:30147, delay:0.0002s, distance:294.92m (Euclidean)
[2025-03-07 13:59:05,749] [INFO] [30105] Received COMMIT: id:1741323542381, from:30053, delay:0.0000s, distance:139.75m (Euclidean)
[2025-03-07 13:59:05,772] [INFO] [30105] Received COMMIT: id:1741323542381, from:30015, delay:0.0000s, distance:194.24m (Euclidean)
[2025-03-07 13:59:05,930] [INFO] [30105] Received COMMIT: id:1741323542381, from:30108, delay:0.0000s, distance:125.28m (Euclidean)
[2025-03-07 13:59:05,930] [INFO] [30105] Received COMMIT: id:1741323542381, from:30118, delay:0.0000s, distance:131.80m (Euclidean)
[2025-03-07 13:59:05,930] [INFO] [30105] Received PREPARE: id:1741323542381, from:30063, delay:0.0001s, distance:208.16m (Euclidean)
[2025-03-07 13:59:05,930] [INFO] [30105] Missing PRE-PREPARE for REQUEST 1741323542381; ignoring PREPARE
[2025-03-07 13:59:05,940] [INFO] [30105] Received PREPARE: id:1741323542381, from:30051, delay:0.0000s, distance:122.46m (Euclidean)
[2025-03-07 13:59:05,940] [INFO] [30105] Missing PRE-PREPARE for REQUEST 1741323542381; ignoring PREPARE
[2025-03-07 13:59:06,040] [INFO] [30105] Received PREPARE: id:1741323542381, from:30041, delay:0.0000s, distance:161.52m (Euclidean)
[2025-03-07 13:59:06,040] [INFO] [30105] Missing PRE-PREPARE for REQUEST 1741323542381; ignoring PREPARE
[2025-03-07 13:59:06,058] [INFO] [30105] Received PREPARE: id:1741323542381, from:30024, delay:0.0001s, distance:207.96m (Euclidean)
[2025-03-07 13:59:06,058] [INFO] [30105] Missing PRE-PREPARE for REQUEST 1741323542381; ignoring PREPARE
[2025-03-07 13:59:06,136] [INFO] [30105] Received PREPARE: id:1741323542381, from:30130, delay:0.0000s, distance:124.37m (Euclidean)
[2025-03-07 13:59:06,136] [INFO] [30105] Missing PRE-PREPARE for REQUEST 1741323542381; ignoring PREPARE
[2025-03-07 13:59:06,136] [INFO] [30105] Received PREPARE: id:1741323542381, from:30037, delay:0.0002s, distance:284.28m (Euclidean)
[2025-03-07 13:59:06,136] [INFO] [30105] Missing PRE-PREPARE for REQUEST 1741323542381; ignoring PREPARE
[2025-03-07 13:59:06,136] [INFO] [30105] Received PREPARE: id:1741323542381, from:30144, delay:0.0002s, distance:277.51m (Euclidean)
[2025-03-07 13:59:06,136] [INFO] [30105] Missing PRE-PREPARE for REQUEST 1741323542381; ignoring PREPARE
[2025-03-07 13:59:06,136] [INFO] [30105] Received COMMIT: id:1741323542381, from:30066, delay:0.0000s, distance:188.89m (Euclidean)
[2025-03-07 13:59:06,138] [INFO] [30105] Received COMMIT: id:1741323542381, from:30110, delay:0.0001s, distance:258.19m (Euclidean)
[2025-03-07 13:59:06,138] [INFO] [30105] Received PREPARE: id:1741323542381, from:30029, delay:0.0002s, distance:296.28m (Euclidean)
[2025-03-07 13:59:06,138] [INFO] [30105] Missing PRE-PREPARE for REQUEST 1741323542381; ignoring PREPARE
[2025-03-07 13:59:06,142] [INFO] [30105] Received COMMIT: id:1741323542381, from:30144, delay:0.0002s, distance:277.51m (Euclidean)
[2025-03-07 13:59:06,148] [INFO] [30105] Received PREPARE: id:1741323542381, from:30005, delay:0.0002s, distance:261.02m (Euclidean)
[2025-03-07 13:59:06,148] [INFO] [30105] Missing PRE-PREPARE for REQUEST 1741323542381; ignoring PREPARE
[2025-03-07 13:59:06,170] [INFO] [30105] Received PREPARE: id:1741323542381, from:30035, delay:0.0001s, distance:223.19m (Euclidean)
[2025-03-07 13:59:06,170] [INFO] [30105] Missing PRE-PREPARE for REQUEST 1741323542381; ignoring PREPARE
[2025-03-07 13:59:06,183] [INFO] [30105] Received COMMIT: id:1741323542381, from:30005, delay:0.0002s, distance:261.02m (Euclidean)
[2025-03-07 13:59:06,187] [INFO] [30105] Received COMMIT: id:1741323542381, from:30029, delay:0.0002s, distance:296.28m (Euclidean)
[2025-03-07 13:59:06,187] [INFO] [30105] Received COMMIT: id:1741323542381, from:30057, delay:0.0000s, distance:65.09m (Euclidean)
[2025-03-07 13:59:06,203] [INFO] [30105] Received COMMIT: id:1741323542381, from:30013, delay:0.0001s, distance:185.71m (Euclidean)
[2025-03-07 13:59:06,250] [INFO] [30105] Received COMMIT: id:1741323542381, from:30035, delay:0.0001s, distance:223.19m (Euclidean)
[2025-03-07 13:59:06,290] [INFO] [30105] Received COMMIT: id:1741323542381, from:30161, delay:0.0000s, distance:176.54m (Euclidean)
[2025-03-07 13:59:06,314] [INFO] [30105] Received COMMIT: id:1741323542381, from:30130, delay:0.0000s, distance:124.37m (Euclidean)
[2025-03-07 13:59:06,329] [INFO] [30105] Received PREPARE: id:1741323542381, from:30171, delay:0.0000s, distance:143.45m (Euclidean)
[2025-03-07 13:59:06,329] [INFO] [30105] Missing PRE-PREPARE for REQUEST 1741323542381; ignoring PREPARE
[2025-03-07 13:59:06,345] [INFO] [30105] Received PREPARE: id:1741323542381, from:30023, delay:0.0000s, distance:136.01m (Euclidean)
[2025-03-07 13:59:06,345] [INFO] [30105] Missing PRE-PREPARE for REQUEST 1741323542381; ignoring PREPARE
[2025-03-07 13:59:06,361] [INFO] [30105] Received COMMIT: id:1741323542381, from:30171, delay:0.0000s, distance:143.45m (Euclidean)
[2025-03-07 13:59:06,417] [INFO] [30105] Received COMMIT: id:1741323542381, from:30170, delay:0.0001s, distance:229.47m (Euclidean)
[2025-03-07 13:59:06,422] [INFO] [30105] Received PREPARE: id:1741323542381, from:30085, delay:0.0000s, distance:170.86m (Euclidean)
[2025-03-07 13:59:06,422] [INFO] [30105] Missing PRE-PREPARE for REQUEST 1741323542381; ignoring PREPARE
[2025-03-07 13:59:06,424] [INFO] [30105] Received COMMIT: id:1741323542381, from:30060, delay:0.0000s, distance:95.86m (Euclidean)
[2025-03-07 13:59:06,424] [INFO] [30105] Received PREPARE: id:1741323542381, from:30154, delay:0.0001s, distance:218.27m (Euclidean)
[2025-03-07 13:59:06,424] [INFO] [30105] Missing PRE-PREPARE for REQUEST 1741323542381; ignoring PREPARE
[2025-03-07 13:59:06,424] [INFO] [30105] Received PREPARE: id:1741323542381, from:30199, delay:0.0002s, distance:275.87m (Euclidean)
[2025-03-07 13:59:06,424] [INFO] [30105] Missing PRE-PREPARE for REQUEST 1741323542381; ignoring PREPARE
[2025-03-07 13:59:06,433] [INFO] [30105] Received COMMIT: id:1741323542381, from:30023, delay:0.0000s, distance:136.01m (Euclidean)
[2025-03-07 13:59:06,450] [INFO] [30105] Received COMMIT: id:1741323542381, from:30154, delay:0.0001s, distance:218.27m (Euclidean)
[2025-03-07 13:59:06,486] [INFO] [30105] Received COMMIT: id:1741323542381, from:30028, delay:0.0002s, distance:258.79m (Euclidean)
[2025-03-07 13:59:06,594] [INFO] [30105] Received COMMIT: id:1741323542381, from:30037, delay:0.0002s, distance:284.28m (Euclidean)
[2025-03-07 13:59:06,660] [INFO] [30105] Received PREPARE: id:1741323542381, from:30177, delay:0.0001s, distance:226.92m (Euclidean)
[2025-03-07 13:59:06,660] [INFO] [30105] Missing PRE-PREPARE for REQUEST 1741323542381; ignoring PREPARE
[2025-03-07 13:59:06,688] [INFO] [30105] Received COMMIT: id:1741323542381, from:30181, delay:0.0000s, distance:107.68m (Euclidean)
[2025-03-07 13:59:06,825] [INFO] [30105] Received COMMIT: id:1741323542381, from:30115, delay:0.0001s, distance:153.79m (Euclidean)
[2025-03-07 13:59:06,842] [INFO] [30105] Received PREPARE: id:1741323542381, from:30096, delay:0.0001s, distance:244.02m (Euclidean)
[2025-03-07 13:59:06,842] [INFO] [30105] Missing PRE-PREPARE for REQUEST 1741323542381; ignoring PREPARE
[2025-03-07 13:59:06,847] [INFO] [30105] Received PREPARE: id:1741323542381, from:30175, delay:0.0001s, distance:203.45m (Euclidean)
[2025-03-07 13:59:06,847] [INFO] [30105] Missing PRE-PREPARE for REQUEST 1741323542381; ignoring PREPARE
[2025-03-07 13:59:06,849] [INFO] [30105] Received PREPARE: id:1741323542381, from:30056, delay:0.0002s, distance:252.44m (Euclidean)
[2025-03-07 13:59:06,849] [INFO] [30105] Missing PRE-PREPARE for REQUEST 1741323542381; ignoring PREPARE
[2025-03-07 13:59:06,949] [INFO] [30105] Received PREPARE: id:1741323542381, from:30092, delay:0.0001s, distance:213.43m (Euclidean)
[2025-03-07 13:59:06,949] [INFO] [30105] Missing PRE-PREPARE for REQUEST 1741323542381; ignoring PREPARE
[2025-03-07 13:59:06,991] [INFO] [30105] Received COMMIT: id:1741323542381, from:30041, delay:0.0000s, distance:161.52m (Euclidean)
[2025-03-07 13:59:07,033] [INFO] [30105] Received PREPARE: id:1741323542381, from:30049, delay:0.0000s, distance:148.67m (Euclidean)
[2025-03-07 13:59:07,033] [INFO] [30105] Missing PRE-PREPARE for REQUEST 1741323542381; ignoring PREPARE
[2025-03-07 13:59:07,035] [INFO] [30105] Received COMMIT: id:1741323542381, from:30049, delay:0.0000s, distance:148.67m (Euclidean)
[2025-03-07 13:59:07,038] [INFO] [30105] Received COMMIT: id:1741323542381, from:30196, delay:0.0001s, distance:196.49m (Euclidean)
[2025-03-07 13:59:07,107] [INFO] [30105] Received COMMIT: id:1741323542381, from:30085, delay:0.0000s, distance:170.86m (Euclidean)
[2025-03-07 13:59:07,212] [INFO] [30105] Received COMMIT: id:1741323542381, from:30051, delay:0.0000s, distance:122.46m (Euclidean)
[2025-03-07 13:59:07,242] [INFO] [30105] Received COMMIT: id:1741323542381, from:30149, delay:0.0000s, distance:172.00m (Euclidean)
[2025-03-07 13:59:07,316] [INFO] [30105] Received PREPARE: id:1741323542381, from:30136, delay:0.0002s, distance:279.44m (Euclidean)
[2025-03-07 13:59:07,316] [INFO] [30105] Missing PRE-PREPARE for REQUEST 1741323542381; ignoring PREPARE
[2025-03-07 13:59:07,377] [INFO] [30105] Received PREPARE: id:1741323542381, from:30191, delay:0.0002s, distance:255.72m (Euclidean)
[2025-03-07 13:59:07,377] [INFO] [30105] Missing PRE-PREPARE for REQUEST 1741323542381; ignoring PREPARE
[2025-03-07 13:59:07,384] [INFO] [30105] Received PREPARE: id:1741323542381, from:30129, delay:0.0000s, distance:124.63m (Euclidean)
[2025-03-07 13:59:07,384] [INFO] [30105] Missing PRE-PREPARE for REQUEST 1741323542381; ignoring PREPARE
[2025-03-07 13:59:07,415] [INFO] [30105] Received COMMIT: id:1741323542381, from:30175, delay:0.0001s, distance:203.45m (Euclidean)
[2025-03-07 13:59:07,494] [INFO] [30105] Received COMMIT: id:1741323542381, from:30092, delay:0.0001s, distance:213.43m (Euclidean)
[2025-03-07 13:59:07,524] [INFO] [30105] Received COMMIT: id:1741323542381, from:30136, delay:0.0002s, distance:279.44m (Euclidean)
[2025-03-07 13:59:07,547] [INFO] [30105] Received COMMIT: id:1741323542381, from:30129, delay:0.0000s, distance:124.63m (Euclidean)
[2025-03-07 13:59:07,557] [INFO] [30105] Received COMMIT: id:1741323542381, from:30056, delay:0.0002s, distance:252.44m (Euclidean)
[2025-03-07 13:59:07,652] [INFO] [30105] Received PREPARE: id:1741323542381, from:30102, delay:0.0001s, distance:231.94m (Euclidean)
[2025-03-07 13:59:07,652] [INFO] [30105] Missing PRE-PREPARE for REQUEST 1741323542381; ignoring PREPARE
[2025-03-07 13:59:07,652] [INFO] [30105] Received COMMIT: id:1741323542381, from:30102, delay:0.0001s, distance:231.94m (Euclidean)
[2025-03-07 13:59:07,685] [INFO] [30105] Received PREPARE: id:1741323542381, from:30124, delay:0.0002s, distance:266.99m (Euclidean)
[2025-03-07 13:59:07,685] [INFO] [30105] Missing PRE-PREPARE for REQUEST 1741323542381; ignoring PREPARE
[2025-03-07 13:59:07,850] [INFO] [30105] Received COMMIT: id:1741323542381, from:30174, delay:0.0001s, distance:204.83m (Euclidean)
[2025-03-07 13:59:07,894] [INFO] [30105] Received COMMIT: id:1741323542381, from:30096, delay:0.0001s, distance:244.02m (Euclidean)
[2025-03-07 13:59:08,109] [INFO] [30105] Received COMMIT: id:1741323542381, from:30199, delay:0.0002s, distance:275.87m (Euclidean)
[2025-03-07 13:59:08,174] [INFO] [30105] Received COMMIT: id:1741323542381, from:30089, delay:0.0000s, distance:67.41m (Euclidean)
[2025-03-07 13:59:08,335] [INFO] [30105] Received COMMIT: id:1741323542381, from:30124, delay:0.0002s, distance:266.99m (Euclidean)
[2025-03-07 13:59:08,337] [INFO] [30105] Received COMMIT: id:1741323542381, from:30133, delay:0.0001s, distance:224.37m (Euclidean)
[2025-03-07 13:59:08,347] [INFO] [30105] Received PREPARE: id:1741323542381, from:30119, delay:0.0002s, distance:293.89m (Euclidean)
[2025-03-07 13:59:08,347] [INFO] [30105] Missing PRE-PREPARE for REQUEST 1741323542381; ignoring PREPARE
[2025-03-07 13:59:08,347] [INFO] [30105] Received COMMIT: id:1741323542381, from:30168, delay:0.0000s, distance:145.07m (Euclidean)
[2025-03-07 13:59:08,371] [INFO] [30105] Received COMMIT: id:1741323542381, from:30119, delay:0.0002s, distance:293.89m (Euclidean)
[2025-03-07 13:59:08,485] [INFO] [30105] Received COMMIT: id:1741323542381, from:30177, delay:0.0001s, distance:226.92m (Euclidean)
[2025-03-07 13:59:08,697] [INFO] [30105] Received COMMIT: id:1741323542381, from:30123, delay:0.0000s, distance:148.29m (Euclidean)
[2025-03-07 13:59:08,697] [INFO] [30105] Received PREPARE: id:1741323542381, from:30046, delay:0.0000s, distance:136.49m (Euclidean)
[2025-03-07 13:59:08,697] [INFO] [30105] Missing PRE-PREPARE for REQUEST 1741323542381; ignoring PREPARE
[2025-03-07 13:59:08,697] [INFO] [30105] Received COMMIT: id:1741323542381, from:30046, delay:0.0000s, distance:136.49m (Euclidean)
[2025-03-07 13:59:08,760] [INFO] [30105] Received COMMIT: id:1741323542381, from:30024, delay:0.0001s, distance:207.96m (Euclidean)
[2025-03-07 13:59:08,822] [INFO] [30105] Received COMMIT: id:1741323542381, from:30191, delay:0.0002s, distance:255.72m (Euclidean)
[2025-03-07 13:59:08,842] [INFO] [30105] Received PREPARE: id:1741323542381, from:30182, delay:0.0002s, distance:253.74m (Euclidean)
[2025-03-07 13:59:08,842] [INFO] [30105] Missing PRE-PREPARE for REQUEST 1741323542381; ignoring PREPARE
[2025-03-07 13:59:08,966] [INFO] [30105] Received PREPARE: id:1741323542381, from:30120, delay:0.0001s, distance:191.83m (Euclidean)
[2025-03-07 13:59:08,968] [INFO] [30105] Missing PRE-PREPARE for REQUEST 1741323542381; ignoring PREPARE
[2025-03-07 13:59:09,075] [INFO] [30105] Received COMMIT: id:1741323542381, from:30063, delay:0.0001s, distance:208.16m (Euclidean)
[2025-03-07 13:59:09,102] [INFO] [30105] Received COMMIT: id:1741323542381, from:30120, delay:0.0001s, distance:191.83m (Euclidean)
[2025-03-07 13:59:09,122] [INFO] [30105] Received PREPARE: id:1741323542381, from:30059, delay:0.0001s, distance:180.77m (Euclidean)
[2025-03-07 13:59:09,122] [INFO] [30105] Missing PRE-PREPARE for REQUEST 1741323542381; ignoring PREPARE
[2025-03-07 13:59:09,122] [INFO] [30105] Received COMMIT: id:1741323542381, from:30059, delay:0.0001s, distance:180.77m (Euclidean)
[2025-03-07 13:59:09,305] [INFO] [30105] Received PREPARE: id:1741323542381, from:30116, delay:0.0000s, distance:194.73m (Euclidean)
[2025-03-07 13:59:09,305] [INFO] [30105] Missing PRE-PREPARE for REQUEST 1741323542381; ignoring PREPARE
[2025-03-07 13:59:09,305] [INFO] [30105] Received COMMIT: id:1741323542381, from:30116, delay:0.0000s, distance:194.73m (Euclidean)
[2025-03-07 13:59:09,569] [INFO] [30105] Received COMMIT: id:1741323542381, from:30182, delay:0.0002s, distance:253.74m (Euclidean)
[2025-03-07 13:59:09,645] [INFO] [30105] Received PREPARE: id:1741323542381, from:30090, delay:0.0001s, distance:265.07m (Euclidean)
[2025-03-07 13:59:09,645] [INFO] [30105] Missing PRE-PREPARE for REQUEST 1741323542381; ignoring PREPARE
[2025-03-07 13:59:09,647] [INFO] [30105] Received COMMIT: id:1741323542381, from:30090, delay:0.0001s, distance:265.07m (Euclidean)
[2025-03-07 13:59:09,774] [INFO] [30105] Received PREPARE: id:1741323542381, from:30021, delay:0.0001s, distance:222.27m (Euclidean)
[2025-03-07 13:59:09,774] [INFO] [30105] Missing PRE-PREPARE for REQUEST 1741323542381; ignoring PREPARE
[2025-03-07 13:59:09,779] [INFO] [30105] Received COMMIT: id:1741323542381, from:30021, delay:0.0001s, distance:222.27m (Euclidean)
[2025-03-07 13:59:10,303] [INFO] [30105] Received PREPARE: id:1741323542381, from:30093, delay:0.0001s, distance:155.31m (Euclidean)
[2025-03-07 13:59:10,303] [INFO] [30105] Missing PRE-PREPARE for REQUEST 1741323542381; ignoring PREPARE
[2025-03-07 13:59:10,303] [INFO] [30105] Received COMMIT: id:1741323542381, from:30093, delay:0.0001s, distance:155.31m (Euclidean)
[2025-03-07 13:59:10,439] [INFO] [30105] Received PREPARE: id:1741323542381, from:30100, delay:0.0002s, distance:287.66m (Euclidean)
[2025-03-07 13:59:10,439] [INFO] [30105] Missing PRE-PREPARE for REQUEST 1741323542381; ignoring PREPARE
[2025-03-07 13:59:10,439] [INFO] [30105] Received COMMIT: id:1741323542381, from:30100, delay:0.0002s, distance:287.66m (Euclidean)
[2025-03-07 13:59:10,562] [INFO] [30105] Received PREPARE: id:1741323542381, from:30178, delay:0.0001s, distance:230.16m (Euclidean)
[2025-03-07 13:59:10,562] [INFO] [30105] Missing PRE-PREPARE for REQUEST 1741323542381; ignoring PREPARE
[2025-03-07 13:59:10,565] [INFO] [30105] Received COMMIT: id:1741323542381, from:30178, delay:0.0001s, distance:230.16m (Euclidean)
[2025-03-07 13:59:10,592] [INFO] [30105] Received PREPARE: id:1741323542381, from:30111, delay:0.0000s, distance:192.54m (Euclidean)
[2025-03-07 13:59:10,592] [INFO] [30105] Missing PRE-PREPARE for REQUEST 1741323542381; ignoring PREPARE
[2025-03-07 13:59:10,592] [INFO] [30105] Received COMMIT: id:1741323542381, from:30111, delay:0.0000s, distance:192.54m (Euclidean)
[2025-03-07 13:59:10,671] [INFO] [30105] Received PREPARE: id:1741323542381, from:30098, delay:0.0001s, distance:217.15m (Euclidean)
[2025-03-07 13:59:10,671] [INFO] [30105] Missing PRE-PREPARE for REQUEST 1741323542381; ignoring PREPARE
[2025-03-07 13:59:10,673] [INFO] [30105] Received COMMIT: id:1741323542381, from:30098, delay:0.0001s, distance:217.15m (Euclidean)
[2025-03-07 13:59:10,835] [INFO] [30105] Received PREPARE: id:1741323542381, from:30076, delay:0.0001s, distance:206.28m (Euclidean)
[2025-03-07 13:59:10,835] [INFO] [30105] Missing PRE-PREPARE for REQUEST 1741323542381; ignoring PREPARE
[2025-03-07 13:59:10,837] [INFO] [30105] Received COMMIT: id:1741323542381, from:30076, delay:0.0001s, distance:206.28m (Euclidean)
[2025-03-07 13:59:10,858] [INFO] [30105] Received PREPARE: id:1741323542381, from:30040, delay:0.0001s, distance:202.55m (Euclidean)
[2025-03-07 13:59:10,858] [INFO] [30105] Missing PRE-PREPARE for REQUEST 1741323542381; ignoring PREPARE
[2025-03-07 13:59:10,858] [INFO] [30105] Received COMMIT: id:1741323542381, from:30040, delay:0.0001s, distance:202.55m (Euclidean)
[2025-03-07 13:59:11,173] [INFO] [30105] Received PREPARE: id:1741323542381, from:30070, delay:0.0001s, distance:156.51m (Euclidean)
[2025-03-07 13:59:11,173] [INFO] [30105] Missing PRE-PREPARE for REQUEST 1741323542381; ignoring PREPARE
[2025-03-07 13:59:11,173] [INFO] [30105] Received COMMIT: id:1741323542381, from:30070, delay:0.0001s, distance:156.51m (Euclidean)
[2025-03-07 13:59:11,186] [INFO] [30105] Received PREPARE: id:1741323542381, from:30054, delay:0.0001s, distance:165.49m (Euclidean)
[2025-03-07 13:59:11,186] [INFO] [30105] Missing PRE-PREPARE for REQUEST 1741323542381; ignoring PREPARE
[2025-03-07 13:59:11,186] [INFO] [30105] Received COMMIT: id:1741323542381, from:30054, delay:0.0001s, distance:165.49m (Euclidean)
[2025-03-07 13:59:11,380] [INFO] [30105] Received PREPARE: id:1741323542381, from:30020, delay:0.0002s, distance:265.74m (Euclidean)
[2025-03-07 13:59:11,380] [INFO] [30105] Missing PRE-PREPARE for REQUEST 1741323542381; ignoring PREPARE
[2025-03-07 13:59:11,380] [INFO] [30105] Received PREPARE: id:1741323542381, from:30074, delay:0.0002s, distance:267.84m (Euclidean)
[2025-03-07 13:59:11,380] [INFO] [30105] Missing PRE-PREPARE for REQUEST 1741323542381; ignoring PREPARE
[2025-03-07 13:59:11,380] [INFO] [30105] Received COMMIT: id:1741323542381, from:30020, delay:0.0002s, distance:265.74m (Euclidean)
[2025-03-07 13:59:11,380] [INFO] [30105] Received COMMIT: id:1741323542381, from:30074, delay:0.0002s, distance:267.84m (Euclidean)
[2025-03-07 13:59:11,655] [INFO] [30105] Received PREPARE: id:1741323542381, from:30121, delay:0.0001s, distance:179.85m (Euclidean)
[2025-03-07 13:59:11,655] [INFO] [30105] Missing PRE-PREPARE for REQUEST 1741323542381; ignoring PREPARE
[2025-03-07 13:59:11,671] [INFO] [30105] Received COMMIT: id:1741323542381, from:30121, delay:0.0001s, distance:179.85m (Euclidean)
[2025-03-07 13:59:11,734] [INFO] [30105] Received PREPARE: id:1741323542381, from:30113, delay:0.0001s, distance:203.74m (Euclidean)
[2025-03-07 13:59:11,734] [INFO] [30105] Missing PRE-PREPARE for REQUEST 1741323542381; ignoring PREPARE
[2025-03-07 13:59:11,734] [INFO] [30105] Received COMMIT: id:1741323542381, from:30113, delay:0.0001s, distance:203.74m (Euclidean)
[2025-03-07 13:59:11,796] [INFO] [30105] Received PREPARE: id:1741323542381, from:30048, delay:0.0001s, distance:247.38m (Euclidean)
[2025-03-07 13:59:11,796] [INFO] [30105] Missing PRE-PREPARE for REQUEST 1741323542381; ignoring PREPARE
[2025-03-07 13:59:11,796] [INFO] [30105] Received COMMIT: id:1741323542381, from:30048, delay:0.0001s, distance:247.38m (Euclidean)
[2025-03-07 13:59:11,928] [INFO] [30105] Received PREPARE: id:1741323542381, from:30137, delay:0.0000s, distance:150.87m (Euclidean)
[2025-03-07 13:59:11,928] [INFO] [30105] Missing PRE-PREPARE for REQUEST 1741323542381; ignoring PREPARE
[2025-03-07 13:59:11,940] [INFO] [30105] Received PREPARE: id:1741323542381, from:30061, delay:0.0000s, distance:80.87m (Euclidean)
[2025-03-07 13:59:11,944] [INFO] [30105] Missing PRE-PREPARE for REQUEST 1741323542381; ignoring PREPARE
[2025-03-07 13:59:12,528] [INFO] [30105] Received PREPARE: id:1741323542381, from:30043, delay:0.0000s, distance:174.29m (Euclidean)
[2025-03-07 13:59:12,528] [INFO] [30105] Missing PRE-PREPARE for REQUEST 1741323542381; ignoring PREPARE
[2025-03-07 13:59:12,560] [INFO] [30105] Received COMMIT: id:1741323542381, from:30043, delay:0.0000s, distance:174.29m (Euclidean)
[2025-03-07 13:59:12,580] [INFO] [30105] Received PREPARE: id:1741323542381, from:30103, delay:0.0001s, distance:231.91m (Euclidean)
[2025-03-07 13:59:12,580] [INFO] [30105] Missing PRE-PREPARE for REQUEST 1741323542381; ignoring PREPARE
[2025-03-07 13:59:12,580] [INFO] [30105] Received COMMIT: id:1741323542381, from:30103, delay:0.0001s, distance:231.91m (Euclidean)
[2025-03-07 13:59:12,795] [INFO] [30105] Received PREPARE: id:1741323542381, from:30011, delay:0.0001s, distance:226.11m (Euclidean)
[2025-03-07 13:59:12,795] [INFO] [30105] Missing PRE-PREPARE for REQUEST 1741323542381; ignoring PREPARE
[2025-03-07 13:59:12,808] [INFO] [30105] Received COMMIT: id:1741323542381, from:30011, delay:0.0001s, distance:226.11m (Euclidean)
[2025-03-07 13:59:12,890] [INFO] [30105] Received PRE-PREPARE: id:1741323542381, from:Leader(30000), delay:0.0001s, distance:216.03m (Euclidean)
[2025-03-07 13:59:12,890] [INFO] [30105] Broadcasting PREPARE for REQUEST 1741323542381
[2025-03-07 13:59:12,903] [INFO] [30105] Not broadcasting to fault node: 30077
[2025-03-07 13:59:12,915] [INFO] [30105] Not broadcasting to fault node: 30184
[2025-03-07 13:59:12,965] [INFO] [30105] Received COMMIT: id:1741323542381, from:30000, delay:0.0001s, distance:216.03m (Euclidean)
[2025-03-07 13:59:13,211] [INFO] [30105] Received PREPARE: id:1741323542381, from:30073, delay:0.0000s, distance:249.93m (Euclidean)
[2025-03-07 13:59:13,211] [INFO] [30105] Broadcasting COMMIT for REQUEST 1741323542381
[2025-03-07 13:59:13,220] [INFO] [30105] Not broadcasting to fault node: 30077
[2025-03-07 13:59:13,241] [INFO] [30105] Not broadcasting to fault node: 30184
[2025-03-07 13:59:13,327] [INFO] [30105] Received COMMIT: id:1741323542381, from:30073, delay:0.0000s, distance:249.93m (Euclidean)
[2025-03-07 13:59:13,465] [INFO] [30105] Received COMMIT: id:1741323542381, from:30137, delay:0.0000s, distance:150.87m (Euclidean)
[2025-03-07 13:59:13,767] [INFO] [30105] Received PREPARE: id:1741323542381, from:30165, delay:0.0000s, distance:118.74m (Euclidean)
[2025-03-07 13:59:13,782] [INFO] [30105] Received PREPARE: id:1741323542381, from:30132, delay:0.0000s, distance:104.67m (Euclidean)
[2025-03-07 13:59:13,854] [INFO] [30105] Received PREPARE: id:1741323542381, from:30122, delay:0.0000s, distance:129.20m (Euclidean)
[2025-03-07 13:59:13,854] [INFO] [30105] Received COMMIT: id:1741323542381, from:30122, delay:0.0000s, distance:129.20m (Euclidean)
[2025-03-07 13:59:14,023] [INFO] [30105] Received PREPARE: id:1741323542381, from:30198, delay:0.0001s, distance:160.91m (Euclidean)
[2025-03-07 13:59:14,264] [INFO] [30105] Received COMMIT: id:1741323542381, from:30165, delay:0.0000s, distance:118.74m (Euclidean)
[2025-03-07 13:59:14,273] [INFO] [30105] Received PREPARE: id:1741323542381, from:30104, delay:0.0000s, distance:80.29m (Euclidean)
[2025-03-07 13:59:14,360] [INFO] [30105] Received PREPARE: id:1741323542381, from:30016, delay:0.0000s, distance:72.27m (Euclidean)
[2025-03-07 13:59:14,365] [INFO] [30105] Received COMMIT: id:1741323542381, from:30016, delay:0.0000s, distance:72.27m (Euclidean)
[2025-03-07 13:59:14,728] [INFO] [30105] Received PREPARE: id:1741323542381, from:30034, delay:0.0000s, distance:187.14m (Euclidean)
[2025-03-07 13:59:14,728] [INFO] [30105] Received COMMIT: id:1741323542381, from:30034, delay:0.0000s, distance:187.14m (Euclidean)
[2025-03-07 13:59:15,065] [INFO] [30105] Received PREPARE: id:1741323542381, from:30006, delay:0.0002s, distance:268.91m (Euclidean)
[2025-03-07 13:59:15,065] [INFO] [30105] Received COMMIT: id:1741323542381, from:30006, delay:0.0002s, distance:268.91m (Euclidean)
[2025-03-07 13:59:15,137] [INFO] [30105] Received PREPARE: id:1741323542381, from:30036, delay:0.0000s, distance:147.67m (Euclidean)
[2025-03-07 13:59:15,209] [INFO] [30105] Received PREPARE: id:1741323542381, from:30081, delay:0.0001s, distance:182.12m (Euclidean)
[2025-03-07 13:59:15,209] [INFO] [30105] Received COMMIT: id:1741323542381, from:30081, delay:0.0001s, distance:182.12m (Euclidean)
[2025-03-07 13:59:15,381] [INFO] [30105] Received PREPARE: id:1741323542381, from:30087, delay:0.0000s, distance:142.59m (Euclidean)
[2025-03-07 13:59:15,381] [INFO] [30105] Received COMMIT: id:1741323542381, from:30087, delay:0.0000s, distance:142.59m (Euclidean)
[2025-03-07 13:59:15,569] [INFO] [30105] Received PREPARE: id:1741323542381, from:30114, delay:0.0000s, distance:113.75m (Euclidean)
[2025-03-07 13:59:15,629] [INFO] [30105] Received PREPARE: id:1741323542381, from:30001, delay:0.0000s, distance:133.37m (Euclidean)
[2025-03-07 13:59:15,677] [INFO] [30105] Received COMMIT: id:1741323542381, from:30036, delay:0.0000s, distance:147.67m (Euclidean)
[2025-03-07 13:59:15,865] [INFO] [30105] Received COMMIT: id:1741323542381, from:30114, delay:0.0000s, distance:113.75m (Euclidean)
[2025-03-07 13:59:16,169] [INFO] [30105] Received COMMIT: id:1741323542381, from:30091, delay:0.0001s, distance:247.34m (Euclidean)
[2025-03-07 13:59:16,169] [INFO] [30105] Received PREPARE: id:1741323542381, from:30091, delay:0.0001s, distance:247.34m (Euclidean)
[2025-03-07 13:59:16,573] [INFO] [30105] Received COMMIT: id:1741323542381, from:30061, delay:0.0000s, distance:80.87m (Euclidean)
[2025-03-07 13:59:16,651] [INFO] [30105] Received PREPARE: id:1741323542381, from:30160, delay:0.0001s, distance:240.21m (Euclidean)
[2025-03-07 13:59:16,750] [INFO] [30105] Received COMMIT: id:1741323542381, from:30198, delay:0.0001s, distance:160.91m (Euclidean)
[2025-03-07 13:59:16,780] [INFO] [30105] Received PREPARE: id:1741323542381, from:30038, delay:0.0000s, distance:53.98m (Euclidean)
[2025-03-07 13:59:16,846] [INFO] [30105] Received PREPARE: id:1741323542381, from:30042, delay:0.0000s, distance:161.06m (Euclidean)
[2025-03-07 13:59:16,860] [INFO] [30105] Received COMMIT: id:1741323542381, from:30042, delay:0.0000s, distance:161.06m (Euclidean)
[2025-03-07 13:59:16,922] [INFO] [30105] Received PREPARE: id:1741323542381, from:30026, delay:0.0002s, distance:293.00m (Euclidean)
[2025-03-07 13:59:16,922] [INFO] [30105] Received COMMIT: id:1741323542381, from:30026, delay:0.0002s, distance:293.00m (Euclidean)
[2025-03-07 13:59:16,922] [INFO] [30105] Received PREPARE: id:1741323542381, from:30064, delay:0.0002s, distance:255.86m (Euclidean)
[2025-03-07 13:59:16,922] [INFO] [30105] Received COMMIT: id:1741323542381, from:30064, delay:0.0002s, distance:255.86m (Euclidean)
[2025-03-07 13:59:16,936] [INFO] [30105] Received PREPARE: id:1741323542381, from:30052, delay:0.0001s, distance:164.21m (Euclidean)
[2025-03-07 13:59:16,964] [INFO] [30105] Received PREPARE: id:1741323542381, from:30193, delay:0.0002s, distance:271.80m (Euclidean)
[2025-03-07 13:59:16,965] [INFO] [30105] Received COMMIT: id:1741323542381, from:30193, delay:0.0002s, distance:271.80m (Euclidean)
[2025-03-07 13:59:16,985] [INFO] [30105] Received COMMIT: id:1741323542381, from:30132, delay:0.0000s, distance:104.67m (Euclidean)
[2025-03-07 13:59:16,995] [INFO] [30105] Received PREPARE: id:1741323542381, from:30145, delay:0.0001s, distance:246.86m (Euclidean)
[2025-03-07 13:59:16,997] [INFO] [30105] Received COMMIT: id:1741323542381, from:30145, delay:0.0001s, distance:246.86m (Euclidean)
[2025-03-07 13:59:17,009] [INFO] [30105] Received COMMIT: id:1741323542381, from:30052, delay:0.0001s, distance:164.21m (Euclidean)
[2025-03-07 13:59:17,059] [INFO] [30105] Received PREPARE: id:1741323542381, from:30142, delay:0.0000s, distance:126.08m (Euclidean)
[2025-03-07 13:59:17,059] [INFO] [30105] Received COMMIT: id:1741323542381, from:30142, delay:0.0000s, distance:126.08m (Euclidean)
[2025-03-07 13:59:17,140] [INFO] [30105] Received COMMIT: id:1741323542381, from:30160, delay:0.0001s, distance:240.21m (Euclidean)
[2025-03-07 13:59:17,432] [INFO] [30105] Received PREPARE: id:1741323542381, from:30079, delay:0.0001s, distance:156.74m (Euclidean)
[2025-03-07 13:59:17,493] [INFO] [30105] Received COMMIT: id:1741323542381, from:30001, delay:0.0000s, distance:133.37m (Euclidean)
[2025-03-07 13:59:17,769] [INFO] [30105] Received PREPARE: id:1741323542381, from:30055, delay:0.0001s, distance:203.09m (Euclidean)
[2025-03-07 13:59:17,769] [INFO] [30105] Received COMMIT: id:1741323542381, from:30055, delay:0.0001s, distance:203.09m (Euclidean)
[2025-03-07 13:59:18,335] [INFO] [30105] Received PREPARE: id:1741323542381, from:30008, delay:0.0000s, distance:157.91m (Euclidean)
[2025-03-07 13:59:18,335] [INFO] [30105] Received COMMIT: id:1741323542381, from:30008, delay:0.0000s, distance:157.91m (Euclidean)
[2025-03-07 13:59:18,417] [INFO] [30105] Received COMMIT: id:1741323542381, from:30038, delay:0.0000s, distance:53.98m (Euclidean)
[2025-03-07 13:59:18,660] [INFO] [30105] Received COMMIT: id:1741323542381, from:30079, delay:0.0001s, distance:156.74m (Euclidean)
[2025-03-07 13:59:18,793] [INFO] [30105] Received PREPARE: id:1741323542381, from:30141, delay:0.0001s, distance:234.78m (Euclidean)
[2025-03-07 13:59:18,855] [INFO] [30105] Received COMMIT: id:1741323542381, from:30141, delay:0.0001s, distance:234.78m (Euclidean)
[2025-03-07 13:59:19,357] [INFO] [30105] Received PREPARE: id:1741323542381, from:30138, delay:0.0001s, distance:157.01m (Euclidean)
[2025-03-07 13:59:19,357] [INFO] [30105] Received COMMIT: id:1741323542381, from:30138, delay:0.0001s, distance:157.01m (Euclidean)
[2025-03-07 13:59:19,587] [INFO] [30105] Received COMMIT: id:1741323542381, from:30058, delay:0.0001s, distance:243.37m (Euclidean)
[2025-03-07 13:59:19,587] [INFO] [30105] Received PREPARE: id:1741323542381, from:30058, delay:0.0001s, distance:243.37m (Euclidean)
[2025-03-07 13:59:19,732] [INFO] [30105] Received PREPARE: id:1741323542381, from:30010, delay:0.0001s, distance:204.30m (Euclidean)
[2025-03-07 13:59:19,732] [INFO] [30105] Received COMMIT: id:1741323542381, from:30010, delay:0.0001s, distance:204.30m (Euclidean)
[2025-03-07 13:59:19,936] [INFO] [30105] Received PREPARE: id:1741323542381, from:30131, delay:0.0001s, distance:230.48m (Euclidean)
[2025-03-07 13:59:19,938] [INFO] [30105] Received COMMIT: id:1741323542381, from:30131, delay:0.0001s, distance:230.48m (Euclidean)
[2025-03-07 13:59:20,416] [INFO] [30105] Received PREPARE: id:1741323542381, from:30143, delay:0.0000s, distance:99.83m (Euclidean)
[2025-03-07 13:59:20,416] [INFO] [30105] Received COMMIT: id:1741323542381, from:30143, delay:0.0000s, distance:99.83m (Euclidean)
[2025-03-07 13:59:20,546] [INFO] [30105] Received PREPARE: id:1741323542381, from:30083, delay:0.0001s, distance:163.74m (Euclidean)
[2025-03-07 13:59:20,548] [INFO] [30105] Received COMMIT: id:1741323542381, from:30083, delay:0.0001s, distance:163.74m (Euclidean)
[2025-03-07 13:59:20,869] [INFO] [30105] Received PREPARE: id:1741323542381, from:30194, delay:0.0002s, distance:250.58m (Euclidean)
[2025-03-07 13:59:20,869] [INFO] [30105] Received COMMIT: id:1741323542381, from:30194, delay:0.0002s, distance:250.58m (Euclidean)
[2025-03-07 13:59:20,943] [INFO] [30105] Received PREPARE: id:1741323542381, from:30031, delay:0.0001s, distance:213.80m (Euclidean)
[2025-03-07 13:59:20,943] [INFO] [30105] Received COMMIT: id:1741323542381, from:30031, delay:0.0001s, distance:213.80m (Euclidean)
[2025-03-07 13:59:21,177] [INFO] [30105] Received COMMIT: id:1741323542381, from:30050, delay:0.0002s, distance:298.59m (Euclidean)
[2025-03-07 13:59:21,177] [INFO] [30105] Received PREPARE: id:1741323542381, from:30050, delay:0.0002s, distance:298.59m (Euclidean)
[2025-03-07 13:59:21,214] [INFO] [30105] Received PREPARE: id:1741323542381, from:30187, delay:0.0001s, distance:151.27m (Euclidean)
[2025-03-07 13:59:21,214] [INFO] [30105] Received COMMIT: id:1741323542381, from:30187, delay:0.0001s, distance:151.27m (Euclidean)
[2025-03-07 13:59:22,506] [INFO] [30105] Received PREPARE: id:1741323542381, from:30088, delay:0.0002s, distance:250.94m (Euclidean)
[2025-03-07 13:59:22,508] [INFO] [30105] Received COMMIT: id:1741323542381, from:30088, delay:0.0002s, distance:250.94m (Euclidean)
[2025-03-07 13:59:22,738] [INFO] [30105] Received PREPARE: id:1741323542381, from:30009, delay:0.0001s, distance:155.50m (Euclidean)
[2025-03-07 13:59:22,738] [INFO] [30105] Received PREPARE: id:1741323542381, from:30101, delay:0.0001s, distance:190.70m (Euclidean)
[2025-03-07 13:59:22,740] [INFO] [30105] Received COMMIT: id:1741323542381, from:30101, delay:0.0001s, distance:190.70m (Euclidean)
[2025-03-07 13:59:22,861] [INFO] [30105] Received PREPARE: id:1741323542381, from:30117, delay:0.0002s, distance:279.39m (Euclidean)
[2025-03-07 13:59:22,861] [INFO] [30105] Received COMMIT: id:1741323542381, from:30117, delay:0.0002s, distance:279.39m (Euclidean)
[2025-03-07 13:59:23,770] [INFO] [30105] Received PREPARE: id:1741323542381, from:30039, delay:0.0001s, distance:187.40m (Euclidean)
[2025-03-07 13:59:23,774] [INFO] [30105] Received COMMIT: id:1741323542381, from:30039, delay:0.0001s, distance:187.40m (Euclidean)
[2025-03-07 13:59:23,999] [INFO] [30105] Received PREPARE: id:1741323542381, from:30045, delay:0.0002s, distance:266.76m (Euclidean)
[2025-03-07 13:59:23,999] [INFO] [30105] Received COMMIT: id:1741323542381, from:30045, delay:0.0002s, distance:266.76m (Euclidean)
[2025-03-07 13:59:24,287] [INFO] [30105] Received PREPARE: id:1741323542381, from:30188, delay:0.0002s, distance:271.48m (Euclidean)
[2025-03-07 13:59:24,375] [INFO] [30105] Received COMMIT: id:1741323542381, from:30188, delay:0.0002s, distance:271.48m (Euclidean)
[2025-03-07 13:59:24,377] [INFO] [30105] Received COMMIT: id:1741323542381, from:30009, delay:0.0001s, distance:155.50m (Euclidean)
[2025-03-07 13:59:24,518] [INFO] [30105] Received COMMIT: id:1741323542381, from:30104, delay:0.0000s, distance:80.29m (Euclidean)
[2025-03-07 13:59:24,545] [INFO] [30105] Received PREPARE: id:1741323542381, from:30014, delay:0.0001s, distance:188.69m (Euclidean)
[2025-03-07 13:59:24,545] [INFO] [30105] Received COMMIT: id:1741323542381, from:30014, delay:0.0001s, distance:188.69m (Euclidean)
[2025-03-07 13:59:24,592] [INFO] [30105] Received PREPARE: id:1741323542381, from:30173, delay:0.0001s, distance:207.61m (Euclidean)
[2025-03-07 13:59:24,604] [INFO] [30105] Received COMMIT: id:1741323542381, from:30173, delay:0.0001s, distance:207.61m (Euclidean)
[2025-03-07 13:59:24,877] [INFO] [30105] Received PREPARE: id:1741323542381, from:30099, delay:0.0002s, distance:263.97m (Euclidean)
[2025-03-07 13:59:24,893] [INFO] [30105] Received COMMIT: id:1741323542381, from:30099, delay:0.0002s, distance:263.97m (Euclidean)
[2025-03-07 13:59:25,319] [INFO] [30105] Received PREPARE: id:1741323542381, from:30162, delay:0.0002s, distance:292.69m (Euclidean)
[2025-03-07 13:59:25,319] [INFO] [30105] Received COMMIT: id:1741323542381, from:30162, delay:0.0002s, distance:292.69m (Euclidean)
[2025-03-07 13:59:25,319] [INFO] [30105] Received PREPARE: id:1741323542381, from:30156, delay:0.0001s, distance:165.76m (Euclidean)
[2025-03-07 13:59:25,319] [INFO] [30105] Received COMMIT: id:1741323542381, from:30156, delay:0.0001s, distance:165.76m (Euclidean)
[2025-03-07 13:59:25,375] [INFO] [30105] Received PREPARE: id:1741323542381, from:30166, delay:0.0001s, distance:225.61m (Euclidean)
[2025-03-07 13:59:25,376] [INFO] [30105] Received COMMIT: id:1741323542381, from:30166, delay:0.0001s, distance:225.61m (Euclidean)
[2025-03-07 13:59:25,430] [INFO] [30105] Received PREPARE: id:1741323542381, from:30082, delay:0.0000s, distance:72.14m (Euclidean)
[2025-03-07 13:59:25,430] [INFO] [30105] Received COMMIT: id:1741323542381, from:30082, delay:0.0000s, distance:72.14m (Euclidean)
[2025-03-07 13:59:25,566] [INFO] [30105] Received PREPARE: id:1741323542381, from:30094, delay:0.0001s, distance:172.52m (Euclidean)
[2025-03-07 13:59:25,566] [INFO] [30105] Received COMMIT: id:1741323542381, from:30094, delay:0.0001s, distance:172.52m (Euclidean)
[2025-03-07 13:59:25,798] [INFO] [30105] Received PREPARE: id:1741323542381, from:30159, delay:0.0002s, distance:253.91m (Euclidean)
[2025-03-07 13:59:25,798] [INFO] [30105] Received COMMIT: id:1741323542381, from:30159, delay:0.0002s, distance:253.91m (Euclidean)
[2025-03-07 13:59:26,311] [INFO] [30105] Received PREPARE: id:1741323542381, from:30151, delay:0.0000s, distance:197.25m (Euclidean)
[2025-03-07 13:59:26,311] [INFO] [30105] Received COMMIT: id:1741323542381, from:30151, delay:0.0000s, distance:197.25m (Euclidean)
[2025-03-07 13:59:26,411] [INFO] [30105] Received PREPARE: id:1741323542381, from:30185, delay:0.0000s, distance:114.36m (Euclidean)
[2025-03-07 13:59:27,036] [INFO] [30105] Received PREPARE: id:1741323542381, from:30084, delay:0.0002s, distance:288.09m (Euclidean)
[2025-03-07 13:59:27,042] [INFO] [30105] Received COMMIT: id:1741323542381, from:30084, delay:0.0002s, distance:288.09m (Euclidean)
[2025-03-07 13:59:27,395] [INFO] [30105] Received PREPARE: id:1741323542381, from:30186, delay:0.0000s, distance:160.78m (Euclidean)
[2025-03-07 13:59:27,409] [INFO] [30105] Received COMMIT: id:1741323542381, from:30186, delay:0.0000s, distance:160.78m (Euclidean)
[2025-03-07 13:59:27,464] [INFO] [30105] Received PREPARE: id:1741323542381, from:30075, delay:0.0001s, distance:210.80m (Euclidean)
[2025-03-07 13:59:27,465] [INFO] [30105] Received COMMIT: id:1741323542381, from:30075, delay:0.0001s, distance:210.80m (Euclidean)
[2025-03-07 13:59:27,493] [INFO] [30105] Received PREPARE: id:1741323542381, from:30002, delay:0.0001s, distance:178.23m (Euclidean)
[2025-03-07 13:59:27,526] [INFO] [30105] Received PREPARE: id:1741323542381, from:30139, delay:0.0001s, distance:181.59m (Euclidean)
[2025-03-07 13:59:27,550] [INFO] [30105] Received COMMIT: id:1741323542381, from:30139, delay:0.0001s, distance:181.59m (Euclidean)
[2025-03-07 13:59:28,238] [INFO] [30105] Received PREPARE: id:1741323542381, from:30163, delay:0.0001s, distance:180.75m (Euclidean)
[2025-03-07 13:59:28,247] [INFO] [30105] Received COMMIT: id:1741323542381, from:30163, delay:0.0001s, distance:180.75m (Euclidean)
[2025-03-07 13:59:28,324] [INFO] [30105] Received COMMIT: id:1741323542381, from:30185, delay:0.0000s, distance:114.36m (Euclidean)
[2025-03-07 13:59:28,456] [INFO] [30105] Received PREPARE: id:1741323542381, from:30047, delay:0.0001s, distance:185.33m (Euclidean)
[2025-03-07 13:59:28,474] [INFO] [30105] Received COMMIT: id:1741323542381, from:30047, delay:0.0001s, distance:185.33m (Euclidean)
[2025-03-07 13:59:28,546] [INFO] [30105] Received PREPARE: id:1741323542381, from:30018, delay:0.0000s, distance:168.53m (Euclidean)
[2025-03-07 13:59:28,546] [INFO] [30105] Received COMMIT: id:1741323542381, from:30018, delay:0.0000s, distance:168.53m (Euclidean)
[2025-03-07 13:59:28,589] [INFO] [30105] Received PREPARE: id:1741323542381, from:30044, delay:0.0001s, distance:180.16m (Euclidean)
[2025-03-07 13:59:28,589] [INFO] [30105] Received COMMIT: id:1741323542381, from:30044, delay:0.0001s, distance:180.16m (Euclidean)
[2025-03-07 13:59:28,726] [INFO] [30105] Received PREPARE: id:1741323542381, from:30097, delay:0.0001s, distance:228.61m (Euclidean)
[2025-03-07 13:59:28,928] [INFO] [30105] Received PREPARE: id:1741323542381, from:30183, delay:0.0002s, distance:285.26m (Euclidean)
[2025-03-07 13:59:28,959] [INFO] [30105] Received COMMIT: id:1741323542381, from:30183, delay:0.0002s, distance:285.26m (Euclidean)
[2025-03-07 13:59:33,283] [INFO] [30105] Received PREPARE: id:1741323542381, from:30192, delay:0.0002s, distance:263.32m (Euclidean)
[2025-03-07 13:59:37,188] [INFO] [30105] Received COMMIT: id:1741323542381, from:30097, delay:0.0001s, distance:228.61m (Euclidean)
[2025-03-07 13:59:37,588] [INFO] [30105] Received COMMIT: id:1741323542381, from:30012, delay:0.0002s, distance:265.29m (Euclidean)
[2025-03-07 13:59:37,912] [INFO] [30105] Received COMMIT: id:1741323542381, from:30002, delay:0.0001s, distance:178.23m (Euclidean)
[2025-03-07 13:59:38,072] [INFO] [30105] Received PREPARE: id:1741323542381, from:30030, delay:0.0002s, distance:287.35m (Euclidean)
[2025-03-07 13:59:38,221] [INFO] [30105] Received COMMIT: id:1741323542381, from:30030, delay:0.0002s, distance:287.35m (Euclidean)
[2025-03-07 13:59:38,341] [INFO] [30105] Received PREPARE: id:1741323542381, from:30078, delay:0.0002s, distance:271.62m (Euclidean)
[2025-03-07 13:59:38,460] [INFO] [30105] Received COMMIT: id:1741323542381, from:30078, delay:0.0002s, distance:271.62m (Euclidean)
[2025-03-07 13:59:38,529] [INFO] [30105] Received COMMIT: id:1741323542381, from:30192, delay:0.0002s, distance:263.32m (Euclidean)
[2025-03-07 13:59:38,556] [INFO] [30105] Received PREPARE: id:1741323542381, from:30164, delay:0.0002s, distance:281.96m (Euclidean)
[2025-03-07 13:59:38,581] [INFO] [30105] Received COMMIT: id:1741323542381, from:30164, delay:0.0002s, distance:281.96m (Euclidean)
[2025-03-07 13:59:38,736] [INFO] [30105] Received COMMIT: id:1741323542381, from:30172, delay:0.0001s, distance:248.13m (Euclidean)
