[2025-03-07 13:53:28,462] [INFO] Starting node at localhost:30128 | index=129 | f=1, k=4 | Role: Replica
[2025-03-07 13:53:39,142] [INFO] [30128] Received PREPARE: id:1741323218379, from:30098, delay:0.0000s, distance:299.31m (Euclidean)
[2025-03-07 13:53:39,142] [INFO] [30128] Missing PRE-PREPARE for REQUEST 1741323218379; ignoring PREPARE
[2025-03-07 13:53:39,243] [INFO] [30128] Received PREPARE: id:1741323218379, from:30097, delay:0.0000s, distance:80.74m (Euclidean)
[2025-03-07 13:53:39,243] [INFO] [30128] Missing PRE-PREPARE for REQUEST 1741323218379; ignoring PREPARE
[2025-03-07 13:53:39,421] [INFO] [30128] Received PREPARE: id:1741323218379, from:30087, delay:0.0000s, distance:59.90m (Euclidean)
[2025-03-07 13:53:39,421] [INFO] [30128] Missing PRE-PREPARE for REQUEST 1741323218379; ignoring PREPARE
[2025-03-07 13:53:39,645] [INFO] [30128] Received COMMIT: id:1741323218379, from:30098, delay:0.0000s, distance:299.31m (Euclidean)
[2025-03-07 13:53:39,723] [INFO] [30128] Received PREPARE: id:1741323218379, from:30001, delay:0.0000s, distance:200.41m (Euclidean)
[2025-03-07 13:53:39,723] [INFO] [30128] Missing PRE-PREPARE for REQUEST 1741323218379; ignoring PREPARE
[2025-03-07 13:53:39,737] [INFO] [30128] Received COMMIT: id:1741323218379, from:30097, delay:0.0000s, distance:80.74m (Euclidean)
[2025-03-07 13:53:39,753] [INFO] [30128] Received PREPARE: id:1741323218379, from:30070, delay:0.0000s, distance:115.16m (Euclidean)
[2025-03-07 13:53:39,753] [INFO] [30128] Missing PRE-PREPARE for REQUEST 1741323218379; ignoring PREPARE
[2025-03-07 13:53:39,773] [INFO] [30128] Received PREPARE: id:1741323218379, from:30090, delay:0.0000s, distance:16.53m (Euclidean)
[2025-03-07 13:53:39,773] [INFO] [30128] Missing PRE-PREPARE for REQUEST 1741323218379; ignoring PREPARE
[2025-03-07 13:53:39,799] [INFO] [30128] Received COMMIT: id:1741323218379, from:30001, delay:0.0000s, distance:200.41m (Euclidean)
[2025-03-07 13:53:39,800] [INFO] [30128] Received PREPARE: id:1741323218379, from:30005, delay:0.0000s, distance:130.16m (Euclidean)
[2025-03-07 13:53:39,800] [INFO] [30128] Missing PRE-PREPARE for REQUEST 1741323218379; ignoring PREPARE
[2025-03-07 13:53:39,863] [INFO] [30128] Received COMMIT: id:1741323218379, from:30070, delay:0.0000s, distance:115.16m (Euclidean)
[2025-03-07 13:53:39,933] [INFO] [30128] Received PREPARE: id:1741323218379, from:30026, delay:0.0000s, distance:59.47m (Euclidean)
[2025-03-07 13:53:39,933] [INFO] [30128] Missing PRE-PREPARE for REQUEST 1741323218379; ignoring PREPARE
[2025-03-07 13:53:39,933] [INFO] [30128] Received COMMIT: id:1741323218379, from:30026, delay:0.0000s, distance:59.47m (Euclidean)
[2025-03-07 13:53:39,943] [INFO] [30128] Received PREPARE: id:1741323218379, from:30021, delay:0.0001s, distance:233.59m (Euclidean)
[2025-03-07 13:53:39,943] [INFO] [30128] Missing PRE-PREPARE for REQUEST 1741323218379; ignoring PREPARE
[2025-03-07 13:53:39,943] [INFO] [30128] Received COMMIT: id:1741323218379, from:30021, delay:0.0001s, distance:233.59m (Euclidean)
[2025-03-07 13:53:39,959] [INFO] [30128] Received COMMIT: id:1741323218379, from:30005, delay:0.0000s, distance:130.16m (Euclidean)
[2025-03-07 13:53:40,066] [INFO] [30128] Received PREPARE: id:1741323218379, from:30083, delay:0.0000s, distance:79.22m (Euclidean)
[2025-03-07 13:53:40,066] [INFO] [30128] Missing PRE-PREPARE for REQUEST 1741323218379; ignoring PREPARE
[2025-03-07 13:53:40,066] [INFO] [30128] Received PREPARE: id:1741323218379, from:30033, delay:0.0000s, distance:149.30m (Euclidean)
[2025-03-07 13:53:40,066] [INFO] [30128] Missing PRE-PREPARE for REQUEST 1741323218379; ignoring PREPARE
[2025-03-07 13:53:40,066] [INFO] [30128] Received COMMIT: id:1741323218379, from:30033, delay:0.0000s, distance:149.30m (Euclidean)
[2025-03-07 13:53:40,085] [INFO] [30128] Received COMMIT: id:1741323218379, from:30087, delay:0.0000s, distance:59.90m (Euclidean)
[2025-03-07 13:53:40,169] [INFO] [30128] Received PREPARE: id:1741323218379, from:30020, delay:0.0001s, distance:228.36m (Euclidean)
[2025-03-07 13:53:40,169] [INFO] [30128] Missing PRE-PREPARE for REQUEST 1741323218379; ignoring PREPARE
[2025-03-07 13:53:40,178] [INFO] [30128] Received COMMIT: id:1741323218379, from:30020, delay:0.0001s, distance:228.36m (Euclidean)
[2025-03-07 13:53:40,275] [INFO] [30128] Received PREPARE: id:1741323218379, from:30049, delay:0.0000s, distance:68.72m (Euclidean)
[2025-03-07 13:53:40,275] [INFO] [30128] Missing PRE-PREPARE for REQUEST 1741323218379; ignoring PREPARE
[2025-03-07 13:53:40,275] [INFO] [30128] Received COMMIT: id:1741323218379, from:30049, delay:0.0000s, distance:68.72m (Euclidean)
[2025-03-07 13:53:40,577] [INFO] [30128] Received PREPARE: id:1741323218379, from:30028, delay:0.0000s, distance:141.68m (Euclidean)
[2025-03-07 13:53:40,577] [INFO] [30128] Missing PRE-PREPARE for REQUEST 1741323218379; ignoring PREPARE
[2025-03-07 13:53:40,577] [INFO] [30128] Received COMMIT: id:1741323218379, from:30028, delay:0.0000s, distance:141.68m (Euclidean)
[2025-03-07 13:53:40,671] [INFO] [30128] Received PREPARE: id:1741323218379, from:30002, delay:0.0000s, distance:121.84m (Euclidean)
[2025-03-07 13:53:40,671] [INFO] [30128] Missing PRE-PREPARE for REQUEST 1741323218379; ignoring PREPARE
[2025-03-07 13:53:40,687] [INFO] [30128] Received COMMIT: id:1741323218379, from:30002, delay:0.0000s, distance:121.84m (Euclidean)
[2025-03-07 13:53:40,735] [INFO] [30128] Received PREPARE: id:1741323218379, from:30061, delay:0.0000s, distance:147.24m (Euclidean)
[2025-03-07 13:53:40,735] [INFO] [30128] Missing PRE-PREPARE for REQUEST 1741323218379; ignoring PREPARE
[2025-03-07 13:53:40,782] [INFO] [30128] Received PREPARE: id:1741323218379, from:30091, delay:0.0000s, distance:145.83m (Euclidean)
[2025-03-07 13:53:40,782] [INFO] [30128] Missing PRE-PREPARE for REQUEST 1741323218379; ignoring PREPARE
[2025-03-07 13:53:40,782] [INFO] [30128] Received COMMIT: id:1741323218379, from:30091, delay:0.0000s, distance:145.83m (Euclidean)
[2025-03-07 13:53:40,893] [INFO] [30128] Received PREPARE: id:1741323218379, from:30073, delay:0.0000s, distance:123.93m (Euclidean)
[2025-03-07 13:53:40,893] [INFO] [30128] Missing PRE-PREPARE for REQUEST 1741323218379; ignoring PREPARE
[2025-03-07 13:53:40,991] [INFO] [30128] Received PREPARE: id:1741323218379, from:30062, delay:0.0000s, distance:145.39m (Euclidean)
[2025-03-07 13:53:40,991] [INFO] [30128] Missing PRE-PREPARE for REQUEST 1741323218379; ignoring PREPARE
[2025-03-07 13:53:40,991] [INFO] [30128] Received COMMIT: id:1741323218379, from:30062, delay:0.0000s, distance:145.39m (Euclidean)
[2025-03-07 13:53:41,006] [INFO] [30128] Received PREPARE: id:1741323218379, from:30047, delay:0.0001s, distance:240.27m (Euclidean)
[2025-03-07 13:53:41,006] [INFO] [30128] Missing PRE-PREPARE for REQUEST 1741323218379; ignoring PREPARE
[2025-03-07 13:53:41,006] [INFO] [30128] Received COMMIT: id:1741323218379, from:30047, delay:0.0001s, distance:240.27m (Euclidean)
[2025-03-07 13:53:41,022] [INFO] [30128] Received PREPARE: id:1741323218379, from:30006, delay:0.0001s, distance:194.61m (Euclidean)
[2025-03-07 13:53:41,022] [INFO] [30128] Missing PRE-PREPARE for REQUEST 1741323218379; ignoring PREPARE
[2025-03-07 13:53:41,022] [INFO] [30128] Received COMMIT: id:1741323218379, from:30006, delay:0.0001s, distance:194.61m (Euclidean)
[2025-03-07 13:53:41,160] [INFO] [30128] Received PREPARE: id:1741323218379, from:30086, delay:0.0001s, distance:155.06m (Euclidean)
[2025-03-07 13:53:41,160] [INFO] [30128] Missing PRE-PREPARE for REQUEST 1741323218379; ignoring PREPARE
[2025-03-07 13:53:41,162] [INFO] [30128] Received COMMIT: id:1741323218379, from:30086, delay:0.0001s, distance:155.06m (Euclidean)
[2025-03-07 13:53:41,193] [INFO] [30128] Received PREPARE: id:1741323218379, from:30058, delay:0.0000s, distance:118.54m (Euclidean)
[2025-03-07 13:53:41,193] [INFO] [30128] Missing PRE-PREPARE for REQUEST 1741323218379; ignoring PREPARE
[2025-03-07 13:53:41,193] [INFO] [30128] Received COMMIT: id:1741323218379, from:30058, delay:0.0000s, distance:118.54m (Euclidean)
[2025-03-07 13:53:41,241] [INFO] [30128] Received PREPARE: id:1741323218379, from:30055, delay:0.0000s, distance:128.89m (Euclidean)
[2025-03-07 13:53:41,241] [INFO] [30128] Missing PRE-PREPARE for REQUEST 1741323218379; ignoring PREPARE
[2025-03-07 13:53:41,596] [INFO] [30128] Received COMMIT: id:1741323218379, from:30083, delay:0.0000s, distance:79.22m (Euclidean)
[2025-03-07 13:53:41,652] [INFO] [30128] Received PREPARE: id:1741323218379, from:30037, delay:0.0001s, distance:177.11m (Euclidean)
[2025-03-07 13:53:41,652] [INFO] [30128] Missing PRE-PREPARE for REQUEST 1741323218379; ignoring PREPARE
[2025-03-07 13:53:41,652] [INFO] [30128] Received COMMIT: id:1741323218379, from:30037, delay:0.0001s, distance:177.11m (Euclidean)
[2025-03-07 13:53:41,652] [INFO] [30128] Received PREPARE: id:1741323218379, from:30060, delay:0.0001s, distance:237.35m (Euclidean)
[2025-03-07 13:53:41,652] [INFO] [30128] Missing PRE-PREPARE for REQUEST 1741323218379; ignoring PREPARE
[2025-03-07 13:53:41,652] [INFO] [30128] Received COMMIT: id:1741323218379, from:30060, delay:0.0001s, distance:237.35m (Euclidean)
[2025-03-07 13:53:41,779] [INFO] [30128] Received COMMIT: id:1741323218379, from:30090, delay:0.0000s, distance:16.53m (Euclidean)
[2025-03-07 13:53:42,032] [INFO] [30128] Received PREPARE: id:1741323218379, from:30013, delay:0.0001s, distance:206.76m (Euclidean)
[2025-03-07 13:53:42,032] [INFO] [30128] Missing PRE-PREPARE for REQUEST 1741323218379; ignoring PREPARE
[2025-03-07 13:53:42,048] [INFO] [30128] Received COMMIT: id:1741323218379, from:30013, delay:0.0001s, distance:206.76m (Euclidean)
[2025-03-07 13:53:42,305] [INFO] [30128] Received PREPARE: id:1741323218379, from:30017, delay:0.0000s, distance:168.98m (Euclidean)
[2025-03-07 13:53:42,305] [INFO] [30128] Missing PRE-PREPARE for REQUEST 1741323218379; ignoring PREPARE
[2025-03-07 13:53:42,305] [INFO] [30128] Received COMMIT: id:1741323218379, from:30017, delay:0.0000s, distance:168.98m (Euclidean)
[2025-03-07 13:53:42,506] [INFO] [30128] Received PREPARE: id:1741323218379, from:30040, delay:0.0000s, distance:107.16m (Euclidean)
[2025-03-07 13:53:42,506] [INFO] [30128] Missing PRE-PREPARE for REQUEST 1741323218379; ignoring PREPARE
[2025-03-07 13:53:42,506] [INFO] [30128] Received COMMIT: id:1741323218379, from:30040, delay:0.0000s, distance:107.16m (Euclidean)
[2025-03-07 13:53:42,702] [INFO] [30128] Received PREPARE: id:1741323218379, from:30034, delay:0.0001s, distance:237.22m (Euclidean)
[2025-03-07 13:53:42,702] [INFO] [30128] Missing PRE-PREPARE for REQUEST 1741323218379; ignoring PREPARE
[2025-03-07 13:53:42,702] [INFO] [30128] Received COMMIT: id:1741323218379, from:30034, delay:0.0001s, distance:237.22m (Euclidean)
[2025-03-07 13:53:42,727] [INFO] [30128] Received PREPARE: id:1741323218379, from:30039, delay:0.0001s, distance:171.73m (Euclidean)
[2025-03-07 13:53:42,727] [INFO] [30128] Missing PRE-PREPARE for REQUEST 1741323218379; ignoring PREPARE
[2025-03-07 13:53:42,759] [INFO] [30128] Received PREPARE: id:1741323218379, from:30092, delay:0.0002s, distance:267.42m (Euclidean)
[2025-03-07 13:53:42,759] [INFO] [30128] Missing PRE-PREPARE for REQUEST 1741323218379; ignoring PREPARE
[2025-03-07 13:53:42,759] [INFO] [30128] Received COMMIT: id:1741323218379, from:30092, delay:0.0002s, distance:267.42m (Euclidean)
[2025-03-07 13:53:42,759] [INFO] [30128] Received COMMIT: id:1741323218379, from:30053, delay:0.0000s, distance:128.89m (Euclidean)
[2025-03-07 13:53:42,759] [INFO] [30128] Received PREPARE: id:1741323218379, from:30053, delay:0.0000s, distance:128.89m (Euclidean)
[2025-03-07 13:53:42,759] [INFO] [30128] Missing PRE-PREPARE for REQUEST 1741323218379; ignoring PREPARE
[2025-03-07 13:53:42,797] [INFO] [30128] Received COMMIT: id:1741323218379, from:30061, delay:0.0000s, distance:147.24m (Euclidean)
[2025-03-07 13:53:42,805] [INFO] [30128] Received COMMIT: id:1741323218379, from:30039, delay:0.0001s, distance:171.73m (Euclidean)
[2025-03-07 13:53:42,853] [INFO] [30128] Received PREPARE: id:1741323218379, from:30012, delay:0.0002s, distance:294.33m (Euclidean)
[2025-03-07 13:53:42,853] [INFO] [30128] Missing PRE-PREPARE for REQUEST 1741323218379; ignoring PREPARE
[2025-03-07 13:53:42,853] [INFO] [30128] Received COMMIT: id:1741323218379, from:30012, delay:0.0002s, distance:294.33m (Euclidean)
[2025-03-07 13:53:43,133] [INFO] [30128] Received COMMIT: id:1741323218379, from:30073, delay:0.0000s, distance:123.93m (Euclidean)
[2025-03-07 13:53:43,314] [INFO] [30128] Received PREPARE: id:1741323218379, from:30041, delay:0.0001s, distance:218.37m (Euclidean)
[2025-03-07 13:53:43,314] [INFO] [30128] Missing PRE-PREPARE for REQUEST 1741323218379; ignoring PREPARE
[2025-03-07 13:53:43,314] [INFO] [30128] Received COMMIT: id:1741323218379, from:30044, delay:0.0002s, distance:270.74m (Euclidean)
[2025-03-07 13:53:43,314] [INFO] [30128] Received COMMIT: id:1741323218379, from:30041, delay:0.0001s, distance:218.37m (Euclidean)
[2025-03-07 13:53:43,314] [INFO] [30128] Received PREPARE: id:1741323218379, from:30044, delay:0.0002s, distance:270.74m (Euclidean)
[2025-03-07 13:53:43,314] [INFO] [30128] Missing PRE-PREPARE for REQUEST 1741323218379; ignoring PREPARE
[2025-03-07 13:53:43,314] [INFO] [30128] Received COMMIT: id:1741323218379, from:30055, delay:0.0000s, distance:128.89m (Euclidean)
[2025-03-07 13:53:43,423] [INFO] [30128] Received PREPARE: id:1741323218379, from:30052, delay:0.0001s, distance:237.00m (Euclidean)
[2025-03-07 13:53:43,423] [INFO] [30128] Missing PRE-PREPARE for REQUEST 1741323218379; ignoring PREPARE
[2025-03-07 13:53:43,423] [INFO] [30128] Received COMMIT: id:1741323218379, from:30052, delay:0.0001s, distance:237.00m (Euclidean)
[2025-03-07 13:53:43,470] [INFO] [30128] Received PREPARE: id:1741323218379, from:30019, delay:0.0002s, distance:254.19m (Euclidean)
[2025-03-07 13:53:43,470] [INFO] [30128] Missing PRE-PREPARE for REQUEST 1741323218379; ignoring PREPARE
[2025-03-07 13:53:43,470] [INFO] [30128] Received COMMIT: id:1741323218379, from:30019, delay:0.0002s, distance:254.19m (Euclidean)
[2025-03-07 13:53:43,596] [INFO] [30128] Received PREPARE: id:1741323218379, from:30078, delay:0.0002s, distance:262.06m (Euclidean)
[2025-03-07 13:53:43,596] [INFO] [30128] Missing PRE-PREPARE for REQUEST 1741323218379; ignoring PREPARE
[2025-03-07 13:53:43,596] [INFO] [30128] Received COMMIT: id:1741323218379, from:30078, delay:0.0002s, distance:262.06m (Euclidean)
[2025-03-07 13:53:43,818] [INFO] [30128] Received PREPARE: id:1741323218379, from:30072, delay:0.0001s, distance:239.50m (Euclidean)
[2025-03-07 13:53:43,818] [INFO] [30128] Missing PRE-PREPARE for REQUEST 1741323218379; ignoring PREPARE
[2025-03-07 13:53:43,818] [INFO] [30128] Received COMMIT: id:1741323218379, from:30072, delay:0.0001s, distance:239.50m (Euclidean)
[2025-03-07 13:53:43,881] [INFO] [30128] Received PREPARE: id:1741323218379, from:30088, delay:0.0000s, distance:144.97m (Euclidean)
[2025-03-07 13:53:43,881] [INFO] [30128] Missing PRE-PREPARE for REQUEST 1741323218379; ignoring PREPARE
[2025-03-07 13:53:43,881] [INFO] [30128] Received COMMIT: id:1741323218379, from:30088, delay:0.0000s, distance:144.97m (Euclidean)
[2025-03-07 13:53:43,947] [INFO] [30128] Received PREPARE: id:1741323218379, from:30095, delay:0.0001s, distance:180.09m (Euclidean)
[2025-03-07 13:53:43,947] [INFO] [30128] Missing PRE-PREPARE for REQUEST 1741323218379; ignoring PREPARE
[2025-03-07 13:53:44,102] [INFO] [30128] Received PREPARE: id:1741323218379, from:30094, delay:0.0001s, distance:238.47m (Euclidean)
[2025-03-07 13:53:44,102] [INFO] [30128] Missing PRE-PREPARE for REQUEST 1741323218379; ignoring PREPARE
[2025-03-07 13:53:44,118] [INFO] [30128] Received COMMIT: id:1741323218379, from:30094, delay:0.0001s, distance:238.47m (Euclidean)
[2025-03-07 13:53:44,231] [INFO] [30128] Received PREPARE: id:1741323218379, from:30081, delay:0.0001s, distance:241.85m (Euclidean)
[2025-03-07 13:53:44,231] [INFO] [30128] Missing PRE-PREPARE for REQUEST 1741323218379; ignoring PREPARE
[2025-03-07 13:53:44,231] [INFO] [30128] Received COMMIT: id:1741323218379, from:30081, delay:0.0001s, distance:241.85m (Euclidean)
[2025-03-07 13:53:44,434] [INFO] [30128] Received PREPARE: id:1741323218379, from:30030, delay:0.0001s, distance:241.95m (Euclidean)
[2025-03-07 13:53:44,434] [INFO] [30128] Missing PRE-PREPARE for REQUEST 1741323218379; ignoring PREPARE
[2025-03-07 13:53:44,443] [INFO] [30128] Received COMMIT: id:1741323218379, from:30030, delay:0.0001s, distance:241.95m (Euclidean)
[2025-03-07 13:53:44,443] [INFO] [30128] Received PREPARE: id:1741323218379, from:30096, delay:0.0002s, distance:265.50m (Euclidean)
[2025-03-07 13:53:44,443] [INFO] [30128] Missing PRE-PREPARE for REQUEST 1741323218379; ignoring PREPARE
[2025-03-07 13:53:44,443] [INFO] [30128] Received COMMIT: id:1741323218379, from:30096, delay:0.0002s, distance:265.50m (Euclidean)
[2025-03-07 13:53:44,670] [INFO] [30128] Received PREPARE: id:1741323218379, from:30024, delay:0.0002s, distance:253.61m (Euclidean)
[2025-03-07 13:53:44,670] [INFO] [30128] Missing PRE-PREPARE for REQUEST 1741323218379; ignoring PREPARE
[2025-03-07 13:53:44,670] [INFO] [30128] Received COMMIT: id:1741323218379, from:30024, delay:0.0002s, distance:253.61m (Euclidean)
[2025-03-07 13:53:44,781] [INFO] [30128] Received PREPARE: id:1741323218379, from:30104, delay:0.0001s, distance:187.71m (Euclidean)
[2025-03-07 13:53:44,781] [INFO] [30128] Missing PRE-PREPARE for REQUEST 1741323218379; ignoring PREPARE
[2025-03-07 13:53:44,781] [INFO] [30128] Received COMMIT: id:1741323218379, from:30104, delay:0.0001s, distance:187.71m (Euclidean)
[2025-03-07 13:53:44,879] [INFO] [30128] Received COMMIT: id:1741323218379, from:30095, delay:0.0001s, distance:180.09m (Euclidean)
[2025-03-07 13:53:44,991] [INFO] [30128] Received PREPARE: id:1741323218379, from:30117, delay:0.0001s, distance:214.27m (Euclidean)
[2025-03-07 13:53:44,991] [INFO] [30128] Missing PRE-PREPARE for REQUEST 1741323218379; ignoring PREPARE
[2025-03-07 13:53:44,991] [INFO] [30128] Received COMMIT: id:1741323218379, from:30117, delay:0.0001s, distance:214.27m (Euclidean)
[2025-03-07 13:53:45,309] [INFO] [30128] Received PREPARE: id:1741323218379, from:30003, delay:0.0000s, distance:160.70m (Euclidean)
[2025-03-07 13:53:45,309] [INFO] [30128] Missing PRE-PREPARE for REQUEST 1741323218379; ignoring PREPARE
[2025-03-07 13:53:45,309] [INFO] [30128] Received COMMIT: id:1741323218379, from:30003, delay:0.0000s, distance:160.70m (Euclidean)
[2025-03-07 13:53:45,477] [INFO] [30128] Received PREPARE: id:1741323218379, from:30010, delay:0.0000s, distance:146.51m (Euclidean)
[2025-03-07 13:53:45,477] [INFO] [30128] Missing PRE-PREPARE for REQUEST 1741323218379; ignoring PREPARE
[2025-03-07 13:53:45,477] [INFO] [30128] Received PREPARE: id:1741323218379, from:30042, delay:0.0002s, distance:263.67m (Euclidean)
[2025-03-07 13:53:45,477] [INFO] [30128] Missing PRE-PREPARE for REQUEST 1741323218379; ignoring PREPARE
[2025-03-07 13:53:45,477] [INFO] [30128] Received PREPARE: id:1741323218379, from:30046, delay:0.0001s, distance:167.42m (Euclidean)
[2025-03-07 13:53:45,477] [INFO] [30128] Missing PRE-PREPARE for REQUEST 1741323218379; ignoring PREPARE
[2025-03-07 13:53:45,477] [INFO] [30128] Received COMMIT: id:1741323218379, from:30042, delay:0.0002s, distance:263.67m (Euclidean)
[2025-03-07 13:53:45,477] [INFO] [30128] Received COMMIT: id:1741323218379, from:30010, delay:0.0000s, distance:146.51m (Euclidean)
[2025-03-07 13:53:45,477] [INFO] [30128] Received COMMIT: id:1741323218379, from:30046, delay:0.0001s, distance:167.42m (Euclidean)
[2025-03-07 13:53:45,477] [INFO] [30128] Received PREPARE: id:1741323218379, from:30032, delay:0.0000s, distance:148.18m (Euclidean)
[2025-03-07 13:53:45,477] [INFO] [30128] Missing PRE-PREPARE for REQUEST 1741323218379; ignoring PREPARE
[2025-03-07 13:53:45,477] [INFO] [30128] Received COMMIT: id:1741323218379, from:30032, delay:0.0000s, distance:148.18m (Euclidean)
[2025-03-07 13:53:45,493] [INFO] [30128] Received PREPARE: id:1741323218379, from:30011, delay:0.0001s, distance:167.95m (Euclidean)
[2025-03-07 13:53:45,493] [INFO] [30128] Missing PRE-PREPARE for REQUEST 1741323218379; ignoring PREPARE
[2025-03-07 13:53:45,493] [INFO] [30128] Received COMMIT: id:1741323218379, from:30011, delay:0.0001s, distance:167.95m (Euclidean)
[2025-03-07 13:53:45,572] [INFO] [30128] Received PREPARE: id:1741323218379, from:30031, delay:0.0001s, distance:232.84m (Euclidean)
[2025-03-07 13:53:45,572] [INFO] [30128] Missing PRE-PREPARE for REQUEST 1741323218379; ignoring PREPARE
[2025-03-07 13:53:45,572] [INFO] [30128] Received COMMIT: id:1741323218379, from:30031, delay:0.0001s, distance:232.84m (Euclidean)
[2025-03-07 13:53:45,658] [INFO] [30128] Received PREPARE: id:1741323218379, from:30099, delay:0.0000s, distance:199.43m (Euclidean)
[2025-03-07 13:53:45,658] [INFO] [30128] Missing PRE-PREPARE for REQUEST 1741323218379; ignoring PREPARE
[2025-03-07 13:53:45,658] [INFO] [30128] Received COMMIT: id:1741323218379, from:30099, delay:0.0000s, distance:199.43m (Euclidean)
[2025-03-07 13:53:45,699] [INFO] [30128] Received PREPARE: id:1741323218379, from:30004, delay:0.0001s, distance:231.49m (Euclidean)
[2025-03-07 13:53:45,699] [INFO] [30128] Missing PRE-PREPARE for REQUEST 1741323218379; ignoring PREPARE
[2025-03-07 13:53:45,699] [INFO] [30128] Received COMMIT: id:1741323218379, from:30004, delay:0.0001s, distance:231.49m (Euclidean)
[2025-03-07 13:53:45,747] [INFO] [30128] Received PREPARE: id:1741323218379, from:30035, delay:0.0001s, distance:151.81m (Euclidean)
[2025-03-07 13:53:45,747] [INFO] [30128] Missing PRE-PREPARE for REQUEST 1741323218379; ignoring PREPARE
[2025-03-07 13:53:45,747] [INFO] [30128] Received COMMIT: id:1741323218379, from:30035, delay:0.0001s, distance:151.81m (Euclidean)
[2025-03-07 13:53:45,797] [INFO] [30128] Received PREPARE: id:1741323218379, from:30036, delay:0.0002s, distance:256.46m (Euclidean)
[2025-03-07 13:53:45,797] [INFO] [30128] Missing PRE-PREPARE for REQUEST 1741323218379; ignoring PREPARE
[2025-03-07 13:53:45,810] [INFO] [30128] Received COMMIT: id:1741323218379, from:30036, delay:0.0002s, distance:256.46m (Euclidean)
[2025-03-07 13:53:45,921] [INFO] [30128] Received PREPARE: id:1741323218379, from:30014, delay:0.0001s, distance:201.39m (Euclidean)
[2025-03-07 13:53:45,921] [INFO] [30128] Missing PRE-PREPARE for REQUEST 1741323218379; ignoring PREPARE
[2025-03-07 13:53:45,921] [INFO] [30128] Received COMMIT: id:1741323218379, from:30014, delay:0.0001s, distance:201.39m (Euclidean)
[2025-03-07 13:53:46,047] [INFO] [30128] Received PREPARE: id:1741323218379, from:30089, delay:0.0001s, distance:204.81m (Euclidean)
[2025-03-07 13:53:46,047] [INFO] [30128] Missing PRE-PREPARE for REQUEST 1741323218379; ignoring PREPARE
[2025-03-07 13:53:46,047] [INFO] [30128] Received COMMIT: id:1741323218379, from:30089, delay:0.0001s, distance:204.81m (Euclidean)
[2025-03-07 13:53:46,158] [INFO] [30128] Received PREPARE: id:1741323218379, from:30048, delay:0.0000s, distance:97.96m (Euclidean)
[2025-03-07 13:53:46,158] [INFO] [30128] Missing PRE-PREPARE for REQUEST 1741323218379; ignoring PREPARE
[2025-03-07 13:53:46,158] [INFO] [30128] Received COMMIT: id:1741323218379, from:30048, delay:0.0000s, distance:97.96m (Euclidean)
[2025-03-07 13:53:46,205] [INFO] [30128] Received PREPARE: id:1741323218379, from:30016, delay:0.0001s, distance:177.21m (Euclidean)
[2025-03-07 13:53:46,205] [INFO] [30128] Missing PRE-PREPARE for REQUEST 1741323218379; ignoring PREPARE
[2025-03-07 13:53:46,205] [INFO] [30128] Received COMMIT: id:1741323218379, from:30016, delay:0.0001s, distance:177.21m (Euclidean)
[2025-03-07 13:53:46,668] [INFO] [30128] Received PREPARE: id:1741323218379, from:30043, delay:0.0002s, distance:269.90m (Euclidean)
[2025-03-07 13:53:46,668] [INFO] [30128] Missing PRE-PREPARE for REQUEST 1741323218379; ignoring PREPARE
[2025-03-07 13:53:46,668] [INFO] [30128] Received COMMIT: id:1741323218379, from:30043, delay:0.0002s, distance:269.90m (Euclidean)
[2025-03-07 13:53:46,918] [INFO] [30128] Received PRE-PREPARE: id:1741323218379, from:Leader(30000), delay:0.0000s, distance:162.97m (Euclidean)
[2025-03-07 13:53:46,918] [INFO] [30128] Broadcasting PREPARE for REQUEST 1741323218379
[2025-03-07 13:53:47,044] [INFO] [30128] Received COMMIT: id:1741323218379, from:30102, delay:0.0001s, distance:223.99m (Euclidean)
[2025-03-07 13:53:47,044] [INFO] [30128] Received PREPARE: id:1741323218379, from:30102, delay:0.0001s, distance:223.99m (Euclidean)
[2025-03-07 13:53:47,044] [INFO] [30128] Broadcasting COMMIT for REQUEST 1741323218379
[2025-03-07 13:53:47,155] [INFO] [30128] Received PREPARE: id:1741323218379, from:30110, delay:0.0000s, distance:134.48m (Euclidean)
[2025-03-07 13:53:47,155] [INFO] [30128] Received COMMIT: id:1741323218379, from:30110, delay:0.0000s, distance:134.48m (Euclidean)
[2025-03-07 13:53:47,204] [INFO] [30128] Received PREPARE: id:1741323218379, from:30135, delay:0.0001s, distance:170.00m (Euclidean)
[2025-03-07 13:53:47,204] [INFO] [30128] Received COMMIT: id:1741323218379, from:30135, delay:0.0001s, distance:170.00m (Euclidean)
[2025-03-07 13:53:47,284] [INFO] [30128] Received PREPARE: id:1741323218379, from:30134, delay:0.0000s, distance:107.47m (Euclidean)
[2025-03-07 13:53:47,284] [INFO] [30128] Received COMMIT: id:1741323218379, from:30134, delay:0.0000s, distance:107.47m (Euclidean)
[2025-03-07 13:53:47,413] [INFO] [30128] Received PREPARE: id:1741323218379, from:30007, delay:0.0002s, distance:261.87m (Euclidean)
[2025-03-07 13:53:47,413] [INFO] [30128] Received COMMIT: id:1741323218379, from:30007, delay:0.0002s, distance:261.87m (Euclidean)
[2025-03-07 13:53:47,509] [INFO] [30128] Received PREPARE: id:1741323218379, from:30158, delay:0.0000s, distance:96.14m (Euclidean)
[2025-03-07 13:53:47,629] [INFO] [30128] Received COMMIT: id:1741323218379, from:30158, delay:0.0000s, distance:96.14m (Euclidean)
[2025-03-07 13:53:47,774] [INFO] [30128] Received PREPARE: id:1741323218379, from:30136, delay:0.0001s, distance:166.94m (Euclidean)
[2025-03-07 13:53:47,774] [INFO] [30128] Received COMMIT: id:1741323218379, from:30136, delay:0.0001s, distance:166.94m (Euclidean)
[2025-03-07 13:53:47,774] [INFO] [30128] Received PREPARE: id:1741323218379, from:30147, delay:0.0000s, distance:134.38m (Euclidean)
[2025-03-07 13:53:47,803] [INFO] [30128] Received PREPARE: id:1741323218379, from:30153, delay:0.0001s, distance:158.02m (Euclidean)
[2025-03-07 13:53:47,803] [INFO] [30128] Received COMMIT: id:1741323218379, from:30153, delay:0.0001s, distance:158.02m (Euclidean)
[2025-03-07 13:53:47,947] [INFO] [30128] Received PREPARE: id:1741323218379, from:30154, delay:0.0000s, distance:21.19m (Euclidean)
[2025-03-07 13:53:47,947] [INFO] [30128] Received COMMIT: id:1741323218379, from:30154, delay:0.0000s, distance:21.19m (Euclidean)
[2025-03-07 13:53:47,964] [INFO] [30128] Received COMMIT: id:1741323218379, from:30147, delay:0.0000s, distance:134.38m (Euclidean)
[2025-03-07 13:53:47,994] [INFO] [30128] Received PREPARE: id:1741323218379, from:30139, delay:0.0001s, distance:197.81m (Euclidean)
[2025-03-07 13:53:47,994] [INFO] [30128] Received COMMIT: id:1741323218379, from:30139, delay:0.0001s, distance:197.81m (Euclidean)
[2025-03-07 13:53:48,140] [INFO] [30128] Received PREPARE: id:1741323218379, from:30122, delay:0.0002s, distance:276.52m (Euclidean)
[2025-03-07 13:53:48,146] [INFO] [30128] Received COMMIT: id:1741323218379, from:30122, delay:0.0002s, distance:276.52m (Euclidean)
[2025-03-07 13:53:48,156] [INFO] [30128] Received PREPARE: id:1741323218379, from:30157, delay:0.0000s, distance:40.11m (Euclidean)
[2025-03-07 13:53:48,214] [INFO] [30128] Received PREPARE: id:1741323218379, from:30105, delay:0.0001s, distance:183.27m (Euclidean)
[2025-03-07 13:53:48,214] [INFO] [30128] Received COMMIT: id:1741323218379, from:30105, delay:0.0001s, distance:183.27m (Euclidean)
[2025-03-07 13:53:48,325] [INFO] [30128] Received COMMIT: id:1741323218379, from:30157, delay:0.0000s, distance:40.11m (Euclidean)
[2025-03-07 13:53:48,719] [INFO] [30128] Received PREPARE: id:1741323218379, from:30109, delay:0.0001s, distance:227.97m (Euclidean)
[2025-03-07 13:53:48,723] [INFO] [30128] Received COMMIT: id:1741323218379, from:30109, delay:0.0001s, distance:227.97m (Euclidean)
[2025-03-07 13:53:48,853] [INFO] [30128] Received PREPARE: id:1741323218379, from:30131, delay:0.0000s, distance:179.49m (Euclidean)
[2025-03-07 13:53:48,853] [INFO] [30128] Received COMMIT: id:1741323218379, from:30131, delay:0.0000s, distance:179.49m (Euclidean)
[2025-03-07 13:53:48,977] [INFO] [30128] Received PREPARE: id:1741323218379, from:30144, delay:0.0000s, distance:145.33m (Euclidean)
[2025-03-07 13:53:49,107] [INFO] [30128] Received PREPARE: id:1741323218379, from:30107, delay:0.0001s, distance:151.86m (Euclidean)
[2025-03-07 13:53:49,110] [INFO] [30128] Received COMMIT: id:1741323218379, from:30107, delay:0.0001s, distance:151.86m (Euclidean)
[2025-03-07 13:53:49,162] [INFO] [30128] Received PREPARE: id:1741323218379, from:30151, delay:0.0001s, distance:213.29m (Euclidean)
[2025-03-07 13:53:49,180] [INFO] [30128] Received COMMIT: id:1741323218379, from:30151, delay:0.0001s, distance:213.29m (Euclidean)
[2025-03-07 13:53:49,215] [INFO] [30128] Received PREPARE: id:1741323218379, from:30133, delay:0.0001s, distance:205.04m (Euclidean)
[2025-03-07 13:53:49,246] [INFO] [30128] Received COMMIT: id:1741323218379, from:30133, delay:0.0001s, distance:205.04m (Euclidean)
[2025-03-07 13:53:49,260] [INFO] [30128] Received PREPARE: id:1741323218379, from:30112, delay:0.0001s, distance:152.90m (Euclidean)
[2025-03-07 13:53:49,260] [INFO] [30128] Received COMMIT: id:1741323218379, from:30144, delay:0.0000s, distance:145.33m (Euclidean)
[2025-03-07 13:53:49,497] [INFO] [30128] Received PREPARE: id:1741323218379, from:30126, delay:0.0000s, distance:249.63m (Euclidean)
[2025-03-07 13:53:49,522] [INFO] [30128] Received COMMIT: id:1741323218379, from:30112, delay:0.0001s, distance:152.90m (Euclidean)
[2025-03-07 13:53:49,741] [INFO] [30128] Received PREPARE: id:1741323218379, from:30148, delay:0.0002s, distance:282.47m (Euclidean)
[2025-03-07 13:53:49,762] [INFO] [30128] Received COMMIT: id:1741323218379, from:30148, delay:0.0002s, distance:282.47m (Euclidean)
[2025-03-07 13:53:50,019] [INFO] [30128] Received PREPARE: id:1741323218379, from:30114, delay:0.0002s, distance:296.63m (Euclidean)
[2025-03-07 13:53:50,037] [INFO] [30128] Received COMMIT: id:1741323218379, from:30114, delay:0.0002s, distance:296.63m (Euclidean)
[2025-03-07 13:53:50,175] [INFO] [30128] Received COMMIT: id:1741323218379, from:30126, delay:0.0000s, distance:249.63m (Euclidean)
[2025-03-07 13:53:50,303] [INFO] [30128] Received PREPARE: id:1741323218379, from:30130, delay:0.0000s, distance:131.84m (Euclidean)
[2025-03-07 13:53:50,316] [INFO] [30128] Received COMMIT: id:1741323218379, from:30130, delay:0.0000s, distance:131.84m (Euclidean)
[2025-03-07 13:53:50,949] [INFO] [30128] Received PREPARE: id:1741323218379, from:30121, delay:0.0000s, distance:138.27m (Euclidean)
[2025-03-07 13:53:50,965] [INFO] [30128] Received COMMIT: id:1741323218379, from:30000, delay:0.0000s, distance:162.97m (Euclidean)
[2025-03-07 13:53:50,965] [INFO] [30128] Received COMMIT: id:1741323218379, from:30015, delay:0.0001s, distance:217.88m (Euclidean)
[2025-03-07 13:53:50,965] [INFO] [30128] Received COMMIT: id:1741323218379, from:30121, delay:0.0000s, distance:138.27m (Euclidean)
[2025-03-07 13:53:50,965] [INFO] [30128] Received PREPARE: id:1741323218379, from:30015, delay:0.0001s, distance:217.88m (Euclidean)
[2025-03-07 13:53:51,020] [INFO] [30128] Received PREPARE: id:1741323218379, from:30118, delay:0.0000s, distance:149.30m (Euclidean)
[2025-03-07 13:53:51,171] [ERROR] [30128] Error sending to http://localhost:30071/prepare: Cannot connect to host localhost:30071 ssl:default [Connect call failed ('127.0.0.1', 30071)]
Traceback (most recent call last):
  File "D:\anaconda\envs\PBFT\lib\site-packages\aiohttp\connector.py", line 980, in _wrap_create_connection
    return await self._loop.create_connection(*args, **kwargs)  # type: ignore[return-value]  # noqa
  File "D:\anaconda\envs\PBFT\lib\asyncio\base_events.py", line 948, in create_connection
    raise exceptions[0]
  File "D:\anaconda\envs\PBFT\lib\asyncio\base_events.py", line 935, in create_connection
    await self.sock_connect(sock, address)
  File "D:\anaconda\envs\PBFT\lib\asyncio\selector_events.py", line 475, in sock_connect
    return await fut
  File "D:\anaconda\envs\PBFT\lib\asyncio\selector_events.py", line 505, in _sock_connect_cb
    raise OSError(err, f'Connect call failed {address}')
ConnectionRefusedError: [Errno 10061] Connect call failed ('127.0.0.1', 30071)

The above exception was the direct cause of the following exception:

Traceback (most recent call last):
  File "pbft.py", line 236, in send_message
    await send_with_delay(self.session, self.node_info, target, url, data, self.bandwidth_data)
  File "pbft.py", line 63, in send_with_delay
    async with session.post(url, json=data) as resp:
  File "D:\anaconda\envs\PBFT\lib\site-packages\aiohttp\client.py", line 1141, in __aenter__
    self._resp = await self._coro
  File "D:\anaconda\envs\PBFT\lib\site-packages\aiohttp\client.py", line 537, in _request
    req, traces=traces, timeout=real_timeout
  File "D:\anaconda\envs\PBFT\lib\site-packages\aiohttp\connector.py", line 540, in connect
    proto = await self._create_connection(req, traces, timeout)
  File "D:\anaconda\envs\PBFT\lib\site-packages\aiohttp\connector.py", line 901, in _create_connection
    _, proto = await self._create_direct_connection(req, traces, timeout)
  File "D:\anaconda\envs\PBFT\lib\site-packages\aiohttp\connector.py", line 1206, in _create_direct_connection
    raise last_exc
  File "D:\anaconda\envs\PBFT\lib\site-packages\aiohttp\connector.py", line 1187, in _create_direct_connection
    client_error=client_error,
  File "D:\anaconda\envs\PBFT\lib\site-packages\aiohttp\connector.py", line 988, in _wrap_create_connection
    raise client_error(req.connection_key, exc) from exc
aiohttp.client_exceptions.ClientConnectorError: Cannot connect to host localhost:30071 ssl:default [Connect call failed ('127.0.0.1', 30071)]
[2025-03-07 13:53:51,440] [ERROR] [30128] Error sending to http://localhost:30029/prepare: Cannot connect to host localhost:30029 ssl:default [Connect call failed ('127.0.0.1', 30029)]
Traceback (most recent call last):
  File "D:\anaconda\envs\PBFT\lib\site-packages\aiohttp\connector.py", line 980, in _wrap_create_connection
    return await self._loop.create_connection(*args, **kwargs)  # type: ignore[return-value]  # noqa
  File "D:\anaconda\envs\PBFT\lib\asyncio\base_events.py", line 948, in create_connection
    raise exceptions[0]
  File "D:\anaconda\envs\PBFT\lib\asyncio\base_events.py", line 935, in create_connection
    await self.sock_connect(sock, address)
  File "D:\anaconda\envs\PBFT\lib\asyncio\selector_events.py", line 475, in sock_connect
    return await fut
  File "D:\anaconda\envs\PBFT\lib\asyncio\selector_events.py", line 505, in _sock_connect_cb
    raise OSError(err, f'Connect call failed {address}')
ConnectionRefusedError: [Errno 10061] Connect call failed ('127.0.0.1', 30029)

The above exception was the direct cause of the following exception:

Traceback (most recent call last):
  File "pbft.py", line 236, in send_message
    await send_with_delay(self.session, self.node_info, target, url, data, self.bandwidth_data)
  File "pbft.py", line 63, in send_with_delay
    async with session.post(url, json=data) as resp:
  File "D:\anaconda\envs\PBFT\lib\site-packages\aiohttp\client.py", line 1141, in __aenter__
    self._resp = await self._coro
  File "D:\anaconda\envs\PBFT\lib\site-packages\aiohttp\client.py", line 537, in _request
    req, traces=traces, timeout=real_timeout
  File "D:\anaconda\envs\PBFT\lib\site-packages\aiohttp\connector.py", line 540, in connect
    proto = await self._create_connection(req, traces, timeout)
  File "D:\anaconda\envs\PBFT\lib\site-packages\aiohttp\connector.py", line 901, in _create_connection
    _, proto = await self._create_direct_connection(req, traces, timeout)
  File "D:\anaconda\envs\PBFT\lib\site-packages\aiohttp\connector.py", line 1206, in _create_direct_connection
    raise last_exc
  File "D:\anaconda\envs\PBFT\lib\site-packages\aiohttp\connector.py", line 1187, in _create_direct_connection
    client_error=client_error,
  File "D:\anaconda\envs\PBFT\lib\site-packages\aiohttp\connector.py", line 988, in _wrap_create_connection
    raise client_error(req.connection_key, exc) from exc
aiohttp.client_exceptions.ClientConnectorError: Cannot connect to host localhost:30029 ssl:default [Connect call failed ('127.0.0.1', 30029)]
[2025-03-07 13:53:51,519] [INFO] [30128] Received PREPARE: id:1741323218379, from:30119, delay:0.0002s, distance:256.90m (Euclidean)
[2025-03-07 13:53:51,519] [INFO] [30128] Received COMMIT: id:1741323218379, from:30119, delay:0.0002s, distance:256.90m (Euclidean)
[2025-03-07 13:53:51,551] [ERROR] [30128] Error sending to http://localhost:30066/prepare: Cannot connect to host localhost:30066 ssl:default [Connect call failed ('127.0.0.1', 30066)]
Traceback (most recent call last):
  File "D:\anaconda\envs\PBFT\lib\site-packages\aiohttp\connector.py", line 980, in _wrap_create_connection
    return await self._loop.create_connection(*args, **kwargs)  # type: ignore[return-value]  # noqa
  File "D:\anaconda\envs\PBFT\lib\asyncio\base_events.py", line 948, in create_connection
    raise exceptions[0]
  File "D:\anaconda\envs\PBFT\lib\asyncio\base_events.py", line 935, in create_connection
    await self.sock_connect(sock, address)
  File "D:\anaconda\envs\PBFT\lib\asyncio\selector_events.py", line 475, in sock_connect
    return await fut
  File "D:\anaconda\envs\PBFT\lib\asyncio\selector_events.py", line 505, in _sock_connect_cb
    raise OSError(err, f'Connect call failed {address}')
ConnectionRefusedError: [Errno 10061] Connect call failed ('127.0.0.1', 30066)

The above exception was the direct cause of the following exception:

Traceback (most recent call last):
  File "pbft.py", line 236, in send_message
    await send_with_delay(self.session, self.node_info, target, url, data, self.bandwidth_data)
  File "pbft.py", line 63, in send_with_delay
    async with session.post(url, json=data) as resp:
  File "D:\anaconda\envs\PBFT\lib\site-packages\aiohttp\client.py", line 1141, in __aenter__
    self._resp = await self._coro
  File "D:\anaconda\envs\PBFT\lib\site-packages\aiohttp\client.py", line 537, in _request
    req, traces=traces, timeout=real_timeout
  File "D:\anaconda\envs\PBFT\lib\site-packages\aiohttp\connector.py", line 540, in connect
    proto = await self._create_connection(req, traces, timeout)
  File "D:\anaconda\envs\PBFT\lib\site-packages\aiohttp\connector.py", line 901, in _create_connection
    _, proto = await self._create_direct_connection(req, traces, timeout)
  File "D:\anaconda\envs\PBFT\lib\site-packages\aiohttp\connector.py", line 1206, in _create_direct_connection
    raise last_exc
  File "D:\anaconda\envs\PBFT\lib\site-packages\aiohttp\connector.py", line 1187, in _create_direct_connection
    client_error=client_error,
  File "D:\anaconda\envs\PBFT\lib\site-packages\aiohttp\connector.py", line 988, in _wrap_create_connection
    raise client_error(req.connection_key, exc) from exc
aiohttp.client_exceptions.ClientConnectorError: Cannot connect to host localhost:30066 ssl:default [Connect call failed ('127.0.0.1', 30066)]
[2025-03-07 13:53:51,569] [ERROR] [30128] Error sending to http://localhost:30063/prepare: Cannot connect to host localhost:30063 ssl:default [Connect call failed ('127.0.0.1', 30063)]
Traceback (most recent call last):
  File "D:\anaconda\envs\PBFT\lib\site-packages\aiohttp\connector.py", line 980, in _wrap_create_connection
    return await self._loop.create_connection(*args, **kwargs)  # type: ignore[return-value]  # noqa
  File "D:\anaconda\envs\PBFT\lib\asyncio\base_events.py", line 948, in create_connection
    raise exceptions[0]
  File "D:\anaconda\envs\PBFT\lib\asyncio\base_events.py", line 935, in create_connection
    await self.sock_connect(sock, address)
  File "D:\anaconda\envs\PBFT\lib\asyncio\selector_events.py", line 475, in sock_connect
    return await fut
  File "D:\anaconda\envs\PBFT\lib\asyncio\selector_events.py", line 505, in _sock_connect_cb
    raise OSError(err, f'Connect call failed {address}')
ConnectionRefusedError: [Errno 10061] Connect call failed ('127.0.0.1', 30063)

The above exception was the direct cause of the following exception:

Traceback (most recent call last):
  File "pbft.py", line 236, in send_message
    await send_with_delay(self.session, self.node_info, target, url, data, self.bandwidth_data)
  File "pbft.py", line 63, in send_with_delay
    async with session.post(url, json=data) as resp:
  File "D:\anaconda\envs\PBFT\lib\site-packages\aiohttp\client.py", line 1141, in __aenter__
    self._resp = await self._coro
  File "D:\anaconda\envs\PBFT\lib\site-packages\aiohttp\client.py", line 537, in _request
    req, traces=traces, timeout=real_timeout
  File "D:\anaconda\envs\PBFT\lib\site-packages\aiohttp\connector.py", line 540, in connect
    proto = await self._create_connection(req, traces, timeout)
  File "D:\anaconda\envs\PBFT\lib\site-packages\aiohttp\connector.py", line 901, in _create_connection
    _, proto = await self._create_direct_connection(req, traces, timeout)
  File "D:\anaconda\envs\PBFT\lib\site-packages\aiohttp\connector.py", line 1206, in _create_direct_connection
    raise last_exc
  File "D:\anaconda\envs\PBFT\lib\site-packages\aiohttp\connector.py", line 1187, in _create_direct_connection
    client_error=client_error,
  File "D:\anaconda\envs\PBFT\lib\site-packages\aiohttp\connector.py", line 988, in _wrap_create_connection
    raise client_error(req.connection_key, exc) from exc
aiohttp.client_exceptions.ClientConnectorError: Cannot connect to host localhost:30063 ssl:default [Connect call failed ('127.0.0.1', 30063)]
[2025-03-07 13:53:51,803] [ERROR] [30128] Error sending to http://localhost:30023/prepare: Cannot connect to host localhost:30023 ssl:default [Connect call failed ('127.0.0.1', 30023)]
Traceback (most recent call last):
  File "D:\anaconda\envs\PBFT\lib\site-packages\aiohttp\connector.py", line 980, in _wrap_create_connection
    return await self._loop.create_connection(*args, **kwargs)  # type: ignore[return-value]  # noqa
  File "D:\anaconda\envs\PBFT\lib\asyncio\base_events.py", line 948, in create_connection
    raise exceptions[0]
  File "D:\anaconda\envs\PBFT\lib\asyncio\base_events.py", line 935, in create_connection
    await self.sock_connect(sock, address)
  File "D:\anaconda\envs\PBFT\lib\asyncio\selector_events.py", line 475, in sock_connect
    return await fut
  File "D:\anaconda\envs\PBFT\lib\asyncio\selector_events.py", line 505, in _sock_connect_cb
    raise OSError(err, f'Connect call failed {address}')
ConnectionRefusedError: [Errno 10061] Connect call failed ('127.0.0.1', 30023)

The above exception was the direct cause of the following exception:

Traceback (most recent call last):
  File "pbft.py", line 236, in send_message
    await send_with_delay(self.session, self.node_info, target, url, data, self.bandwidth_data)
  File "pbft.py", line 63, in send_with_delay
    async with session.post(url, json=data) as resp:
  File "D:\anaconda\envs\PBFT\lib\site-packages\aiohttp\client.py", line 1141, in __aenter__
    self._resp = await self._coro
  File "D:\anaconda\envs\PBFT\lib\site-packages\aiohttp\client.py", line 537, in _request
    req, traces=traces, timeout=real_timeout
  File "D:\anaconda\envs\PBFT\lib\site-packages\aiohttp\connector.py", line 540, in connect
    proto = await self._create_connection(req, traces, timeout)
  File "D:\anaconda\envs\PBFT\lib\site-packages\aiohttp\connector.py", line 901, in _create_connection
    _, proto = await self._create_direct_connection(req, traces, timeout)
  File "D:\anaconda\envs\PBFT\lib\site-packages\aiohttp\connector.py", line 1206, in _create_direct_connection
    raise last_exc
  File "D:\anaconda\envs\PBFT\lib\site-packages\aiohttp\connector.py", line 1187, in _create_direct_connection
    client_error=client_error,
  File "D:\anaconda\envs\PBFT\lib\site-packages\aiohttp\connector.py", line 988, in _wrap_create_connection
    raise client_error(req.connection_key, exc) from exc
aiohttp.client_exceptions.ClientConnectorError: Cannot connect to host localhost:30023 ssl:default [Connect call failed ('127.0.0.1', 30023)]
[2025-03-07 13:53:51,819] [ERROR] [30128] Error sending to http://localhost:30023/commit: Cannot connect to host localhost:30023 ssl:default [Connect call failed ('::1', 30023, 0, 0)]
Traceback (most recent call last):
  File "D:\anaconda\envs\PBFT\lib\site-packages\aiohttp\connector.py", line 980, in _wrap_create_connection
    return await self._loop.create_connection(*args, **kwargs)  # type: ignore[return-value]  # noqa
  File "D:\anaconda\envs\PBFT\lib\asyncio\base_events.py", line 948, in create_connection
    raise exceptions[0]
  File "D:\anaconda\envs\PBFT\lib\asyncio\base_events.py", line 935, in create_connection
    await self.sock_connect(sock, address)
  File "D:\anaconda\envs\PBFT\lib\asyncio\selector_events.py", line 475, in sock_connect
    return await fut
  File "D:\anaconda\envs\PBFT\lib\asyncio\selector_events.py", line 505, in _sock_connect_cb
    raise OSError(err, f'Connect call failed {address}')
ConnectionRefusedError: [Errno 10061] Connect call failed ('::1', 30023, 0, 0)

The above exception was the direct cause of the following exception:

Traceback (most recent call last):
  File "pbft.py", line 236, in send_message
    await send_with_delay(self.session, self.node_info, target, url, data, self.bandwidth_data)
  File "pbft.py", line 63, in send_with_delay
    async with session.post(url, json=data) as resp:
  File "D:\anaconda\envs\PBFT\lib\site-packages\aiohttp\client.py", line 1141, in __aenter__
    self._resp = await self._coro
  File "D:\anaconda\envs\PBFT\lib\site-packages\aiohttp\client.py", line 537, in _request
    req, traces=traces, timeout=real_timeout
  File "D:\anaconda\envs\PBFT\lib\site-packages\aiohttp\connector.py", line 540, in connect
    proto = await self._create_connection(req, traces, timeout)
  File "D:\anaconda\envs\PBFT\lib\site-packages\aiohttp\connector.py", line 901, in _create_connection
    _, proto = await self._create_direct_connection(req, traces, timeout)
  File "D:\anaconda\envs\PBFT\lib\site-packages\aiohttp\connector.py", line 1206, in _create_direct_connection
    raise last_exc
  File "D:\anaconda\envs\PBFT\lib\site-packages\aiohttp\connector.py", line 1187, in _create_direct_connection
    client_error=client_error,
  File "D:\anaconda\envs\PBFT\lib\site-packages\aiohttp\connector.py", line 988, in _wrap_create_connection
    raise client_error(req.connection_key, exc) from exc
aiohttp.client_exceptions.ClientConnectorError: Cannot connect to host localhost:30023 ssl:default [Connect call failed ('::1', 30023, 0, 0)]
[2025-03-07 13:53:51,835] [ERROR] [30128] Error sending to http://localhost:30065/prepare: Cannot connect to host localhost:30065 ssl:default [Connect call failed ('127.0.0.1', 30065)]
Traceback (most recent call last):
  File "D:\anaconda\envs\PBFT\lib\site-packages\aiohttp\connector.py", line 980, in _wrap_create_connection
    return await self._loop.create_connection(*args, **kwargs)  # type: ignore[return-value]  # noqa
  File "D:\anaconda\envs\PBFT\lib\asyncio\base_events.py", line 948, in create_connection
    raise exceptions[0]
  File "D:\anaconda\envs\PBFT\lib\asyncio\base_events.py", line 935, in create_connection
    await self.sock_connect(sock, address)
  File "D:\anaconda\envs\PBFT\lib\asyncio\selector_events.py", line 475, in sock_connect
    return await fut
  File "D:\anaconda\envs\PBFT\lib\asyncio\selector_events.py", line 505, in _sock_connect_cb
    raise OSError(err, f'Connect call failed {address}')
ConnectionRefusedError: [Errno 10061] Connect call failed ('127.0.0.1', 30065)

The above exception was the direct cause of the following exception:

Traceback (most recent call last):
  File "pbft.py", line 236, in send_message
    await send_with_delay(self.session, self.node_info, target, url, data, self.bandwidth_data)
  File "pbft.py", line 63, in send_with_delay
    async with session.post(url, json=data) as resp:
  File "D:\anaconda\envs\PBFT\lib\site-packages\aiohttp\client.py", line 1141, in __aenter__
    self._resp = await self._coro
  File "D:\anaconda\envs\PBFT\lib\site-packages\aiohttp\client.py", line 537, in _request
    req, traces=traces, timeout=real_timeout
  File "D:\anaconda\envs\PBFT\lib\site-packages\aiohttp\connector.py", line 540, in connect
    proto = await self._create_connection(req, traces, timeout)
  File "D:\anaconda\envs\PBFT\lib\site-packages\aiohttp\connector.py", line 901, in _create_connection
    _, proto = await self._create_direct_connection(req, traces, timeout)
  File "D:\anaconda\envs\PBFT\lib\site-packages\aiohttp\connector.py", line 1206, in _create_direct_connection
    raise last_exc
  File "D:\anaconda\envs\PBFT\lib\site-packages\aiohttp\connector.py", line 1187, in _create_direct_connection
    client_error=client_error,
  File "D:\anaconda\envs\PBFT\lib\site-packages\aiohttp\connector.py", line 988, in _wrap_create_connection
    raise client_error(req.connection_key, exc) from exc
aiohttp.client_exceptions.ClientConnectorError: Cannot connect to host localhost:30065 ssl:default [Connect call failed ('127.0.0.1', 30065)]
[2025-03-07 13:53:51,882] [INFO] [30128] Received PREPARE: id:1741323218379, from:30116, delay:0.0002s, distance:265.79m (Euclidean)
[2025-03-07 13:53:51,882] [INFO] [30128] Received COMMIT: id:1741323218379, from:30116, delay:0.0002s, distance:265.79m (Euclidean)
[2025-03-07 13:53:52,024] [ERROR] [30128] Error sending to http://localhost:30025/prepare: Cannot connect to host localhost:30025 ssl:default [Connect call failed ('127.0.0.1', 30025)]
Traceback (most recent call last):
  File "D:\anaconda\envs\PBFT\lib\site-packages\aiohttp\connector.py", line 980, in _wrap_create_connection
    return await self._loop.create_connection(*args, **kwargs)  # type: ignore[return-value]  # noqa
  File "D:\anaconda\envs\PBFT\lib\asyncio\base_events.py", line 948, in create_connection
    raise exceptions[0]
  File "D:\anaconda\envs\PBFT\lib\asyncio\base_events.py", line 935, in create_connection
    await self.sock_connect(sock, address)
  File "D:\anaconda\envs\PBFT\lib\asyncio\selector_events.py", line 475, in sock_connect
    return await fut
  File "D:\anaconda\envs\PBFT\lib\asyncio\selector_events.py", line 505, in _sock_connect_cb
    raise OSError(err, f'Connect call failed {address}')
ConnectionRefusedError: [Errno 10061] Connect call failed ('127.0.0.1', 30025)

The above exception was the direct cause of the following exception:

Traceback (most recent call last):
  File "pbft.py", line 236, in send_message
    await send_with_delay(self.session, self.node_info, target, url, data, self.bandwidth_data)
  File "pbft.py", line 63, in send_with_delay
    async with session.post(url, json=data) as resp:
  File "D:\anaconda\envs\PBFT\lib\site-packages\aiohttp\client.py", line 1141, in __aenter__
    self._resp = await self._coro
  File "D:\anaconda\envs\PBFT\lib\site-packages\aiohttp\client.py", line 537, in _request
    req, traces=traces, timeout=real_timeout
  File "D:\anaconda\envs\PBFT\lib\site-packages\aiohttp\connector.py", line 540, in connect
    proto = await self._create_connection(req, traces, timeout)
  File "D:\anaconda\envs\PBFT\lib\site-packages\aiohttp\connector.py", line 901, in _create_connection
    _, proto = await self._create_direct_connection(req, traces, timeout)
  File "D:\anaconda\envs\PBFT\lib\site-packages\aiohttp\connector.py", line 1206, in _create_direct_connection
    raise last_exc
  File "D:\anaconda\envs\PBFT\lib\site-packages\aiohttp\connector.py", line 1187, in _create_direct_connection
    client_error=client_error,
  File "D:\anaconda\envs\PBFT\lib\site-packages\aiohttp\connector.py", line 988, in _wrap_create_connection
    raise client_error(req.connection_key, exc) from exc
aiohttp.client_exceptions.ClientConnectorError: Cannot connect to host localhost:30025 ssl:default [Connect call failed ('127.0.0.1', 30025)]
[2025-03-07 13:53:52,024] [ERROR] [30128] Error sending to http://localhost:30027/prepare: Cannot connect to host localhost:30027 ssl:default [Connect call failed ('127.0.0.1', 30027)]
Traceback (most recent call last):
  File "D:\anaconda\envs\PBFT\lib\site-packages\aiohttp\connector.py", line 980, in _wrap_create_connection
    return await self._loop.create_connection(*args, **kwargs)  # type: ignore[return-value]  # noqa
  File "D:\anaconda\envs\PBFT\lib\asyncio\base_events.py", line 948, in create_connection
    raise exceptions[0]
  File "D:\anaconda\envs\PBFT\lib\asyncio\base_events.py", line 935, in create_connection
    await self.sock_connect(sock, address)
  File "D:\anaconda\envs\PBFT\lib\asyncio\selector_events.py", line 475, in sock_connect
    return await fut
  File "D:\anaconda\envs\PBFT\lib\asyncio\selector_events.py", line 505, in _sock_connect_cb
    raise OSError(err, f'Connect call failed {address}')
ConnectionRefusedError: [Errno 10061] Connect call failed ('127.0.0.1', 30027)

The above exception was the direct cause of the following exception:

Traceback (most recent call last):
  File "pbft.py", line 236, in send_message
    await send_with_delay(self.session, self.node_info, target, url, data, self.bandwidth_data)
  File "pbft.py", line 63, in send_with_delay
    async with session.post(url, json=data) as resp:
  File "D:\anaconda\envs\PBFT\lib\site-packages\aiohttp\client.py", line 1141, in __aenter__
    self._resp = await self._coro
  File "D:\anaconda\envs\PBFT\lib\site-packages\aiohttp\client.py", line 537, in _request
    req, traces=traces, timeout=real_timeout
  File "D:\anaconda\envs\PBFT\lib\site-packages\aiohttp\connector.py", line 540, in connect
    proto = await self._create_connection(req, traces, timeout)
  File "D:\anaconda\envs\PBFT\lib\site-packages\aiohttp\connector.py", line 901, in _create_connection
    _, proto = await self._create_direct_connection(req, traces, timeout)
  File "D:\anaconda\envs\PBFT\lib\site-packages\aiohttp\connector.py", line 1206, in _create_direct_connection
    raise last_exc
  File "D:\anaconda\envs\PBFT\lib\site-packages\aiohttp\connector.py", line 1187, in _create_direct_connection
    client_error=client_error,
  File "D:\anaconda\envs\PBFT\lib\site-packages\aiohttp\connector.py", line 988, in _wrap_create_connection
    raise client_error(req.connection_key, exc) from exc
aiohttp.client_exceptions.ClientConnectorError: Cannot connect to host localhost:30027 ssl:default [Connect call failed ('127.0.0.1', 30027)]
[2025-03-07 13:53:52,024] [ERROR] [30128] Error sending to http://localhost:30027/commit: Cannot connect to host localhost:30027 ssl:default [Connect call failed ('::1', 30027, 0, 0)]
Traceback (most recent call last):
  File "D:\anaconda\envs\PBFT\lib\site-packages\aiohttp\connector.py", line 980, in _wrap_create_connection
    return await self._loop.create_connection(*args, **kwargs)  # type: ignore[return-value]  # noqa
  File "D:\anaconda\envs\PBFT\lib\asyncio\base_events.py", line 948, in create_connection
    raise exceptions[0]
  File "D:\anaconda\envs\PBFT\lib\asyncio\base_events.py", line 935, in create_connection
    await self.sock_connect(sock, address)
  File "D:\anaconda\envs\PBFT\lib\asyncio\selector_events.py", line 475, in sock_connect
    return await fut
  File "D:\anaconda\envs\PBFT\lib\asyncio\selector_events.py", line 505, in _sock_connect_cb
    raise OSError(err, f'Connect call failed {address}')
ConnectionRefusedError: [Errno 10061] Connect call failed ('::1', 30027, 0, 0)

The above exception was the direct cause of the following exception:

Traceback (most recent call last):
  File "pbft.py", line 236, in send_message
    await send_with_delay(self.session, self.node_info, target, url, data, self.bandwidth_data)
  File "pbft.py", line 63, in send_with_delay
    async with session.post(url, json=data) as resp:
  File "D:\anaconda\envs\PBFT\lib\site-packages\aiohttp\client.py", line 1141, in __aenter__
    self._resp = await self._coro
  File "D:\anaconda\envs\PBFT\lib\site-packages\aiohttp\client.py", line 537, in _request
    req, traces=traces, timeout=real_timeout
  File "D:\anaconda\envs\PBFT\lib\site-packages\aiohttp\connector.py", line 540, in connect
    proto = await self._create_connection(req, traces, timeout)
  File "D:\anaconda\envs\PBFT\lib\site-packages\aiohttp\connector.py", line 901, in _create_connection
    _, proto = await self._create_direct_connection(req, traces, timeout)
  File "D:\anaconda\envs\PBFT\lib\site-packages\aiohttp\connector.py", line 1206, in _create_direct_connection
    raise last_exc
  File "D:\anaconda\envs\PBFT\lib\site-packages\aiohttp\connector.py", line 1187, in _create_direct_connection
    client_error=client_error,
  File "D:\anaconda\envs\PBFT\lib\site-packages\aiohttp\connector.py", line 988, in _wrap_create_connection
    raise client_error(req.connection_key, exc) from exc
aiohttp.client_exceptions.ClientConnectorError: Cannot connect to host localhost:30027 ssl:default [Connect call failed ('::1', 30027, 0, 0)]
[2025-03-07 13:53:52,236] [ERROR] [30128] Error sending to http://localhost:30066/commit: Cannot connect to host localhost:30066 ssl:default [Connect call failed ('::1', 30066, 0, 0)]
Traceback (most recent call last):
  File "D:\anaconda\envs\PBFT\lib\site-packages\aiohttp\connector.py", line 980, in _wrap_create_connection
    return await self._loop.create_connection(*args, **kwargs)  # type: ignore[return-value]  # noqa
  File "D:\anaconda\envs\PBFT\lib\asyncio\base_events.py", line 948, in create_connection
    raise exceptions[0]
  File "D:\anaconda\envs\PBFT\lib\asyncio\base_events.py", line 935, in create_connection
    await self.sock_connect(sock, address)
  File "D:\anaconda\envs\PBFT\lib\asyncio\selector_events.py", line 475, in sock_connect
    return await fut
  File "D:\anaconda\envs\PBFT\lib\asyncio\selector_events.py", line 505, in _sock_connect_cb
    raise OSError(err, f'Connect call failed {address}')
ConnectionRefusedError: [Errno 10061] Connect call failed ('::1', 30066, 0, 0)

The above exception was the direct cause of the following exception:

Traceback (most recent call last):
  File "pbft.py", line 236, in send_message
    await send_with_delay(self.session, self.node_info, target, url, data, self.bandwidth_data)
  File "pbft.py", line 63, in send_with_delay
    async with session.post(url, json=data) as resp:
  File "D:\anaconda\envs\PBFT\lib\site-packages\aiohttp\client.py", line 1141, in __aenter__
    self._resp = await self._coro
  File "D:\anaconda\envs\PBFT\lib\site-packages\aiohttp\client.py", line 537, in _request
    req, traces=traces, timeout=real_timeout
  File "D:\anaconda\envs\PBFT\lib\site-packages\aiohttp\connector.py", line 540, in connect
    proto = await self._create_connection(req, traces, timeout)
  File "D:\anaconda\envs\PBFT\lib\site-packages\aiohttp\connector.py", line 901, in _create_connection
    _, proto = await self._create_direct_connection(req, traces, timeout)
  File "D:\anaconda\envs\PBFT\lib\site-packages\aiohttp\connector.py", line 1206, in _create_direct_connection
    raise last_exc
  File "D:\anaconda\envs\PBFT\lib\site-packages\aiohttp\connector.py", line 1187, in _create_direct_connection
    client_error=client_error,
  File "D:\anaconda\envs\PBFT\lib\site-packages\aiohttp\connector.py", line 988, in _wrap_create_connection
    raise client_error(req.connection_key, exc) from exc
aiohttp.client_exceptions.ClientConnectorError: Cannot connect to host localhost:30066 ssl:default [Connect call failed ('::1', 30066, 0, 0)]
[2025-03-07 13:53:52,242] [ERROR] [30128] Error sending to http://localhost:30063/commit: Cannot connect to host localhost:30063 ssl:default [Connect call failed ('::1', 30063, 0, 0)]
Traceback (most recent call last):
  File "D:\anaconda\envs\PBFT\lib\site-packages\aiohttp\connector.py", line 980, in _wrap_create_connection
    return await self._loop.create_connection(*args, **kwargs)  # type: ignore[return-value]  # noqa
  File "D:\anaconda\envs\PBFT\lib\asyncio\base_events.py", line 948, in create_connection
    raise exceptions[0]
  File "D:\anaconda\envs\PBFT\lib\asyncio\base_events.py", line 935, in create_connection
    await self.sock_connect(sock, address)
  File "D:\anaconda\envs\PBFT\lib\asyncio\selector_events.py", line 475, in sock_connect
    return await fut
  File "D:\anaconda\envs\PBFT\lib\asyncio\selector_events.py", line 505, in _sock_connect_cb
    raise OSError(err, f'Connect call failed {address}')
ConnectionRefusedError: [Errno 10061] Connect call failed ('::1', 30063, 0, 0)

The above exception was the direct cause of the following exception:

Traceback (most recent call last):
  File "pbft.py", line 236, in send_message
    await send_with_delay(self.session, self.node_info, target, url, data, self.bandwidth_data)
  File "pbft.py", line 63, in send_with_delay
    async with session.post(url, json=data) as resp:
  File "D:\anaconda\envs\PBFT\lib\site-packages\aiohttp\client.py", line 1141, in __aenter__
    self._resp = await self._coro
  File "D:\anaconda\envs\PBFT\lib\site-packages\aiohttp\client.py", line 537, in _request
    req, traces=traces, timeout=real_timeout
  File "D:\anaconda\envs\PBFT\lib\site-packages\aiohttp\connector.py", line 540, in connect
    proto = await self._create_connection(req, traces, timeout)
  File "D:\anaconda\envs\PBFT\lib\site-packages\aiohttp\connector.py", line 901, in _create_connection
    _, proto = await self._create_direct_connection(req, traces, timeout)
  File "D:\anaconda\envs\PBFT\lib\site-packages\aiohttp\connector.py", line 1206, in _create_direct_connection
    raise last_exc
  File "D:\anaconda\envs\PBFT\lib\site-packages\aiohttp\connector.py", line 1187, in _create_direct_connection
    client_error=client_error,
  File "D:\anaconda\envs\PBFT\lib\site-packages\aiohttp\connector.py", line 988, in _wrap_create_connection
    raise client_error(req.connection_key, exc) from exc
aiohttp.client_exceptions.ClientConnectorError: Cannot connect to host localhost:30063 ssl:default [Connect call failed ('::1', 30063, 0, 0)]
[2025-03-07 13:53:52,291] [ERROR] [30128] Error sending to http://localhost:30038/prepare: Cannot connect to host localhost:30038 ssl:default [Connect call failed ('127.0.0.1', 30038)]
Traceback (most recent call last):
  File "D:\anaconda\envs\PBFT\lib\site-packages\aiohttp\connector.py", line 980, in _wrap_create_connection
    return await self._loop.create_connection(*args, **kwargs)  # type: ignore[return-value]  # noqa
  File "D:\anaconda\envs\PBFT\lib\asyncio\base_events.py", line 948, in create_connection
    raise exceptions[0]
  File "D:\anaconda\envs\PBFT\lib\asyncio\base_events.py", line 935, in create_connection
    await self.sock_connect(sock, address)
  File "D:\anaconda\envs\PBFT\lib\asyncio\selector_events.py", line 475, in sock_connect
    return await fut
  File "D:\anaconda\envs\PBFT\lib\asyncio\selector_events.py", line 505, in _sock_connect_cb
    raise OSError(err, f'Connect call failed {address}')
ConnectionRefusedError: [Errno 10061] Connect call failed ('127.0.0.1', 30038)

The above exception was the direct cause of the following exception:

Traceback (most recent call last):
  File "pbft.py", line 236, in send_message
    await send_with_delay(self.session, self.node_info, target, url, data, self.bandwidth_data)
  File "pbft.py", line 63, in send_with_delay
    async with session.post(url, json=data) as resp:
  File "D:\anaconda\envs\PBFT\lib\site-packages\aiohttp\client.py", line 1141, in __aenter__
    self._resp = await self._coro
  File "D:\anaconda\envs\PBFT\lib\site-packages\aiohttp\client.py", line 537, in _request
    req, traces=traces, timeout=real_timeout
  File "D:\anaconda\envs\PBFT\lib\site-packages\aiohttp\connector.py", line 540, in connect
    proto = await self._create_connection(req, traces, timeout)
  File "D:\anaconda\envs\PBFT\lib\site-packages\aiohttp\connector.py", line 901, in _create_connection
    _, proto = await self._create_direct_connection(req, traces, timeout)
  File "D:\anaconda\envs\PBFT\lib\site-packages\aiohttp\connector.py", line 1206, in _create_direct_connection
    raise last_exc
  File "D:\anaconda\envs\PBFT\lib\site-packages\aiohttp\connector.py", line 1187, in _create_direct_connection
    client_error=client_error,
  File "D:\anaconda\envs\PBFT\lib\site-packages\aiohttp\connector.py", line 988, in _wrap_create_connection
    raise client_error(req.connection_key, exc) from exc
aiohttp.client_exceptions.ClientConnectorError: Cannot connect to host localhost:30038 ssl:default [Connect call failed ('127.0.0.1', 30038)]
[2025-03-07 13:53:52,359] [INFO] [30128] Received PREPARE: id:1741323218379, from:30129, delay:0.0001s, distance:201.18m (Euclidean)
[2025-03-07 13:53:52,359] [INFO] [30128] Received COMMIT: id:1741323218379, from:30129, delay:0.0001s, distance:201.18m (Euclidean)
[2025-03-07 13:53:52,434] [INFO] [30128] Received PREPARE: id:1741323218379, from:30127, delay:0.0001s, distance:186.29m (Euclidean)
[2025-03-07 13:53:52,481] [ERROR] [30128] Error sending to http://localhost:30075/prepare: Cannot connect to host localhost:30075 ssl:default [Connect call failed ('127.0.0.1', 30075)]
Traceback (most recent call last):
  File "D:\anaconda\envs\PBFT\lib\site-packages\aiohttp\connector.py", line 980, in _wrap_create_connection
    return await self._loop.create_connection(*args, **kwargs)  # type: ignore[return-value]  # noqa
  File "D:\anaconda\envs\PBFT\lib\asyncio\base_events.py", line 948, in create_connection
    raise exceptions[0]
  File "D:\anaconda\envs\PBFT\lib\asyncio\base_events.py", line 935, in create_connection
    await self.sock_connect(sock, address)
  File "D:\anaconda\envs\PBFT\lib\asyncio\selector_events.py", line 475, in sock_connect
    return await fut
  File "D:\anaconda\envs\PBFT\lib\asyncio\selector_events.py", line 505, in _sock_connect_cb
    raise OSError(err, f'Connect call failed {address}')
ConnectionRefusedError: [Errno 10061] Connect call failed ('127.0.0.1', 30075)

The above exception was the direct cause of the following exception:

Traceback (most recent call last):
  File "pbft.py", line 236, in send_message
    await send_with_delay(self.session, self.node_info, target, url, data, self.bandwidth_data)
  File "pbft.py", line 63, in send_with_delay
    async with session.post(url, json=data) as resp:
  File "D:\anaconda\envs\PBFT\lib\site-packages\aiohttp\client.py", line 1141, in __aenter__
    self._resp = await self._coro
  File "D:\anaconda\envs\PBFT\lib\site-packages\aiohttp\client.py", line 537, in _request
    req, traces=traces, timeout=real_timeout
  File "D:\anaconda\envs\PBFT\lib\site-packages\aiohttp\connector.py", line 540, in connect
    proto = await self._create_connection(req, traces, timeout)
  File "D:\anaconda\envs\PBFT\lib\site-packages\aiohttp\connector.py", line 901, in _create_connection
    _, proto = await self._create_direct_connection(req, traces, timeout)
  File "D:\anaconda\envs\PBFT\lib\site-packages\aiohttp\connector.py", line 1206, in _create_direct_connection
    raise last_exc
  File "D:\anaconda\envs\PBFT\lib\site-packages\aiohttp\connector.py", line 1187, in _create_direct_connection
    client_error=client_error,
  File "D:\anaconda\envs\PBFT\lib\site-packages\aiohttp\connector.py", line 988, in _wrap_create_connection
    raise client_error(req.connection_key, exc) from exc
aiohttp.client_exceptions.ClientConnectorError: Cannot connect to host localhost:30075 ssl:default [Connect call failed ('127.0.0.1', 30075)]
[2025-03-07 13:53:52,528] [ERROR] [30128] Error sending to http://localhost:30138/prepare: Cannot connect to host localhost:30138 ssl:default [Connect call failed ('127.0.0.1', 30138)]
Traceback (most recent call last):
  File "D:\anaconda\envs\PBFT\lib\site-packages\aiohttp\connector.py", line 980, in _wrap_create_connection
    return await self._loop.create_connection(*args, **kwargs)  # type: ignore[return-value]  # noqa
  File "D:\anaconda\envs\PBFT\lib\asyncio\base_events.py", line 948, in create_connection
    raise exceptions[0]
  File "D:\anaconda\envs\PBFT\lib\asyncio\base_events.py", line 935, in create_connection
    await self.sock_connect(sock, address)
  File "D:\anaconda\envs\PBFT\lib\asyncio\selector_events.py", line 475, in sock_connect
    return await fut
  File "D:\anaconda\envs\PBFT\lib\asyncio\selector_events.py", line 505, in _sock_connect_cb
    raise OSError(err, f'Connect call failed {address}')
ConnectionRefusedError: [Errno 10061] Connect call failed ('127.0.0.1', 30138)

The above exception was the direct cause of the following exception:

Traceback (most recent call last):
  File "pbft.py", line 236, in send_message
    await send_with_delay(self.session, self.node_info, target, url, data, self.bandwidth_data)
  File "pbft.py", line 63, in send_with_delay
    async with session.post(url, json=data) as resp:
  File "D:\anaconda\envs\PBFT\lib\site-packages\aiohttp\client.py", line 1141, in __aenter__
    self._resp = await self._coro
  File "D:\anaconda\envs\PBFT\lib\site-packages\aiohttp\client.py", line 537, in _request
    req, traces=traces, timeout=real_timeout
  File "D:\anaconda\envs\PBFT\lib\site-packages\aiohttp\connector.py", line 540, in connect
    proto = await self._create_connection(req, traces, timeout)
  File "D:\anaconda\envs\PBFT\lib\site-packages\aiohttp\connector.py", line 901, in _create_connection
    _, proto = await self._create_direct_connection(req, traces, timeout)
  File "D:\anaconda\envs\PBFT\lib\site-packages\aiohttp\connector.py", line 1206, in _create_direct_connection
    raise last_exc
  File "D:\anaconda\envs\PBFT\lib\site-packages\aiohttp\connector.py", line 1187, in _create_direct_connection
    client_error=client_error,
  File "D:\anaconda\envs\PBFT\lib\site-packages\aiohttp\connector.py", line 988, in _wrap_create_connection
    raise client_error(req.connection_key, exc) from exc
aiohttp.client_exceptions.ClientConnectorError: Cannot connect to host localhost:30138 ssl:default [Connect call failed ('127.0.0.1', 30138)]
[2025-03-07 13:53:52,544] [ERROR] [30128] Error sending to http://localhost:30140/prepare: Cannot connect to host localhost:30140 ssl:default [Connect call failed ('127.0.0.1', 30140)]
Traceback (most recent call last):
  File "D:\anaconda\envs\PBFT\lib\site-packages\aiohttp\connector.py", line 980, in _wrap_create_connection
    return await self._loop.create_connection(*args, **kwargs)  # type: ignore[return-value]  # noqa
  File "D:\anaconda\envs\PBFT\lib\asyncio\base_events.py", line 948, in create_connection
    raise exceptions[0]
  File "D:\anaconda\envs\PBFT\lib\asyncio\base_events.py", line 935, in create_connection
    await self.sock_connect(sock, address)
  File "D:\anaconda\envs\PBFT\lib\asyncio\selector_events.py", line 475, in sock_connect
    return await fut
  File "D:\anaconda\envs\PBFT\lib\asyncio\selector_events.py", line 505, in _sock_connect_cb
    raise OSError(err, f'Connect call failed {address}')
ConnectionRefusedError: [Errno 10061] Connect call failed ('127.0.0.1', 30140)

The above exception was the direct cause of the following exception:

Traceback (most recent call last):
  File "pbft.py", line 236, in send_message
    await send_with_delay(self.session, self.node_info, target, url, data, self.bandwidth_data)
  File "pbft.py", line 63, in send_with_delay
    async with session.post(url, json=data) as resp:
  File "D:\anaconda\envs\PBFT\lib\site-packages\aiohttp\client.py", line 1141, in __aenter__
    self._resp = await self._coro
  File "D:\anaconda\envs\PBFT\lib\site-packages\aiohttp\client.py", line 537, in _request
    req, traces=traces, timeout=real_timeout
  File "D:\anaconda\envs\PBFT\lib\site-packages\aiohttp\connector.py", line 540, in connect
    proto = await self._create_connection(req, traces, timeout)
  File "D:\anaconda\envs\PBFT\lib\site-packages\aiohttp\connector.py", line 901, in _create_connection
    _, proto = await self._create_direct_connection(req, traces, timeout)
  File "D:\anaconda\envs\PBFT\lib\site-packages\aiohttp\connector.py", line 1206, in _create_direct_connection
    raise last_exc
  File "D:\anaconda\envs\PBFT\lib\site-packages\aiohttp\connector.py", line 1187, in _create_direct_connection
    client_error=client_error,
  File "D:\anaconda\envs\PBFT\lib\site-packages\aiohttp\connector.py", line 988, in _wrap_create_connection
    raise client_error(req.connection_key, exc) from exc
aiohttp.client_exceptions.ClientConnectorError: Cannot connect to host localhost:30140 ssl:default [Connect call failed ('127.0.0.1', 30140)]
[2025-03-07 13:53:52,544] [ERROR] [30128] Error sending to http://localhost:30065/commit: Cannot connect to host localhost:30065 ssl:default [Connect call failed ('::1', 30065, 0, 0)]
Traceback (most recent call last):
  File "D:\anaconda\envs\PBFT\lib\site-packages\aiohttp\connector.py", line 980, in _wrap_create_connection
    return await self._loop.create_connection(*args, **kwargs)  # type: ignore[return-value]  # noqa
  File "D:\anaconda\envs\PBFT\lib\asyncio\base_events.py", line 948, in create_connection
    raise exceptions[0]
  File "D:\anaconda\envs\PBFT\lib\asyncio\base_events.py", line 935, in create_connection
    await self.sock_connect(sock, address)
  File "D:\anaconda\envs\PBFT\lib\asyncio\selector_events.py", line 475, in sock_connect
    return await fut
  File "D:\anaconda\envs\PBFT\lib\asyncio\selector_events.py", line 505, in _sock_connect_cb
    raise OSError(err, f'Connect call failed {address}')
ConnectionRefusedError: [Errno 10061] Connect call failed ('::1', 30065, 0, 0)

The above exception was the direct cause of the following exception:

Traceback (most recent call last):
  File "pbft.py", line 236, in send_message
    await send_with_delay(self.session, self.node_info, target, url, data, self.bandwidth_data)
  File "pbft.py", line 63, in send_with_delay
    async with session.post(url, json=data) as resp:
  File "D:\anaconda\envs\PBFT\lib\site-packages\aiohttp\client.py", line 1141, in __aenter__
    self._resp = await self._coro
  File "D:\anaconda\envs\PBFT\lib\site-packages\aiohttp\client.py", line 537, in _request
    req, traces=traces, timeout=real_timeout
  File "D:\anaconda\envs\PBFT\lib\site-packages\aiohttp\connector.py", line 540, in connect
    proto = await self._create_connection(req, traces, timeout)
  File "D:\anaconda\envs\PBFT\lib\site-packages\aiohttp\connector.py", line 901, in _create_connection
    _, proto = await self._create_direct_connection(req, traces, timeout)
  File "D:\anaconda\envs\PBFT\lib\site-packages\aiohttp\connector.py", line 1206, in _create_direct_connection
    raise last_exc
  File "D:\anaconda\envs\PBFT\lib\site-packages\aiohttp\connector.py", line 1187, in _create_direct_connection
    client_error=client_error,
  File "D:\anaconda\envs\PBFT\lib\site-packages\aiohttp\connector.py", line 988, in _wrap_create_connection
    raise client_error(req.connection_key, exc) from exc
aiohttp.client_exceptions.ClientConnectorError: Cannot connect to host localhost:30065 ssl:default [Connect call failed ('::1', 30065, 0, 0)]
[2025-03-07 13:53:52,547] [ERROR] [30128] Error sending to http://localhost:30071/commit: Cannot connect to host localhost:30071 ssl:default [Connect call failed ('::1', 30071, 0, 0)]
Traceback (most recent call last):
  File "D:\anaconda\envs\PBFT\lib\site-packages\aiohttp\connector.py", line 980, in _wrap_create_connection
    return await self._loop.create_connection(*args, **kwargs)  # type: ignore[return-value]  # noqa
  File "D:\anaconda\envs\PBFT\lib\asyncio\base_events.py", line 948, in create_connection
    raise exceptions[0]
  File "D:\anaconda\envs\PBFT\lib\asyncio\base_events.py", line 935, in create_connection
    await self.sock_connect(sock, address)
  File "D:\anaconda\envs\PBFT\lib\asyncio\selector_events.py", line 475, in sock_connect
    return await fut
  File "D:\anaconda\envs\PBFT\lib\asyncio\selector_events.py", line 505, in _sock_connect_cb
    raise OSError(err, f'Connect call failed {address}')
ConnectionRefusedError: [Errno 10061] Connect call failed ('::1', 30071, 0, 0)

The above exception was the direct cause of the following exception:

Traceback (most recent call last):
  File "pbft.py", line 236, in send_message
    await send_with_delay(self.session, self.node_info, target, url, data, self.bandwidth_data)
  File "pbft.py", line 63, in send_with_delay
    async with session.post(url, json=data) as resp:
  File "D:\anaconda\envs\PBFT\lib\site-packages\aiohttp\client.py", line 1141, in __aenter__
    self._resp = await self._coro
  File "D:\anaconda\envs\PBFT\lib\site-packages\aiohttp\client.py", line 537, in _request
    req, traces=traces, timeout=real_timeout
  File "D:\anaconda\envs\PBFT\lib\site-packages\aiohttp\connector.py", line 540, in connect
    proto = await self._create_connection(req, traces, timeout)
  File "D:\anaconda\envs\PBFT\lib\site-packages\aiohttp\connector.py", line 901, in _create_connection
    _, proto = await self._create_direct_connection(req, traces, timeout)
  File "D:\anaconda\envs\PBFT\lib\site-packages\aiohttp\connector.py", line 1206, in _create_direct_connection
    raise last_exc
  File "D:\anaconda\envs\PBFT\lib\site-packages\aiohttp\connector.py", line 1187, in _create_direct_connection
    client_error=client_error,
  File "D:\anaconda\envs\PBFT\lib\site-packages\aiohttp\connector.py", line 988, in _wrap_create_connection
    raise client_error(req.connection_key, exc) from exc
aiohttp.client_exceptions.ClientConnectorError: Cannot connect to host localhost:30071 ssl:default [Connect call failed ('::1', 30071, 0, 0)]
[2025-03-07 13:53:52,547] [ERROR] [30128] Error sending to http://localhost:30124/commit: Cannot connect to host localhost:30124 ssl:default [Connect call failed ('::1', 30124, 0, 0)]
Traceback (most recent call last):
  File "D:\anaconda\envs\PBFT\lib\site-packages\aiohttp\connector.py", line 980, in _wrap_create_connection
    return await self._loop.create_connection(*args, **kwargs)  # type: ignore[return-value]  # noqa
  File "D:\anaconda\envs\PBFT\lib\asyncio\base_events.py", line 948, in create_connection
    raise exceptions[0]
  File "D:\anaconda\envs\PBFT\lib\asyncio\base_events.py", line 935, in create_connection
    await self.sock_connect(sock, address)
  File "D:\anaconda\envs\PBFT\lib\asyncio\selector_events.py", line 475, in sock_connect
    return await fut
  File "D:\anaconda\envs\PBFT\lib\asyncio\selector_events.py", line 505, in _sock_connect_cb
    raise OSError(err, f'Connect call failed {address}')
ConnectionRefusedError: [Errno 10061] Connect call failed ('::1', 30124, 0, 0)

The above exception was the direct cause of the following exception:

Traceback (most recent call last):
  File "pbft.py", line 236, in send_message
    await send_with_delay(self.session, self.node_info, target, url, data, self.bandwidth_data)
  File "pbft.py", line 63, in send_with_delay
    async with session.post(url, json=data) as resp:
  File "D:\anaconda\envs\PBFT\lib\site-packages\aiohttp\client.py", line 1141, in __aenter__
    self._resp = await self._coro
  File "D:\anaconda\envs\PBFT\lib\site-packages\aiohttp\client.py", line 537, in _request
    req, traces=traces, timeout=real_timeout
  File "D:\anaconda\envs\PBFT\lib\site-packages\aiohttp\connector.py", line 540, in connect
    proto = await self._create_connection(req, traces, timeout)
  File "D:\anaconda\envs\PBFT\lib\site-packages\aiohttp\connector.py", line 901, in _create_connection
    _, proto = await self._create_direct_connection(req, traces, timeout)
  File "D:\anaconda\envs\PBFT\lib\site-packages\aiohttp\connector.py", line 1206, in _create_direct_connection
    raise last_exc
  File "D:\anaconda\envs\PBFT\lib\site-packages\aiohttp\connector.py", line 1187, in _create_direct_connection
    client_error=client_error,
  File "D:\anaconda\envs\PBFT\lib\site-packages\aiohttp\connector.py", line 988, in _wrap_create_connection
    raise client_error(req.connection_key, exc) from exc
aiohttp.client_exceptions.ClientConnectorError: Cannot connect to host localhost:30124 ssl:default [Connect call failed ('::1', 30124, 0, 0)]
[2025-03-07 13:53:52,560] [ERROR] [30128] Error sending to http://localhost:30124/prepare: Cannot connect to host localhost:30124 ssl:default [Connect call failed ('127.0.0.1', 30124)]
Traceback (most recent call last):
  File "D:\anaconda\envs\PBFT\lib\site-packages\aiohttp\connector.py", line 980, in _wrap_create_connection
    return await self._loop.create_connection(*args, **kwargs)  # type: ignore[return-value]  # noqa
  File "D:\anaconda\envs\PBFT\lib\asyncio\base_events.py", line 948, in create_connection
    raise exceptions[0]
  File "D:\anaconda\envs\PBFT\lib\asyncio\base_events.py", line 935, in create_connection
    await self.sock_connect(sock, address)
  File "D:\anaconda\envs\PBFT\lib\asyncio\selector_events.py", line 475, in sock_connect
    return await fut
  File "D:\anaconda\envs\PBFT\lib\asyncio\selector_events.py", line 505, in _sock_connect_cb
    raise OSError(err, f'Connect call failed {address}')
ConnectionRefusedError: [Errno 10061] Connect call failed ('127.0.0.1', 30124)

The above exception was the direct cause of the following exception:

Traceback (most recent call last):
  File "pbft.py", line 236, in send_message
    await send_with_delay(self.session, self.node_info, target, url, data, self.bandwidth_data)
  File "pbft.py", line 63, in send_with_delay
    async with session.post(url, json=data) as resp:
  File "D:\anaconda\envs\PBFT\lib\site-packages\aiohttp\client.py", line 1141, in __aenter__
    self._resp = await self._coro
  File "D:\anaconda\envs\PBFT\lib\site-packages\aiohttp\client.py", line 537, in _request
    req, traces=traces, timeout=real_timeout
  File "D:\anaconda\envs\PBFT\lib\site-packages\aiohttp\connector.py", line 540, in connect
    proto = await self._create_connection(req, traces, timeout)
  File "D:\anaconda\envs\PBFT\lib\site-packages\aiohttp\connector.py", line 901, in _create_connection
    _, proto = await self._create_direct_connection(req, traces, timeout)
  File "D:\anaconda\envs\PBFT\lib\site-packages\aiohttp\connector.py", line 1206, in _create_direct_connection
    raise last_exc
  File "D:\anaconda\envs\PBFT\lib\site-packages\aiohttp\connector.py", line 1187, in _create_direct_connection
    client_error=client_error,
  File "D:\anaconda\envs\PBFT\lib\site-packages\aiohttp\connector.py", line 988, in _wrap_create_connection
    raise client_error(req.connection_key, exc) from exc
aiohttp.client_exceptions.ClientConnectorError: Cannot connect to host localhost:30124 ssl:default [Connect call failed ('127.0.0.1', 30124)]
[2025-03-07 13:53:52,608] [INFO] [30128] Received COMMIT: id:1741323218379, from:30118, delay:0.0000s, distance:149.30m (Euclidean)
[2025-03-07 13:53:52,623] [ERROR] [30128] Error sending to http://localhost:30076/prepare: Cannot connect to host localhost:30076 ssl:default [Connect call failed ('127.0.0.1', 30076)]
Traceback (most recent call last):
  File "D:\anaconda\envs\PBFT\lib\site-packages\aiohttp\connector.py", line 980, in _wrap_create_connection
    return await self._loop.create_connection(*args, **kwargs)  # type: ignore[return-value]  # noqa
  File "D:\anaconda\envs\PBFT\lib\asyncio\base_events.py", line 948, in create_connection
    raise exceptions[0]
  File "D:\anaconda\envs\PBFT\lib\asyncio\base_events.py", line 935, in create_connection
    await self.sock_connect(sock, address)
  File "D:\anaconda\envs\PBFT\lib\asyncio\selector_events.py", line 475, in sock_connect
    return await fut
  File "D:\anaconda\envs\PBFT\lib\asyncio\selector_events.py", line 505, in _sock_connect_cb
    raise OSError(err, f'Connect call failed {address}')
ConnectionRefusedError: [Errno 10061] Connect call failed ('127.0.0.1', 30076)

The above exception was the direct cause of the following exception:

Traceback (most recent call last):
  File "pbft.py", line 236, in send_message
    await send_with_delay(self.session, self.node_info, target, url, data, self.bandwidth_data)
  File "pbft.py", line 63, in send_with_delay
    async with session.post(url, json=data) as resp:
  File "D:\anaconda\envs\PBFT\lib\site-packages\aiohttp\client.py", line 1141, in __aenter__
    self._resp = await self._coro
  File "D:\anaconda\envs\PBFT\lib\site-packages\aiohttp\client.py", line 537, in _request
    req, traces=traces, timeout=real_timeout
  File "D:\anaconda\envs\PBFT\lib\site-packages\aiohttp\connector.py", line 540, in connect
    proto = await self._create_connection(req, traces, timeout)
  File "D:\anaconda\envs\PBFT\lib\site-packages\aiohttp\connector.py", line 901, in _create_connection
    _, proto = await self._create_direct_connection(req, traces, timeout)
  File "D:\anaconda\envs\PBFT\lib\site-packages\aiohttp\connector.py", line 1206, in _create_direct_connection
    raise last_exc
  File "D:\anaconda\envs\PBFT\lib\site-packages\aiohttp\connector.py", line 1187, in _create_direct_connection
    client_error=client_error,
  File "D:\anaconda\envs\PBFT\lib\site-packages\aiohttp\connector.py", line 988, in _wrap_create_connection
    raise client_error(req.connection_key, exc) from exc
aiohttp.client_exceptions.ClientConnectorError: Cannot connect to host localhost:30076 ssl:default [Connect call failed ('127.0.0.1', 30076)]
[2025-03-07 13:53:52,623] [ERROR] [30128] Error sending to http://localhost:30075/commit: Cannot connect to host localhost:30075 ssl:default [Connect call failed ('::1', 30075, 0, 0)]
Traceback (most recent call last):
  File "D:\anaconda\envs\PBFT\lib\site-packages\aiohttp\connector.py", line 980, in _wrap_create_connection
    return await self._loop.create_connection(*args, **kwargs)  # type: ignore[return-value]  # noqa
  File "D:\anaconda\envs\PBFT\lib\asyncio\base_events.py", line 948, in create_connection
    raise exceptions[0]
  File "D:\anaconda\envs\PBFT\lib\asyncio\base_events.py", line 935, in create_connection
    await self.sock_connect(sock, address)
  File "D:\anaconda\envs\PBFT\lib\asyncio\selector_events.py", line 475, in sock_connect
    return await fut
  File "D:\anaconda\envs\PBFT\lib\asyncio\selector_events.py", line 505, in _sock_connect_cb
    raise OSError(err, f'Connect call failed {address}')
ConnectionRefusedError: [Errno 10061] Connect call failed ('::1', 30075, 0, 0)

The above exception was the direct cause of the following exception:

Traceback (most recent call last):
  File "pbft.py", line 236, in send_message
    await send_with_delay(self.session, self.node_info, target, url, data, self.bandwidth_data)
  File "pbft.py", line 63, in send_with_delay
    async with session.post(url, json=data) as resp:
  File "D:\anaconda\envs\PBFT\lib\site-packages\aiohttp\client.py", line 1141, in __aenter__
    self._resp = await self._coro
  File "D:\anaconda\envs\PBFT\lib\site-packages\aiohttp\client.py", line 537, in _request
    req, traces=traces, timeout=real_timeout
  File "D:\anaconda\envs\PBFT\lib\site-packages\aiohttp\connector.py", line 540, in connect
    proto = await self._create_connection(req, traces, timeout)
  File "D:\anaconda\envs\PBFT\lib\site-packages\aiohttp\connector.py", line 901, in _create_connection
    _, proto = await self._create_direct_connection(req, traces, timeout)
  File "D:\anaconda\envs\PBFT\lib\site-packages\aiohttp\connector.py", line 1206, in _create_direct_connection
    raise last_exc
  File "D:\anaconda\envs\PBFT\lib\site-packages\aiohttp\connector.py", line 1187, in _create_direct_connection
    client_error=client_error,
  File "D:\anaconda\envs\PBFT\lib\site-packages\aiohttp\connector.py", line 988, in _wrap_create_connection
    raise client_error(req.connection_key, exc) from exc
aiohttp.client_exceptions.ClientConnectorError: Cannot connect to host localhost:30075 ssl:default [Connect call failed ('::1', 30075, 0, 0)]
[2025-03-07 13:53:52,639] [ERROR] [30128] Error sending to http://localhost:30038/commit: Cannot connect to host localhost:30038 ssl:default [Connect call failed ('::1', 30038, 0, 0)]
Traceback (most recent call last):
  File "D:\anaconda\envs\PBFT\lib\site-packages\aiohttp\connector.py", line 980, in _wrap_create_connection
    return await self._loop.create_connection(*args, **kwargs)  # type: ignore[return-value]  # noqa
  File "D:\anaconda\envs\PBFT\lib\asyncio\base_events.py", line 948, in create_connection
    raise exceptions[0]
  File "D:\anaconda\envs\PBFT\lib\asyncio\base_events.py", line 935, in create_connection
    await self.sock_connect(sock, address)
  File "D:\anaconda\envs\PBFT\lib\asyncio\selector_events.py", line 475, in sock_connect
    return await fut
  File "D:\anaconda\envs\PBFT\lib\asyncio\selector_events.py", line 505, in _sock_connect_cb
    raise OSError(err, f'Connect call failed {address}')
ConnectionRefusedError: [Errno 10061] Connect call failed ('::1', 30038, 0, 0)

The above exception was the direct cause of the following exception:

Traceback (most recent call last):
  File "pbft.py", line 236, in send_message
    await send_with_delay(self.session, self.node_info, target, url, data, self.bandwidth_data)
  File "pbft.py", line 63, in send_with_delay
    async with session.post(url, json=data) as resp:
  File "D:\anaconda\envs\PBFT\lib\site-packages\aiohttp\client.py", line 1141, in __aenter__
    self._resp = await self._coro
  File "D:\anaconda\envs\PBFT\lib\site-packages\aiohttp\client.py", line 537, in _request
    req, traces=traces, timeout=real_timeout
  File "D:\anaconda\envs\PBFT\lib\site-packages\aiohttp\connector.py", line 540, in connect
    proto = await self._create_connection(req, traces, timeout)
  File "D:\anaconda\envs\PBFT\lib\site-packages\aiohttp\connector.py", line 901, in _create_connection
    _, proto = await self._create_direct_connection(req, traces, timeout)
  File "D:\anaconda\envs\PBFT\lib\site-packages\aiohttp\connector.py", line 1206, in _create_direct_connection
    raise last_exc
  File "D:\anaconda\envs\PBFT\lib\site-packages\aiohttp\connector.py", line 1187, in _create_direct_connection
    client_error=client_error,
  File "D:\anaconda\envs\PBFT\lib\site-packages\aiohttp\connector.py", line 988, in _wrap_create_connection
    raise client_error(req.connection_key, exc) from exc
aiohttp.client_exceptions.ClientConnectorError: Cannot connect to host localhost:30038 ssl:default [Connect call failed ('::1', 30038, 0, 0)]
[2025-03-07 13:53:52,673] [ERROR] [30128] Error sending to http://localhost:30125/prepare: Cannot connect to host localhost:30125 ssl:default [Connect call failed ('127.0.0.1', 30125)]
Traceback (most recent call last):
  File "D:\anaconda\envs\PBFT\lib\site-packages\aiohttp\connector.py", line 980, in _wrap_create_connection
    return await self._loop.create_connection(*args, **kwargs)  # type: ignore[return-value]  # noqa
  File "D:\anaconda\envs\PBFT\lib\asyncio\base_events.py", line 948, in create_connection
    raise exceptions[0]
  File "D:\anaconda\envs\PBFT\lib\asyncio\base_events.py", line 935, in create_connection
    await self.sock_connect(sock, address)
  File "D:\anaconda\envs\PBFT\lib\asyncio\selector_events.py", line 475, in sock_connect
    return await fut
  File "D:\anaconda\envs\PBFT\lib\asyncio\selector_events.py", line 505, in _sock_connect_cb
    raise OSError(err, f'Connect call failed {address}')
ConnectionRefusedError: [Errno 10061] Connect call failed ('127.0.0.1', 30125)

The above exception was the direct cause of the following exception:

Traceback (most recent call last):
  File "pbft.py", line 236, in send_message
    await send_with_delay(self.session, self.node_info, target, url, data, self.bandwidth_data)
  File "pbft.py", line 63, in send_with_delay
    async with session.post(url, json=data) as resp:
  File "D:\anaconda\envs\PBFT\lib\site-packages\aiohttp\client.py", line 1141, in __aenter__
    self._resp = await self._coro
  File "D:\anaconda\envs\PBFT\lib\site-packages\aiohttp\client.py", line 537, in _request
    req, traces=traces, timeout=real_timeout
  File "D:\anaconda\envs\PBFT\lib\site-packages\aiohttp\connector.py", line 540, in connect
    proto = await self._create_connection(req, traces, timeout)
  File "D:\anaconda\envs\PBFT\lib\site-packages\aiohttp\connector.py", line 901, in _create_connection
    _, proto = await self._create_direct_connection(req, traces, timeout)
  File "D:\anaconda\envs\PBFT\lib\site-packages\aiohttp\connector.py", line 1206, in _create_direct_connection
    raise last_exc
  File "D:\anaconda\envs\PBFT\lib\site-packages\aiohttp\connector.py", line 1187, in _create_direct_connection
    client_error=client_error,
  File "D:\anaconda\envs\PBFT\lib\site-packages\aiohttp\connector.py", line 988, in _wrap_create_connection
    raise client_error(req.connection_key, exc) from exc
aiohttp.client_exceptions.ClientConnectorError: Cannot connect to host localhost:30125 ssl:default [Connect call failed ('127.0.0.1', 30125)]
[2025-03-07 13:53:52,687] [ERROR] [30128] Error sending to http://localhost:30125/commit: Cannot connect to host localhost:30125 ssl:default [Connect call failed ('::1', 30125, 0, 0)]
Traceback (most recent call last):
  File "D:\anaconda\envs\PBFT\lib\site-packages\aiohttp\connector.py", line 980, in _wrap_create_connection
    return await self._loop.create_connection(*args, **kwargs)  # type: ignore[return-value]  # noqa
  File "D:\anaconda\envs\PBFT\lib\asyncio\base_events.py", line 948, in create_connection
    raise exceptions[0]
  File "D:\anaconda\envs\PBFT\lib\asyncio\base_events.py", line 935, in create_connection
    await self.sock_connect(sock, address)
  File "D:\anaconda\envs\PBFT\lib\asyncio\selector_events.py", line 475, in sock_connect
    return await fut
  File "D:\anaconda\envs\PBFT\lib\asyncio\selector_events.py", line 505, in _sock_connect_cb
    raise OSError(err, f'Connect call failed {address}')
ConnectionRefusedError: [Errno 10061] Connect call failed ('::1', 30125, 0, 0)

The above exception was the direct cause of the following exception:

Traceback (most recent call last):
  File "pbft.py", line 236, in send_message
    await send_with_delay(self.session, self.node_info, target, url, data, self.bandwidth_data)
  File "pbft.py", line 63, in send_with_delay
    async with session.post(url, json=data) as resp:
  File "D:\anaconda\envs\PBFT\lib\site-packages\aiohttp\client.py", line 1141, in __aenter__
    self._resp = await self._coro
  File "D:\anaconda\envs\PBFT\lib\site-packages\aiohttp\client.py", line 537, in _request
    req, traces=traces, timeout=real_timeout
  File "D:\anaconda\envs\PBFT\lib\site-packages\aiohttp\connector.py", line 540, in connect
    proto = await self._create_connection(req, traces, timeout)
  File "D:\anaconda\envs\PBFT\lib\site-packages\aiohttp\connector.py", line 901, in _create_connection
    _, proto = await self._create_direct_connection(req, traces, timeout)
  File "D:\anaconda\envs\PBFT\lib\site-packages\aiohttp\connector.py", line 1206, in _create_direct_connection
    raise last_exc
  File "D:\anaconda\envs\PBFT\lib\site-packages\aiohttp\connector.py", line 1187, in _create_direct_connection
    client_error=client_error,
  File "D:\anaconda\envs\PBFT\lib\site-packages\aiohttp\connector.py", line 988, in _wrap_create_connection
    raise client_error(req.connection_key, exc) from exc
aiohttp.client_exceptions.ClientConnectorError: Cannot connect to host localhost:30125 ssl:default [Connect call failed ('::1', 30125, 0, 0)]
[2025-03-07 13:53:52,719] [ERROR] [30128] Error sending to http://localhost:30138/commit: Cannot connect to host localhost:30138 ssl:default [Connect call failed ('::1', 30138, 0, 0)]
Traceback (most recent call last):
  File "D:\anaconda\envs\PBFT\lib\site-packages\aiohttp\connector.py", line 980, in _wrap_create_connection
    return await self._loop.create_connection(*args, **kwargs)  # type: ignore[return-value]  # noqa
  File "D:\anaconda\envs\PBFT\lib\asyncio\base_events.py", line 948, in create_connection
    raise exceptions[0]
  File "D:\anaconda\envs\PBFT\lib\asyncio\base_events.py", line 935, in create_connection
    await self.sock_connect(sock, address)
  File "D:\anaconda\envs\PBFT\lib\asyncio\selector_events.py", line 475, in sock_connect
    return await fut
  File "D:\anaconda\envs\PBFT\lib\asyncio\selector_events.py", line 505, in _sock_connect_cb
    raise OSError(err, f'Connect call failed {address}')
ConnectionRefusedError: [Errno 10061] Connect call failed ('::1', 30138, 0, 0)

The above exception was the direct cause of the following exception:

Traceback (most recent call last):
  File "pbft.py", line 236, in send_message
    await send_with_delay(self.session, self.node_info, target, url, data, self.bandwidth_data)
  File "pbft.py", line 63, in send_with_delay
    async with session.post(url, json=data) as resp:
  File "D:\anaconda\envs\PBFT\lib\site-packages\aiohttp\client.py", line 1141, in __aenter__
    self._resp = await self._coro
  File "D:\anaconda\envs\PBFT\lib\site-packages\aiohttp\client.py", line 537, in _request
    req, traces=traces, timeout=real_timeout
  File "D:\anaconda\envs\PBFT\lib\site-packages\aiohttp\connector.py", line 540, in connect
    proto = await self._create_connection(req, traces, timeout)
  File "D:\anaconda\envs\PBFT\lib\site-packages\aiohttp\connector.py", line 901, in _create_connection
    _, proto = await self._create_direct_connection(req, traces, timeout)
  File "D:\anaconda\envs\PBFT\lib\site-packages\aiohttp\connector.py", line 1206, in _create_direct_connection
    raise last_exc
  File "D:\anaconda\envs\PBFT\lib\site-packages\aiohttp\connector.py", line 1187, in _create_direct_connection
    client_error=client_error,
  File "D:\anaconda\envs\PBFT\lib\site-packages\aiohttp\connector.py", line 988, in _wrap_create_connection
    raise client_error(req.connection_key, exc) from exc
aiohttp.client_exceptions.ClientConnectorError: Cannot connect to host localhost:30138 ssl:default [Connect call failed ('::1', 30138, 0, 0)]
[2025-03-07 13:53:52,720] [ERROR] [30128] Error sending to http://localhost:30140/commit: Cannot connect to host localhost:30140 ssl:default [Connect call failed ('::1', 30140, 0, 0)]
Traceback (most recent call last):
  File "D:\anaconda\envs\PBFT\lib\site-packages\aiohttp\connector.py", line 980, in _wrap_create_connection
    return await self._loop.create_connection(*args, **kwargs)  # type: ignore[return-value]  # noqa
  File "D:\anaconda\envs\PBFT\lib\asyncio\base_events.py", line 948, in create_connection
    raise exceptions[0]
  File "D:\anaconda\envs\PBFT\lib\asyncio\base_events.py", line 935, in create_connection
    await self.sock_connect(sock, address)
  File "D:\anaconda\envs\PBFT\lib\asyncio\selector_events.py", line 475, in sock_connect
    return await fut
  File "D:\anaconda\envs\PBFT\lib\asyncio\selector_events.py", line 505, in _sock_connect_cb
    raise OSError(err, f'Connect call failed {address}')
ConnectionRefusedError: [Errno 10061] Connect call failed ('::1', 30140, 0, 0)

The above exception was the direct cause of the following exception:

Traceback (most recent call last):
  File "pbft.py", line 236, in send_message
    await send_with_delay(self.session, self.node_info, target, url, data, self.bandwidth_data)
  File "pbft.py", line 63, in send_with_delay
    async with session.post(url, json=data) as resp:
  File "D:\anaconda\envs\PBFT\lib\site-packages\aiohttp\client.py", line 1141, in __aenter__
    self._resp = await self._coro
  File "D:\anaconda\envs\PBFT\lib\site-packages\aiohttp\client.py", line 537, in _request
    req, traces=traces, timeout=real_timeout
  File "D:\anaconda\envs\PBFT\lib\site-packages\aiohttp\connector.py", line 540, in connect
    proto = await self._create_connection(req, traces, timeout)
  File "D:\anaconda\envs\PBFT\lib\site-packages\aiohttp\connector.py", line 901, in _create_connection
    _, proto = await self._create_direct_connection(req, traces, timeout)
  File "D:\anaconda\envs\PBFT\lib\site-packages\aiohttp\connector.py", line 1206, in _create_direct_connection
    raise last_exc
  File "D:\anaconda\envs\PBFT\lib\site-packages\aiohttp\connector.py", line 1187, in _create_direct_connection
    client_error=client_error,
  File "D:\anaconda\envs\PBFT\lib\site-packages\aiohttp\connector.py", line 988, in _wrap_create_connection
    raise client_error(req.connection_key, exc) from exc
aiohttp.client_exceptions.ClientConnectorError: Cannot connect to host localhost:30140 ssl:default [Connect call failed ('::1', 30140, 0, 0)]
[2025-03-07 13:53:52,751] [ERROR] [30128] Error sending to http://localhost:30029/commit: Cannot connect to host localhost:30029 ssl:default [Connect call failed ('::1', 30029, 0, 0)]
Traceback (most recent call last):
  File "D:\anaconda\envs\PBFT\lib\site-packages\aiohttp\connector.py", line 980, in _wrap_create_connection
    return await self._loop.create_connection(*args, **kwargs)  # type: ignore[return-value]  # noqa
  File "D:\anaconda\envs\PBFT\lib\asyncio\base_events.py", line 948, in create_connection
    raise exceptions[0]
  File "D:\anaconda\envs\PBFT\lib\asyncio\base_events.py", line 935, in create_connection
    await self.sock_connect(sock, address)
  File "D:\anaconda\envs\PBFT\lib\asyncio\selector_events.py", line 475, in sock_connect
    return await fut
  File "D:\anaconda\envs\PBFT\lib\asyncio\selector_events.py", line 505, in _sock_connect_cb
    raise OSError(err, f'Connect call failed {address}')
ConnectionRefusedError: [Errno 10061] Connect call failed ('::1', 30029, 0, 0)

The above exception was the direct cause of the following exception:

Traceback (most recent call last):
  File "pbft.py", line 236, in send_message
    await send_with_delay(self.session, self.node_info, target, url, data, self.bandwidth_data)
  File "pbft.py", line 63, in send_with_delay
    async with session.post(url, json=data) as resp:
  File "D:\anaconda\envs\PBFT\lib\site-packages\aiohttp\client.py", line 1141, in __aenter__
    self._resp = await self._coro
  File "D:\anaconda\envs\PBFT\lib\site-packages\aiohttp\client.py", line 537, in _request
    req, traces=traces, timeout=real_timeout
  File "D:\anaconda\envs\PBFT\lib\site-packages\aiohttp\connector.py", line 540, in connect
    proto = await self._create_connection(req, traces, timeout)
  File "D:\anaconda\envs\PBFT\lib\site-packages\aiohttp\connector.py", line 901, in _create_connection
    _, proto = await self._create_direct_connection(req, traces, timeout)
  File "D:\anaconda\envs\PBFT\lib\site-packages\aiohttp\connector.py", line 1206, in _create_direct_connection
    raise last_exc
  File "D:\anaconda\envs\PBFT\lib\site-packages\aiohttp\connector.py", line 1187, in _create_direct_connection
    client_error=client_error,
  File "D:\anaconda\envs\PBFT\lib\site-packages\aiohttp\connector.py", line 988, in _wrap_create_connection
    raise client_error(req.connection_key, exc) from exc
aiohttp.client_exceptions.ClientConnectorError: Cannot connect to host localhost:30029 ssl:default [Connect call failed ('::1', 30029, 0, 0)]
[2025-03-07 13:53:52,783] [ERROR] [30128] Error sending to http://localhost:30103/prepare: Cannot connect to host localhost:30103 ssl:default [Connect call failed ('127.0.0.1', 30103)]
Traceback (most recent call last):
  File "D:\anaconda\envs\PBFT\lib\site-packages\aiohttp\connector.py", line 980, in _wrap_create_connection
    return await self._loop.create_connection(*args, **kwargs)  # type: ignore[return-value]  # noqa
  File "D:\anaconda\envs\PBFT\lib\asyncio\base_events.py", line 948, in create_connection
    raise exceptions[0]
  File "D:\anaconda\envs\PBFT\lib\asyncio\base_events.py", line 935, in create_connection
    await self.sock_connect(sock, address)
  File "D:\anaconda\envs\PBFT\lib\asyncio\selector_events.py", line 475, in sock_connect
    return await fut
  File "D:\anaconda\envs\PBFT\lib\asyncio\selector_events.py", line 505, in _sock_connect_cb
    raise OSError(err, f'Connect call failed {address}')
ConnectionRefusedError: [Errno 10061] Connect call failed ('127.0.0.1', 30103)

The above exception was the direct cause of the following exception:

Traceback (most recent call last):
  File "pbft.py", line 236, in send_message
    await send_with_delay(self.session, self.node_info, target, url, data, self.bandwidth_data)
  File "pbft.py", line 63, in send_with_delay
    async with session.post(url, json=data) as resp:
  File "D:\anaconda\envs\PBFT\lib\site-packages\aiohttp\client.py", line 1141, in __aenter__
    self._resp = await self._coro
  File "D:\anaconda\envs\PBFT\lib\site-packages\aiohttp\client.py", line 537, in _request
    req, traces=traces, timeout=real_timeout
  File "D:\anaconda\envs\PBFT\lib\site-packages\aiohttp\connector.py", line 540, in connect
    proto = await self._create_connection(req, traces, timeout)
  File "D:\anaconda\envs\PBFT\lib\site-packages\aiohttp\connector.py", line 901, in _create_connection
    _, proto = await self._create_direct_connection(req, traces, timeout)
  File "D:\anaconda\envs\PBFT\lib\site-packages\aiohttp\connector.py", line 1206, in _create_direct_connection
    raise last_exc
  File "D:\anaconda\envs\PBFT\lib\site-packages\aiohttp\connector.py", line 1187, in _create_direct_connection
    client_error=client_error,
  File "D:\anaconda\envs\PBFT\lib\site-packages\aiohttp\connector.py", line 988, in _wrap_create_connection
    raise client_error(req.connection_key, exc) from exc
aiohttp.client_exceptions.ClientConnectorError: Cannot connect to host localhost:30103 ssl:default [Connect call failed ('127.0.0.1', 30103)]
[2025-03-07 13:53:52,800] [ERROR] [30128] Error sending to http://localhost:30141/prepare: Cannot connect to host localhost:30141 ssl:default [Connect call failed ('127.0.0.1', 30141)]
Traceback (most recent call last):
  File "D:\anaconda\envs\PBFT\lib\site-packages\aiohttp\connector.py", line 980, in _wrap_create_connection
    return await self._loop.create_connection(*args, **kwargs)  # type: ignore[return-value]  # noqa
  File "D:\anaconda\envs\PBFT\lib\asyncio\base_events.py", line 948, in create_connection
    raise exceptions[0]
  File "D:\anaconda\envs\PBFT\lib\asyncio\base_events.py", line 935, in create_connection
    await self.sock_connect(sock, address)
  File "D:\anaconda\envs\PBFT\lib\asyncio\selector_events.py", line 475, in sock_connect
    return await fut
  File "D:\anaconda\envs\PBFT\lib\asyncio\selector_events.py", line 505, in _sock_connect_cb
    raise OSError(err, f'Connect call failed {address}')
ConnectionRefusedError: [Errno 10061] Connect call failed ('127.0.0.1', 30141)

The above exception was the direct cause of the following exception:

Traceback (most recent call last):
  File "pbft.py", line 236, in send_message
    await send_with_delay(self.session, self.node_info, target, url, data, self.bandwidth_data)
  File "pbft.py", line 63, in send_with_delay
    async with session.post(url, json=data) as resp:
  File "D:\anaconda\envs\PBFT\lib\site-packages\aiohttp\client.py", line 1141, in __aenter__
    self._resp = await self._coro
  File "D:\anaconda\envs\PBFT\lib\site-packages\aiohttp\client.py", line 537, in _request
    req, traces=traces, timeout=real_timeout
  File "D:\anaconda\envs\PBFT\lib\site-packages\aiohttp\connector.py", line 540, in connect
    proto = await self._create_connection(req, traces, timeout)
  File "D:\anaconda\envs\PBFT\lib\site-packages\aiohttp\connector.py", line 901, in _create_connection
    _, proto = await self._create_direct_connection(req, traces, timeout)
  File "D:\anaconda\envs\PBFT\lib\site-packages\aiohttp\connector.py", line 1206, in _create_direct_connection
    raise last_exc
  File "D:\anaconda\envs\PBFT\lib\site-packages\aiohttp\connector.py", line 1187, in _create_direct_connection
    client_error=client_error,
  File "D:\anaconda\envs\PBFT\lib\site-packages\aiohttp\connector.py", line 988, in _wrap_create_connection
    raise client_error(req.connection_key, exc) from exc
aiohttp.client_exceptions.ClientConnectorError: Cannot connect to host localhost:30141 ssl:default [Connect call failed ('127.0.0.1', 30141)]
[2025-03-07 13:53:52,800] [ERROR] [30128] Error sending to http://localhost:30076/commit: Cannot connect to host localhost:30076 ssl:default [Connect call failed ('::1', 30076, 0, 0)]
Traceback (most recent call last):
  File "D:\anaconda\envs\PBFT\lib\site-packages\aiohttp\connector.py", line 980, in _wrap_create_connection
    return await self._loop.create_connection(*args, **kwargs)  # type: ignore[return-value]  # noqa
  File "D:\anaconda\envs\PBFT\lib\asyncio\base_events.py", line 948, in create_connection
    raise exceptions[0]
  File "D:\anaconda\envs\PBFT\lib\asyncio\base_events.py", line 935, in create_connection
    await self.sock_connect(sock, address)
  File "D:\anaconda\envs\PBFT\lib\asyncio\selector_events.py", line 475, in sock_connect
    return await fut
  File "D:\anaconda\envs\PBFT\lib\asyncio\selector_events.py", line 505, in _sock_connect_cb
    raise OSError(err, f'Connect call failed {address}')
ConnectionRefusedError: [Errno 10061] Connect call failed ('::1', 30076, 0, 0)

The above exception was the direct cause of the following exception:

Traceback (most recent call last):
  File "pbft.py", line 236, in send_message
    await send_with_delay(self.session, self.node_info, target, url, data, self.bandwidth_data)
  File "pbft.py", line 63, in send_with_delay
    async with session.post(url, json=data) as resp:
  File "D:\anaconda\envs\PBFT\lib\site-packages\aiohttp\client.py", line 1141, in __aenter__
    self._resp = await self._coro
  File "D:\anaconda\envs\PBFT\lib\site-packages\aiohttp\client.py", line 537, in _request
    req, traces=traces, timeout=real_timeout
  File "D:\anaconda\envs\PBFT\lib\site-packages\aiohttp\connector.py", line 540, in connect
    proto = await self._create_connection(req, traces, timeout)
  File "D:\anaconda\envs\PBFT\lib\site-packages\aiohttp\connector.py", line 901, in _create_connection
    _, proto = await self._create_direct_connection(req, traces, timeout)
  File "D:\anaconda\envs\PBFT\lib\site-packages\aiohttp\connector.py", line 1206, in _create_direct_connection
    raise last_exc
  File "D:\anaconda\envs\PBFT\lib\site-packages\aiohttp\connector.py", line 1187, in _create_direct_connection
    client_error=client_error,
  File "D:\anaconda\envs\PBFT\lib\site-packages\aiohttp\connector.py", line 988, in _wrap_create_connection
    raise client_error(req.connection_key, exc) from exc
aiohttp.client_exceptions.ClientConnectorError: Cannot connect to host localhost:30076 ssl:default [Connect call failed ('::1', 30076, 0, 0)]
[2025-03-07 13:53:52,802] [ERROR] [30128] Error sending to http://localhost:30141/commit: Cannot connect to host localhost:30141 ssl:default [Connect call failed ('::1', 30141, 0, 0)]
Traceback (most recent call last):
  File "D:\anaconda\envs\PBFT\lib\site-packages\aiohttp\connector.py", line 980, in _wrap_create_connection
    return await self._loop.create_connection(*args, **kwargs)  # type: ignore[return-value]  # noqa
  File "D:\anaconda\envs\PBFT\lib\asyncio\base_events.py", line 948, in create_connection
    raise exceptions[0]
  File "D:\anaconda\envs\PBFT\lib\asyncio\base_events.py", line 935, in create_connection
    await self.sock_connect(sock, address)
  File "D:\anaconda\envs\PBFT\lib\asyncio\selector_events.py", line 475, in sock_connect
    return await fut
  File "D:\anaconda\envs\PBFT\lib\asyncio\selector_events.py", line 505, in _sock_connect_cb
    raise OSError(err, f'Connect call failed {address}')
ConnectionRefusedError: [Errno 10061] Connect call failed ('::1', 30141, 0, 0)

The above exception was the direct cause of the following exception:

Traceback (most recent call last):
  File "pbft.py", line 236, in send_message
    await send_with_delay(self.session, self.node_info, target, url, data, self.bandwidth_data)
  File "pbft.py", line 63, in send_with_delay
    async with session.post(url, json=data) as resp:
  File "D:\anaconda\envs\PBFT\lib\site-packages\aiohttp\client.py", line 1141, in __aenter__
    self._resp = await self._coro
  File "D:\anaconda\envs\PBFT\lib\site-packages\aiohttp\client.py", line 537, in _request
    req, traces=traces, timeout=real_timeout
  File "D:\anaconda\envs\PBFT\lib\site-packages\aiohttp\connector.py", line 540, in connect
    proto = await self._create_connection(req, traces, timeout)
  File "D:\anaconda\envs\PBFT\lib\site-packages\aiohttp\connector.py", line 901, in _create_connection
    _, proto = await self._create_direct_connection(req, traces, timeout)
  File "D:\anaconda\envs\PBFT\lib\site-packages\aiohttp\connector.py", line 1206, in _create_direct_connection
    raise last_exc
  File "D:\anaconda\envs\PBFT\lib\site-packages\aiohttp\connector.py", line 1187, in _create_direct_connection
    client_error=client_error,
  File "D:\anaconda\envs\PBFT\lib\site-packages\aiohttp\connector.py", line 988, in _wrap_create_connection
    raise client_error(req.connection_key, exc) from exc
aiohttp.client_exceptions.ClientConnectorError: Cannot connect to host localhost:30141 ssl:default [Connect call failed ('::1', 30141, 0, 0)]
[2025-03-07 13:53:52,802] [ERROR] [30128] Error sending to http://localhost:30143/prepare: Cannot connect to host localhost:30143 ssl:default [Connect call failed ('127.0.0.1', 30143)]
Traceback (most recent call last):
  File "D:\anaconda\envs\PBFT\lib\site-packages\aiohttp\connector.py", line 980, in _wrap_create_connection
    return await self._loop.create_connection(*args, **kwargs)  # type: ignore[return-value]  # noqa
  File "D:\anaconda\envs\PBFT\lib\asyncio\base_events.py", line 948, in create_connection
    raise exceptions[0]
  File "D:\anaconda\envs\PBFT\lib\asyncio\base_events.py", line 935, in create_connection
    await self.sock_connect(sock, address)
  File "D:\anaconda\envs\PBFT\lib\asyncio\selector_events.py", line 475, in sock_connect
    return await fut
  File "D:\anaconda\envs\PBFT\lib\asyncio\selector_events.py", line 505, in _sock_connect_cb
    raise OSError(err, f'Connect call failed {address}')
ConnectionRefusedError: [Errno 10061] Connect call failed ('127.0.0.1', 30143)

The above exception was the direct cause of the following exception:

Traceback (most recent call last):
  File "pbft.py", line 236, in send_message
    await send_with_delay(self.session, self.node_info, target, url, data, self.bandwidth_data)
  File "pbft.py", line 63, in send_with_delay
    async with session.post(url, json=data) as resp:
  File "D:\anaconda\envs\PBFT\lib\site-packages\aiohttp\client.py", line 1141, in __aenter__
    self._resp = await self._coro
  File "D:\anaconda\envs\PBFT\lib\site-packages\aiohttp\client.py", line 537, in _request
    req, traces=traces, timeout=real_timeout
  File "D:\anaconda\envs\PBFT\lib\site-packages\aiohttp\connector.py", line 540, in connect
    proto = await self._create_connection(req, traces, timeout)
  File "D:\anaconda\envs\PBFT\lib\site-packages\aiohttp\connector.py", line 901, in _create_connection
    _, proto = await self._create_direct_connection(req, traces, timeout)
  File "D:\anaconda\envs\PBFT\lib\site-packages\aiohttp\connector.py", line 1206, in _create_direct_connection
    raise last_exc
  File "D:\anaconda\envs\PBFT\lib\site-packages\aiohttp\connector.py", line 1187, in _create_direct_connection
    client_error=client_error,
  File "D:\anaconda\envs\PBFT\lib\site-packages\aiohttp\connector.py", line 988, in _wrap_create_connection
    raise client_error(req.connection_key, exc) from exc
aiohttp.client_exceptions.ClientConnectorError: Cannot connect to host localhost:30143 ssl:default [Connect call failed ('127.0.0.1', 30143)]
[2025-03-07 13:53:52,802] [ERROR] [30128] Error sending to http://localhost:30103/commit: Cannot connect to host localhost:30103 ssl:default [Connect call failed ('::1', 30103, 0, 0)]
Traceback (most recent call last):
  File "D:\anaconda\envs\PBFT\lib\site-packages\aiohttp\connector.py", line 980, in _wrap_create_connection
    return await self._loop.create_connection(*args, **kwargs)  # type: ignore[return-value]  # noqa
  File "D:\anaconda\envs\PBFT\lib\asyncio\base_events.py", line 948, in create_connection
    raise exceptions[0]
  File "D:\anaconda\envs\PBFT\lib\asyncio\base_events.py", line 935, in create_connection
    await self.sock_connect(sock, address)
  File "D:\anaconda\envs\PBFT\lib\asyncio\selector_events.py", line 475, in sock_connect
    return await fut
  File "D:\anaconda\envs\PBFT\lib\asyncio\selector_events.py", line 505, in _sock_connect_cb
    raise OSError(err, f'Connect call failed {address}')
ConnectionRefusedError: [Errno 10061] Connect call failed ('::1', 30103, 0, 0)

The above exception was the direct cause of the following exception:

Traceback (most recent call last):
  File "pbft.py", line 236, in send_message
    await send_with_delay(self.session, self.node_info, target, url, data, self.bandwidth_data)
  File "pbft.py", line 63, in send_with_delay
    async with session.post(url, json=data) as resp:
  File "D:\anaconda\envs\PBFT\lib\site-packages\aiohttp\client.py", line 1141, in __aenter__
    self._resp = await self._coro
  File "D:\anaconda\envs\PBFT\lib\site-packages\aiohttp\client.py", line 537, in _request
    req, traces=traces, timeout=real_timeout
  File "D:\anaconda\envs\PBFT\lib\site-packages\aiohttp\connector.py", line 540, in connect
    proto = await self._create_connection(req, traces, timeout)
  File "D:\anaconda\envs\PBFT\lib\site-packages\aiohttp\connector.py", line 901, in _create_connection
    _, proto = await self._create_direct_connection(req, traces, timeout)
  File "D:\anaconda\envs\PBFT\lib\site-packages\aiohttp\connector.py", line 1206, in _create_direct_connection
    raise last_exc
  File "D:\anaconda\envs\PBFT\lib\site-packages\aiohttp\connector.py", line 1187, in _create_direct_connection
    client_error=client_error,
  File "D:\anaconda\envs\PBFT\lib\site-packages\aiohttp\connector.py", line 988, in _wrap_create_connection
    raise client_error(req.connection_key, exc) from exc
aiohttp.client_exceptions.ClientConnectorError: Cannot connect to host localhost:30103 ssl:default [Connect call failed ('::1', 30103, 0, 0)]
[2025-03-07 13:53:52,804] [INFO] [30128] Received COMMIT: id:1741323218379, from:30123, delay:0.0000s, distance:74.29m (Euclidean)
[2025-03-07 13:53:52,804] [INFO] [30128] Received PREPARE: id:1741323218379, from:30123, delay:0.0000s, distance:74.29m (Euclidean)
[2025-03-07 13:53:52,815] [ERROR] [30128] Error sending to http://localhost:30025/commit: Cannot connect to host localhost:30025 ssl:default [Connect call failed ('::1', 30025, 0, 0)]
Traceback (most recent call last):
  File "D:\anaconda\envs\PBFT\lib\site-packages\aiohttp\connector.py", line 980, in _wrap_create_connection
    return await self._loop.create_connection(*args, **kwargs)  # type: ignore[return-value]  # noqa
  File "D:\anaconda\envs\PBFT\lib\asyncio\base_events.py", line 948, in create_connection
    raise exceptions[0]
  File "D:\anaconda\envs\PBFT\lib\asyncio\base_events.py", line 935, in create_connection
    await self.sock_connect(sock, address)
  File "D:\anaconda\envs\PBFT\lib\asyncio\selector_events.py", line 475, in sock_connect
    return await fut
  File "D:\anaconda\envs\PBFT\lib\asyncio\selector_events.py", line 505, in _sock_connect_cb
    raise OSError(err, f'Connect call failed {address}')
ConnectionRefusedError: [Errno 10061] Connect call failed ('::1', 30025, 0, 0)

The above exception was the direct cause of the following exception:

Traceback (most recent call last):
  File "pbft.py", line 236, in send_message
    await send_with_delay(self.session, self.node_info, target, url, data, self.bandwidth_data)
  File "pbft.py", line 63, in send_with_delay
    async with session.post(url, json=data) as resp:
  File "D:\anaconda\envs\PBFT\lib\site-packages\aiohttp\client.py", line 1141, in __aenter__
    self._resp = await self._coro
  File "D:\anaconda\envs\PBFT\lib\site-packages\aiohttp\client.py", line 537, in _request
    req, traces=traces, timeout=real_timeout
  File "D:\anaconda\envs\PBFT\lib\site-packages\aiohttp\connector.py", line 540, in connect
    proto = await self._create_connection(req, traces, timeout)
  File "D:\anaconda\envs\PBFT\lib\site-packages\aiohttp\connector.py", line 901, in _create_connection
    _, proto = await self._create_direct_connection(req, traces, timeout)
  File "D:\anaconda\envs\PBFT\lib\site-packages\aiohttp\connector.py", line 1206, in _create_direct_connection
    raise last_exc
  File "D:\anaconda\envs\PBFT\lib\site-packages\aiohttp\connector.py", line 1187, in _create_direct_connection
    client_error=client_error,
  File "D:\anaconda\envs\PBFT\lib\site-packages\aiohttp\connector.py", line 988, in _wrap_create_connection
    raise client_error(req.connection_key, exc) from exc
aiohttp.client_exceptions.ClientConnectorError: Cannot connect to host localhost:30025 ssl:default [Connect call failed ('::1', 30025, 0, 0)]
[2025-03-07 13:53:52,815] [ERROR] [30128] Error sending to http://localhost:30143/commit: Cannot connect to host localhost:30143 ssl:default [Connect call failed ('::1', 30143, 0, 0)]
Traceback (most recent call last):
  File "D:\anaconda\envs\PBFT\lib\site-packages\aiohttp\connector.py", line 980, in _wrap_create_connection
    return await self._loop.create_connection(*args, **kwargs)  # type: ignore[return-value]  # noqa
  File "D:\anaconda\envs\PBFT\lib\asyncio\base_events.py", line 948, in create_connection
    raise exceptions[0]
  File "D:\anaconda\envs\PBFT\lib\asyncio\base_events.py", line 935, in create_connection
    await self.sock_connect(sock, address)
  File "D:\anaconda\envs\PBFT\lib\asyncio\selector_events.py", line 475, in sock_connect
    return await fut
  File "D:\anaconda\envs\PBFT\lib\asyncio\selector_events.py", line 505, in _sock_connect_cb
    raise OSError(err, f'Connect call failed {address}')
ConnectionRefusedError: [Errno 10061] Connect call failed ('::1', 30143, 0, 0)

The above exception was the direct cause of the following exception:

Traceback (most recent call last):
  File "pbft.py", line 236, in send_message
    await send_with_delay(self.session, self.node_info, target, url, data, self.bandwidth_data)
  File "pbft.py", line 63, in send_with_delay
    async with session.post(url, json=data) as resp:
  File "D:\anaconda\envs\PBFT\lib\site-packages\aiohttp\client.py", line 1141, in __aenter__
    self._resp = await self._coro
  File "D:\anaconda\envs\PBFT\lib\site-packages\aiohttp\client.py", line 537, in _request
    req, traces=traces, timeout=real_timeout
  File "D:\anaconda\envs\PBFT\lib\site-packages\aiohttp\connector.py", line 540, in connect
    proto = await self._create_connection(req, traces, timeout)
  File "D:\anaconda\envs\PBFT\lib\site-packages\aiohttp\connector.py", line 901, in _create_connection
    _, proto = await self._create_direct_connection(req, traces, timeout)
  File "D:\anaconda\envs\PBFT\lib\site-packages\aiohttp\connector.py", line 1206, in _create_direct_connection
    raise last_exc
  File "D:\anaconda\envs\PBFT\lib\site-packages\aiohttp\connector.py", line 1187, in _create_direct_connection
    client_error=client_error,
  File "D:\anaconda\envs\PBFT\lib\site-packages\aiohttp\connector.py", line 988, in _wrap_create_connection
    raise client_error(req.connection_key, exc) from exc
aiohttp.client_exceptions.ClientConnectorError: Cannot connect to host localhost:30143 ssl:default [Connect call failed ('::1', 30143, 0, 0)]
[2025-03-07 13:53:52,830] [ERROR] [30128] Error sending to http://localhost:30093/prepare: Cannot connect to host localhost:30093 ssl:default [Connect call failed ('127.0.0.1', 30093)]
Traceback (most recent call last):
  File "D:\anaconda\envs\PBFT\lib\site-packages\aiohttp\connector.py", line 980, in _wrap_create_connection
    return await self._loop.create_connection(*args, **kwargs)  # type: ignore[return-value]  # noqa
  File "D:\anaconda\envs\PBFT\lib\asyncio\base_events.py", line 948, in create_connection
    raise exceptions[0]
  File "D:\anaconda\envs\PBFT\lib\asyncio\base_events.py", line 935, in create_connection
    await self.sock_connect(sock, address)
  File "D:\anaconda\envs\PBFT\lib\asyncio\selector_events.py", line 475, in sock_connect
    return await fut
  File "D:\anaconda\envs\PBFT\lib\asyncio\selector_events.py", line 505, in _sock_connect_cb
    raise OSError(err, f'Connect call failed {address}')
ConnectionRefusedError: [Errno 10061] Connect call failed ('127.0.0.1', 30093)

The above exception was the direct cause of the following exception:

Traceback (most recent call last):
  File "pbft.py", line 236, in send_message
    await send_with_delay(self.session, self.node_info, target, url, data, self.bandwidth_data)
  File "pbft.py", line 63, in send_with_delay
    async with session.post(url, json=data) as resp:
  File "D:\anaconda\envs\PBFT\lib\site-packages\aiohttp\client.py", line 1141, in __aenter__
    self._resp = await self._coro
  File "D:\anaconda\envs\PBFT\lib\site-packages\aiohttp\client.py", line 537, in _request
    req, traces=traces, timeout=real_timeout
  File "D:\anaconda\envs\PBFT\lib\site-packages\aiohttp\connector.py", line 540, in connect
    proto = await self._create_connection(req, traces, timeout)
  File "D:\anaconda\envs\PBFT\lib\site-packages\aiohttp\connector.py", line 901, in _create_connection
    _, proto = await self._create_direct_connection(req, traces, timeout)
  File "D:\anaconda\envs\PBFT\lib\site-packages\aiohttp\connector.py", line 1206, in _create_direct_connection
    raise last_exc
  File "D:\anaconda\envs\PBFT\lib\site-packages\aiohttp\connector.py", line 1187, in _create_direct_connection
    client_error=client_error,
  File "D:\anaconda\envs\PBFT\lib\site-packages\aiohttp\connector.py", line 988, in _wrap_create_connection
    raise client_error(req.connection_key, exc) from exc
aiohttp.client_exceptions.ClientConnectorError: Cannot connect to host localhost:30093 ssl:default [Connect call failed ('127.0.0.1', 30093)]
[2025-03-07 13:53:52,862] [ERROR] [30128] Error sending to http://localhost:30093/commit: Cannot connect to host localhost:30093 ssl:default [Connect call failed ('::1', 30093, 0, 0)]
Traceback (most recent call last):
  File "D:\anaconda\envs\PBFT\lib\site-packages\aiohttp\connector.py", line 980, in _wrap_create_connection
    return await self._loop.create_connection(*args, **kwargs)  # type: ignore[return-value]  # noqa
  File "D:\anaconda\envs\PBFT\lib\asyncio\base_events.py", line 948, in create_connection
    raise exceptions[0]
  File "D:\anaconda\envs\PBFT\lib\asyncio\base_events.py", line 935, in create_connection
    await self.sock_connect(sock, address)
  File "D:\anaconda\envs\PBFT\lib\asyncio\selector_events.py", line 475, in sock_connect
    return await fut
  File "D:\anaconda\envs\PBFT\lib\asyncio\selector_events.py", line 505, in _sock_connect_cb
    raise OSError(err, f'Connect call failed {address}')
ConnectionRefusedError: [Errno 10061] Connect call failed ('::1', 30093, 0, 0)

The above exception was the direct cause of the following exception:

Traceback (most recent call last):
  File "pbft.py", line 236, in send_message
    await send_with_delay(self.session, self.node_info, target, url, data, self.bandwidth_data)
  File "pbft.py", line 63, in send_with_delay
    async with session.post(url, json=data) as resp:
  File "D:\anaconda\envs\PBFT\lib\site-packages\aiohttp\client.py", line 1141, in __aenter__
    self._resp = await self._coro
  File "D:\anaconda\envs\PBFT\lib\site-packages\aiohttp\client.py", line 537, in _request
    req, traces=traces, timeout=real_timeout
  File "D:\anaconda\envs\PBFT\lib\site-packages\aiohttp\connector.py", line 540, in connect
    proto = await self._create_connection(req, traces, timeout)
  File "D:\anaconda\envs\PBFT\lib\site-packages\aiohttp\connector.py", line 901, in _create_connection
    _, proto = await self._create_direct_connection(req, traces, timeout)
  File "D:\anaconda\envs\PBFT\lib\site-packages\aiohttp\connector.py", line 1206, in _create_direct_connection
    raise last_exc
  File "D:\anaconda\envs\PBFT\lib\site-packages\aiohttp\connector.py", line 1187, in _create_direct_connection
    client_error=client_error,
  File "D:\anaconda\envs\PBFT\lib\site-packages\aiohttp\connector.py", line 988, in _wrap_create_connection
    raise client_error(req.connection_key, exc) from exc
aiohttp.client_exceptions.ClientConnectorError: Cannot connect to host localhost:30093 ssl:default [Connect call failed ('::1', 30093, 0, 0)]
[2025-03-07 13:53:52,862] [ERROR] [30128] Error sending to http://localhost:30137/prepare: Cannot connect to host localhost:30137 ssl:default [Connect call failed ('127.0.0.1', 30137)]
Traceback (most recent call last):
  File "D:\anaconda\envs\PBFT\lib\site-packages\aiohttp\connector.py", line 980, in _wrap_create_connection
    return await self._loop.create_connection(*args, **kwargs)  # type: ignore[return-value]  # noqa
  File "D:\anaconda\envs\PBFT\lib\asyncio\base_events.py", line 948, in create_connection
    raise exceptions[0]
  File "D:\anaconda\envs\PBFT\lib\asyncio\base_events.py", line 935, in create_connection
    await self.sock_connect(sock, address)
  File "D:\anaconda\envs\PBFT\lib\asyncio\selector_events.py", line 475, in sock_connect
    return await fut
  File "D:\anaconda\envs\PBFT\lib\asyncio\selector_events.py", line 505, in _sock_connect_cb
    raise OSError(err, f'Connect call failed {address}')
ConnectionRefusedError: [Errno 10061] Connect call failed ('127.0.0.1', 30137)

The above exception was the direct cause of the following exception:

Traceback (most recent call last):
  File "pbft.py", line 236, in send_message
    await send_with_delay(self.session, self.node_info, target, url, data, self.bandwidth_data)
  File "pbft.py", line 63, in send_with_delay
    async with session.post(url, json=data) as resp:
  File "D:\anaconda\envs\PBFT\lib\site-packages\aiohttp\client.py", line 1141, in __aenter__
    self._resp = await self._coro
  File "D:\anaconda\envs\PBFT\lib\site-packages\aiohttp\client.py", line 537, in _request
    req, traces=traces, timeout=real_timeout
  File "D:\anaconda\envs\PBFT\lib\site-packages\aiohttp\connector.py", line 540, in connect
    proto = await self._create_connection(req, traces, timeout)
  File "D:\anaconda\envs\PBFT\lib\site-packages\aiohttp\connector.py", line 901, in _create_connection
    _, proto = await self._create_direct_connection(req, traces, timeout)
  File "D:\anaconda\envs\PBFT\lib\site-packages\aiohttp\connector.py", line 1206, in _create_direct_connection
    raise last_exc
  File "D:\anaconda\envs\PBFT\lib\site-packages\aiohttp\connector.py", line 1187, in _create_direct_connection
    client_error=client_error,
  File "D:\anaconda\envs\PBFT\lib\site-packages\aiohttp\connector.py", line 988, in _wrap_create_connection
    raise client_error(req.connection_key, exc) from exc
aiohttp.client_exceptions.ClientConnectorError: Cannot connect to host localhost:30137 ssl:default [Connect call failed ('127.0.0.1', 30137)]
[2025-03-07 13:53:52,878] [ERROR] [30128] Error sending to http://localhost:30137/commit: Cannot connect to host localhost:30137 ssl:default [Connect call failed ('::1', 30137, 0, 0)]
Traceback (most recent call last):
  File "D:\anaconda\envs\PBFT\lib\site-packages\aiohttp\connector.py", line 980, in _wrap_create_connection
    return await self._loop.create_connection(*args, **kwargs)  # type: ignore[return-value]  # noqa
  File "D:\anaconda\envs\PBFT\lib\asyncio\base_events.py", line 948, in create_connection
    raise exceptions[0]
  File "D:\anaconda\envs\PBFT\lib\asyncio\base_events.py", line 935, in create_connection
    await self.sock_connect(sock, address)
  File "D:\anaconda\envs\PBFT\lib\asyncio\selector_events.py", line 475, in sock_connect
    return await fut
  File "D:\anaconda\envs\PBFT\lib\asyncio\selector_events.py", line 505, in _sock_connect_cb
    raise OSError(err, f'Connect call failed {address}')
ConnectionRefusedError: [Errno 10061] Connect call failed ('::1', 30137, 0, 0)

The above exception was the direct cause of the following exception:

Traceback (most recent call last):
  File "pbft.py", line 236, in send_message
    await send_with_delay(self.session, self.node_info, target, url, data, self.bandwidth_data)
  File "pbft.py", line 63, in send_with_delay
    async with session.post(url, json=data) as resp:
  File "D:\anaconda\envs\PBFT\lib\site-packages\aiohttp\client.py", line 1141, in __aenter__
    self._resp = await self._coro
  File "D:\anaconda\envs\PBFT\lib\site-packages\aiohttp\client.py", line 537, in _request
    req, traces=traces, timeout=real_timeout
  File "D:\anaconda\envs\PBFT\lib\site-packages\aiohttp\connector.py", line 540, in connect
    proto = await self._create_connection(req, traces, timeout)
  File "D:\anaconda\envs\PBFT\lib\site-packages\aiohttp\connector.py", line 901, in _create_connection
    _, proto = await self._create_direct_connection(req, traces, timeout)
  File "D:\anaconda\envs\PBFT\lib\site-packages\aiohttp\connector.py", line 1206, in _create_direct_connection
    raise last_exc
  File "D:\anaconda\envs\PBFT\lib\site-packages\aiohttp\connector.py", line 1187, in _create_direct_connection
    client_error=client_error,
  File "D:\anaconda\envs\PBFT\lib\site-packages\aiohttp\connector.py", line 988, in _wrap_create_connection
    raise client_error(req.connection_key, exc) from exc
aiohttp.client_exceptions.ClientConnectorError: Cannot connect to host localhost:30137 ssl:default [Connect call failed ('::1', 30137, 0, 0)]
[2025-03-07 13:53:52,941] [INFO] [30128] Received COMMIT: id:1741323218379, from:30127, delay:0.0001s, distance:186.29m (Euclidean)
[2025-03-07 13:53:52,989] [ERROR] [30128] Error sending to http://localhost:30100/commit: Cannot connect to host localhost:30100 ssl:default [Connect call failed ('::1', 30100, 0, 0)]
Traceback (most recent call last):
  File "D:\anaconda\envs\PBFT\lib\site-packages\aiohttp\connector.py", line 980, in _wrap_create_connection
    return await self._loop.create_connection(*args, **kwargs)  # type: ignore[return-value]  # noqa
  File "D:\anaconda\envs\PBFT\lib\asyncio\base_events.py", line 948, in create_connection
    raise exceptions[0]
  File "D:\anaconda\envs\PBFT\lib\asyncio\base_events.py", line 935, in create_connection
    await self.sock_connect(sock, address)
  File "D:\anaconda\envs\PBFT\lib\asyncio\selector_events.py", line 475, in sock_connect
    return await fut
  File "D:\anaconda\envs\PBFT\lib\asyncio\selector_events.py", line 505, in _sock_connect_cb
    raise OSError(err, f'Connect call failed {address}')
ConnectionRefusedError: [Errno 10061] Connect call failed ('::1', 30100, 0, 0)

The above exception was the direct cause of the following exception:

Traceback (most recent call last):
  File "pbft.py", line 236, in send_message
    await send_with_delay(self.session, self.node_info, target, url, data, self.bandwidth_data)
  File "pbft.py", line 63, in send_with_delay
    async with session.post(url, json=data) as resp:
  File "D:\anaconda\envs\PBFT\lib\site-packages\aiohttp\client.py", line 1141, in __aenter__
    self._resp = await self._coro
  File "D:\anaconda\envs\PBFT\lib\site-packages\aiohttp\client.py", line 537, in _request
    req, traces=traces, timeout=real_timeout
  File "D:\anaconda\envs\PBFT\lib\site-packages\aiohttp\connector.py", line 540, in connect
    proto = await self._create_connection(req, traces, timeout)
  File "D:\anaconda\envs\PBFT\lib\site-packages\aiohttp\connector.py", line 901, in _create_connection
    _, proto = await self._create_direct_connection(req, traces, timeout)
  File "D:\anaconda\envs\PBFT\lib\site-packages\aiohttp\connector.py", line 1206, in _create_direct_connection
    raise last_exc
  File "D:\anaconda\envs\PBFT\lib\site-packages\aiohttp\connector.py", line 1187, in _create_direct_connection
    client_error=client_error,
  File "D:\anaconda\envs\PBFT\lib\site-packages\aiohttp\connector.py", line 988, in _wrap_create_connection
    raise client_error(req.connection_key, exc) from exc
aiohttp.client_exceptions.ClientConnectorError: Cannot connect to host localhost:30100 ssl:default [Connect call failed ('::1', 30100, 0, 0)]
[2025-03-07 13:53:52,989] [ERROR] [30128] Error sending to http://localhost:30085/prepare: Cannot connect to host localhost:30085 ssl:default [Connect call failed ('127.0.0.1', 30085)]
Traceback (most recent call last):
  File "D:\anaconda\envs\PBFT\lib\site-packages\aiohttp\connector.py", line 980, in _wrap_create_connection
    return await self._loop.create_connection(*args, **kwargs)  # type: ignore[return-value]  # noqa
  File "D:\anaconda\envs\PBFT\lib\asyncio\base_events.py", line 948, in create_connection
    raise exceptions[0]
  File "D:\anaconda\envs\PBFT\lib\asyncio\base_events.py", line 935, in create_connection
    await self.sock_connect(sock, address)
  File "D:\anaconda\envs\PBFT\lib\asyncio\selector_events.py", line 475, in sock_connect
    return await fut
  File "D:\anaconda\envs\PBFT\lib\asyncio\selector_events.py", line 505, in _sock_connect_cb
    raise OSError(err, f'Connect call failed {address}')
ConnectionRefusedError: [Errno 10061] Connect call failed ('127.0.0.1', 30085)

The above exception was the direct cause of the following exception:

Traceback (most recent call last):
  File "pbft.py", line 236, in send_message
    await send_with_delay(self.session, self.node_info, target, url, data, self.bandwidth_data)
  File "pbft.py", line 63, in send_with_delay
    async with session.post(url, json=data) as resp:
  File "D:\anaconda\envs\PBFT\lib\site-packages\aiohttp\client.py", line 1141, in __aenter__
    self._resp = await self._coro
  File "D:\anaconda\envs\PBFT\lib\site-packages\aiohttp\client.py", line 537, in _request
    req, traces=traces, timeout=real_timeout
  File "D:\anaconda\envs\PBFT\lib\site-packages\aiohttp\connector.py", line 540, in connect
    proto = await self._create_connection(req, traces, timeout)
  File "D:\anaconda\envs\PBFT\lib\site-packages\aiohttp\connector.py", line 901, in _create_connection
    _, proto = await self._create_direct_connection(req, traces, timeout)
  File "D:\anaconda\envs\PBFT\lib\site-packages\aiohttp\connector.py", line 1206, in _create_direct_connection
    raise last_exc
  File "D:\anaconda\envs\PBFT\lib\site-packages\aiohttp\connector.py", line 1187, in _create_direct_connection
    client_error=client_error,
  File "D:\anaconda\envs\PBFT\lib\site-packages\aiohttp\connector.py", line 988, in _wrap_create_connection
    raise client_error(req.connection_key, exc) from exc
aiohttp.client_exceptions.ClientConnectorError: Cannot connect to host localhost:30085 ssl:default [Connect call failed ('127.0.0.1', 30085)]
[2025-03-07 13:53:52,989] [ERROR] [30128] Error sending to http://localhost:30100/prepare: Cannot connect to host localhost:30100 ssl:default [Connect call failed ('127.0.0.1', 30100)]
Traceback (most recent call last):
  File "D:\anaconda\envs\PBFT\lib\site-packages\aiohttp\connector.py", line 980, in _wrap_create_connection
    return await self._loop.create_connection(*args, **kwargs)  # type: ignore[return-value]  # noqa
  File "D:\anaconda\envs\PBFT\lib\asyncio\base_events.py", line 948, in create_connection
    raise exceptions[0]
  File "D:\anaconda\envs\PBFT\lib\asyncio\base_events.py", line 935, in create_connection
    await self.sock_connect(sock, address)
  File "D:\anaconda\envs\PBFT\lib\asyncio\selector_events.py", line 475, in sock_connect
    return await fut
  File "D:\anaconda\envs\PBFT\lib\asyncio\selector_events.py", line 505, in _sock_connect_cb
    raise OSError(err, f'Connect call failed {address}')
ConnectionRefusedError: [Errno 10061] Connect call failed ('127.0.0.1', 30100)

The above exception was the direct cause of the following exception:

Traceback (most recent call last):
  File "pbft.py", line 236, in send_message
    await send_with_delay(self.session, self.node_info, target, url, data, self.bandwidth_data)
  File "pbft.py", line 63, in send_with_delay
    async with session.post(url, json=data) as resp:
  File "D:\anaconda\envs\PBFT\lib\site-packages\aiohttp\client.py", line 1141, in __aenter__
    self._resp = await self._coro
  File "D:\anaconda\envs\PBFT\lib\site-packages\aiohttp\client.py", line 537, in _request
    req, traces=traces, timeout=real_timeout
  File "D:\anaconda\envs\PBFT\lib\site-packages\aiohttp\connector.py", line 540, in connect
    proto = await self._create_connection(req, traces, timeout)
  File "D:\anaconda\envs\PBFT\lib\site-packages\aiohttp\connector.py", line 901, in _create_connection
    _, proto = await self._create_direct_connection(req, traces, timeout)
  File "D:\anaconda\envs\PBFT\lib\site-packages\aiohttp\connector.py", line 1206, in _create_direct_connection
    raise last_exc
  File "D:\anaconda\envs\PBFT\lib\site-packages\aiohttp\connector.py", line 1187, in _create_direct_connection
    client_error=client_error,
  File "D:\anaconda\envs\PBFT\lib\site-packages\aiohttp\connector.py", line 988, in _wrap_create_connection
    raise client_error(req.connection_key, exc) from exc
aiohttp.client_exceptions.ClientConnectorError: Cannot connect to host localhost:30100 ssl:default [Connect call failed ('127.0.0.1', 30100)]
[2025-03-07 13:53:53,005] [INFO] [30128] Received PREPARE: id:1741323218379, from:30150, delay:0.0001s, distance:196.41m (Euclidean)
[2025-03-07 13:53:53,020] [ERROR] [30128] Error sending to http://localhost:30101/prepare: Cannot connect to host localhost:30101 ssl:default [Connect call failed ('127.0.0.1', 30101)]
Traceback (most recent call last):
  File "D:\anaconda\envs\PBFT\lib\site-packages\aiohttp\connector.py", line 980, in _wrap_create_connection
    return await self._loop.create_connection(*args, **kwargs)  # type: ignore[return-value]  # noqa
  File "D:\anaconda\envs\PBFT\lib\asyncio\base_events.py", line 948, in create_connection
    raise exceptions[0]
  File "D:\anaconda\envs\PBFT\lib\asyncio\base_events.py", line 935, in create_connection
    await self.sock_connect(sock, address)
  File "D:\anaconda\envs\PBFT\lib\asyncio\selector_events.py", line 475, in sock_connect
    return await fut
  File "D:\anaconda\envs\PBFT\lib\asyncio\selector_events.py", line 505, in _sock_connect_cb
    raise OSError(err, f'Connect call failed {address}')
ConnectionRefusedError: [Errno 10061] Connect call failed ('127.0.0.1', 30101)

The above exception was the direct cause of the following exception:

Traceback (most recent call last):
  File "pbft.py", line 236, in send_message
    await send_with_delay(self.session, self.node_info, target, url, data, self.bandwidth_data)
  File "pbft.py", line 63, in send_with_delay
    async with session.post(url, json=data) as resp:
  File "D:\anaconda\envs\PBFT\lib\site-packages\aiohttp\client.py", line 1141, in __aenter__
    self._resp = await self._coro
  File "D:\anaconda\envs\PBFT\lib\site-packages\aiohttp\client.py", line 537, in _request
    req, traces=traces, timeout=real_timeout
  File "D:\anaconda\envs\PBFT\lib\site-packages\aiohttp\connector.py", line 540, in connect
    proto = await self._create_connection(req, traces, timeout)
  File "D:\anaconda\envs\PBFT\lib\site-packages\aiohttp\connector.py", line 901, in _create_connection
    _, proto = await self._create_direct_connection(req, traces, timeout)
  File "D:\anaconda\envs\PBFT\lib\site-packages\aiohttp\connector.py", line 1206, in _create_direct_connection
    raise last_exc
  File "D:\anaconda\envs\PBFT\lib\site-packages\aiohttp\connector.py", line 1187, in _create_direct_connection
    client_error=client_error,
  File "D:\anaconda\envs\PBFT\lib\site-packages\aiohttp\connector.py", line 988, in _wrap_create_connection
    raise client_error(req.connection_key, exc) from exc
aiohttp.client_exceptions.ClientConnectorError: Cannot connect to host localhost:30101 ssl:default [Connect call failed ('127.0.0.1', 30101)]
[2025-03-07 13:53:53,036] [ERROR] [30128] Error sending to http://localhost:30085/commit: Cannot connect to host localhost:30085 ssl:default [Connect call failed ('::1', 30085, 0, 0)]
Traceback (most recent call last):
  File "D:\anaconda\envs\PBFT\lib\site-packages\aiohttp\connector.py", line 980, in _wrap_create_connection
    return await self._loop.create_connection(*args, **kwargs)  # type: ignore[return-value]  # noqa
  File "D:\anaconda\envs\PBFT\lib\asyncio\base_events.py", line 948, in create_connection
    raise exceptions[0]
  File "D:\anaconda\envs\PBFT\lib\asyncio\base_events.py", line 935, in create_connection
    await self.sock_connect(sock, address)
  File "D:\anaconda\envs\PBFT\lib\asyncio\selector_events.py", line 475, in sock_connect
    return await fut
  File "D:\anaconda\envs\PBFT\lib\asyncio\selector_events.py", line 505, in _sock_connect_cb
    raise OSError(err, f'Connect call failed {address}')
ConnectionRefusedError: [Errno 10061] Connect call failed ('::1', 30085, 0, 0)

The above exception was the direct cause of the following exception:

Traceback (most recent call last):
  File "pbft.py", line 236, in send_message
    await send_with_delay(self.session, self.node_info, target, url, data, self.bandwidth_data)
  File "pbft.py", line 63, in send_with_delay
    async with session.post(url, json=data) as resp:
  File "D:\anaconda\envs\PBFT\lib\site-packages\aiohttp\client.py", line 1141, in __aenter__
    self._resp = await self._coro
  File "D:\anaconda\envs\PBFT\lib\site-packages\aiohttp\client.py", line 537, in _request
    req, traces=traces, timeout=real_timeout
  File "D:\anaconda\envs\PBFT\lib\site-packages\aiohttp\connector.py", line 540, in connect
    proto = await self._create_connection(req, traces, timeout)
  File "D:\anaconda\envs\PBFT\lib\site-packages\aiohttp\connector.py", line 901, in _create_connection
    _, proto = await self._create_direct_connection(req, traces, timeout)
  File "D:\anaconda\envs\PBFT\lib\site-packages\aiohttp\connector.py", line 1206, in _create_direct_connection
    raise last_exc
  File "D:\anaconda\envs\PBFT\lib\site-packages\aiohttp\connector.py", line 1187, in _create_direct_connection
    client_error=client_error,
  File "D:\anaconda\envs\PBFT\lib\site-packages\aiohttp\connector.py", line 988, in _wrap_create_connection
    raise client_error(req.connection_key, exc) from exc
aiohttp.client_exceptions.ClientConnectorError: Cannot connect to host localhost:30085 ssl:default [Connect call failed ('::1', 30085, 0, 0)]
[2025-03-07 13:53:53,036] [ERROR] [30128] Error sending to http://localhost:30101/commit: Cannot connect to host localhost:30101 ssl:default [Connect call failed ('::1', 30101, 0, 0)]
Traceback (most recent call last):
  File "D:\anaconda\envs\PBFT\lib\site-packages\aiohttp\connector.py", line 980, in _wrap_create_connection
    return await self._loop.create_connection(*args, **kwargs)  # type: ignore[return-value]  # noqa
  File "D:\anaconda\envs\PBFT\lib\asyncio\base_events.py", line 948, in create_connection
    raise exceptions[0]
  File "D:\anaconda\envs\PBFT\lib\asyncio\base_events.py", line 935, in create_connection
    await self.sock_connect(sock, address)
  File "D:\anaconda\envs\PBFT\lib\asyncio\selector_events.py", line 475, in sock_connect
    return await fut
  File "D:\anaconda\envs\PBFT\lib\asyncio\selector_events.py", line 505, in _sock_connect_cb
    raise OSError(err, f'Connect call failed {address}')
ConnectionRefusedError: [Errno 10061] Connect call failed ('::1', 30101, 0, 0)

The above exception was the direct cause of the following exception:

Traceback (most recent call last):
  File "pbft.py", line 236, in send_message
    await send_with_delay(self.session, self.node_info, target, url, data, self.bandwidth_data)
  File "pbft.py", line 63, in send_with_delay
    async with session.post(url, json=data) as resp:
  File "D:\anaconda\envs\PBFT\lib\site-packages\aiohttp\client.py", line 1141, in __aenter__
    self._resp = await self._coro
  File "D:\anaconda\envs\PBFT\lib\site-packages\aiohttp\client.py", line 537, in _request
    req, traces=traces, timeout=real_timeout
  File "D:\anaconda\envs\PBFT\lib\site-packages\aiohttp\connector.py", line 540, in connect
    proto = await self._create_connection(req, traces, timeout)
  File "D:\anaconda\envs\PBFT\lib\site-packages\aiohttp\connector.py", line 901, in _create_connection
    _, proto = await self._create_direct_connection(req, traces, timeout)
  File "D:\anaconda\envs\PBFT\lib\site-packages\aiohttp\connector.py", line 1206, in _create_direct_connection
    raise last_exc
  File "D:\anaconda\envs\PBFT\lib\site-packages\aiohttp\connector.py", line 1187, in _create_direct_connection
    client_error=client_error,
  File "D:\anaconda\envs\PBFT\lib\site-packages\aiohttp\connector.py", line 988, in _wrap_create_connection
    raise client_error(req.connection_key, exc) from exc
aiohttp.client_exceptions.ClientConnectorError: Cannot connect to host localhost:30101 ssl:default [Connect call failed ('::1', 30101, 0, 0)]
[2025-03-07 13:53:53,100] [INFO] [30128] Received PREPARE: id:1741323218379, from:30149, delay:0.0000s, distance:125.14m (Euclidean)
[2025-03-07 13:53:53,100] [INFO] [30128] Received COMMIT: id:1741323218379, from:30149, delay:0.0000s, distance:125.14m (Euclidean)
[2025-03-07 13:53:53,341] [INFO] [30128] Received COMMIT: id:1741323218379, from:30150, delay:0.0001s, distance:196.41m (Euclidean)
[2025-03-07 13:53:53,590] [INFO] [30128] Received PREPARE: id:1741323218379, from:30106, delay:0.0001s, distance:202.46m (Euclidean)
[2025-03-07 13:53:53,590] [INFO] [30128] Received COMMIT: id:1741323218379, from:30106, delay:0.0001s, distance:202.46m (Euclidean)
[2025-03-07 13:53:53,894] [INFO] [30128] Received PREPARE: id:1741323218379, from:30113, delay:0.0000s, distance:124.43m (Euclidean)
[2025-03-07 13:53:53,894] [INFO] [30128] Received COMMIT: id:1741323218379, from:30113, delay:0.0000s, distance:124.43m (Euclidean)
[2025-03-07 13:53:53,944] [INFO] [30128] Received PREPARE: id:1741323218379, from:30146, delay:0.0001s, distance:179.54m (Euclidean)
[2025-03-07 13:53:53,944] [INFO] [30128] Received COMMIT: id:1741323218379, from:30146, delay:0.0001s, distance:179.54m (Euclidean)
[2025-03-07 13:53:53,970] [INFO] [30128] Received PREPARE: id:1741323218379, from:30108, delay:0.0001s, distance:233.28m (Euclidean)
[2025-03-07 13:53:53,970] [INFO] [30128] Received COMMIT: id:1741323218379, from:30108, delay:0.0001s, distance:233.28m (Euclidean)
[2025-03-07 13:53:54,097] [INFO] [30128] Received PREPARE: id:1741323218379, from:30132, delay:0.0002s, distance:293.42m (Euclidean)
[2025-03-07 13:53:54,113] [INFO] [30128] Received COMMIT: id:1741323218379, from:30132, delay:0.0002s, distance:293.42m (Euclidean)
[2025-03-07 13:53:54,195] [INFO] [30128] Received PREPARE: id:1741323218379, from:30159, delay:0.0002s, distance:293.61m (Euclidean)
[2025-03-07 13:53:54,195] [INFO] [30128] Received COMMIT: id:1741323218379, from:30159, delay:0.0002s, distance:293.61m (Euclidean)
[2025-03-07 13:53:54,295] [INFO] [30128] Received PREPARE: id:1741323218379, from:30156, delay:0.0001s, distance:230.48m (Euclidean)
[2025-03-07 13:53:54,303] [INFO] [30128] Received COMMIT: id:1741323218379, from:30156, delay:0.0001s, distance:230.48m (Euclidean)
[2025-03-07 13:53:54,334] [INFO] [30128] Received PREPARE: id:1741323218379, from:30120, delay:0.0001s, distance:236.03m (Euclidean)
[2025-03-07 13:53:54,370] [INFO] [30128] Received COMMIT: id:1741323218379, from:30120, delay:0.0001s, distance:236.03m (Euclidean)
[2025-03-07 13:53:54,385] [INFO] [30128] Received PREPARE: id:1741323218379, from:30142, delay:0.0001s, distance:206.69m (Euclidean)
[2025-03-07 13:53:54,387] [INFO] [30128] Received COMMIT: id:1741323218379, from:30142, delay:0.0001s, distance:206.69m (Euclidean)
[2025-03-07 13:53:54,511] [INFO] [30128] Received PREPARE: id:1741323218379, from:30152, delay:0.0001s, distance:213.92m (Euclidean)
[2025-03-07 13:53:54,543] [INFO] [30128] Received COMMIT: id:1741323218379, from:30152, delay:0.0001s, distance:213.92m (Euclidean)
[2025-03-07 13:53:54,554] [INFO] [30128] Received PREPARE: id:1741323218379, from:30111, delay:0.0000s, distance:67.33m (Euclidean)
[2025-03-07 13:53:54,569] [INFO] [30128] Received COMMIT: id:1741323218379, from:30111, delay:0.0000s, distance:67.33m (Euclidean)
[2025-03-07 13:53:54,603] [INFO] [30128] Received COMMIT: id:1741323218379, from:30115, delay:0.0001s, distance:208.08m (Euclidean)
[2025-03-07 13:53:54,603] [INFO] [30128] Received PREPARE: id:1741323218379, from:30115, delay:0.0001s, distance:208.08m (Euclidean)
[2025-03-07 13:53:55,660] [INFO] [30128] Received PREPARE: id:1741323218379, from:30022, delay:0.0001s, distance:219.61m (Euclidean)
[2025-03-07 13:53:55,669] [INFO] [30128] Received COMMIT: id:1741323218379, from:30022, delay:0.0001s, distance:219.61m (Euclidean)
[2025-03-07 13:53:55,692] [INFO] [30128] Received PREPARE: id:1741323218379, from:30155, delay:0.0002s, distance:281.70m (Euclidean)
[2025-03-07 13:53:55,692] [INFO] [30128] Received COMMIT: id:1741323218379, from:30155, delay:0.0002s, distance:281.70m (Euclidean)
[2025-03-07 13:54:53,458] [INFO] Starting node at localhost:30128 | index=129 | f=1, k=4 | Role: Replica
[2025-03-07 13:57:39,907] [INFO] Starting node at localhost:30128 | index=129 | f=1, k=4 | Role: Replica
[2025-03-07 13:58:42,323] [INFO] Starting node at localhost:30128 | index=129 | f=1, k=4 | Role: Replica
[2025-03-07 13:59:02,623] [INFO] [30128] Received PRE-PREPARE: id:1741323542381, from:Leader(30000), delay:0.0000s, distance:159.23m (Euclidean)
[2025-03-07 13:59:02,623] [INFO] [30128] Broadcasting PREPARE for REQUEST 1741323542381
[2025-03-07 13:59:02,632] [INFO] [30128] Not broadcasting to fault node: 30077
[2025-03-07 13:59:02,646] [INFO] [30128] Not broadcasting to fault node: 30184
[2025-03-07 13:59:03,296] [INFO] [30128] Received PREPARE: id:1741323542381, from:30090, delay:0.0000s, distance:100.17m (Euclidean)
[2025-03-07 13:59:03,300] [INFO] [30128] Received PREPARE: id:1741323542381, from:30147, delay:0.0000s, distance:100.05m (Euclidean)
[2025-03-07 13:59:03,300] [INFO] [30128] Broadcasting COMMIT for REQUEST 1741323542381
[2025-03-07 13:59:03,333] [INFO] [30128] Not broadcasting to fault node: 30077
[2025-03-07 13:59:03,383] [INFO] [30128] Not broadcasting to fault node: 30184
[2025-03-07 13:59:03,387] [INFO] [30128] Received PREPARE: id:1741323542381, from:30178, delay:0.0000s, distance:150.44m (Euclidean)
[2025-03-07 13:59:03,586] [INFO] [30128] Received PREPARE: id:1741323542381, from:30080, delay:0.0000s, distance:150.05m (Euclidean)
[2025-03-07 13:59:03,631] [INFO] [30128] Received PREPARE: id:1741323542381, from:30027, delay:0.0000s, distance:299.11m (Euclidean)
[2025-03-07 13:59:03,631] [INFO] [30128] Received PREPARE: id:1741323542381, from:30110, delay:0.0000s, distance:120.68m (Euclidean)
[2025-03-07 13:59:03,675] [INFO] [30128] Received PREPARE: id:1741323542381, from:30158, delay:0.0000s, distance:75.86m (Euclidean)
[2025-03-07 13:59:03,734] [INFO] [30128] Received PREPARE: id:1741323542381, from:30155, delay:0.0000s, distance:76.41m (Euclidean)
[2025-03-07 13:59:03,762] [INFO] [30128] Received PREPARE: id:1741323542381, from:30102, delay:0.0000s, distance:127.79m (Euclidean)
[2025-03-07 13:59:03,893] [INFO] [30128] Received PREPARE: id:1741323542381, from:30136, delay:0.0000s, distance:91.27m (Euclidean)
[2025-03-07 13:59:03,985] [INFO] [30128] Received PREPARE: id:1741323542381, from:30124, delay:0.0000s, distance:130.28m (Euclidean)
[2025-03-07 13:59:03,985] [INFO] [30128] Received PREPARE: id:1741323542381, from:30196, delay:0.0001s, distance:213.26m (Euclidean)
[2025-03-07 13:59:03,986] [INFO] [30128] Received PREPARE: id:1741323542381, from:30074, delay:0.0000s, distance:143.26m (Euclidean)
[2025-03-07 13:59:04,057] [INFO] [30128] Received PREPARE: id:1741323542381, from:30133, delay:0.0001s, distance:220.99m (Euclidean)
[2025-03-07 13:59:04,119] [INFO] [30128] Received PREPARE: id:1741323542381, from:30100, delay:0.0000s, distance:106.58m (Euclidean)
[2025-03-07 13:59:04,119] [INFO] [30128] Received PREPARE: id:1741323542381, from:30119, delay:0.0001s, distance:186.69m (Euclidean)
[2025-03-07 13:59:04,134] [INFO] [30128] Received COMMIT: id:1741323542381, from:30110, delay:0.0000s, distance:120.68m (Euclidean)
[2025-03-07 13:59:04,151] [INFO] [30128] Received COMMIT: id:1741323542381, from:30147, delay:0.0000s, distance:100.05m (Euclidean)
[2025-03-07 13:59:04,151] [INFO] [LEADER 30128] Sending REPLY for REQUEST 1741323542381 to CLIENT
[2025-03-07 13:59:04,184] [INFO] [30128] Received PREPARE: id:1741323542381, from:30007, delay:0.0000s, distance:190.29m (Euclidean)
[2025-03-07 13:59:04,363] [INFO] [30128] Received PREPARE: id:1741323542381, from:30144, delay:0.0000s, distance:113.06m (Euclidean)
[2025-03-07 13:59:04,380] [INFO] [30128] Received PREPARE: id:1741323542381, from:30025, delay:0.0001s, distance:219.03m (Euclidean)
[2025-03-07 13:59:04,464] [INFO] [30128] Received PREPARE: id:1741323542381, from:30167, delay:0.0000s, distance:95.88m (Euclidean)
[2025-03-07 13:59:04,464] [INFO] [30128] Received COMMIT: id:1741323542381, from:30167, delay:0.0000s, distance:95.88m (Euclidean)
[2025-03-07 13:59:04,522] [INFO] [30128] Received PREPARE: id:1741323542381, from:30037, delay:0.0001s, distance:155.45m (Euclidean)
[2025-03-07 13:59:04,570] [INFO] [30128] Received COMMIT: id:1741323542381, from:30133, delay:0.0001s, distance:220.99m (Euclidean)
[2025-03-07 13:59:04,628] [INFO] [30128] Received COMMIT: id:1741323542381, from:30007, delay:0.0000s, distance:190.29m (Euclidean)
[2025-03-07 13:59:04,632] [INFO] [30128] Received PREPARE: id:1741323542381, from:30107, delay:0.0000s, distance:81.17m (Euclidean)
[2025-03-07 13:59:04,643] [INFO] [30128] Received COMMIT: id:1741323542381, from:30100, delay:0.0000s, distance:106.58m (Euclidean)
[2025-03-07 13:59:04,679] [INFO] [30128] Received PREPARE: id:1741323542381, from:30115, delay:0.0001s, distance:234.15m (Euclidean)
[2025-03-07 13:59:04,683] [INFO] [30128] Received COMMIT: id:1741323542381, from:30115, delay:0.0001s, distance:234.15m (Euclidean)
[2025-03-07 13:59:04,827] [INFO] [30128] Received COMMIT: id:1741323542381, from:30155, delay:0.0000s, distance:76.41m (Euclidean)
[2025-03-07 13:59:04,882] [INFO] [30128] Received COMMIT: id:1741323542381, from:30158, delay:0.0000s, distance:75.86m (Euclidean)
[2025-03-07 13:59:05,012] [INFO] [30128] Received PREPARE: id:1741323542381, from:30161, delay:0.0000s, distance:177.76m (Euclidean)
[2025-03-07 13:59:05,129] [INFO] [30128] Received COMMIT: id:1741323542381, from:30196, delay:0.0001s, distance:213.26m (Euclidean)
[2025-03-07 13:59:05,138] [INFO] [30128] Received COMMIT: id:1741323542381, from:30144, delay:0.0000s, distance:113.06m (Euclidean)
[2025-03-07 13:59:05,280] [INFO] [30128] Received COMMIT: id:1741323542381, from:30119, delay:0.0001s, distance:186.69m (Euclidean)
[2025-03-07 13:59:05,399] [INFO] [30128] Received PREPARE: id:1741323542381, from:30035, delay:0.0001s, distance:175.65m (Euclidean)
[2025-03-07 13:59:05,549] [INFO] [30128] Received PREPARE: id:1741323542381, from:30174, delay:0.0001s, distance:234.47m (Euclidean)
[2025-03-07 13:59:05,549] [INFO] [30128] Received COMMIT: id:1741323542381, from:30027, delay:0.0000s, distance:299.11m (Euclidean)
[2025-03-07 13:59:05,617] [INFO] [30128] Received PREPARE: id:1741323542381, from:30127, delay:0.0002s, distance:290.99m (Euclidean)
[2025-03-07 13:59:05,672] [INFO] [30128] Received PREPARE: id:1741323542381, from:30005, delay:0.0001s, distance:191.32m (Euclidean)
[2025-03-07 13:59:05,687] [INFO] [30128] Received PREPARE: id:1741323542381, from:30180, delay:0.0000s, distance:103.56m (Euclidean)
[2025-03-07 13:59:05,820] [INFO] [30128] Received PREPARE: id:1741323542381, from:30157, delay:0.0001s, distance:242.02m (Euclidean)
[2025-03-07 13:59:05,933] [INFO] [30128] Received COMMIT: id:1741323542381, from:30157, delay:0.0001s, distance:242.02m (Euclidean)
[2025-03-07 13:59:05,935] [INFO] [30128] Received COMMIT: id:1741323542381, from:30005, delay:0.0001s, distance:191.32m (Euclidean)
[2025-03-07 13:59:06,173] [INFO] [30128] Received PREPARE: id:1741323542381, from:30053, delay:0.0001s, distance:231.98m (Euclidean)
[2025-03-07 13:59:06,177] [INFO] [30128] Received COMMIT: id:1741323542381, from:30080, delay:0.0000s, distance:150.05m (Euclidean)
[2025-03-07 13:59:06,177] [INFO] [30128] Received PREPARE: id:1741323542381, from:30199, delay:0.0001s, distance:188.00m (Euclidean)
[2025-03-07 13:59:06,264] [INFO] [30128] Received COMMIT: id:1741323542381, from:30090, delay:0.0000s, distance:100.17m (Euclidean)
[2025-03-07 13:59:06,264] [INFO] [30128] Received PREPARE: id:1741323542381, from:30015, delay:0.0000s, distance:177.93m (Euclidean)
[2025-03-07 13:59:06,302] [INFO] [30128] Received PREPARE: id:1741323542381, from:30130, delay:0.0002s, distance:277.87m (Euclidean)
[2025-03-07 13:59:06,306] [INFO] [30128] Received PREPARE: id:1741323542381, from:30175, delay:0.0000s, distance:170.63m (Euclidean)
[2025-03-07 13:59:06,387] [INFO] [30128] Received COMMIT: id:1741323542381, from:30035, delay:0.0001s, distance:175.65m (Euclidean)
[2025-03-07 13:59:06,472] [INFO] [30128] Received PREPARE: id:1741323542381, from:30041, delay:0.0001s, distance:207.77m (Euclidean)
[2025-03-07 13:59:06,474] [INFO] [30128] Received PREPARE: id:1741323542381, from:30023, delay:0.0002s, distance:286.68m (Euclidean)
[2025-03-07 13:59:06,645] [INFO] [30128] Received PREPARE: id:1741323542381, from:30121, delay:0.0001s, distance:232.49m (Euclidean)
[2025-03-07 13:59:06,688] [INFO] [30128] Received COMMIT: id:1741323542381, from:30130, delay:0.0002s, distance:277.87m (Euclidean)
[2025-03-07 13:59:06,688] [INFO] [30128] Received COMMIT: id:1741323542381, from:30180, delay:0.0000s, distance:103.56m (Euclidean)
[2025-03-07 13:59:06,688] [INFO] [30128] Received PREPARE: id:1741323542381, from:30049, delay:0.0001s, distance:222.78m (Euclidean)
[2025-03-07 13:59:06,688] [INFO] [30128] Received COMMIT: id:1741323542381, from:30121, delay:0.0001s, distance:232.49m (Euclidean)
[2025-03-07 13:59:06,688] [INFO] [30128] Received PREPARE: id:1741323542381, from:30171, delay:0.0001s, distance:235.82m (Euclidean)
[2025-03-07 13:59:06,817] [INFO] [30128] Received PREPARE: id:1741323542381, from:30181, delay:0.0002s, distance:275.99m (Euclidean)
[2025-03-07 13:59:06,821] [INFO] [30128] Received PREPARE: id:1741323542381, from:30060, delay:0.0002s, distance:283.75m (Euclidean)
[2025-03-07 13:59:06,821] [INFO] [30128] Received COMMIT: id:1741323542381, from:30037, delay:0.0001s, distance:155.45m (Euclidean)
[2025-03-07 13:59:06,823] [INFO] [30128] Received COMMIT: id:1741323542381, from:30127, delay:0.0002s, distance:290.99m (Euclidean)
[2025-03-07 13:59:06,823] [INFO] [30128] Received COMMIT: id:1741323542381, from:30025, delay:0.0001s, distance:219.03m (Euclidean)
[2025-03-07 13:59:06,878] [INFO] [30128] Received PREPARE: id:1741323542381, from:30191, delay:0.0001s, distance:176.57m (Euclidean)
[2025-03-07 13:59:06,878] [INFO] [30128] Received COMMIT: id:1741323542381, from:30053, delay:0.0001s, distance:231.98m (Euclidean)
[2025-03-07 13:59:06,934] [INFO] [30128] Received COMMIT: id:1741323542381, from:30015, delay:0.0000s, distance:177.93m (Euclidean)
[2025-03-07 13:59:06,973] [INFO] [30128] Received COMMIT: id:1741323542381, from:30060, delay:0.0002s, distance:283.75m (Euclidean)
[2025-03-07 13:59:06,975] [INFO] [30128] Received COMMIT: id:1741323542381, from:30178, delay:0.0000s, distance:150.44m (Euclidean)
[2025-03-07 13:59:07,052] [INFO] [30128] Received PREPARE: id:1741323542381, from:30070, delay:0.0001s, distance:231.56m (Euclidean)
[2025-03-07 13:59:07,069] [INFO] [30128] Received PREPARE: id:1741323542381, from:30190, delay:0.0001s, distance:189.16m (Euclidean)
[2025-03-07 13:59:07,072] [INFO] [30128] Received COMMIT: id:1741323542381, from:30041, delay:0.0001s, distance:207.77m (Euclidean)
[2025-03-07 13:59:07,096] [INFO] [30128] Received COMMIT: id:1741323542381, from:30102, delay:0.0000s, distance:127.79m (Euclidean)
[2025-03-07 13:59:07,130] [INFO] [30128] Received COMMIT: id:1741323542381, from:30174, delay:0.0001s, distance:234.47m (Euclidean)
[2025-03-07 13:59:07,202] [INFO] [30128] Received PREPARE: id:1741323542381, from:30111, delay:0.0000s, distance:164.49m (Euclidean)
[2025-03-07 13:59:07,242] [INFO] [30128] Received PREPARE: id:1741323542381, from:30179, delay:0.0000s, distance:137.07m (Euclidean)
[2025-03-07 13:59:07,273] [INFO] [30128] Received COMMIT: id:1741323542381, from:30199, delay:0.0001s, distance:188.00m (Euclidean)
[2025-03-07 13:59:07,431] [INFO] [30128] Received PREPARE: id:1741323542381, from:30129, delay:0.0001s, distance:233.56m (Euclidean)
[2025-03-07 13:59:07,431] [INFO] [30128] Received PREPARE: id:1741323542381, from:30056, delay:0.0000s, distance:145.60m (Euclidean)
[2025-03-07 13:59:07,500] [INFO] [30128] Received COMMIT: id:1741323542381, from:30070, delay:0.0001s, distance:231.56m (Euclidean)
[2025-03-07 13:59:07,516] [INFO] [30128] Received PREPARE: id:1741323542381, from:30020, delay:0.0000s, distance:144.37m (Euclidean)
[2025-03-07 13:59:07,516] [INFO] [30128] Received COMMIT: id:1741323542381, from:30181, delay:0.0002s, distance:275.99m (Euclidean)
[2025-03-07 13:59:07,516] [INFO] [30128] Received COMMIT: id:1741323542381, from:30056, delay:0.0000s, distance:145.60m (Euclidean)
[2025-03-07 13:59:07,516] [INFO] [30128] Received PREPARE: id:1741323542381, from:30076, delay:0.0001s, distance:246.31m (Euclidean)
[2025-03-07 13:59:07,534] [INFO] [30128] Received COMMIT: id:1741323542381, from:30111, delay:0.0000s, distance:164.49m (Euclidean)
[2025-03-07 13:59:07,549] [INFO] [30128] Received COMMIT: id:1741323542381, from:30107, delay:0.0000s, distance:81.17m (Euclidean)
[2025-03-07 13:59:07,549] [INFO] [30128] Received COMMIT: id:1741323542381, from:30020, delay:0.0000s, distance:144.37m (Euclidean)
[2025-03-07 13:59:07,575] [INFO] [30128] Received PREPARE: id:1741323542381, from:30013, delay:0.0001s, distance:244.57m (Euclidean)
[2025-03-07 13:59:07,577] [INFO] [30128] Received COMMIT: id:1741323542381, from:30013, delay:0.0001s, distance:244.57m (Euclidean)
[2025-03-07 13:59:07,689] [INFO] [30128] Received COMMIT: id:1741323542381, from:30023, delay:0.0002s, distance:286.68m (Euclidean)
[2025-03-07 13:59:07,689] [INFO] [30128] Received COMMIT: id:1741323542381, from:30179, delay:0.0000s, distance:137.07m (Euclidean)
[2025-03-07 13:59:07,731] [INFO] [30128] Received PREPARE: id:1741323542381, from:30063, delay:0.0001s, distance:180.52m (Euclidean)
[2025-03-07 13:59:07,731] [INFO] [30128] Received COMMIT: id:1741323542381, from:30063, delay:0.0001s, distance:180.52m (Euclidean)
[2025-03-07 13:59:07,748] [INFO] [30128] Received COMMIT: id:1741323542381, from:30175, delay:0.0000s, distance:170.63m (Euclidean)
[2025-03-07 13:59:07,809] [INFO] [30128] Received COMMIT: id:1741323542381, from:30076, delay:0.0001s, distance:246.31m (Euclidean)
[2025-03-07 13:59:07,825] [INFO] [30128] Received PREPARE: id:1741323542381, from:30123, delay:0.0002s, distance:278.85m (Euclidean)
[2025-03-07 13:59:07,914] [INFO] [30128] Received COMMIT: id:1741323542381, from:30161, delay:0.0000s, distance:177.76m (Euclidean)
[2025-03-07 13:59:07,996] [INFO] [30128] Received PREPARE: id:1741323542381, from:30095, delay:0.0001s, distance:207.08m (Euclidean)
[2025-03-07 13:59:07,996] [INFO] [30128] Received COMMIT: id:1741323542381, from:30095, delay:0.0001s, distance:207.08m (Euclidean)
[2025-03-07 13:59:08,064] [INFO] [30128] Received COMMIT: id:1741323542381, from:30190, delay:0.0001s, distance:189.16m (Euclidean)
[2025-03-07 13:59:08,066] [INFO] [30128] Received COMMIT: id:1741323542381, from:30123, delay:0.0002s, distance:278.85m (Euclidean)
[2025-03-07 13:59:08,105] [INFO] [30128] Received PREPARE: id:1741323542381, from:30109, delay:0.0000s, distance:87.22m (Euclidean)
[2025-03-07 13:59:08,211] [INFO] [30128] Received COMMIT: id:1741323542381, from:30074, delay:0.0000s, distance:143.26m (Euclidean)
[2025-03-07 13:59:08,260] [INFO] [30128] Received COMMIT: id:1741323542381, from:30109, delay:0.0000s, distance:87.22m (Euclidean)
[2025-03-07 13:59:08,262] [INFO] [30128] Received PREPARE: id:1741323542381, from:30054, delay:0.0002s, distance:269.00m (Euclidean)
[2025-03-07 13:59:08,262] [INFO] [30128] Received PREPARE: id:1741323542381, from:30029, delay:0.0001s, distance:214.56m (Euclidean)
[2025-03-07 13:59:08,287] [INFO] [30128] Received COMMIT: id:1741323542381, from:30054, delay:0.0002s, distance:269.00m (Euclidean)
[2025-03-07 13:59:08,287] [INFO] [30128] Received COMMIT: id:1741323542381, from:30029, delay:0.0001s, distance:214.56m (Euclidean)
[2025-03-07 13:59:08,289] [INFO] [30128] Received COMMIT: id:1741323542381, from:30129, delay:0.0001s, distance:233.56m (Euclidean)
[2025-03-07 13:59:08,289] [INFO] [30128] Received PREPARE: id:1741323542381, from:30051, delay:0.0002s, distance:280.55m (Euclidean)
[2025-03-07 13:59:08,289] [INFO] [30128] Received COMMIT: id:1741323542381, from:30051, delay:0.0002s, distance:280.55m (Euclidean)
[2025-03-07 13:59:08,291] [INFO] [30128] Received COMMIT: id:1741323542381, from:30136, delay:0.0000s, distance:91.27m (Euclidean)
[2025-03-07 13:59:08,309] [INFO] [30128] Received COMMIT: id:1741323542381, from:30049, delay:0.0001s, distance:222.78m (Euclidean)
[2025-03-07 13:59:08,347] [INFO] [30128] Received COMMIT: id:1741323542381, from:30171, delay:0.0001s, distance:235.82m (Euclidean)
[2025-03-07 13:59:08,525] [INFO] [30128] Received PREPARE: id:1741323542381, from:30170, delay:0.0000s, distance:149.92m (Euclidean)
[2025-03-07 13:59:08,593] [INFO] [30128] Received COMMIT: id:1741323542381, from:30170, delay:0.0000s, distance:149.92m (Euclidean)
[2025-03-07 13:59:08,717] [INFO] [30128] Received PREPARE: id:1741323542381, from:30189, delay:0.0002s, distance:262.38m (Euclidean)
[2025-03-07 13:59:08,726] [INFO] [30128] Received COMMIT: id:1741323542381, from:30191, delay:0.0001s, distance:176.57m (Euclidean)
[2025-03-07 13:59:08,972] [INFO] [30128] Received PREPARE: id:1741323542381, from:30113, delay:0.0000s, distance:167.15m (Euclidean)
[2025-03-07 13:59:08,972] [INFO] [30128] Received PREPARE: id:1741323542381, from:30126, delay:0.0001s, distance:170.91m (Euclidean)
[2025-03-07 13:59:08,972] [INFO] [30128] Received PREPARE: id:1741323542381, from:30089, delay:0.0002s, distance:292.61m (Euclidean)
[2025-03-07 13:59:08,974] [INFO] [30128] Received COMMIT: id:1741323542381, from:30126, delay:0.0001s, distance:170.91m (Euclidean)
[2025-03-07 13:59:08,974] [INFO] [30128] Received COMMIT: id:1741323542381, from:30108, delay:0.0001s, distance:242.89m (Euclidean)
[2025-03-07 13:59:08,974] [INFO] [30128] Received COMMIT: id:1741323542381, from:30089, delay:0.0002s, distance:292.61m (Euclidean)
[2025-03-07 13:59:08,974] [INFO] [30128] Received COMMIT: id:1741323542381, from:30113, delay:0.0000s, distance:167.15m (Euclidean)
[2025-03-07 13:59:08,974] [INFO] [30128] Received PREPARE: id:1741323542381, from:30108, delay:0.0001s, distance:242.89m (Euclidean)
[2025-03-07 13:59:09,033] [INFO] [30128] Received COMMIT: id:1741323542381, from:30124, delay:0.0000s, distance:130.28m (Euclidean)
[2025-03-07 13:59:09,058] [INFO] [30128] Received PREPARE: id:1741323542381, from:30149, delay:0.0001s, distance:214.70m (Euclidean)
[2025-03-07 13:59:09,075] [INFO] [30128] Received PREPARE: id:1741323542381, from:30092, delay:0.0001s, distance:216.12m (Euclidean)
[2025-03-07 13:59:09,075] [INFO] [30128] Received COMMIT: id:1741323542381, from:30092, delay:0.0001s, distance:216.12m (Euclidean)
[2025-03-07 13:59:09,091] [INFO] [30128] Received PREPARE: id:1741323542381, from:30168, delay:0.0002s, distance:287.74m (Euclidean)
[2025-03-07 13:59:09,108] [INFO] [30128] Received COMMIT: id:1741323542381, from:30168, delay:0.0002s, distance:287.74m (Euclidean)
[2025-03-07 13:59:09,118] [INFO] [30128] Received COMMIT: id:1741323542381, from:30189, delay:0.0002s, distance:262.38m (Euclidean)
[2025-03-07 13:59:09,122] [INFO] [30128] Received COMMIT: id:1741323542381, from:30149, delay:0.0001s, distance:214.70m (Euclidean)
[2025-03-07 13:59:09,199] [INFO] [30128] Received PREPARE: id:1741323542381, from:30040, delay:0.0002s, distance:262.06m (Euclidean)
[2025-03-07 13:59:09,199] [INFO] [30128] Received COMMIT: id:1741323542381, from:30040, delay:0.0002s, distance:262.06m (Euclidean)
[2025-03-07 13:59:09,409] [INFO] [30128] Received PREPARE: id:1741323542381, from:30195, delay:0.0001s, distance:209.16m (Euclidean)
[2025-03-07 13:59:09,409] [INFO] [30128] Received COMMIT: id:1741323542381, from:30195, delay:0.0001s, distance:209.16m (Euclidean)
[2025-03-07 13:59:09,581] [INFO] [30128] Received PREPARE: id:1741323542381, from:30059, delay:0.0001s, distance:211.45m (Euclidean)
[2025-03-07 13:59:09,584] [INFO] [30128] Received COMMIT: id:1741323542381, from:30059, delay:0.0001s, distance:211.45m (Euclidean)
[2025-03-07 13:59:09,647] [INFO] [30128] Received PREPARE: id:1741323542381, from:30146, delay:0.0000s, distance:200.34m (Euclidean)
[2025-03-07 13:59:09,657] [INFO] [30128] Received PREPARE: id:1741323542381, from:30098, delay:0.0001s, distance:175.76m (Euclidean)
[2025-03-07 13:59:09,657] [INFO] [30128] Received COMMIT: id:1741323542381, from:30098, delay:0.0001s, distance:175.76m (Euclidean)
[2025-03-07 13:59:09,666] [INFO] [30128] Received PREPARE: id:1741323542381, from:30046, delay:0.0001s, distance:242.69m (Euclidean)
[2025-03-07 13:59:09,666] [INFO] [30128] Received COMMIT: id:1741323542381, from:30046, delay:0.0001s, distance:242.69m (Euclidean)
[2025-03-07 13:59:09,716] [INFO] [30128] Received PREPARE: id:1741323542381, from:30182, delay:0.0001s, distance:176.00m (Euclidean)
[2025-03-07 13:59:09,728] [INFO] [30128] Received COMMIT: id:1741323542381, from:30182, delay:0.0001s, distance:176.00m (Euclidean)
[2025-03-07 13:59:09,768] [INFO] [30128] Received PREPARE: id:1741323542381, from:30177, delay:0.0001s, distance:186.20m (Euclidean)
[2025-03-07 13:59:09,768] [INFO] [30128] Received COMMIT: id:1741323542381, from:30177, delay:0.0001s, distance:186.20m (Euclidean)
[2025-03-07 13:59:09,996] [INFO] [30128] Received PREPARE: id:1741323542381, from:30062, delay:0.0000s, distance:129.69m (Euclidean)
[2025-03-07 13:59:09,998] [INFO] [30128] Received COMMIT: id:1741323542381, from:30062, delay:0.0000s, distance:129.69m (Euclidean)
[2025-03-07 13:59:10,202] [INFO] [30128] Received PREPARE: id:1741323542381, from:30028, delay:0.0001s, distance:248.40m (Euclidean)
[2025-03-07 13:59:10,233] [INFO] [30128] Received COMMIT: id:1741323542381, from:30028, delay:0.0001s, distance:248.40m (Euclidean)
[2025-03-07 13:59:10,351] [INFO] [30128] Received PREPARE: id:1741323542381, from:30176, delay:0.0001s, distance:225.29m (Euclidean)
[2025-03-07 13:59:10,355] [INFO] [30128] Received COMMIT: id:1741323542381, from:30176, delay:0.0001s, distance:225.29m (Euclidean)
[2025-03-07 13:59:10,382] [INFO] [30128] Received PREPARE: id:1741323542381, from:30112, delay:0.0002s, distance:291.05m (Euclidean)
[2025-03-07 13:59:10,398] [INFO] [30128] Received COMMIT: id:1741323542381, from:30112, delay:0.0002s, distance:291.05m (Euclidean)
[2025-03-07 13:59:10,526] [INFO] [30128] Received PREPARE: id:1741323542381, from:30154, delay:0.0000s, distance:161.22m (Euclidean)
[2025-03-07 13:59:10,526] [INFO] [30128] Received COMMIT: id:1741323542381, from:30154, delay:0.0000s, distance:161.22m (Euclidean)
[2025-03-07 13:59:10,749] [INFO] [30128] Received PREPARE: id:1741323542381, from:30066, delay:0.0000s, distance:182.40m (Euclidean)
[2025-03-07 13:59:10,776] [INFO] [30128] Received PREPARE: id:1741323542381, from:30048, delay:0.0000s, distance:104.52m (Euclidean)
[2025-03-07 13:59:10,779] [INFO] [30128] Received COMMIT: id:1741323542381, from:30048, delay:0.0000s, distance:104.52m (Euclidean)
[2025-03-07 13:59:10,779] [INFO] [30128] Received COMMIT: id:1741323542381, from:30066, delay:0.0000s, distance:182.40m (Euclidean)
[2025-03-07 13:59:10,779] [INFO] [30128] Received PREPARE: id:1741323542381, from:30150, delay:0.0000s, distance:123.35m (Euclidean)
[2025-03-07 13:59:10,785] [INFO] [30128] Received COMMIT: id:1741323542381, from:30150, delay:0.0000s, distance:123.35m (Euclidean)
[2025-03-07 13:59:10,830] [INFO] [30128] Received PREPARE: id:1741323542381, from:30057, delay:0.0002s, distance:295.57m (Euclidean)
[2025-03-07 13:59:10,833] [INFO] [30128] Received PREPARE: id:1741323542381, from:30120, delay:0.0001s, distance:210.98m (Euclidean)
[2025-03-07 13:59:10,833] [INFO] [30128] Received COMMIT: id:1741323542381, from:30057, delay:0.0002s, distance:295.57m (Euclidean)
[2025-03-07 13:59:10,833] [INFO] [30128] Received COMMIT: id:1741323542381, from:30120, delay:0.0001s, distance:210.98m (Euclidean)
[2025-03-07 13:59:11,048] [INFO] [30128] Received PREPARE: id:1741323542381, from:30116, delay:0.0001s, distance:214.68m (Euclidean)
[2025-03-07 13:59:11,048] [INFO] [30128] Received COMMIT: id:1741323542381, from:30116, delay:0.0001s, distance:214.68m (Euclidean)
[2025-03-07 13:59:11,074] [INFO] [30128] Received PREPARE: id:1741323542381, from:30096, delay:0.0001s, distance:157.51m (Euclidean)
[2025-03-07 13:59:11,074] [INFO] [30128] Received COMMIT: id:1741323542381, from:30096, delay:0.0001s, distance:157.51m (Euclidean)
[2025-03-07 13:59:11,127] [INFO] [30128] Received PREPARE: id:1741323542381, from:30043, delay:0.0000s, distance:198.11m (Euclidean)
[2025-03-07 13:59:11,127] [INFO] [30128] Received COMMIT: id:1741323542381, from:30043, delay:0.0000s, distance:198.11m (Euclidean)
[2025-03-07 13:59:11,160] [INFO] [30128] Received PREPARE: id:1741323542381, from:30085, delay:0.0001s, distance:206.54m (Euclidean)
[2025-03-07 13:59:11,160] [INFO] [30128] Received COMMIT: id:1741323542381, from:30085, delay:0.0001s, distance:206.54m (Euclidean)
[2025-03-07 13:59:11,477] [INFO] [30128] Received PREPARE: id:1741323542381, from:30118, delay:0.0002s, distance:251.00m (Euclidean)
[2025-03-07 13:59:11,484] [INFO] [30128] Received COMMIT: id:1741323542381, from:30118, delay:0.0002s, distance:251.00m (Euclidean)
[2025-03-07 13:59:11,671] [INFO] [30128] Received PREPARE: id:1741323542381, from:30065, delay:0.0001s, distance:213.40m (Euclidean)
[2025-03-07 13:59:11,671] [INFO] [30128] Received COMMIT: id:1741323542381, from:30065, delay:0.0001s, distance:213.40m (Euclidean)
[2025-03-07 13:59:11,977] [INFO] [30128] Received PREPARE: id:1741323542381, from:30004, delay:0.0001s, distance:209.52m (Euclidean)
[2025-03-07 13:59:11,977] [INFO] [30128] Received COMMIT: id:1741323542381, from:30004, delay:0.0001s, distance:209.52m (Euclidean)
[2025-03-07 13:59:12,113] [INFO] [30128] Received PREPARE: id:1741323542381, from:30021, delay:0.0000s, distance:131.44m (Euclidean)
[2025-03-07 13:59:12,113] [INFO] [30128] Received COMMIT: id:1741323542381, from:30021, delay:0.0000s, distance:131.44m (Euclidean)
[2025-03-07 13:59:12,183] [INFO] [30128] Received PREPARE: id:1741323542381, from:30011, delay:0.0000s, distance:145.41m (Euclidean)
[2025-03-07 13:59:12,186] [INFO] [30128] Received COMMIT: id:1741323542381, from:30011, delay:0.0000s, distance:145.41m (Euclidean)
[2025-03-07 13:59:12,243] [INFO] [30128] Received PREPARE: id:1741323542381, from:30103, delay:0.0000s, distance:120.93m (Euclidean)
[2025-03-07 13:59:12,245] [INFO] [30128] Received COMMIT: id:1741323542381, from:30103, delay:0.0000s, distance:120.93m (Euclidean)
[2025-03-07 13:59:12,465] [INFO] [30128] Received PREPARE: id:1741323542381, from:30093, delay:0.0001s, distance:234.85m (Euclidean)
[2025-03-07 13:59:12,465] [INFO] [30128] Received COMMIT: id:1741323542381, from:30093, delay:0.0001s, distance:234.85m (Euclidean)
[2025-03-07 13:59:12,468] [INFO] [30128] Received PREPARE: id:1741323542381, from:30024, delay:0.0001s, distance:230.30m (Euclidean)
[2025-03-07 13:59:12,468] [INFO] [30128] Received COMMIT: id:1741323542381, from:30024, delay:0.0001s, distance:230.30m (Euclidean)
[2025-03-07 13:59:12,540] [INFO] [30128] Received COMMIT: id:1741323542381, from:30000, delay:0.0000s, distance:159.23m (Euclidean)
[2025-03-07 13:59:12,721] [INFO] [30128] Received PREPARE: id:1741323542381, from:30086, delay:0.0000s, distance:95.61m (Euclidean)
[2025-03-07 13:59:12,740] [INFO] [30128] Received PREPARE: id:1741323542381, from:30156, delay:0.0000s, distance:249.66m (Euclidean)
[2025-03-07 13:59:12,905] [INFO] [30128] Received COMMIT: id:1741323542381, from:30086, delay:0.0000s, distance:95.61m (Euclidean)
[2025-03-07 13:59:13,717] [INFO] [30128] Received COMMIT: id:1741323542381, from:30146, delay:0.0000s, distance:200.34m (Euclidean)
[2025-03-07 13:59:13,991] [INFO] [30128] Received PREPARE: id:1741323542381, from:30153, delay:0.0000s, distance:98.71m (Euclidean)
[2025-03-07 13:59:14,011] [INFO] [30128] Received COMMIT: id:1741323542381, from:30153, delay:0.0000s, distance:98.71m (Euclidean)
[2025-03-07 13:59:14,166] [INFO] [30128] Received PREPARE: id:1741323542381, from:30125, delay:0.0000s, distance:86.59m (Euclidean)
[2025-03-07 13:59:14,175] [INFO] [30128] Received COMMIT: id:1741323542381, from:30125, delay:0.0000s, distance:86.59m (Euclidean)
[2025-03-07 13:59:14,399] [INFO] [30128] Received PREPARE: id:1741323542381, from:30140, delay:0.0000s, distance:96.97m (Euclidean)
[2025-03-07 13:59:14,399] [INFO] [30128] Received COMMIT: id:1741323542381, from:30140, delay:0.0000s, distance:96.97m (Euclidean)
[2025-03-07 13:59:14,777] [INFO] [30128] Received PREPARE: id:1741323542381, from:30068, delay:0.0000s, distance:75.91m (Euclidean)
[2025-03-07 13:59:14,785] [INFO] [30128] Received PREPARE: id:1741323542381, from:30026, delay:0.0002s, distance:277.85m (Euclidean)
[2025-03-07 13:59:14,789] [INFO] [30128] Received COMMIT: id:1741323542381, from:30026, delay:0.0002s, distance:277.85m (Euclidean)
[2025-03-07 13:59:15,048] [INFO] [30128] Received PREPARE: id:1741323542381, from:30003, delay:0.0000s, distance:51.36m (Euclidean)
[2025-03-07 13:59:15,048] [INFO] [30128] Received COMMIT: id:1741323542381, from:30003, delay:0.0000s, distance:51.36m (Euclidean)
[2025-03-07 13:59:15,399] [INFO] [30128] Received PREPARE: id:1741323542381, from:30034, delay:0.0001s, distance:223.52m (Euclidean)
[2025-03-07 13:59:15,399] [INFO] [30128] Received COMMIT: id:1741323542381, from:30034, delay:0.0001s, distance:223.52m (Euclidean)
[2025-03-07 13:59:15,415] [INFO] [30128] Received COMMIT: id:1741323542381, from:30068, delay:0.0000s, distance:75.91m (Euclidean)
[2025-03-07 13:59:15,462] [INFO] [30128] Received PREPARE: id:1741323542381, from:30117, delay:0.0001s, distance:228.78m (Euclidean)
[2025-03-07 13:59:15,462] [INFO] [30128] Received COMMIT: id:1741323542381, from:30117, delay:0.0001s, distance:228.78m (Euclidean)
[2025-03-07 13:59:15,513] [INFO] [30128] Received PREPARE: id:1741323542381, from:30033, delay:0.0001s, distance:165.68m (Euclidean)
[2025-03-07 13:59:15,706] [INFO] [30128] Received PREPARE: id:1741323542381, from:30088, delay:0.0001s, distance:211.06m (Euclidean)
[2025-03-07 13:59:15,706] [INFO] [30128] Received COMMIT: id:1741323542381, from:30088, delay:0.0001s, distance:211.06m (Euclidean)
[2025-03-07 13:59:15,763] [INFO] [30128] Received PREPARE: id:1741323542381, from:30071, delay:0.0001s, distance:214.56m (Euclidean)
[2025-03-07 13:59:15,770] [INFO] [30128] Received COMMIT: id:1741323542381, from:30071, delay:0.0001s, distance:214.56m (Euclidean)
[2025-03-07 13:59:16,290] [INFO] [30128] Received PREPARE: id:1741323542381, from:30017, delay:0.0000s, distance:86.25m (Euclidean)
[2025-03-07 13:59:16,302] [INFO] [30128] Received PREPARE: id:1741323542381, from:30197, delay:0.0000s, distance:61.69m (Euclidean)
[2025-03-07 13:59:16,306] [INFO] [30128] Received COMMIT: id:1741323542381, from:30197, delay:0.0000s, distance:61.69m (Euclidean)
[2025-03-07 13:59:16,411] [INFO] [30128] Received PREPARE: id:1741323542381, from:30019, delay:0.0000s, distance:47.01m (Euclidean)
[2025-03-07 13:59:16,411] [INFO] [30128] Received COMMIT: id:1741323542381, from:30019, delay:0.0000s, distance:47.01m (Euclidean)
[2025-03-07 13:59:16,647] [INFO] [30128] Received PREPARE: id:1741323542381, from:30069, delay:0.0002s, distance:266.84m (Euclidean)
[2025-03-07 13:59:16,959] [INFO] [30128] Received COMMIT: id:1741323542381, from:30156, delay:0.0000s, distance:249.66m (Euclidean)
[2025-03-07 13:59:17,558] [INFO] [30128] Received COMMIT: id:1741323542381, from:30033, delay:0.0001s, distance:165.68m (Euclidean)
[2025-03-07 13:59:18,169] [INFO] [30128] Received PREPARE: id:1741323542381, from:30081, delay:0.0002s, distance:251.67m (Euclidean)
[2025-03-07 13:59:18,779] [INFO] [30128] Received PREPARE: id:1741323542381, from:30032, delay:0.0001s, distance:206.95m (Euclidean)
[2025-03-07 13:59:18,779] [INFO] [30128] Received COMMIT: id:1741323542381, from:30032, delay:0.0001s, distance:206.95m (Euclidean)
[2025-03-07 13:59:18,855] [INFO] [30128] Received PREPARE: id:1741323542381, from:30008, delay:0.0001s, distance:250.36m (Euclidean)
[2025-03-07 13:59:18,971] [INFO] [30128] Received COMMIT: id:1741323542381, from:30069, delay:0.0002s, distance:266.84m (Euclidean)
[2025-03-07 13:59:18,972] [INFO] [30128] Received COMMIT: id:1741323542381, from:30081, delay:0.0002s, distance:251.67m (Euclidean)
[2025-03-07 13:59:19,681] [INFO] [30128] Received PREPARE: id:1741323542381, from:30152, delay:0.0000s, distance:136.93m (Euclidean)
[2025-03-07 13:59:19,708] [INFO] [30128] Received COMMIT: id:1741323542381, from:30152, delay:0.0000s, distance:136.93m (Euclidean)
[2025-03-07 13:59:19,738] [INFO] [30128] Received PREPARE: id:1741323542381, from:30042, delay:0.0001s, distance:254.32m (Euclidean)
[2025-03-07 13:59:19,753] [INFO] [30128] Received COMMIT: id:1741323542381, from:30042, delay:0.0001s, distance:254.32m (Euclidean)
[2025-03-07 13:59:19,940] [INFO] [30128] Received PREPARE: id:1741323542381, from:30159, delay:0.0001s, distance:179.03m (Euclidean)
[2025-03-07 13:59:19,940] [INFO] [30128] Received COMMIT: id:1741323542381, from:30159, delay:0.0001s, distance:179.03m (Euclidean)
[2025-03-07 13:59:19,952] [INFO] [30128] Received COMMIT: id:1741323542381, from:30017, delay:0.0000s, distance:86.25m (Euclidean)
[2025-03-07 13:59:20,147] [INFO] [30128] Received PREPARE: id:1741323542381, from:30050, delay:0.0002s, distance:287.35m (Euclidean)
[2025-03-07 13:59:20,147] [INFO] [30128] Received COMMIT: id:1741323542381, from:30050, delay:0.0002s, distance:287.35m (Euclidean)
[2025-03-07 13:59:20,416] [INFO] [30128] Received PREPARE: id:1741323542381, from:30135, delay:0.0001s, distance:221.88m (Euclidean)
[2025-03-07 13:59:20,416] [INFO] [30128] Received COMMIT: id:1741323542381, from:30135, delay:0.0001s, distance:221.88m (Euclidean)
[2025-03-07 13:59:20,550] [INFO] [30128] Received PREPARE: id:1741323542381, from:30067, delay:0.0001s, distance:236.62m (Euclidean)
[2025-03-07 13:59:20,552] [INFO] [30128] Received COMMIT: id:1741323542381, from:30067, delay:0.0001s, distance:236.62m (Euclidean)
[2025-03-07 13:59:21,136] [INFO] [30128] Received PREPARE: id:1741323542381, from:30151, delay:0.0001s, distance:209.76m (Euclidean)
[2025-03-07 13:59:21,138] [INFO] [30128] Received COMMIT: id:1741323542381, from:30151, delay:0.0001s, distance:209.76m (Euclidean)
[2025-03-07 13:59:21,212] [INFO] [30128] Received PREPARE: id:1741323542381, from:30064, delay:0.0001s, distance:240.05m (Euclidean)
[2025-03-07 13:59:21,212] [INFO] [30128] Received COMMIT: id:1741323542381, from:30064, delay:0.0001s, distance:240.05m (Euclidean)
[2025-03-07 13:59:21,255] [INFO] [30128] Received PREPARE: id:1741323542381, from:30134, delay:0.0001s, distance:220.09m (Euclidean)
[2025-03-07 13:59:21,257] [INFO] [30128] Received COMMIT: id:1741323542381, from:30134, delay:0.0001s, distance:220.09m (Euclidean)
[2025-03-07 13:59:21,309] [INFO] [30128] Received PREPARE: id:1741323542381, from:30188, delay:0.0001s, distance:173.14m (Euclidean)
[2025-03-07 13:59:21,311] [INFO] [30128] Received COMMIT: id:1741323542381, from:30188, delay:0.0001s, distance:173.14m (Euclidean)
[2025-03-07 13:59:21,319] [INFO] [30128] Received PREPARE: id:1741323542381, from:30139, delay:0.0002s, distance:273.71m (Euclidean)
[2025-03-07 13:59:21,319] [INFO] [30128] Received COMMIT: id:1741323542381, from:30139, delay:0.0002s, distance:273.71m (Euclidean)
[2025-03-07 13:59:21,485] [INFO] [30128] Received PREPARE: id:1741323542381, from:30052, delay:0.0002s, distance:280.20m (Euclidean)
[2025-03-07 13:59:21,514] [INFO] [30128] Received COMMIT: id:1741323542381, from:30052, delay:0.0002s, distance:280.20m (Euclidean)
[2025-03-07 13:59:22,021] [INFO] [30128] Received PREPARE: id:1741323542381, from:30173, delay:0.0002s, distance:272.53m (Euclidean)
[2025-03-07 13:59:22,021] [INFO] [30128] Received COMMIT: id:1741323542381, from:30173, delay:0.0002s, distance:272.53m (Euclidean)
[2025-03-07 13:59:22,074] [INFO] [30128] Received PREPARE: id:1741323542381, from:30193, delay:0.0001s, distance:207.58m (Euclidean)
[2025-03-07 13:59:22,076] [INFO] [30128] Received COMMIT: id:1741323542381, from:30193, delay:0.0001s, distance:207.58m (Euclidean)
[2025-03-07 13:59:22,141] [INFO] [30128] Received PREPARE: id:1741323542381, from:30162, delay:0.0000s, distance:115.28m (Euclidean)
[2025-03-07 13:59:22,514] [INFO] [30128] Received PREPARE: id:1741323542381, from:30186, delay:0.0001s, distance:234.10m (Euclidean)
[2025-03-07 13:59:22,514] [INFO] [30128] Received PREPARE: id:1741323542381, from:30094, delay:0.0001s, distance:246.16m (Euclidean)
[2025-03-07 13:59:22,514] [INFO] [30128] Received COMMIT: id:1741323542381, from:30094, delay:0.0001s, distance:246.16m (Euclidean)
[2025-03-07 13:59:22,514] [INFO] [30128] Received COMMIT: id:1741323542381, from:30186, delay:0.0001s, distance:234.10m (Euclidean)
[2025-03-07 13:59:22,622] [INFO] [30128] Received PREPARE: id:1741323542381, from:30145, delay:0.0002s, distance:265.73m (Euclidean)
[2025-03-07 13:59:22,622] [INFO] [30128] Received COMMIT: id:1741323542381, from:30145, delay:0.0002s, distance:265.73m (Euclidean)
[2025-03-07 13:59:22,649] [INFO] [30128] Received PREPARE: id:1741323542381, from:30131, delay:0.0001s, distance:194.06m (Euclidean)
[2025-03-07 13:59:22,651] [INFO] [30128] Received COMMIT: id:1741323542381, from:30131, delay:0.0001s, distance:194.06m (Euclidean)
[2025-03-07 13:59:22,720] [INFO] [30128] Received PREPARE: id:1741323542381, from:30006, delay:0.0001s, distance:233.78m (Euclidean)
[2025-03-07 13:59:22,722] [INFO] [30128] Received COMMIT: id:1741323542381, from:30006, delay:0.0001s, distance:233.78m (Euclidean)
[2025-03-07 13:59:22,912] [INFO] [30128] Received PREPARE: id:1741323542381, from:30091, delay:0.0001s, distance:177.72m (Euclidean)
[2025-03-07 13:59:22,912] [INFO] [30128] Received COMMIT: id:1741323542381, from:30091, delay:0.0001s, distance:177.72m (Euclidean)
[2025-03-07 13:59:22,957] [INFO] [30128] Received PREPARE: id:1741323542381, from:30084, delay:0.0001s, distance:195.44m (Euclidean)
[2025-03-07 13:59:22,957] [INFO] [30128] Received COMMIT: id:1741323542381, from:30084, delay:0.0001s, distance:195.44m (Euclidean)
[2025-03-07 13:59:23,144] [INFO] [30128] Received COMMIT: id:1741323542381, from:30008, delay:0.0001s, distance:250.36m (Euclidean)
[2025-03-07 13:59:23,376] [INFO] [30128] Received PREPARE: id:1741323542381, from:30141, delay:0.0001s, distance:218.77m (Euclidean)
[2025-03-07 13:59:23,376] [INFO] [30128] Received COMMIT: id:1741323542381, from:30141, delay:0.0001s, distance:218.77m (Euclidean)
[2025-03-07 13:59:23,711] [INFO] [30128] Received PREPARE: id:1741323542381, from:30160, delay:0.0001s, distance:222.81m (Euclidean)
[2025-03-07 13:59:23,711] [INFO] [30128] Received COMMIT: id:1741323542381, from:30160, delay:0.0001s, distance:222.81m (Euclidean)
[2025-03-07 13:59:23,867] [INFO] [30128] Received PREPARE: id:1741323542381, from:30073, delay:0.0001s, distance:224.32m (Euclidean)
[2025-03-07 13:59:23,880] [INFO] [30128] Received COMMIT: id:1741323542381, from:30073, delay:0.0001s, distance:224.32m (Euclidean)
[2025-03-07 13:59:24,104] [INFO] [30128] Received COMMIT: id:1741323542381, from:30162, delay:0.0000s, distance:115.28m (Euclidean)
[2025-03-07 13:59:24,584] [INFO] [30128] Received PREPARE: id:1741323542381, from:30083, delay:0.0002s, distance:297.78m (Euclidean)
[2025-03-07 13:59:24,584] [INFO] [30128] Received COMMIT: id:1741323542381, from:30083, delay:0.0002s, distance:297.78m (Euclidean)
[2025-03-07 13:59:24,634] [INFO] [30128] Received PREPARE: id:1741323542381, from:30039, delay:0.0002s, distance:285.04m (Euclidean)
[2025-03-07 13:59:24,636] [INFO] [30128] Received PREPARE: id:1741323542381, from:30194, delay:0.0001s, distance:172.24m (Euclidean)
[2025-03-07 13:59:24,636] [INFO] [30128] Received COMMIT: id:1741323542381, from:30194, delay:0.0001s, distance:172.24m (Euclidean)
[2025-03-07 13:59:24,636] [INFO] [30128] Received COMMIT: id:1741323542381, from:30039, delay:0.0002s, distance:285.04m (Euclidean)
[2025-03-07 13:59:24,841] [INFO] [30128] Received PREPARE: id:1741323542381, from:30001, delay:0.0002s, distance:297.89m (Euclidean)
[2025-03-07 13:59:24,841] [INFO] [30128] Received COMMIT: id:1741323542381, from:30001, delay:0.0002s, distance:297.89m (Euclidean)
[2025-03-07 13:59:25,065] [INFO] [30128] Received PREPARE: id:1741323542381, from:30075, delay:0.0001s, distance:224.57m (Euclidean)
[2025-03-07 13:59:25,065] [INFO] [30128] Received COMMIT: id:1741323542381, from:30075, delay:0.0001s, distance:224.57m (Euclidean)
[2025-03-07 13:59:25,079] [INFO] [30128] Received PREPARE: id:1741323542381, from:30055, delay:0.0002s, distance:276.27m (Euclidean)
[2025-03-07 13:59:25,079] [INFO] [30128] Received COMMIT: id:1741323542381, from:30055, delay:0.0002s, distance:276.27m (Euclidean)
[2025-03-07 13:59:25,288] [INFO] [30128] Received PREPARE: id:1741323542381, from:30138, delay:0.0002s, distance:269.07m (Euclidean)
[2025-03-07 13:59:25,319] [INFO] [30128] Received COMMIT: id:1741323542381, from:30138, delay:0.0002s, distance:269.07m (Euclidean)
[2025-03-07 13:59:25,697] [INFO] [30128] Received PREPARE: id:1741323542381, from:30022, delay:0.0000s, distance:146.79m (Euclidean)
[2025-03-07 13:59:25,697] [INFO] [30128] Received COMMIT: id:1741323542381, from:30022, delay:0.0000s, distance:146.79m (Euclidean)
[2025-03-07 13:59:26,072] [INFO] [30128] Received PREPARE: id:1741323542381, from:30148, delay:0.0001s, distance:198.75m (Euclidean)
[2025-03-07 13:59:26,072] [INFO] [30128] Received COMMIT: id:1741323542381, from:30148, delay:0.0001s, distance:198.75m (Euclidean)
[2025-03-07 13:59:26,263] [INFO] [30128] Received PREPARE: id:1741323542381, from:30101, delay:0.0002s, distance:274.85m (Euclidean)
[2025-03-07 13:59:26,263] [INFO] [30128] Received COMMIT: id:1741323542381, from:30101, delay:0.0002s, distance:274.85m (Euclidean)
[2025-03-07 13:59:26,545] [INFO] [30128] Received PREPARE: id:1741323542381, from:30099, delay:0.0002s, distance:254.16m (Euclidean)
[2025-03-07 13:59:26,546] [INFO] [30128] Received COMMIT: id:1741323542381, from:30099, delay:0.0002s, distance:254.16m (Euclidean)
[2025-03-07 13:59:26,644] [INFO] [30128] Received PREPARE: id:1741323542381, from:30045, delay:0.0002s, distance:282.41m (Euclidean)
[2025-03-07 13:59:26,644] [INFO] [30128] Received COMMIT: id:1741323542381, from:30045, delay:0.0002s, distance:282.41m (Euclidean)
[2025-03-07 13:59:26,767] [INFO] [30128] Received PREPARE: id:1741323542381, from:30166, delay:0.0002s, distance:250.76m (Euclidean)
[2025-03-07 13:59:26,767] [INFO] [30128] Received COMMIT: id:1741323542381, from:30166, delay:0.0002s, distance:250.76m (Euclidean)
[2025-03-07 13:59:28,619] [INFO] [30128] Received PREPARE: id:1741323542381, from:30097, delay:0.0002s, distance:269.43m (Euclidean)
[2025-03-07 13:59:28,628] [INFO] [30128] Received COMMIT: id:1741323542381, from:30097, delay:0.0002s, distance:269.43m (Euclidean)
[2025-03-07 13:59:28,660] [INFO] [30128] Received PREPARE: id:1741323542381, from:30183, delay:0.0000s, distance:133.46m (Euclidean)
[2025-03-07 13:59:28,680] [INFO] [30128] Received COMMIT: id:1741323542381, from:30183, delay:0.0000s, distance:133.46m (Euclidean)
[2025-03-07 13:59:28,710] [INFO] [30128] Received PREPARE: id:1741323542381, from:30078, delay:0.0001s, distance:183.61m (Euclidean)
[2025-03-07 13:59:28,857] [INFO] [30128] Received COMMIT: id:1741323542381, from:30078, delay:0.0001s, distance:183.61m (Euclidean)
[2025-03-07 13:59:28,934] [INFO] [30128] Received PREPARE: id:1741323542381, from:30072, delay:0.0002s, distance:275.00m (Euclidean)
[2025-03-07 13:59:28,988] [INFO] [30128] Received COMMIT: id:1741323542381, from:30072, delay:0.0002s, distance:275.00m (Euclidean)
[2025-03-07 13:59:33,169] [INFO] [30128] Received PREPARE: id:1741323542381, from:30172, delay:0.0001s, distance:209.39m (Euclidean)
[2025-03-07 13:59:33,283] [INFO] [30128] Received PREPARE: id:1741323542381, from:30002, delay:0.0002s, distance:265.24m (Euclidean)
[2025-03-07 13:59:33,353] [INFO] [30128] Received PREPARE: id:1741323542381, from:30030, delay:0.0001s, distance:247.04m (Euclidean)
[2025-03-07 13:59:37,290] [INFO] [30128] Received COMMIT: id:1741323542381, from:30030, delay:0.0001s, distance:247.04m (Euclidean)
[2025-03-07 13:59:37,588] [INFO] [30128] Received COMMIT: id:1741323542381, from:30012, delay:0.0002s, distance:285.50m (Euclidean)
[2025-03-07 13:59:38,015] [INFO] [30128] Received COMMIT: id:1741323542381, from:30018, delay:0.0001s, distance:223.04m (Euclidean)
[2025-03-07 13:59:38,119] [INFO] [30128] Received COMMIT: id:1741323542381, from:30002, delay:0.0002s, distance:265.24m (Euclidean)
[2025-03-07 13:59:38,531] [INFO] [30128] Received PREPARE: id:1741323542381, from:30192, delay:0.0002s, distance:274.41m (Euclidean)
[2025-03-07 13:59:38,600] [INFO] [30128] Received PREPARE: id:1741323542381, from:30163, delay:0.0002s, distance:298.69m (Euclidean)
[2025-03-07 13:59:38,664] [INFO] [30128] Received COMMIT: id:1741323542381, from:30192, delay:0.0002s, distance:274.41m (Euclidean)
[2025-03-07 13:59:38,664] [INFO] [30128] Received COMMIT: id:1741323542381, from:30172, delay:0.0001s, distance:209.39m (Euclidean)
[2025-03-07 13:59:38,738] [INFO] [30128] Received COMMIT: id:1741323542381, from:30163, delay:0.0002s, distance:298.69m (Euclidean)
[2025-03-07 13:59:38,833] [INFO] [30128] Received PREPARE: id:1741323542381, from:30164, delay:0.0001s, distance:184.36m (Euclidean)
[2025-03-07 13:59:38,835] [INFO] [30128] Received COMMIT: id:1741323542381, from:30164, delay:0.0001s, distance:184.36m (Euclidean)
