[2025-03-07 13:53:28,863] [INFO] Starting node at localhost:30130 | index=131 | f=1, k=4 | Role: Replica
[2025-03-07 13:53:39,049] [INFO] [30130] Received PREPARE: id:1741323218379, from:30006, delay:0.0000s, distance:299.35m (Euclidean)
[2025-03-07 13:53:39,049] [INFO] [30130] Missing PRE-PREPARE for REQUEST 1741323218379; ignoring PREPARE
[2025-03-07 13:53:39,154] [INFO] [30130] Received PREPARE: id:1741323218379, from:30035, delay:0.0000s, distance:200.32m (Euclidean)
[2025-03-07 13:53:39,154] [INFO] [30130] Missing PRE-PREPARE for REQUEST 1741323218379; ignoring PREPARE
[2025-03-07 13:53:39,250] [INFO] [30130] Received PREPARE: id:1741323218379, from:30002, delay:0.0000s, distance:150.79m (Euclidean)
[2025-03-07 13:53:39,250] [INFO] [30130] Missing PRE-PREPARE for REQUEST 1741323218379; ignoring PREPARE
[2025-03-07 13:53:39,462] [INFO] [30130] Received COMMIT: id:1741323218379, from:30006, delay:0.0000s, distance:299.35m (Euclidean)
[2025-03-07 13:53:39,690] [INFO] [30130] Received PREPARE: id:1741323218379, from:30086, delay:0.0000s, distance:112.16m (Euclidean)
[2025-03-07 13:53:39,690] [INFO] [30130] Missing PRE-PREPARE for REQUEST 1741323218379; ignoring PREPARE
[2025-03-07 13:53:39,690] [INFO] [30130] Received COMMIT: id:1741323218379, from:30086, delay:0.0000s, distance:112.16m (Euclidean)
[2025-03-07 13:53:39,799] [INFO] [30130] Received PREPARE: id:1741323218379, from:30005, delay:0.0000s, distance:124.34m (Euclidean)
[2025-03-07 13:53:39,799] [INFO] [30130] Missing PRE-PREPARE for REQUEST 1741323218379; ignoring PREPARE
[2025-03-07 13:53:39,800] [INFO] [30130] Received COMMIT: id:1741323218379, from:30005, delay:0.0000s, distance:124.34m (Euclidean)
[2025-03-07 13:53:39,913] [INFO] [30130] Received PREPARE: id:1741323218379, from:30090, delay:0.0000s, distance:131.56m (Euclidean)
[2025-03-07 13:53:39,913] [INFO] [30130] Missing PRE-PREPARE for REQUEST 1741323218379; ignoring PREPARE
[2025-03-07 13:53:39,913] [INFO] [30130] Received COMMIT: id:1741323218379, from:30090, delay:0.0000s, distance:131.56m (Euclidean)
[2025-03-07 13:53:39,974] [INFO] [30130] Received PREPARE: id:1741323218379, from:30083, delay:0.0000s, distance:78.70m (Euclidean)
[2025-03-07 13:53:39,974] [INFO] [30130] Missing PRE-PREPARE for REQUEST 1741323218379; ignoring PREPARE
[2025-03-07 13:53:39,974] [INFO] [30130] Received COMMIT: id:1741323218379, from:30083, delay:0.0000s, distance:78.70m (Euclidean)
[2025-03-07 13:53:39,990] [INFO] [30130] Received PREPARE: id:1741323218379, from:30087, delay:0.0001s, distance:190.43m (Euclidean)
[2025-03-07 13:53:39,990] [INFO] [30130] Missing PRE-PREPARE for REQUEST 1741323218379; ignoring PREPARE
[2025-03-07 13:53:40,021] [INFO] [30130] Received COMMIT: id:1741323218379, from:30087, delay:0.0001s, distance:190.43m (Euclidean)
[2025-03-07 13:53:40,132] [INFO] [30130] Received PREPARE: id:1741323218379, from:30021, delay:0.0002s, distance:275.56m (Euclidean)
[2025-03-07 13:53:40,132] [INFO] [30130] Missing PRE-PREPARE for REQUEST 1741323218379; ignoring PREPARE
[2025-03-07 13:53:40,148] [INFO] [30130] Received COMMIT: id:1741323218379, from:30021, delay:0.0002s, distance:275.56m (Euclidean)
[2025-03-07 13:53:40,314] [INFO] [30130] Received PREPARE: id:1741323218379, from:30070, delay:0.0001s, distance:162.81m (Euclidean)
[2025-03-07 13:53:40,314] [INFO] [30130] Missing PRE-PREPARE for REQUEST 1741323218379; ignoring PREPARE
[2025-03-07 13:53:40,314] [INFO] [30130] Received COMMIT: id:1741323218379, from:30070, delay:0.0001s, distance:162.81m (Euclidean)
[2025-03-07 13:53:40,450] [INFO] [30130] Received PREPARE: id:1741323218379, from:30060, delay:0.0001s, distance:178.34m (Euclidean)
[2025-03-07 13:53:40,450] [INFO] [30130] Missing PRE-PREPARE for REQUEST 1741323218379; ignoring PREPARE
[2025-03-07 13:53:40,450] [INFO] [30130] Received COMMIT: id:1741323218379, from:30060, delay:0.0001s, distance:178.34m (Euclidean)
[2025-03-07 13:53:40,497] [INFO] [30130] Received PREPARE: id:1741323218379, from:30073, delay:0.0000s, distance:16.28m (Euclidean)
[2025-03-07 13:53:40,497] [INFO] [30130] Missing PRE-PREPARE for REQUEST 1741323218379; ignoring PREPARE
[2025-03-07 13:53:40,497] [INFO] [30130] Received COMMIT: id:1741323218379, from:30073, delay:0.0000s, distance:16.28m (Euclidean)
[2025-03-07 13:53:40,561] [INFO] [30130] Received PREPARE: id:1741323218379, from:30026, delay:0.0001s, distance:181.65m (Euclidean)
[2025-03-07 13:53:40,561] [INFO] [30130] Missing PRE-PREPARE for REQUEST 1741323218379; ignoring PREPARE
[2025-03-07 13:53:40,561] [INFO] [30130] Received COMMIT: id:1741323218379, from:30026, delay:0.0001s, distance:181.65m (Euclidean)
[2025-03-07 13:53:40,735] [INFO] [30130] Received PREPARE: id:1741323218379, from:30061, delay:0.0000s, distance:146.31m (Euclidean)
[2025-03-07 13:53:40,735] [INFO] [30130] Missing PRE-PREPARE for REQUEST 1741323218379; ignoring PREPARE
[2025-03-07 13:53:40,735] [INFO] [30130] Received COMMIT: id:1741323218379, from:30061, delay:0.0000s, distance:146.31m (Euclidean)
[2025-03-07 13:53:41,150] [INFO] [30130] Received PREPARE: id:1741323218379, from:30033, delay:0.0001s, distance:168.34m (Euclidean)
[2025-03-07 13:53:41,150] [INFO] [30130] Missing PRE-PREPARE for REQUEST 1741323218379; ignoring PREPARE
[2025-03-07 13:53:41,150] [INFO] [30130] Received COMMIT: id:1741323218379, from:30033, delay:0.0001s, distance:168.34m (Euclidean)
[2025-03-07 13:53:41,171] [INFO] [30130] Received COMMIT: id:1741323218379, from:30002, delay:0.0000s, distance:150.79m (Euclidean)
[2025-03-07 13:53:41,465] [INFO] [30130] Received PREPARE: id:1741323218379, from:30030, delay:0.0001s, distance:196.62m (Euclidean)
[2025-03-07 13:53:41,465] [INFO] [30130] Missing PRE-PREPARE for REQUEST 1741323218379; ignoring PREPARE
[2025-03-07 13:53:41,465] [INFO] [30130] Received COMMIT: id:1741323218379, from:30030, delay:0.0001s, distance:196.62m (Euclidean)
[2025-03-07 13:53:41,621] [INFO] [30130] Received PREPARE: id:1741323218379, from:30097, delay:0.0001s, distance:211.24m (Euclidean)
[2025-03-07 13:53:41,621] [INFO] [30130] Missing PRE-PREPARE for REQUEST 1741323218379; ignoring PREPARE
[2025-03-07 13:53:41,621] [INFO] [30130] Received COMMIT: id:1741323218379, from:30097, delay:0.0001s, distance:211.24m (Euclidean)
[2025-03-07 13:53:41,636] [INFO] [30130] Received PREPARE: id:1741323218379, from:30032, delay:0.0000s, distance:126.01m (Euclidean)
[2025-03-07 13:53:41,636] [INFO] [30130] Missing PRE-PREPARE for REQUEST 1741323218379; ignoring PREPARE
[2025-03-07 13:53:41,700] [INFO] [30130] Received PREPARE: id:1741323218379, from:30091, delay:0.0000s, distance:139.52m (Euclidean)
[2025-03-07 13:53:41,700] [INFO] [30130] Missing PRE-PREPARE for REQUEST 1741323218379; ignoring PREPARE
[2025-03-07 13:53:41,741] [INFO] [30130] Received PREPARE: id:1741323218379, from:30117, delay:0.0001s, distance:183.66m (Euclidean)
[2025-03-07 13:53:41,741] [INFO] [30130] Missing PRE-PREPARE for REQUEST 1741323218379; ignoring PREPARE
[2025-03-07 13:53:41,741] [INFO] [30130] Received COMMIT: id:1741323218379, from:30117, delay:0.0001s, distance:183.66m (Euclidean)
[2025-03-07 13:53:42,379] [INFO] [30130] Received PREPARE: id:1741323218379, from:30096, delay:0.0002s, distance:255.55m (Euclidean)
[2025-03-07 13:53:42,379] [INFO] [30130] Missing PRE-PREPARE for REQUEST 1741323218379; ignoring PREPARE
[2025-03-07 13:53:42,379] [INFO] [30130] Received COMMIT: id:1741323218379, from:30096, delay:0.0002s, distance:255.55m (Euclidean)
[2025-03-07 13:53:42,553] [INFO] [30130] Received PREPARE: id:1741323218379, from:30099, delay:0.0001s, distance:223.95m (Euclidean)
[2025-03-07 13:53:42,553] [INFO] [30130] Missing PRE-PREPARE for REQUEST 1741323218379; ignoring PREPARE
[2025-03-07 13:53:42,553] [INFO] [30130] Received COMMIT: id:1741323218379, from:30099, delay:0.0001s, distance:223.95m (Euclidean)
[2025-03-07 13:53:42,616] [INFO] [30130] Received PREPARE: id:1741323218379, from:30062, delay:0.0001s, distance:229.28m (Euclidean)
[2025-03-07 13:53:42,616] [INFO] [30130] Missing PRE-PREPARE for REQUEST 1741323218379; ignoring PREPARE
[2025-03-07 13:53:42,616] [INFO] [30130] Received COMMIT: id:1741323218379, from:30062, delay:0.0001s, distance:229.28m (Euclidean)
[2025-03-07 13:53:42,616] [INFO] [30130] Received COMMIT: id:1741323218379, from:30089, delay:0.0001s, distance:214.63m (Euclidean)
[2025-03-07 13:53:42,616] [INFO] [30130] Received COMMIT: id:1741323218379, from:30095, delay:0.0000s, distance:121.73m (Euclidean)
[2025-03-07 13:53:42,616] [INFO] [30130] Received PREPARE: id:1741323218379, from:30095, delay:0.0000s, distance:121.73m (Euclidean)
[2025-03-07 13:53:42,616] [INFO] [30130] Missing PRE-PREPARE for REQUEST 1741323218379; ignoring PREPARE
[2025-03-07 13:53:42,616] [INFO] [30130] Received PREPARE: id:1741323218379, from:30089, delay:0.0001s, distance:214.63m (Euclidean)
[2025-03-07 13:53:42,616] [INFO] [30130] Missing PRE-PREPARE for REQUEST 1741323218379; ignoring PREPARE
[2025-03-07 13:53:42,893] [INFO] [30130] Received COMMIT: id:1741323218379, from:30035, delay:0.0000s, distance:200.32m (Euclidean)
[2025-03-07 13:53:43,350] [INFO] [30130] Received COMMIT: id:1741323218379, from:30032, delay:0.0000s, distance:126.01m (Euclidean)
[2025-03-07 13:53:43,596] [INFO] [30130] Received PREPARE: id:1741323218379, from:30028, delay:0.0001s, distance:192.23m (Euclidean)
[2025-03-07 13:53:43,596] [INFO] [30130] Missing PRE-PREPARE for REQUEST 1741323218379; ignoring PREPARE
[2025-03-07 13:53:43,596] [INFO] [30130] Received COMMIT: id:1741323218379, from:30028, delay:0.0001s, distance:192.23m (Euclidean)
[2025-03-07 13:53:43,628] [INFO] [30130] Received PREPARE: id:1741323218379, from:30018, delay:0.0002s, distance:276.26m (Euclidean)
[2025-03-07 13:53:43,628] [INFO] [30130] Missing PRE-PREPARE for REQUEST 1741323218379; ignoring PREPARE
[2025-03-07 13:53:43,628] [INFO] [30130] Received COMMIT: id:1741323218379, from:30018, delay:0.0002s, distance:276.26m (Euclidean)
[2025-03-07 13:53:44,015] [INFO] [30130] Received PREPARE: id:1741323218379, from:30037, delay:0.0002s, distance:267.46m (Euclidean)
[2025-03-07 13:53:44,102] [INFO] [30130] Missing PRE-PREPARE for REQUEST 1741323218379; ignoring PREPARE
[2025-03-07 13:53:44,102] [INFO] [30130] Received COMMIT: id:1741323218379, from:30037, delay:0.0002s, distance:267.46m (Euclidean)
[2025-03-07 13:53:44,102] [INFO] [30130] Received COMMIT: id:1741323218379, from:30053, delay:0.0001s, distance:235.29m (Euclidean)
[2025-03-07 13:53:44,102] [INFO] [30130] Received PREPARE: id:1741323218379, from:30053, delay:0.0001s, distance:235.29m (Euclidean)
[2025-03-07 13:53:44,102] [INFO] [30130] Missing PRE-PREPARE for REQUEST 1741323218379; ignoring PREPARE
[2025-03-07 13:53:44,102] [INFO] [30130] Received PREPARE: id:1741323218379, from:30052, delay:0.0001s, distance:174.92m (Euclidean)
[2025-03-07 13:53:44,102] [INFO] [30130] Missing PRE-PREPARE for REQUEST 1741323218379; ignoring PREPARE
[2025-03-07 13:53:44,102] [INFO] [30130] Received COMMIT: id:1741323218379, from:30052, delay:0.0001s, distance:174.92m (Euclidean)
[2025-03-07 13:53:44,151] [INFO] [30130] Received PREPARE: id:1741323218379, from:30094, delay:0.0002s, distance:277.56m (Euclidean)
[2025-03-07 13:53:44,151] [INFO] [30130] Missing PRE-PREPARE for REQUEST 1741323218379; ignoring PREPARE
[2025-03-07 13:53:44,151] [INFO] [30130] Received COMMIT: id:1741323218379, from:30094, delay:0.0002s, distance:277.56m (Euclidean)
[2025-03-07 13:53:44,181] [INFO] [30130] Received PREPARE: id:1741323218379, from:30036, delay:0.0002s, distance:297.48m (Euclidean)
[2025-03-07 13:53:44,181] [INFO] [30130] Missing PRE-PREPARE for REQUEST 1741323218379; ignoring PREPARE
[2025-03-07 13:53:44,181] [INFO] [30130] Received COMMIT: id:1741323218379, from:30036, delay:0.0002s, distance:297.48m (Euclidean)
[2025-03-07 13:53:44,293] [INFO] [30130] Received PREPARE: id:1741323218379, from:30011, delay:0.0001s, distance:215.87m (Euclidean)
[2025-03-07 13:53:44,293] [INFO] [30130] Missing PRE-PREPARE for REQUEST 1741323218379; ignoring PREPARE
[2025-03-07 13:53:44,293] [INFO] [30130] Received COMMIT: id:1741323218379, from:30011, delay:0.0001s, distance:215.87m (Euclidean)
[2025-03-07 13:53:44,309] [INFO] [30130] Received PREPARE: id:1741323218379, from:30058, delay:0.0001s, distance:246.13m (Euclidean)
[2025-03-07 13:53:44,309] [INFO] [30130] Missing PRE-PREPARE for REQUEST 1741323218379; ignoring PREPARE
[2025-03-07 13:53:44,309] [INFO] [30130] Received COMMIT: id:1741323218379, from:30058, delay:0.0001s, distance:246.13m (Euclidean)
[2025-03-07 13:53:44,339] [INFO] [30130] Received PREPARE: id:1741323218379, from:30055, delay:0.0001s, distance:173.25m (Euclidean)
[2025-03-07 13:53:44,339] [INFO] [30130] Missing PRE-PREPARE for REQUEST 1741323218379; ignoring PREPARE
[2025-03-07 13:53:44,339] [INFO] [30130] Received COMMIT: id:1741323218379, from:30055, delay:0.0001s, distance:173.25m (Euclidean)
[2025-03-07 13:53:44,349] [INFO] [30130] Received PREPARE: id:1741323218379, from:30046, delay:0.0000s, distance:131.50m (Euclidean)
[2025-03-07 13:53:44,349] [INFO] [30130] Missing PRE-PREPARE for REQUEST 1741323218379; ignoring PREPARE
[2025-03-07 13:53:44,371] [INFO] [30130] Received COMMIT: id:1741323218379, from:30046, delay:0.0000s, distance:131.50m (Euclidean)
[2025-03-07 13:53:44,371] [INFO] [30130] Received PREPARE: id:1741323218379, from:30003, delay:0.0000s, distance:115.58m (Euclidean)
[2025-03-07 13:53:44,371] [INFO] [30130] Missing PRE-PREPARE for REQUEST 1741323218379; ignoring PREPARE
[2025-03-07 13:53:44,371] [INFO] [30130] Received COMMIT: id:1741323218379, from:30003, delay:0.0000s, distance:115.58m (Euclidean)
[2025-03-07 13:53:44,411] [INFO] [30130] Received PREPARE: id:1741323218379, from:30034, delay:0.0002s, distance:283.25m (Euclidean)
[2025-03-07 13:53:44,411] [INFO] [30130] Missing PRE-PREPARE for REQUEST 1741323218379; ignoring PREPARE
[2025-03-07 13:53:44,411] [INFO] [30130] Received COMMIT: id:1741323218379, from:30034, delay:0.0002s, distance:283.25m (Euclidean)
[2025-03-07 13:53:44,577] [INFO] [30130] Received PREPARE: id:1741323218379, from:30088, delay:0.0001s, distance:185.71m (Euclidean)
[2025-03-07 13:53:44,577] [INFO] [30130] Missing PRE-PREPARE for REQUEST 1741323218379; ignoring PREPARE
[2025-03-07 13:53:44,577] [INFO] [30130] Received COMMIT: id:1741323218379, from:30088, delay:0.0001s, distance:185.71m (Euclidean)
[2025-03-07 13:53:44,993] [INFO] [30130] Received PREPARE: id:1741323218379, from:30047, delay:0.0002s, distance:250.93m (Euclidean)
[2025-03-07 13:53:44,993] [INFO] [30130] Missing PRE-PREPARE for REQUEST 1741323218379; ignoring PREPARE
[2025-03-07 13:53:44,993] [INFO] [30130] Received COMMIT: id:1741323218379, from:30047, delay:0.0002s, distance:250.93m (Euclidean)
[2025-03-07 13:53:45,098] [INFO] [30130] Received PREPARE: id:1741323218379, from:30016, delay:0.0001s, distance:234.98m (Euclidean)
[2025-03-07 13:53:45,098] [INFO] [30130] Missing PRE-PREPARE for REQUEST 1741323218379; ignoring PREPARE
[2025-03-07 13:53:45,098] [INFO] [30130] Received COMMIT: id:1741323218379, from:30016, delay:0.0001s, distance:234.98m (Euclidean)
[2025-03-07 13:53:45,146] [INFO] [30130] Received COMMIT: id:1741323218379, from:30091, delay:0.0000s, distance:139.52m (Euclidean)
[2025-03-07 13:53:45,196] [INFO] [30130] Received PREPARE: id:1741323218379, from:30040, delay:0.0001s, distance:220.81m (Euclidean)
[2025-03-07 13:53:45,196] [INFO] [30130] Missing PRE-PREPARE for REQUEST 1741323218379; ignoring PREPARE
[2025-03-07 13:53:45,209] [INFO] [30130] Received COMMIT: id:1741323218379, from:30040, delay:0.0001s, distance:220.81m (Euclidean)
[2025-03-07 13:53:45,241] [INFO] [30130] Received PREPARE: id:1741323218379, from:30024, delay:0.0002s, distance:256.91m (Euclidean)
[2025-03-07 13:53:45,241] [INFO] [30130] Missing PRE-PREPARE for REQUEST 1741323218379; ignoring PREPARE
[2025-03-07 13:53:45,241] [INFO] [30130] Received COMMIT: id:1741323218379, from:30024, delay:0.0002s, distance:256.91m (Euclidean)
[2025-03-07 13:53:45,288] [INFO] [30130] Received PREPARE: id:1741323218379, from:30004, delay:0.0002s, distance:266.79m (Euclidean)
[2025-03-07 13:53:45,288] [INFO] [30130] Missing PRE-PREPARE for REQUEST 1741323218379; ignoring PREPARE
[2025-03-07 13:53:45,288] [INFO] [30130] Received COMMIT: id:1741323218379, from:30004, delay:0.0002s, distance:266.79m (Euclidean)
[2025-03-07 13:53:45,309] [INFO] [30130] Received PREPARE: id:1741323218379, from:30013, delay:0.0002s, distance:278.78m (Euclidean)
[2025-03-07 13:53:45,309] [INFO] [30130] Missing PRE-PREPARE for REQUEST 1741323218379; ignoring PREPARE
[2025-03-07 13:53:45,309] [INFO] [30130] Received COMMIT: id:1741323218379, from:30013, delay:0.0002s, distance:278.78m (Euclidean)
[2025-03-07 13:53:45,826] [INFO] [30130] Received PREPARE: id:1741323218379, from:30017, delay:0.0001s, distance:202.03m (Euclidean)
[2025-03-07 13:53:45,826] [INFO] [30130] Missing PRE-PREPARE for REQUEST 1741323218379; ignoring PREPARE
[2025-03-07 13:53:45,826] [INFO] [30130] Received COMMIT: id:1741323218379, from:30017, delay:0.0001s, distance:202.03m (Euclidean)
[2025-03-07 13:53:45,892] [INFO] [30130] Received PREPARE: id:1741323218379, from:30014, delay:0.0002s, distance:294.81m (Euclidean)
[2025-03-07 13:53:45,892] [INFO] [30130] Missing PRE-PREPARE for REQUEST 1741323218379; ignoring PREPARE
[2025-03-07 13:53:45,892] [INFO] [30130] Received COMMIT: id:1741323218379, from:30014, delay:0.0002s, distance:294.81m (Euclidean)
[2025-03-07 13:53:45,905] [INFO] [30130] Received PREPARE: id:1741323218379, from:30001, delay:0.0001s, distance:227.08m (Euclidean)
[2025-03-07 13:53:45,905] [INFO] [30130] Missing PRE-PREPARE for REQUEST 1741323218379; ignoring PREPARE
[2025-03-07 13:53:45,905] [INFO] [30130] Received COMMIT: id:1741323218379, from:30001, delay:0.0001s, distance:227.08m (Euclidean)
[2025-03-07 13:53:45,921] [INFO] [30130] Received PREPARE: id:1741323218379, from:30039, delay:0.0001s, distance:226.17m (Euclidean)
[2025-03-07 13:53:45,921] [INFO] [30130] Missing PRE-PREPARE for REQUEST 1741323218379; ignoring PREPARE
[2025-03-07 13:53:45,921] [INFO] [30130] Received COMMIT: id:1741323218379, from:30039, delay:0.0001s, distance:226.17m (Euclidean)
[2025-03-07 13:53:46,143] [INFO] [30130] Received PREPARE: id:1741323218379, from:30043, delay:0.0002s, distance:269.39m (Euclidean)
[2025-03-07 13:53:46,143] [INFO] [30130] Missing PRE-PREPARE for REQUEST 1741323218379; ignoring PREPARE
[2025-03-07 13:53:46,143] [INFO] [30130] Received COMMIT: id:1741323218379, from:30043, delay:0.0002s, distance:269.39m (Euclidean)
[2025-03-07 13:53:46,356] [INFO] [30130] Received PREPARE: id:1741323218379, from:30048, delay:0.0000s, distance:75.72m (Euclidean)
[2025-03-07 13:53:46,356] [INFO] [30130] Missing PRE-PREPARE for REQUEST 1741323218379; ignoring PREPARE
[2025-03-07 13:53:46,363] [INFO] [30130] Received COMMIT: id:1741323218379, from:30048, delay:0.0000s, distance:75.72m (Euclidean)
[2025-03-07 13:53:46,539] [INFO] [30130] Received PREPARE: id:1741323218379, from:30010, delay:0.0000s, distance:144.55m (Euclidean)
[2025-03-07 13:53:46,539] [INFO] [30130] Missing PRE-PREPARE for REQUEST 1741323218379; ignoring PREPARE
[2025-03-07 13:53:46,539] [INFO] [30130] Received COMMIT: id:1741323218379, from:30010, delay:0.0000s, distance:144.55m (Euclidean)
[2025-03-07 13:53:46,574] [INFO] [30130] Received PREPARE: id:1741323218379, from:30049, delay:0.0000s, distance:145.08m (Euclidean)
[2025-03-07 13:53:46,574] [INFO] [30130] Missing PRE-PREPARE for REQUEST 1741323218379; ignoring PREPARE
[2025-03-07 13:53:46,574] [INFO] [30130] Received COMMIT: id:1741323218379, from:30049, delay:0.0000s, distance:145.08m (Euclidean)
[2025-03-07 13:53:46,605] [INFO] [30130] Received PREPARE: id:1741323218379, from:30041, delay:0.0001s, distance:218.45m (Euclidean)
[2025-03-07 13:53:46,605] [INFO] [30130] Missing PRE-PREPARE for REQUEST 1741323218379; ignoring PREPARE
[2025-03-07 13:53:46,605] [INFO] [30130] Received COMMIT: id:1741323218379, from:30041, delay:0.0001s, distance:218.45m (Euclidean)
[2025-03-07 13:53:46,668] [INFO] [30130] Received PREPARE: id:1741323218379, from:30102, delay:0.0002s, distance:270.42m (Euclidean)
[2025-03-07 13:53:46,668] [INFO] [30130] Missing PRE-PREPARE for REQUEST 1741323218379; ignoring PREPARE
[2025-03-07 13:53:46,668] [INFO] [30130] Received COMMIT: id:1741323218379, from:30102, delay:0.0002s, distance:270.42m (Euclidean)
[2025-03-07 13:53:46,697] [INFO] [30130] Received PREPARE: id:1741323218379, from:30104, delay:0.0001s, distance:156.67m (Euclidean)
[2025-03-07 13:53:46,697] [INFO] [30130] Missing PRE-PREPARE for REQUEST 1741323218379; ignoring PREPARE
[2025-03-07 13:53:46,697] [INFO] [30130] Received COMMIT: id:1741323218379, from:30104, delay:0.0001s, distance:156.67m (Euclidean)
[2025-03-07 13:53:46,807] [INFO] [30130] Received PREPARE: id:1741323218379, from:30110, delay:0.0000s, distance:48.67m (Euclidean)
[2025-03-07 13:53:46,807] [INFO] [30130] Missing PRE-PREPARE for REQUEST 1741323218379; ignoring PREPARE
[2025-03-07 13:53:46,950] [INFO] [30130] Received PREPARE: id:1741323218379, from:30134, delay:0.0000s, distance:38.44m (Euclidean)
[2025-03-07 13:53:46,950] [INFO] [30130] Missing PRE-PREPARE for REQUEST 1741323218379; ignoring PREPARE
[2025-03-07 13:53:46,983] [INFO] [30130] Received COMMIT: id:1741323218379, from:30110, delay:0.0000s, distance:48.67m (Euclidean)
[2025-03-07 13:53:47,013] [INFO] [30130] Received PREPARE: id:1741323218379, from:30131, delay:0.0000s, distance:200.78m (Euclidean)
[2025-03-07 13:53:47,013] [INFO] [30130] Missing PRE-PREPARE for REQUEST 1741323218379; ignoring PREPARE
[2025-03-07 13:53:47,180] [INFO] [30130] Received PREPARE: id:1741323218379, from:30007, delay:0.0002s, distance:293.31m (Euclidean)
[2025-03-07 13:53:47,180] [INFO] [30130] Missing PRE-PREPARE for REQUEST 1741323218379; ignoring PREPARE
[2025-03-07 13:53:47,180] [INFO] [30130] Received COMMIT: id:1741323218379, from:30007, delay:0.0002s, distance:293.31m (Euclidean)
[2025-03-07 13:53:47,234] [INFO] [30130] Received COMMIT: id:1741323218379, from:30134, delay:0.0000s, distance:38.44m (Euclidean)
[2025-03-07 13:53:47,509] [INFO] [30130] Received PREPARE: id:1741323218379, from:30158, delay:0.0000s, distance:67.37m (Euclidean)
[2025-03-07 13:53:47,509] [INFO] [30130] Missing PRE-PREPARE for REQUEST 1741323218379; ignoring PREPARE
[2025-03-07 13:53:47,509] [INFO] [30130] Received COMMIT: id:1741323218379, from:30158, delay:0.0000s, distance:67.37m (Euclidean)
[2025-03-07 13:53:47,756] [INFO] [30130] Received PREPARE: id:1741323218379, from:30105, delay:0.0001s, distance:175.29m (Euclidean)
[2025-03-07 13:53:47,756] [INFO] [30130] Missing PRE-PREPARE for REQUEST 1741323218379; ignoring PREPARE
[2025-03-07 13:53:47,772] [INFO] [30130] Received COMMIT: id:1741323218379, from:30105, delay:0.0001s, distance:175.29m (Euclidean)
[2025-03-07 13:53:47,929] [INFO] [30130] Received PREPARE: id:1741323218379, from:30153, delay:0.0000s, distance:98.29m (Euclidean)
[2025-03-07 13:53:47,929] [INFO] [30130] Missing PRE-PREPARE for REQUEST 1741323218379; ignoring PREPARE
[2025-03-07 13:53:47,929] [INFO] [30130] Received COMMIT: id:1741323218379, from:30153, delay:0.0000s, distance:98.29m (Euclidean)
[2025-03-07 13:53:47,994] [INFO] [30130] Received PREPARE: id:1741323218379, from:30136, delay:0.0002s, distance:257.98m (Euclidean)
[2025-03-07 13:53:47,994] [INFO] [30130] Missing PRE-PREPARE for REQUEST 1741323218379; ignoring PREPARE
[2025-03-07 13:53:47,994] [INFO] [30130] Received COMMIT: id:1741323218379, from:30136, delay:0.0002s, distance:257.98m (Euclidean)
[2025-03-07 13:53:48,008] [INFO] [30130] Received PREPARE: id:1741323218379, from:30122, delay:0.0002s, distance:284.67m (Euclidean)
[2025-03-07 13:53:48,008] [INFO] [30130] Missing PRE-PREPARE for REQUEST 1741323218379; ignoring PREPARE
[2025-03-07 13:53:48,008] [INFO] [30130] Received COMMIT: id:1741323218379, from:30122, delay:0.0002s, distance:284.67m (Euclidean)
[2025-03-07 13:53:48,231] [INFO] [30130] Received PREPARE: id:1741323218379, from:30157, delay:0.0000s, distance:113.66m (Euclidean)
[2025-03-07 13:53:48,231] [INFO] [30130] Missing PRE-PREPARE for REQUEST 1741323218379; ignoring PREPARE
[2025-03-07 13:53:48,231] [INFO] [30130] Received COMMIT: id:1741323218379, from:30157, delay:0.0000s, distance:113.66m (Euclidean)
[2025-03-07 13:53:48,293] [INFO] [30130] Received PREPARE: id:1741323218379, from:30139, delay:0.0001s, distance:211.20m (Euclidean)
[2025-03-07 13:53:48,293] [INFO] [30130] Missing PRE-PREPARE for REQUEST 1741323218379; ignoring PREPARE
[2025-03-07 13:53:48,293] [INFO] [30130] Received COMMIT: id:1741323218379, from:30139, delay:0.0001s, distance:211.20m (Euclidean)
[2025-03-07 13:53:48,311] [INFO] [30130] Received PREPARE: id:1741323218379, from:30147, delay:0.0000s, distance:80.61m (Euclidean)
[2025-03-07 13:53:48,311] [INFO] [30130] Missing PRE-PREPARE for REQUEST 1741323218379; ignoring PREPARE
[2025-03-07 13:53:48,311] [INFO] [30130] Received COMMIT: id:1741323218379, from:30147, delay:0.0000s, distance:80.61m (Euclidean)
[2025-03-07 13:53:48,349] [INFO] [30130] Received COMMIT: id:1741323218379, from:30131, delay:0.0000s, distance:200.78m (Euclidean)
[2025-03-07 13:53:48,381] [INFO] [30130] Received PREPARE: id:1741323218379, from:30135, delay:0.0002s, distance:274.44m (Euclidean)
[2025-03-07 13:53:48,381] [INFO] [30130] Missing PRE-PREPARE for REQUEST 1741323218379; ignoring PREPARE
[2025-03-07 13:53:48,388] [INFO] [30130] Received COMMIT: id:1741323218379, from:30135, delay:0.0002s, distance:274.44m (Euclidean)
[2025-03-07 13:53:48,471] [INFO] [30130] Received PREPARE: id:1741323218379, from:30128, delay:0.0000s, distance:131.84m (Euclidean)
[2025-03-07 13:53:48,471] [INFO] [30130] Missing PRE-PREPARE for REQUEST 1741323218379; ignoring PREPARE
[2025-03-07 13:53:48,490] [INFO] [30130] Received PREPARE: id:1741323218379, from:30154, delay:0.0000s, distance:149.28m (Euclidean)
[2025-03-07 13:53:48,490] [INFO] [30130] Missing PRE-PREPARE for REQUEST 1741323218379; ignoring PREPARE
[2025-03-07 13:53:48,490] [INFO] [30130] Received COMMIT: id:1741323218379, from:30154, delay:0.0000s, distance:149.28m (Euclidean)
[2025-03-07 13:53:48,641] [INFO] [30130] Received PREPARE: id:1741323218379, from:30109, delay:0.0001s, distance:204.27m (Euclidean)
[2025-03-07 13:53:48,641] [INFO] [30130] Missing PRE-PREPARE for REQUEST 1741323218379; ignoring PREPARE
[2025-03-07 13:53:48,641] [INFO] [30130] Received COMMIT: id:1741323218379, from:30109, delay:0.0001s, distance:204.27m (Euclidean)
[2025-03-07 13:53:48,779] [INFO] [30130] Received COMMIT: id:1741323218379, from:30128, delay:0.0000s, distance:131.84m (Euclidean)
[2025-03-07 13:53:48,912] [INFO] [30130] Received PREPARE: id:1741323218379, from:30144, delay:0.0000s, distance:57.58m (Euclidean)
[2025-03-07 13:53:48,912] [INFO] [30130] Missing PRE-PREPARE for REQUEST 1741323218379; ignoring PREPARE
[2025-03-07 13:53:49,020] [INFO] [30130] Received PREPARE: id:1741323218379, from:30133, delay:0.0000s, distance:88.11m (Euclidean)
[2025-03-07 13:53:49,020] [INFO] [30130] Missing PRE-PREPARE for REQUEST 1741323218379; ignoring PREPARE
[2025-03-07 13:53:49,094] [INFO] [30130] Received PREPARE: id:1741323218379, from:30107, delay:0.0001s, distance:245.50m (Euclidean)
[2025-03-07 13:53:49,094] [INFO] [30130] Missing PRE-PREPARE for REQUEST 1741323218379; ignoring PREPARE
[2025-03-07 13:53:49,107] [INFO] [30130] Received COMMIT: id:1741323218379, from:30107, delay:0.0001s, distance:245.50m (Euclidean)
[2025-03-07 13:53:49,120] [INFO] [30130] Received COMMIT: id:1741323218379, from:30133, delay:0.0000s, distance:88.11m (Euclidean)
[2025-03-07 13:53:49,120] [INFO] [30130] Received PREPARE: id:1741323218379, from:30112, delay:0.0000s, distance:31.14m (Euclidean)
[2025-03-07 13:53:49,120] [INFO] [30130] Missing PRE-PREPARE for REQUEST 1741323218379; ignoring PREPARE
[2025-03-07 13:53:49,246] [INFO] [30130] Received COMMIT: id:1741323218379, from:30144, delay:0.0000s, distance:57.58m (Euclidean)
[2025-03-07 13:53:49,373] [INFO] [30130] Received PREPARE: id:1741323218379, from:30151, delay:0.0002s, distance:259.17m (Euclidean)
[2025-03-07 13:53:49,373] [INFO] [30130] Missing PRE-PREPARE for REQUEST 1741323218379; ignoring PREPARE
[2025-03-07 13:53:49,391] [INFO] [30130] Received COMMIT: id:1741323218379, from:30151, delay:0.0002s, distance:259.17m (Euclidean)
[2025-03-07 13:53:49,489] [INFO] [30130] Received COMMIT: id:1741323218379, from:30112, delay:0.0000s, distance:31.14m (Euclidean)
[2025-03-07 13:53:49,621] [INFO] [30130] Received PRE-PREPARE: id:1741323218379, from:Leader(30000), delay:0.0001s, distance:204.09m (Euclidean)
[2025-03-07 13:53:49,621] [INFO] [30130] Broadcasting PREPARE for REQUEST 1741323218379
[2025-03-07 13:53:49,795] [INFO] [30130] Received PREPARE: id:1741323218379, from:30148, delay:0.0002s, distance:269.56m (Euclidean)
[2025-03-07 13:53:49,795] [INFO] [30130] Broadcasting COMMIT for REQUEST 1741323218379
[2025-03-07 13:53:49,874] [INFO] [30130] Received COMMIT: id:1741323218379, from:30148, delay:0.0002s, distance:269.56m (Euclidean)
[2025-03-07 13:53:50,013] [INFO] [30130] Received PREPARE: id:1741323218379, from:30114, delay:0.0002s, distance:276.79m (Euclidean)
[2025-03-07 13:53:50,149] [INFO] [30130] Received COMMIT: id:1741323218379, from:30114, delay:0.0002s, distance:276.79m (Euclidean)
[2025-03-07 13:53:50,353] [INFO] [30130] Received PREPARE: id:1741323218379, from:30015, delay:0.0000s, distance:102.04m (Euclidean)
[2025-03-07 13:53:50,446] [INFO] [30130] Received COMMIT: id:1741323218379, from:30015, delay:0.0000s, distance:102.04m (Euclidean)
[2025-03-07 13:53:50,861] [INFO] [30130] Received COMMIT: id:1741323218379, from:30000, delay:0.0001s, distance:204.09m (Euclidean)
[2025-03-07 13:53:51,012] [INFO] [30130] Received PREPARE: id:1741323218379, from:30126, delay:0.0001s, distance:234.88m (Euclidean)
[2025-03-07 13:53:51,020] [INFO] [30130] Received COMMIT: id:1741323218379, from:30126, delay:0.0001s, distance:234.88m (Euclidean)
[2025-03-07 13:53:51,823] [INFO] [30130] Received PREPARE: id:1741323218379, from:30129, delay:0.0000s, distance:182.24m (Euclidean)
[2025-03-07 13:53:51,823] [INFO] [30130] Received COMMIT: id:1741323218379, from:30129, delay:0.0000s, distance:182.24m (Euclidean)
[2025-03-07 13:53:51,852] [INFO] [30130] Received PREPARE: id:1741323218379, from:30121, delay:0.0001s, distance:175.22m (Euclidean)
[2025-03-07 13:53:51,852] [INFO] [30130] Received COMMIT: id:1741323218379, from:30121, delay:0.0001s, distance:175.22m (Euclidean)
[2025-03-07 13:53:52,544] [INFO] [30130] Received PREPARE: id:1741323218379, from:30118, delay:0.0001s, distance:217.40m (Euclidean)
[2025-03-07 13:53:52,547] [INFO] [30130] Received COMMIT: id:1741323218379, from:30118, delay:0.0001s, distance:217.40m (Euclidean)
[2025-03-07 13:53:53,005] [INFO] [30130] Received PREPARE: id:1741323218379, from:30113, delay:0.0000s, distance:106.23m (Euclidean)
[2025-03-07 13:53:53,005] [INFO] [30130] Received COMMIT: id:1741323218379, from:30113, delay:0.0000s, distance:106.23m (Euclidean)
[2025-03-07 13:53:53,384] [INFO] [30130] Received PREPARE: id:1741323218379, from:30155, delay:0.0002s, distance:260.49m (Euclidean)
[2025-03-07 13:53:53,384] [INFO] [30130] Received COMMIT: id:1741323218379, from:30155, delay:0.0002s, distance:260.49m (Euclidean)
[2025-03-07 13:53:53,416] [INFO] [30130] Received PREPARE: id:1741323218379, from:30142, delay:0.0000s, distance:130.18m (Euclidean)
[2025-03-07 13:53:53,416] [INFO] [30130] Received COMMIT: id:1741323218379, from:30142, delay:0.0000s, distance:130.18m (Euclidean)
[2025-03-07 13:53:53,480] [INFO] [30130] Received PREPARE: id:1741323218379, from:30149, delay:0.0000s, distance:106.52m (Euclidean)
[2025-03-07 13:53:53,480] [INFO] [30130] Received COMMIT: id:1741323218379, from:30149, delay:0.0000s, distance:106.52m (Euclidean)
[2025-03-07 13:53:53,780] [ERROR] [30130] Error sending to http://localhost:30066/prepare: Cannot connect to host localhost:30066 ssl:default [Connect call failed ('127.0.0.1', 30066)]
Traceback (most recent call last):
  File "D:\anaconda\envs\PBFT\lib\site-packages\aiohttp\connector.py", line 980, in _wrap_create_connection
    return await self._loop.create_connection(*args, **kwargs)  # type: ignore[return-value]  # noqa
  File "D:\anaconda\envs\PBFT\lib\asyncio\base_events.py", line 948, in create_connection
    raise exceptions[0]
  File "D:\anaconda\envs\PBFT\lib\asyncio\base_events.py", line 935, in create_connection
    await self.sock_connect(sock, address)
  File "D:\anaconda\envs\PBFT\lib\asyncio\selector_events.py", line 475, in sock_connect
    return await fut
  File "D:\anaconda\envs\PBFT\lib\asyncio\selector_events.py", line 505, in _sock_connect_cb
    raise OSError(err, f'Connect call failed {address}')
ConnectionRefusedError: [Errno 10061] Connect call failed ('127.0.0.1', 30066)

The above exception was the direct cause of the following exception:

Traceback (most recent call last):
  File "pbft.py", line 236, in send_message
    await send_with_delay(self.session, self.node_info, target, url, data, self.bandwidth_data)
  File "pbft.py", line 63, in send_with_delay
    async with session.post(url, json=data) as resp:
  File "D:\anaconda\envs\PBFT\lib\site-packages\aiohttp\client.py", line 1141, in __aenter__
    self._resp = await self._coro
  File "D:\anaconda\envs\PBFT\lib\site-packages\aiohttp\client.py", line 537, in _request
    req, traces=traces, timeout=real_timeout
  File "D:\anaconda\envs\PBFT\lib\site-packages\aiohttp\connector.py", line 540, in connect
    proto = await self._create_connection(req, traces, timeout)
  File "D:\anaconda\envs\PBFT\lib\site-packages\aiohttp\connector.py", line 901, in _create_connection
    _, proto = await self._create_direct_connection(req, traces, timeout)
  File "D:\anaconda\envs\PBFT\lib\site-packages\aiohttp\connector.py", line 1206, in _create_direct_connection
    raise last_exc
  File "D:\anaconda\envs\PBFT\lib\site-packages\aiohttp\connector.py", line 1187, in _create_direct_connection
    client_error=client_error,
  File "D:\anaconda\envs\PBFT\lib\site-packages\aiohttp\connector.py", line 988, in _wrap_create_connection
    raise client_error(req.connection_key, exc) from exc
aiohttp.client_exceptions.ClientConnectorError: Cannot connect to host localhost:30066 ssl:default [Connect call failed ('127.0.0.1', 30066)]
[2025-03-07 13:53:53,828] [ERROR] [30130] Error sending to http://localhost:30071/prepare: Cannot connect to host localhost:30071 ssl:default [Connect call failed ('127.0.0.1', 30071)]
Traceback (most recent call last):
  File "D:\anaconda\envs\PBFT\lib\site-packages\aiohttp\connector.py", line 980, in _wrap_create_connection
    return await self._loop.create_connection(*args, **kwargs)  # type: ignore[return-value]  # noqa
  File "D:\anaconda\envs\PBFT\lib\asyncio\base_events.py", line 948, in create_connection
    raise exceptions[0]
  File "D:\anaconda\envs\PBFT\lib\asyncio\base_events.py", line 935, in create_connection
    await self.sock_connect(sock, address)
  File "D:\anaconda\envs\PBFT\lib\asyncio\selector_events.py", line 475, in sock_connect
    return await fut
  File "D:\anaconda\envs\PBFT\lib\asyncio\selector_events.py", line 505, in _sock_connect_cb
    raise OSError(err, f'Connect call failed {address}')
ConnectionRefusedError: [Errno 10061] Connect call failed ('127.0.0.1', 30071)

The above exception was the direct cause of the following exception:

Traceback (most recent call last):
  File "pbft.py", line 236, in send_message
    await send_with_delay(self.session, self.node_info, target, url, data, self.bandwidth_data)
  File "pbft.py", line 63, in send_with_delay
    async with session.post(url, json=data) as resp:
  File "D:\anaconda\envs\PBFT\lib\site-packages\aiohttp\client.py", line 1141, in __aenter__
    self._resp = await self._coro
  File "D:\anaconda\envs\PBFT\lib\site-packages\aiohttp\client.py", line 537, in _request
    req, traces=traces, timeout=real_timeout
  File "D:\anaconda\envs\PBFT\lib\site-packages\aiohttp\connector.py", line 540, in connect
    proto = await self._create_connection(req, traces, timeout)
  File "D:\anaconda\envs\PBFT\lib\site-packages\aiohttp\connector.py", line 901, in _create_connection
    _, proto = await self._create_direct_connection(req, traces, timeout)
  File "D:\anaconda\envs\PBFT\lib\site-packages\aiohttp\connector.py", line 1206, in _create_direct_connection
    raise last_exc
  File "D:\anaconda\envs\PBFT\lib\site-packages\aiohttp\connector.py", line 1187, in _create_direct_connection
    client_error=client_error,
  File "D:\anaconda\envs\PBFT\lib\site-packages\aiohttp\connector.py", line 988, in _wrap_create_connection
    raise client_error(req.connection_key, exc) from exc
aiohttp.client_exceptions.ClientConnectorError: Cannot connect to host localhost:30071 ssl:default [Connect call failed ('127.0.0.1', 30071)]
[2025-03-07 13:53:53,828] [ERROR] [30130] Error sending to http://localhost:30076/prepare: Cannot connect to host localhost:30076 ssl:default [Connect call failed ('127.0.0.1', 30076)]
Traceback (most recent call last):
  File "D:\anaconda\envs\PBFT\lib\site-packages\aiohttp\connector.py", line 980, in _wrap_create_connection
    return await self._loop.create_connection(*args, **kwargs)  # type: ignore[return-value]  # noqa
  File "D:\anaconda\envs\PBFT\lib\asyncio\base_events.py", line 948, in create_connection
    raise exceptions[0]
  File "D:\anaconda\envs\PBFT\lib\asyncio\base_events.py", line 935, in create_connection
    await self.sock_connect(sock, address)
  File "D:\anaconda\envs\PBFT\lib\asyncio\selector_events.py", line 475, in sock_connect
    return await fut
  File "D:\anaconda\envs\PBFT\lib\asyncio\selector_events.py", line 505, in _sock_connect_cb
    raise OSError(err, f'Connect call failed {address}')
ConnectionRefusedError: [Errno 10061] Connect call failed ('127.0.0.1', 30076)

The above exception was the direct cause of the following exception:

Traceback (most recent call last):
  File "pbft.py", line 236, in send_message
    await send_with_delay(self.session, self.node_info, target, url, data, self.bandwidth_data)
  File "pbft.py", line 63, in send_with_delay
    async with session.post(url, json=data) as resp:
  File "D:\anaconda\envs\PBFT\lib\site-packages\aiohttp\client.py", line 1141, in __aenter__
    self._resp = await self._coro
  File "D:\anaconda\envs\PBFT\lib\site-packages\aiohttp\client.py", line 537, in _request
    req, traces=traces, timeout=real_timeout
  File "D:\anaconda\envs\PBFT\lib\site-packages\aiohttp\connector.py", line 540, in connect
    proto = await self._create_connection(req, traces, timeout)
  File "D:\anaconda\envs\PBFT\lib\site-packages\aiohttp\connector.py", line 901, in _create_connection
    _, proto = await self._create_direct_connection(req, traces, timeout)
  File "D:\anaconda\envs\PBFT\lib\site-packages\aiohttp\connector.py", line 1206, in _create_direct_connection
    raise last_exc
  File "D:\anaconda\envs\PBFT\lib\site-packages\aiohttp\connector.py", line 1187, in _create_direct_connection
    client_error=client_error,
  File "D:\anaconda\envs\PBFT\lib\site-packages\aiohttp\connector.py", line 988, in _wrap_create_connection
    raise client_error(req.connection_key, exc) from exc
aiohttp.client_exceptions.ClientConnectorError: Cannot connect to host localhost:30076 ssl:default [Connect call failed ('127.0.0.1', 30076)]
[2025-03-07 13:53:53,844] [ERROR] [30130] Error sending to http://localhost:30075/prepare: Cannot connect to host localhost:30075 ssl:default [Connect call failed ('127.0.0.1', 30075)]
Traceback (most recent call last):
  File "D:\anaconda\envs\PBFT\lib\site-packages\aiohttp\connector.py", line 980, in _wrap_create_connection
    return await self._loop.create_connection(*args, **kwargs)  # type: ignore[return-value]  # noqa
  File "D:\anaconda\envs\PBFT\lib\asyncio\base_events.py", line 948, in create_connection
    raise exceptions[0]
  File "D:\anaconda\envs\PBFT\lib\asyncio\base_events.py", line 935, in create_connection
    await self.sock_connect(sock, address)
  File "D:\anaconda\envs\PBFT\lib\asyncio\selector_events.py", line 475, in sock_connect
    return await fut
  File "D:\anaconda\envs\PBFT\lib\asyncio\selector_events.py", line 505, in _sock_connect_cb
    raise OSError(err, f'Connect call failed {address}')
ConnectionRefusedError: [Errno 10061] Connect call failed ('127.0.0.1', 30075)

The above exception was the direct cause of the following exception:

Traceback (most recent call last):
  File "pbft.py", line 236, in send_message
    await send_with_delay(self.session, self.node_info, target, url, data, self.bandwidth_data)
  File "pbft.py", line 63, in send_with_delay
    async with session.post(url, json=data) as resp:
  File "D:\anaconda\envs\PBFT\lib\site-packages\aiohttp\client.py", line 1141, in __aenter__
    self._resp = await self._coro
  File "D:\anaconda\envs\PBFT\lib\site-packages\aiohttp\client.py", line 537, in _request
    req, traces=traces, timeout=real_timeout
  File "D:\anaconda\envs\PBFT\lib\site-packages\aiohttp\connector.py", line 540, in connect
    proto = await self._create_connection(req, traces, timeout)
  File "D:\anaconda\envs\PBFT\lib\site-packages\aiohttp\connector.py", line 901, in _create_connection
    _, proto = await self._create_direct_connection(req, traces, timeout)
  File "D:\anaconda\envs\PBFT\lib\site-packages\aiohttp\connector.py", line 1206, in _create_direct_connection
    raise last_exc
  File "D:\anaconda\envs\PBFT\lib\site-packages\aiohttp\connector.py", line 1187, in _create_direct_connection
    client_error=client_error,
  File "D:\anaconda\envs\PBFT\lib\site-packages\aiohttp\connector.py", line 988, in _wrap_create_connection
    raise client_error(req.connection_key, exc) from exc
aiohttp.client_exceptions.ClientConnectorError: Cannot connect to host localhost:30075 ssl:default [Connect call failed ('127.0.0.1', 30075)]
[2025-03-07 13:53:53,876] [ERROR] [30130] Error sending to http://localhost:30023/prepare: Cannot connect to host localhost:30023 ssl:default [Connect call failed ('127.0.0.1', 30023)]
Traceback (most recent call last):
  File "D:\anaconda\envs\PBFT\lib\site-packages\aiohttp\connector.py", line 980, in _wrap_create_connection
    return await self._loop.create_connection(*args, **kwargs)  # type: ignore[return-value]  # noqa
  File "D:\anaconda\envs\PBFT\lib\asyncio\base_events.py", line 948, in create_connection
    raise exceptions[0]
  File "D:\anaconda\envs\PBFT\lib\asyncio\base_events.py", line 935, in create_connection
    await self.sock_connect(sock, address)
  File "D:\anaconda\envs\PBFT\lib\asyncio\selector_events.py", line 475, in sock_connect
    return await fut
  File "D:\anaconda\envs\PBFT\lib\asyncio\selector_events.py", line 505, in _sock_connect_cb
    raise OSError(err, f'Connect call failed {address}')
ConnectionRefusedError: [Errno 10061] Connect call failed ('127.0.0.1', 30023)

The above exception was the direct cause of the following exception:

Traceback (most recent call last):
  File "pbft.py", line 236, in send_message
    await send_with_delay(self.session, self.node_info, target, url, data, self.bandwidth_data)
  File "pbft.py", line 63, in send_with_delay
    async with session.post(url, json=data) as resp:
  File "D:\anaconda\envs\PBFT\lib\site-packages\aiohttp\client.py", line 1141, in __aenter__
    self._resp = await self._coro
  File "D:\anaconda\envs\PBFT\lib\site-packages\aiohttp\client.py", line 537, in _request
    req, traces=traces, timeout=real_timeout
  File "D:\anaconda\envs\PBFT\lib\site-packages\aiohttp\connector.py", line 540, in connect
    proto = await self._create_connection(req, traces, timeout)
  File "D:\anaconda\envs\PBFT\lib\site-packages\aiohttp\connector.py", line 901, in _create_connection
    _, proto = await self._create_direct_connection(req, traces, timeout)
  File "D:\anaconda\envs\PBFT\lib\site-packages\aiohttp\connector.py", line 1206, in _create_direct_connection
    raise last_exc
  File "D:\anaconda\envs\PBFT\lib\site-packages\aiohttp\connector.py", line 1187, in _create_direct_connection
    client_error=client_error,
  File "D:\anaconda\envs\PBFT\lib\site-packages\aiohttp\connector.py", line 988, in _wrap_create_connection
    raise client_error(req.connection_key, exc) from exc
aiohttp.client_exceptions.ClientConnectorError: Cannot connect to host localhost:30023 ssl:default [Connect call failed ('127.0.0.1', 30023)]
[2025-03-07 13:53:53,876] [INFO] [30130] Received PREPARE: id:1741323218379, from:30123, delay:0.0001s, distance:191.33m (Euclidean)
[2025-03-07 13:53:53,880] [INFO] [30130] Received COMMIT: id:1741323218379, from:30123, delay:0.0001s, distance:191.33m (Euclidean)
[2025-03-07 13:53:53,970] [ERROR] [30130] Error sending to http://localhost:30029/prepare: Cannot connect to host localhost:30029 ssl:default [Connect call failed ('127.0.0.1', 30029)]
Traceback (most recent call last):
  File "D:\anaconda\envs\PBFT\lib\site-packages\aiohttp\connector.py", line 980, in _wrap_create_connection
    return await self._loop.create_connection(*args, **kwargs)  # type: ignore[return-value]  # noqa
  File "D:\anaconda\envs\PBFT\lib\asyncio\base_events.py", line 948, in create_connection
    raise exceptions[0]
  File "D:\anaconda\envs\PBFT\lib\asyncio\base_events.py", line 935, in create_connection
    await self.sock_connect(sock, address)
  File "D:\anaconda\envs\PBFT\lib\asyncio\selector_events.py", line 475, in sock_connect
    return await fut
  File "D:\anaconda\envs\PBFT\lib\asyncio\selector_events.py", line 505, in _sock_connect_cb
    raise OSError(err, f'Connect call failed {address}')
ConnectionRefusedError: [Errno 10061] Connect call failed ('127.0.0.1', 30029)

The above exception was the direct cause of the following exception:

Traceback (most recent call last):
  File "pbft.py", line 236, in send_message
    await send_with_delay(self.session, self.node_info, target, url, data, self.bandwidth_data)
  File "pbft.py", line 63, in send_with_delay
    async with session.post(url, json=data) as resp:
  File "D:\anaconda\envs\PBFT\lib\site-packages\aiohttp\client.py", line 1141, in __aenter__
    self._resp = await self._coro
  File "D:\anaconda\envs\PBFT\lib\site-packages\aiohttp\client.py", line 537, in _request
    req, traces=traces, timeout=real_timeout
  File "D:\anaconda\envs\PBFT\lib\site-packages\aiohttp\connector.py", line 540, in connect
    proto = await self._create_connection(req, traces, timeout)
  File "D:\anaconda\envs\PBFT\lib\site-packages\aiohttp\connector.py", line 901, in _create_connection
    _, proto = await self._create_direct_connection(req, traces, timeout)
  File "D:\anaconda\envs\PBFT\lib\site-packages\aiohttp\connector.py", line 1206, in _create_direct_connection
    raise last_exc
  File "D:\anaconda\envs\PBFT\lib\site-packages\aiohttp\connector.py", line 1187, in _create_direct_connection
    client_error=client_error,
  File "D:\anaconda\envs\PBFT\lib\site-packages\aiohttp\connector.py", line 988, in _wrap_create_connection
    raise client_error(req.connection_key, exc) from exc
aiohttp.client_exceptions.ClientConnectorError: Cannot connect to host localhost:30029 ssl:default [Connect call failed ('127.0.0.1', 30029)]
[2025-03-07 13:53:54,002] [ERROR] [30130] Error sending to http://localhost:30075/commit: Cannot connect to host localhost:30075 ssl:default [Connect call failed ('::1', 30075, 0, 0)]
Traceback (most recent call last):
  File "D:\anaconda\envs\PBFT\lib\site-packages\aiohttp\connector.py", line 980, in _wrap_create_connection
    return await self._loop.create_connection(*args, **kwargs)  # type: ignore[return-value]  # noqa
  File "D:\anaconda\envs\PBFT\lib\asyncio\base_events.py", line 948, in create_connection
    raise exceptions[0]
  File "D:\anaconda\envs\PBFT\lib\asyncio\base_events.py", line 935, in create_connection
    await self.sock_connect(sock, address)
  File "D:\anaconda\envs\PBFT\lib\asyncio\selector_events.py", line 475, in sock_connect
    return await fut
  File "D:\anaconda\envs\PBFT\lib\asyncio\selector_events.py", line 505, in _sock_connect_cb
    raise OSError(err, f'Connect call failed {address}')
ConnectionRefusedError: [Errno 10061] Connect call failed ('::1', 30075, 0, 0)

The above exception was the direct cause of the following exception:

Traceback (most recent call last):
  File "pbft.py", line 236, in send_message
    await send_with_delay(self.session, self.node_info, target, url, data, self.bandwidth_data)
  File "pbft.py", line 63, in send_with_delay
    async with session.post(url, json=data) as resp:
  File "D:\anaconda\envs\PBFT\lib\site-packages\aiohttp\client.py", line 1141, in __aenter__
    self._resp = await self._coro
  File "D:\anaconda\envs\PBFT\lib\site-packages\aiohttp\client.py", line 537, in _request
    req, traces=traces, timeout=real_timeout
  File "D:\anaconda\envs\PBFT\lib\site-packages\aiohttp\connector.py", line 540, in connect
    proto = await self._create_connection(req, traces, timeout)
  File "D:\anaconda\envs\PBFT\lib\site-packages\aiohttp\connector.py", line 901, in _create_connection
    _, proto = await self._create_direct_connection(req, traces, timeout)
  File "D:\anaconda\envs\PBFT\lib\site-packages\aiohttp\connector.py", line 1206, in _create_direct_connection
    raise last_exc
  File "D:\anaconda\envs\PBFT\lib\site-packages\aiohttp\connector.py", line 1187, in _create_direct_connection
    client_error=client_error,
  File "D:\anaconda\envs\PBFT\lib\site-packages\aiohttp\connector.py", line 988, in _wrap_create_connection
    raise client_error(req.connection_key, exc) from exc
aiohttp.client_exceptions.ClientConnectorError: Cannot connect to host localhost:30075 ssl:default [Connect call failed ('::1', 30075, 0, 0)]
[2025-03-07 13:53:54,034] [ERROR] [30130] Error sending to http://localhost:30025/prepare: Cannot connect to host localhost:30025 ssl:default [Connect call failed ('127.0.0.1', 30025)]
Traceback (most recent call last):
  File "D:\anaconda\envs\PBFT\lib\site-packages\aiohttp\connector.py", line 980, in _wrap_create_connection
    return await self._loop.create_connection(*args, **kwargs)  # type: ignore[return-value]  # noqa
  File "D:\anaconda\envs\PBFT\lib\asyncio\base_events.py", line 948, in create_connection
    raise exceptions[0]
  File "D:\anaconda\envs\PBFT\lib\asyncio\base_events.py", line 935, in create_connection
    await self.sock_connect(sock, address)
  File "D:\anaconda\envs\PBFT\lib\asyncio\selector_events.py", line 475, in sock_connect
    return await fut
  File "D:\anaconda\envs\PBFT\lib\asyncio\selector_events.py", line 505, in _sock_connect_cb
    raise OSError(err, f'Connect call failed {address}')
ConnectionRefusedError: [Errno 10061] Connect call failed ('127.0.0.1', 30025)

The above exception was the direct cause of the following exception:

Traceback (most recent call last):
  File "pbft.py", line 236, in send_message
    await send_with_delay(self.session, self.node_info, target, url, data, self.bandwidth_data)
  File "pbft.py", line 63, in send_with_delay
    async with session.post(url, json=data) as resp:
  File "D:\anaconda\envs\PBFT\lib\site-packages\aiohttp\client.py", line 1141, in __aenter__
    self._resp = await self._coro
  File "D:\anaconda\envs\PBFT\lib\site-packages\aiohttp\client.py", line 537, in _request
    req, traces=traces, timeout=real_timeout
  File "D:\anaconda\envs\PBFT\lib\site-packages\aiohttp\connector.py", line 540, in connect
    proto = await self._create_connection(req, traces, timeout)
  File "D:\anaconda\envs\PBFT\lib\site-packages\aiohttp\connector.py", line 901, in _create_connection
    _, proto = await self._create_direct_connection(req, traces, timeout)
  File "D:\anaconda\envs\PBFT\lib\site-packages\aiohttp\connector.py", line 1206, in _create_direct_connection
    raise last_exc
  File "D:\anaconda\envs\PBFT\lib\site-packages\aiohttp\connector.py", line 1187, in _create_direct_connection
    client_error=client_error,
  File "D:\anaconda\envs\PBFT\lib\site-packages\aiohttp\connector.py", line 988, in _wrap_create_connection
    raise client_error(req.connection_key, exc) from exc
aiohttp.client_exceptions.ClientConnectorError: Cannot connect to host localhost:30025 ssl:default [Connect call failed ('127.0.0.1', 30025)]
[2025-03-07 13:53:54,034] [ERROR] [30130] Error sending to http://localhost:30027/prepare: Cannot connect to host localhost:30027 ssl:default [Connect call failed ('127.0.0.1', 30027)]
Traceback (most recent call last):
  File "D:\anaconda\envs\PBFT\lib\site-packages\aiohttp\connector.py", line 980, in _wrap_create_connection
    return await self._loop.create_connection(*args, **kwargs)  # type: ignore[return-value]  # noqa
  File "D:\anaconda\envs\PBFT\lib\asyncio\base_events.py", line 948, in create_connection
    raise exceptions[0]
  File "D:\anaconda\envs\PBFT\lib\asyncio\base_events.py", line 935, in create_connection
    await self.sock_connect(sock, address)
  File "D:\anaconda\envs\PBFT\lib\asyncio\selector_events.py", line 475, in sock_connect
    return await fut
  File "D:\anaconda\envs\PBFT\lib\asyncio\selector_events.py", line 505, in _sock_connect_cb
    raise OSError(err, f'Connect call failed {address}')
ConnectionRefusedError: [Errno 10061] Connect call failed ('127.0.0.1', 30027)

The above exception was the direct cause of the following exception:

Traceback (most recent call last):
  File "pbft.py", line 236, in send_message
    await send_with_delay(self.session, self.node_info, target, url, data, self.bandwidth_data)
  File "pbft.py", line 63, in send_with_delay
    async with session.post(url, json=data) as resp:
  File "D:\anaconda\envs\PBFT\lib\site-packages\aiohttp\client.py", line 1141, in __aenter__
    self._resp = await self._coro
  File "D:\anaconda\envs\PBFT\lib\site-packages\aiohttp\client.py", line 537, in _request
    req, traces=traces, timeout=real_timeout
  File "D:\anaconda\envs\PBFT\lib\site-packages\aiohttp\connector.py", line 540, in connect
    proto = await self._create_connection(req, traces, timeout)
  File "D:\anaconda\envs\PBFT\lib\site-packages\aiohttp\connector.py", line 901, in _create_connection
    _, proto = await self._create_direct_connection(req, traces, timeout)
  File "D:\anaconda\envs\PBFT\lib\site-packages\aiohttp\connector.py", line 1206, in _create_direct_connection
    raise last_exc
  File "D:\anaconda\envs\PBFT\lib\site-packages\aiohttp\connector.py", line 1187, in _create_direct_connection
    client_error=client_error,
  File "D:\anaconda\envs\PBFT\lib\site-packages\aiohttp\connector.py", line 988, in _wrap_create_connection
    raise client_error(req.connection_key, exc) from exc
aiohttp.client_exceptions.ClientConnectorError: Cannot connect to host localhost:30027 ssl:default [Connect call failed ('127.0.0.1', 30027)]
[2025-03-07 13:53:54,129] [INFO] [30130] Received PREPARE: id:1741323218379, from:30106, delay:0.0002s, distance:268.30m (Euclidean)
[2025-03-07 13:53:54,129] [INFO] [30130] Received COMMIT: id:1741323218379, from:30106, delay:0.0002s, distance:268.30m (Euclidean)
[2025-03-07 13:53:54,145] [INFO] [30130] Received PREPARE: id:1741323218379, from:30111, delay:0.0000s, distance:170.68m (Euclidean)
[2025-03-07 13:53:54,145] [INFO] [30130] Received COMMIT: id:1741323218379, from:30111, delay:0.0000s, distance:170.68m (Euclidean)
[2025-03-07 13:53:54,303] [ERROR] [30130] Error sending to http://localhost:30063/prepare: Cannot connect to host localhost:30063 ssl:default [Connect call failed ('127.0.0.1', 30063)]
Traceback (most recent call last):
  File "D:\anaconda\envs\PBFT\lib\site-packages\aiohttp\connector.py", line 980, in _wrap_create_connection
    return await self._loop.create_connection(*args, **kwargs)  # type: ignore[return-value]  # noqa
  File "D:\anaconda\envs\PBFT\lib\asyncio\base_events.py", line 948, in create_connection
    raise exceptions[0]
  File "D:\anaconda\envs\PBFT\lib\asyncio\base_events.py", line 935, in create_connection
    await self.sock_connect(sock, address)
  File "D:\anaconda\envs\PBFT\lib\asyncio\selector_events.py", line 475, in sock_connect
    return await fut
  File "D:\anaconda\envs\PBFT\lib\asyncio\selector_events.py", line 505, in _sock_connect_cb
    raise OSError(err, f'Connect call failed {address}')
ConnectionRefusedError: [Errno 10061] Connect call failed ('127.0.0.1', 30063)

The above exception was the direct cause of the following exception:

Traceback (most recent call last):
  File "pbft.py", line 236, in send_message
    await send_with_delay(self.session, self.node_info, target, url, data, self.bandwidth_data)
  File "pbft.py", line 63, in send_with_delay
    async with session.post(url, json=data) as resp:
  File "D:\anaconda\envs\PBFT\lib\site-packages\aiohttp\client.py", line 1141, in __aenter__
    self._resp = await self._coro
  File "D:\anaconda\envs\PBFT\lib\site-packages\aiohttp\client.py", line 537, in _request
    req, traces=traces, timeout=real_timeout
  File "D:\anaconda\envs\PBFT\lib\site-packages\aiohttp\connector.py", line 540, in connect
    proto = await self._create_connection(req, traces, timeout)
  File "D:\anaconda\envs\PBFT\lib\site-packages\aiohttp\connector.py", line 901, in _create_connection
    _, proto = await self._create_direct_connection(req, traces, timeout)
  File "D:\anaconda\envs\PBFT\lib\site-packages\aiohttp\connector.py", line 1206, in _create_direct_connection
    raise last_exc
  File "D:\anaconda\envs\PBFT\lib\site-packages\aiohttp\connector.py", line 1187, in _create_direct_connection
    client_error=client_error,
  File "D:\anaconda\envs\PBFT\lib\site-packages\aiohttp\connector.py", line 988, in _wrap_create_connection
    raise client_error(req.connection_key, exc) from exc
aiohttp.client_exceptions.ClientConnectorError: Cannot connect to host localhost:30063 ssl:default [Connect call failed ('127.0.0.1', 30063)]
[2025-03-07 13:53:54,334] [ERROR] [30130] Error sending to http://localhost:30063/commit: Cannot connect to host localhost:30063 ssl:default [Connect call failed ('::1', 30063, 0, 0)]
Traceback (most recent call last):
  File "D:\anaconda\envs\PBFT\lib\site-packages\aiohttp\connector.py", line 980, in _wrap_create_connection
    return await self._loop.create_connection(*args, **kwargs)  # type: ignore[return-value]  # noqa
  File "D:\anaconda\envs\PBFT\lib\asyncio\base_events.py", line 948, in create_connection
    raise exceptions[0]
  File "D:\anaconda\envs\PBFT\lib\asyncio\base_events.py", line 935, in create_connection
    await self.sock_connect(sock, address)
  File "D:\anaconda\envs\PBFT\lib\asyncio\selector_events.py", line 475, in sock_connect
    return await fut
  File "D:\anaconda\envs\PBFT\lib\asyncio\selector_events.py", line 505, in _sock_connect_cb
    raise OSError(err, f'Connect call failed {address}')
ConnectionRefusedError: [Errno 10061] Connect call failed ('::1', 30063, 0, 0)

The above exception was the direct cause of the following exception:

Traceback (most recent call last):
  File "pbft.py", line 236, in send_message
    await send_with_delay(self.session, self.node_info, target, url, data, self.bandwidth_data)
  File "pbft.py", line 63, in send_with_delay
    async with session.post(url, json=data) as resp:
  File "D:\anaconda\envs\PBFT\lib\site-packages\aiohttp\client.py", line 1141, in __aenter__
    self._resp = await self._coro
  File "D:\anaconda\envs\PBFT\lib\site-packages\aiohttp\client.py", line 537, in _request
    req, traces=traces, timeout=real_timeout
  File "D:\anaconda\envs\PBFT\lib\site-packages\aiohttp\connector.py", line 540, in connect
    proto = await self._create_connection(req, traces, timeout)
  File "D:\anaconda\envs\PBFT\lib\site-packages\aiohttp\connector.py", line 901, in _create_connection
    _, proto = await self._create_direct_connection(req, traces, timeout)
  File "D:\anaconda\envs\PBFT\lib\site-packages\aiohttp\connector.py", line 1206, in _create_direct_connection
    raise last_exc
  File "D:\anaconda\envs\PBFT\lib\site-packages\aiohttp\connector.py", line 1187, in _create_direct_connection
    client_error=client_error,
  File "D:\anaconda\envs\PBFT\lib\site-packages\aiohttp\connector.py", line 988, in _wrap_create_connection
    raise client_error(req.connection_key, exc) from exc
aiohttp.client_exceptions.ClientConnectorError: Cannot connect to host localhost:30063 ssl:default [Connect call failed ('::1', 30063, 0, 0)]
[2025-03-07 13:53:54,349] [ERROR] [30130] Error sending to http://localhost:30140/prepare: Cannot connect to host localhost:30140 ssl:default [Connect call failed ('127.0.0.1', 30140)]
Traceback (most recent call last):
  File "D:\anaconda\envs\PBFT\lib\site-packages\aiohttp\connector.py", line 980, in _wrap_create_connection
    return await self._loop.create_connection(*args, **kwargs)  # type: ignore[return-value]  # noqa
  File "D:\anaconda\envs\PBFT\lib\asyncio\base_events.py", line 948, in create_connection
    raise exceptions[0]
  File "D:\anaconda\envs\PBFT\lib\asyncio\base_events.py", line 935, in create_connection
    await self.sock_connect(sock, address)
  File "D:\anaconda\envs\PBFT\lib\asyncio\selector_events.py", line 475, in sock_connect
    return await fut
  File "D:\anaconda\envs\PBFT\lib\asyncio\selector_events.py", line 505, in _sock_connect_cb
    raise OSError(err, f'Connect call failed {address}')
ConnectionRefusedError: [Errno 10061] Connect call failed ('127.0.0.1', 30140)

The above exception was the direct cause of the following exception:

Traceback (most recent call last):
  File "pbft.py", line 236, in send_message
    await send_with_delay(self.session, self.node_info, target, url, data, self.bandwidth_data)
  File "pbft.py", line 63, in send_with_delay
    async with session.post(url, json=data) as resp:
  File "D:\anaconda\envs\PBFT\lib\site-packages\aiohttp\client.py", line 1141, in __aenter__
    self._resp = await self._coro
  File "D:\anaconda\envs\PBFT\lib\site-packages\aiohttp\client.py", line 537, in _request
    req, traces=traces, timeout=real_timeout
  File "D:\anaconda\envs\PBFT\lib\site-packages\aiohttp\connector.py", line 540, in connect
    proto = await self._create_connection(req, traces, timeout)
  File "D:\anaconda\envs\PBFT\lib\site-packages\aiohttp\connector.py", line 901, in _create_connection
    _, proto = await self._create_direct_connection(req, traces, timeout)
  File "D:\anaconda\envs\PBFT\lib\site-packages\aiohttp\connector.py", line 1206, in _create_direct_connection
    raise last_exc
  File "D:\anaconda\envs\PBFT\lib\site-packages\aiohttp\connector.py", line 1187, in _create_direct_connection
    client_error=client_error,
  File "D:\anaconda\envs\PBFT\lib\site-packages\aiohttp\connector.py", line 988, in _wrap_create_connection
    raise client_error(req.connection_key, exc) from exc
aiohttp.client_exceptions.ClientConnectorError: Cannot connect to host localhost:30140 ssl:default [Connect call failed ('127.0.0.1', 30140)]
[2025-03-07 13:53:54,383] [ERROR] [30130] Error sending to http://localhost:30038/prepare: Cannot connect to host localhost:30038 ssl:default [Connect call failed ('127.0.0.1', 30038)]
Traceback (most recent call last):
  File "D:\anaconda\envs\PBFT\lib\site-packages\aiohttp\connector.py", line 980, in _wrap_create_connection
    return await self._loop.create_connection(*args, **kwargs)  # type: ignore[return-value]  # noqa
  File "D:\anaconda\envs\PBFT\lib\asyncio\base_events.py", line 948, in create_connection
    raise exceptions[0]
  File "D:\anaconda\envs\PBFT\lib\asyncio\base_events.py", line 935, in create_connection
    await self.sock_connect(sock, address)
  File "D:\anaconda\envs\PBFT\lib\asyncio\selector_events.py", line 475, in sock_connect
    return await fut
  File "D:\anaconda\envs\PBFT\lib\asyncio\selector_events.py", line 505, in _sock_connect_cb
    raise OSError(err, f'Connect call failed {address}')
ConnectionRefusedError: [Errno 10061] Connect call failed ('127.0.0.1', 30038)

The above exception was the direct cause of the following exception:

Traceback (most recent call last):
  File "pbft.py", line 236, in send_message
    await send_with_delay(self.session, self.node_info, target, url, data, self.bandwidth_data)
  File "pbft.py", line 63, in send_with_delay
    async with session.post(url, json=data) as resp:
  File "D:\anaconda\envs\PBFT\lib\site-packages\aiohttp\client.py", line 1141, in __aenter__
    self._resp = await self._coro
  File "D:\anaconda\envs\PBFT\lib\site-packages\aiohttp\client.py", line 537, in _request
    req, traces=traces, timeout=real_timeout
  File "D:\anaconda\envs\PBFT\lib\site-packages\aiohttp\connector.py", line 540, in connect
    proto = await self._create_connection(req, traces, timeout)
  File "D:\anaconda\envs\PBFT\lib\site-packages\aiohttp\connector.py", line 901, in _create_connection
    _, proto = await self._create_direct_connection(req, traces, timeout)
  File "D:\anaconda\envs\PBFT\lib\site-packages\aiohttp\connector.py", line 1206, in _create_direct_connection
    raise last_exc
  File "D:\anaconda\envs\PBFT\lib\site-packages\aiohttp\connector.py", line 1187, in _create_direct_connection
    client_error=client_error,
  File "D:\anaconda\envs\PBFT\lib\site-packages\aiohttp\connector.py", line 988, in _wrap_create_connection
    raise client_error(req.connection_key, exc) from exc
aiohttp.client_exceptions.ClientConnectorError: Cannot connect to host localhost:30038 ssl:default [Connect call failed ('127.0.0.1', 30038)]
[2025-03-07 13:53:55,440] [ERROR] [30130] Error sending to http://localhost:30085/prepare: Cannot connect to host localhost:30085 ssl:default [Connect call failed ('127.0.0.1', 30085)]
Traceback (most recent call last):
  File "D:\anaconda\envs\PBFT\lib\site-packages\aiohttp\connector.py", line 980, in _wrap_create_connection
    return await self._loop.create_connection(*args, **kwargs)  # type: ignore[return-value]  # noqa
  File "D:\anaconda\envs\PBFT\lib\asyncio\base_events.py", line 948, in create_connection
    raise exceptions[0]
  File "D:\anaconda\envs\PBFT\lib\asyncio\base_events.py", line 935, in create_connection
    await self.sock_connect(sock, address)
  File "D:\anaconda\envs\PBFT\lib\asyncio\selector_events.py", line 475, in sock_connect
    return await fut
  File "D:\anaconda\envs\PBFT\lib\asyncio\selector_events.py", line 505, in _sock_connect_cb
    raise OSError(err, f'Connect call failed {address}')
ConnectionRefusedError: [Errno 10061] Connect call failed ('127.0.0.1', 30085)

The above exception was the direct cause of the following exception:

Traceback (most recent call last):
  File "pbft.py", line 236, in send_message
    await send_with_delay(self.session, self.node_info, target, url, data, self.bandwidth_data)
  File "pbft.py", line 63, in send_with_delay
    async with session.post(url, json=data) as resp:
  File "D:\anaconda\envs\PBFT\lib\site-packages\aiohttp\client.py", line 1141, in __aenter__
    self._resp = await self._coro
  File "D:\anaconda\envs\PBFT\lib\site-packages\aiohttp\client.py", line 537, in _request
    req, traces=traces, timeout=real_timeout
  File "D:\anaconda\envs\PBFT\lib\site-packages\aiohttp\connector.py", line 540, in connect
    proto = await self._create_connection(req, traces, timeout)
  File "D:\anaconda\envs\PBFT\lib\site-packages\aiohttp\connector.py", line 901, in _create_connection
    _, proto = await self._create_direct_connection(req, traces, timeout)
  File "D:\anaconda\envs\PBFT\lib\site-packages\aiohttp\connector.py", line 1206, in _create_direct_connection
    raise last_exc
  File "D:\anaconda\envs\PBFT\lib\site-packages\aiohttp\connector.py", line 1187, in _create_direct_connection
    client_error=client_error,
  File "D:\anaconda\envs\PBFT\lib\site-packages\aiohttp\connector.py", line 988, in _wrap_create_connection
    raise client_error(req.connection_key, exc) from exc
aiohttp.client_exceptions.ClientConnectorError: Cannot connect to host localhost:30085 ssl:default [Connect call failed ('127.0.0.1', 30085)]
[2025-03-07 13:53:55,447] [ERROR] [30130] Error sending to http://localhost:30100/prepare: Cannot connect to host localhost:30100 ssl:default [Connect call failed ('127.0.0.1', 30100)]
Traceback (most recent call last):
  File "D:\anaconda\envs\PBFT\lib\site-packages\aiohttp\connector.py", line 980, in _wrap_create_connection
    return await self._loop.create_connection(*args, **kwargs)  # type: ignore[return-value]  # noqa
  File "D:\anaconda\envs\PBFT\lib\asyncio\base_events.py", line 948, in create_connection
    raise exceptions[0]
  File "D:\anaconda\envs\PBFT\lib\asyncio\base_events.py", line 935, in create_connection
    await self.sock_connect(sock, address)
  File "D:\anaconda\envs\PBFT\lib\asyncio\selector_events.py", line 475, in sock_connect
    return await fut
  File "D:\anaconda\envs\PBFT\lib\asyncio\selector_events.py", line 505, in _sock_connect_cb
    raise OSError(err, f'Connect call failed {address}')
ConnectionRefusedError: [Errno 10061] Connect call failed ('127.0.0.1', 30100)

The above exception was the direct cause of the following exception:

Traceback (most recent call last):
  File "pbft.py", line 236, in send_message
    await send_with_delay(self.session, self.node_info, target, url, data, self.bandwidth_data)
  File "pbft.py", line 63, in send_with_delay
    async with session.post(url, json=data) as resp:
  File "D:\anaconda\envs\PBFT\lib\site-packages\aiohttp\client.py", line 1141, in __aenter__
    self._resp = await self._coro
  File "D:\anaconda\envs\PBFT\lib\site-packages\aiohttp\client.py", line 537, in _request
    req, traces=traces, timeout=real_timeout
  File "D:\anaconda\envs\PBFT\lib\site-packages\aiohttp\connector.py", line 540, in connect
    proto = await self._create_connection(req, traces, timeout)
  File "D:\anaconda\envs\PBFT\lib\site-packages\aiohttp\connector.py", line 901, in _create_connection
    _, proto = await self._create_direct_connection(req, traces, timeout)
  File "D:\anaconda\envs\PBFT\lib\site-packages\aiohttp\connector.py", line 1206, in _create_direct_connection
    raise last_exc
  File "D:\anaconda\envs\PBFT\lib\site-packages\aiohttp\connector.py", line 1187, in _create_direct_connection
    client_error=client_error,
  File "D:\anaconda\envs\PBFT\lib\site-packages\aiohttp\connector.py", line 988, in _wrap_create_connection
    raise client_error(req.connection_key, exc) from exc
aiohttp.client_exceptions.ClientConnectorError: Cannot connect to host localhost:30100 ssl:default [Connect call failed ('127.0.0.1', 30100)]
[2025-03-07 13:53:55,447] [ERROR] [30130] Error sending to http://localhost:30101/prepare: Cannot connect to host localhost:30101 ssl:default [Connect call failed ('127.0.0.1', 30101)]
Traceback (most recent call last):
  File "D:\anaconda\envs\PBFT\lib\site-packages\aiohttp\connector.py", line 980, in _wrap_create_connection
    return await self._loop.create_connection(*args, **kwargs)  # type: ignore[return-value]  # noqa
  File "D:\anaconda\envs\PBFT\lib\asyncio\base_events.py", line 948, in create_connection
    raise exceptions[0]
  File "D:\anaconda\envs\PBFT\lib\asyncio\base_events.py", line 935, in create_connection
    await self.sock_connect(sock, address)
  File "D:\anaconda\envs\PBFT\lib\asyncio\selector_events.py", line 475, in sock_connect
    return await fut
  File "D:\anaconda\envs\PBFT\lib\asyncio\selector_events.py", line 505, in _sock_connect_cb
    raise OSError(err, f'Connect call failed {address}')
ConnectionRefusedError: [Errno 10061] Connect call failed ('127.0.0.1', 30101)

The above exception was the direct cause of the following exception:

Traceback (most recent call last):
  File "pbft.py", line 236, in send_message
    await send_with_delay(self.session, self.node_info, target, url, data, self.bandwidth_data)
  File "pbft.py", line 63, in send_with_delay
    async with session.post(url, json=data) as resp:
  File "D:\anaconda\envs\PBFT\lib\site-packages\aiohttp\client.py", line 1141, in __aenter__
    self._resp = await self._coro
  File "D:\anaconda\envs\PBFT\lib\site-packages\aiohttp\client.py", line 537, in _request
    req, traces=traces, timeout=real_timeout
  File "D:\anaconda\envs\PBFT\lib\site-packages\aiohttp\connector.py", line 540, in connect
    proto = await self._create_connection(req, traces, timeout)
  File "D:\anaconda\envs\PBFT\lib\site-packages\aiohttp\connector.py", line 901, in _create_connection
    _, proto = await self._create_direct_connection(req, traces, timeout)
  File "D:\anaconda\envs\PBFT\lib\site-packages\aiohttp\connector.py", line 1206, in _create_direct_connection
    raise last_exc
  File "D:\anaconda\envs\PBFT\lib\site-packages\aiohttp\connector.py", line 1187, in _create_direct_connection
    client_error=client_error,
  File "D:\anaconda\envs\PBFT\lib\site-packages\aiohttp\connector.py", line 988, in _wrap_create_connection
    raise client_error(req.connection_key, exc) from exc
aiohttp.client_exceptions.ClientConnectorError: Cannot connect to host localhost:30101 ssl:default [Connect call failed ('127.0.0.1', 30101)]
[2025-03-07 13:53:55,447] [ERROR] [30130] Error sending to http://localhost:30100/commit: Cannot connect to host localhost:30100 ssl:default [Connect call failed ('::1', 30100, 0, 0)]
Traceback (most recent call last):
  File "D:\anaconda\envs\PBFT\lib\site-packages\aiohttp\connector.py", line 980, in _wrap_create_connection
    return await self._loop.create_connection(*args, **kwargs)  # type: ignore[return-value]  # noqa
  File "D:\anaconda\envs\PBFT\lib\asyncio\base_events.py", line 948, in create_connection
    raise exceptions[0]
  File "D:\anaconda\envs\PBFT\lib\asyncio\base_events.py", line 935, in create_connection
    await self.sock_connect(sock, address)
  File "D:\anaconda\envs\PBFT\lib\asyncio\selector_events.py", line 475, in sock_connect
    return await fut
  File "D:\anaconda\envs\PBFT\lib\asyncio\selector_events.py", line 505, in _sock_connect_cb
    raise OSError(err, f'Connect call failed {address}')
ConnectionRefusedError: [Errno 10061] Connect call failed ('::1', 30100, 0, 0)

The above exception was the direct cause of the following exception:

Traceback (most recent call last):
  File "pbft.py", line 236, in send_message
    await send_with_delay(self.session, self.node_info, target, url, data, self.bandwidth_data)
  File "pbft.py", line 63, in send_with_delay
    async with session.post(url, json=data) as resp:
  File "D:\anaconda\envs\PBFT\lib\site-packages\aiohttp\client.py", line 1141, in __aenter__
    self._resp = await self._coro
  File "D:\anaconda\envs\PBFT\lib\site-packages\aiohttp\client.py", line 537, in _request
    req, traces=traces, timeout=real_timeout
  File "D:\anaconda\envs\PBFT\lib\site-packages\aiohttp\connector.py", line 540, in connect
    proto = await self._create_connection(req, traces, timeout)
  File "D:\anaconda\envs\PBFT\lib\site-packages\aiohttp\connector.py", line 901, in _create_connection
    _, proto = await self._create_direct_connection(req, traces, timeout)
  File "D:\anaconda\envs\PBFT\lib\site-packages\aiohttp\connector.py", line 1206, in _create_direct_connection
    raise last_exc
  File "D:\anaconda\envs\PBFT\lib\site-packages\aiohttp\connector.py", line 1187, in _create_direct_connection
    client_error=client_error,
  File "D:\anaconda\envs\PBFT\lib\site-packages\aiohttp\connector.py", line 988, in _wrap_create_connection
    raise client_error(req.connection_key, exc) from exc
aiohttp.client_exceptions.ClientConnectorError: Cannot connect to host localhost:30100 ssl:default [Connect call failed ('::1', 30100, 0, 0)]
[2025-03-07 13:53:55,447] [ERROR] [30130] Error sending to http://localhost:30029/commit: Cannot connect to host localhost:30029 ssl:default [Connect call failed ('::1', 30029, 0, 0)]
Traceback (most recent call last):
  File "D:\anaconda\envs\PBFT\lib\site-packages\aiohttp\connector.py", line 980, in _wrap_create_connection
    return await self._loop.create_connection(*args, **kwargs)  # type: ignore[return-value]  # noqa
  File "D:\anaconda\envs\PBFT\lib\asyncio\base_events.py", line 948, in create_connection
    raise exceptions[0]
  File "D:\anaconda\envs\PBFT\lib\asyncio\base_events.py", line 935, in create_connection
    await self.sock_connect(sock, address)
  File "D:\anaconda\envs\PBFT\lib\asyncio\selector_events.py", line 475, in sock_connect
    return await fut
  File "D:\anaconda\envs\PBFT\lib\asyncio\selector_events.py", line 505, in _sock_connect_cb
    raise OSError(err, f'Connect call failed {address}')
ConnectionRefusedError: [Errno 10061] Connect call failed ('::1', 30029, 0, 0)

The above exception was the direct cause of the following exception:

Traceback (most recent call last):
  File "pbft.py", line 236, in send_message
    await send_with_delay(self.session, self.node_info, target, url, data, self.bandwidth_data)
  File "pbft.py", line 63, in send_with_delay
    async with session.post(url, json=data) as resp:
  File "D:\anaconda\envs\PBFT\lib\site-packages\aiohttp\client.py", line 1141, in __aenter__
    self._resp = await self._coro
  File "D:\anaconda\envs\PBFT\lib\site-packages\aiohttp\client.py", line 537, in _request
    req, traces=traces, timeout=real_timeout
  File "D:\anaconda\envs\PBFT\lib\site-packages\aiohttp\connector.py", line 540, in connect
    proto = await self._create_connection(req, traces, timeout)
  File "D:\anaconda\envs\PBFT\lib\site-packages\aiohttp\connector.py", line 901, in _create_connection
    _, proto = await self._create_direct_connection(req, traces, timeout)
  File "D:\anaconda\envs\PBFT\lib\site-packages\aiohttp\connector.py", line 1206, in _create_direct_connection
    raise last_exc
  File "D:\anaconda\envs\PBFT\lib\site-packages\aiohttp\connector.py", line 1187, in _create_direct_connection
    client_error=client_error,
  File "D:\anaconda\envs\PBFT\lib\site-packages\aiohttp\connector.py", line 988, in _wrap_create_connection
    raise client_error(req.connection_key, exc) from exc
aiohttp.client_exceptions.ClientConnectorError: Cannot connect to host localhost:30029 ssl:default [Connect call failed ('::1', 30029, 0, 0)]
[2025-03-07 13:53:55,447] [ERROR] [30130] Error sending to http://localhost:30137/prepare: Cannot connect to host localhost:30137 ssl:default [Connect call failed ('127.0.0.1', 30137)]
Traceback (most recent call last):
  File "D:\anaconda\envs\PBFT\lib\site-packages\aiohttp\connector.py", line 980, in _wrap_create_connection
    return await self._loop.create_connection(*args, **kwargs)  # type: ignore[return-value]  # noqa
  File "D:\anaconda\envs\PBFT\lib\asyncio\base_events.py", line 948, in create_connection
    raise exceptions[0]
  File "D:\anaconda\envs\PBFT\lib\asyncio\base_events.py", line 935, in create_connection
    await self.sock_connect(sock, address)
  File "D:\anaconda\envs\PBFT\lib\asyncio\selector_events.py", line 475, in sock_connect
    return await fut
  File "D:\anaconda\envs\PBFT\lib\asyncio\selector_events.py", line 505, in _sock_connect_cb
    raise OSError(err, f'Connect call failed {address}')
ConnectionRefusedError: [Errno 10061] Connect call failed ('127.0.0.1', 30137)

The above exception was the direct cause of the following exception:

Traceback (most recent call last):
  File "pbft.py", line 236, in send_message
    await send_with_delay(self.session, self.node_info, target, url, data, self.bandwidth_data)
  File "pbft.py", line 63, in send_with_delay
    async with session.post(url, json=data) as resp:
  File "D:\anaconda\envs\PBFT\lib\site-packages\aiohttp\client.py", line 1141, in __aenter__
    self._resp = await self._coro
  File "D:\anaconda\envs\PBFT\lib\site-packages\aiohttp\client.py", line 537, in _request
    req, traces=traces, timeout=real_timeout
  File "D:\anaconda\envs\PBFT\lib\site-packages\aiohttp\connector.py", line 540, in connect
    proto = await self._create_connection(req, traces, timeout)
  File "D:\anaconda\envs\PBFT\lib\site-packages\aiohttp\connector.py", line 901, in _create_connection
    _, proto = await self._create_direct_connection(req, traces, timeout)
  File "D:\anaconda\envs\PBFT\lib\site-packages\aiohttp\connector.py", line 1206, in _create_direct_connection
    raise last_exc
  File "D:\anaconda\envs\PBFT\lib\site-packages\aiohttp\connector.py", line 1187, in _create_direct_connection
    client_error=client_error,
  File "D:\anaconda\envs\PBFT\lib\site-packages\aiohttp\connector.py", line 988, in _wrap_create_connection
    raise client_error(req.connection_key, exc) from exc
aiohttp.client_exceptions.ClientConnectorError: Cannot connect to host localhost:30137 ssl:default [Connect call failed ('127.0.0.1', 30137)]
[2025-03-07 13:53:55,447] [ERROR] [30130] Error sending to http://localhost:30141/prepare: Cannot connect to host localhost:30141 ssl:default [Connect call failed ('127.0.0.1', 30141)]
Traceback (most recent call last):
  File "D:\anaconda\envs\PBFT\lib\site-packages\aiohttp\connector.py", line 980, in _wrap_create_connection
    return await self._loop.create_connection(*args, **kwargs)  # type: ignore[return-value]  # noqa
  File "D:\anaconda\envs\PBFT\lib\asyncio\base_events.py", line 948, in create_connection
    raise exceptions[0]
  File "D:\anaconda\envs\PBFT\lib\asyncio\base_events.py", line 935, in create_connection
    await self.sock_connect(sock, address)
  File "D:\anaconda\envs\PBFT\lib\asyncio\selector_events.py", line 475, in sock_connect
    return await fut
  File "D:\anaconda\envs\PBFT\lib\asyncio\selector_events.py", line 505, in _sock_connect_cb
    raise OSError(err, f'Connect call failed {address}')
ConnectionRefusedError: [Errno 10061] Connect call failed ('127.0.0.1', 30141)

The above exception was the direct cause of the following exception:

Traceback (most recent call last):
  File "pbft.py", line 236, in send_message
    await send_with_delay(self.session, self.node_info, target, url, data, self.bandwidth_data)
  File "pbft.py", line 63, in send_with_delay
    async with session.post(url, json=data) as resp:
  File "D:\anaconda\envs\PBFT\lib\site-packages\aiohttp\client.py", line 1141, in __aenter__
    self._resp = await self._coro
  File "D:\anaconda\envs\PBFT\lib\site-packages\aiohttp\client.py", line 537, in _request
    req, traces=traces, timeout=real_timeout
  File "D:\anaconda\envs\PBFT\lib\site-packages\aiohttp\connector.py", line 540, in connect
    proto = await self._create_connection(req, traces, timeout)
  File "D:\anaconda\envs\PBFT\lib\site-packages\aiohttp\connector.py", line 901, in _create_connection
    _, proto = await self._create_direct_connection(req, traces, timeout)
  File "D:\anaconda\envs\PBFT\lib\site-packages\aiohttp\connector.py", line 1206, in _create_direct_connection
    raise last_exc
  File "D:\anaconda\envs\PBFT\lib\site-packages\aiohttp\connector.py", line 1187, in _create_direct_connection
    client_error=client_error,
  File "D:\anaconda\envs\PBFT\lib\site-packages\aiohttp\connector.py", line 988, in _wrap_create_connection
    raise client_error(req.connection_key, exc) from exc
aiohttp.client_exceptions.ClientConnectorError: Cannot connect to host localhost:30141 ssl:default [Connect call failed ('127.0.0.1', 30141)]
[2025-03-07 13:53:55,447] [ERROR] [30130] Error sending to http://localhost:30076/commit: Cannot connect to host localhost:30076 ssl:default [Connect call failed ('::1', 30076, 0, 0)]
Traceback (most recent call last):
  File "D:\anaconda\envs\PBFT\lib\site-packages\aiohttp\connector.py", line 980, in _wrap_create_connection
    return await self._loop.create_connection(*args, **kwargs)  # type: ignore[return-value]  # noqa
  File "D:\anaconda\envs\PBFT\lib\asyncio\base_events.py", line 948, in create_connection
    raise exceptions[0]
  File "D:\anaconda\envs\PBFT\lib\asyncio\base_events.py", line 935, in create_connection
    await self.sock_connect(sock, address)
  File "D:\anaconda\envs\PBFT\lib\asyncio\selector_events.py", line 475, in sock_connect
    return await fut
  File "D:\anaconda\envs\PBFT\lib\asyncio\selector_events.py", line 505, in _sock_connect_cb
    raise OSError(err, f'Connect call failed {address}')
ConnectionRefusedError: [Errno 10061] Connect call failed ('::1', 30076, 0, 0)

The above exception was the direct cause of the following exception:

Traceback (most recent call last):
  File "pbft.py", line 236, in send_message
    await send_with_delay(self.session, self.node_info, target, url, data, self.bandwidth_data)
  File "pbft.py", line 63, in send_with_delay
    async with session.post(url, json=data) as resp:
  File "D:\anaconda\envs\PBFT\lib\site-packages\aiohttp\client.py", line 1141, in __aenter__
    self._resp = await self._coro
  File "D:\anaconda\envs\PBFT\lib\site-packages\aiohttp\client.py", line 537, in _request
    req, traces=traces, timeout=real_timeout
  File "D:\anaconda\envs\PBFT\lib\site-packages\aiohttp\connector.py", line 540, in connect
    proto = await self._create_connection(req, traces, timeout)
  File "D:\anaconda\envs\PBFT\lib\site-packages\aiohttp\connector.py", line 901, in _create_connection
    _, proto = await self._create_direct_connection(req, traces, timeout)
  File "D:\anaconda\envs\PBFT\lib\site-packages\aiohttp\connector.py", line 1206, in _create_direct_connection
    raise last_exc
  File "D:\anaconda\envs\PBFT\lib\site-packages\aiohttp\connector.py", line 1187, in _create_direct_connection
    client_error=client_error,
  File "D:\anaconda\envs\PBFT\lib\site-packages\aiohttp\connector.py", line 988, in _wrap_create_connection
    raise client_error(req.connection_key, exc) from exc
aiohttp.client_exceptions.ClientConnectorError: Cannot connect to host localhost:30076 ssl:default [Connect call failed ('::1', 30076, 0, 0)]
[2025-03-07 13:53:55,456] [ERROR] [30130] Error sending to http://localhost:30101/commit: Cannot connect to host localhost:30101 ssl:default [Connect call failed ('::1', 30101, 0, 0)]
Traceback (most recent call last):
  File "D:\anaconda\envs\PBFT\lib\site-packages\aiohttp\connector.py", line 980, in _wrap_create_connection
    return await self._loop.create_connection(*args, **kwargs)  # type: ignore[return-value]  # noqa
  File "D:\anaconda\envs\PBFT\lib\asyncio\base_events.py", line 948, in create_connection
    raise exceptions[0]
  File "D:\anaconda\envs\PBFT\lib\asyncio\base_events.py", line 935, in create_connection
    await self.sock_connect(sock, address)
  File "D:\anaconda\envs\PBFT\lib\asyncio\selector_events.py", line 475, in sock_connect
    return await fut
  File "D:\anaconda\envs\PBFT\lib\asyncio\selector_events.py", line 505, in _sock_connect_cb
    raise OSError(err, f'Connect call failed {address}')
ConnectionRefusedError: [Errno 10061] Connect call failed ('::1', 30101, 0, 0)

The above exception was the direct cause of the following exception:

Traceback (most recent call last):
  File "pbft.py", line 236, in send_message
    await send_with_delay(self.session, self.node_info, target, url, data, self.bandwidth_data)
  File "pbft.py", line 63, in send_with_delay
    async with session.post(url, json=data) as resp:
  File "D:\anaconda\envs\PBFT\lib\site-packages\aiohttp\client.py", line 1141, in __aenter__
    self._resp = await self._coro
  File "D:\anaconda\envs\PBFT\lib\site-packages\aiohttp\client.py", line 537, in _request
    req, traces=traces, timeout=real_timeout
  File "D:\anaconda\envs\PBFT\lib\site-packages\aiohttp\connector.py", line 540, in connect
    proto = await self._create_connection(req, traces, timeout)
  File "D:\anaconda\envs\PBFT\lib\site-packages\aiohttp\connector.py", line 901, in _create_connection
    _, proto = await self._create_direct_connection(req, traces, timeout)
  File "D:\anaconda\envs\PBFT\lib\site-packages\aiohttp\connector.py", line 1206, in _create_direct_connection
    raise last_exc
  File "D:\anaconda\envs\PBFT\lib\site-packages\aiohttp\connector.py", line 1187, in _create_direct_connection
    client_error=client_error,
  File "D:\anaconda\envs\PBFT\lib\site-packages\aiohttp\connector.py", line 988, in _wrap_create_connection
    raise client_error(req.connection_key, exc) from exc
aiohttp.client_exceptions.ClientConnectorError: Cannot connect to host localhost:30101 ssl:default [Connect call failed ('::1', 30101, 0, 0)]
[2025-03-07 13:53:55,456] [ERROR] [30130] Error sending to http://localhost:30137/commit: Cannot connect to host localhost:30137 ssl:default [Connect call failed ('::1', 30137, 0, 0)]
Traceback (most recent call last):
  File "D:\anaconda\envs\PBFT\lib\site-packages\aiohttp\connector.py", line 980, in _wrap_create_connection
    return await self._loop.create_connection(*args, **kwargs)  # type: ignore[return-value]  # noqa
  File "D:\anaconda\envs\PBFT\lib\asyncio\base_events.py", line 948, in create_connection
    raise exceptions[0]
  File "D:\anaconda\envs\PBFT\lib\asyncio\base_events.py", line 935, in create_connection
    await self.sock_connect(sock, address)
  File "D:\anaconda\envs\PBFT\lib\asyncio\selector_events.py", line 475, in sock_connect
    return await fut
  File "D:\anaconda\envs\PBFT\lib\asyncio\selector_events.py", line 505, in _sock_connect_cb
    raise OSError(err, f'Connect call failed {address}')
ConnectionRefusedError: [Errno 10061] Connect call failed ('::1', 30137, 0, 0)

The above exception was the direct cause of the following exception:

Traceback (most recent call last):
  File "pbft.py", line 236, in send_message
    await send_with_delay(self.session, self.node_info, target, url, data, self.bandwidth_data)
  File "pbft.py", line 63, in send_with_delay
    async with session.post(url, json=data) as resp:
  File "D:\anaconda\envs\PBFT\lib\site-packages\aiohttp\client.py", line 1141, in __aenter__
    self._resp = await self._coro
  File "D:\anaconda\envs\PBFT\lib\site-packages\aiohttp\client.py", line 537, in _request
    req, traces=traces, timeout=real_timeout
  File "D:\anaconda\envs\PBFT\lib\site-packages\aiohttp\connector.py", line 540, in connect
    proto = await self._create_connection(req, traces, timeout)
  File "D:\anaconda\envs\PBFT\lib\site-packages\aiohttp\connector.py", line 901, in _create_connection
    _, proto = await self._create_direct_connection(req, traces, timeout)
  File "D:\anaconda\envs\PBFT\lib\site-packages\aiohttp\connector.py", line 1206, in _create_direct_connection
    raise last_exc
  File "D:\anaconda\envs\PBFT\lib\site-packages\aiohttp\connector.py", line 1187, in _create_direct_connection
    client_error=client_error,
  File "D:\anaconda\envs\PBFT\lib\site-packages\aiohttp\connector.py", line 988, in _wrap_create_connection
    raise client_error(req.connection_key, exc) from exc
aiohttp.client_exceptions.ClientConnectorError: Cannot connect to host localhost:30137 ssl:default [Connect call failed ('::1', 30137, 0, 0)]
[2025-03-07 13:53:55,456] [ERROR] [30130] Error sending to http://localhost:30103/prepare: Cannot connect to host localhost:30103 ssl:default [Connect call failed ('127.0.0.1', 30103)]
Traceback (most recent call last):
  File "D:\anaconda\envs\PBFT\lib\site-packages\aiohttp\connector.py", line 980, in _wrap_create_connection
    return await self._loop.create_connection(*args, **kwargs)  # type: ignore[return-value]  # noqa
  File "D:\anaconda\envs\PBFT\lib\asyncio\base_events.py", line 948, in create_connection
    raise exceptions[0]
  File "D:\anaconda\envs\PBFT\lib\asyncio\base_events.py", line 935, in create_connection
    await self.sock_connect(sock, address)
  File "D:\anaconda\envs\PBFT\lib\asyncio\selector_events.py", line 475, in sock_connect
    return await fut
  File "D:\anaconda\envs\PBFT\lib\asyncio\selector_events.py", line 505, in _sock_connect_cb
    raise OSError(err, f'Connect call failed {address}')
ConnectionRefusedError: [Errno 10061] Connect call failed ('127.0.0.1', 30103)

The above exception was the direct cause of the following exception:

Traceback (most recent call last):
  File "pbft.py", line 236, in send_message
    await send_with_delay(self.session, self.node_info, target, url, data, self.bandwidth_data)
  File "pbft.py", line 63, in send_with_delay
    async with session.post(url, json=data) as resp:
  File "D:\anaconda\envs\PBFT\lib\site-packages\aiohttp\client.py", line 1141, in __aenter__
    self._resp = await self._coro
  File "D:\anaconda\envs\PBFT\lib\site-packages\aiohttp\client.py", line 537, in _request
    req, traces=traces, timeout=real_timeout
  File "D:\anaconda\envs\PBFT\lib\site-packages\aiohttp\connector.py", line 540, in connect
    proto = await self._create_connection(req, traces, timeout)
  File "D:\anaconda\envs\PBFT\lib\site-packages\aiohttp\connector.py", line 901, in _create_connection
    _, proto = await self._create_direct_connection(req, traces, timeout)
  File "D:\anaconda\envs\PBFT\lib\site-packages\aiohttp\connector.py", line 1206, in _create_direct_connection
    raise last_exc
  File "D:\anaconda\envs\PBFT\lib\site-packages\aiohttp\connector.py", line 1187, in _create_direct_connection
    client_error=client_error,
  File "D:\anaconda\envs\PBFT\lib\site-packages\aiohttp\connector.py", line 988, in _wrap_create_connection
    raise client_error(req.connection_key, exc) from exc
aiohttp.client_exceptions.ClientConnectorError: Cannot connect to host localhost:30103 ssl:default [Connect call failed ('127.0.0.1', 30103)]
[2025-03-07 13:53:55,458] [ERROR] [30130] Error sending to http://localhost:30124/prepare: Cannot connect to host localhost:30124 ssl:default [Connect call failed ('127.0.0.1', 30124)]
Traceback (most recent call last):
  File "D:\anaconda\envs\PBFT\lib\site-packages\aiohttp\connector.py", line 980, in _wrap_create_connection
    return await self._loop.create_connection(*args, **kwargs)  # type: ignore[return-value]  # noqa
  File "D:\anaconda\envs\PBFT\lib\asyncio\base_events.py", line 948, in create_connection
    raise exceptions[0]
  File "D:\anaconda\envs\PBFT\lib\asyncio\base_events.py", line 935, in create_connection
    await self.sock_connect(sock, address)
  File "D:\anaconda\envs\PBFT\lib\asyncio\selector_events.py", line 475, in sock_connect
    return await fut
  File "D:\anaconda\envs\PBFT\lib\asyncio\selector_events.py", line 505, in _sock_connect_cb
    raise OSError(err, f'Connect call failed {address}')
ConnectionRefusedError: [Errno 10061] Connect call failed ('127.0.0.1', 30124)

The above exception was the direct cause of the following exception:

Traceback (most recent call last):
  File "pbft.py", line 236, in send_message
    await send_with_delay(self.session, self.node_info, target, url, data, self.bandwidth_data)
  File "pbft.py", line 63, in send_with_delay
    async with session.post(url, json=data) as resp:
  File "D:\anaconda\envs\PBFT\lib\site-packages\aiohttp\client.py", line 1141, in __aenter__
    self._resp = await self._coro
  File "D:\anaconda\envs\PBFT\lib\site-packages\aiohttp\client.py", line 537, in _request
    req, traces=traces, timeout=real_timeout
  File "D:\anaconda\envs\PBFT\lib\site-packages\aiohttp\connector.py", line 540, in connect
    proto = await self._create_connection(req, traces, timeout)
  File "D:\anaconda\envs\PBFT\lib\site-packages\aiohttp\connector.py", line 901, in _create_connection
    _, proto = await self._create_direct_connection(req, traces, timeout)
  File "D:\anaconda\envs\PBFT\lib\site-packages\aiohttp\connector.py", line 1206, in _create_direct_connection
    raise last_exc
  File "D:\anaconda\envs\PBFT\lib\site-packages\aiohttp\connector.py", line 1187, in _create_direct_connection
    client_error=client_error,
  File "D:\anaconda\envs\PBFT\lib\site-packages\aiohttp\connector.py", line 988, in _wrap_create_connection
    raise client_error(req.connection_key, exc) from exc
aiohttp.client_exceptions.ClientConnectorError: Cannot connect to host localhost:30124 ssl:default [Connect call failed ('127.0.0.1', 30124)]
[2025-03-07 13:53:55,459] [ERROR] [30130] Error sending to http://localhost:30125/prepare: Cannot connect to host localhost:30125 ssl:default [Connect call failed ('127.0.0.1', 30125)]
Traceback (most recent call last):
  File "D:\anaconda\envs\PBFT\lib\site-packages\aiohttp\connector.py", line 980, in _wrap_create_connection
    return await self._loop.create_connection(*args, **kwargs)  # type: ignore[return-value]  # noqa
  File "D:\anaconda\envs\PBFT\lib\asyncio\base_events.py", line 948, in create_connection
    raise exceptions[0]
  File "D:\anaconda\envs\PBFT\lib\asyncio\base_events.py", line 935, in create_connection
    await self.sock_connect(sock, address)
  File "D:\anaconda\envs\PBFT\lib\asyncio\selector_events.py", line 475, in sock_connect
    return await fut
  File "D:\anaconda\envs\PBFT\lib\asyncio\selector_events.py", line 505, in _sock_connect_cb
    raise OSError(err, f'Connect call failed {address}')
ConnectionRefusedError: [Errno 10061] Connect call failed ('127.0.0.1', 30125)

The above exception was the direct cause of the following exception:

Traceback (most recent call last):
  File "pbft.py", line 236, in send_message
    await send_with_delay(self.session, self.node_info, target, url, data, self.bandwidth_data)
  File "pbft.py", line 63, in send_with_delay
    async with session.post(url, json=data) as resp:
  File "D:\anaconda\envs\PBFT\lib\site-packages\aiohttp\client.py", line 1141, in __aenter__
    self._resp = await self._coro
  File "D:\anaconda\envs\PBFT\lib\site-packages\aiohttp\client.py", line 537, in _request
    req, traces=traces, timeout=real_timeout
  File "D:\anaconda\envs\PBFT\lib\site-packages\aiohttp\connector.py", line 540, in connect
    proto = await self._create_connection(req, traces, timeout)
  File "D:\anaconda\envs\PBFT\lib\site-packages\aiohttp\connector.py", line 901, in _create_connection
    _, proto = await self._create_direct_connection(req, traces, timeout)
  File "D:\anaconda\envs\PBFT\lib\site-packages\aiohttp\connector.py", line 1206, in _create_direct_connection
    raise last_exc
  File "D:\anaconda\envs\PBFT\lib\site-packages\aiohttp\connector.py", line 1187, in _create_direct_connection
    client_error=client_error,
  File "D:\anaconda\envs\PBFT\lib\site-packages\aiohttp\connector.py", line 988, in _wrap_create_connection
    raise client_error(req.connection_key, exc) from exc
aiohttp.client_exceptions.ClientConnectorError: Cannot connect to host localhost:30125 ssl:default [Connect call failed ('127.0.0.1', 30125)]
[2025-03-07 13:53:55,463] [ERROR] [30130] Error sending to http://localhost:30071/commit: Cannot connect to host localhost:30071 ssl:default [Connect call failed ('::1', 30071, 0, 0)]
Traceback (most recent call last):
  File "D:\anaconda\envs\PBFT\lib\site-packages\aiohttp\connector.py", line 980, in _wrap_create_connection
    return await self._loop.create_connection(*args, **kwargs)  # type: ignore[return-value]  # noqa
  File "D:\anaconda\envs\PBFT\lib\asyncio\base_events.py", line 948, in create_connection
    raise exceptions[0]
  File "D:\anaconda\envs\PBFT\lib\asyncio\base_events.py", line 935, in create_connection
    await self.sock_connect(sock, address)
  File "D:\anaconda\envs\PBFT\lib\asyncio\selector_events.py", line 475, in sock_connect
    return await fut
  File "D:\anaconda\envs\PBFT\lib\asyncio\selector_events.py", line 505, in _sock_connect_cb
    raise OSError(err, f'Connect call failed {address}')
ConnectionRefusedError: [Errno 10061] Connect call failed ('::1', 30071, 0, 0)

The above exception was the direct cause of the following exception:

Traceback (most recent call last):
  File "pbft.py", line 236, in send_message
    await send_with_delay(self.session, self.node_info, target, url, data, self.bandwidth_data)
  File "pbft.py", line 63, in send_with_delay
    async with session.post(url, json=data) as resp:
  File "D:\anaconda\envs\PBFT\lib\site-packages\aiohttp\client.py", line 1141, in __aenter__
    self._resp = await self._coro
  File "D:\anaconda\envs\PBFT\lib\site-packages\aiohttp\client.py", line 537, in _request
    req, traces=traces, timeout=real_timeout
  File "D:\anaconda\envs\PBFT\lib\site-packages\aiohttp\connector.py", line 540, in connect
    proto = await self._create_connection(req, traces, timeout)
  File "D:\anaconda\envs\PBFT\lib\site-packages\aiohttp\connector.py", line 901, in _create_connection
    _, proto = await self._create_direct_connection(req, traces, timeout)
  File "D:\anaconda\envs\PBFT\lib\site-packages\aiohttp\connector.py", line 1206, in _create_direct_connection
    raise last_exc
  File "D:\anaconda\envs\PBFT\lib\site-packages\aiohttp\connector.py", line 1187, in _create_direct_connection
    client_error=client_error,
  File "D:\anaconda\envs\PBFT\lib\site-packages\aiohttp\connector.py", line 988, in _wrap_create_connection
    raise client_error(req.connection_key, exc) from exc
aiohttp.client_exceptions.ClientConnectorError: Cannot connect to host localhost:30071 ssl:default [Connect call failed ('::1', 30071, 0, 0)]
[2025-03-07 13:53:55,471] [ERROR] [30130] Error sending to http://localhost:30038/commit: Cannot connect to host localhost:30038 ssl:default [Connect call failed ('::1', 30038, 0, 0)]
Traceback (most recent call last):
  File "D:\anaconda\envs\PBFT\lib\site-packages\aiohttp\connector.py", line 980, in _wrap_create_connection
    return await self._loop.create_connection(*args, **kwargs)  # type: ignore[return-value]  # noqa
  File "D:\anaconda\envs\PBFT\lib\asyncio\base_events.py", line 948, in create_connection
    raise exceptions[0]
  File "D:\anaconda\envs\PBFT\lib\asyncio\base_events.py", line 935, in create_connection
    await self.sock_connect(sock, address)
  File "D:\anaconda\envs\PBFT\lib\asyncio\selector_events.py", line 475, in sock_connect
    return await fut
  File "D:\anaconda\envs\PBFT\lib\asyncio\selector_events.py", line 505, in _sock_connect_cb
    raise OSError(err, f'Connect call failed {address}')
ConnectionRefusedError: [Errno 10061] Connect call failed ('::1', 30038, 0, 0)

The above exception was the direct cause of the following exception:

Traceback (most recent call last):
  File "pbft.py", line 236, in send_message
    await send_with_delay(self.session, self.node_info, target, url, data, self.bandwidth_data)
  File "pbft.py", line 63, in send_with_delay
    async with session.post(url, json=data) as resp:
  File "D:\anaconda\envs\PBFT\lib\site-packages\aiohttp\client.py", line 1141, in __aenter__
    self._resp = await self._coro
  File "D:\anaconda\envs\PBFT\lib\site-packages\aiohttp\client.py", line 537, in _request
    req, traces=traces, timeout=real_timeout
  File "D:\anaconda\envs\PBFT\lib\site-packages\aiohttp\connector.py", line 540, in connect
    proto = await self._create_connection(req, traces, timeout)
  File "D:\anaconda\envs\PBFT\lib\site-packages\aiohttp\connector.py", line 901, in _create_connection
    _, proto = await self._create_direct_connection(req, traces, timeout)
  File "D:\anaconda\envs\PBFT\lib\site-packages\aiohttp\connector.py", line 1206, in _create_direct_connection
    raise last_exc
  File "D:\anaconda\envs\PBFT\lib\site-packages\aiohttp\connector.py", line 1187, in _create_direct_connection
    client_error=client_error,
  File "D:\anaconda\envs\PBFT\lib\site-packages\aiohttp\connector.py", line 988, in _wrap_create_connection
    raise client_error(req.connection_key, exc) from exc
aiohttp.client_exceptions.ClientConnectorError: Cannot connect to host localhost:30038 ssl:default [Connect call failed ('::1', 30038, 0, 0)]
[2025-03-07 13:53:55,472] [ERROR] [30130] Error sending to http://localhost:30103/commit: Cannot connect to host localhost:30103 ssl:default [Connect call failed ('::1', 30103, 0, 0)]
Traceback (most recent call last):
  File "D:\anaconda\envs\PBFT\lib\site-packages\aiohttp\connector.py", line 980, in _wrap_create_connection
    return await self._loop.create_connection(*args, **kwargs)  # type: ignore[return-value]  # noqa
  File "D:\anaconda\envs\PBFT\lib\asyncio\base_events.py", line 948, in create_connection
    raise exceptions[0]
  File "D:\anaconda\envs\PBFT\lib\asyncio\base_events.py", line 935, in create_connection
    await self.sock_connect(sock, address)
  File "D:\anaconda\envs\PBFT\lib\asyncio\selector_events.py", line 475, in sock_connect
    return await fut
  File "D:\anaconda\envs\PBFT\lib\asyncio\selector_events.py", line 505, in _sock_connect_cb
    raise OSError(err, f'Connect call failed {address}')
ConnectionRefusedError: [Errno 10061] Connect call failed ('::1', 30103, 0, 0)

The above exception was the direct cause of the following exception:

Traceback (most recent call last):
  File "pbft.py", line 236, in send_message
    await send_with_delay(self.session, self.node_info, target, url, data, self.bandwidth_data)
  File "pbft.py", line 63, in send_with_delay
    async with session.post(url, json=data) as resp:
  File "D:\anaconda\envs\PBFT\lib\site-packages\aiohttp\client.py", line 1141, in __aenter__
    self._resp = await self._coro
  File "D:\anaconda\envs\PBFT\lib\site-packages\aiohttp\client.py", line 537, in _request
    req, traces=traces, timeout=real_timeout
  File "D:\anaconda\envs\PBFT\lib\site-packages\aiohttp\connector.py", line 540, in connect
    proto = await self._create_connection(req, traces, timeout)
  File "D:\anaconda\envs\PBFT\lib\site-packages\aiohttp\connector.py", line 901, in _create_connection
    _, proto = await self._create_direct_connection(req, traces, timeout)
  File "D:\anaconda\envs\PBFT\lib\site-packages\aiohttp\connector.py", line 1206, in _create_direct_connection
    raise last_exc
  File "D:\anaconda\envs\PBFT\lib\site-packages\aiohttp\connector.py", line 1187, in _create_direct_connection
    client_error=client_error,
  File "D:\anaconda\envs\PBFT\lib\site-packages\aiohttp\connector.py", line 988, in _wrap_create_connection
    raise client_error(req.connection_key, exc) from exc
aiohttp.client_exceptions.ClientConnectorError: Cannot connect to host localhost:30103 ssl:default [Connect call failed ('::1', 30103, 0, 0)]
[2025-03-07 13:53:55,472] [ERROR] [30130] Error sending to http://localhost:30027/commit: Cannot connect to host localhost:30027 ssl:default [Connect call failed ('::1', 30027, 0, 0)]
Traceback (most recent call last):
  File "D:\anaconda\envs\PBFT\lib\site-packages\aiohttp\connector.py", line 980, in _wrap_create_connection
    return await self._loop.create_connection(*args, **kwargs)  # type: ignore[return-value]  # noqa
  File "D:\anaconda\envs\PBFT\lib\asyncio\base_events.py", line 948, in create_connection
    raise exceptions[0]
  File "D:\anaconda\envs\PBFT\lib\asyncio\base_events.py", line 935, in create_connection
    await self.sock_connect(sock, address)
  File "D:\anaconda\envs\PBFT\lib\asyncio\selector_events.py", line 475, in sock_connect
    return await fut
  File "D:\anaconda\envs\PBFT\lib\asyncio\selector_events.py", line 505, in _sock_connect_cb
    raise OSError(err, f'Connect call failed {address}')
ConnectionRefusedError: [Errno 10061] Connect call failed ('::1', 30027, 0, 0)

The above exception was the direct cause of the following exception:

Traceback (most recent call last):
  File "pbft.py", line 236, in send_message
    await send_with_delay(self.session, self.node_info, target, url, data, self.bandwidth_data)
  File "pbft.py", line 63, in send_with_delay
    async with session.post(url, json=data) as resp:
  File "D:\anaconda\envs\PBFT\lib\site-packages\aiohttp\client.py", line 1141, in __aenter__
    self._resp = await self._coro
  File "D:\anaconda\envs\PBFT\lib\site-packages\aiohttp\client.py", line 537, in _request
    req, traces=traces, timeout=real_timeout
  File "D:\anaconda\envs\PBFT\lib\site-packages\aiohttp\connector.py", line 540, in connect
    proto = await self._create_connection(req, traces, timeout)
  File "D:\anaconda\envs\PBFT\lib\site-packages\aiohttp\connector.py", line 901, in _create_connection
    _, proto = await self._create_direct_connection(req, traces, timeout)
  File "D:\anaconda\envs\PBFT\lib\site-packages\aiohttp\connector.py", line 1206, in _create_direct_connection
    raise last_exc
  File "D:\anaconda\envs\PBFT\lib\site-packages\aiohttp\connector.py", line 1187, in _create_direct_connection
    client_error=client_error,
  File "D:\anaconda\envs\PBFT\lib\site-packages\aiohttp\connector.py", line 988, in _wrap_create_connection
    raise client_error(req.connection_key, exc) from exc
aiohttp.client_exceptions.ClientConnectorError: Cannot connect to host localhost:30027 ssl:default [Connect call failed ('::1', 30027, 0, 0)]
[2025-03-07 13:53:55,474] [ERROR] [30130] Error sending to http://localhost:30124/commit: Cannot connect to host localhost:30124 ssl:default [Connect call failed ('::1', 30124, 0, 0)]
Traceback (most recent call last):
  File "D:\anaconda\envs\PBFT\lib\site-packages\aiohttp\connector.py", line 980, in _wrap_create_connection
    return await self._loop.create_connection(*args, **kwargs)  # type: ignore[return-value]  # noqa
  File "D:\anaconda\envs\PBFT\lib\asyncio\base_events.py", line 948, in create_connection
    raise exceptions[0]
  File "D:\anaconda\envs\PBFT\lib\asyncio\base_events.py", line 935, in create_connection
    await self.sock_connect(sock, address)
  File "D:\anaconda\envs\PBFT\lib\asyncio\selector_events.py", line 475, in sock_connect
    return await fut
  File "D:\anaconda\envs\PBFT\lib\asyncio\selector_events.py", line 505, in _sock_connect_cb
    raise OSError(err, f'Connect call failed {address}')
ConnectionRefusedError: [Errno 10061] Connect call failed ('::1', 30124, 0, 0)

The above exception was the direct cause of the following exception:

Traceback (most recent call last):
  File "pbft.py", line 236, in send_message
    await send_with_delay(self.session, self.node_info, target, url, data, self.bandwidth_data)
  File "pbft.py", line 63, in send_with_delay
    async with session.post(url, json=data) as resp:
  File "D:\anaconda\envs\PBFT\lib\site-packages\aiohttp\client.py", line 1141, in __aenter__
    self._resp = await self._coro
  File "D:\anaconda\envs\PBFT\lib\site-packages\aiohttp\client.py", line 537, in _request
    req, traces=traces, timeout=real_timeout
  File "D:\anaconda\envs\PBFT\lib\site-packages\aiohttp\connector.py", line 540, in connect
    proto = await self._create_connection(req, traces, timeout)
  File "D:\anaconda\envs\PBFT\lib\site-packages\aiohttp\connector.py", line 901, in _create_connection
    _, proto = await self._create_direct_connection(req, traces, timeout)
  File "D:\anaconda\envs\PBFT\lib\site-packages\aiohttp\connector.py", line 1206, in _create_direct_connection
    raise last_exc
  File "D:\anaconda\envs\PBFT\lib\site-packages\aiohttp\connector.py", line 1187, in _create_direct_connection
    client_error=client_error,
  File "D:\anaconda\envs\PBFT\lib\site-packages\aiohttp\connector.py", line 988, in _wrap_create_connection
    raise client_error(req.connection_key, exc) from exc
aiohttp.client_exceptions.ClientConnectorError: Cannot connect to host localhost:30124 ssl:default [Connect call failed ('::1', 30124, 0, 0)]
[2025-03-07 13:53:55,474] [ERROR] [30130] Error sending to http://localhost:30093/prepare: Cannot connect to host localhost:30093 ssl:default [Connect call failed ('127.0.0.1', 30093)]
Traceback (most recent call last):
  File "D:\anaconda\envs\PBFT\lib\site-packages\aiohttp\connector.py", line 980, in _wrap_create_connection
    return await self._loop.create_connection(*args, **kwargs)  # type: ignore[return-value]  # noqa
  File "D:\anaconda\envs\PBFT\lib\asyncio\base_events.py", line 948, in create_connection
    raise exceptions[0]
  File "D:\anaconda\envs\PBFT\lib\asyncio\base_events.py", line 935, in create_connection
    await self.sock_connect(sock, address)
  File "D:\anaconda\envs\PBFT\lib\asyncio\selector_events.py", line 475, in sock_connect
    return await fut
  File "D:\anaconda\envs\PBFT\lib\asyncio\selector_events.py", line 505, in _sock_connect_cb
    raise OSError(err, f'Connect call failed {address}')
ConnectionRefusedError: [Errno 10061] Connect call failed ('127.0.0.1', 30093)

The above exception was the direct cause of the following exception:

Traceback (most recent call last):
  File "pbft.py", line 236, in send_message
    await send_with_delay(self.session, self.node_info, target, url, data, self.bandwidth_data)
  File "pbft.py", line 63, in send_with_delay
    async with session.post(url, json=data) as resp:
  File "D:\anaconda\envs\PBFT\lib\site-packages\aiohttp\client.py", line 1141, in __aenter__
    self._resp = await self._coro
  File "D:\anaconda\envs\PBFT\lib\site-packages\aiohttp\client.py", line 537, in _request
    req, traces=traces, timeout=real_timeout
  File "D:\anaconda\envs\PBFT\lib\site-packages\aiohttp\connector.py", line 540, in connect
    proto = await self._create_connection(req, traces, timeout)
  File "D:\anaconda\envs\PBFT\lib\site-packages\aiohttp\connector.py", line 901, in _create_connection
    _, proto = await self._create_direct_connection(req, traces, timeout)
  File "D:\anaconda\envs\PBFT\lib\site-packages\aiohttp\connector.py", line 1206, in _create_direct_connection
    raise last_exc
  File "D:\anaconda\envs\PBFT\lib\site-packages\aiohttp\connector.py", line 1187, in _create_direct_connection
    client_error=client_error,
  File "D:\anaconda\envs\PBFT\lib\site-packages\aiohttp\connector.py", line 988, in _wrap_create_connection
    raise client_error(req.connection_key, exc) from exc
aiohttp.client_exceptions.ClientConnectorError: Cannot connect to host localhost:30093 ssl:default [Connect call failed ('127.0.0.1', 30093)]
[2025-03-07 13:53:55,474] [ERROR] [30130] Error sending to http://localhost:30138/prepare: Cannot connect to host localhost:30138 ssl:default [Connect call failed ('127.0.0.1', 30138)]
Traceback (most recent call last):
  File "D:\anaconda\envs\PBFT\lib\site-packages\aiohttp\connector.py", line 980, in _wrap_create_connection
    return await self._loop.create_connection(*args, **kwargs)  # type: ignore[return-value]  # noqa
  File "D:\anaconda\envs\PBFT\lib\asyncio\base_events.py", line 948, in create_connection
    raise exceptions[0]
  File "D:\anaconda\envs\PBFT\lib\asyncio\base_events.py", line 935, in create_connection
    await self.sock_connect(sock, address)
  File "D:\anaconda\envs\PBFT\lib\asyncio\selector_events.py", line 475, in sock_connect
    return await fut
  File "D:\anaconda\envs\PBFT\lib\asyncio\selector_events.py", line 505, in _sock_connect_cb
    raise OSError(err, f'Connect call failed {address}')
ConnectionRefusedError: [Errno 10061] Connect call failed ('127.0.0.1', 30138)

The above exception was the direct cause of the following exception:

Traceback (most recent call last):
  File "pbft.py", line 236, in send_message
    await send_with_delay(self.session, self.node_info, target, url, data, self.bandwidth_data)
  File "pbft.py", line 63, in send_with_delay
    async with session.post(url, json=data) as resp:
  File "D:\anaconda\envs\PBFT\lib\site-packages\aiohttp\client.py", line 1141, in __aenter__
    self._resp = await self._coro
  File "D:\anaconda\envs\PBFT\lib\site-packages\aiohttp\client.py", line 537, in _request
    req, traces=traces, timeout=real_timeout
  File "D:\anaconda\envs\PBFT\lib\site-packages\aiohttp\connector.py", line 540, in connect
    proto = await self._create_connection(req, traces, timeout)
  File "D:\anaconda\envs\PBFT\lib\site-packages\aiohttp\connector.py", line 901, in _create_connection
    _, proto = await self._create_direct_connection(req, traces, timeout)
  File "D:\anaconda\envs\PBFT\lib\site-packages\aiohttp\connector.py", line 1206, in _create_direct_connection
    raise last_exc
  File "D:\anaconda\envs\PBFT\lib\site-packages\aiohttp\connector.py", line 1187, in _create_direct_connection
    client_error=client_error,
  File "D:\anaconda\envs\PBFT\lib\site-packages\aiohttp\connector.py", line 988, in _wrap_create_connection
    raise client_error(req.connection_key, exc) from exc
aiohttp.client_exceptions.ClientConnectorError: Cannot connect to host localhost:30138 ssl:default [Connect call failed ('127.0.0.1', 30138)]
[2025-03-07 13:53:55,477] [ERROR] [30130] Error sending to http://localhost:30085/commit: Cannot connect to host localhost:30085 ssl:default [Connect call failed ('::1', 30085, 0, 0)]
Traceback (most recent call last):
  File "D:\anaconda\envs\PBFT\lib\site-packages\aiohttp\connector.py", line 980, in _wrap_create_connection
    return await self._loop.create_connection(*args, **kwargs)  # type: ignore[return-value]  # noqa
  File "D:\anaconda\envs\PBFT\lib\asyncio\base_events.py", line 948, in create_connection
    raise exceptions[0]
  File "D:\anaconda\envs\PBFT\lib\asyncio\base_events.py", line 935, in create_connection
    await self.sock_connect(sock, address)
  File "D:\anaconda\envs\PBFT\lib\asyncio\selector_events.py", line 475, in sock_connect
    return await fut
  File "D:\anaconda\envs\PBFT\lib\asyncio\selector_events.py", line 505, in _sock_connect_cb
    raise OSError(err, f'Connect call failed {address}')
ConnectionRefusedError: [Errno 10061] Connect call failed ('::1', 30085, 0, 0)

The above exception was the direct cause of the following exception:

Traceback (most recent call last):
  File "pbft.py", line 236, in send_message
    await send_with_delay(self.session, self.node_info, target, url, data, self.bandwidth_data)
  File "pbft.py", line 63, in send_with_delay
    async with session.post(url, json=data) as resp:
  File "D:\anaconda\envs\PBFT\lib\site-packages\aiohttp\client.py", line 1141, in __aenter__
    self._resp = await self._coro
  File "D:\anaconda\envs\PBFT\lib\site-packages\aiohttp\client.py", line 537, in _request
    req, traces=traces, timeout=real_timeout
  File "D:\anaconda\envs\PBFT\lib\site-packages\aiohttp\connector.py", line 540, in connect
    proto = await self._create_connection(req, traces, timeout)
  File "D:\anaconda\envs\PBFT\lib\site-packages\aiohttp\connector.py", line 901, in _create_connection
    _, proto = await self._create_direct_connection(req, traces, timeout)
  File "D:\anaconda\envs\PBFT\lib\site-packages\aiohttp\connector.py", line 1206, in _create_direct_connection
    raise last_exc
  File "D:\anaconda\envs\PBFT\lib\site-packages\aiohttp\connector.py", line 1187, in _create_direct_connection
    client_error=client_error,
  File "D:\anaconda\envs\PBFT\lib\site-packages\aiohttp\connector.py", line 988, in _wrap_create_connection
    raise client_error(req.connection_key, exc) from exc
aiohttp.client_exceptions.ClientConnectorError: Cannot connect to host localhost:30085 ssl:default [Connect call failed ('::1', 30085, 0, 0)]
[2025-03-07 13:53:55,477] [ERROR] [30130] Error sending to http://localhost:30025/commit: Cannot connect to host localhost:30025 ssl:default [Connect call failed ('::1', 30025, 0, 0)]
Traceback (most recent call last):
  File "D:\anaconda\envs\PBFT\lib\site-packages\aiohttp\connector.py", line 980, in _wrap_create_connection
    return await self._loop.create_connection(*args, **kwargs)  # type: ignore[return-value]  # noqa
  File "D:\anaconda\envs\PBFT\lib\asyncio\base_events.py", line 948, in create_connection
    raise exceptions[0]
  File "D:\anaconda\envs\PBFT\lib\asyncio\base_events.py", line 935, in create_connection
    await self.sock_connect(sock, address)
  File "D:\anaconda\envs\PBFT\lib\asyncio\selector_events.py", line 475, in sock_connect
    return await fut
  File "D:\anaconda\envs\PBFT\lib\asyncio\selector_events.py", line 505, in _sock_connect_cb
    raise OSError(err, f'Connect call failed {address}')
ConnectionRefusedError: [Errno 10061] Connect call failed ('::1', 30025, 0, 0)

The above exception was the direct cause of the following exception:

Traceback (most recent call last):
  File "pbft.py", line 236, in send_message
    await send_with_delay(self.session, self.node_info, target, url, data, self.bandwidth_data)
  File "pbft.py", line 63, in send_with_delay
    async with session.post(url, json=data) as resp:
  File "D:\anaconda\envs\PBFT\lib\site-packages\aiohttp\client.py", line 1141, in __aenter__
    self._resp = await self._coro
  File "D:\anaconda\envs\PBFT\lib\site-packages\aiohttp\client.py", line 537, in _request
    req, traces=traces, timeout=real_timeout
  File "D:\anaconda\envs\PBFT\lib\site-packages\aiohttp\connector.py", line 540, in connect
    proto = await self._create_connection(req, traces, timeout)
  File "D:\anaconda\envs\PBFT\lib\site-packages\aiohttp\connector.py", line 901, in _create_connection
    _, proto = await self._create_direct_connection(req, traces, timeout)
  File "D:\anaconda\envs\PBFT\lib\site-packages\aiohttp\connector.py", line 1206, in _create_direct_connection
    raise last_exc
  File "D:\anaconda\envs\PBFT\lib\site-packages\aiohttp\connector.py", line 1187, in _create_direct_connection
    client_error=client_error,
  File "D:\anaconda\envs\PBFT\lib\site-packages\aiohttp\connector.py", line 988, in _wrap_create_connection
    raise client_error(req.connection_key, exc) from exc
aiohttp.client_exceptions.ClientConnectorError: Cannot connect to host localhost:30025 ssl:default [Connect call failed ('::1', 30025, 0, 0)]
[2025-03-07 13:53:55,477] [ERROR] [30130] Error sending to http://localhost:30066/commit: Cannot connect to host localhost:30066 ssl:default [Connect call failed ('::1', 30066, 0, 0)]
Traceback (most recent call last):
  File "D:\anaconda\envs\PBFT\lib\site-packages\aiohttp\connector.py", line 980, in _wrap_create_connection
    return await self._loop.create_connection(*args, **kwargs)  # type: ignore[return-value]  # noqa
  File "D:\anaconda\envs\PBFT\lib\asyncio\base_events.py", line 948, in create_connection
    raise exceptions[0]
  File "D:\anaconda\envs\PBFT\lib\asyncio\base_events.py", line 935, in create_connection
    await self.sock_connect(sock, address)
  File "D:\anaconda\envs\PBFT\lib\asyncio\selector_events.py", line 475, in sock_connect
    return await fut
  File "D:\anaconda\envs\PBFT\lib\asyncio\selector_events.py", line 505, in _sock_connect_cb
    raise OSError(err, f'Connect call failed {address}')
ConnectionRefusedError: [Errno 10061] Connect call failed ('::1', 30066, 0, 0)

The above exception was the direct cause of the following exception:

Traceback (most recent call last):
  File "pbft.py", line 236, in send_message
    await send_with_delay(self.session, self.node_info, target, url, data, self.bandwidth_data)
  File "pbft.py", line 63, in send_with_delay
    async with session.post(url, json=data) as resp:
  File "D:\anaconda\envs\PBFT\lib\site-packages\aiohttp\client.py", line 1141, in __aenter__
    self._resp = await self._coro
  File "D:\anaconda\envs\PBFT\lib\site-packages\aiohttp\client.py", line 537, in _request
    req, traces=traces, timeout=real_timeout
  File "D:\anaconda\envs\PBFT\lib\site-packages\aiohttp\connector.py", line 540, in connect
    proto = await self._create_connection(req, traces, timeout)
  File "D:\anaconda\envs\PBFT\lib\site-packages\aiohttp\connector.py", line 901, in _create_connection
    _, proto = await self._create_direct_connection(req, traces, timeout)
  File "D:\anaconda\envs\PBFT\lib\site-packages\aiohttp\connector.py", line 1206, in _create_direct_connection
    raise last_exc
  File "D:\anaconda\envs\PBFT\lib\site-packages\aiohttp\connector.py", line 1187, in _create_direct_connection
    client_error=client_error,
  File "D:\anaconda\envs\PBFT\lib\site-packages\aiohttp\connector.py", line 988, in _wrap_create_connection
    raise client_error(req.connection_key, exc) from exc
aiohttp.client_exceptions.ClientConnectorError: Cannot connect to host localhost:30066 ssl:default [Connect call failed ('::1', 30066, 0, 0)]
[2025-03-07 13:53:55,477] [ERROR] [30130] Error sending to http://localhost:30093/commit: Cannot connect to host localhost:30093 ssl:default [Connect call failed ('::1', 30093, 0, 0)]
Traceback (most recent call last):
  File "D:\anaconda\envs\PBFT\lib\site-packages\aiohttp\connector.py", line 980, in _wrap_create_connection
    return await self._loop.create_connection(*args, **kwargs)  # type: ignore[return-value]  # noqa
  File "D:\anaconda\envs\PBFT\lib\asyncio\base_events.py", line 948, in create_connection
    raise exceptions[0]
  File "D:\anaconda\envs\PBFT\lib\asyncio\base_events.py", line 935, in create_connection
    await self.sock_connect(sock, address)
  File "D:\anaconda\envs\PBFT\lib\asyncio\selector_events.py", line 475, in sock_connect
    return await fut
  File "D:\anaconda\envs\PBFT\lib\asyncio\selector_events.py", line 505, in _sock_connect_cb
    raise OSError(err, f'Connect call failed {address}')
ConnectionRefusedError: [Errno 10061] Connect call failed ('::1', 30093, 0, 0)

The above exception was the direct cause of the following exception:

Traceback (most recent call last):
  File "pbft.py", line 236, in send_message
    await send_with_delay(self.session, self.node_info, target, url, data, self.bandwidth_data)
  File "pbft.py", line 63, in send_with_delay
    async with session.post(url, json=data) as resp:
  File "D:\anaconda\envs\PBFT\lib\site-packages\aiohttp\client.py", line 1141, in __aenter__
    self._resp = await self._coro
  File "D:\anaconda\envs\PBFT\lib\site-packages\aiohttp\client.py", line 537, in _request
    req, traces=traces, timeout=real_timeout
  File "D:\anaconda\envs\PBFT\lib\site-packages\aiohttp\connector.py", line 540, in connect
    proto = await self._create_connection(req, traces, timeout)
  File "D:\anaconda\envs\PBFT\lib\site-packages\aiohttp\connector.py", line 901, in _create_connection
    _, proto = await self._create_direct_connection(req, traces, timeout)
  File "D:\anaconda\envs\PBFT\lib\site-packages\aiohttp\connector.py", line 1206, in _create_direct_connection
    raise last_exc
  File "D:\anaconda\envs\PBFT\lib\site-packages\aiohttp\connector.py", line 1187, in _create_direct_connection
    client_error=client_error,
  File "D:\anaconda\envs\PBFT\lib\site-packages\aiohttp\connector.py", line 988, in _wrap_create_connection
    raise client_error(req.connection_key, exc) from exc
aiohttp.client_exceptions.ClientConnectorError: Cannot connect to host localhost:30093 ssl:default [Connect call failed ('::1', 30093, 0, 0)]
[2025-03-07 13:53:55,477] [ERROR] [30130] Error sending to http://localhost:30141/commit: Cannot connect to host localhost:30141 ssl:default [Connect call failed ('::1', 30141, 0, 0)]
Traceback (most recent call last):
  File "D:\anaconda\envs\PBFT\lib\site-packages\aiohttp\connector.py", line 980, in _wrap_create_connection
    return await self._loop.create_connection(*args, **kwargs)  # type: ignore[return-value]  # noqa
  File "D:\anaconda\envs\PBFT\lib\asyncio\base_events.py", line 948, in create_connection
    raise exceptions[0]
  File "D:\anaconda\envs\PBFT\lib\asyncio\base_events.py", line 935, in create_connection
    await self.sock_connect(sock, address)
  File "D:\anaconda\envs\PBFT\lib\asyncio\selector_events.py", line 475, in sock_connect
    return await fut
  File "D:\anaconda\envs\PBFT\lib\asyncio\selector_events.py", line 505, in _sock_connect_cb
    raise OSError(err, f'Connect call failed {address}')
ConnectionRefusedError: [Errno 10061] Connect call failed ('::1', 30141, 0, 0)

The above exception was the direct cause of the following exception:

Traceback (most recent call last):
  File "pbft.py", line 236, in send_message
    await send_with_delay(self.session, self.node_info, target, url, data, self.bandwidth_data)
  File "pbft.py", line 63, in send_with_delay
    async with session.post(url, json=data) as resp:
  File "D:\anaconda\envs\PBFT\lib\site-packages\aiohttp\client.py", line 1141, in __aenter__
    self._resp = await self._coro
  File "D:\anaconda\envs\PBFT\lib\site-packages\aiohttp\client.py", line 537, in _request
    req, traces=traces, timeout=real_timeout
  File "D:\anaconda\envs\PBFT\lib\site-packages\aiohttp\connector.py", line 540, in connect
    proto = await self._create_connection(req, traces, timeout)
  File "D:\anaconda\envs\PBFT\lib\site-packages\aiohttp\connector.py", line 901, in _create_connection
    _, proto = await self._create_direct_connection(req, traces, timeout)
  File "D:\anaconda\envs\PBFT\lib\site-packages\aiohttp\connector.py", line 1206, in _create_direct_connection
    raise last_exc
  File "D:\anaconda\envs\PBFT\lib\site-packages\aiohttp\connector.py", line 1187, in _create_direct_connection
    client_error=client_error,
  File "D:\anaconda\envs\PBFT\lib\site-packages\aiohttp\connector.py", line 988, in _wrap_create_connection
    raise client_error(req.connection_key, exc) from exc
aiohttp.client_exceptions.ClientConnectorError: Cannot connect to host localhost:30141 ssl:default [Connect call failed ('::1', 30141, 0, 0)]
[2025-03-07 13:53:55,484] [ERROR] [30130] Error sending to http://localhost:30138/commit: Cannot connect to host localhost:30138 ssl:default [Connect call failed ('::1', 30138, 0, 0)]
Traceback (most recent call last):
  File "D:\anaconda\envs\PBFT\lib\site-packages\aiohttp\connector.py", line 980, in _wrap_create_connection
    return await self._loop.create_connection(*args, **kwargs)  # type: ignore[return-value]  # noqa
  File "D:\anaconda\envs\PBFT\lib\asyncio\base_events.py", line 948, in create_connection
    raise exceptions[0]
  File "D:\anaconda\envs\PBFT\lib\asyncio\base_events.py", line 935, in create_connection
    await self.sock_connect(sock, address)
  File "D:\anaconda\envs\PBFT\lib\asyncio\selector_events.py", line 475, in sock_connect
    return await fut
  File "D:\anaconda\envs\PBFT\lib\asyncio\selector_events.py", line 505, in _sock_connect_cb
    raise OSError(err, f'Connect call failed {address}')
ConnectionRefusedError: [Errno 10061] Connect call failed ('::1', 30138, 0, 0)

The above exception was the direct cause of the following exception:

Traceback (most recent call last):
  File "pbft.py", line 236, in send_message
    await send_with_delay(self.session, self.node_info, target, url, data, self.bandwidth_data)
  File "pbft.py", line 63, in send_with_delay
    async with session.post(url, json=data) as resp:
  File "D:\anaconda\envs\PBFT\lib\site-packages\aiohttp\client.py", line 1141, in __aenter__
    self._resp = await self._coro
  File "D:\anaconda\envs\PBFT\lib\site-packages\aiohttp\client.py", line 537, in _request
    req, traces=traces, timeout=real_timeout
  File "D:\anaconda\envs\PBFT\lib\site-packages\aiohttp\connector.py", line 540, in connect
    proto = await self._create_connection(req, traces, timeout)
  File "D:\anaconda\envs\PBFT\lib\site-packages\aiohttp\connector.py", line 901, in _create_connection
    _, proto = await self._create_direct_connection(req, traces, timeout)
  File "D:\anaconda\envs\PBFT\lib\site-packages\aiohttp\connector.py", line 1206, in _create_direct_connection
    raise last_exc
  File "D:\anaconda\envs\PBFT\lib\site-packages\aiohttp\connector.py", line 1187, in _create_direct_connection
    client_error=client_error,
  File "D:\anaconda\envs\PBFT\lib\site-packages\aiohttp\connector.py", line 988, in _wrap_create_connection
    raise client_error(req.connection_key, exc) from exc
aiohttp.client_exceptions.ClientConnectorError: Cannot connect to host localhost:30138 ssl:default [Connect call failed ('::1', 30138, 0, 0)]
[2025-03-07 13:53:55,485] [ERROR] [30130] Error sending to http://localhost:30140/commit: Cannot connect to host localhost:30140 ssl:default [Connect call failed ('::1', 30140, 0, 0)]
Traceback (most recent call last):
  File "D:\anaconda\envs\PBFT\lib\site-packages\aiohttp\connector.py", line 980, in _wrap_create_connection
    return await self._loop.create_connection(*args, **kwargs)  # type: ignore[return-value]  # noqa
  File "D:\anaconda\envs\PBFT\lib\asyncio\base_events.py", line 948, in create_connection
    raise exceptions[0]
  File "D:\anaconda\envs\PBFT\lib\asyncio\base_events.py", line 935, in create_connection
    await self.sock_connect(sock, address)
  File "D:\anaconda\envs\PBFT\lib\asyncio\selector_events.py", line 475, in sock_connect
    return await fut
  File "D:\anaconda\envs\PBFT\lib\asyncio\selector_events.py", line 505, in _sock_connect_cb
    raise OSError(err, f'Connect call failed {address}')
ConnectionRefusedError: [Errno 10061] Connect call failed ('::1', 30140, 0, 0)

The above exception was the direct cause of the following exception:

Traceback (most recent call last):
  File "pbft.py", line 236, in send_message
    await send_with_delay(self.session, self.node_info, target, url, data, self.bandwidth_data)
  File "pbft.py", line 63, in send_with_delay
    async with session.post(url, json=data) as resp:
  File "D:\anaconda\envs\PBFT\lib\site-packages\aiohttp\client.py", line 1141, in __aenter__
    self._resp = await self._coro
  File "D:\anaconda\envs\PBFT\lib\site-packages\aiohttp\client.py", line 537, in _request
    req, traces=traces, timeout=real_timeout
  File "D:\anaconda\envs\PBFT\lib\site-packages\aiohttp\connector.py", line 540, in connect
    proto = await self._create_connection(req, traces, timeout)
  File "D:\anaconda\envs\PBFT\lib\site-packages\aiohttp\connector.py", line 901, in _create_connection
    _, proto = await self._create_direct_connection(req, traces, timeout)
  File "D:\anaconda\envs\PBFT\lib\site-packages\aiohttp\connector.py", line 1206, in _create_direct_connection
    raise last_exc
  File "D:\anaconda\envs\PBFT\lib\site-packages\aiohttp\connector.py", line 1187, in _create_direct_connection
    client_error=client_error,
  File "D:\anaconda\envs\PBFT\lib\site-packages\aiohttp\connector.py", line 988, in _wrap_create_connection
    raise client_error(req.connection_key, exc) from exc
aiohttp.client_exceptions.ClientConnectorError: Cannot connect to host localhost:30140 ssl:default [Connect call failed ('::1', 30140, 0, 0)]
[2025-03-07 13:53:55,485] [ERROR] [30130] Error sending to http://localhost:30125/commit: Cannot connect to host localhost:30125 ssl:default [Connect call failed ('::1', 30125, 0, 0)]
Traceback (most recent call last):
  File "D:\anaconda\envs\PBFT\lib\site-packages\aiohttp\connector.py", line 980, in _wrap_create_connection
    return await self._loop.create_connection(*args, **kwargs)  # type: ignore[return-value]  # noqa
  File "D:\anaconda\envs\PBFT\lib\asyncio\base_events.py", line 948, in create_connection
    raise exceptions[0]
  File "D:\anaconda\envs\PBFT\lib\asyncio\base_events.py", line 935, in create_connection
    await self.sock_connect(sock, address)
  File "D:\anaconda\envs\PBFT\lib\asyncio\selector_events.py", line 475, in sock_connect
    return await fut
  File "D:\anaconda\envs\PBFT\lib\asyncio\selector_events.py", line 505, in _sock_connect_cb
    raise OSError(err, f'Connect call failed {address}')
ConnectionRefusedError: [Errno 10061] Connect call failed ('::1', 30125, 0, 0)

The above exception was the direct cause of the following exception:

Traceback (most recent call last):
  File "pbft.py", line 236, in send_message
    await send_with_delay(self.session, self.node_info, target, url, data, self.bandwidth_data)
  File "pbft.py", line 63, in send_with_delay
    async with session.post(url, json=data) as resp:
  File "D:\anaconda\envs\PBFT\lib\site-packages\aiohttp\client.py", line 1141, in __aenter__
    self._resp = await self._coro
  File "D:\anaconda\envs\PBFT\lib\site-packages\aiohttp\client.py", line 537, in _request
    req, traces=traces, timeout=real_timeout
  File "D:\anaconda\envs\PBFT\lib\site-packages\aiohttp\connector.py", line 540, in connect
    proto = await self._create_connection(req, traces, timeout)
  File "D:\anaconda\envs\PBFT\lib\site-packages\aiohttp\connector.py", line 901, in _create_connection
    _, proto = await self._create_direct_connection(req, traces, timeout)
  File "D:\anaconda\envs\PBFT\lib\site-packages\aiohttp\connector.py", line 1206, in _create_direct_connection
    raise last_exc
  File "D:\anaconda\envs\PBFT\lib\site-packages\aiohttp\connector.py", line 1187, in _create_direct_connection
    client_error=client_error,
  File "D:\anaconda\envs\PBFT\lib\site-packages\aiohttp\connector.py", line 988, in _wrap_create_connection
    raise client_error(req.connection_key, exc) from exc
aiohttp.client_exceptions.ClientConnectorError: Cannot connect to host localhost:30125 ssl:default [Connect call failed ('::1', 30125, 0, 0)]
[2025-03-07 13:53:55,485] [ERROR] [30130] Error sending to http://localhost:30023/commit: Cannot connect to host localhost:30023 ssl:default [Connect call failed ('::1', 30023, 0, 0)]
Traceback (most recent call last):
  File "D:\anaconda\envs\PBFT\lib\site-packages\aiohttp\connector.py", line 980, in _wrap_create_connection
    return await self._loop.create_connection(*args, **kwargs)  # type: ignore[return-value]  # noqa
  File "D:\anaconda\envs\PBFT\lib\asyncio\base_events.py", line 948, in create_connection
    raise exceptions[0]
  File "D:\anaconda\envs\PBFT\lib\asyncio\base_events.py", line 935, in create_connection
    await self.sock_connect(sock, address)
  File "D:\anaconda\envs\PBFT\lib\asyncio\selector_events.py", line 475, in sock_connect
    return await fut
  File "D:\anaconda\envs\PBFT\lib\asyncio\selector_events.py", line 505, in _sock_connect_cb
    raise OSError(err, f'Connect call failed {address}')
ConnectionRefusedError: [Errno 10061] Connect call failed ('::1', 30023, 0, 0)

The above exception was the direct cause of the following exception:

Traceback (most recent call last):
  File "pbft.py", line 236, in send_message
    await send_with_delay(self.session, self.node_info, target, url, data, self.bandwidth_data)
  File "pbft.py", line 63, in send_with_delay
    async with session.post(url, json=data) as resp:
  File "D:\anaconda\envs\PBFT\lib\site-packages\aiohttp\client.py", line 1141, in __aenter__
    self._resp = await self._coro
  File "D:\anaconda\envs\PBFT\lib\site-packages\aiohttp\client.py", line 537, in _request
    req, traces=traces, timeout=real_timeout
  File "D:\anaconda\envs\PBFT\lib\site-packages\aiohttp\connector.py", line 540, in connect
    proto = await self._create_connection(req, traces, timeout)
  File "D:\anaconda\envs\PBFT\lib\site-packages\aiohttp\connector.py", line 901, in _create_connection
    _, proto = await self._create_direct_connection(req, traces, timeout)
  File "D:\anaconda\envs\PBFT\lib\site-packages\aiohttp\connector.py", line 1206, in _create_direct_connection
    raise last_exc
  File "D:\anaconda\envs\PBFT\lib\site-packages\aiohttp\connector.py", line 1187, in _create_direct_connection
    client_error=client_error,
  File "D:\anaconda\envs\PBFT\lib\site-packages\aiohttp\connector.py", line 988, in _wrap_create_connection
    raise client_error(req.connection_key, exc) from exc
aiohttp.client_exceptions.ClientConnectorError: Cannot connect to host localhost:30023 ssl:default [Connect call failed ('::1', 30023, 0, 0)]
[2025-03-07 13:53:55,488] [INFO] [30130] Received PREPARE: id:1741323218379, from:30152, delay:0.0002s, distance:269.20m (Euclidean)
[2025-03-07 13:53:55,488] [INFO] [30130] Received PREPARE: id:1741323218379, from:30132, delay:0.0002s, distance:263.64m (Euclidean)
[2025-03-07 13:53:55,488] [INFO] [30130] Received PREPARE: id:1741323218379, from:30120, delay:0.0001s, distance:167.27m (Euclidean)
[2025-03-07 13:53:55,488] [INFO] [30130] Received PREPARE: id:1741323218379, from:30145, delay:0.0002s, distance:262.79m (Euclidean)
[2025-03-07 13:53:55,488] [INFO] [30130] Received PREPARE: id:1741323218379, from:30146, delay:0.0002s, distance:256.53m (Euclidean)
[2025-03-07 13:53:55,490] [INFO] [30130] Received COMMIT: id:1741323218379, from:30108, delay:0.0002s, distance:282.27m (Euclidean)
[2025-03-07 13:53:55,490] [INFO] [30130] Received PREPARE: id:1741323218379, from:30108, delay:0.0002s, distance:282.27m (Euclidean)
[2025-03-07 13:53:55,490] [INFO] [30130] Received COMMIT: id:1741323218379, from:30156, delay:0.0001s, distance:245.40m (Euclidean)
[2025-03-07 13:53:55,490] [INFO] [30130] Received PREPARE: id:1741323218379, from:30115, delay:0.0001s, distance:203.42m (Euclidean)
[2025-03-07 13:53:55,490] [INFO] [30130] Received COMMIT: id:1741323218379, from:30146, delay:0.0002s, distance:256.53m (Euclidean)
[2025-03-07 13:53:55,490] [INFO] [30130] Received COMMIT: id:1741323218379, from:30132, delay:0.0002s, distance:263.64m (Euclidean)
[2025-03-07 13:53:55,490] [INFO] [30130] Received PREPARE: id:1741323218379, from:30156, delay:0.0001s, distance:245.40m (Euclidean)
[2025-03-07 13:53:55,490] [INFO] [30130] Received COMMIT: id:1741323218379, from:30145, delay:0.0002s, distance:262.79m (Euclidean)
[2025-03-07 13:53:55,490] [INFO] [30130] Received COMMIT: id:1741323218379, from:30120, delay:0.0001s, distance:167.27m (Euclidean)
[2025-03-07 13:53:55,490] [INFO] [30130] Received COMMIT: id:1741323218379, from:30152, delay:0.0002s, distance:269.20m (Euclidean)
[2025-03-07 13:53:55,490] [INFO] [30130] Received COMMIT: id:1741323218379, from:30115, delay:0.0001s, distance:203.42m (Euclidean)
[2025-03-07 13:53:55,658] [INFO] [30130] Received PREPARE: id:1741323218379, from:30022, delay:0.0002s, distance:264.39m (Euclidean)
[2025-03-07 13:53:55,669] [INFO] [30130] Received COMMIT: id:1741323218379, from:30022, delay:0.0002s, distance:264.39m (Euclidean)
[2025-03-07 13:54:53,860] [INFO] Starting node at localhost:30130 | index=131 | f=1, k=4 | Role: Replica
[2025-03-07 13:57:40,308] [INFO] Starting node at localhost:30130 | index=131 | f=1, k=4 | Role: Replica
[2025-03-07 13:58:42,729] [INFO] Starting node at localhost:30130 | index=131 | f=1, k=4 | Role: Replica
[2025-03-07 13:59:02,613] [INFO] [30130] Received PRE-PREPARE: id:1741323542381, from:Leader(30000), delay:0.0000s, distance:122.82m (Euclidean)
[2025-03-07 13:59:02,613] [INFO] [30130] Broadcasting PREPARE for REQUEST 1741323542381
[2025-03-07 13:59:02,625] [INFO] [30130] Not broadcasting to fault node: 30077
[2025-03-07 13:59:02,664] [INFO] [30130] Not broadcasting to fault node: 30184
[2025-03-07 13:59:03,090] [INFO] [30130] Received PREPARE: id:1741323542381, from:30092, delay:0.0000s, distance:100.66m (Euclidean)
[2025-03-07 13:59:03,501] [INFO] [30130] Received PREPARE: id:1741323542381, from:30133, delay:0.0000s, distance:104.54m (Euclidean)
[2025-03-07 13:59:03,501] [INFO] [30130] Broadcasting COMMIT for REQUEST 1741323542381
[2025-03-07 13:59:03,513] [INFO] [30130] Not broadcasting to fault node: 30077
[2025-03-07 13:59:03,538] [INFO] [30130] Not broadcasting to fault node: 30184
[2025-03-07 13:59:03,734] [INFO] [30130] Received COMMIT: id:1741323542381, from:30092, delay:0.0000s, distance:100.66m (Euclidean)
[2025-03-07 13:59:03,913] [INFO] [30130] Received PREPARE: id:1741323542381, from:30115, delay:0.0000s, distance:76.11m (Euclidean)
[2025-03-07 13:59:03,915] [INFO] [30130] Received COMMIT: id:1741323542381, from:30133, delay:0.0000s, distance:104.54m (Euclidean)
[2025-03-07 13:59:03,917] [INFO] [LEADER 30130] Sending REPLY for REQUEST 1741323542381 to CLIENT
[2025-03-07 13:59:04,014] [INFO] [30130] Received PREPARE: id:1741323542381, from:30095, delay:0.0001s, distance:169.15m (Euclidean)
[2025-03-07 13:59:04,067] [INFO] [30130] Received PREPARE: id:1741323542381, from:30089, delay:0.0000s, distance:106.92m (Euclidean)
[2025-03-07 13:59:04,088] [INFO] [30130] Received PREPARE: id:1741323542381, from:30074, delay:0.0001s, distance:166.78m (Euclidean)
[2025-03-07 13:59:04,088] [INFO] [30130] Received PREPARE: id:1741323542381, from:30127, delay:0.0000s, distance:85.72m (Euclidean)
[2025-03-07 13:59:04,113] [INFO] [30130] Received PREPARE: id:1741323542381, from:30013, delay:0.0000s, distance:134.54m (Euclidean)
[2025-03-07 13:59:04,162] [INFO] [30130] Received PREPARE: id:1741323542381, from:30007, delay:0.0000s, distance:125.17m (Euclidean)
[2025-03-07 13:59:04,197] [INFO] [30130] Received COMMIT: id:1741323542381, from:30127, delay:0.0000s, distance:85.72m (Euclidean)
[2025-03-07 13:59:04,329] [INFO] [30130] Received COMMIT: id:1741323542381, from:30102, delay:0.0000s, distance:153.53m (Euclidean)
[2025-03-07 13:59:04,329] [INFO] [30130] Received PREPARE: id:1741323542381, from:30102, delay:0.0000s, distance:153.53m (Euclidean)
[2025-03-07 13:59:04,329] [INFO] [30130] Received PREPARE: id:1741323542381, from:30093, delay:0.0000s, distance:60.00m (Euclidean)
[2025-03-07 13:59:04,331] [INFO] [30130] Received PREPARE: id:1741323542381, from:30155, delay:0.0002s, distance:292.67m (Euclidean)
[2025-03-07 13:59:04,340] [INFO] [30130] Received PREPARE: id:1741323542381, from:30046, delay:0.0000s, distance:90.53m (Euclidean)
[2025-03-07 13:59:04,584] [INFO] [30130] Received PREPARE: id:1741323542381, from:30037, delay:0.0001s, distance:195.87m (Euclidean)
[2025-03-07 13:59:04,597] [INFO] [30130] Received PREPARE: id:1741323542381, from:30057, delay:0.0000s, distance:119.94m (Euclidean)
[2025-03-07 13:59:04,597] [INFO] [30130] Received PREPARE: id:1741323542381, from:30169, delay:0.0001s, distance:223.62m (Euclidean)
[2025-03-07 13:59:04,616] [INFO] [30130] Received COMMIT: id:1741323542381, from:30057, delay:0.0000s, distance:119.94m (Euclidean)
[2025-03-07 13:59:04,616] [INFO] [30130] Received COMMIT: id:1741323542381, from:30169, delay:0.0001s, distance:223.62m (Euclidean)
[2025-03-07 13:59:04,618] [INFO] [30130] Received PREPARE: id:1741323542381, from:30106, delay:0.0000s, distance:75.36m (Euclidean)
[2025-03-07 13:59:04,679] [INFO] [30130] Received COMMIT: id:1741323542381, from:30007, delay:0.0000s, distance:125.17m (Euclidean)
[2025-03-07 13:59:04,681] [INFO] [30130] Received COMMIT: id:1741323542381, from:30115, delay:0.0000s, distance:76.11m (Euclidean)
[2025-03-07 13:59:04,728] [INFO] [30130] Received COMMIT: id:1741323542381, from:30155, delay:0.0002s, distance:292.67m (Euclidean)
[2025-03-07 13:59:04,836] [INFO] [30130] Received PREPARE: id:1741323542381, from:30147, delay:0.0001s, distance:203.15m (Euclidean)
[2025-03-07 13:59:04,859] [INFO] [30130] Received PREPARE: id:1741323542381, from:30128, delay:0.0002s, distance:277.87m (Euclidean)
[2025-03-07 13:59:05,284] [INFO] [30130] Received COMMIT: id:1741323542381, from:30128, delay:0.0002s, distance:277.87m (Euclidean)
[2025-03-07 13:59:05,286] [INFO] [30130] Received PREPARE: id:1741323542381, from:30181, delay:0.0000s, distance:112.13m (Euclidean)
[2025-03-07 13:59:05,286] [INFO] [30130] Received PREPARE: id:1741323542381, from:30060, delay:0.0000s, distance:45.45m (Euclidean)
[2025-03-07 13:59:05,385] [INFO] [30130] Received PREPARE: id:1741323542381, from:30029, delay:0.0001s, distance:190.73m (Euclidean)
[2025-03-07 13:59:05,647] [INFO] [30130] Received PREPARE: id:1741323542381, from:30025, delay:0.0000s, distance:109.53m (Euclidean)
[2025-03-07 13:59:05,647] [INFO] [30130] Received PREPARE: id:1741323542381, from:30157, delay:0.0000s, distance:46.16m (Euclidean)
[2025-03-07 13:59:05,650] [INFO] [30130] Received COMMIT: id:1741323542381, from:30121, delay:0.0000s, distance:125.76m (Euclidean)
[2025-03-07 13:59:05,650] [INFO] [30130] Received PREPARE: id:1741323542381, from:30035, delay:0.0001s, distance:186.89m (Euclidean)
[2025-03-07 13:59:05,650] [INFO] [30130] Received PREPARE: id:1741323542381, from:30149, delay:0.0000s, distance:171.43m (Euclidean)
[2025-03-07 13:59:05,650] [INFO] [30130] Received PREPARE: id:1741323542381, from:30121, delay:0.0000s, distance:125.76m (Euclidean)
[2025-03-07 13:59:05,651] [INFO] [30130] Received PREPARE: id:1741323542381, from:30053, delay:0.0000s, distance:139.59m (Euclidean)
[2025-03-07 13:59:05,651] [INFO] [30130] Received PREPARE: id:1741323542381, from:30174, delay:0.0001s, distance:173.53m (Euclidean)
[2025-03-07 13:59:05,749] [INFO] [30130] Received COMMIT: id:1741323542381, from:30157, delay:0.0000s, distance:46.16m (Euclidean)
[2025-03-07 13:59:05,749] [INFO] [30130] Received COMMIT: id:1741323542381, from:30035, delay:0.0001s, distance:186.89m (Euclidean)
[2025-03-07 13:59:05,749] [INFO] [30130] Received PREPARE: id:1741323542381, from:30070, delay:0.0000s, distance:83.08m (Euclidean)
[2025-03-07 13:59:05,995] [INFO] [30130] Received PREPARE: id:1741323542381, from:30111, delay:0.0000s, distance:132.41m (Euclidean)
[2025-03-07 13:59:06,264] [INFO] [30130] Received COMMIT: id:1741323542381, from:30029, delay:0.0001s, distance:190.73m (Euclidean)
[2025-03-07 13:59:06,266] [INFO] [30130] Received PREPARE: id:1741323542381, from:30199, delay:0.0001s, distance:181.62m (Euclidean)
[2025-03-07 13:59:06,314] [INFO] [30130] Received PREPARE: id:1741323542381, from:30175, delay:0.0000s, distance:188.52m (Euclidean)
[2025-03-07 13:59:06,314] [INFO] [30130] Received PREPARE: id:1741323542381, from:30171, delay:0.0000s, distance:56.32m (Euclidean)
[2025-03-07 13:59:06,314] [INFO] [30130] Received COMMIT: id:1741323542381, from:30149, delay:0.0000s, distance:171.43m (Euclidean)
[2025-03-07 13:59:06,316] [INFO] [30130] Received PREPARE: id:1741323542381, from:30085, delay:0.0000s, distance:143.48m (Euclidean)
[2025-03-07 13:59:06,316] [INFO] [30130] Received COMMIT: id:1741323542381, from:30037, delay:0.0001s, distance:195.87m (Euclidean)
[2025-03-07 13:59:06,957] [INFO] [30130] Received PREPARE: id:1741323542381, from:30098, delay:0.0001s, distance:184.08m (Euclidean)
[2025-03-07 13:59:06,959] [INFO] [30130] Received PREPARE: id:1741323542381, from:30049, delay:0.0000s, distance:129.40m (Euclidean)
[2025-03-07 13:59:06,959] [INFO] [30130] Received COMMIT: id:1741323542381, from:30093, delay:0.0000s, distance:60.00m (Euclidean)
[2025-03-07 13:59:06,959] [INFO] [30130] Received COMMIT: id:1741323542381, from:30085, delay:0.0000s, distance:143.48m (Euclidean)
[2025-03-07 13:59:06,964] [INFO] [30130] Received PREPARE: id:1741323542381, from:30113, delay:0.0000s, distance:117.04m (Euclidean)
[2025-03-07 13:59:07,011] [INFO] [30130] Received COMMIT: id:1741323542381, from:30025, delay:0.0000s, distance:109.53m (Euclidean)
[2025-03-07 13:59:07,011] [INFO] [30130] Received COMMIT: id:1741323542381, from:30095, delay:0.0001s, distance:169.15m (Euclidean)
[2025-03-07 13:59:07,011] [INFO] [30130] Received COMMIT: id:1741323542381, from:30171, delay:0.0000s, distance:56.32m (Euclidean)
[2025-03-07 13:59:07,011] [INFO] [30130] Received COMMIT: id:1741323542381, from:30106, delay:0.0000s, distance:75.36m (Euclidean)
[2025-03-07 13:59:07,011] [INFO] [30130] Received COMMIT: id:1741323542381, from:30021, delay:0.0000s, distance:177.98m (Euclidean)
[2025-03-07 13:59:07,011] [INFO] [30130] Received PREPARE: id:1741323542381, from:30021, delay:0.0000s, distance:177.98m (Euclidean)
[2025-03-07 13:59:07,019] [INFO] [30130] Received PREPARE: id:1741323542381, from:30191, delay:0.0001s, distance:182.80m (Euclidean)
[2025-03-07 13:59:07,019] [INFO] [30130] Received COMMIT: id:1741323542381, from:30013, delay:0.0000s, distance:134.54m (Euclidean)
[2025-03-07 13:59:07,019] [INFO] [30130] Received PREPARE: id:1741323542381, from:30167, delay:0.0002s, distance:294.75m (Euclidean)
[2025-03-07 13:59:07,020] [INFO] [30130] Received COMMIT: id:1741323542381, from:30113, delay:0.0000s, distance:117.04m (Euclidean)
[2025-03-07 13:59:07,020] [INFO] [30130] Received PREPARE: id:1741323542381, from:30161, delay:0.0000s, distance:110.32m (Euclidean)
[2025-03-07 13:59:07,022] [INFO] [30130] Received COMMIT: id:1741323542381, from:30147, delay:0.0001s, distance:203.15m (Euclidean)
[2025-03-07 13:59:07,022] [INFO] [30130] Received PREPARE: id:1741323542381, from:30177, delay:0.0000s, distance:129.99m (Euclidean)
[2025-03-07 13:59:07,163] [INFO] [30130] Received COMMIT: id:1741323542381, from:30046, delay:0.0000s, distance:90.53m (Euclidean)
[2025-03-07 13:59:07,163] [INFO] [30130] Received PREPARE: id:1741323542381, from:30066, delay:0.0000s, distance:139.96m (Euclidean)
[2025-03-07 13:59:07,163] [INFO] [30130] Received COMMIT: id:1741323542381, from:30053, delay:0.0000s, distance:139.59m (Euclidean)
[2025-03-07 13:59:07,163] [INFO] [30130] Received COMMIT: id:1741323542381, from:30049, delay:0.0000s, distance:129.40m (Euclidean)
[2025-03-07 13:59:07,163] [INFO] [30130] Received PREPARE: id:1741323542381, from:30170, delay:0.0000s, distance:182.50m (Euclidean)
[2025-03-07 13:59:07,163] [INFO] [30130] Received PREPARE: id:1741323542381, from:30179, delay:0.0002s, distance:283.60m (Euclidean)
[2025-03-07 13:59:07,163] [INFO] [30130] Received COMMIT: id:1741323542381, from:30024, delay:0.0000s, distance:148.63m (Euclidean)
[2025-03-07 13:59:07,163] [INFO] [30130] Received PREPARE: id:1741323542381, from:30024, delay:0.0000s, distance:148.63m (Euclidean)
[2025-03-07 13:59:07,163] [INFO] [30130] Received COMMIT: id:1741323542381, from:30116, delay:0.0001s, distance:202.56m (Euclidean)
[2025-03-07 13:59:07,174] [INFO] [30130] Received PREPARE: id:1741323542381, from:30116, delay:0.0001s, distance:202.56m (Euclidean)
[2025-03-07 13:59:07,174] [INFO] [30130] Received COMMIT: id:1741323542381, from:30167, delay:0.0002s, distance:294.75m (Euclidean)
[2025-03-07 13:59:07,447] [INFO] [30130] Received COMMIT: id:1741323542381, from:30181, delay:0.0000s, distance:112.13m (Euclidean)
[2025-03-07 13:59:07,447] [INFO] [30130] Received PREPARE: id:1741323542381, from:30180, delay:0.0002s, distance:251.28m (Euclidean)
[2025-03-07 13:59:07,467] [INFO] [30130] Received PREPARE: id:1741323542381, from:30051, delay:0.0000s, distance:31.79m (Euclidean)
[2025-03-07 13:59:07,669] [INFO] [30130] Received COMMIT: id:1741323542381, from:30015, delay:0.0000s, distance:111.53m (Euclidean)
[2025-03-07 13:59:07,671] [INFO] [30130] Received COMMIT: id:1741323542381, from:30089, delay:0.0000s, distance:106.92m (Euclidean)
[2025-03-07 13:59:07,671] [INFO] [30130] Received PREPARE: id:1741323542381, from:30136, delay:0.0001s, distance:201.74m (Euclidean)
[2025-03-07 13:59:07,673] [INFO] [30130] Received PREPARE: id:1741323542381, from:30015, delay:0.0000s, distance:111.53m (Euclidean)
[2025-03-07 13:59:07,673] [INFO] [30130] Received COMMIT: id:1741323542381, from:30066, delay:0.0000s, distance:139.96m (Euclidean)
[2025-03-07 13:59:07,673] [INFO] [30130] Received PREPARE: id:1741323542381, from:30129, delay:0.0000s, distance:62.59m (Euclidean)
[2025-03-07 13:59:07,673] [INFO] [30130] Received PREPARE: id:1741323542381, from:30076, delay:0.0001s, distance:176.73m (Euclidean)
[2025-03-07 13:59:07,673] [INFO] [30130] Received COMMIT: id:1741323542381, from:30051, delay:0.0000s, distance:31.79m (Euclidean)
[2025-03-07 13:59:07,673] [INFO] [30130] Received COMMIT: id:1741323542381, from:30098, delay:0.0001s, distance:184.08m (Euclidean)
[2025-03-07 13:59:07,715] [INFO] [30130] Received COMMIT: id:1741323542381, from:30199, delay:0.0001s, distance:181.62m (Euclidean)
[2025-03-07 13:59:07,715] [INFO] [30130] Received COMMIT: id:1741323542381, from:30175, delay:0.0000s, distance:188.52m (Euclidean)
[2025-03-07 13:59:07,715] [INFO] [30130] Received PREPARE: id:1741323542381, from:30103, delay:0.0000s, distance:166.41m (Euclidean)
[2025-03-07 13:59:07,715] [INFO] [30130] Received COMMIT: id:1741323542381, from:30060, delay:0.0000s, distance:45.45m (Euclidean)
[2025-03-07 13:59:07,715] [INFO] [30130] Received COMMIT: id:1741323542381, from:30180, delay:0.0002s, distance:251.28m (Euclidean)
[2025-03-07 13:59:07,904] [INFO] [30130] Received COMMIT: id:1741323542381, from:30161, delay:0.0000s, distance:110.32m (Euclidean)
[2025-03-07 13:59:07,904] [INFO] [30130] Received PREPARE: id:1741323542381, from:30027, delay:0.0001s, distance:166.30m (Euclidean)
[2025-03-07 13:59:07,904] [INFO] [30130] Received COMMIT: id:1741323542381, from:30070, delay:0.0000s, distance:83.08m (Euclidean)
[2025-03-07 13:59:07,904] [INFO] [30130] Received COMMIT: id:1741323542381, from:30170, delay:0.0000s, distance:182.50m (Euclidean)
[2025-03-07 13:59:07,904] [INFO] [30130] Received PREPARE: id:1741323542381, from:30119, delay:0.0002s, distance:266.35m (Euclidean)
[2025-03-07 13:59:07,904] [INFO] [30130] Received COMMIT: id:1741323542381, from:30136, delay:0.0001s, distance:201.74m (Euclidean)
[2025-03-07 13:59:07,904] [INFO] [30130] Received PREPARE: id:1741323542381, from:30023, delay:0.0001s, distance:182.28m (Euclidean)
[2025-03-07 13:59:07,904] [INFO] [30130] Received COMMIT: id:1741323542381, from:30027, delay:0.0001s, distance:166.30m (Euclidean)
[2025-03-07 13:59:07,904] [INFO] [30130] Received COMMIT: id:1741323542381, from:30023, delay:0.0001s, distance:182.28m (Euclidean)
[2025-03-07 13:59:07,904] [INFO] [30130] Received COMMIT: id:1741323542381, from:30129, delay:0.0000s, distance:62.59m (Euclidean)
[2025-03-07 13:59:07,967] [INFO] [30130] Received COMMIT: id:1741323542381, from:30076, delay:0.0001s, distance:176.73m (Euclidean)
[2025-03-07 13:59:07,967] [INFO] [30130] Received PREPARE: id:1741323542381, from:30118, delay:0.0000s, distance:82.05m (Euclidean)
[2025-03-07 13:59:07,969] [INFO] [30130] Received COMMIT: id:1741323542381, from:30174, delay:0.0001s, distance:173.53m (Euclidean)
[2025-03-07 13:59:08,014] [INFO] [30130] Received COMMIT: id:1741323542381, from:30119, delay:0.0002s, distance:266.35m (Euclidean)
[2025-03-07 13:59:08,014] [INFO] [30130] Received PREPARE: id:1741323542381, from:30126, delay:0.0001s, distance:236.63m (Euclidean)
[2025-03-07 13:59:08,014] [INFO] [30130] Received COMMIT: id:1741323542381, from:30011, delay:0.0000s, distance:165.65m (Euclidean)
[2025-03-07 13:59:08,014] [INFO] [30130] Received COMMIT: id:1741323542381, from:30126, delay:0.0001s, distance:236.63m (Euclidean)
[2025-03-07 13:59:08,014] [INFO] [30130] Received COMMIT: id:1741323542381, from:30177, delay:0.0000s, distance:129.99m (Euclidean)
[2025-03-07 13:59:08,014] [INFO] [30130] Received COMMIT: id:1741323542381, from:30179, delay:0.0002s, distance:283.60m (Euclidean)
[2025-03-07 13:59:08,014] [INFO] [30130] Received PREPARE: id:1741323542381, from:30011, delay:0.0000s, distance:165.65m (Euclidean)
[2025-03-07 13:59:08,058] [INFO] [30130] Received PREPARE: id:1741323542381, from:30123, delay:0.0001s, distance:190.79m (Euclidean)
[2025-03-07 13:59:08,058] [INFO] [30130] Received COMMIT: id:1741323542381, from:30118, delay:0.0000s, distance:82.05m (Euclidean)
[2025-03-07 13:59:08,109] [INFO] [30130] Received COMMIT: id:1741323542381, from:30028, delay:0.0001s, distance:240.60m (Euclidean)
[2025-03-07 13:59:08,109] [INFO] [30130] Received PREPARE: id:1741323542381, from:30195, delay:0.0001s, distance:156.07m (Euclidean)
[2025-03-07 13:59:08,109] [INFO] [30130] Received PREPARE: id:1741323542381, from:30028, delay:0.0001s, distance:240.60m (Euclidean)
[2025-03-07 13:59:08,109] [INFO] [30130] Received COMMIT: id:1741323542381, from:30111, delay:0.0000s, distance:132.41m (Euclidean)
[2025-03-07 13:59:08,109] [INFO] [30130] Received COMMIT: id:1741323542381, from:30074, delay:0.0001s, distance:166.78m (Euclidean)
[2025-03-07 13:59:08,109] [INFO] [30130] Received COMMIT: id:1741323542381, from:30195, delay:0.0001s, distance:156.07m (Euclidean)
[2025-03-07 13:59:08,109] [INFO] [30130] Received PREPARE: id:1741323542381, from:30109, delay:0.0001s, distance:218.17m (Euclidean)
[2025-03-07 13:59:08,327] [INFO] [30130] Received COMMIT: id:1741323542381, from:30191, delay:0.0001s, distance:182.80m (Euclidean)
[2025-03-07 13:59:08,341] [INFO] [30130] Received COMMIT: id:1741323542381, from:30109, delay:0.0001s, distance:218.17m (Euclidean)
[2025-03-07 13:59:08,356] [INFO] [30130] Received COMMIT: id:1741323542381, from:30123, delay:0.0001s, distance:190.79m (Euclidean)
[2025-03-07 13:59:08,356] [INFO] [30130] Received COMMIT: id:1741323542381, from:30103, delay:0.0000s, distance:166.41m (Euclidean)
[2025-03-07 13:59:08,475] [INFO] [30130] Received PREPARE: id:1741323542381, from:30182, delay:0.0001s, distance:213.12m (Euclidean)
[2025-03-07 13:59:08,593] [INFO] [30130] Received COMMIT: id:1741323542381, from:30168, delay:0.0000s, distance:78.20m (Euclidean)
[2025-03-07 13:59:08,599] [INFO] [30130] Received PREPARE: id:1741323542381, from:30168, delay:0.0000s, distance:78.20m (Euclidean)
[2025-03-07 13:59:08,599] [INFO] [30130] Received PREPARE: id:1741323542381, from:30144, delay:0.0001s, distance:201.76m (Euclidean)
[2025-03-07 13:59:08,600] [INFO] [30130] Received COMMIT: id:1741323542381, from:30144, delay:0.0001s, distance:201.76m (Euclidean)
[2025-03-07 13:59:08,711] [INFO] [30130] Received PREPARE: id:1741323542381, from:30158, delay:0.0001s, distance:239.93m (Euclidean)
[2025-03-07 13:59:08,739] [INFO] [30130] Received PREPARE: id:1741323542381, from:30112, delay:0.0001s, distance:153.65m (Euclidean)
[2025-03-07 13:59:08,859] [INFO] [30130] Received PREPARE: id:1741323542381, from:30065, delay:0.0000s, distance:129.78m (Euclidean)
[2025-03-07 13:59:08,859] [INFO] [30130] Received COMMIT: id:1741323542381, from:30065, delay:0.0000s, distance:129.78m (Euclidean)
[2025-03-07 13:59:08,907] [INFO] [30130] Received COMMIT: id:1741323542381, from:30158, delay:0.0001s, distance:239.93m (Euclidean)
[2025-03-07 13:59:08,964] [INFO] [30130] Received PREPARE: id:1741323542381, from:30059, delay:0.0001s, distance:162.93m (Euclidean)
[2025-03-07 13:59:09,126] [INFO] [30130] Received COMMIT: id:1741323542381, from:30112, delay:0.0001s, distance:153.65m (Euclidean)
[2025-03-07 13:59:09,130] [INFO] [30130] Received PREPARE: id:1741323542381, from:30107, delay:0.0001s, distance:241.35m (Euclidean)
[2025-03-07 13:59:09,130] [INFO] [30130] Received PREPARE: id:1741323542381, from:30120, delay:0.0001s, distance:186.24m (Euclidean)
[2025-03-07 13:59:09,130] [INFO] [30130] Received COMMIT: id:1741323542381, from:30120, delay:0.0001s, distance:186.24m (Euclidean)
[2025-03-07 13:59:09,130] [INFO] [30130] Received COMMIT: id:1741323542381, from:30107, delay:0.0001s, distance:241.35m (Euclidean)
[2025-03-07 13:59:09,260] [INFO] [30130] Received PREPARE: id:1741323542381, from:30043, delay:0.0000s, distance:99.93m (Euclidean)
[2025-03-07 13:59:09,260] [INFO] [30130] Received PREPARE: id:1741323542381, from:30176, delay:0.0000s, distance:103.93m (Euclidean)
[2025-03-07 13:59:09,260] [INFO] [30130] Received COMMIT: id:1741323542381, from:30043, delay:0.0000s, distance:99.93m (Euclidean)
[2025-03-07 13:59:09,262] [INFO] [30130] Received COMMIT: id:1741323542381, from:30176, delay:0.0000s, distance:103.93m (Euclidean)
[2025-03-07 13:59:09,312] [INFO] [30130] Received PREPARE: id:1741323542381, from:30196, delay:0.0000s, distance:111.11m (Euclidean)
[2025-03-07 13:59:09,312] [INFO] [30130] Received COMMIT: id:1741323542381, from:30196, delay:0.0000s, distance:111.11m (Euclidean)
[2025-03-07 13:59:09,320] [INFO] [30130] Received PREPARE: id:1741323542381, from:30005, delay:0.0001s, distance:203.59m (Euclidean)
[2025-03-07 13:59:09,320] [INFO] [30130] Received COMMIT: id:1741323542381, from:30005, delay:0.0001s, distance:203.59m (Euclidean)
[2025-03-07 13:59:09,341] [INFO] [30130] Received COMMIT: id:1741323542381, from:30182, delay:0.0001s, distance:213.12m (Euclidean)
[2025-03-07 13:59:09,452] [INFO] [30130] Received PREPARE: id:1741323542381, from:30124, delay:0.0001s, distance:231.78m (Euclidean)
[2025-03-07 13:59:09,474] [INFO] [30130] Received COMMIT: id:1741323542381, from:30110, delay:0.0001s, distance:210.53m (Euclidean)
[2025-03-07 13:59:09,474] [INFO] [30130] Received COMMIT: id:1741323542381, from:30124, delay:0.0001s, distance:231.78m (Euclidean)
[2025-03-07 13:59:09,474] [INFO] [30130] Received PREPARE: id:1741323542381, from:30110, delay:0.0001s, distance:210.53m (Euclidean)
[2025-03-07 13:59:09,553] [INFO] [30130] Received PREPARE: id:1741323542381, from:30056, delay:0.0001s, distance:232.24m (Euclidean)
[2025-03-07 13:59:09,569] [INFO] [30130] Received COMMIT: id:1741323542381, from:30056, delay:0.0001s, distance:232.24m (Euclidean)
[2025-03-07 13:59:09,673] [INFO] [30130] Received COMMIT: id:1741323542381, from:30059, delay:0.0001s, distance:162.93m (Euclidean)
[2025-03-07 13:59:09,864] [INFO] [30130] Received PREPARE: id:1741323542381, from:30189, delay:0.0000s, distance:134.75m (Euclidean)
[2025-03-07 13:59:09,929] [INFO] [30130] Received COMMIT: id:1741323542381, from:30189, delay:0.0000s, distance:134.75m (Euclidean)
[2025-03-07 13:59:10,085] [INFO] [30130] Received PREPARE: id:1741323542381, from:30041, delay:0.0000s, distance:109.62m (Euclidean)
[2025-03-07 13:59:10,085] [INFO] [30130] Received COMMIT: id:1741323542381, from:30041, delay:0.0000s, distance:109.62m (Euclidean)
[2025-03-07 13:59:10,263] [INFO] [30130] Received PREPARE: id:1741323542381, from:30150, delay:0.0000s, distance:176.98m (Euclidean)
[2025-03-07 13:59:10,263] [INFO] [30130] Received COMMIT: id:1741323542381, from:30150, delay:0.0000s, distance:176.98m (Euclidean)
[2025-03-07 13:59:10,327] [INFO] [30130] Received PREPARE: id:1741323542381, from:30096, delay:0.0001s, distance:212.64m (Euclidean)
[2025-03-07 13:59:10,337] [INFO] [30130] Received PREPARE: id:1741323542381, from:30154, delay:0.0000s, distance:125.64m (Euclidean)
[2025-03-07 13:59:10,337] [INFO] [30130] Received COMMIT: id:1741323542381, from:30154, delay:0.0000s, distance:125.64m (Euclidean)
[2025-03-07 13:59:10,376] [INFO] [30130] Received COMMIT: id:1741323542381, from:30096, delay:0.0001s, distance:212.64m (Euclidean)
[2025-03-07 13:59:10,420] [INFO] [30130] Received PREPARE: id:1741323542381, from:30108, delay:0.0000s, distance:86.06m (Euclidean)
[2025-03-07 13:59:10,424] [INFO] [30130] Received COMMIT: id:1741323542381, from:30108, delay:0.0000s, distance:86.06m (Euclidean)
[2025-03-07 13:59:10,717] [INFO] [30130] Received PREPARE: id:1741323542381, from:30100, delay:0.0001s, distance:204.24m (Euclidean)
[2025-03-07 13:59:10,717] [INFO] [30130] Received COMMIT: id:1741323542381, from:30100, delay:0.0001s, distance:204.24m (Euclidean)
[2025-03-07 13:59:10,856] [INFO] [30130] Received COMMIT: id:1741323542381, from:30062, delay:0.0002s, distance:275.21m (Euclidean)
[2025-03-07 13:59:10,857] [INFO] [30130] Received PREPARE: id:1741323542381, from:30062, delay:0.0002s, distance:275.21m (Euclidean)
[2025-03-07 13:59:11,411] [INFO] [30130] Received PREPARE: id:1741323542381, from:30063, delay:0.0000s, distance:127.63m (Euclidean)
[2025-03-07 13:59:11,411] [INFO] [30130] Received COMMIT: id:1741323542381, from:30063, delay:0.0000s, distance:127.63m (Euclidean)
[2025-03-07 13:59:11,531] [INFO] [30130] Received PREPARE: id:1741323542381, from:30048, delay:0.0000s, distance:183.02m (Euclidean)
[2025-03-07 13:59:11,531] [INFO] [30130] Received COMMIT: id:1741323542381, from:30048, delay:0.0000s, distance:183.02m (Euclidean)
[2025-03-07 13:59:11,796] [INFO] [30130] Received PREPARE: id:1741323542381, from:30040, delay:0.0001s, distance:213.52m (Euclidean)
[2025-03-07 13:59:11,796] [INFO] [30130] Received COMMIT: id:1741323542381, from:30040, delay:0.0001s, distance:213.52m (Euclidean)
[2025-03-07 13:59:11,940] [INFO] [30130] Received PREPARE: id:1741323542381, from:30054, delay:0.0001s, distance:195.91m (Euclidean)
[2025-03-07 13:59:11,940] [INFO] [30130] Received COMMIT: id:1741323542381, from:30054, delay:0.0001s, distance:195.91m (Euclidean)
[2025-03-07 13:59:12,038] [INFO] [30130] Received PREPARE: id:1741323542381, from:30004, delay:0.0000s, distance:171.06m (Euclidean)
[2025-03-07 13:59:12,038] [INFO] [30130] Received COMMIT: id:1741323542381, from:30004, delay:0.0000s, distance:171.06m (Euclidean)
[2025-03-07 13:59:12,065] [INFO] [30130] Received PREPARE: id:1741323542381, from:30090, delay:0.0001s, distance:222.06m (Euclidean)
[2025-03-07 13:59:12,065] [INFO] [30130] Received COMMIT: id:1741323542381, from:30090, delay:0.0001s, distance:222.06m (Euclidean)
[2025-03-07 13:59:12,278] [INFO] [30130] Received PREPARE: id:1741323542381, from:30178, delay:0.0000s, distance:194.30m (Euclidean)
[2025-03-07 13:59:12,278] [INFO] [30130] Received COMMIT: id:1741323542381, from:30178, delay:0.0000s, distance:194.30m (Euclidean)
[2025-03-07 13:59:12,328] [INFO] [30130] Received PREPARE: id:1741323542381, from:30020, delay:0.0001s, distance:232.77m (Euclidean)
[2025-03-07 13:59:12,330] [INFO] [30130] Received COMMIT: id:1741323542381, from:30020, delay:0.0001s, distance:232.77m (Euclidean)
[2025-03-07 13:59:14,122] [INFO] [30130] Received PREPARE: id:1741323542381, from:30016, delay:0.0000s, distance:79.63m (Euclidean)
[2025-03-07 13:59:14,324] [INFO] [30130] Received PREPARE: id:1741323542381, from:30165, delay:0.0001s, distance:198.67m (Euclidean)
[2025-03-07 13:59:14,324] [INFO] [30130] Received COMMIT: id:1741323542381, from:30165, delay:0.0001s, distance:198.67m (Euclidean)
[2025-03-07 13:59:14,843] [INFO] [30130] Received PREPARE: id:1741323542381, from:30061, delay:0.0001s, distance:162.01m (Euclidean)
[2025-03-07 13:59:14,843] [INFO] [30130] Received COMMIT: id:1741323542381, from:30061, delay:0.0001s, distance:162.01m (Euclidean)
[2025-03-07 13:59:15,029] [INFO] [30130] Received PREPARE: id:1741323542381, from:30026, delay:0.0002s, distance:286.59m (Euclidean)
[2025-03-07 13:59:15,029] [INFO] [30130] Received COMMIT: id:1741323542381, from:30026, delay:0.0002s, distance:286.59m (Euclidean)
[2025-03-07 13:59:15,119] [INFO] [30130] Received COMMIT: id:1741323542381, from:30016, delay:0.0000s, distance:79.63m (Euclidean)
[2025-03-07 13:59:15,227] [INFO] [30130] Received PREPARE: id:1741323542381, from:30086, delay:0.0002s, distance:289.94m (Euclidean)
[2025-03-07 13:59:15,227] [INFO] [30130] Received COMMIT: id:1741323542381, from:30086, delay:0.0002s, distance:289.94m (Euclidean)
[2025-03-07 13:59:15,264] [INFO] [30130] Received PREPARE: id:1741323542381, from:30132, delay:0.0001s, distance:193.09m (Euclidean)
[2025-03-07 13:59:15,465] [INFO] [30130] Received PREPARE: id:1741323542381, from:30052, delay:0.0001s, distance:198.34m (Euclidean)
[2025-03-07 13:59:15,465] [INFO] [30130] Received COMMIT: id:1741323542381, from:30052, delay:0.0001s, distance:198.34m (Euclidean)
[2025-03-07 13:59:15,571] [INFO] [30130] Received PREPARE: id:1741323542381, from:30088, delay:0.0001s, distance:215.74m (Euclidean)
[2025-03-07 13:59:15,571] [INFO] [30130] Received COMMIT: id:1741323542381, from:30088, delay:0.0001s, distance:215.74m (Euclidean)
[2025-03-07 13:59:15,964] [INFO] [30130] Received PREPARE: id:1741323542381, from:30194, delay:0.0001s, distance:230.63m (Euclidean)
[2025-03-07 13:59:15,964] [INFO] [30130] Received COMMIT: id:1741323542381, from:30194, delay:0.0001s, distance:230.63m (Euclidean)
[2025-03-07 13:59:16,070] [INFO] [30130] Received COMMIT: id:1741323542381, from:30132, delay:0.0001s, distance:193.09m (Euclidean)
[2025-03-07 13:59:16,433] [INFO] [30130] Received PREPARE: id:1741323542381, from:30087, delay:0.0001s, distance:229.54m (Euclidean)
[2025-03-07 13:59:16,497] [INFO] [30130] Received COMMIT: id:1741323542381, from:30087, delay:0.0001s, distance:229.54m (Euclidean)
[2025-03-07 13:59:16,512] [INFO] [30130] Received PREPARE: id:1741323542381, from:30140, delay:0.0002s, distance:282.11m (Euclidean)
[2025-03-07 13:59:16,591] [INFO] [30130] Received PREPARE: id:1741323542381, from:30001, delay:0.0001s, distance:165.92m (Euclidean)
[2025-03-07 13:59:16,593] [INFO] [30130] Received COMMIT: id:1741323542381, from:30001, delay:0.0001s, distance:165.92m (Euclidean)
[2025-03-07 13:59:16,692] [INFO] [30130] Received PREPARE: id:1741323542381, from:30081, delay:0.0001s, distance:170.35m (Euclidean)
[2025-03-07 13:59:16,713] [INFO] [30130] Received COMMIT: id:1741323542381, from:30081, delay:0.0001s, distance:170.35m (Euclidean)
[2025-03-07 13:59:16,731] [INFO] [30130] Received PREPARE: id:1741323542381, from:30145, delay:0.0001s, distance:231.89m (Euclidean)
[2025-03-07 13:59:16,815] [INFO] [30130] Received COMMIT: id:1741323542381, from:30140, delay:0.0002s, distance:282.11m (Euclidean)
[2025-03-07 13:59:16,815] [INFO] [30130] Received PREPARE: id:1741323542381, from:30034, delay:0.0001s, distance:204.87m (Euclidean)
[2025-03-07 13:59:16,829] [INFO] [30130] Received COMMIT: id:1741323542381, from:30034, delay:0.0001s, distance:204.87m (Euclidean)
[2025-03-07 13:59:17,178] [INFO] [30130] Received COMMIT: id:1741323542381, from:30145, delay:0.0001s, distance:231.89m (Euclidean)
[2025-03-07 13:59:17,402] [INFO] [30130] Received PREPARE: id:1741323542381, from:30117, delay:0.0002s, distance:284.39m (Euclidean)
[2025-03-07 13:59:17,404] [INFO] [30130] Received COMMIT: id:1741323542381, from:30117, delay:0.0002s, distance:284.39m (Euclidean)
[2025-03-07 13:59:17,442] [INFO] [30130] Received PREPARE: id:1741323542381, from:30038, delay:0.0000s, distance:141.08m (Euclidean)
[2025-03-07 13:59:17,649] [INFO] [30130] Received PREPARE: id:1741323542381, from:30006, delay:0.0002s, distance:272.00m (Euclidean)
[2025-03-07 13:59:17,649] [INFO] [30130] Received COMMIT: id:1741323542381, from:30006, delay:0.0002s, distance:272.00m (Euclidean)
[2025-03-07 13:59:17,715] [INFO] [30130] Received PREPARE: id:1741323542381, from:30114, delay:0.0001s, distance:202.02m (Euclidean)
[2025-03-07 13:59:17,719] [INFO] [30130] Received COMMIT: id:1741323542381, from:30114, delay:0.0001s, distance:202.02m (Euclidean)
[2025-03-07 13:59:17,745] [INFO] [30130] Received PREPARE: id:1741323542381, from:30198, delay:0.0000s, distance:93.94m (Euclidean)
[2025-03-07 13:59:17,745] [INFO] [30130] Received COMMIT: id:1741323542381, from:30198, delay:0.0000s, distance:93.94m (Euclidean)
[2025-03-07 13:59:18,020] [INFO] [30130] Received COMMIT: id:1741323542381, from:30038, delay:0.0000s, distance:141.08m (Euclidean)
[2025-03-07 13:59:18,404] [INFO] [30130] Received PREPARE: id:1741323542381, from:30010, delay:0.0002s, distance:258.24m (Euclidean)
[2025-03-07 13:59:18,417] [INFO] [30130] Received COMMIT: id:1741323542381, from:30010, delay:0.0002s, distance:258.24m (Euclidean)
[2025-03-07 13:59:18,713] [INFO] [30130] Received PREPARE: id:1741323542381, from:30151, delay:0.0001s, distance:201.51m (Euclidean)
[2025-03-07 13:59:18,713] [INFO] [30130] Received COMMIT: id:1741323542381, from:30151, delay:0.0001s, distance:201.51m (Euclidean)
[2025-03-07 13:59:19,486] [INFO] [30130] Received PREPARE: id:1741323542381, from:30156, delay:0.0001s, distance:195.63m (Euclidean)
[2025-03-07 13:59:19,591] [INFO] [30130] Received PREPARE: id:1741323542381, from:30134, delay:0.0002s, distance:271.18m (Euclidean)
[2025-03-07 13:59:19,712] [INFO] [30130] Received COMMIT: id:1741323542381, from:30156, delay:0.0001s, distance:195.63m (Euclidean)
[2025-03-07 13:59:19,807] [INFO] [30130] Received COMMIT: id:1741323542381, from:30134, delay:0.0002s, distance:271.18m (Euclidean)
[2025-03-07 13:59:19,908] [INFO] [30130] Received PREPARE: id:1741323542381, from:30083, delay:0.0000s, distance:108.73m (Euclidean)
[2025-03-07 13:59:19,910] [INFO] [30130] Received COMMIT: id:1741323542381, from:30083, delay:0.0000s, distance:108.73m (Euclidean)
[2025-03-07 13:59:19,922] [INFO] [30130] Received PREPARE: id:1741323542381, from:30019, delay:0.0002s, distance:276.51m (Euclidean)
[2025-03-07 13:59:19,922] [INFO] [30130] Received COMMIT: id:1741323542381, from:30019, delay:0.0002s, distance:276.51m (Euclidean)
[2025-03-07 13:59:19,983] [INFO] [30130] Received PREPARE: id:1741323542381, from:30173, delay:0.0002s, distance:254.83m (Euclidean)
[2025-03-07 13:59:20,033] [INFO] [30130] Received PREPARE: id:1741323542381, from:30186, delay:0.0000s, distance:173.54m (Euclidean)
[2025-03-07 13:59:20,090] [INFO] [30130] Received PREPARE: id:1741323542381, from:30159, delay:0.0001s, distance:232.95m (Euclidean)
[2025-03-07 13:59:20,090] [INFO] [30130] Received COMMIT: id:1741323542381, from:30159, delay:0.0001s, distance:232.95m (Euclidean)
[2025-03-07 13:59:20,208] [INFO] [30130] Received PREPARE: id:1741323542381, from:30143, delay:0.0001s, distance:181.68m (Euclidean)
[2025-03-07 13:59:20,208] [INFO] [30130] Received COMMIT: id:1741323542381, from:30143, delay:0.0001s, distance:181.68m (Euclidean)
[2025-03-07 13:59:20,856] [INFO] [30130] Received PREPARE: id:1741323542381, from:30105, delay:0.0000s, distance:124.37m (Euclidean)
[2025-03-07 13:59:20,858] [INFO] [30130] Received COMMIT: id:1741323542381, from:30105, delay:0.0000s, distance:124.37m (Euclidean)
[2025-03-07 13:59:20,929] [INFO] [30130] Received PREPARE: id:1741323542381, from:30009, delay:0.0000s, distance:104.45m (Euclidean)
[2025-03-07 13:59:21,020] [INFO] [30130] Received PREPARE: id:1741323542381, from:30141, delay:0.0001s, distance:211.48m (Euclidean)
[2025-03-07 13:59:21,020] [INFO] [30130] Received COMMIT: id:1741323542381, from:30141, delay:0.0001s, distance:211.48m (Euclidean)
[2025-03-07 13:59:21,142] [INFO] [30130] Received PREPARE: id:1741323542381, from:30193, delay:0.0002s, distance:283.35m (Euclidean)
[2025-03-07 13:59:21,142] [INFO] [30130] Received COMMIT: id:1741323542381, from:30193, delay:0.0002s, distance:283.35m (Euclidean)
[2025-03-07 13:59:21,188] [INFO] [30130] Received COMMIT: id:1741323542381, from:30173, delay:0.0002s, distance:254.83m (Euclidean)
[2025-03-07 13:59:21,345] [INFO] [30130] Received PREPARE: id:1741323542381, from:30091, delay:0.0001s, distance:243.71m (Euclidean)
[2025-03-07 13:59:21,345] [INFO] [30130] Received COMMIT: id:1741323542381, from:30091, delay:0.0001s, distance:243.71m (Euclidean)
[2025-03-07 13:59:21,505] [INFO] [30130] Received PREPARE: id:1741323542381, from:30153, delay:0.0002s, distance:261.19m (Euclidean)
[2025-03-07 13:59:21,558] [INFO] [30130] Received COMMIT: id:1741323542381, from:30153, delay:0.0002s, distance:261.19m (Euclidean)
[2025-03-07 13:59:21,574] [INFO] [30130] Received COMMIT: id:1741323542381, from:30186, delay:0.0000s, distance:173.54m (Euclidean)
[2025-03-07 13:59:21,826] [INFO] [30130] Received PREPARE: id:1741323542381, from:30031, delay:0.0002s, distance:289.21m (Euclidean)
[2025-03-07 13:59:21,826] [INFO] [30130] Received COMMIT: id:1741323542381, from:30031, delay:0.0002s, distance:289.21m (Euclidean)
[2025-03-07 13:59:22,039] [INFO] [30130] Received PREPARE: id:1741323542381, from:30137, delay:0.0001s, distance:216.83m (Euclidean)
[2025-03-07 13:59:22,039] [INFO] [30130] Received COMMIT: id:1741323542381, from:30137, delay:0.0001s, distance:216.83m (Euclidean)
[2025-03-07 13:59:22,241] [INFO] [30130] Received PREPARE: id:1741323542381, from:30166, delay:0.0002s, distance:257.03m (Euclidean)
[2025-03-07 13:59:22,241] [INFO] [30130] Received COMMIT: id:1741323542381, from:30166, delay:0.0002s, distance:257.03m (Euclidean)
[2025-03-07 13:59:22,243] [INFO] [30130] Received PREPARE: id:1741323542381, from:30073, delay:0.0001s, distance:233.59m (Euclidean)
[2025-03-07 13:59:22,245] [INFO] [30130] Received COMMIT: id:1741323542381, from:30073, delay:0.0001s, distance:233.59m (Euclidean)
[2025-03-07 13:59:22,447] [INFO] [30130] Received PREPARE: id:1741323542381, from:30188, delay:0.0002s, distance:263.74m (Euclidean)
[2025-03-07 13:59:22,447] [INFO] [30130] Received COMMIT: id:1741323542381, from:30188, delay:0.0002s, distance:263.74m (Euclidean)
[2025-03-07 13:59:22,487] [INFO] [30130] Received COMMIT: id:1741323542381, from:30000, delay:0.0000s, distance:122.82m (Euclidean)
[2025-03-07 13:59:22,533] [INFO] [30130] Received PREPARE: id:1741323542381, from:30055, delay:0.0001s, distance:240.53m (Euclidean)
[2025-03-07 13:59:22,533] [INFO] [30130] Received COMMIT: id:1741323542381, from:30055, delay:0.0001s, distance:240.53m (Euclidean)
[2025-03-07 13:59:22,622] [INFO] [30130] Received PREPARE: id:1741323542381, from:30104, delay:0.0001s, distance:170.45m (Euclidean)
[2025-03-07 13:59:22,626] [INFO] [30130] Received PREPARE: id:1741323542381, from:30064, delay:0.0002s, distance:265.31m (Euclidean)
[2025-03-07 13:59:22,626] [INFO] [30130] Received PREPARE: id:1741323542381, from:30014, delay:0.0001s, distance:214.74m (Euclidean)
[2025-03-07 13:59:22,626] [INFO] [30130] Received COMMIT: id:1741323542381, from:30104, delay:0.0001s, distance:170.45m (Euclidean)
[2025-03-07 13:59:22,626] [INFO] [30130] Received COMMIT: id:1741323542381, from:30064, delay:0.0002s, distance:265.31m (Euclidean)
[2025-03-07 13:59:22,628] [INFO] [30130] Received COMMIT: id:1741323542381, from:30014, delay:0.0001s, distance:214.74m (Euclidean)
[2025-03-07 13:59:22,766] [INFO] [30130] Received PREPARE: id:1741323542381, from:30036, delay:0.0001s, distance:248.84m (Euclidean)
[2025-03-07 13:59:22,766] [INFO] [30130] Received COMMIT: id:1741323542381, from:30036, delay:0.0001s, distance:248.84m (Euclidean)
[2025-03-07 13:59:23,006] [INFO] [30130] Received PREPARE: id:1741323542381, from:30079, delay:0.0001s, distance:205.77m (Euclidean)
[2025-03-07 13:59:23,006] [INFO] [30130] Received COMMIT: id:1741323542381, from:30079, delay:0.0001s, distance:205.77m (Euclidean)
[2025-03-07 13:59:23,039] [INFO] [30130] Received PREPARE: id:1741323542381, from:30138, delay:0.0001s, distance:180.09m (Euclidean)
[2025-03-07 13:59:23,039] [INFO] [30130] Received COMMIT: id:1741323542381, from:30138, delay:0.0001s, distance:180.09m (Euclidean)
[2025-03-07 13:59:23,124] [INFO] [30130] Received PREPARE: id:1741323542381, from:30084, delay:0.0002s, distance:287.25m (Euclidean)
[2025-03-07 13:59:23,126] [INFO] [30130] Received COMMIT: id:1741323542381, from:30084, delay:0.0002s, distance:287.25m (Euclidean)
[2025-03-07 13:59:23,558] [INFO] [30130] Received COMMIT: id:1741323542381, from:30009, delay:0.0000s, distance:104.45m (Euclidean)
[2025-03-07 13:59:23,567] [INFO] [30130] Received PREPARE: id:1741323542381, from:30099, delay:0.0002s, distance:287.35m (Euclidean)
[2025-03-07 13:59:23,637] [INFO] [30130] Received PREPARE: id:1741323542381, from:30122, delay:0.0001s, distance:204.01m (Euclidean)
[2025-03-07 13:59:23,637] [INFO] [30130] Received COMMIT: id:1741323542381, from:30122, delay:0.0001s, distance:204.01m (Euclidean)
[2025-03-07 13:59:23,670] [INFO] [30130] Received COMMIT: id:1741323542381, from:30099, delay:0.0002s, distance:287.35m (Euclidean)
[2025-03-07 13:59:24,423] [INFO] [30130] Received PREPARE: id:1741323542381, from:30039, delay:0.0001s, distance:241.86m (Euclidean)
[2025-03-07 13:59:24,425] [INFO] [30130] Received COMMIT: id:1741323542381, from:30039, delay:0.0001s, distance:241.86m (Euclidean)
[2025-03-07 13:59:24,506] [INFO] [30130] Received PREPARE: id:1741323542381, from:30160, delay:0.0001s, distance:247.71m (Euclidean)
[2025-03-07 13:59:24,506] [INFO] [30130] Received COMMIT: id:1741323542381, from:30160, delay:0.0001s, distance:247.71m (Euclidean)
[2025-03-07 13:59:24,687] [INFO] [30130] Received PREPARE: id:1741323542381, from:30187, delay:0.0001s, distance:224.50m (Euclidean)
[2025-03-07 13:59:24,687] [INFO] [30130] Received COMMIT: id:1741323542381, from:30187, delay:0.0001s, distance:224.50m (Euclidean)
[2025-03-07 13:59:24,723] [INFO] [30130] Received PREPARE: id:1741323542381, from:30131, delay:0.0001s, distance:207.23m (Euclidean)
[2025-03-07 13:59:24,723] [INFO] [30130] Received COMMIT: id:1741323542381, from:30131, delay:0.0001s, distance:207.23m (Euclidean)
[2025-03-07 13:59:25,047] [INFO] [30130] Received PREPARE: id:1741323542381, from:30152, delay:0.0002s, distance:277.42m (Euclidean)
[2025-03-07 13:59:25,047] [INFO] [30130] Received COMMIT: id:1741323542381, from:30152, delay:0.0002s, distance:277.42m (Euclidean)
[2025-03-07 13:59:25,145] [INFO] [30130] Received PREPARE: id:1741323542381, from:30042, delay:0.0000s, distance:195.32m (Euclidean)
[2025-03-07 13:59:25,145] [INFO] [30130] Received COMMIT: id:1741323542381, from:30042, delay:0.0000s, distance:195.32m (Euclidean)
[2025-03-07 13:59:25,303] [INFO] [30130] Received PREPARE: id:1741323542381, from:30101, delay:0.0001s, distance:182.25m (Euclidean)
[2025-03-07 13:59:25,303] [INFO] [30130] Received COMMIT: id:1741323542381, from:30101, delay:0.0001s, distance:182.25m (Euclidean)
[2025-03-07 13:59:25,629] [INFO] [30130] Received PREPARE: id:1741323542381, from:30075, delay:0.0001s, distance:181.98m (Euclidean)
[2025-03-07 13:59:25,643] [INFO] [30130] Received COMMIT: id:1741323542381, from:30075, delay:0.0001s, distance:181.98m (Euclidean)
[2025-03-07 13:59:25,666] [INFO] [30130] Received PREPARE: id:1741323542381, from:30094, delay:0.0001s, distance:187.00m (Euclidean)
[2025-03-07 13:59:25,727] [INFO] [30130] Received COMMIT: id:1741323542381, from:30094, delay:0.0001s, distance:187.00m (Euclidean)
[2025-03-07 13:59:25,856] [INFO] [30130] Received PREPARE: id:1741323542381, from:30142, delay:0.0001s, distance:161.68m (Euclidean)
[2025-03-07 13:59:27,155] [INFO] [30130] Received COMMIT: id:1741323542381, from:30142, delay:0.0001s, distance:161.68m (Euclidean)
[2025-03-07 13:59:27,157] [INFO] [30130] Received COMMIT: id:1741323542381, from:30008, delay:0.0000s, distance:194.54m (Euclidean)
[2025-03-07 13:59:27,158] [INFO] [30130] Received COMMIT: id:1741323542381, from:30022, delay:0.0002s, distance:283.59m (Euclidean)
[2025-03-07 13:59:27,158] [INFO] [30130] Received PREPARE: id:1741323542381, from:30082, delay:0.0001s, distance:157.51m (Euclidean)
[2025-03-07 13:59:27,158] [INFO] [30130] Received COMMIT: id:1741323542381, from:30185, delay:0.0001s, distance:193.77m (Euclidean)
[2025-03-07 13:59:27,158] [INFO] [30130] Received COMMIT: id:1741323542381, from:30082, delay:0.0001s, distance:157.51m (Euclidean)
[2025-03-07 13:59:27,159] [INFO] [30130] Received PREPARE: id:1741323542381, from:30185, delay:0.0001s, distance:193.77m (Euclidean)
[2025-03-07 13:59:27,159] [INFO] [30130] Received PREPARE: id:1741323542381, from:30068, delay:0.0002s, distance:269.48m (Euclidean)
[2025-03-07 13:59:27,159] [INFO] [30130] Received PREPARE: id:1741323542381, from:30008, delay:0.0000s, distance:194.54m (Euclidean)
[2025-03-07 13:59:27,159] [INFO] [30130] Received PREPARE: id:1741323542381, from:30022, delay:0.0002s, distance:283.59m (Euclidean)
[2025-03-07 13:59:27,159] [INFO] [30130] Received COMMIT: id:1741323542381, from:30068, delay:0.0002s, distance:269.48m (Euclidean)
[2025-03-07 13:59:27,167] [INFO] [30130] Received PREPARE: id:1741323542381, from:30017, delay:0.0002s, distance:260.06m (Euclidean)
[2025-03-07 13:59:27,168] [INFO] [30130] Received COMMIT: id:1741323542381, from:30017, delay:0.0002s, distance:260.06m (Euclidean)
[2025-03-07 13:59:27,528] [INFO] [30130] Received PREPARE: id:1741323542381, from:30139, delay:0.0001s, distance:229.83m (Euclidean)
[2025-03-07 13:59:27,548] [INFO] [30130] Received COMMIT: id:1741323542381, from:30139, delay:0.0001s, distance:229.83m (Euclidean)
[2025-03-07 13:59:27,560] [INFO] [30130] Received PREPARE: id:1741323542381, from:30162, delay:0.0001s, distance:240.08m (Euclidean)
[2025-03-07 13:59:27,560] [INFO] [30130] Received COMMIT: id:1741323542381, from:30162, delay:0.0001s, distance:240.08m (Euclidean)
[2025-03-07 13:59:28,610] [INFO] [30130] Received PREPARE: id:1741323542381, from:30164, delay:0.0002s, distance:277.17m (Euclidean)
[2025-03-07 13:59:28,817] [INFO] [30130] Received PREPARE: id:1741323542381, from:30002, delay:0.0001s, distance:158.80m (Euclidean)
[2025-03-07 13:59:28,988] [INFO] [30130] Received PREPARE: id:1741323542381, from:30072, delay:0.0002s, distance:292.74m (Euclidean)
[2025-03-07 13:59:33,185] [INFO] [30130] Received COMMIT: id:1741323542381, from:30072, delay:0.0002s, distance:292.74m (Euclidean)
[2025-03-07 13:59:37,318] [INFO] [30130] Received COMMIT: id:1741323542381, from:30164, delay:0.0002s, distance:277.17m (Euclidean)
[2025-03-07 13:59:37,476] [INFO] [30130] Received PREPARE: id:1741323542381, from:30078, delay:0.0002s, distance:251.08m (Euclidean)
[2025-03-07 13:59:37,584] [INFO] [30130] Received PREPARE: id:1741323542381, from:30012, delay:0.0002s, distance:259.05m (Euclidean)
[2025-03-07 13:59:37,588] [INFO] [30130] Received COMMIT: id:1741323542381, from:30012, delay:0.0002s, distance:259.05m (Euclidean)
[2025-03-07 13:59:37,963] [INFO] [30130] Received COMMIT: id:1741323542381, from:30018, delay:0.0000s, distance:177.17m (Euclidean)
[2025-03-07 13:59:37,964] [INFO] [30130] Received PREPARE: id:1741323542381, from:30018, delay:0.0000s, distance:177.17m (Euclidean)
[2025-03-07 13:59:38,070] [INFO] [30130] Received COMMIT: id:1741323542381, from:30002, delay:0.0001s, distance:158.80m (Euclidean)
[2025-03-07 13:59:38,111] [INFO] [30130] Received PREPARE: id:1741323542381, from:30047, delay:0.0001s, distance:230.63m (Euclidean)
[2025-03-07 13:59:38,156] [INFO] [30130] Received COMMIT: id:1741323542381, from:30047, delay:0.0001s, distance:230.63m (Euclidean)
[2025-03-07 13:59:38,227] [INFO] [30130] Received PREPARE: id:1741323542381, from:30097, delay:0.0002s, distance:260.38m (Euclidean)
[2025-03-07 13:59:38,287] [INFO] [30130] Received PREPARE: id:1741323542381, from:30044, delay:0.0002s, distance:260.31m (Euclidean)
[2025-03-07 13:59:38,326] [INFO] [30130] Received COMMIT: id:1741323542381, from:30044, delay:0.0002s, distance:260.31m (Euclidean)
[2025-03-07 13:59:38,525] [INFO] [30130] Received PREPARE: id:1741323542381, from:30183, delay:0.0001s, distance:248.40m (Euclidean)
[2025-03-07 13:59:38,529] [INFO] [30130] Received COMMIT: id:1741323542381, from:30183, delay:0.0001s, distance:248.40m (Euclidean)
[2025-03-07 13:59:38,655] [INFO] [30130] Received COMMIT: id:1741323542381, from:30163, delay:0.0001s, distance:243.83m (Euclidean)
[2025-03-07 13:59:38,779] [INFO] [30130] Received PREPARE: id:1741323542381, from:30172, delay:0.0001s, distance:229.25m (Euclidean)
[2025-03-07 13:59:38,793] [INFO] [30130] Received COMMIT: id:1741323542381, from:30172, delay:0.0001s, distance:229.25m (Euclidean)
