[2025-03-07 13:53:31,873] [INFO] Starting node at localhost:30145 | index=146 | f=1, k=4 | Role: Replica
[2025-03-07 13:53:39,164] [INFO] [30145] Received PREPARE: id:1741323218379, from:30117, delay:0.0000s, distance:249.53m (Euclidean)
[2025-03-07 13:53:39,164] [INFO] [30145] Missing PRE-PREPARE for REQUEST 1741323218379; ignoring PREPARE
[2025-03-07 13:53:39,440] [INFO] [30145] Received PREPARE: id:1741323218379, from:30028, delay:0.0000s, distance:249.44m (Euclidean)
[2025-03-07 13:53:39,440] [INFO] [30145] Missing PRE-PREPARE for REQUEST 1741323218379; ignoring PREPARE
[2025-03-07 13:53:39,543] [INFO] [30145] Received PREPARE: id:1741323218379, from:30096, delay:0.0000s, distance:89.61m (Euclidean)
[2025-03-07 13:53:39,543] [INFO] [30145] Missing PRE-PREPARE for REQUEST 1741323218379; ignoring PREPARE
[2025-03-07 13:53:39,573] [INFO] [30145] Received COMMIT: id:1741323218379, from:30096, delay:0.0000s, distance:89.61m (Euclidean)
[2025-03-07 13:53:40,782] [INFO] [30145] Received PREPARE: id:1741323218379, from:30009, delay:0.0001s, distance:202.52m (Euclidean)
[2025-03-07 13:53:40,782] [INFO] [30145] Missing PRE-PREPARE for REQUEST 1741323218379; ignoring PREPARE
[2025-03-07 13:53:40,782] [INFO] [30145] Received COMMIT: id:1741323218379, from:30009, delay:0.0001s, distance:202.52m (Euclidean)
[2025-03-07 13:53:41,053] [INFO] [30145] Received COMMIT: id:1741323218379, from:30117, delay:0.0000s, distance:249.53m (Euclidean)
[2025-03-07 13:53:41,212] [INFO] [30145] Received COMMIT: id:1741323218379, from:30028, delay:0.0000s, distance:249.44m (Euclidean)
[2025-03-07 13:53:41,293] [INFO] [30145] Received PREPARE: id:1741323218379, from:30005, delay:0.0002s, distance:278.67m (Euclidean)
[2025-03-07 13:53:41,293] [INFO] [30145] Missing PRE-PREPARE for REQUEST 1741323218379; ignoring PREPARE
[2025-03-07 13:53:41,293] [INFO] [30145] Received COMMIT: id:1741323218379, from:30005, delay:0.0002s, distance:278.67m (Euclidean)
[2025-03-07 13:53:41,320] [INFO] [30145] Received PREPARE: id:1741323218379, from:30030, delay:0.0000s, distance:113.46m (Euclidean)
[2025-03-07 13:53:41,320] [INFO] [30145] Missing PRE-PREPARE for REQUEST 1741323218379; ignoring PREPARE
[2025-03-07 13:53:41,320] [INFO] [30145] Received COMMIT: id:1741323218379, from:30030, delay:0.0000s, distance:113.46m (Euclidean)
[2025-03-07 13:53:41,354] [INFO] [30145] Received PREPARE: id:1741323218379, from:30041, delay:0.0000s, distance:138.05m (Euclidean)
[2025-03-07 13:53:41,354] [INFO] [30145] Missing PRE-PREPARE for REQUEST 1741323218379; ignoring PREPARE
[2025-03-07 13:53:41,354] [INFO] [30145] Received COMMIT: id:1741323218379, from:30041, delay:0.0000s, distance:138.05m (Euclidean)
[2025-03-07 13:53:41,573] [INFO] [30145] Received PREPARE: id:1741323218379, from:30047, delay:0.0001s, distance:243.60m (Euclidean)
[2025-03-07 13:53:41,573] [INFO] [30145] Missing PRE-PREPARE for REQUEST 1741323218379; ignoring PREPARE
[2025-03-07 13:53:41,573] [INFO] [30145] Received COMMIT: id:1741323218379, from:30047, delay:0.0001s, distance:243.60m (Euclidean)
[2025-03-07 13:53:42,000] [INFO] [30145] Received PREPARE: id:1741323218379, from:30018, delay:0.0000s, distance:21.04m (Euclidean)
[2025-03-07 13:53:42,000] [INFO] [30145] Missing PRE-PREPARE for REQUEST 1741323218379; ignoring PREPARE
[2025-03-07 13:53:42,000] [INFO] [30145] Received COMMIT: id:1741323218379, from:30018, delay:0.0000s, distance:21.04m (Euclidean)
[2025-03-07 13:53:42,096] [INFO] [30145] Received PREPARE: id:1741323218379, from:30060, delay:0.0001s, distance:240.08m (Euclidean)
[2025-03-07 13:53:42,096] [INFO] [30145] Missing PRE-PREPARE for REQUEST 1741323218379; ignoring PREPARE
[2025-03-07 13:53:42,096] [INFO] [30145] Received COMMIT: id:1741323218379, from:30060, delay:0.0001s, distance:240.08m (Euclidean)
[2025-03-07 13:53:42,143] [INFO] [30145] Received PREPARE: id:1741323218379, from:30037, delay:0.0002s, distance:286.88m (Euclidean)
[2025-03-07 13:53:42,143] [INFO] [30145] Missing PRE-PREPARE for REQUEST 1741323218379; ignoring PREPARE
[2025-03-07 13:53:42,143] [INFO] [30145] Received COMMIT: id:1741323218379, from:30037, delay:0.0002s, distance:286.88m (Euclidean)
[2025-03-07 13:53:42,177] [INFO] [30145] Received PREPARE: id:1741323218379, from:30017, delay:0.0000s, distance:182.39m (Euclidean)
[2025-03-07 13:53:42,177] [INFO] [30145] Missing PRE-PREPARE for REQUEST 1741323218379; ignoring PREPARE
[2025-03-07 13:53:42,177] [INFO] [30145] Received COMMIT: id:1741323218379, from:30017, delay:0.0000s, distance:182.39m (Euclidean)
[2025-03-07 13:53:42,305] [INFO] [30145] Received PREPARE: id:1741323218379, from:30024, delay:0.0001s, distance:153.07m (Euclidean)
[2025-03-07 13:53:42,305] [INFO] [30145] Missing PRE-PREPARE for REQUEST 1741323218379; ignoring PREPARE
[2025-03-07 13:53:42,332] [INFO] [30145] Received PREPARE: id:1741323218379, from:30062, delay:0.0002s, distance:271.16m (Euclidean)
[2025-03-07 13:53:42,332] [INFO] [30145] Missing PRE-PREPARE for REQUEST 1741323218379; ignoring PREPARE
[2025-03-07 13:53:42,332] [INFO] [30145] Received COMMIT: id:1741323218379, from:30062, delay:0.0002s, distance:271.16m (Euclidean)
[2025-03-07 13:53:42,338] [INFO] [30145] Received PREPARE: id:1741323218379, from:30089, delay:0.0001s, distance:235.12m (Euclidean)
[2025-03-07 13:53:42,338] [INFO] [30145] Missing PRE-PREPARE for REQUEST 1741323218379; ignoring PREPARE
[2025-03-07 13:53:42,338] [INFO] [30145] Received COMMIT: id:1741323218379, from:30089, delay:0.0001s, distance:235.12m (Euclidean)
[2025-03-07 13:53:42,657] [INFO] [30145] Received PREPARE: id:1741323218379, from:30019, delay:0.0002s, distance:251.74m (Euclidean)
[2025-03-07 13:53:42,657] [INFO] [30145] Missing PRE-PREPARE for REQUEST 1741323218379; ignoring PREPARE
[2025-03-07 13:53:42,657] [INFO] [30145] Received COMMIT: id:1741323218379, from:30019, delay:0.0002s, distance:251.74m (Euclidean)
[2025-03-07 13:53:42,824] [INFO] [30145] Received PREPARE: id:1741323218379, from:30099, delay:0.0000s, distance:181.86m (Euclidean)
[2025-03-07 13:53:42,824] [INFO] [30145] Missing PRE-PREPARE for REQUEST 1741323218379; ignoring PREPARE
[2025-03-07 13:53:42,824] [INFO] [30145] Received COMMIT: id:1741323218379, from:30099, delay:0.0000s, distance:181.86m (Euclidean)
[2025-03-07 13:53:42,916] [INFO] [30145] Received PREPARE: id:1741323218379, from:30055, delay:0.0001s, distance:245.99m (Euclidean)
[2025-03-07 13:53:42,916] [INFO] [30145] Missing PRE-PREPARE for REQUEST 1741323218379; ignoring PREPARE
[2025-03-07 13:53:42,916] [INFO] [30145] Received COMMIT: id:1741323218379, from:30055, delay:0.0001s, distance:245.99m (Euclidean)
[2025-03-07 13:53:42,968] [INFO] [30145] Received PREPARE: id:1741323218379, from:30039, delay:0.0002s, distance:286.54m (Euclidean)
[2025-03-07 13:53:42,968] [INFO] [30145] Missing PRE-PREPARE for REQUEST 1741323218379; ignoring PREPARE
[2025-03-07 13:53:42,968] [INFO] [30145] Received COMMIT: id:1741323218379, from:30039, delay:0.0002s, distance:286.54m (Euclidean)
[2025-03-07 13:53:43,110] [INFO] [30145] Received PREPARE: id:1741323218379, from:30088, delay:0.0001s, distance:240.77m (Euclidean)
[2025-03-07 13:53:43,110] [INFO] [30145] Missing PRE-PREPARE for REQUEST 1741323218379; ignoring PREPARE
[2025-03-07 13:53:43,176] [INFO] [30145] Received PREPARE: id:1741323218379, from:30048, delay:0.0002s, distance:292.51m (Euclidean)
[2025-03-07 13:53:43,176] [INFO] [30145] Missing PRE-PREPARE for REQUEST 1741323218379; ignoring PREPARE
[2025-03-07 13:53:43,176] [INFO] [30145] Received COMMIT: id:1741323218379, from:30048, delay:0.0002s, distance:292.51m (Euclidean)
[2025-03-07 13:53:43,216] [INFO] [30145] Received COMMIT: id:1741323218379, from:30088, delay:0.0001s, distance:240.77m (Euclidean)
[2025-03-07 13:53:43,314] [INFO] [30145] Received PREPARE: id:1741323218379, from:30033, delay:0.0002s, distance:274.42m (Euclidean)
[2025-03-07 13:53:43,314] [INFO] [30145] Missing PRE-PREPARE for REQUEST 1741323218379; ignoring PREPARE
[2025-03-07 13:53:43,314] [INFO] [30145] Received COMMIT: id:1741323218379, from:30033, delay:0.0002s, distance:274.42m (Euclidean)
[2025-03-07 13:53:43,446] [INFO] [30145] Received PREPARE: id:1741323218379, from:30016, delay:0.0001s, distance:235.39m (Euclidean)
[2025-03-07 13:53:43,446] [INFO] [30145] Missing PRE-PREPARE for REQUEST 1741323218379; ignoring PREPARE
[2025-03-07 13:53:43,446] [INFO] [30145] Received COMMIT: id:1741323218379, from:30016, delay:0.0001s, distance:235.39m (Euclidean)
[2025-03-07 13:53:43,675] [INFO] [30145] Received PREPARE: id:1741323218379, from:30012, delay:0.0002s, distance:292.95m (Euclidean)
[2025-03-07 13:53:43,675] [INFO] [30145] Missing PRE-PREPARE for REQUEST 1741323218379; ignoring PREPARE
[2025-03-07 13:53:43,675] [INFO] [30145] Received COMMIT: id:1741323218379, from:30012, delay:0.0002s, distance:292.95m (Euclidean)
[2025-03-07 13:53:43,738] [INFO] [30145] Received PREPARE: id:1741323218379, from:30032, delay:0.0000s, distance:171.43m (Euclidean)
[2025-03-07 13:53:43,738] [INFO] [30145] Missing PRE-PREPARE for REQUEST 1741323218379; ignoring PREPARE
[2025-03-07 13:53:43,738] [INFO] [30145] Received COMMIT: id:1741323218379, from:30032, delay:0.0000s, distance:171.43m (Euclidean)
[2025-03-07 13:53:44,039] [INFO] [30145] Received PREPARE: id:1741323218379, from:30078, delay:0.0002s, distance:254.45m (Euclidean)
[2025-03-07 13:53:44,039] [INFO] [30145] Missing PRE-PREPARE for REQUEST 1741323218379; ignoring PREPARE
[2025-03-07 13:53:44,039] [INFO] [30145] Received COMMIT: id:1741323218379, from:30078, delay:0.0002s, distance:254.45m (Euclidean)
[2025-03-07 13:53:44,231] [INFO] [30145] Received PREPARE: id:1741323218379, from:30011, delay:0.0002s, distance:278.99m (Euclidean)
[2025-03-07 13:53:44,231] [INFO] [30145] Missing PRE-PREPARE for REQUEST 1741323218379; ignoring PREPARE
[2025-03-07 13:53:44,231] [INFO] [30145] Received COMMIT: id:1741323218379, from:30044, delay:0.0002s, distance:274.78m (Euclidean)
[2025-03-07 13:53:44,231] [INFO] [30145] Received COMMIT: id:1741323218379, from:30011, delay:0.0002s, distance:278.99m (Euclidean)
[2025-03-07 13:53:44,231] [INFO] [30145] Received PREPARE: id:1741323218379, from:30044, delay:0.0002s, distance:274.78m (Euclidean)
[2025-03-07 13:53:44,231] [INFO] [30145] Missing PRE-PREPARE for REQUEST 1741323218379; ignoring PREPARE
[2025-03-07 13:53:44,309] [INFO] [30145] Received COMMIT: id:1741323218379, from:30024, delay:0.0001s, distance:153.07m (Euclidean)
[2025-03-07 13:53:44,585] [INFO] [30145] Received PREPARE: id:1741323218379, from:30034, delay:0.0001s, distance:247.12m (Euclidean)
[2025-03-07 13:53:44,592] [INFO] [30145] Missing PRE-PREPARE for REQUEST 1741323218379; ignoring PREPARE
[2025-03-07 13:53:44,592] [INFO] [30145] Received COMMIT: id:1741323218379, from:30034, delay:0.0001s, distance:247.12m (Euclidean)
[2025-03-07 13:53:44,617] [INFO] [30145] Received PREPARE: id:1741323218379, from:30013, delay:0.0002s, distance:291.55m (Euclidean)
[2025-03-07 13:53:44,617] [INFO] [30145] Missing PRE-PREPARE for REQUEST 1741323218379; ignoring PREPARE
[2025-03-07 13:53:44,619] [INFO] [30145] Received COMMIT: id:1741323218379, from:30013, delay:0.0002s, distance:291.55m (Euclidean)
[2025-03-07 13:53:44,656] [INFO] [30145] Received PREPARE: id:1741323218379, from:30061, delay:0.0001s, distance:235.83m (Euclidean)
[2025-03-07 13:53:44,656] [INFO] [30145] Missing PRE-PREPARE for REQUEST 1741323218379; ignoring PREPARE
[2025-03-07 13:53:44,656] [INFO] [30145] Received COMMIT: id:1741323218379, from:30061, delay:0.0001s, distance:235.83m (Euclidean)
[2025-03-07 13:53:44,845] [INFO] [30145] Received PREPARE: id:1741323218379, from:30052, delay:0.0001s, distance:190.74m (Euclidean)
[2025-03-07 13:53:44,845] [INFO] [30145] Missing PRE-PREPARE for REQUEST 1741323218379; ignoring PREPARE
[2025-03-07 13:53:44,845] [INFO] [30145] Received COMMIT: id:1741323218379, from:30052, delay:0.0001s, distance:190.74m (Euclidean)
[2025-03-07 13:53:44,849] [INFO] [30145] Received PREPARE: id:1741323218379, from:30073, delay:0.0002s, distance:269.62m (Euclidean)
[2025-03-07 13:53:44,849] [INFO] [30145] Missing PRE-PREPARE for REQUEST 1741323218379; ignoring PREPARE
[2025-03-07 13:53:44,849] [INFO] [30145] Received COMMIT: id:1741323218379, from:30073, delay:0.0002s, distance:269.62m (Euclidean)
[2025-03-07 13:53:45,056] [INFO] [30145] Received PREPARE: id:1741323218379, from:30091, delay:0.0001s, distance:178.83m (Euclidean)
[2025-03-07 13:53:45,056] [INFO] [30145] Missing PRE-PREPARE for REQUEST 1741323218379; ignoring PREPARE
[2025-03-07 13:53:45,209] [INFO] [30145] Received COMMIT: id:1741323218379, from:30091, delay:0.0001s, distance:178.83m (Euclidean)
[2025-03-07 13:53:45,400] [INFO] [30145] Received PREPARE: id:1741323218379, from:30095, delay:0.0001s, distance:182.42m (Euclidean)
[2025-03-07 13:53:45,400] [INFO] [30145] Missing PRE-PREPARE for REQUEST 1741323218379; ignoring PREPARE
[2025-03-07 13:53:45,400] [INFO] [30145] Received COMMIT: id:1741323218379, from:30095, delay:0.0001s, distance:182.42m (Euclidean)
[2025-03-07 13:53:45,419] [INFO] [30145] Received PREPARE: id:1741323218379, from:30094, delay:0.0002s, distance:267.97m (Euclidean)
[2025-03-07 13:53:45,419] [INFO] [30145] Missing PRE-PREPARE for REQUEST 1741323218379; ignoring PREPARE
[2025-03-07 13:53:45,419] [INFO] [30145] Received COMMIT: id:1741323218379, from:30094, delay:0.0002s, distance:267.97m (Euclidean)
[2025-03-07 13:53:45,509] [INFO] [30145] Received PREPARE: id:1741323218379, from:30070, delay:0.0002s, distance:265.50m (Euclidean)
[2025-03-07 13:53:45,509] [INFO] [30145] Missing PRE-PREPARE for REQUEST 1741323218379; ignoring PREPARE
[2025-03-07 13:53:45,509] [INFO] [30145] Received PREPARE: id:1741323218379, from:30043, delay:0.0000s, distance:137.91m (Euclidean)
[2025-03-07 13:53:45,509] [INFO] [30145] Missing PRE-PREPARE for REQUEST 1741323218379; ignoring PREPARE
[2025-03-07 13:53:45,509] [INFO] [30145] Received COMMIT: id:1741323218379, from:30070, delay:0.0002s, distance:265.50m (Euclidean)
[2025-03-07 13:53:45,509] [INFO] [30145] Received COMMIT: id:1741323218379, from:30043, delay:0.0000s, distance:137.91m (Euclidean)
[2025-03-07 13:53:45,541] [INFO] [30145] Received PREPARE: id:1741323218379, from:30036, delay:0.0001s, distance:197.28m (Euclidean)
[2025-03-07 13:53:45,541] [INFO] [30145] Missing PRE-PREPARE for REQUEST 1741323218379; ignoring PREPARE
[2025-03-07 13:53:45,541] [INFO] [30145] Received COMMIT: id:1741323218379, from:30036, delay:0.0001s, distance:197.28m (Euclidean)
[2025-03-07 13:53:45,668] [INFO] [30145] Received PREPARE: id:1741323218379, from:30002, delay:0.0002s, distance:256.51m (Euclidean)
[2025-03-07 13:53:45,668] [INFO] [30145] Missing PRE-PREPARE for REQUEST 1741323218379; ignoring PREPARE
[2025-03-07 13:53:45,668] [INFO] [30145] Received COMMIT: id:1741323218379, from:30046, delay:0.0001s, distance:196.65m (Euclidean)
[2025-03-07 13:53:45,668] [INFO] [30145] Received COMMIT: id:1741323218379, from:30098, delay:0.0001s, distance:225.59m (Euclidean)
[2025-03-07 13:53:45,668] [INFO] [30145] Received COMMIT: id:1741323218379, from:30002, delay:0.0002s, distance:256.51m (Euclidean)
[2025-03-07 13:53:45,668] [INFO] [30145] Received PREPARE: id:1741323218379, from:30046, delay:0.0001s, distance:196.65m (Euclidean)
[2025-03-07 13:53:45,668] [INFO] [30145] Missing PRE-PREPARE for REQUEST 1741323218379; ignoring PREPARE
[2025-03-07 13:53:45,668] [INFO] [30145] Received PREPARE: id:1741323218379, from:30098, delay:0.0001s, distance:225.59m (Euclidean)
[2025-03-07 13:53:45,668] [INFO] [30145] Missing PRE-PREPARE for REQUEST 1741323218379; ignoring PREPARE
[2025-03-07 13:53:45,699] [INFO] [30145] Received PREPARE: id:1741323218379, from:30031, delay:0.0002s, distance:282.06m (Euclidean)
[2025-03-07 13:53:45,699] [INFO] [30145] Missing PRE-PREPARE for REQUEST 1741323218379; ignoring PREPARE
[2025-03-07 13:53:45,699] [INFO] [30145] Received COMMIT: id:1741323218379, from:30031, delay:0.0002s, distance:282.06m (Euclidean)
[2025-03-07 13:53:45,764] [INFO] [30145] Received PREPARE: id:1741323218379, from:30049, delay:0.0002s, distance:275.71m (Euclidean)
[2025-03-07 13:53:45,764] [INFO] [30145] Missing PRE-PREPARE for REQUEST 1741323218379; ignoring PREPARE
[2025-03-07 13:53:45,764] [INFO] [30145] Received COMMIT: id:1741323218379, from:30049, delay:0.0002s, distance:275.71m (Euclidean)
[2025-03-07 13:53:45,916] [INFO] [30145] Received PREPARE: id:1741323218379, from:30102, delay:0.0001s, distance:207.21m (Euclidean)
[2025-03-07 13:53:45,916] [INFO] [30145] Missing PRE-PREPARE for REQUEST 1741323218379; ignoring PREPARE
[2025-03-07 13:53:45,921] [INFO] [30145] Received COMMIT: id:1741323218379, from:30102, delay:0.0001s, distance:207.21m (Euclidean)
[2025-03-07 13:53:45,952] [INFO] [30145] Received PREPARE: id:1741323218379, from:30086, delay:0.0001s, distance:179.91m (Euclidean)
[2025-03-07 13:53:45,952] [INFO] [30145] Missing PRE-PREPARE for REQUEST 1741323218379; ignoring PREPARE
[2025-03-07 13:53:45,952] [INFO] [30145] Received COMMIT: id:1741323218379, from:30086, delay:0.0001s, distance:179.91m (Euclidean)
[2025-03-07 13:53:46,003] [INFO] [30145] Received PREPARE: id:1741323218379, from:30083, delay:0.0002s, distance:296.14m (Euclidean)
[2025-03-07 13:53:46,003] [INFO] [30145] Missing PRE-PREPARE for REQUEST 1741323218379; ignoring PREPARE
[2025-03-07 13:53:46,003] [INFO] [30145] Received COMMIT: id:1741323218379, from:30083, delay:0.0002s, distance:296.14m (Euclidean)
[2025-03-07 13:53:46,363] [INFO] [30145] Received PREPARE: id:1741323218379, from:30042, delay:0.0002s, distance:280.22m (Euclidean)
[2025-03-07 13:53:46,386] [INFO] [30145] Missing PRE-PREPARE for REQUEST 1741323218379; ignoring PREPARE
[2025-03-07 13:53:46,386] [INFO] [30145] Received COMMIT: id:1741323218379, from:30042, delay:0.0002s, distance:280.22m (Euclidean)
[2025-03-07 13:53:46,398] [INFO] [30145] Received PREPARE: id:1741323218379, from:30004, delay:0.0001s, distance:183.54m (Euclidean)
[2025-03-07 13:53:46,398] [INFO] [30145] Missing PRE-PREPARE for REQUEST 1741323218379; ignoring PREPARE
[2025-03-07 13:53:46,412] [INFO] [30145] Received COMMIT: id:1741323218379, from:30004, delay:0.0001s, distance:183.54m (Euclidean)
[2025-03-07 13:53:46,431] [INFO] [30145] Received PREPARE: id:1741323218379, from:30035, delay:0.0001s, distance:231.76m (Euclidean)
[2025-03-07 13:53:46,431] [INFO] [30145] Missing PRE-PREPARE for REQUEST 1741323218379; ignoring PREPARE
[2025-03-07 13:53:46,431] [INFO] [30145] Received COMMIT: id:1741323218379, from:30035, delay:0.0001s, distance:231.76m (Euclidean)
[2025-03-07 13:53:46,433] [INFO] [30145] Received PREPARE: id:1741323218379, from:30104, delay:0.0000s, distance:130.46m (Euclidean)
[2025-03-07 13:53:46,433] [INFO] [30145] Missing PRE-PREPARE for REQUEST 1741323218379; ignoring PREPARE
[2025-03-07 13:53:46,433] [INFO] [30145] Received COMMIT: id:1741323218379, from:30104, delay:0.0000s, distance:130.46m (Euclidean)
[2025-03-07 13:53:46,464] [INFO] [30145] Received PREPARE: id:1741323218379, from:30010, delay:0.0000s, distance:178.13m (Euclidean)
[2025-03-07 13:53:46,464] [INFO] [30145] Missing PRE-PREPARE for REQUEST 1741323218379; ignoring PREPARE
[2025-03-07 13:53:46,464] [INFO] [30145] Received COMMIT: id:1741323218379, from:30010, delay:0.0000s, distance:178.13m (Euclidean)
[2025-03-07 13:53:46,476] [INFO] [30145] Received PREPARE: id:1741323218379, from:30072, delay:0.0002s, distance:267.57m (Euclidean)
[2025-03-07 13:53:46,476] [INFO] [30145] Missing PRE-PREPARE for REQUEST 1741323218379; ignoring PREPARE
[2025-03-07 13:53:46,476] [INFO] [30145] Received COMMIT: id:1741323218379, from:30072, delay:0.0002s, distance:267.57m (Euclidean)
[2025-03-07 13:53:46,649] [INFO] [30145] Received PREPARE: id:1741323218379, from:30001, delay:0.0001s, distance:208.98m (Euclidean)
[2025-03-07 13:53:46,649] [INFO] [30145] Missing PRE-PREPARE for REQUEST 1741323218379; ignoring PREPARE
[2025-03-07 13:53:46,665] [INFO] [30145] Received COMMIT: id:1741323218379, from:30001, delay:0.0001s, distance:208.98m (Euclidean)
[2025-03-07 13:53:46,981] [INFO] [30145] Received PREPARE: id:1741323218379, from:30003, delay:0.0000s, distance:159.05m (Euclidean)
[2025-03-07 13:53:46,981] [INFO] [30145] Missing PRE-PREPARE for REQUEST 1741323218379; ignoring PREPARE
[2025-03-07 13:53:46,983] [INFO] [30145] Received COMMIT: id:1741323218379, from:30003, delay:0.0000s, distance:159.05m (Euclidean)
[2025-03-07 13:53:47,441] [INFO] [30145] Received PREPARE: id:1741323218379, from:30134, delay:0.0002s, distance:257.37m (Euclidean)
[2025-03-07 13:53:47,441] [INFO] [30145] Missing PRE-PREPARE for REQUEST 1741323218379; ignoring PREPARE
[2025-03-07 13:53:47,455] [INFO] [30145] Received COMMIT: id:1741323218379, from:30134, delay:0.0002s, distance:257.37m (Euclidean)
[2025-03-07 13:53:47,455] [INFO] [30145] Received PREPARE: id:1741323218379, from:30122, delay:0.0000s, distance:128.40m (Euclidean)
[2025-03-07 13:53:47,455] [INFO] [30145] Missing PRE-PREPARE for REQUEST 1741323218379; ignoring PREPARE
[2025-03-07 13:53:47,455] [INFO] [30145] Received COMMIT: id:1741323218379, from:30122, delay:0.0000s, distance:128.40m (Euclidean)
[2025-03-07 13:53:47,756] [INFO] [30145] Received PREPARE: id:1741323218379, from:30110, delay:0.0002s, distance:279.82m (Euclidean)
[2025-03-07 13:53:47,756] [INFO] [30145] Missing PRE-PREPARE for REQUEST 1741323218379; ignoring PREPARE
[2025-03-07 13:53:47,756] [INFO] [30145] Received COMMIT: id:1741323218379, from:30110, delay:0.0002s, distance:279.82m (Euclidean)
[2025-03-07 13:53:47,850] [INFO] [30145] Received PREPARE: id:1741323218379, from:30136, delay:0.0002s, distance:283.44m (Euclidean)
[2025-03-07 13:53:47,850] [INFO] [30145] Missing PRE-PREPARE for REQUEST 1741323218379; ignoring PREPARE
[2025-03-07 13:53:47,850] [INFO] [30145] Received COMMIT: id:1741323218379, from:30136, delay:0.0002s, distance:283.44m (Euclidean)
[2025-03-07 13:53:47,882] [INFO] [30145] Received PREPARE: id:1741323218379, from:30153, delay:0.0001s, distance:187.02m (Euclidean)
[2025-03-07 13:53:47,882] [INFO] [30145] Missing PRE-PREPARE for REQUEST 1741323218379; ignoring PREPARE
[2025-03-07 13:53:47,882] [INFO] [30145] Received COMMIT: id:1741323218379, from:30153, delay:0.0001s, distance:187.02m (Euclidean)
[2025-03-07 13:53:47,918] [INFO] [30145] Received PREPARE: id:1741323218379, from:30105, delay:0.0002s, distance:276.97m (Euclidean)
[2025-03-07 13:53:47,918] [INFO] [30145] Missing PRE-PREPARE for REQUEST 1741323218379; ignoring PREPARE
[2025-03-07 13:53:47,918] [INFO] [30145] Received COMMIT: id:1741323218379, from:30105, delay:0.0002s, distance:276.97m (Euclidean)
[2025-03-07 13:53:48,039] [INFO] [30145] Received PREPARE: id:1741323218379, from:30158, delay:0.0002s, distance:288.96m (Euclidean)
[2025-03-07 13:53:48,039] [INFO] [30145] Missing PRE-PREPARE for REQUEST 1741323218379; ignoring PREPARE
[2025-03-07 13:53:48,039] [INFO] [30145] Received COMMIT: id:1741323218379, from:30158, delay:0.0002s, distance:288.96m (Euclidean)
[2025-03-07 13:53:48,249] [INFO] [30145] Received PREPARE: id:1741323218379, from:30147, delay:0.0001s, distance:193.18m (Euclidean)
[2025-03-07 13:53:48,249] [INFO] [30145] Missing PRE-PREPARE for REQUEST 1741323218379; ignoring PREPARE
[2025-03-07 13:53:48,249] [INFO] [30145] Received COMMIT: id:1741323218379, from:30147, delay:0.0001s, distance:193.18m (Euclidean)
[2025-03-07 13:53:48,532] [INFO] [30145] Received PREPARE: id:1741323218379, from:30131, delay:0.0000s, distance:162.46m (Euclidean)
[2025-03-07 13:53:48,532] [INFO] [30145] Missing PRE-PREPARE for REQUEST 1741323218379; ignoring PREPARE
[2025-03-07 13:53:48,532] [INFO] [30145] Received COMMIT: id:1741323218379, from:30131, delay:0.0000s, distance:162.46m (Euclidean)
[2025-03-07 13:53:48,829] [INFO] [30145] Received PREPARE: id:1741323218379, from:30109, delay:0.0001s, distance:189.23m (Euclidean)
[2025-03-07 13:53:48,829] [INFO] [30145] Missing PRE-PREPARE for REQUEST 1741323218379; ignoring PREPARE
[2025-03-07 13:53:48,829] [INFO] [30145] Received COMMIT: id:1741323218379, from:30109, delay:0.0001s, distance:189.23m (Euclidean)
[2025-03-07 13:53:49,193] [INFO] [30145] Received PREPARE: id:1741323218379, from:30144, delay:0.0001s, distance:245.18m (Euclidean)
[2025-03-07 13:53:49,193] [INFO] [30145] Missing PRE-PREPARE for REQUEST 1741323218379; ignoring PREPARE
[2025-03-07 13:53:49,205] [INFO] [30145] Received COMMIT: id:1741323218379, from:30144, delay:0.0001s, distance:245.18m (Euclidean)
[2025-03-07 13:53:49,260] [INFO] [30145] Received PREPARE: id:1741323218379, from:30133, delay:0.0001s, distance:211.78m (Euclidean)
[2025-03-07 13:53:49,260] [INFO] [30145] Missing PRE-PREPARE for REQUEST 1741323218379; ignoring PREPARE
[2025-03-07 13:53:49,272] [INFO] [30145] Received COMMIT: id:1741323218379, from:30133, delay:0.0001s, distance:211.78m (Euclidean)
[2025-03-07 13:53:49,437] [INFO] [30145] Received PREPARE: id:1741323218379, from:30148, delay:0.0000s, distance:136.91m (Euclidean)
[2025-03-07 13:53:49,437] [INFO] [30145] Missing PRE-PREPARE for REQUEST 1741323218379; ignoring PREPARE
[2025-03-07 13:53:49,648] [INFO] [30145] Received PREPARE: id:1741323218379, from:30112, delay:0.0002s, distance:258.72m (Euclidean)
[2025-03-07 13:53:49,648] [INFO] [30145] Missing PRE-PREPARE for REQUEST 1741323218379; ignoring PREPARE
[2025-03-07 13:53:49,648] [INFO] [30145] Received COMMIT: id:1741323218379, from:30112, delay:0.0002s, distance:258.72m (Euclidean)
[2025-03-07 13:53:49,657] [INFO] [30145] Received COMMIT: id:1741323218379, from:30148, delay:0.0000s, distance:136.91m (Euclidean)
[2025-03-07 13:53:50,118] [INFO] [30145] Received PREPARE: id:1741323218379, from:30126, delay:0.0000s, distance:126.29m (Euclidean)
[2025-03-07 13:53:50,118] [INFO] [30145] Missing PRE-PREPARE for REQUEST 1741323218379; ignoring PREPARE
[2025-03-07 13:53:50,118] [INFO] [30145] Received COMMIT: id:1741323218379, from:30126, delay:0.0000s, distance:126.29m (Euclidean)
[2025-03-07 13:53:50,217] [INFO] [30145] Received PREPARE: id:1741323218379, from:30114, delay:0.0000s, distance:94.37m (Euclidean)
[2025-03-07 13:53:50,217] [INFO] [30145] Missing PRE-PREPARE for REQUEST 1741323218379; ignoring PREPARE
[2025-03-07 13:53:50,222] [INFO] [30145] Received COMMIT: id:1741323218379, from:30114, delay:0.0000s, distance:94.37m (Euclidean)
[2025-03-07 13:53:50,722] [INFO] [30145] Received PREPARE: id:1741323218379, from:30015, delay:0.0001s, distance:241.86m (Euclidean)
[2025-03-07 13:53:50,722] [INFO] [30145] Missing PRE-PREPARE for REQUEST 1741323218379; ignoring PREPARE
[2025-03-07 13:53:50,724] [INFO] [30145] Received COMMIT: id:1741323218379, from:30015, delay:0.0001s, distance:241.86m (Euclidean)
[2025-03-07 13:53:50,759] [INFO] [30145] Received PREPARE: id:1741323218379, from:30129, delay:0.0000s, distance:118.95m (Euclidean)
[2025-03-07 13:53:50,807] [INFO] [30145] Missing PRE-PREPARE for REQUEST 1741323218379; ignoring PREPARE
[2025-03-07 13:53:50,807] [INFO] [30145] Received COMMIT: id:1741323218379, from:30129, delay:0.0000s, distance:118.95m (Euclidean)
[2025-03-07 13:53:50,870] [INFO] [30145] Received PRE-PREPARE: id:1741323218379, from:Leader(30000), delay:0.0000s, distance:192.34m (Euclidean)
[2025-03-07 13:53:50,870] [INFO] [30145] Broadcasting PREPARE for REQUEST 1741323218379
[2025-03-07 13:53:50,905] [INFO] [30145] Received COMMIT: id:1741323218379, from:30000, delay:0.0000s, distance:192.34m (Euclidean)
[2025-03-07 13:53:50,965] [INFO] [30145] Received PREPARE: id:1741323218379, from:30130, delay:0.0002s, distance:262.79m (Euclidean)
[2025-03-07 13:53:50,965] [INFO] [30145] Broadcasting COMMIT for REQUEST 1741323218379
[2025-03-07 13:53:51,020] [INFO] [30145] Received COMMIT: id:1741323218379, from:30130, delay:0.0002s, distance:262.79m (Euclidean)
[2025-03-07 13:53:51,347] [INFO] [30145] Received PREPARE: id:1741323218379, from:30115, delay:0.0000s, distance:150.15m (Euclidean)
[2025-03-07 13:53:51,803] [INFO] [30145] Received COMMIT: id:1741323218379, from:30115, delay:0.0000s, distance:150.15m (Euclidean)
[2025-03-07 13:53:52,291] [INFO] [30145] Received PREPARE: id:1741323218379, from:30116, delay:0.0002s, distance:269.68m (Euclidean)
[2025-03-07 13:53:52,359] [INFO] [30145] Received COMMIT: id:1741323218379, from:30116, delay:0.0002s, distance:269.68m (Euclidean)
[2025-03-07 13:53:53,038] [INFO] [30145] Received PREPARE: id:1741323218379, from:30118, delay:0.0001s, distance:242.33m (Euclidean)
[2025-03-07 13:53:53,038] [INFO] [30145] Received COMMIT: id:1741323218379, from:30118, delay:0.0001s, distance:242.33m (Euclidean)
[2025-03-07 13:53:53,226] [INFO] [30145] Received PREPARE: id:1741323218379, from:30142, delay:0.0000s, distance:144.82m (Euclidean)
[2025-03-07 13:53:53,242] [INFO] [30145] Received COMMIT: id:1741323218379, from:30142, delay:0.0000s, distance:144.82m (Euclidean)
[2025-03-07 13:53:53,321] [INFO] [30145] Received PREPARE: id:1741323218379, from:30120, delay:0.0000s, distance:104.96m (Euclidean)
[2025-03-07 13:53:53,341] [INFO] [30145] Received PREPARE: id:1741323218379, from:30121, delay:0.0002s, distance:271.19m (Euclidean)
[2025-03-07 13:53:53,341] [INFO] [30145] Received COMMIT: id:1741323218379, from:30121, delay:0.0002s, distance:271.19m (Euclidean)
[2025-03-07 13:53:53,374] [INFO] [30145] Received PREPARE: id:1741323218379, from:30155, delay:0.0000s, distance:67.45m (Euclidean)
[2025-03-07 13:53:53,374] [INFO] [30145] Received COMMIT: id:1741323218379, from:30155, delay:0.0000s, distance:67.45m (Euclidean)
[2025-03-07 13:53:53,590] [INFO] [30145] Received PREPARE: id:1741323218379, from:30113, delay:0.0000s, distance:198.98m (Euclidean)
[2025-03-07 13:53:53,590] [INFO] [30145] Received COMMIT: id:1741323218379, from:30113, delay:0.0000s, distance:198.98m (Euclidean)
[2025-03-07 13:53:53,860] [INFO] [30145] Received PREPARE: id:1741323218379, from:30149, delay:0.0002s, distance:274.56m (Euclidean)
[2025-03-07 13:53:53,860] [INFO] [30145] Received COMMIT: id:1741323218379, from:30149, delay:0.0002s, distance:274.56m (Euclidean)
[2025-03-07 13:53:54,182] [INFO] [30145] Received PREPARE: id:1741323218379, from:30132, delay:0.0000s, distance:79.17m (Euclidean)
[2025-03-07 13:53:54,182] [INFO] [30145] Received COMMIT: id:1741323218379, from:30132, delay:0.0000s, distance:79.17m (Euclidean)
[2025-03-07 13:53:54,217] [INFO] [30145] Received COMMIT: id:1741323218379, from:30120, delay:0.0000s, distance:104.96m (Euclidean)
[2025-03-07 13:53:54,321] [INFO] [30145] Received PREPARE: id:1741323218379, from:30152, delay:0.0001s, distance:221.48m (Euclidean)
[2025-03-07 13:53:54,334] [INFO] [30145] Received COMMIT: id:1741323218379, from:30152, delay:0.0001s, distance:221.48m (Euclidean)
[2025-03-07 13:53:54,368] [INFO] [30145] Received PREPARE: id:1741323218379, from:30108, delay:0.0001s, distance:227.26m (Euclidean)
[2025-03-07 13:53:54,370] [INFO] [30145] Received COMMIT: id:1741323218379, from:30108, delay:0.0001s, distance:227.26m (Euclidean)
[2025-03-07 13:53:54,405] [INFO] [30145] Received PREPARE: id:1741323218379, from:30159, delay:0.0001s, distance:223.47m (Euclidean)
[2025-03-07 13:53:54,453] [INFO] [30145] Received PREPARE: id:1741323218379, from:30111, delay:0.0001s, distance:285.72m (Euclidean)
[2025-03-07 13:53:54,475] [INFO] [30145] Received PREPARE: id:1741323218379, from:30146, delay:0.0002s, distance:273.61m (Euclidean)
[2025-03-07 13:53:54,485] [INFO] [30145] Received COMMIT: id:1741323218379, from:30111, delay:0.0001s, distance:285.72m (Euclidean)
[2025-03-07 13:53:54,493] [INFO] [30145] Received COMMIT: id:1741323218379, from:30146, delay:0.0002s, distance:273.61m (Euclidean)
[2025-03-07 13:53:54,543] [INFO] [30145] Received PREPARE: id:1741323218379, from:30156, delay:0.0001s, distance:151.98m (Euclidean)
[2025-03-07 13:53:54,554] [INFO] [30145] Received COMMIT: id:1741323218379, from:30156, delay:0.0001s, distance:151.98m (Euclidean)
[2025-03-07 13:53:55,206] [ERROR] [30145] Error sending to http://localhost:30140/prepare: Cannot connect to host localhost:30140 ssl:default [Connect call failed ('127.0.0.1', 30140)]
Traceback (most recent call last):
  File "D:\anaconda\envs\PBFT\lib\site-packages\aiohttp\connector.py", line 980, in _wrap_create_connection
    return await self._loop.create_connection(*args, **kwargs)  # type: ignore[return-value]  # noqa
  File "D:\anaconda\envs\PBFT\lib\asyncio\base_events.py", line 948, in create_connection
    raise exceptions[0]
  File "D:\anaconda\envs\PBFT\lib\asyncio\base_events.py", line 935, in create_connection
    await self.sock_connect(sock, address)
  File "D:\anaconda\envs\PBFT\lib\asyncio\selector_events.py", line 475, in sock_connect
    return await fut
  File "D:\anaconda\envs\PBFT\lib\asyncio\selector_events.py", line 505, in _sock_connect_cb
    raise OSError(err, f'Connect call failed {address}')
ConnectionRefusedError: [Errno 10061] Connect call failed ('127.0.0.1', 30140)

The above exception was the direct cause of the following exception:

Traceback (most recent call last):
  File "pbft.py", line 236, in send_message
    await send_with_delay(self.session, self.node_info, target, url, data, self.bandwidth_data)
  File "pbft.py", line 63, in send_with_delay
    async with session.post(url, json=data) as resp:
  File "D:\anaconda\envs\PBFT\lib\site-packages\aiohttp\client.py", line 1141, in __aenter__
    self._resp = await self._coro
  File "D:\anaconda\envs\PBFT\lib\site-packages\aiohttp\client.py", line 537, in _request
    req, traces=traces, timeout=real_timeout
  File "D:\anaconda\envs\PBFT\lib\site-packages\aiohttp\connector.py", line 540, in connect
    proto = await self._create_connection(req, traces, timeout)
  File "D:\anaconda\envs\PBFT\lib\site-packages\aiohttp\connector.py", line 901, in _create_connection
    _, proto = await self._create_direct_connection(req, traces, timeout)
  File "D:\anaconda\envs\PBFT\lib\site-packages\aiohttp\connector.py", line 1206, in _create_direct_connection
    raise last_exc
  File "D:\anaconda\envs\PBFT\lib\site-packages\aiohttp\connector.py", line 1187, in _create_direct_connection
    client_error=client_error,
  File "D:\anaconda\envs\PBFT\lib\site-packages\aiohttp\connector.py", line 988, in _wrap_create_connection
    raise client_error(req.connection_key, exc) from exc
aiohttp.client_exceptions.ClientConnectorError: Cannot connect to host localhost:30140 ssl:default [Connect call failed ('127.0.0.1', 30140)]
[2025-03-07 13:53:55,249] [ERROR] [30145] Error sending to http://localhost:30038/prepare: Cannot connect to host localhost:30038 ssl:default [Connect call failed ('127.0.0.1', 30038)]
Traceback (most recent call last):
  File "D:\anaconda\envs\PBFT\lib\site-packages\aiohttp\connector.py", line 980, in _wrap_create_connection
    return await self._loop.create_connection(*args, **kwargs)  # type: ignore[return-value]  # noqa
  File "D:\anaconda\envs\PBFT\lib\asyncio\base_events.py", line 948, in create_connection
    raise exceptions[0]
  File "D:\anaconda\envs\PBFT\lib\asyncio\base_events.py", line 935, in create_connection
    await self.sock_connect(sock, address)
  File "D:\anaconda\envs\PBFT\lib\asyncio\selector_events.py", line 475, in sock_connect
    return await fut
  File "D:\anaconda\envs\PBFT\lib\asyncio\selector_events.py", line 505, in _sock_connect_cb
    raise OSError(err, f'Connect call failed {address}')
ConnectionRefusedError: [Errno 10061] Connect call failed ('127.0.0.1', 30038)

The above exception was the direct cause of the following exception:

Traceback (most recent call last):
  File "pbft.py", line 236, in send_message
    await send_with_delay(self.session, self.node_info, target, url, data, self.bandwidth_data)
  File "pbft.py", line 63, in send_with_delay
    async with session.post(url, json=data) as resp:
  File "D:\anaconda\envs\PBFT\lib\site-packages\aiohttp\client.py", line 1141, in __aenter__
    self._resp = await self._coro
  File "D:\anaconda\envs\PBFT\lib\site-packages\aiohttp\client.py", line 537, in _request
    req, traces=traces, timeout=real_timeout
  File "D:\anaconda\envs\PBFT\lib\site-packages\aiohttp\connector.py", line 540, in connect
    proto = await self._create_connection(req, traces, timeout)
  File "D:\anaconda\envs\PBFT\lib\site-packages\aiohttp\connector.py", line 901, in _create_connection
    _, proto = await self._create_direct_connection(req, traces, timeout)
  File "D:\anaconda\envs\PBFT\lib\site-packages\aiohttp\connector.py", line 1206, in _create_direct_connection
    raise last_exc
  File "D:\anaconda\envs\PBFT\lib\site-packages\aiohttp\connector.py", line 1187, in _create_direct_connection
    client_error=client_error,
  File "D:\anaconda\envs\PBFT\lib\site-packages\aiohttp\connector.py", line 988, in _wrap_create_connection
    raise client_error(req.connection_key, exc) from exc
aiohttp.client_exceptions.ClientConnectorError: Cannot connect to host localhost:30038 ssl:default [Connect call failed ('127.0.0.1', 30038)]
[2025-03-07 13:53:55,265] [ERROR] [30145] Error sending to http://localhost:30103/prepare: Cannot connect to host localhost:30103 ssl:default [Connect call failed ('127.0.0.1', 30103)]
Traceback (most recent call last):
  File "D:\anaconda\envs\PBFT\lib\site-packages\aiohttp\connector.py", line 980, in _wrap_create_connection
    return await self._loop.create_connection(*args, **kwargs)  # type: ignore[return-value]  # noqa
  File "D:\anaconda\envs\PBFT\lib\asyncio\base_events.py", line 948, in create_connection
    raise exceptions[0]
  File "D:\anaconda\envs\PBFT\lib\asyncio\base_events.py", line 935, in create_connection
    await self.sock_connect(sock, address)
  File "D:\anaconda\envs\PBFT\lib\asyncio\selector_events.py", line 475, in sock_connect
    return await fut
  File "D:\anaconda\envs\PBFT\lib\asyncio\selector_events.py", line 505, in _sock_connect_cb
    raise OSError(err, f'Connect call failed {address}')
ConnectionRefusedError: [Errno 10061] Connect call failed ('127.0.0.1', 30103)

The above exception was the direct cause of the following exception:

Traceback (most recent call last):
  File "pbft.py", line 236, in send_message
    await send_with_delay(self.session, self.node_info, target, url, data, self.bandwidth_data)
  File "pbft.py", line 63, in send_with_delay
    async with session.post(url, json=data) as resp:
  File "D:\anaconda\envs\PBFT\lib\site-packages\aiohttp\client.py", line 1141, in __aenter__
    self._resp = await self._coro
  File "D:\anaconda\envs\PBFT\lib\site-packages\aiohttp\client.py", line 537, in _request
    req, traces=traces, timeout=real_timeout
  File "D:\anaconda\envs\PBFT\lib\site-packages\aiohttp\connector.py", line 540, in connect
    proto = await self._create_connection(req, traces, timeout)
  File "D:\anaconda\envs\PBFT\lib\site-packages\aiohttp\connector.py", line 901, in _create_connection
    _, proto = await self._create_direct_connection(req, traces, timeout)
  File "D:\anaconda\envs\PBFT\lib\site-packages\aiohttp\connector.py", line 1206, in _create_direct_connection
    raise last_exc
  File "D:\anaconda\envs\PBFT\lib\site-packages\aiohttp\connector.py", line 1187, in _create_direct_connection
    client_error=client_error,
  File "D:\anaconda\envs\PBFT\lib\site-packages\aiohttp\connector.py", line 988, in _wrap_create_connection
    raise client_error(req.connection_key, exc) from exc
aiohttp.client_exceptions.ClientConnectorError: Cannot connect to host localhost:30103 ssl:default [Connect call failed ('127.0.0.1', 30103)]
[2025-03-07 13:53:55,297] [ERROR] [30145] Error sending to http://localhost:30066/prepare: Cannot connect to host localhost:30066 ssl:default [Connect call failed ('127.0.0.1', 30066)]
Traceback (most recent call last):
  File "D:\anaconda\envs\PBFT\lib\site-packages\aiohttp\connector.py", line 980, in _wrap_create_connection
    return await self._loop.create_connection(*args, **kwargs)  # type: ignore[return-value]  # noqa
  File "D:\anaconda\envs\PBFT\lib\asyncio\base_events.py", line 948, in create_connection
    raise exceptions[0]
  File "D:\anaconda\envs\PBFT\lib\asyncio\base_events.py", line 935, in create_connection
    await self.sock_connect(sock, address)
  File "D:\anaconda\envs\PBFT\lib\asyncio\selector_events.py", line 475, in sock_connect
    return await fut
  File "D:\anaconda\envs\PBFT\lib\asyncio\selector_events.py", line 505, in _sock_connect_cb
    raise OSError(err, f'Connect call failed {address}')
ConnectionRefusedError: [Errno 10061] Connect call failed ('127.0.0.1', 30066)

The above exception was the direct cause of the following exception:

Traceback (most recent call last):
  File "pbft.py", line 236, in send_message
    await send_with_delay(self.session, self.node_info, target, url, data, self.bandwidth_data)
  File "pbft.py", line 63, in send_with_delay
    async with session.post(url, json=data) as resp:
  File "D:\anaconda\envs\PBFT\lib\site-packages\aiohttp\client.py", line 1141, in __aenter__
    self._resp = await self._coro
  File "D:\anaconda\envs\PBFT\lib\site-packages\aiohttp\client.py", line 537, in _request
    req, traces=traces, timeout=real_timeout
  File "D:\anaconda\envs\PBFT\lib\site-packages\aiohttp\connector.py", line 540, in connect
    proto = await self._create_connection(req, traces, timeout)
  File "D:\anaconda\envs\PBFT\lib\site-packages\aiohttp\connector.py", line 901, in _create_connection
    _, proto = await self._create_direct_connection(req, traces, timeout)
  File "D:\anaconda\envs\PBFT\lib\site-packages\aiohttp\connector.py", line 1206, in _create_direct_connection
    raise last_exc
  File "D:\anaconda\envs\PBFT\lib\site-packages\aiohttp\connector.py", line 1187, in _create_direct_connection
    client_error=client_error,
  File "D:\anaconda\envs\PBFT\lib\site-packages\aiohttp\connector.py", line 988, in _wrap_create_connection
    raise client_error(req.connection_key, exc) from exc
aiohttp.client_exceptions.ClientConnectorError: Cannot connect to host localhost:30066 ssl:default [Connect call failed ('127.0.0.1', 30066)]
[2025-03-07 13:53:55,329] [ERROR] [30145] Error sending to http://localhost:30023/prepare: Cannot connect to host localhost:30023 ssl:default [Connect call failed ('127.0.0.1', 30023)]
Traceback (most recent call last):
  File "D:\anaconda\envs\PBFT\lib\site-packages\aiohttp\connector.py", line 980, in _wrap_create_connection
    return await self._loop.create_connection(*args, **kwargs)  # type: ignore[return-value]  # noqa
  File "D:\anaconda\envs\PBFT\lib\asyncio\base_events.py", line 948, in create_connection
    raise exceptions[0]
  File "D:\anaconda\envs\PBFT\lib\asyncio\base_events.py", line 935, in create_connection
    await self.sock_connect(sock, address)
  File "D:\anaconda\envs\PBFT\lib\asyncio\selector_events.py", line 475, in sock_connect
    return await fut
  File "D:\anaconda\envs\PBFT\lib\asyncio\selector_events.py", line 505, in _sock_connect_cb
    raise OSError(err, f'Connect call failed {address}')
ConnectionRefusedError: [Errno 10061] Connect call failed ('127.0.0.1', 30023)

The above exception was the direct cause of the following exception:

Traceback (most recent call last):
  File "pbft.py", line 236, in send_message
    await send_with_delay(self.session, self.node_info, target, url, data, self.bandwidth_data)
  File "pbft.py", line 63, in send_with_delay
    async with session.post(url, json=data) as resp:
  File "D:\anaconda\envs\PBFT\lib\site-packages\aiohttp\client.py", line 1141, in __aenter__
    self._resp = await self._coro
  File "D:\anaconda\envs\PBFT\lib\site-packages\aiohttp\client.py", line 537, in _request
    req, traces=traces, timeout=real_timeout
  File "D:\anaconda\envs\PBFT\lib\site-packages\aiohttp\connector.py", line 540, in connect
    proto = await self._create_connection(req, traces, timeout)
  File "D:\anaconda\envs\PBFT\lib\site-packages\aiohttp\connector.py", line 901, in _create_connection
    _, proto = await self._create_direct_connection(req, traces, timeout)
  File "D:\anaconda\envs\PBFT\lib\site-packages\aiohttp\connector.py", line 1206, in _create_direct_connection
    raise last_exc
  File "D:\anaconda\envs\PBFT\lib\site-packages\aiohttp\connector.py", line 1187, in _create_direct_connection
    client_error=client_error,
  File "D:\anaconda\envs\PBFT\lib\site-packages\aiohttp\connector.py", line 988, in _wrap_create_connection
    raise client_error(req.connection_key, exc) from exc
aiohttp.client_exceptions.ClientConnectorError: Cannot connect to host localhost:30023 ssl:default [Connect call failed ('127.0.0.1', 30023)]
[2025-03-07 13:53:55,424] [ERROR] [30145] Error sending to http://localhost:30025/prepare: Cannot connect to host localhost:30025 ssl:default [Connect call failed ('127.0.0.1', 30025)]
Traceback (most recent call last):
  File "D:\anaconda\envs\PBFT\lib\site-packages\aiohttp\connector.py", line 980, in _wrap_create_connection
    return await self._loop.create_connection(*args, **kwargs)  # type: ignore[return-value]  # noqa
  File "D:\anaconda\envs\PBFT\lib\asyncio\base_events.py", line 948, in create_connection
    raise exceptions[0]
  File "D:\anaconda\envs\PBFT\lib\asyncio\base_events.py", line 935, in create_connection
    await self.sock_connect(sock, address)
  File "D:\anaconda\envs\PBFT\lib\asyncio\selector_events.py", line 475, in sock_connect
    return await fut
  File "D:\anaconda\envs\PBFT\lib\asyncio\selector_events.py", line 505, in _sock_connect_cb
    raise OSError(err, f'Connect call failed {address}')
ConnectionRefusedError: [Errno 10061] Connect call failed ('127.0.0.1', 30025)

The above exception was the direct cause of the following exception:

Traceback (most recent call last):
  File "pbft.py", line 236, in send_message
    await send_with_delay(self.session, self.node_info, target, url, data, self.bandwidth_data)
  File "pbft.py", line 63, in send_with_delay
    async with session.post(url, json=data) as resp:
  File "D:\anaconda\envs\PBFT\lib\site-packages\aiohttp\client.py", line 1141, in __aenter__
    self._resp = await self._coro
  File "D:\anaconda\envs\PBFT\lib\site-packages\aiohttp\client.py", line 537, in _request
    req, traces=traces, timeout=real_timeout
  File "D:\anaconda\envs\PBFT\lib\site-packages\aiohttp\connector.py", line 540, in connect
    proto = await self._create_connection(req, traces, timeout)
  File "D:\anaconda\envs\PBFT\lib\site-packages\aiohttp\connector.py", line 901, in _create_connection
    _, proto = await self._create_direct_connection(req, traces, timeout)
  File "D:\anaconda\envs\PBFT\lib\site-packages\aiohttp\connector.py", line 1206, in _create_direct_connection
    raise last_exc
  File "D:\anaconda\envs\PBFT\lib\site-packages\aiohttp\connector.py", line 1187, in _create_direct_connection
    client_error=client_error,
  File "D:\anaconda\envs\PBFT\lib\site-packages\aiohttp\connector.py", line 988, in _wrap_create_connection
    raise client_error(req.connection_key, exc) from exc
aiohttp.client_exceptions.ClientConnectorError: Cannot connect to host localhost:30025 ssl:default [Connect call failed ('127.0.0.1', 30025)]
[2025-03-07 13:53:55,431] [INFO] [30145] Received COMMIT: id:1741323218379, from:30159, delay:0.0001s, distance:223.47m (Euclidean)
[2025-03-07 13:53:55,468] [ERROR] [30145] Error sending to http://localhost:30027/prepare: Cannot connect to host localhost:30027 ssl:default [Connect call failed ('127.0.0.1', 30027)]
Traceback (most recent call last):
  File "D:\anaconda\envs\PBFT\lib\site-packages\aiohttp\connector.py", line 980, in _wrap_create_connection
    return await self._loop.create_connection(*args, **kwargs)  # type: ignore[return-value]  # noqa
  File "D:\anaconda\envs\PBFT\lib\asyncio\base_events.py", line 948, in create_connection
    raise exceptions[0]
  File "D:\anaconda\envs\PBFT\lib\asyncio\base_events.py", line 935, in create_connection
    await self.sock_connect(sock, address)
  File "D:\anaconda\envs\PBFT\lib\asyncio\selector_events.py", line 475, in sock_connect
    return await fut
  File "D:\anaconda\envs\PBFT\lib\asyncio\selector_events.py", line 505, in _sock_connect_cb
    raise OSError(err, f'Connect call failed {address}')
ConnectionRefusedError: [Errno 10061] Connect call failed ('127.0.0.1', 30027)

The above exception was the direct cause of the following exception:

Traceback (most recent call last):
  File "pbft.py", line 236, in send_message
    await send_with_delay(self.session, self.node_info, target, url, data, self.bandwidth_data)
  File "pbft.py", line 63, in send_with_delay
    async with session.post(url, json=data) as resp:
  File "D:\anaconda\envs\PBFT\lib\site-packages\aiohttp\client.py", line 1141, in __aenter__
    self._resp = await self._coro
  File "D:\anaconda\envs\PBFT\lib\site-packages\aiohttp\client.py", line 537, in _request
    req, traces=traces, timeout=real_timeout
  File "D:\anaconda\envs\PBFT\lib\site-packages\aiohttp\connector.py", line 540, in connect
    proto = await self._create_connection(req, traces, timeout)
  File "D:\anaconda\envs\PBFT\lib\site-packages\aiohttp\connector.py", line 901, in _create_connection
    _, proto = await self._create_direct_connection(req, traces, timeout)
  File "D:\anaconda\envs\PBFT\lib\site-packages\aiohttp\connector.py", line 1206, in _create_direct_connection
    raise last_exc
  File "D:\anaconda\envs\PBFT\lib\site-packages\aiohttp\connector.py", line 1187, in _create_direct_connection
    client_error=client_error,
  File "D:\anaconda\envs\PBFT\lib\site-packages\aiohttp\connector.py", line 988, in _wrap_create_connection
    raise client_error(req.connection_key, exc) from exc
aiohttp.client_exceptions.ClientConnectorError: Cannot connect to host localhost:30027 ssl:default [Connect call failed ('127.0.0.1', 30027)]
[2025-03-07 13:53:55,708] [ERROR] [30145] Error sending to http://localhost:30100/prepare: Cannot connect to host localhost:30100 ssl:default [Connect call failed ('127.0.0.1', 30100)]
Traceback (most recent call last):
  File "D:\anaconda\envs\PBFT\lib\site-packages\aiohttp\connector.py", line 980, in _wrap_create_connection
    return await self._loop.create_connection(*args, **kwargs)  # type: ignore[return-value]  # noqa
  File "D:\anaconda\envs\PBFT\lib\asyncio\base_events.py", line 948, in create_connection
    raise exceptions[0]
  File "D:\anaconda\envs\PBFT\lib\asyncio\base_events.py", line 935, in create_connection
    await self.sock_connect(sock, address)
  File "D:\anaconda\envs\PBFT\lib\asyncio\selector_events.py", line 475, in sock_connect
    return await fut
  File "D:\anaconda\envs\PBFT\lib\asyncio\selector_events.py", line 505, in _sock_connect_cb
    raise OSError(err, f'Connect call failed {address}')
ConnectionRefusedError: [Errno 10061] Connect call failed ('127.0.0.1', 30100)

The above exception was the direct cause of the following exception:

Traceback (most recent call last):
  File "pbft.py", line 236, in send_message
    await send_with_delay(self.session, self.node_info, target, url, data, self.bandwidth_data)
  File "pbft.py", line 63, in send_with_delay
    async with session.post(url, json=data) as resp:
  File "D:\anaconda\envs\PBFT\lib\site-packages\aiohttp\client.py", line 1141, in __aenter__
    self._resp = await self._coro
  File "D:\anaconda\envs\PBFT\lib\site-packages\aiohttp\client.py", line 537, in _request
    req, traces=traces, timeout=real_timeout
  File "D:\anaconda\envs\PBFT\lib\site-packages\aiohttp\connector.py", line 540, in connect
    proto = await self._create_connection(req, traces, timeout)
  File "D:\anaconda\envs\PBFT\lib\site-packages\aiohttp\connector.py", line 901, in _create_connection
    _, proto = await self._create_direct_connection(req, traces, timeout)
  File "D:\anaconda\envs\PBFT\lib\site-packages\aiohttp\connector.py", line 1206, in _create_direct_connection
    raise last_exc
  File "D:\anaconda\envs\PBFT\lib\site-packages\aiohttp\connector.py", line 1187, in _create_direct_connection
    client_error=client_error,
  File "D:\anaconda\envs\PBFT\lib\site-packages\aiohttp\connector.py", line 988, in _wrap_create_connection
    raise client_error(req.connection_key, exc) from exc
aiohttp.client_exceptions.ClientConnectorError: Cannot connect to host localhost:30100 ssl:default [Connect call failed ('127.0.0.1', 30100)]
[2025-03-07 13:53:55,771] [ERROR] [30145] Error sending to http://localhost:30101/prepare: Cannot connect to host localhost:30101 ssl:default [Connect call failed ('127.0.0.1', 30101)]
Traceback (most recent call last):
  File "D:\anaconda\envs\PBFT\lib\site-packages\aiohttp\connector.py", line 980, in _wrap_create_connection
    return await self._loop.create_connection(*args, **kwargs)  # type: ignore[return-value]  # noqa
  File "D:\anaconda\envs\PBFT\lib\asyncio\base_events.py", line 948, in create_connection
    raise exceptions[0]
  File "D:\anaconda\envs\PBFT\lib\asyncio\base_events.py", line 935, in create_connection
    await self.sock_connect(sock, address)
  File "D:\anaconda\envs\PBFT\lib\asyncio\selector_events.py", line 475, in sock_connect
    return await fut
  File "D:\anaconda\envs\PBFT\lib\asyncio\selector_events.py", line 505, in _sock_connect_cb
    raise OSError(err, f'Connect call failed {address}')
ConnectionRefusedError: [Errno 10061] Connect call failed ('127.0.0.1', 30101)

The above exception was the direct cause of the following exception:

Traceback (most recent call last):
  File "pbft.py", line 236, in send_message
    await send_with_delay(self.session, self.node_info, target, url, data, self.bandwidth_data)
  File "pbft.py", line 63, in send_with_delay
    async with session.post(url, json=data) as resp:
  File "D:\anaconda\envs\PBFT\lib\site-packages\aiohttp\client.py", line 1141, in __aenter__
    self._resp = await self._coro
  File "D:\anaconda\envs\PBFT\lib\site-packages\aiohttp\client.py", line 537, in _request
    req, traces=traces, timeout=real_timeout
  File "D:\anaconda\envs\PBFT\lib\site-packages\aiohttp\connector.py", line 540, in connect
    proto = await self._create_connection(req, traces, timeout)
  File "D:\anaconda\envs\PBFT\lib\site-packages\aiohttp\connector.py", line 901, in _create_connection
    _, proto = await self._create_direct_connection(req, traces, timeout)
  File "D:\anaconda\envs\PBFT\lib\site-packages\aiohttp\connector.py", line 1206, in _create_direct_connection
    raise last_exc
  File "D:\anaconda\envs\PBFT\lib\site-packages\aiohttp\connector.py", line 1187, in _create_direct_connection
    client_error=client_error,
  File "D:\anaconda\envs\PBFT\lib\site-packages\aiohttp\connector.py", line 988, in _wrap_create_connection
    raise client_error(req.connection_key, exc) from exc
aiohttp.client_exceptions.ClientConnectorError: Cannot connect to host localhost:30101 ssl:default [Connect call failed ('127.0.0.1', 30101)]
[2025-03-07 13:53:55,978] [ERROR] [30145] Error sending to http://localhost:30038/commit: Cannot connect to host localhost:30038 ssl:default [Connect call failed ('::1', 30038, 0, 0)]
Traceback (most recent call last):
  File "D:\anaconda\envs\PBFT\lib\site-packages\aiohttp\connector.py", line 980, in _wrap_create_connection
    return await self._loop.create_connection(*args, **kwargs)  # type: ignore[return-value]  # noqa
  File "D:\anaconda\envs\PBFT\lib\asyncio\base_events.py", line 948, in create_connection
    raise exceptions[0]
  File "D:\anaconda\envs\PBFT\lib\asyncio\base_events.py", line 935, in create_connection
    await self.sock_connect(sock, address)
  File "D:\anaconda\envs\PBFT\lib\asyncio\selector_events.py", line 475, in sock_connect
    return await fut
  File "D:\anaconda\envs\PBFT\lib\asyncio\selector_events.py", line 505, in _sock_connect_cb
    raise OSError(err, f'Connect call failed {address}')
ConnectionRefusedError: [Errno 10061] Connect call failed ('::1', 30038, 0, 0)

The above exception was the direct cause of the following exception:

Traceback (most recent call last):
  File "pbft.py", line 236, in send_message
    await send_with_delay(self.session, self.node_info, target, url, data, self.bandwidth_data)
  File "pbft.py", line 63, in send_with_delay
    async with session.post(url, json=data) as resp:
  File "D:\anaconda\envs\PBFT\lib\site-packages\aiohttp\client.py", line 1141, in __aenter__
    self._resp = await self._coro
  File "D:\anaconda\envs\PBFT\lib\site-packages\aiohttp\client.py", line 537, in _request
    req, traces=traces, timeout=real_timeout
  File "D:\anaconda\envs\PBFT\lib\site-packages\aiohttp\connector.py", line 540, in connect
    proto = await self._create_connection(req, traces, timeout)
  File "D:\anaconda\envs\PBFT\lib\site-packages\aiohttp\connector.py", line 901, in _create_connection
    _, proto = await self._create_direct_connection(req, traces, timeout)
  File "D:\anaconda\envs\PBFT\lib\site-packages\aiohttp\connector.py", line 1206, in _create_direct_connection
    raise last_exc
  File "D:\anaconda\envs\PBFT\lib\site-packages\aiohttp\connector.py", line 1187, in _create_direct_connection
    client_error=client_error,
  File "D:\anaconda\envs\PBFT\lib\site-packages\aiohttp\connector.py", line 988, in _wrap_create_connection
    raise client_error(req.connection_key, exc) from exc
aiohttp.client_exceptions.ClientConnectorError: Cannot connect to host localhost:30038 ssl:default [Connect call failed ('::1', 30038, 0, 0)]
[2025-03-07 13:53:55,994] [ERROR] [30145] Error sending to http://localhost:30023/commit: Cannot connect to host localhost:30023 ssl:default [Connect call failed ('::1', 30023, 0, 0)]
Traceback (most recent call last):
  File "D:\anaconda\envs\PBFT\lib\site-packages\aiohttp\connector.py", line 980, in _wrap_create_connection
    return await self._loop.create_connection(*args, **kwargs)  # type: ignore[return-value]  # noqa
  File "D:\anaconda\envs\PBFT\lib\asyncio\base_events.py", line 948, in create_connection
    raise exceptions[0]
  File "D:\anaconda\envs\PBFT\lib\asyncio\base_events.py", line 935, in create_connection
    await self.sock_connect(sock, address)
  File "D:\anaconda\envs\PBFT\lib\asyncio\selector_events.py", line 475, in sock_connect
    return await fut
  File "D:\anaconda\envs\PBFT\lib\asyncio\selector_events.py", line 505, in _sock_connect_cb
    raise OSError(err, f'Connect call failed {address}')
ConnectionRefusedError: [Errno 10061] Connect call failed ('::1', 30023, 0, 0)

The above exception was the direct cause of the following exception:

Traceback (most recent call last):
  File "pbft.py", line 236, in send_message
    await send_with_delay(self.session, self.node_info, target, url, data, self.bandwidth_data)
  File "pbft.py", line 63, in send_with_delay
    async with session.post(url, json=data) as resp:
  File "D:\anaconda\envs\PBFT\lib\site-packages\aiohttp\client.py", line 1141, in __aenter__
    self._resp = await self._coro
  File "D:\anaconda\envs\PBFT\lib\site-packages\aiohttp\client.py", line 537, in _request
    req, traces=traces, timeout=real_timeout
  File "D:\anaconda\envs\PBFT\lib\site-packages\aiohttp\connector.py", line 540, in connect
    proto = await self._create_connection(req, traces, timeout)
  File "D:\anaconda\envs\PBFT\lib\site-packages\aiohttp\connector.py", line 901, in _create_connection
    _, proto = await self._create_direct_connection(req, traces, timeout)
  File "D:\anaconda\envs\PBFT\lib\site-packages\aiohttp\connector.py", line 1206, in _create_direct_connection
    raise last_exc
  File "D:\anaconda\envs\PBFT\lib\site-packages\aiohttp\connector.py", line 1187, in _create_direct_connection
    client_error=client_error,
  File "D:\anaconda\envs\PBFT\lib\site-packages\aiohttp\connector.py", line 988, in _wrap_create_connection
    raise client_error(req.connection_key, exc) from exc
aiohttp.client_exceptions.ClientConnectorError: Cannot connect to host localhost:30023 ssl:default [Connect call failed ('::1', 30023, 0, 0)]
[2025-03-07 13:53:56,105] [ERROR] [30145] Error sending to http://localhost:30103/commit: Cannot connect to host localhost:30103 ssl:default [Connect call failed ('::1', 30103, 0, 0)]
Traceback (most recent call last):
  File "D:\anaconda\envs\PBFT\lib\site-packages\aiohttp\connector.py", line 980, in _wrap_create_connection
    return await self._loop.create_connection(*args, **kwargs)  # type: ignore[return-value]  # noqa
  File "D:\anaconda\envs\PBFT\lib\asyncio\base_events.py", line 948, in create_connection
    raise exceptions[0]
  File "D:\anaconda\envs\PBFT\lib\asyncio\base_events.py", line 935, in create_connection
    await self.sock_connect(sock, address)
  File "D:\anaconda\envs\PBFT\lib\asyncio\selector_events.py", line 475, in sock_connect
    return await fut
  File "D:\anaconda\envs\PBFT\lib\asyncio\selector_events.py", line 505, in _sock_connect_cb
    raise OSError(err, f'Connect call failed {address}')
ConnectionRefusedError: [Errno 10061] Connect call failed ('::1', 30103, 0, 0)

The above exception was the direct cause of the following exception:

Traceback (most recent call last):
  File "pbft.py", line 236, in send_message
    await send_with_delay(self.session, self.node_info, target, url, data, self.bandwidth_data)
  File "pbft.py", line 63, in send_with_delay
    async with session.post(url, json=data) as resp:
  File "D:\anaconda\envs\PBFT\lib\site-packages\aiohttp\client.py", line 1141, in __aenter__
    self._resp = await self._coro
  File "D:\anaconda\envs\PBFT\lib\site-packages\aiohttp\client.py", line 537, in _request
    req, traces=traces, timeout=real_timeout
  File "D:\anaconda\envs\PBFT\lib\site-packages\aiohttp\connector.py", line 540, in connect
    proto = await self._create_connection(req, traces, timeout)
  File "D:\anaconda\envs\PBFT\lib\site-packages\aiohttp\connector.py", line 901, in _create_connection
    _, proto = await self._create_direct_connection(req, traces, timeout)
  File "D:\anaconda\envs\PBFT\lib\site-packages\aiohttp\connector.py", line 1206, in _create_direct_connection
    raise last_exc
  File "D:\anaconda\envs\PBFT\lib\site-packages\aiohttp\connector.py", line 1187, in _create_direct_connection
    client_error=client_error,
  File "D:\anaconda\envs\PBFT\lib\site-packages\aiohttp\connector.py", line 988, in _wrap_create_connection
    raise client_error(req.connection_key, exc) from exc
aiohttp.client_exceptions.ClientConnectorError: Cannot connect to host localhost:30103 ssl:default [Connect call failed ('::1', 30103, 0, 0)]
[2025-03-07 13:53:56,648] [ERROR] [30145] Error sending to http://localhost:30093/prepare: Cannot connect to host localhost:30093 ssl:default [Connect call failed ('127.0.0.1', 30093)]
Traceback (most recent call last):
  File "D:\anaconda\envs\PBFT\lib\site-packages\aiohttp\connector.py", line 980, in _wrap_create_connection
    return await self._loop.create_connection(*args, **kwargs)  # type: ignore[return-value]  # noqa
  File "D:\anaconda\envs\PBFT\lib\asyncio\base_events.py", line 948, in create_connection
    raise exceptions[0]
  File "D:\anaconda\envs\PBFT\lib\asyncio\base_events.py", line 935, in create_connection
    await self.sock_connect(sock, address)
  File "D:\anaconda\envs\PBFT\lib\asyncio\selector_events.py", line 475, in sock_connect
    return await fut
  File "D:\anaconda\envs\PBFT\lib\asyncio\selector_events.py", line 505, in _sock_connect_cb
    raise OSError(err, f'Connect call failed {address}')
ConnectionRefusedError: [Errno 10061] Connect call failed ('127.0.0.1', 30093)

The above exception was the direct cause of the following exception:

Traceback (most recent call last):
  File "pbft.py", line 236, in send_message
    await send_with_delay(self.session, self.node_info, target, url, data, self.bandwidth_data)
  File "pbft.py", line 63, in send_with_delay
    async with session.post(url, json=data) as resp:
  File "D:\anaconda\envs\PBFT\lib\site-packages\aiohttp\client.py", line 1141, in __aenter__
    self._resp = await self._coro
  File "D:\anaconda\envs\PBFT\lib\site-packages\aiohttp\client.py", line 537, in _request
    req, traces=traces, timeout=real_timeout
  File "D:\anaconda\envs\PBFT\lib\site-packages\aiohttp\connector.py", line 540, in connect
    proto = await self._create_connection(req, traces, timeout)
  File "D:\anaconda\envs\PBFT\lib\site-packages\aiohttp\connector.py", line 901, in _create_connection
    _, proto = await self._create_direct_connection(req, traces, timeout)
  File "D:\anaconda\envs\PBFT\lib\site-packages\aiohttp\connector.py", line 1206, in _create_direct_connection
    raise last_exc
  File "D:\anaconda\envs\PBFT\lib\site-packages\aiohttp\connector.py", line 1187, in _create_direct_connection
    client_error=client_error,
  File "D:\anaconda\envs\PBFT\lib\site-packages\aiohttp\connector.py", line 988, in _wrap_create_connection
    raise client_error(req.connection_key, exc) from exc
aiohttp.client_exceptions.ClientConnectorError: Cannot connect to host localhost:30093 ssl:default [Connect call failed ('127.0.0.1', 30093)]
[2025-03-07 13:53:56,678] [ERROR] [30145] Error sending to http://localhost:30064/prepare: Cannot connect to host localhost:30064 ssl:default [Connect call failed ('127.0.0.1', 30064)]
Traceback (most recent call last):
  File "D:\anaconda\envs\PBFT\lib\site-packages\aiohttp\connector.py", line 980, in _wrap_create_connection
    return await self._loop.create_connection(*args, **kwargs)  # type: ignore[return-value]  # noqa
  File "D:\anaconda\envs\PBFT\lib\asyncio\base_events.py", line 948, in create_connection
    raise exceptions[0]
  File "D:\anaconda\envs\PBFT\lib\asyncio\base_events.py", line 935, in create_connection
    await self.sock_connect(sock, address)
  File "D:\anaconda\envs\PBFT\lib\asyncio\selector_events.py", line 475, in sock_connect
    return await fut
  File "D:\anaconda\envs\PBFT\lib\asyncio\selector_events.py", line 505, in _sock_connect_cb
    raise OSError(err, f'Connect call failed {address}')
ConnectionRefusedError: [Errno 10061] Connect call failed ('127.0.0.1', 30064)

The above exception was the direct cause of the following exception:

Traceback (most recent call last):
  File "pbft.py", line 236, in send_message
    await send_with_delay(self.session, self.node_info, target, url, data, self.bandwidth_data)
  File "pbft.py", line 63, in send_with_delay
    async with session.post(url, json=data) as resp:
  File "D:\anaconda\envs\PBFT\lib\site-packages\aiohttp\client.py", line 1141, in __aenter__
    self._resp = await self._coro
  File "D:\anaconda\envs\PBFT\lib\site-packages\aiohttp\client.py", line 537, in _request
    req, traces=traces, timeout=real_timeout
  File "D:\anaconda\envs\PBFT\lib\site-packages\aiohttp\connector.py", line 540, in connect
    proto = await self._create_connection(req, traces, timeout)
  File "D:\anaconda\envs\PBFT\lib\site-packages\aiohttp\connector.py", line 901, in _create_connection
    _, proto = await self._create_direct_connection(req, traces, timeout)
  File "D:\anaconda\envs\PBFT\lib\site-packages\aiohttp\connector.py", line 1206, in _create_direct_connection
    raise last_exc
  File "D:\anaconda\envs\PBFT\lib\site-packages\aiohttp\connector.py", line 1187, in _create_direct_connection
    client_error=client_error,
  File "D:\anaconda\envs\PBFT\lib\site-packages\aiohttp\connector.py", line 988, in _wrap_create_connection
    raise client_error(req.connection_key, exc) from exc
aiohttp.client_exceptions.ClientConnectorError: Cannot connect to host localhost:30064 ssl:default [Connect call failed ('127.0.0.1', 30064)]
[2025-03-07 13:53:56,696] [ERROR] [30145] Error sending to http://localhost:30075/prepare: Cannot connect to host localhost:30075 ssl:default [Connect call failed ('127.0.0.1', 30075)]
Traceback (most recent call last):
  File "D:\anaconda\envs\PBFT\lib\site-packages\aiohttp\connector.py", line 980, in _wrap_create_connection
    return await self._loop.create_connection(*args, **kwargs)  # type: ignore[return-value]  # noqa
  File "D:\anaconda\envs\PBFT\lib\asyncio\base_events.py", line 948, in create_connection
    raise exceptions[0]
  File "D:\anaconda\envs\PBFT\lib\asyncio\base_events.py", line 935, in create_connection
    await self.sock_connect(sock, address)
  File "D:\anaconda\envs\PBFT\lib\asyncio\selector_events.py", line 475, in sock_connect
    return await fut
  File "D:\anaconda\envs\PBFT\lib\asyncio\selector_events.py", line 505, in _sock_connect_cb
    raise OSError(err, f'Connect call failed {address}')
ConnectionRefusedError: [Errno 10061] Connect call failed ('127.0.0.1', 30075)

The above exception was the direct cause of the following exception:

Traceback (most recent call last):
  File "pbft.py", line 236, in send_message
    await send_with_delay(self.session, self.node_info, target, url, data, self.bandwidth_data)
  File "pbft.py", line 63, in send_with_delay
    async with session.post(url, json=data) as resp:
  File "D:\anaconda\envs\PBFT\lib\site-packages\aiohttp\client.py", line 1141, in __aenter__
    self._resp = await self._coro
  File "D:\anaconda\envs\PBFT\lib\site-packages\aiohttp\client.py", line 537, in _request
    req, traces=traces, timeout=real_timeout
  File "D:\anaconda\envs\PBFT\lib\site-packages\aiohttp\connector.py", line 540, in connect
    proto = await self._create_connection(req, traces, timeout)
  File "D:\anaconda\envs\PBFT\lib\site-packages\aiohttp\connector.py", line 901, in _create_connection
    _, proto = await self._create_direct_connection(req, traces, timeout)
  File "D:\anaconda\envs\PBFT\lib\site-packages\aiohttp\connector.py", line 1206, in _create_direct_connection
    raise last_exc
  File "D:\anaconda\envs\PBFT\lib\site-packages\aiohttp\connector.py", line 1187, in _create_direct_connection
    client_error=client_error,
  File "D:\anaconda\envs\PBFT\lib\site-packages\aiohttp\connector.py", line 988, in _wrap_create_connection
    raise client_error(req.connection_key, exc) from exc
aiohttp.client_exceptions.ClientConnectorError: Cannot connect to host localhost:30075 ssl:default [Connect call failed ('127.0.0.1', 30075)]
[2025-03-07 13:53:56,710] [ERROR] [30145] Error sending to http://localhost:30076/prepare: Cannot connect to host localhost:30076 ssl:default [Connect call failed ('127.0.0.1', 30076)]
Traceback (most recent call last):
  File "D:\anaconda\envs\PBFT\lib\site-packages\aiohttp\connector.py", line 980, in _wrap_create_connection
    return await self._loop.create_connection(*args, **kwargs)  # type: ignore[return-value]  # noqa
  File "D:\anaconda\envs\PBFT\lib\asyncio\base_events.py", line 948, in create_connection
    raise exceptions[0]
  File "D:\anaconda\envs\PBFT\lib\asyncio\base_events.py", line 935, in create_connection
    await self.sock_connect(sock, address)
  File "D:\anaconda\envs\PBFT\lib\asyncio\selector_events.py", line 475, in sock_connect
    return await fut
  File "D:\anaconda\envs\PBFT\lib\asyncio\selector_events.py", line 505, in _sock_connect_cb
    raise OSError(err, f'Connect call failed {address}')
ConnectionRefusedError: [Errno 10061] Connect call failed ('127.0.0.1', 30076)

The above exception was the direct cause of the following exception:

Traceback (most recent call last):
  File "pbft.py", line 236, in send_message
    await send_with_delay(self.session, self.node_info, target, url, data, self.bandwidth_data)
  File "pbft.py", line 63, in send_with_delay
    async with session.post(url, json=data) as resp:
  File "D:\anaconda\envs\PBFT\lib\site-packages\aiohttp\client.py", line 1141, in __aenter__
    self._resp = await self._coro
  File "D:\anaconda\envs\PBFT\lib\site-packages\aiohttp\client.py", line 537, in _request
    req, traces=traces, timeout=real_timeout
  File "D:\anaconda\envs\PBFT\lib\site-packages\aiohttp\connector.py", line 540, in connect
    proto = await self._create_connection(req, traces, timeout)
  File "D:\anaconda\envs\PBFT\lib\site-packages\aiohttp\connector.py", line 901, in _create_connection
    _, proto = await self._create_direct_connection(req, traces, timeout)
  File "D:\anaconda\envs\PBFT\lib\site-packages\aiohttp\connector.py", line 1206, in _create_direct_connection
    raise last_exc
  File "D:\anaconda\envs\PBFT\lib\site-packages\aiohttp\connector.py", line 1187, in _create_direct_connection
    client_error=client_error,
  File "D:\anaconda\envs\PBFT\lib\site-packages\aiohttp\connector.py", line 988, in _wrap_create_connection
    raise client_error(req.connection_key, exc) from exc
aiohttp.client_exceptions.ClientConnectorError: Cannot connect to host localhost:30076 ssl:default [Connect call failed ('127.0.0.1', 30076)]
[2025-03-07 13:53:56,742] [ERROR] [30145] Error sending to http://localhost:30076/commit: Cannot connect to host localhost:30076 ssl:default [Connect call failed ('::1', 30076, 0, 0)]
Traceback (most recent call last):
  File "D:\anaconda\envs\PBFT\lib\site-packages\aiohttp\connector.py", line 980, in _wrap_create_connection
    return await self._loop.create_connection(*args, **kwargs)  # type: ignore[return-value]  # noqa
  File "D:\anaconda\envs\PBFT\lib\asyncio\base_events.py", line 948, in create_connection
    raise exceptions[0]
  File "D:\anaconda\envs\PBFT\lib\asyncio\base_events.py", line 935, in create_connection
    await self.sock_connect(sock, address)
  File "D:\anaconda\envs\PBFT\lib\asyncio\selector_events.py", line 475, in sock_connect
    return await fut
  File "D:\anaconda\envs\PBFT\lib\asyncio\selector_events.py", line 505, in _sock_connect_cb
    raise OSError(err, f'Connect call failed {address}')
ConnectionRefusedError: [Errno 10061] Connect call failed ('::1', 30076, 0, 0)

The above exception was the direct cause of the following exception:

Traceback (most recent call last):
  File "pbft.py", line 236, in send_message
    await send_with_delay(self.session, self.node_info, target, url, data, self.bandwidth_data)
  File "pbft.py", line 63, in send_with_delay
    async with session.post(url, json=data) as resp:
  File "D:\anaconda\envs\PBFT\lib\site-packages\aiohttp\client.py", line 1141, in __aenter__
    self._resp = await self._coro
  File "D:\anaconda\envs\PBFT\lib\site-packages\aiohttp\client.py", line 537, in _request
    req, traces=traces, timeout=real_timeout
  File "D:\anaconda\envs\PBFT\lib\site-packages\aiohttp\connector.py", line 540, in connect
    proto = await self._create_connection(req, traces, timeout)
  File "D:\anaconda\envs\PBFT\lib\site-packages\aiohttp\connector.py", line 901, in _create_connection
    _, proto = await self._create_direct_connection(req, traces, timeout)
  File "D:\anaconda\envs\PBFT\lib\site-packages\aiohttp\connector.py", line 1206, in _create_direct_connection
    raise last_exc
  File "D:\anaconda\envs\PBFT\lib\site-packages\aiohttp\connector.py", line 1187, in _create_direct_connection
    client_error=client_error,
  File "D:\anaconda\envs\PBFT\lib\site-packages\aiohttp\connector.py", line 988, in _wrap_create_connection
    raise client_error(req.connection_key, exc) from exc
aiohttp.client_exceptions.ClientConnectorError: Cannot connect to host localhost:30076 ssl:default [Connect call failed ('::1', 30076, 0, 0)]
[2025-03-07 13:53:56,965] [ERROR] [30145] Error sending to http://localhost:30101/commit: Cannot connect to host localhost:30101 ssl:default [Connect call failed ('::1', 30101, 0, 0)]
Traceback (most recent call last):
  File "D:\anaconda\envs\PBFT\lib\site-packages\aiohttp\connector.py", line 980, in _wrap_create_connection
    return await self._loop.create_connection(*args, **kwargs)  # type: ignore[return-value]  # noqa
  File "D:\anaconda\envs\PBFT\lib\asyncio\base_events.py", line 948, in create_connection
    raise exceptions[0]
  File "D:\anaconda\envs\PBFT\lib\asyncio\base_events.py", line 935, in create_connection
    await self.sock_connect(sock, address)
  File "D:\anaconda\envs\PBFT\lib\asyncio\selector_events.py", line 475, in sock_connect
    return await fut
  File "D:\anaconda\envs\PBFT\lib\asyncio\selector_events.py", line 505, in _sock_connect_cb
    raise OSError(err, f'Connect call failed {address}')
ConnectionRefusedError: [Errno 10061] Connect call failed ('::1', 30101, 0, 0)

The above exception was the direct cause of the following exception:

Traceback (most recent call last):
  File "pbft.py", line 236, in send_message
    await send_with_delay(self.session, self.node_info, target, url, data, self.bandwidth_data)
  File "pbft.py", line 63, in send_with_delay
    async with session.post(url, json=data) as resp:
  File "D:\anaconda\envs\PBFT\lib\site-packages\aiohttp\client.py", line 1141, in __aenter__
    self._resp = await self._coro
  File "D:\anaconda\envs\PBFT\lib\site-packages\aiohttp\client.py", line 537, in _request
    req, traces=traces, timeout=real_timeout
  File "D:\anaconda\envs\PBFT\lib\site-packages\aiohttp\connector.py", line 540, in connect
    proto = await self._create_connection(req, traces, timeout)
  File "D:\anaconda\envs\PBFT\lib\site-packages\aiohttp\connector.py", line 901, in _create_connection
    _, proto = await self._create_direct_connection(req, traces, timeout)
  File "D:\anaconda\envs\PBFT\lib\site-packages\aiohttp\connector.py", line 1206, in _create_direct_connection
    raise last_exc
  File "D:\anaconda\envs\PBFT\lib\site-packages\aiohttp\connector.py", line 1187, in _create_direct_connection
    client_error=client_error,
  File "D:\anaconda\envs\PBFT\lib\site-packages\aiohttp\connector.py", line 988, in _wrap_create_connection
    raise client_error(req.connection_key, exc) from exc
aiohttp.client_exceptions.ClientConnectorError: Cannot connect to host localhost:30101 ssl:default [Connect call failed ('::1', 30101, 0, 0)]
[2025-03-07 13:53:57,072] [ERROR] [30145] Error sending to http://localhost:30066/commit: Cannot connect to host localhost:30066 ssl:default [Connect call failed ('::1', 30066, 0, 0)]
Traceback (most recent call last):
  File "D:\anaconda\envs\PBFT\lib\site-packages\aiohttp\connector.py", line 980, in _wrap_create_connection
    return await self._loop.create_connection(*args, **kwargs)  # type: ignore[return-value]  # noqa
  File "D:\anaconda\envs\PBFT\lib\asyncio\base_events.py", line 948, in create_connection
    raise exceptions[0]
  File "D:\anaconda\envs\PBFT\lib\asyncio\base_events.py", line 935, in create_connection
    await self.sock_connect(sock, address)
  File "D:\anaconda\envs\PBFT\lib\asyncio\selector_events.py", line 475, in sock_connect
    return await fut
  File "D:\anaconda\envs\PBFT\lib\asyncio\selector_events.py", line 505, in _sock_connect_cb
    raise OSError(err, f'Connect call failed {address}')
ConnectionRefusedError: [Errno 10061] Connect call failed ('::1', 30066, 0, 0)

The above exception was the direct cause of the following exception:

Traceback (most recent call last):
  File "pbft.py", line 236, in send_message
    await send_with_delay(self.session, self.node_info, target, url, data, self.bandwidth_data)
  File "pbft.py", line 63, in send_with_delay
    async with session.post(url, json=data) as resp:
  File "D:\anaconda\envs\PBFT\lib\site-packages\aiohttp\client.py", line 1141, in __aenter__
    self._resp = await self._coro
  File "D:\anaconda\envs\PBFT\lib\site-packages\aiohttp\client.py", line 537, in _request
    req, traces=traces, timeout=real_timeout
  File "D:\anaconda\envs\PBFT\lib\site-packages\aiohttp\connector.py", line 540, in connect
    proto = await self._create_connection(req, traces, timeout)
  File "D:\anaconda\envs\PBFT\lib\site-packages\aiohttp\connector.py", line 901, in _create_connection
    _, proto = await self._create_direct_connection(req, traces, timeout)
  File "D:\anaconda\envs\PBFT\lib\site-packages\aiohttp\connector.py", line 1206, in _create_direct_connection
    raise last_exc
  File "D:\anaconda\envs\PBFT\lib\site-packages\aiohttp\connector.py", line 1187, in _create_direct_connection
    client_error=client_error,
  File "D:\anaconda\envs\PBFT\lib\site-packages\aiohttp\connector.py", line 988, in _wrap_create_connection
    raise client_error(req.connection_key, exc) from exc
aiohttp.client_exceptions.ClientConnectorError: Cannot connect to host localhost:30066 ssl:default [Connect call failed ('::1', 30066, 0, 0)]
[2025-03-07 13:53:57,155] [ERROR] [30145] Error sending to http://localhost:30029/prepare: Cannot connect to host localhost:30029 ssl:default [Connect call failed ('127.0.0.1', 30029)]
Traceback (most recent call last):
  File "D:\anaconda\envs\PBFT\lib\site-packages\aiohttp\connector.py", line 980, in _wrap_create_connection
    return await self._loop.create_connection(*args, **kwargs)  # type: ignore[return-value]  # noqa
  File "D:\anaconda\envs\PBFT\lib\asyncio\base_events.py", line 948, in create_connection
    raise exceptions[0]
  File "D:\anaconda\envs\PBFT\lib\asyncio\base_events.py", line 935, in create_connection
    await self.sock_connect(sock, address)
  File "D:\anaconda\envs\PBFT\lib\asyncio\selector_events.py", line 475, in sock_connect
    return await fut
  File "D:\anaconda\envs\PBFT\lib\asyncio\selector_events.py", line 505, in _sock_connect_cb
    raise OSError(err, f'Connect call failed {address}')
ConnectionRefusedError: [Errno 10061] Connect call failed ('127.0.0.1', 30029)

The above exception was the direct cause of the following exception:

Traceback (most recent call last):
  File "pbft.py", line 236, in send_message
    await send_with_delay(self.session, self.node_info, target, url, data, self.bandwidth_data)
  File "pbft.py", line 63, in send_with_delay
    async with session.post(url, json=data) as resp:
  File "D:\anaconda\envs\PBFT\lib\site-packages\aiohttp\client.py", line 1141, in __aenter__
    self._resp = await self._coro
  File "D:\anaconda\envs\PBFT\lib\site-packages\aiohttp\client.py", line 537, in _request
    req, traces=traces, timeout=real_timeout
  File "D:\anaconda\envs\PBFT\lib\site-packages\aiohttp\connector.py", line 540, in connect
    proto = await self._create_connection(req, traces, timeout)
  File "D:\anaconda\envs\PBFT\lib\site-packages\aiohttp\connector.py", line 901, in _create_connection
    _, proto = await self._create_direct_connection(req, traces, timeout)
  File "D:\anaconda\envs\PBFT\lib\site-packages\aiohttp\connector.py", line 1206, in _create_direct_connection
    raise last_exc
  File "D:\anaconda\envs\PBFT\lib\site-packages\aiohttp\connector.py", line 1187, in _create_direct_connection
    client_error=client_error,
  File "D:\anaconda\envs\PBFT\lib\site-packages\aiohttp\connector.py", line 988, in _wrap_create_connection
    raise client_error(req.connection_key, exc) from exc
aiohttp.client_exceptions.ClientConnectorError: Cannot connect to host localhost:30029 ssl:default [Connect call failed ('127.0.0.1', 30029)]
[2025-03-07 13:53:57,251] [ERROR] [30145] Error sending to http://localhost:30093/commit: Cannot connect to host localhost:30093 ssl:default [Connect call failed ('::1', 30093, 0, 0)]
Traceback (most recent call last):
  File "D:\anaconda\envs\PBFT\lib\site-packages\aiohttp\connector.py", line 980, in _wrap_create_connection
    return await self._loop.create_connection(*args, **kwargs)  # type: ignore[return-value]  # noqa
  File "D:\anaconda\envs\PBFT\lib\asyncio\base_events.py", line 948, in create_connection
    raise exceptions[0]
  File "D:\anaconda\envs\PBFT\lib\asyncio\base_events.py", line 935, in create_connection
    await self.sock_connect(sock, address)
  File "D:\anaconda\envs\PBFT\lib\asyncio\selector_events.py", line 475, in sock_connect
    return await fut
  File "D:\anaconda\envs\PBFT\lib\asyncio\selector_events.py", line 505, in _sock_connect_cb
    raise OSError(err, f'Connect call failed {address}')
ConnectionRefusedError: [Errno 10061] Connect call failed ('::1', 30093, 0, 0)

The above exception was the direct cause of the following exception:

Traceback (most recent call last):
  File "pbft.py", line 236, in send_message
    await send_with_delay(self.session, self.node_info, target, url, data, self.bandwidth_data)
  File "pbft.py", line 63, in send_with_delay
    async with session.post(url, json=data) as resp:
  File "D:\anaconda\envs\PBFT\lib\site-packages\aiohttp\client.py", line 1141, in __aenter__
    self._resp = await self._coro
  File "D:\anaconda\envs\PBFT\lib\site-packages\aiohttp\client.py", line 537, in _request
    req, traces=traces, timeout=real_timeout
  File "D:\anaconda\envs\PBFT\lib\site-packages\aiohttp\connector.py", line 540, in connect
    proto = await self._create_connection(req, traces, timeout)
  File "D:\anaconda\envs\PBFT\lib\site-packages\aiohttp\connector.py", line 901, in _create_connection
    _, proto = await self._create_direct_connection(req, traces, timeout)
  File "D:\anaconda\envs\PBFT\lib\site-packages\aiohttp\connector.py", line 1206, in _create_direct_connection
    raise last_exc
  File "D:\anaconda\envs\PBFT\lib\site-packages\aiohttp\connector.py", line 1187, in _create_direct_connection
    client_error=client_error,
  File "D:\anaconda\envs\PBFT\lib\site-packages\aiohttp\connector.py", line 988, in _wrap_create_connection
    raise client_error(req.connection_key, exc) from exc
aiohttp.client_exceptions.ClientConnectorError: Cannot connect to host localhost:30093 ssl:default [Connect call failed ('::1', 30093, 0, 0)]
[2025-03-07 13:53:57,254] [ERROR] [30145] Error sending to http://localhost:30008/prepare: Cannot connect to host localhost:30008 ssl:default [Connect call failed ('127.0.0.1', 30008)]
Traceback (most recent call last):
  File "D:\anaconda\envs\PBFT\lib\site-packages\aiohttp\connector.py", line 980, in _wrap_create_connection
    return await self._loop.create_connection(*args, **kwargs)  # type: ignore[return-value]  # noqa
  File "D:\anaconda\envs\PBFT\lib\asyncio\base_events.py", line 948, in create_connection
    raise exceptions[0]
  File "D:\anaconda\envs\PBFT\lib\asyncio\base_events.py", line 935, in create_connection
    await self.sock_connect(sock, address)
  File "D:\anaconda\envs\PBFT\lib\asyncio\selector_events.py", line 475, in sock_connect
    return await fut
  File "D:\anaconda\envs\PBFT\lib\asyncio\selector_events.py", line 505, in _sock_connect_cb
    raise OSError(err, f'Connect call failed {address}')
ConnectionRefusedError: [Errno 10061] Connect call failed ('127.0.0.1', 30008)

The above exception was the direct cause of the following exception:

Traceback (most recent call last):
  File "pbft.py", line 236, in send_message
    await send_with_delay(self.session, self.node_info, target, url, data, self.bandwidth_data)
  File "pbft.py", line 63, in send_with_delay
    async with session.post(url, json=data) as resp:
  File "D:\anaconda\envs\PBFT\lib\site-packages\aiohttp\client.py", line 1141, in __aenter__
    self._resp = await self._coro
  File "D:\anaconda\envs\PBFT\lib\site-packages\aiohttp\client.py", line 537, in _request
    req, traces=traces, timeout=real_timeout
  File "D:\anaconda\envs\PBFT\lib\site-packages\aiohttp\connector.py", line 540, in connect
    proto = await self._create_connection(req, traces, timeout)
  File "D:\anaconda\envs\PBFT\lib\site-packages\aiohttp\connector.py", line 901, in _create_connection
    _, proto = await self._create_direct_connection(req, traces, timeout)
  File "D:\anaconda\envs\PBFT\lib\site-packages\aiohttp\connector.py", line 1206, in _create_direct_connection
    raise last_exc
  File "D:\anaconda\envs\PBFT\lib\site-packages\aiohttp\connector.py", line 1187, in _create_direct_connection
    client_error=client_error,
  File "D:\anaconda\envs\PBFT\lib\site-packages\aiohttp\connector.py", line 988, in _wrap_create_connection
    raise client_error(req.connection_key, exc) from exc
aiohttp.client_exceptions.ClientConnectorError: Cannot connect to host localhost:30008 ssl:default [Connect call failed ('127.0.0.1', 30008)]
[2025-03-07 13:53:57,394] [ERROR] [30145] Error sending to http://localhost:30085/prepare: Cannot connect to host localhost:30085 ssl:default [Connect call failed ('127.0.0.1', 30085)]
Traceback (most recent call last):
  File "D:\anaconda\envs\PBFT\lib\site-packages\aiohttp\connector.py", line 980, in _wrap_create_connection
    return await self._loop.create_connection(*args, **kwargs)  # type: ignore[return-value]  # noqa
  File "D:\anaconda\envs\PBFT\lib\asyncio\base_events.py", line 948, in create_connection
    raise exceptions[0]
  File "D:\anaconda\envs\PBFT\lib\asyncio\base_events.py", line 935, in create_connection
    await self.sock_connect(sock, address)
  File "D:\anaconda\envs\PBFT\lib\asyncio\selector_events.py", line 475, in sock_connect
    return await fut
  File "D:\anaconda\envs\PBFT\lib\asyncio\selector_events.py", line 505, in _sock_connect_cb
    raise OSError(err, f'Connect call failed {address}')
ConnectionRefusedError: [Errno 10061] Connect call failed ('127.0.0.1', 30085)

The above exception was the direct cause of the following exception:

Traceback (most recent call last):
  File "pbft.py", line 236, in send_message
    await send_with_delay(self.session, self.node_info, target, url, data, self.bandwidth_data)
  File "pbft.py", line 63, in send_with_delay
    async with session.post(url, json=data) as resp:
  File "D:\anaconda\envs\PBFT\lib\site-packages\aiohttp\client.py", line 1141, in __aenter__
    self._resp = await self._coro
  File "D:\anaconda\envs\PBFT\lib\site-packages\aiohttp\client.py", line 537, in _request
    req, traces=traces, timeout=real_timeout
  File "D:\anaconda\envs\PBFT\lib\site-packages\aiohttp\connector.py", line 540, in connect
    proto = await self._create_connection(req, traces, timeout)
  File "D:\anaconda\envs\PBFT\lib\site-packages\aiohttp\connector.py", line 901, in _create_connection
    _, proto = await self._create_direct_connection(req, traces, timeout)
  File "D:\anaconda\envs\PBFT\lib\site-packages\aiohttp\connector.py", line 1206, in _create_direct_connection
    raise last_exc
  File "D:\anaconda\envs\PBFT\lib\site-packages\aiohttp\connector.py", line 1187, in _create_direct_connection
    client_error=client_error,
  File "D:\anaconda\envs\PBFT\lib\site-packages\aiohttp\connector.py", line 988, in _wrap_create_connection
    raise client_error(req.connection_key, exc) from exc
aiohttp.client_exceptions.ClientConnectorError: Cannot connect to host localhost:30085 ssl:default [Connect call failed ('127.0.0.1', 30085)]
[2025-03-07 13:53:57,394] [ERROR] [30145] Error sending to http://localhost:30085/commit: Cannot connect to host localhost:30085 ssl:default [Connect call failed ('::1', 30085, 0, 0)]
Traceback (most recent call last):
  File "D:\anaconda\envs\PBFT\lib\site-packages\aiohttp\connector.py", line 980, in _wrap_create_connection
    return await self._loop.create_connection(*args, **kwargs)  # type: ignore[return-value]  # noqa
  File "D:\anaconda\envs\PBFT\lib\asyncio\base_events.py", line 948, in create_connection
    raise exceptions[0]
  File "D:\anaconda\envs\PBFT\lib\asyncio\base_events.py", line 935, in create_connection
    await self.sock_connect(sock, address)
  File "D:\anaconda\envs\PBFT\lib\asyncio\selector_events.py", line 475, in sock_connect
    return await fut
  File "D:\anaconda\envs\PBFT\lib\asyncio\selector_events.py", line 505, in _sock_connect_cb
    raise OSError(err, f'Connect call failed {address}')
ConnectionRefusedError: [Errno 10061] Connect call failed ('::1', 30085, 0, 0)

The above exception was the direct cause of the following exception:

Traceback (most recent call last):
  File "pbft.py", line 236, in send_message
    await send_with_delay(self.session, self.node_info, target, url, data, self.bandwidth_data)
  File "pbft.py", line 63, in send_with_delay
    async with session.post(url, json=data) as resp:
  File "D:\anaconda\envs\PBFT\lib\site-packages\aiohttp\client.py", line 1141, in __aenter__
    self._resp = await self._coro
  File "D:\anaconda\envs\PBFT\lib\site-packages\aiohttp\client.py", line 537, in _request
    req, traces=traces, timeout=real_timeout
  File "D:\anaconda\envs\PBFT\lib\site-packages\aiohttp\connector.py", line 540, in connect
    proto = await self._create_connection(req, traces, timeout)
  File "D:\anaconda\envs\PBFT\lib\site-packages\aiohttp\connector.py", line 901, in _create_connection
    _, proto = await self._create_direct_connection(req, traces, timeout)
  File "D:\anaconda\envs\PBFT\lib\site-packages\aiohttp\connector.py", line 1206, in _create_direct_connection
    raise last_exc
  File "D:\anaconda\envs\PBFT\lib\site-packages\aiohttp\connector.py", line 1187, in _create_direct_connection
    client_error=client_error,
  File "D:\anaconda\envs\PBFT\lib\site-packages\aiohttp\connector.py", line 988, in _wrap_create_connection
    raise client_error(req.connection_key, exc) from exc
aiohttp.client_exceptions.ClientConnectorError: Cannot connect to host localhost:30085 ssl:default [Connect call failed ('::1', 30085, 0, 0)]
[2025-03-07 13:53:57,508] [ERROR] [30145] Error sending to http://localhost:30065/commit: Cannot connect to host localhost:30065 ssl:default [Connect call failed ('::1', 30065, 0, 0)]
Traceback (most recent call last):
  File "D:\anaconda\envs\PBFT\lib\site-packages\aiohttp\connector.py", line 980, in _wrap_create_connection
    return await self._loop.create_connection(*args, **kwargs)  # type: ignore[return-value]  # noqa
  File "D:\anaconda\envs\PBFT\lib\asyncio\base_events.py", line 948, in create_connection
    raise exceptions[0]
  File "D:\anaconda\envs\PBFT\lib\asyncio\base_events.py", line 935, in create_connection
    await self.sock_connect(sock, address)
  File "D:\anaconda\envs\PBFT\lib\asyncio\selector_events.py", line 475, in sock_connect
    return await fut
  File "D:\anaconda\envs\PBFT\lib\asyncio\selector_events.py", line 505, in _sock_connect_cb
    raise OSError(err, f'Connect call failed {address}')
ConnectionRefusedError: [Errno 10061] Connect call failed ('::1', 30065, 0, 0)

The above exception was the direct cause of the following exception:

Traceback (most recent call last):
  File "pbft.py", line 236, in send_message
    await send_with_delay(self.session, self.node_info, target, url, data, self.bandwidth_data)
  File "pbft.py", line 63, in send_with_delay
    async with session.post(url, json=data) as resp:
  File "D:\anaconda\envs\PBFT\lib\site-packages\aiohttp\client.py", line 1141, in __aenter__
    self._resp = await self._coro
  File "D:\anaconda\envs\PBFT\lib\site-packages\aiohttp\client.py", line 537, in _request
    req, traces=traces, timeout=real_timeout
  File "D:\anaconda\envs\PBFT\lib\site-packages\aiohttp\connector.py", line 540, in connect
    proto = await self._create_connection(req, traces, timeout)
  File "D:\anaconda\envs\PBFT\lib\site-packages\aiohttp\connector.py", line 901, in _create_connection
    _, proto = await self._create_direct_connection(req, traces, timeout)
  File "D:\anaconda\envs\PBFT\lib\site-packages\aiohttp\connector.py", line 1206, in _create_direct_connection
    raise last_exc
  File "D:\anaconda\envs\PBFT\lib\site-packages\aiohttp\connector.py", line 1187, in _create_direct_connection
    client_error=client_error,
  File "D:\anaconda\envs\PBFT\lib\site-packages\aiohttp\connector.py", line 988, in _wrap_create_connection
    raise client_error(req.connection_key, exc) from exc
aiohttp.client_exceptions.ClientConnectorError: Cannot connect to host localhost:30065 ssl:default [Connect call failed ('::1', 30065, 0, 0)]
[2025-03-07 13:53:57,508] [ERROR] [30145] Error sending to http://localhost:30064/commit: Cannot connect to host localhost:30064 ssl:default [Connect call failed ('::1', 30064, 0, 0)]
Traceback (most recent call last):
  File "D:\anaconda\envs\PBFT\lib\site-packages\aiohttp\connector.py", line 980, in _wrap_create_connection
    return await self._loop.create_connection(*args, **kwargs)  # type: ignore[return-value]  # noqa
  File "D:\anaconda\envs\PBFT\lib\asyncio\base_events.py", line 948, in create_connection
    raise exceptions[0]
  File "D:\anaconda\envs\PBFT\lib\asyncio\base_events.py", line 935, in create_connection
    await self.sock_connect(sock, address)
  File "D:\anaconda\envs\PBFT\lib\asyncio\selector_events.py", line 475, in sock_connect
    return await fut
  File "D:\anaconda\envs\PBFT\lib\asyncio\selector_events.py", line 505, in _sock_connect_cb
    raise OSError(err, f'Connect call failed {address}')
ConnectionRefusedError: [Errno 10061] Connect call failed ('::1', 30064, 0, 0)

The above exception was the direct cause of the following exception:

Traceback (most recent call last):
  File "pbft.py", line 236, in send_message
    await send_with_delay(self.session, self.node_info, target, url, data, self.bandwidth_data)
  File "pbft.py", line 63, in send_with_delay
    async with session.post(url, json=data) as resp:
  File "D:\anaconda\envs\PBFT\lib\site-packages\aiohttp\client.py", line 1141, in __aenter__
    self._resp = await self._coro
  File "D:\anaconda\envs\PBFT\lib\site-packages\aiohttp\client.py", line 537, in _request
    req, traces=traces, timeout=real_timeout
  File "D:\anaconda\envs\PBFT\lib\site-packages\aiohttp\connector.py", line 540, in connect
    proto = await self._create_connection(req, traces, timeout)
  File "D:\anaconda\envs\PBFT\lib\site-packages\aiohttp\connector.py", line 901, in _create_connection
    _, proto = await self._create_direct_connection(req, traces, timeout)
  File "D:\anaconda\envs\PBFT\lib\site-packages\aiohttp\connector.py", line 1206, in _create_direct_connection
    raise last_exc
  File "D:\anaconda\envs\PBFT\lib\site-packages\aiohttp\connector.py", line 1187, in _create_direct_connection
    client_error=client_error,
  File "D:\anaconda\envs\PBFT\lib\site-packages\aiohttp\connector.py", line 988, in _wrap_create_connection
    raise client_error(req.connection_key, exc) from exc
aiohttp.client_exceptions.ClientConnectorError: Cannot connect to host localhost:30064 ssl:default [Connect call failed ('::1', 30064, 0, 0)]
[2025-03-07 13:53:57,508] [ERROR] [30145] Error sending to http://localhost:30027/commit: Cannot connect to host localhost:30027 ssl:default [Connect call failed ('::1', 30027, 0, 0)]
Traceback (most recent call last):
  File "D:\anaconda\envs\PBFT\lib\site-packages\aiohttp\connector.py", line 980, in _wrap_create_connection
    return await self._loop.create_connection(*args, **kwargs)  # type: ignore[return-value]  # noqa
  File "D:\anaconda\envs\PBFT\lib\asyncio\base_events.py", line 948, in create_connection
    raise exceptions[0]
  File "D:\anaconda\envs\PBFT\lib\asyncio\base_events.py", line 935, in create_connection
    await self.sock_connect(sock, address)
  File "D:\anaconda\envs\PBFT\lib\asyncio\selector_events.py", line 475, in sock_connect
    return await fut
  File "D:\anaconda\envs\PBFT\lib\asyncio\selector_events.py", line 505, in _sock_connect_cb
    raise OSError(err, f'Connect call failed {address}')
ConnectionRefusedError: [Errno 10061] Connect call failed ('::1', 30027, 0, 0)

The above exception was the direct cause of the following exception:

Traceback (most recent call last):
  File "pbft.py", line 236, in send_message
    await send_with_delay(self.session, self.node_info, target, url, data, self.bandwidth_data)
  File "pbft.py", line 63, in send_with_delay
    async with session.post(url, json=data) as resp:
  File "D:\anaconda\envs\PBFT\lib\site-packages\aiohttp\client.py", line 1141, in __aenter__
    self._resp = await self._coro
  File "D:\anaconda\envs\PBFT\lib\site-packages\aiohttp\client.py", line 537, in _request
    req, traces=traces, timeout=real_timeout
  File "D:\anaconda\envs\PBFT\lib\site-packages\aiohttp\connector.py", line 540, in connect
    proto = await self._create_connection(req, traces, timeout)
  File "D:\anaconda\envs\PBFT\lib\site-packages\aiohttp\connector.py", line 901, in _create_connection
    _, proto = await self._create_direct_connection(req, traces, timeout)
  File "D:\anaconda\envs\PBFT\lib\site-packages\aiohttp\connector.py", line 1206, in _create_direct_connection
    raise last_exc
  File "D:\anaconda\envs\PBFT\lib\site-packages\aiohttp\connector.py", line 1187, in _create_direct_connection
    client_error=client_error,
  File "D:\anaconda\envs\PBFT\lib\site-packages\aiohttp\connector.py", line 988, in _wrap_create_connection
    raise client_error(req.connection_key, exc) from exc
aiohttp.client_exceptions.ClientConnectorError: Cannot connect to host localhost:30027 ssl:default [Connect call failed ('::1', 30027, 0, 0)]
[2025-03-07 13:53:57,537] [ERROR] [30145] Error sending to http://localhost:30065/prepare: Cannot connect to host localhost:30065 ssl:default [Connect call failed ('127.0.0.1', 30065)]
Traceback (most recent call last):
  File "D:\anaconda\envs\PBFT\lib\site-packages\aiohttp\connector.py", line 980, in _wrap_create_connection
    return await self._loop.create_connection(*args, **kwargs)  # type: ignore[return-value]  # noqa
  File "D:\anaconda\envs\PBFT\lib\asyncio\base_events.py", line 948, in create_connection
    raise exceptions[0]
  File "D:\anaconda\envs\PBFT\lib\asyncio\base_events.py", line 935, in create_connection
    await self.sock_connect(sock, address)
  File "D:\anaconda\envs\PBFT\lib\asyncio\selector_events.py", line 475, in sock_connect
    return await fut
  File "D:\anaconda\envs\PBFT\lib\asyncio\selector_events.py", line 505, in _sock_connect_cb
    raise OSError(err, f'Connect call failed {address}')
ConnectionRefusedError: [Errno 10061] Connect call failed ('127.0.0.1', 30065)

The above exception was the direct cause of the following exception:

Traceback (most recent call last):
  File "pbft.py", line 236, in send_message
    await send_with_delay(self.session, self.node_info, target, url, data, self.bandwidth_data)
  File "pbft.py", line 63, in send_with_delay
    async with session.post(url, json=data) as resp:
  File "D:\anaconda\envs\PBFT\lib\site-packages\aiohttp\client.py", line 1141, in __aenter__
    self._resp = await self._coro
  File "D:\anaconda\envs\PBFT\lib\site-packages\aiohttp\client.py", line 537, in _request
    req, traces=traces, timeout=real_timeout
  File "D:\anaconda\envs\PBFT\lib\site-packages\aiohttp\connector.py", line 540, in connect
    proto = await self._create_connection(req, traces, timeout)
  File "D:\anaconda\envs\PBFT\lib\site-packages\aiohttp\connector.py", line 901, in _create_connection
    _, proto = await self._create_direct_connection(req, traces, timeout)
  File "D:\anaconda\envs\PBFT\lib\site-packages\aiohttp\connector.py", line 1206, in _create_direct_connection
    raise last_exc
  File "D:\anaconda\envs\PBFT\lib\site-packages\aiohttp\connector.py", line 1187, in _create_direct_connection
    client_error=client_error,
  File "D:\anaconda\envs\PBFT\lib\site-packages\aiohttp\connector.py", line 988, in _wrap_create_connection
    raise client_error(req.connection_key, exc) from exc
aiohttp.client_exceptions.ClientConnectorError: Cannot connect to host localhost:30065 ssl:default [Connect call failed ('127.0.0.1', 30065)]
[2025-03-07 13:53:57,648] [ERROR] [30145] Error sending to http://localhost:30029/commit: Cannot connect to host localhost:30029 ssl:default [Connect call failed ('::1', 30029, 0, 0)]
Traceback (most recent call last):
  File "D:\anaconda\envs\PBFT\lib\site-packages\aiohttp\connector.py", line 980, in _wrap_create_connection
    return await self._loop.create_connection(*args, **kwargs)  # type: ignore[return-value]  # noqa
  File "D:\anaconda\envs\PBFT\lib\asyncio\base_events.py", line 948, in create_connection
    raise exceptions[0]
  File "D:\anaconda\envs\PBFT\lib\asyncio\base_events.py", line 935, in create_connection
    await self.sock_connect(sock, address)
  File "D:\anaconda\envs\PBFT\lib\asyncio\selector_events.py", line 475, in sock_connect
    return await fut
  File "D:\anaconda\envs\PBFT\lib\asyncio\selector_events.py", line 505, in _sock_connect_cb
    raise OSError(err, f'Connect call failed {address}')
ConnectionRefusedError: [Errno 10061] Connect call failed ('::1', 30029, 0, 0)

The above exception was the direct cause of the following exception:

Traceback (most recent call last):
  File "pbft.py", line 236, in send_message
    await send_with_delay(self.session, self.node_info, target, url, data, self.bandwidth_data)
  File "pbft.py", line 63, in send_with_delay
    async with session.post(url, json=data) as resp:
  File "D:\anaconda\envs\PBFT\lib\site-packages\aiohttp\client.py", line 1141, in __aenter__
    self._resp = await self._coro
  File "D:\anaconda\envs\PBFT\lib\site-packages\aiohttp\client.py", line 537, in _request
    req, traces=traces, timeout=real_timeout
  File "D:\anaconda\envs\PBFT\lib\site-packages\aiohttp\connector.py", line 540, in connect
    proto = await self._create_connection(req, traces, timeout)
  File "D:\anaconda\envs\PBFT\lib\site-packages\aiohttp\connector.py", line 901, in _create_connection
    _, proto = await self._create_direct_connection(req, traces, timeout)
  File "D:\anaconda\envs\PBFT\lib\site-packages\aiohttp\connector.py", line 1206, in _create_direct_connection
    raise last_exc
  File "D:\anaconda\envs\PBFT\lib\site-packages\aiohttp\connector.py", line 1187, in _create_direct_connection
    client_error=client_error,
  File "D:\anaconda\envs\PBFT\lib\site-packages\aiohttp\connector.py", line 988, in _wrap_create_connection
    raise client_error(req.connection_key, exc) from exc
aiohttp.client_exceptions.ClientConnectorError: Cannot connect to host localhost:30029 ssl:default [Connect call failed ('::1', 30029, 0, 0)]
[2025-03-07 13:53:57,759] [ERROR] [30145] Error sending to http://localhost:30075/commit: Cannot connect to host localhost:30075 ssl:default [Connect call failed ('::1', 30075, 0, 0)]
Traceback (most recent call last):
  File "D:\anaconda\envs\PBFT\lib\site-packages\aiohttp\connector.py", line 980, in _wrap_create_connection
    return await self._loop.create_connection(*args, **kwargs)  # type: ignore[return-value]  # noqa
  File "D:\anaconda\envs\PBFT\lib\asyncio\base_events.py", line 948, in create_connection
    raise exceptions[0]
  File "D:\anaconda\envs\PBFT\lib\asyncio\base_events.py", line 935, in create_connection
    await self.sock_connect(sock, address)
  File "D:\anaconda\envs\PBFT\lib\asyncio\selector_events.py", line 475, in sock_connect
    return await fut
  File "D:\anaconda\envs\PBFT\lib\asyncio\selector_events.py", line 505, in _sock_connect_cb
    raise OSError(err, f'Connect call failed {address}')
ConnectionRefusedError: [Errno 10061] Connect call failed ('::1', 30075, 0, 0)

The above exception was the direct cause of the following exception:

Traceback (most recent call last):
  File "pbft.py", line 236, in send_message
    await send_with_delay(self.session, self.node_info, target, url, data, self.bandwidth_data)
  File "pbft.py", line 63, in send_with_delay
    async with session.post(url, json=data) as resp:
  File "D:\anaconda\envs\PBFT\lib\site-packages\aiohttp\client.py", line 1141, in __aenter__
    self._resp = await self._coro
  File "D:\anaconda\envs\PBFT\lib\site-packages\aiohttp\client.py", line 537, in _request
    req, traces=traces, timeout=real_timeout
  File "D:\anaconda\envs\PBFT\lib\site-packages\aiohttp\connector.py", line 540, in connect
    proto = await self._create_connection(req, traces, timeout)
  File "D:\anaconda\envs\PBFT\lib\site-packages\aiohttp\connector.py", line 901, in _create_connection
    _, proto = await self._create_direct_connection(req, traces, timeout)
  File "D:\anaconda\envs\PBFT\lib\site-packages\aiohttp\connector.py", line 1206, in _create_direct_connection
    raise last_exc
  File "D:\anaconda\envs\PBFT\lib\site-packages\aiohttp\connector.py", line 1187, in _create_direct_connection
    client_error=client_error,
  File "D:\anaconda\envs\PBFT\lib\site-packages\aiohttp\connector.py", line 988, in _wrap_create_connection
    raise client_error(req.connection_key, exc) from exc
aiohttp.client_exceptions.ClientConnectorError: Cannot connect to host localhost:30075 ssl:default [Connect call failed ('::1', 30075, 0, 0)]
[2025-03-07 13:53:57,888] [ERROR] [30145] Error sending to http://localhost:30025/commit: Cannot connect to host localhost:30025 ssl:default [Connect call failed ('::1', 30025, 0, 0)]
Traceback (most recent call last):
  File "D:\anaconda\envs\PBFT\lib\site-packages\aiohttp\connector.py", line 980, in _wrap_create_connection
    return await self._loop.create_connection(*args, **kwargs)  # type: ignore[return-value]  # noqa
  File "D:\anaconda\envs\PBFT\lib\asyncio\base_events.py", line 948, in create_connection
    raise exceptions[0]
  File "D:\anaconda\envs\PBFT\lib\asyncio\base_events.py", line 935, in create_connection
    await self.sock_connect(sock, address)
  File "D:\anaconda\envs\PBFT\lib\asyncio\selector_events.py", line 475, in sock_connect
    return await fut
  File "D:\anaconda\envs\PBFT\lib\asyncio\selector_events.py", line 505, in _sock_connect_cb
    raise OSError(err, f'Connect call failed {address}')
ConnectionRefusedError: [Errno 10061] Connect call failed ('::1', 30025, 0, 0)

The above exception was the direct cause of the following exception:

Traceback (most recent call last):
  File "pbft.py", line 236, in send_message
    await send_with_delay(self.session, self.node_info, target, url, data, self.bandwidth_data)
  File "pbft.py", line 63, in send_with_delay
    async with session.post(url, json=data) as resp:
  File "D:\anaconda\envs\PBFT\lib\site-packages\aiohttp\client.py", line 1141, in __aenter__
    self._resp = await self._coro
  File "D:\anaconda\envs\PBFT\lib\site-packages\aiohttp\client.py", line 537, in _request
    req, traces=traces, timeout=real_timeout
  File "D:\anaconda\envs\PBFT\lib\site-packages\aiohttp\connector.py", line 540, in connect
    proto = await self._create_connection(req, traces, timeout)
  File "D:\anaconda\envs\PBFT\lib\site-packages\aiohttp\connector.py", line 901, in _create_connection
    _, proto = await self._create_direct_connection(req, traces, timeout)
  File "D:\anaconda\envs\PBFT\lib\site-packages\aiohttp\connector.py", line 1206, in _create_direct_connection
    raise last_exc
  File "D:\anaconda\envs\PBFT\lib\site-packages\aiohttp\connector.py", line 1187, in _create_direct_connection
    client_error=client_error,
  File "D:\anaconda\envs\PBFT\lib\site-packages\aiohttp\connector.py", line 988, in _wrap_create_connection
    raise client_error(req.connection_key, exc) from exc
aiohttp.client_exceptions.ClientConnectorError: Cannot connect to host localhost:30025 ssl:default [Connect call failed ('::1', 30025, 0, 0)]
[2025-03-07 13:53:57,888] [ERROR] [30145] Error sending to http://localhost:30100/commit: Cannot connect to host localhost:30100 ssl:default [Connect call failed ('::1', 30100, 0, 0)]
Traceback (most recent call last):
  File "D:\anaconda\envs\PBFT\lib\site-packages\aiohttp\connector.py", line 980, in _wrap_create_connection
    return await self._loop.create_connection(*args, **kwargs)  # type: ignore[return-value]  # noqa
  File "D:\anaconda\envs\PBFT\lib\asyncio\base_events.py", line 948, in create_connection
    raise exceptions[0]
  File "D:\anaconda\envs\PBFT\lib\asyncio\base_events.py", line 935, in create_connection
    await self.sock_connect(sock, address)
  File "D:\anaconda\envs\PBFT\lib\asyncio\selector_events.py", line 475, in sock_connect
    return await fut
  File "D:\anaconda\envs\PBFT\lib\asyncio\selector_events.py", line 505, in _sock_connect_cb
    raise OSError(err, f'Connect call failed {address}')
ConnectionRefusedError: [Errno 10061] Connect call failed ('::1', 30100, 0, 0)

The above exception was the direct cause of the following exception:

Traceback (most recent call last):
  File "pbft.py", line 236, in send_message
    await send_with_delay(self.session, self.node_info, target, url, data, self.bandwidth_data)
  File "pbft.py", line 63, in send_with_delay
    async with session.post(url, json=data) as resp:
  File "D:\anaconda\envs\PBFT\lib\site-packages\aiohttp\client.py", line 1141, in __aenter__
    self._resp = await self._coro
  File "D:\anaconda\envs\PBFT\lib\site-packages\aiohttp\client.py", line 537, in _request
    req, traces=traces, timeout=real_timeout
  File "D:\anaconda\envs\PBFT\lib\site-packages\aiohttp\connector.py", line 540, in connect
    proto = await self._create_connection(req, traces, timeout)
  File "D:\anaconda\envs\PBFT\lib\site-packages\aiohttp\connector.py", line 901, in _create_connection
    _, proto = await self._create_direct_connection(req, traces, timeout)
  File "D:\anaconda\envs\PBFT\lib\site-packages\aiohttp\connector.py", line 1206, in _create_direct_connection
    raise last_exc
  File "D:\anaconda\envs\PBFT\lib\site-packages\aiohttp\connector.py", line 1187, in _create_direct_connection
    client_error=client_error,
  File "D:\anaconda\envs\PBFT\lib\site-packages\aiohttp\connector.py", line 988, in _wrap_create_connection
    raise client_error(req.connection_key, exc) from exc
aiohttp.client_exceptions.ClientConnectorError: Cannot connect to host localhost:30100 ssl:default [Connect call failed ('::1', 30100, 0, 0)]
[2025-03-07 13:53:57,918] [ERROR] [30145] Error sending to http://localhost:30140/commit: Cannot connect to host localhost:30140 ssl:default [Connect call failed ('::1', 30140, 0, 0)]
Traceback (most recent call last):
  File "D:\anaconda\envs\PBFT\lib\site-packages\aiohttp\connector.py", line 980, in _wrap_create_connection
    return await self._loop.create_connection(*args, **kwargs)  # type: ignore[return-value]  # noqa
  File "D:\anaconda\envs\PBFT\lib\asyncio\base_events.py", line 948, in create_connection
    raise exceptions[0]
  File "D:\anaconda\envs\PBFT\lib\asyncio\base_events.py", line 935, in create_connection
    await self.sock_connect(sock, address)
  File "D:\anaconda\envs\PBFT\lib\asyncio\selector_events.py", line 475, in sock_connect
    return await fut
  File "D:\anaconda\envs\PBFT\lib\asyncio\selector_events.py", line 505, in _sock_connect_cb
    raise OSError(err, f'Connect call failed {address}')
ConnectionRefusedError: [Errno 10061] Connect call failed ('::1', 30140, 0, 0)

The above exception was the direct cause of the following exception:

Traceback (most recent call last):
  File "pbft.py", line 236, in send_message
    await send_with_delay(self.session, self.node_info, target, url, data, self.bandwidth_data)
  File "pbft.py", line 63, in send_with_delay
    async with session.post(url, json=data) as resp:
  File "D:\anaconda\envs\PBFT\lib\site-packages\aiohttp\client.py", line 1141, in __aenter__
    self._resp = await self._coro
  File "D:\anaconda\envs\PBFT\lib\site-packages\aiohttp\client.py", line 537, in _request
    req, traces=traces, timeout=real_timeout
  File "D:\anaconda\envs\PBFT\lib\site-packages\aiohttp\connector.py", line 540, in connect
    proto = await self._create_connection(req, traces, timeout)
  File "D:\anaconda\envs\PBFT\lib\site-packages\aiohttp\connector.py", line 901, in _create_connection
    _, proto = await self._create_direct_connection(req, traces, timeout)
  File "D:\anaconda\envs\PBFT\lib\site-packages\aiohttp\connector.py", line 1206, in _create_direct_connection
    raise last_exc
  File "D:\anaconda\envs\PBFT\lib\site-packages\aiohttp\connector.py", line 1187, in _create_direct_connection
    client_error=client_error,
  File "D:\anaconda\envs\PBFT\lib\site-packages\aiohttp\connector.py", line 988, in _wrap_create_connection
    raise client_error(req.connection_key, exc) from exc
aiohttp.client_exceptions.ClientConnectorError: Cannot connect to host localhost:30140 ssl:default [Connect call failed ('::1', 30140, 0, 0)]
[2025-03-07 13:53:58,015] [ERROR] [30145] Error sending to http://localhost:30008/commit: Cannot connect to host localhost:30008 ssl:default [Connect call failed ('::1', 30008, 0, 0)]
Traceback (most recent call last):
  File "D:\anaconda\envs\PBFT\lib\site-packages\aiohttp\connector.py", line 980, in _wrap_create_connection
    return await self._loop.create_connection(*args, **kwargs)  # type: ignore[return-value]  # noqa
  File "D:\anaconda\envs\PBFT\lib\asyncio\base_events.py", line 948, in create_connection
    raise exceptions[0]
  File "D:\anaconda\envs\PBFT\lib\asyncio\base_events.py", line 935, in create_connection
    await self.sock_connect(sock, address)
  File "D:\anaconda\envs\PBFT\lib\asyncio\selector_events.py", line 475, in sock_connect
    return await fut
  File "D:\anaconda\envs\PBFT\lib\asyncio\selector_events.py", line 505, in _sock_connect_cb
    raise OSError(err, f'Connect call failed {address}')
ConnectionRefusedError: [Errno 10061] Connect call failed ('::1', 30008, 0, 0)

The above exception was the direct cause of the following exception:

Traceback (most recent call last):
  File "pbft.py", line 236, in send_message
    await send_with_delay(self.session, self.node_info, target, url, data, self.bandwidth_data)
  File "pbft.py", line 63, in send_with_delay
    async with session.post(url, json=data) as resp:
  File "D:\anaconda\envs\PBFT\lib\site-packages\aiohttp\client.py", line 1141, in __aenter__
    self._resp = await self._coro
  File "D:\anaconda\envs\PBFT\lib\site-packages\aiohttp\client.py", line 537, in _request
    req, traces=traces, timeout=real_timeout
  File "D:\anaconda\envs\PBFT\lib\site-packages\aiohttp\connector.py", line 540, in connect
    proto = await self._create_connection(req, traces, timeout)
  File "D:\anaconda\envs\PBFT\lib\site-packages\aiohttp\connector.py", line 901, in _create_connection
    _, proto = await self._create_direct_connection(req, traces, timeout)
  File "D:\anaconda\envs\PBFT\lib\site-packages\aiohttp\connector.py", line 1206, in _create_direct_connection
    raise last_exc
  File "D:\anaconda\envs\PBFT\lib\site-packages\aiohttp\connector.py", line 1187, in _create_direct_connection
    client_error=client_error,
  File "D:\anaconda\envs\PBFT\lib\site-packages\aiohttp\connector.py", line 988, in _wrap_create_connection
    raise client_error(req.connection_key, exc) from exc
aiohttp.client_exceptions.ClientConnectorError: Cannot connect to host localhost:30008 ssl:default [Connect call failed ('::1', 30008, 0, 0)]
[2025-03-07 13:53:58,283] [ERROR] [30145] Error sending to http://localhost:30125/prepare: Cannot connect to host localhost:30125 ssl:default [Connect call failed ('127.0.0.1', 30125)]
Traceback (most recent call last):
  File "D:\anaconda\envs\PBFT\lib\site-packages\aiohttp\connector.py", line 980, in _wrap_create_connection
    return await self._loop.create_connection(*args, **kwargs)  # type: ignore[return-value]  # noqa
  File "D:\anaconda\envs\PBFT\lib\asyncio\base_events.py", line 948, in create_connection
    raise exceptions[0]
  File "D:\anaconda\envs\PBFT\lib\asyncio\base_events.py", line 935, in create_connection
    await self.sock_connect(sock, address)
  File "D:\anaconda\envs\PBFT\lib\asyncio\selector_events.py", line 475, in sock_connect
    return await fut
  File "D:\anaconda\envs\PBFT\lib\asyncio\selector_events.py", line 505, in _sock_connect_cb
    raise OSError(err, f'Connect call failed {address}')
ConnectionRefusedError: [Errno 10061] Connect call failed ('127.0.0.1', 30125)

The above exception was the direct cause of the following exception:

Traceback (most recent call last):
  File "pbft.py", line 236, in send_message
    await send_with_delay(self.session, self.node_info, target, url, data, self.bandwidth_data)
  File "pbft.py", line 63, in send_with_delay
    async with session.post(url, json=data) as resp:
  File "D:\anaconda\envs\PBFT\lib\site-packages\aiohttp\client.py", line 1141, in __aenter__
    self._resp = await self._coro
  File "D:\anaconda\envs\PBFT\lib\site-packages\aiohttp\client.py", line 537, in _request
    req, traces=traces, timeout=real_timeout
  File "D:\anaconda\envs\PBFT\lib\site-packages\aiohttp\connector.py", line 540, in connect
    proto = await self._create_connection(req, traces, timeout)
  File "D:\anaconda\envs\PBFT\lib\site-packages\aiohttp\connector.py", line 901, in _create_connection
    _, proto = await self._create_direct_connection(req, traces, timeout)
  File "D:\anaconda\envs\PBFT\lib\site-packages\aiohttp\connector.py", line 1206, in _create_direct_connection
    raise last_exc
  File "D:\anaconda\envs\PBFT\lib\site-packages\aiohttp\connector.py", line 1187, in _create_direct_connection
    client_error=client_error,
  File "D:\anaconda\envs\PBFT\lib\site-packages\aiohttp\connector.py", line 988, in _wrap_create_connection
    raise client_error(req.connection_key, exc) from exc
aiohttp.client_exceptions.ClientConnectorError: Cannot connect to host localhost:30125 ssl:default [Connect call failed ('127.0.0.1', 30125)]
[2025-03-07 13:53:58,298] [ERROR] [30145] Error sending to http://localhost:30124/prepare: Cannot connect to host localhost:30124 ssl:default [Connect call failed ('127.0.0.1', 30124)]
Traceback (most recent call last):
  File "D:\anaconda\envs\PBFT\lib\site-packages\aiohttp\connector.py", line 980, in _wrap_create_connection
    return await self._loop.create_connection(*args, **kwargs)  # type: ignore[return-value]  # noqa
  File "D:\anaconda\envs\PBFT\lib\asyncio\base_events.py", line 948, in create_connection
    raise exceptions[0]
  File "D:\anaconda\envs\PBFT\lib\asyncio\base_events.py", line 935, in create_connection
    await self.sock_connect(sock, address)
  File "D:\anaconda\envs\PBFT\lib\asyncio\selector_events.py", line 475, in sock_connect
    return await fut
  File "D:\anaconda\envs\PBFT\lib\asyncio\selector_events.py", line 505, in _sock_connect_cb
    raise OSError(err, f'Connect call failed {address}')
ConnectionRefusedError: [Errno 10061] Connect call failed ('127.0.0.1', 30124)

The above exception was the direct cause of the following exception:

Traceback (most recent call last):
  File "pbft.py", line 236, in send_message
    await send_with_delay(self.session, self.node_info, target, url, data, self.bandwidth_data)
  File "pbft.py", line 63, in send_with_delay
    async with session.post(url, json=data) as resp:
  File "D:\anaconda\envs\PBFT\lib\site-packages\aiohttp\client.py", line 1141, in __aenter__
    self._resp = await self._coro
  File "D:\anaconda\envs\PBFT\lib\site-packages\aiohttp\client.py", line 537, in _request
    req, traces=traces, timeout=real_timeout
  File "D:\anaconda\envs\PBFT\lib\site-packages\aiohttp\connector.py", line 540, in connect
    proto = await self._create_connection(req, traces, timeout)
  File "D:\anaconda\envs\PBFT\lib\site-packages\aiohttp\connector.py", line 901, in _create_connection
    _, proto = await self._create_direct_connection(req, traces, timeout)
  File "D:\anaconda\envs\PBFT\lib\site-packages\aiohttp\connector.py", line 1206, in _create_direct_connection
    raise last_exc
  File "D:\anaconda\envs\PBFT\lib\site-packages\aiohttp\connector.py", line 1187, in _create_direct_connection
    client_error=client_error,
  File "D:\anaconda\envs\PBFT\lib\site-packages\aiohttp\connector.py", line 988, in _wrap_create_connection
    raise client_error(req.connection_key, exc) from exc
aiohttp.client_exceptions.ClientConnectorError: Cannot connect to host localhost:30124 ssl:default [Connect call failed ('127.0.0.1', 30124)]
[2025-03-07 13:53:58,298] [ERROR] [30145] Error sending to http://localhost:30125/commit: Cannot connect to host localhost:30125 ssl:default [Connect call failed ('::1', 30125, 0, 0)]
Traceback (most recent call last):
  File "D:\anaconda\envs\PBFT\lib\site-packages\aiohttp\connector.py", line 980, in _wrap_create_connection
    return await self._loop.create_connection(*args, **kwargs)  # type: ignore[return-value]  # noqa
  File "D:\anaconda\envs\PBFT\lib\asyncio\base_events.py", line 948, in create_connection
    raise exceptions[0]
  File "D:\anaconda\envs\PBFT\lib\asyncio\base_events.py", line 935, in create_connection
    await self.sock_connect(sock, address)
  File "D:\anaconda\envs\PBFT\lib\asyncio\selector_events.py", line 475, in sock_connect
    return await fut
  File "D:\anaconda\envs\PBFT\lib\asyncio\selector_events.py", line 505, in _sock_connect_cb
    raise OSError(err, f'Connect call failed {address}')
ConnectionRefusedError: [Errno 10061] Connect call failed ('::1', 30125, 0, 0)

The above exception was the direct cause of the following exception:

Traceback (most recent call last):
  File "pbft.py", line 236, in send_message
    await send_with_delay(self.session, self.node_info, target, url, data, self.bandwidth_data)
  File "pbft.py", line 63, in send_with_delay
    async with session.post(url, json=data) as resp:
  File "D:\anaconda\envs\PBFT\lib\site-packages\aiohttp\client.py", line 1141, in __aenter__
    self._resp = await self._coro
  File "D:\anaconda\envs\PBFT\lib\site-packages\aiohttp\client.py", line 537, in _request
    req, traces=traces, timeout=real_timeout
  File "D:\anaconda\envs\PBFT\lib\site-packages\aiohttp\connector.py", line 540, in connect
    proto = await self._create_connection(req, traces, timeout)
  File "D:\anaconda\envs\PBFT\lib\site-packages\aiohttp\connector.py", line 901, in _create_connection
    _, proto = await self._create_direct_connection(req, traces, timeout)
  File "D:\anaconda\envs\PBFT\lib\site-packages\aiohttp\connector.py", line 1206, in _create_direct_connection
    raise last_exc
  File "D:\anaconda\envs\PBFT\lib\site-packages\aiohttp\connector.py", line 1187, in _create_direct_connection
    client_error=client_error,
  File "D:\anaconda\envs\PBFT\lib\site-packages\aiohttp\connector.py", line 988, in _wrap_create_connection
    raise client_error(req.connection_key, exc) from exc
aiohttp.client_exceptions.ClientConnectorError: Cannot connect to host localhost:30125 ssl:default [Connect call failed ('::1', 30125, 0, 0)]
[2025-03-07 13:53:58,298] [ERROR] [30145] Error sending to http://localhost:30138/commit: Cannot connect to host localhost:30138 ssl:default [Connect call failed ('::1', 30138, 0, 0)]
Traceback (most recent call last):
  File "D:\anaconda\envs\PBFT\lib\site-packages\aiohttp\connector.py", line 980, in _wrap_create_connection
    return await self._loop.create_connection(*args, **kwargs)  # type: ignore[return-value]  # noqa
  File "D:\anaconda\envs\PBFT\lib\asyncio\base_events.py", line 948, in create_connection
    raise exceptions[0]
  File "D:\anaconda\envs\PBFT\lib\asyncio\base_events.py", line 935, in create_connection
    await self.sock_connect(sock, address)
  File "D:\anaconda\envs\PBFT\lib\asyncio\selector_events.py", line 475, in sock_connect
    return await fut
  File "D:\anaconda\envs\PBFT\lib\asyncio\selector_events.py", line 505, in _sock_connect_cb
    raise OSError(err, f'Connect call failed {address}')
ConnectionRefusedError: [Errno 10061] Connect call failed ('::1', 30138, 0, 0)

The above exception was the direct cause of the following exception:

Traceback (most recent call last):
  File "pbft.py", line 236, in send_message
    await send_with_delay(self.session, self.node_info, target, url, data, self.bandwidth_data)
  File "pbft.py", line 63, in send_with_delay
    async with session.post(url, json=data) as resp:
  File "D:\anaconda\envs\PBFT\lib\site-packages\aiohttp\client.py", line 1141, in __aenter__
    self._resp = await self._coro
  File "D:\anaconda\envs\PBFT\lib\site-packages\aiohttp\client.py", line 537, in _request
    req, traces=traces, timeout=real_timeout
  File "D:\anaconda\envs\PBFT\lib\site-packages\aiohttp\connector.py", line 540, in connect
    proto = await self._create_connection(req, traces, timeout)
  File "D:\anaconda\envs\PBFT\lib\site-packages\aiohttp\connector.py", line 901, in _create_connection
    _, proto = await self._create_direct_connection(req, traces, timeout)
  File "D:\anaconda\envs\PBFT\lib\site-packages\aiohttp\connector.py", line 1206, in _create_direct_connection
    raise last_exc
  File "D:\anaconda\envs\PBFT\lib\site-packages\aiohttp\connector.py", line 1187, in _create_direct_connection
    client_error=client_error,
  File "D:\anaconda\envs\PBFT\lib\site-packages\aiohttp\connector.py", line 988, in _wrap_create_connection
    raise client_error(req.connection_key, exc) from exc
aiohttp.client_exceptions.ClientConnectorError: Cannot connect to host localhost:30138 ssl:default [Connect call failed ('::1', 30138, 0, 0)]
[2025-03-07 13:53:58,298] [ERROR] [30145] Error sending to http://localhost:30138/prepare: Cannot connect to host localhost:30138 ssl:default [Connect call failed ('127.0.0.1', 30138)]
Traceback (most recent call last):
  File "D:\anaconda\envs\PBFT\lib\site-packages\aiohttp\connector.py", line 980, in _wrap_create_connection
    return await self._loop.create_connection(*args, **kwargs)  # type: ignore[return-value]  # noqa
  File "D:\anaconda\envs\PBFT\lib\asyncio\base_events.py", line 948, in create_connection
    raise exceptions[0]
  File "D:\anaconda\envs\PBFT\lib\asyncio\base_events.py", line 935, in create_connection
    await self.sock_connect(sock, address)
  File "D:\anaconda\envs\PBFT\lib\asyncio\selector_events.py", line 475, in sock_connect
    return await fut
  File "D:\anaconda\envs\PBFT\lib\asyncio\selector_events.py", line 505, in _sock_connect_cb
    raise OSError(err, f'Connect call failed {address}')
ConnectionRefusedError: [Errno 10061] Connect call failed ('127.0.0.1', 30138)

The above exception was the direct cause of the following exception:

Traceback (most recent call last):
  File "pbft.py", line 236, in send_message
    await send_with_delay(self.session, self.node_info, target, url, data, self.bandwidth_data)
  File "pbft.py", line 63, in send_with_delay
    async with session.post(url, json=data) as resp:
  File "D:\anaconda\envs\PBFT\lib\site-packages\aiohttp\client.py", line 1141, in __aenter__
    self._resp = await self._coro
  File "D:\anaconda\envs\PBFT\lib\site-packages\aiohttp\client.py", line 537, in _request
    req, traces=traces, timeout=real_timeout
  File "D:\anaconda\envs\PBFT\lib\site-packages\aiohttp\connector.py", line 540, in connect
    proto = await self._create_connection(req, traces, timeout)
  File "D:\anaconda\envs\PBFT\lib\site-packages\aiohttp\connector.py", line 901, in _create_connection
    _, proto = await self._create_direct_connection(req, traces, timeout)
  File "D:\anaconda\envs\PBFT\lib\site-packages\aiohttp\connector.py", line 1206, in _create_direct_connection
    raise last_exc
  File "D:\anaconda\envs\PBFT\lib\site-packages\aiohttp\connector.py", line 1187, in _create_direct_connection
    client_error=client_error,
  File "D:\anaconda\envs\PBFT\lib\site-packages\aiohttp\connector.py", line 988, in _wrap_create_connection
    raise client_error(req.connection_key, exc) from exc
aiohttp.client_exceptions.ClientConnectorError: Cannot connect to host localhost:30138 ssl:default [Connect call failed ('127.0.0.1', 30138)]
[2025-03-07 13:53:58,298] [ERROR] [30145] Error sending to http://localhost:30124/commit: Cannot connect to host localhost:30124 ssl:default [Connect call failed ('::1', 30124, 0, 0)]
Traceback (most recent call last):
  File "D:\anaconda\envs\PBFT\lib\site-packages\aiohttp\connector.py", line 980, in _wrap_create_connection
    return await self._loop.create_connection(*args, **kwargs)  # type: ignore[return-value]  # noqa
  File "D:\anaconda\envs\PBFT\lib\asyncio\base_events.py", line 948, in create_connection
    raise exceptions[0]
  File "D:\anaconda\envs\PBFT\lib\asyncio\base_events.py", line 935, in create_connection
    await self.sock_connect(sock, address)
  File "D:\anaconda\envs\PBFT\lib\asyncio\selector_events.py", line 475, in sock_connect
    return await fut
  File "D:\anaconda\envs\PBFT\lib\asyncio\selector_events.py", line 505, in _sock_connect_cb
    raise OSError(err, f'Connect call failed {address}')
ConnectionRefusedError: [Errno 10061] Connect call failed ('::1', 30124, 0, 0)

The above exception was the direct cause of the following exception:

Traceback (most recent call last):
  File "pbft.py", line 236, in send_message
    await send_with_delay(self.session, self.node_info, target, url, data, self.bandwidth_data)
  File "pbft.py", line 63, in send_with_delay
    async with session.post(url, json=data) as resp:
  File "D:\anaconda\envs\PBFT\lib\site-packages\aiohttp\client.py", line 1141, in __aenter__
    self._resp = await self._coro
  File "D:\anaconda\envs\PBFT\lib\site-packages\aiohttp\client.py", line 537, in _request
    req, traces=traces, timeout=real_timeout
  File "D:\anaconda\envs\PBFT\lib\site-packages\aiohttp\connector.py", line 540, in connect
    proto = await self._create_connection(req, traces, timeout)
  File "D:\anaconda\envs\PBFT\lib\site-packages\aiohttp\connector.py", line 901, in _create_connection
    _, proto = await self._create_direct_connection(req, traces, timeout)
  File "D:\anaconda\envs\PBFT\lib\site-packages\aiohttp\connector.py", line 1206, in _create_direct_connection
    raise last_exc
  File "D:\anaconda\envs\PBFT\lib\site-packages\aiohttp\connector.py", line 1187, in _create_direct_connection
    client_error=client_error,
  File "D:\anaconda\envs\PBFT\lib\site-packages\aiohttp\connector.py", line 988, in _wrap_create_connection
    raise client_error(req.connection_key, exc) from exc
aiohttp.client_exceptions.ClientConnectorError: Cannot connect to host localhost:30124 ssl:default [Connect call failed ('::1', 30124, 0, 0)]
[2025-03-07 13:53:58,314] [ERROR] [30145] Error sending to http://localhost:30141/prepare: Cannot connect to host localhost:30141 ssl:default [Connect call failed ('127.0.0.1', 30141)]
Traceback (most recent call last):
  File "D:\anaconda\envs\PBFT\lib\site-packages\aiohttp\connector.py", line 980, in _wrap_create_connection
    return await self._loop.create_connection(*args, **kwargs)  # type: ignore[return-value]  # noqa
  File "D:\anaconda\envs\PBFT\lib\asyncio\base_events.py", line 948, in create_connection
    raise exceptions[0]
  File "D:\anaconda\envs\PBFT\lib\asyncio\base_events.py", line 935, in create_connection
    await self.sock_connect(sock, address)
  File "D:\anaconda\envs\PBFT\lib\asyncio\selector_events.py", line 475, in sock_connect
    return await fut
  File "D:\anaconda\envs\PBFT\lib\asyncio\selector_events.py", line 505, in _sock_connect_cb
    raise OSError(err, f'Connect call failed {address}')
ConnectionRefusedError: [Errno 10061] Connect call failed ('127.0.0.1', 30141)

The above exception was the direct cause of the following exception:

Traceback (most recent call last):
  File "pbft.py", line 236, in send_message
    await send_with_delay(self.session, self.node_info, target, url, data, self.bandwidth_data)
  File "pbft.py", line 63, in send_with_delay
    async with session.post(url, json=data) as resp:
  File "D:\anaconda\envs\PBFT\lib\site-packages\aiohttp\client.py", line 1141, in __aenter__
    self._resp = await self._coro
  File "D:\anaconda\envs\PBFT\lib\site-packages\aiohttp\client.py", line 537, in _request
    req, traces=traces, timeout=real_timeout
  File "D:\anaconda\envs\PBFT\lib\site-packages\aiohttp\connector.py", line 540, in connect
    proto = await self._create_connection(req, traces, timeout)
  File "D:\anaconda\envs\PBFT\lib\site-packages\aiohttp\connector.py", line 901, in _create_connection
    _, proto = await self._create_direct_connection(req, traces, timeout)
  File "D:\anaconda\envs\PBFT\lib\site-packages\aiohttp\connector.py", line 1206, in _create_direct_connection
    raise last_exc
  File "D:\anaconda\envs\PBFT\lib\site-packages\aiohttp\connector.py", line 1187, in _create_direct_connection
    client_error=client_error,
  File "D:\anaconda\envs\PBFT\lib\site-packages\aiohttp\connector.py", line 988, in _wrap_create_connection
    raise client_error(req.connection_key, exc) from exc
aiohttp.client_exceptions.ClientConnectorError: Cannot connect to host localhost:30141 ssl:default [Connect call failed ('127.0.0.1', 30141)]
[2025-03-07 13:53:58,314] [ERROR] [30145] Error sending to http://localhost:30141/commit: Cannot connect to host localhost:30141 ssl:default [Connect call failed ('::1', 30141, 0, 0)]
Traceback (most recent call last):
  File "D:\anaconda\envs\PBFT\lib\site-packages\aiohttp\connector.py", line 980, in _wrap_create_connection
    return await self._loop.create_connection(*args, **kwargs)  # type: ignore[return-value]  # noqa
  File "D:\anaconda\envs\PBFT\lib\asyncio\base_events.py", line 948, in create_connection
    raise exceptions[0]
  File "D:\anaconda\envs\PBFT\lib\asyncio\base_events.py", line 935, in create_connection
    await self.sock_connect(sock, address)
  File "D:\anaconda\envs\PBFT\lib\asyncio\selector_events.py", line 475, in sock_connect
    return await fut
  File "D:\anaconda\envs\PBFT\lib\asyncio\selector_events.py", line 505, in _sock_connect_cb
    raise OSError(err, f'Connect call failed {address}')
ConnectionRefusedError: [Errno 10061] Connect call failed ('::1', 30141, 0, 0)

The above exception was the direct cause of the following exception:

Traceback (most recent call last):
  File "pbft.py", line 236, in send_message
    await send_with_delay(self.session, self.node_info, target, url, data, self.bandwidth_data)
  File "pbft.py", line 63, in send_with_delay
    async with session.post(url, json=data) as resp:
  File "D:\anaconda\envs\PBFT\lib\site-packages\aiohttp\client.py", line 1141, in __aenter__
    self._resp = await self._coro
  File "D:\anaconda\envs\PBFT\lib\site-packages\aiohttp\client.py", line 537, in _request
    req, traces=traces, timeout=real_timeout
  File "D:\anaconda\envs\PBFT\lib\site-packages\aiohttp\connector.py", line 540, in connect
    proto = await self._create_connection(req, traces, timeout)
  File "D:\anaconda\envs\PBFT\lib\site-packages\aiohttp\connector.py", line 901, in _create_connection
    _, proto = await self._create_direct_connection(req, traces, timeout)
  File "D:\anaconda\envs\PBFT\lib\site-packages\aiohttp\connector.py", line 1206, in _create_direct_connection
    raise last_exc
  File "D:\anaconda\envs\PBFT\lib\site-packages\aiohttp\connector.py", line 1187, in _create_direct_connection
    client_error=client_error,
  File "D:\anaconda\envs\PBFT\lib\site-packages\aiohttp\connector.py", line 988, in _wrap_create_connection
    raise client_error(req.connection_key, exc) from exc
aiohttp.client_exceptions.ClientConnectorError: Cannot connect to host localhost:30141 ssl:default [Connect call failed ('::1', 30141, 0, 0)]
[2025-03-07 13:53:58,443] [ERROR] [30145] Error sending to http://localhost:30137/prepare: Cannot connect to host localhost:30137 ssl:default [Connect call failed ('127.0.0.1', 30137)]
Traceback (most recent call last):
  File "D:\anaconda\envs\PBFT\lib\site-packages\aiohttp\connector.py", line 980, in _wrap_create_connection
    return await self._loop.create_connection(*args, **kwargs)  # type: ignore[return-value]  # noqa
  File "D:\anaconda\envs\PBFT\lib\asyncio\base_events.py", line 948, in create_connection
    raise exceptions[0]
  File "D:\anaconda\envs\PBFT\lib\asyncio\base_events.py", line 935, in create_connection
    await self.sock_connect(sock, address)
  File "D:\anaconda\envs\PBFT\lib\asyncio\selector_events.py", line 475, in sock_connect
    return await fut
  File "D:\anaconda\envs\PBFT\lib\asyncio\selector_events.py", line 505, in _sock_connect_cb
    raise OSError(err, f'Connect call failed {address}')
ConnectionRefusedError: [Errno 10061] Connect call failed ('127.0.0.1', 30137)

The above exception was the direct cause of the following exception:

Traceback (most recent call last):
  File "pbft.py", line 236, in send_message
    await send_with_delay(self.session, self.node_info, target, url, data, self.bandwidth_data)
  File "pbft.py", line 63, in send_with_delay
    async with session.post(url, json=data) as resp:
  File "D:\anaconda\envs\PBFT\lib\site-packages\aiohttp\client.py", line 1141, in __aenter__
    self._resp = await self._coro
  File "D:\anaconda\envs\PBFT\lib\site-packages\aiohttp\client.py", line 537, in _request
    req, traces=traces, timeout=real_timeout
  File "D:\anaconda\envs\PBFT\lib\site-packages\aiohttp\connector.py", line 540, in connect
    proto = await self._create_connection(req, traces, timeout)
  File "D:\anaconda\envs\PBFT\lib\site-packages\aiohttp\connector.py", line 901, in _create_connection
    _, proto = await self._create_direct_connection(req, traces, timeout)
  File "D:\anaconda\envs\PBFT\lib\site-packages\aiohttp\connector.py", line 1206, in _create_direct_connection
    raise last_exc
  File "D:\anaconda\envs\PBFT\lib\site-packages\aiohttp\connector.py", line 1187, in _create_direct_connection
    client_error=client_error,
  File "D:\anaconda\envs\PBFT\lib\site-packages\aiohttp\connector.py", line 988, in _wrap_create_connection
    raise client_error(req.connection_key, exc) from exc
aiohttp.client_exceptions.ClientConnectorError: Cannot connect to host localhost:30137 ssl:default [Connect call failed ('127.0.0.1', 30137)]
[2025-03-07 13:53:58,473] [ERROR] [30145] Error sending to http://localhost:30137/commit: Cannot connect to host localhost:30137 ssl:default [Connect call failed ('::1', 30137, 0, 0)]
Traceback (most recent call last):
  File "D:\anaconda\envs\PBFT\lib\site-packages\aiohttp\connector.py", line 980, in _wrap_create_connection
    return await self._loop.create_connection(*args, **kwargs)  # type: ignore[return-value]  # noqa
  File "D:\anaconda\envs\PBFT\lib\asyncio\base_events.py", line 948, in create_connection
    raise exceptions[0]
  File "D:\anaconda\envs\PBFT\lib\asyncio\base_events.py", line 935, in create_connection
    await self.sock_connect(sock, address)
  File "D:\anaconda\envs\PBFT\lib\asyncio\selector_events.py", line 475, in sock_connect
    return await fut
  File "D:\anaconda\envs\PBFT\lib\asyncio\selector_events.py", line 505, in _sock_connect_cb
    raise OSError(err, f'Connect call failed {address}')
ConnectionRefusedError: [Errno 10061] Connect call failed ('::1', 30137, 0, 0)

The above exception was the direct cause of the following exception:

Traceback (most recent call last):
  File "pbft.py", line 236, in send_message
    await send_with_delay(self.session, self.node_info, target, url, data, self.bandwidth_data)
  File "pbft.py", line 63, in send_with_delay
    async with session.post(url, json=data) as resp:
  File "D:\anaconda\envs\PBFT\lib\site-packages\aiohttp\client.py", line 1141, in __aenter__
    self._resp = await self._coro
  File "D:\anaconda\envs\PBFT\lib\site-packages\aiohttp\client.py", line 537, in _request
    req, traces=traces, timeout=real_timeout
  File "D:\anaconda\envs\PBFT\lib\site-packages\aiohttp\connector.py", line 540, in connect
    proto = await self._create_connection(req, traces, timeout)
  File "D:\anaconda\envs\PBFT\lib\site-packages\aiohttp\connector.py", line 901, in _create_connection
    _, proto = await self._create_direct_connection(req, traces, timeout)
  File "D:\anaconda\envs\PBFT\lib\site-packages\aiohttp\connector.py", line 1206, in _create_direct_connection
    raise last_exc
  File "D:\anaconda\envs\PBFT\lib\site-packages\aiohttp\connector.py", line 1187, in _create_direct_connection
    client_error=client_error,
  File "D:\anaconda\envs\PBFT\lib\site-packages\aiohttp\connector.py", line 988, in _wrap_create_connection
    raise client_error(req.connection_key, exc) from exc
aiohttp.client_exceptions.ClientConnectorError: Cannot connect to host localhost:30137 ssl:default [Connect call failed ('::1', 30137, 0, 0)]
[2025-03-07 13:54:56,873] [INFO] Starting node at localhost:30145 | index=146 | f=1, k=4 | Role: Replica
[2025-03-07 13:57:43,311] [INFO] Starting node at localhost:30145 | index=146 | f=1, k=4 | Role: Replica
[2025-03-07 13:58:45,727] [INFO] Starting node at localhost:30145 | index=146 | f=1, k=4 | Role: Replica
[2025-03-07 13:59:03,201] [INFO] [30145] Received PREPARE: id:1741323542381, from:30118, delay:0.0000s, distance:150.60m (Euclidean)
[2025-03-07 13:59:03,201] [INFO] [30145] Missing PRE-PREPARE for REQUEST 1741323542381; ignoring PREPARE
[2025-03-07 13:59:03,408] [INFO] [30145] Received PREPARE: id:1741323542381, from:30109, delay:0.0000s, distance:200.74m (Euclidean)
[2025-03-07 13:59:03,408] [INFO] [30145] Missing PRE-PREPARE for REQUEST 1741323542381; ignoring PREPARE
[2025-03-07 13:59:04,190] [INFO] [30145] Received PREPARE: id:1741323542381, from:30126, delay:0.0000s, distance:126.17m (Euclidean)
[2025-03-07 13:59:04,190] [INFO] [30145] Missing PRE-PREPARE for REQUEST 1741323542381; ignoring PREPARE
[2025-03-07 13:59:04,213] [INFO] [30145] Received PREPARE: id:1741323542381, from:30110, delay:0.0000s, distance:152.18m (Euclidean)
[2025-03-07 13:59:04,213] [INFO] [30145] Missing PRE-PREPARE for REQUEST 1741323542381; ignoring PREPARE
[2025-03-07 13:59:04,388] [INFO] [30145] Received COMMIT: id:1741323542381, from:30110, delay:0.0000s, distance:152.18m (Euclidean)
[2025-03-07 13:59:04,443] [INFO] [30145] Received PREPARE: id:1741323542381, from:30037, delay:0.0001s, distance:167.03m (Euclidean)
[2025-03-07 13:59:04,443] [INFO] [30145] Missing PRE-PREPARE for REQUEST 1741323542381; ignoring PREPARE
[2025-03-07 13:59:04,507] [INFO] [30145] Received PREPARE: id:1741323542381, from:30157, delay:0.0001s, distance:238.08m (Euclidean)
[2025-03-07 13:59:04,507] [INFO] [30145] Missing PRE-PREPARE for REQUEST 1741323542381; ignoring PREPARE
[2025-03-07 13:59:04,530] [INFO] [30145] Received COMMIT: id:1741323542381, from:30118, delay:0.0000s, distance:150.60m (Euclidean)
[2025-03-07 13:59:04,543] [INFO] [30145] Received PREPARE: id:1741323542381, from:30013, delay:0.0000s, distance:103.30m (Euclidean)
[2025-03-07 13:59:04,543] [INFO] [30145] Missing PRE-PREPARE for REQUEST 1741323542381; ignoring PREPARE
[2025-03-07 13:59:04,650] [INFO] [30145] Received PREPARE: id:1741323542381, from:30123, delay:0.0002s, distance:275.84m (Euclidean)
[2025-03-07 13:59:04,650] [INFO] [30145] Missing PRE-PREPARE for REQUEST 1741323542381; ignoring PREPARE
[2025-03-07 13:59:04,710] [INFO] [30145] Received COMMIT: id:1741323542381, from:30037, delay:0.0001s, distance:167.03m (Euclidean)
[2025-03-07 13:59:04,788] [INFO] [30145] Received PREPARE: id:1741323542381, from:30196, delay:0.0000s, distance:149.17m (Euclidean)
[2025-03-07 13:59:04,788] [INFO] [30145] Missing PRE-PREPARE for REQUEST 1741323542381; ignoring PREPARE
[2025-03-07 13:59:04,788] [INFO] [30145] Received COMMIT: id:1741323542381, from:30196, delay:0.0000s, distance:149.17m (Euclidean)
[2025-03-07 13:59:04,987] [INFO] [30145] Received COMMIT: id:1741323542381, from:30157, delay:0.0001s, distance:238.08m (Euclidean)
[2025-03-07 13:59:04,989] [INFO] [30145] Received PREPARE: id:1741323542381, from:30149, delay:0.0001s, distance:246.69m (Euclidean)
[2025-03-07 13:59:04,989] [INFO] [30145] Missing PRE-PREPARE for REQUEST 1741323542381; ignoring PREPARE
[2025-03-07 13:59:05,275] [INFO] [30145] Received PREPARE: id:1741323542381, from:30100, delay:0.0001s, distance:186.93m (Euclidean)
[2025-03-07 13:59:05,275] [INFO] [30145] Missing PRE-PREPARE for REQUEST 1741323542381; ignoring PREPARE
[2025-03-07 13:59:05,355] [INFO] [30145] Received COMMIT: id:1741323542381, from:30149, delay:0.0001s, distance:246.69m (Euclidean)
[2025-03-07 13:59:05,398] [INFO] [30145] Received PREPARE: id:1741323542381, from:30113, delay:0.0001s, distance:232.46m (Euclidean)
[2025-03-07 13:59:05,398] [INFO] [30145] Missing PRE-PREPARE for REQUEST 1741323542381; ignoring PREPARE
[2025-03-07 13:59:05,451] [INFO] [30145] Received PREPARE: id:1741323542381, from:30181, delay:0.0002s, distance:268.61m (Euclidean)
[2025-03-07 13:59:05,451] [INFO] [30145] Missing PRE-PREPARE for REQUEST 1741323542381; ignoring PREPARE
[2025-03-07 13:59:05,498] [INFO] [30145] Received PREPARE: id:1741323542381, from:30029, delay:0.0001s, distance:206.79m (Euclidean)
[2025-03-07 13:59:05,498] [INFO] [30145] Missing PRE-PREPARE for REQUEST 1741323542381; ignoring PREPARE
[2025-03-07 13:59:05,498] [INFO] [30145] Received COMMIT: id:1741323542381, from:30029, delay:0.0001s, distance:206.79m (Euclidean)
[2025-03-07 13:59:05,650] [INFO] [30145] Received COMMIT: id:1741323542381, from:30123, delay:0.0002s, distance:275.84m (Euclidean)
[2025-03-07 13:59:05,663] [INFO] [30145] Received PREPARE: id:1741323542381, from:30048, delay:0.0001s, distance:224.84m (Euclidean)
[2025-03-07 13:59:05,663] [INFO] [30145] Missing PRE-PREPARE for REQUEST 1741323542381; ignoring PREPARE
[2025-03-07 13:59:05,719] [INFO] [30145] Received PREPARE: id:1741323542381, from:30147, delay:0.0001s, distance:216.45m (Euclidean)
[2025-03-07 13:59:05,719] [INFO] [30145] Missing PRE-PREPARE for REQUEST 1741323542381; ignoring PREPARE
[2025-03-07 13:59:05,754] [INFO] [30145] Received PREPARE: id:1741323542381, from:30093, delay:0.0001s, distance:182.50m (Euclidean)
[2025-03-07 13:59:05,754] [INFO] [30145] Missing PRE-PREPARE for REQUEST 1741323542381; ignoring PREPARE
[2025-03-07 13:59:05,843] [INFO] [30145] Received PREPARE: id:1741323542381, from:30199, delay:0.0001s, distance:169.28m (Euclidean)
[2025-03-07 13:59:05,843] [INFO] [30145] Missing PRE-PREPARE for REQUEST 1741323542381; ignoring PREPARE
[2025-03-07 13:59:05,993] [INFO] [30145] Received PREPARE: id:1741323542381, from:30098, delay:0.0000s, distance:107.42m (Euclidean)
[2025-03-07 13:59:05,993] [INFO] [30145] Missing PRE-PREPARE for REQUEST 1741323542381; ignoring PREPARE
[2025-03-07 13:59:05,993] [INFO] [30145] Received PREPARE: id:1741323542381, from:30060, delay:0.0001s, distance:199.43m (Euclidean)
[2025-03-07 13:59:05,993] [INFO] [30145] Missing PRE-PREPARE for REQUEST 1741323542381; ignoring PREPARE
[2025-03-07 13:59:05,995] [INFO] [30145] Received COMMIT: id:1741323542381, from:30048, delay:0.0001s, distance:224.84m (Euclidean)
[2025-03-07 13:59:06,018] [INFO] [30145] Received COMMIT: id:1741323542381, from:30126, delay:0.0000s, distance:126.17m (Euclidean)
[2025-03-07 13:59:06,050] [INFO] [30145] Received PREPARE: id:1741323542381, from:30004, delay:0.0000s, distance:175.77m (Euclidean)
[2025-03-07 13:59:06,050] [INFO] [30145] Missing PRE-PREPARE for REQUEST 1741323542381; ignoring PREPARE
[2025-03-07 13:59:06,117] [INFO] [30145] Received COMMIT: id:1741323542381, from:30004, delay:0.0000s, distance:175.77m (Euclidean)
[2025-03-07 13:59:06,142] [INFO] [30145] Received PREPARE: id:1741323542381, from:30053, delay:0.0001s, distance:239.57m (Euclidean)
[2025-03-07 13:59:06,142] [INFO] [30145] Missing PRE-PREPARE for REQUEST 1741323542381; ignoring PREPARE
[2025-03-07 13:59:06,194] [INFO] [30145] Received PREPARE: id:1741323542381, from:30127, delay:0.0001s, distance:216.34m (Euclidean)
[2025-03-07 13:59:06,194] [INFO] [30145] Missing PRE-PREPARE for REQUEST 1741323542381; ignoring PREPARE
[2025-03-07 13:59:06,217] [INFO] [30145] Received PREPARE: id:1741323542381, from:30108, delay:0.0001s, distance:245.30m (Euclidean)
[2025-03-07 13:59:06,217] [INFO] [30145] Missing PRE-PREPARE for REQUEST 1741323542381; ignoring PREPARE
[2025-03-07 13:59:06,243] [INFO] [30145] Received PREPARE: id:1741323542381, from:30054, delay:0.0002s, distance:288.33m (Euclidean)
[2025-03-07 13:59:06,243] [INFO] [30145] Missing PRE-PREPARE for REQUEST 1741323542381; ignoring PREPARE
[2025-03-07 13:59:06,266] [INFO] [30145] Received PREPARE: id:1741323542381, from:30106, delay:0.0001s, distance:222.88m (Euclidean)
[2025-03-07 13:59:06,266] [INFO] [30145] Missing PRE-PREPARE for REQUEST 1741323542381; ignoring PREPARE
[2025-03-07 13:59:06,268] [INFO] [30145] Received COMMIT: id:1741323542381, from:30093, delay:0.0001s, distance:182.50m (Euclidean)
[2025-03-07 13:59:06,327] [INFO] [30145] Received COMMIT: id:1741323542381, from:30106, delay:0.0001s, distance:222.88m (Euclidean)
[2025-03-07 13:59:06,327] [INFO] [30145] Received COMMIT: id:1741323542381, from:30098, delay:0.0000s, distance:107.42m (Euclidean)
[2025-03-07 13:59:06,345] [INFO] [30145] Received COMMIT: id:1741323542381, from:30108, delay:0.0001s, distance:245.30m (Euclidean)
[2025-03-07 13:59:06,381] [INFO] [30145] Received PREPARE: id:1741323542381, from:30041, delay:0.0001s, distance:246.49m (Euclidean)
[2025-03-07 13:59:06,381] [INFO] [30145] Missing PRE-PREPARE for REQUEST 1741323542381; ignoring PREPARE
[2025-03-07 13:59:06,452] [INFO] [30145] Received COMMIT: id:1741323542381, from:30147, delay:0.0001s, distance:216.45m (Euclidean)
[2025-03-07 13:59:06,586] [INFO] [30145] Received COMMIT: id:1741323542381, from:30053, delay:0.0001s, distance:239.57m (Euclidean)
[2025-03-07 13:59:06,586] [INFO] [30145] Received COMMIT: id:1741323542381, from:30054, delay:0.0002s, distance:288.33m (Euclidean)
[2025-03-07 13:59:06,588] [INFO] [30145] Received COMMIT: id:1741323542381, from:30199, delay:0.0001s, distance:169.28m (Euclidean)
[2025-03-07 13:59:06,588] [INFO] [30145] Received PREPARE: id:1741323542381, from:30059, delay:0.0000s, distance:101.70m (Euclidean)
[2025-03-07 13:59:06,588] [INFO] [30145] Missing PRE-PREPARE for REQUEST 1741323542381; ignoring PREPARE
[2025-03-07 13:59:06,645] [INFO] [30145] Received COMMIT: id:1741323542381, from:30013, delay:0.0000s, distance:103.30m (Euclidean)
[2025-03-07 13:59:06,739] [INFO] [30145] Received PREPARE: id:1741323542381, from:30195, delay:0.0002s, distance:278.80m (Euclidean)
[2025-03-07 13:59:06,739] [INFO] [30145] Missing PRE-PREPARE for REQUEST 1741323542381; ignoring PREPARE
[2025-03-07 13:59:06,739] [INFO] [30145] Received COMMIT: id:1741323542381, from:30195, delay:0.0002s, distance:278.80m (Euclidean)
[2025-03-07 13:59:06,760] [INFO] [30145] Received PREPARE: id:1741323542381, from:30080, delay:0.0002s, distance:282.45m (Euclidean)
[2025-03-07 13:59:06,760] [INFO] [30145] Missing PRE-PREPARE for REQUEST 1741323542381; ignoring PREPARE
[2025-03-07 13:59:06,812] [INFO] [30145] Received PREPARE: id:1741323542381, from:30161, delay:0.0001s, distance:209.62m (Euclidean)
[2025-03-07 13:59:06,815] [INFO] [30145] Missing PRE-PREPARE for REQUEST 1741323542381; ignoring PREPARE
[2025-03-07 13:59:06,821] [INFO] [30145] Received COMMIT: id:1741323542381, from:30080, delay:0.0002s, distance:282.45m (Euclidean)
[2025-03-07 13:59:06,825] [INFO] [30145] Received COMMIT: id:1741323542381, from:30060, delay:0.0001s, distance:199.43m (Euclidean)
[2025-03-07 13:59:06,838] [INFO] [30145] Received PREPARE: id:1741323542381, from:30177, delay:0.0002s, distance:278.68m (Euclidean)
[2025-03-07 13:59:06,838] [INFO] [30145] Missing PRE-PREPARE for REQUEST 1741323542381; ignoring PREPARE
[2025-03-07 13:59:06,910] [INFO] [30145] Received COMMIT: id:1741323542381, from:30127, delay:0.0001s, distance:216.34m (Euclidean)
[2025-03-07 13:59:06,973] [INFO] [30145] Received PREPARE: id:1741323542381, from:30169, delay:0.0000s, distance:148.45m (Euclidean)
[2025-03-07 13:59:06,973] [INFO] [30145] Missing PRE-PREPARE for REQUEST 1741323542381; ignoring PREPARE
[2025-03-07 13:59:07,052] [INFO] [30145] Received PREPARE: id:1741323542381, from:30070, delay:0.0002s, distance:261.30m (Euclidean)
[2025-03-07 13:59:07,052] [INFO] [30145] Missing PRE-PREPARE for REQUEST 1741323542381; ignoring PREPARE
[2025-03-07 13:59:07,074] [INFO] [30145] Received COMMIT: id:1741323542381, from:30041, delay:0.0001s, distance:246.49m (Euclidean)
[2025-03-07 13:59:07,151] [INFO] [30145] Received PREPARE: id:1741323542381, from:30111, delay:0.0000s, distance:158.79m (Euclidean)
[2025-03-07 13:59:07,151] [INFO] [30145] Missing PRE-PREPARE for REQUEST 1741323542381; ignoring PREPARE
[2025-03-07 13:59:07,158] [INFO] [30145] Received PREPARE: id:1741323542381, from:30190, delay:0.0002s, distance:251.65m (Euclidean)
[2025-03-07 13:59:07,158] [INFO] [30145] Missing PRE-PREPARE for REQUEST 1741323542381; ignoring PREPARE
[2025-03-07 13:59:07,237] [INFO] [30145] Received PREPARE: id:1741323542381, from:30144, delay:0.0002s, distance:282.98m (Euclidean)
[2025-03-07 13:59:07,237] [INFO] [30145] Missing PRE-PREPARE for REQUEST 1741323542381; ignoring PREPARE
[2025-03-07 13:59:07,237] [INFO] [30145] Received COMMIT: id:1741323542381, from:30144, delay:0.0002s, distance:282.98m (Euclidean)
[2025-03-07 13:59:07,337] [INFO] [30145] Received PREPARE: id:1741323542381, from:30178, delay:0.0001s, distance:255.33m (Euclidean)
[2025-03-07 13:59:07,337] [INFO] [30145] Missing PRE-PREPARE for REQUEST 1741323542381; ignoring PREPARE
[2025-03-07 13:59:07,341] [INFO] [30145] Received COMMIT: id:1741323542381, from:30100, delay:0.0001s, distance:186.93m (Euclidean)
[2025-03-07 13:59:07,373] [INFO] [30145] Received PREPARE: id:1741323542381, from:30168, delay:0.0002s, distance:296.90m (Euclidean)
[2025-03-07 13:59:07,373] [INFO] [30145] Missing PRE-PREPARE for REQUEST 1741323542381; ignoring PREPARE
[2025-03-07 13:59:07,400] [INFO] [30145] Received COMMIT: id:1741323542381, from:30190, delay:0.0002s, distance:251.65m (Euclidean)
[2025-03-07 13:59:07,411] [INFO] [30145] Received PREPARE: id:1741323542381, from:30056, delay:0.0001s, distance:179.44m (Euclidean)
[2025-03-07 13:59:07,411] [INFO] [30145] Missing PRE-PREPARE for REQUEST 1741323542381; ignoring PREPARE
[2025-03-07 13:59:07,431] [INFO] [30145] Received PREPARE: id:1741323542381, from:30150, delay:0.0000s, distance:167.01m (Euclidean)
[2025-03-07 13:59:07,431] [INFO] [30145] Missing PRE-PREPARE for REQUEST 1741323542381; ignoring PREPARE
[2025-03-07 13:59:07,457] [INFO] [30145] Received COMMIT: id:1741323542381, from:30056, delay:0.0001s, distance:179.44m (Euclidean)
[2025-03-07 13:59:07,463] [INFO] [30145] Received COMMIT: id:1741323542381, from:30059, delay:0.0000s, distance:101.70m (Euclidean)
[2025-03-07 13:59:07,510] [INFO] [30145] Received PREPARE: id:1741323542381, from:30120, delay:0.0002s, distance:268.47m (Euclidean)
[2025-03-07 13:59:07,510] [INFO] [30145] Missing PRE-PREPARE for REQUEST 1741323542381; ignoring PREPARE
[2025-03-07 13:59:07,510] [INFO] [30145] Received COMMIT: id:1741323542381, from:30111, delay:0.0000s, distance:158.79m (Euclidean)
[2025-03-07 13:59:07,557] [INFO] [30145] Received COMMIT: id:1741323542381, from:30161, delay:0.0001s, distance:209.62m (Euclidean)
[2025-03-07 13:59:07,638] [INFO] [30145] Received COMMIT: id:1741323542381, from:30070, delay:0.0002s, distance:261.30m (Euclidean)
[2025-03-07 13:59:07,752] [INFO] [30145] Received PREPARE: id:1741323542381, from:30090, delay:0.0001s, distance:207.80m (Euclidean)
[2025-03-07 13:59:07,752] [INFO] [30145] Missing PRE-PREPARE for REQUEST 1741323542381; ignoring PREPARE
[2025-03-07 13:59:07,752] [INFO] [30145] Received PREPARE: id:1741323542381, from:30124, delay:0.0001s, distance:153.99m (Euclidean)
[2025-03-07 13:59:07,752] [INFO] [30145] Missing PRE-PREPARE for REQUEST 1741323542381; ignoring PREPARE
[2025-03-07 13:59:07,754] [INFO] [30145] Received PREPARE: id:1741323542381, from:30136, delay:0.0002s, distance:261.28m (Euclidean)
[2025-03-07 13:59:07,754] [INFO] [30145] Missing PRE-PREPARE for REQUEST 1741323542381; ignoring PREPARE
[2025-03-07 13:59:07,754] [INFO] [30145] Received COMMIT: id:1741323542381, from:30113, delay:0.0001s, distance:232.46m (Euclidean)
[2025-03-07 13:59:07,754] [INFO] [30145] Received COMMIT: id:1741323542381, from:30090, delay:0.0001s, distance:207.80m (Euclidean)
[2025-03-07 13:59:07,754] [INFO] [30145] Received COMMIT: id:1741323542381, from:30169, delay:0.0000s, distance:148.45m (Euclidean)
[2025-03-07 13:59:07,756] [INFO] [30145] Received PREPARE: id:1741323542381, from:30085, delay:0.0000s, distance:116.36m (Euclidean)
[2025-03-07 13:59:07,756] [INFO] [30145] Missing PRE-PREPARE for REQUEST 1741323542381; ignoring PREPARE
[2025-03-07 13:59:07,756] [INFO] [30145] Received PREPARE: id:1741323542381, from:30170, delay:0.0000s, distance:128.59m (Euclidean)
[2025-03-07 13:59:07,756] [INFO] [30145] Missing PRE-PREPARE for REQUEST 1741323542381; ignoring PREPARE
[2025-03-07 13:59:07,756] [INFO] [30145] Received COMMIT: id:1741323542381, from:30170, delay:0.0000s, distance:128.59m (Euclidean)
[2025-03-07 13:59:07,756] [INFO] [30145] Received COMMIT: id:1741323542381, from:30085, delay:0.0000s, distance:116.36m (Euclidean)
[2025-03-07 13:59:07,772] [INFO] [30145] Received COMMIT: id:1741323542381, from:30168, delay:0.0002s, distance:296.90m (Euclidean)
[2025-03-07 13:59:07,857] [INFO] [30145] Received PREPARE: id:1741323542381, from:30092, delay:0.0001s, distance:204.25m (Euclidean)
[2025-03-07 13:59:07,857] [INFO] [30145] Missing PRE-PREPARE for REQUEST 1741323542381; ignoring PREPARE
[2025-03-07 13:59:07,967] [INFO] [30145] Received PREPARE: id:1741323542381, from:30103, delay:0.0001s, distance:222.31m (Euclidean)
[2025-03-07 13:59:07,967] [INFO] [30145] Missing PRE-PREPARE for REQUEST 1741323542381; ignoring PREPARE
[2025-03-07 13:59:07,983] [INFO] [30145] Received COMMIT: id:1741323542381, from:30178, delay:0.0001s, distance:255.33m (Euclidean)
[2025-03-07 13:59:08,074] [INFO] [30145] Received PREPARE: id:1741323542381, from:30128, delay:0.0002s, distance:265.73m (Euclidean)
[2025-03-07 13:59:08,074] [INFO] [30145] Missing PRE-PREPARE for REQUEST 1741323542381; ignoring PREPARE
[2025-03-07 13:59:08,078] [INFO] [30145] Received COMMIT: id:1741323542381, from:30128, delay:0.0002s, distance:265.73m (Euclidean)
[2025-03-07 13:59:08,084] [INFO] [30145] Received COMMIT: id:1741323542381, from:30136, delay:0.0002s, distance:261.28m (Euclidean)
[2025-03-07 13:59:08,097] [INFO] [30145] Received PREPARE: id:1741323542381, from:30089, delay:0.0001s, distance:241.64m (Euclidean)
[2025-03-07 13:59:08,097] [INFO] [30145] Missing PRE-PREPARE for REQUEST 1741323542381; ignoring PREPARE
[2025-03-07 13:59:08,105] [INFO] [30145] Received COMMIT: id:1741323542381, from:30109, delay:0.0000s, distance:200.74m (Euclidean)
[2025-03-07 13:59:08,131] [INFO] [30145] Received COMMIT: id:1741323542381, from:30103, delay:0.0001s, distance:222.31m (Euclidean)
[2025-03-07 13:59:08,160] [INFO] [30145] Received COMMIT: id:1741323542381, from:30092, delay:0.0001s, distance:204.25m (Euclidean)
[2025-03-07 13:59:08,211] [INFO] [30145] Received COMMIT: id:1741323542381, from:30181, delay:0.0002s, distance:268.61m (Euclidean)
[2025-03-07 13:59:08,281] [INFO] [30145] Received PREPARE: id:1741323542381, from:30116, delay:0.0000s, distance:137.27m (Euclidean)
[2025-03-07 13:59:08,281] [INFO] [30145] Missing PRE-PREPARE for REQUEST 1741323542381; ignoring PREPARE
[2025-03-07 13:59:08,283] [INFO] [30145] Received COMMIT: id:1741323542381, from:30116, delay:0.0000s, distance:137.27m (Euclidean)
[2025-03-07 13:59:08,299] [INFO] [30145] Received PREPARE: id:1741323542381, from:30133, delay:0.0001s, distance:231.02m (Euclidean)
[2025-03-07 13:59:08,299] [INFO] [30145] Missing PRE-PREPARE for REQUEST 1741323542381; ignoring PREPARE
[2025-03-07 13:59:08,302] [INFO] [30145] Received PREPARE: id:1741323542381, from:30107, delay:0.0002s, distance:298.37m (Euclidean)
[2025-03-07 13:59:08,302] [INFO] [30145] Missing PRE-PREPARE for REQUEST 1741323542381; ignoring PREPARE
[2025-03-07 13:59:08,302] [INFO] [30145] Received COMMIT: id:1741323542381, from:30107, delay:0.0002s, distance:298.37m (Euclidean)
[2025-03-07 13:59:08,329] [INFO] [30145] Received COMMIT: id:1741323542381, from:30089, delay:0.0001s, distance:241.64m (Euclidean)
[2025-03-07 13:59:08,362] [INFO] [30145] Received COMMIT: id:1741323542381, from:30133, delay:0.0001s, distance:231.02m (Euclidean)
[2025-03-07 13:59:08,362] [INFO] [30145] Received PREPARE: id:1741323542381, from:30129, delay:0.0001s, distance:209.32m (Euclidean)
[2025-03-07 13:59:08,362] [INFO] [30145] Missing PRE-PREPARE for REQUEST 1741323542381; ignoring PREPARE
[2025-03-07 13:59:08,362] [INFO] [30145] Received COMMIT: id:1741323542381, from:30129, delay:0.0001s, distance:209.32m (Euclidean)
[2025-03-07 13:59:08,517] [INFO] [30145] Received COMMIT: id:1741323542381, from:30150, delay:0.0000s, distance:167.01m (Euclidean)
[2025-03-07 13:59:08,639] [INFO] [30145] Received COMMIT: id:1741323542381, from:30124, delay:0.0001s, distance:153.99m (Euclidean)
[2025-03-07 13:59:08,673] [INFO] [30145] Received PREPARE: id:1741323542381, from:30043, delay:0.0001s, distance:243.36m (Euclidean)
[2025-03-07 13:59:08,673] [INFO] [30145] Missing PRE-PREPARE for REQUEST 1741323542381; ignoring PREPARE
[2025-03-07 13:59:08,673] [INFO] [30145] Received COMMIT: id:1741323542381, from:30043, delay:0.0001s, distance:243.36m (Euclidean)
[2025-03-07 13:59:08,749] [INFO] [30145] Received PREPARE: id:1741323542381, from:30020, delay:0.0002s, distance:282.75m (Euclidean)
[2025-03-07 13:59:08,753] [INFO] [30145] Missing PRE-PREPARE for REQUEST 1741323542381; ignoring PREPARE
[2025-03-07 13:59:08,753] [INFO] [30145] Received COMMIT: id:1741323542381, from:30020, delay:0.0002s, distance:282.75m (Euclidean)
[2025-03-07 13:59:08,771] [INFO] [30145] Received COMMIT: id:1741323542381, from:30177, delay:0.0002s, distance:278.68m (Euclidean)
[2025-03-07 13:59:09,071] [INFO] [30145] Received COMMIT: id:1741323542381, from:30120, delay:0.0002s, distance:268.47m (Euclidean)
[2025-03-07 13:59:09,262] [INFO] [30145] Received PREPARE: id:1741323542381, from:30015, delay:0.0001s, distance:239.05m (Euclidean)
[2025-03-07 13:59:09,262] [INFO] [30145] Missing PRE-PREPARE for REQUEST 1741323542381; ignoring PREPARE
[2025-03-07 13:59:09,262] [INFO] [30145] Received COMMIT: id:1741323542381, from:30015, delay:0.0001s, distance:239.05m (Euclidean)
[2025-03-07 13:59:09,365] [INFO] [30145] Received PREPARE: id:1741323542381, from:30112, delay:0.0001s, distance:190.59m (Euclidean)
[2025-03-07 13:59:09,365] [INFO] [30145] Missing PRE-PREPARE for REQUEST 1741323542381; ignoring PREPARE
[2025-03-07 13:59:09,365] [INFO] [30145] Received COMMIT: id:1741323542381, from:30112, delay:0.0001s, distance:190.59m (Euclidean)
[2025-03-07 13:59:09,474] [INFO] [30145] Received PREPARE: id:1741323542381, from:30025, delay:0.0000s, distance:136.64m (Euclidean)
[2025-03-07 13:59:09,474] [INFO] [30145] Missing PRE-PREPARE for REQUEST 1741323542381; ignoring PREPARE
[2025-03-07 13:59:09,474] [INFO] [30145] Received COMMIT: id:1741323542381, from:30025, delay:0.0000s, distance:136.64m (Euclidean)
[2025-03-07 13:59:09,630] [INFO] [30145] Received PREPARE: id:1741323542381, from:30154, delay:0.0001s, distance:240.45m (Euclidean)
[2025-03-07 13:59:09,630] [INFO] [30145] Missing PRE-PREPARE for REQUEST 1741323542381; ignoring PREPARE
[2025-03-07 13:59:09,632] [INFO] [30145] Received COMMIT: id:1741323542381, from:30154, delay:0.0001s, distance:240.45m (Euclidean)
[2025-03-07 13:59:09,765] [INFO] [30145] Received PREPARE: id:1741323542381, from:30171, delay:0.0001s, distance:238.91m (Euclidean)
[2025-03-07 13:59:09,765] [INFO] [30145] Missing PRE-PREPARE for REQUEST 1741323542381; ignoring PREPARE
[2025-03-07 13:59:09,767] [INFO] [30145] Received COMMIT: id:1741323542381, from:30171, delay:0.0001s, distance:238.91m (Euclidean)
[2025-03-07 13:59:09,855] [INFO] [30145] Received PREPARE: id:1741323542381, from:30176, delay:0.0001s, distance:248.69m (Euclidean)
[2025-03-07 13:59:09,855] [INFO] [30145] Missing PRE-PREPARE for REQUEST 1741323542381; ignoring PREPARE
[2025-03-07 13:59:09,857] [INFO] [30145] Received COMMIT: id:1741323542381, from:30176, delay:0.0001s, distance:248.69m (Euclidean)
[2025-03-07 13:59:09,944] [INFO] [30145] Received PREPARE: id:1741323542381, from:30074, delay:0.0001s, distance:208.14m (Euclidean)
[2025-03-07 13:59:09,944] [INFO] [30145] Missing PRE-PREPARE for REQUEST 1741323542381; ignoring PREPARE
[2025-03-07 13:59:09,946] [INFO] [30145] Received COMMIT: id:1741323542381, from:30074, delay:0.0001s, distance:208.14m (Euclidean)
[2025-03-07 13:59:10,139] [INFO] [30145] Received PREPARE: id:1741323542381, from:30021, delay:0.0000s, distance:187.48m (Euclidean)
[2025-03-07 13:59:10,139] [INFO] [30145] Missing PRE-PREPARE for REQUEST 1741323542381; ignoring PREPARE
[2025-03-07 13:59:10,141] [INFO] [30145] Received COMMIT: id:1741323542381, from:30021, delay:0.0000s, distance:187.48m (Euclidean)
[2025-03-07 13:59:10,321] [INFO] [30145] Received PREPARE: id:1741323542381, from:30096, delay:0.0000s, distance:122.60m (Euclidean)
[2025-03-07 13:59:10,321] [INFO] [30145] Missing PRE-PREPARE for REQUEST 1741323542381; ignoring PREPARE
[2025-03-07 13:59:10,374] [INFO] [30145] Received COMMIT: id:1741323542381, from:30096, delay:0.0000s, distance:122.60m (Euclidean)
[2025-03-07 13:59:10,478] [INFO] [30145] Received PREPARE: id:1741323542381, from:30023, delay:0.0002s, distance:277.02m (Euclidean)
[2025-03-07 13:59:10,478] [INFO] [30145] Missing PRE-PREPARE for REQUEST 1741323542381; ignoring PREPARE
[2025-03-07 13:59:10,478] [INFO] [30145] Received PREPARE: id:1741323542381, from:30035, delay:0.0002s, distance:280.81m (Euclidean)
[2025-03-07 13:59:10,478] [INFO] [30145] Missing PRE-PREPARE for REQUEST 1741323542381; ignoring PREPARE
[2025-03-07 13:59:10,482] [INFO] [30145] Received COMMIT: id:1741323542381, from:30023, delay:0.0002s, distance:277.02m (Euclidean)
[2025-03-07 13:59:10,482] [INFO] [30145] Received COMMIT: id:1741323542381, from:30065, delay:0.0002s, distance:291.63m (Euclidean)
[2025-03-07 13:59:10,482] [INFO] [30145] Received COMMIT: id:1741323542381, from:30035, delay:0.0002s, distance:280.81m (Euclidean)
[2025-03-07 13:59:10,482] [INFO] [30145] Received PREPARE: id:1741323542381, from:30065, delay:0.0002s, distance:291.63m (Euclidean)
[2025-03-07 13:59:10,482] [INFO] [30145] Missing PRE-PREPARE for REQUEST 1741323542381; ignoring PREPARE
[2025-03-07 13:59:10,702] [INFO] [30145] Received PREPARE: id:1741323542381, from:30063, delay:0.0000s, distance:148.56m (Euclidean)
[2025-03-07 13:59:10,702] [INFO] [30145] Missing PRE-PREPARE for REQUEST 1741323542381; ignoring PREPARE
[2025-03-07 13:59:10,702] [INFO] [30145] Received COMMIT: id:1741323542381, from:30063, delay:0.0000s, distance:148.56m (Euclidean)
[2025-03-07 13:59:10,717] [INFO] [30145] Received PREPARE: id:1741323542381, from:30049, delay:0.0001s, distance:247.66m (Euclidean)
[2025-03-07 13:59:10,717] [INFO] [30145] Missing PRE-PREPARE for REQUEST 1741323542381; ignoring PREPARE
[2025-03-07 13:59:10,717] [INFO] [30145] Received COMMIT: id:1741323542381, from:30049, delay:0.0001s, distance:247.66m (Euclidean)
[2025-03-07 13:59:10,785] [INFO] [30145] Received PREPARE: id:1741323542381, from:30158, delay:0.0001s, distance:194.63m (Euclidean)
[2025-03-07 13:59:10,787] [INFO] [30145] Missing PRE-PREPARE for REQUEST 1741323542381; ignoring PREPARE
[2025-03-07 13:59:10,787] [INFO] [30145] Received COMMIT: id:1741323542381, from:30158, delay:0.0001s, distance:194.63m (Euclidean)
[2025-03-07 13:59:10,854] [INFO] [30145] Received PREPARE: id:1741323542381, from:30130, delay:0.0001s, distance:231.89m (Euclidean)
[2025-03-07 13:59:10,854] [INFO] [30145] Missing PRE-PREPARE for REQUEST 1741323542381; ignoring PREPARE
[2025-03-07 13:59:10,856] [INFO] [30145] Received COMMIT: id:1741323542381, from:30130, delay:0.0001s, distance:231.89m (Euclidean)
[2025-03-07 13:59:10,907] [INFO] [30145] Received PREPARE: id:1741323542381, from:30057, delay:0.0001s, distance:192.10m (Euclidean)
[2025-03-07 13:59:10,907] [INFO] [30145] Missing PRE-PREPARE for REQUEST 1741323542381; ignoring PREPARE
[2025-03-07 13:59:10,909] [INFO] [30145] Received COMMIT: id:1741323542381, from:30057, delay:0.0001s, distance:192.10m (Euclidean)
[2025-03-07 13:59:11,074] [INFO] [30145] Received PREPARE: id:1741323542381, from:30046, delay:0.0002s, distance:259.02m (Euclidean)
[2025-03-07 13:59:11,074] [INFO] [30145] Missing PRE-PREPARE for REQUEST 1741323542381; ignoring PREPARE
[2025-03-07 13:59:11,074] [INFO] [30145] Received COMMIT: id:1741323542381, from:30046, delay:0.0002s, distance:259.02m (Euclidean)
[2025-03-07 13:59:11,131] [INFO] [30145] Received PREPARE: id:1741323542381, from:30115, delay:0.0002s, distance:258.38m (Euclidean)
[2025-03-07 13:59:11,131] [INFO] [30145] Missing PRE-PREPARE for REQUEST 1741323542381; ignoring PREPARE
[2025-03-07 13:59:11,131] [INFO] [30145] Received COMMIT: id:1741323542381, from:30115, delay:0.0002s, distance:258.38m (Euclidean)
[2025-03-07 13:59:11,156] [INFO] [30145] Received PREPARE: id:1741323542381, from:30121, delay:0.0000s, distance:110.42m (Euclidean)
[2025-03-07 13:59:11,156] [INFO] [30145] Missing PRE-PREPARE for REQUEST 1741323542381; ignoring PREPARE
[2025-03-07 13:59:11,156] [INFO] [30145] Received COMMIT: id:1741323542381, from:30121, delay:0.0000s, distance:110.42m (Euclidean)
[2025-03-07 13:59:11,204] [INFO] [30145] Received PREPARE: id:1741323542381, from:30051, delay:0.0002s, distance:255.84m (Euclidean)
[2025-03-07 13:59:11,204] [INFO] [30145] Missing PRE-PREPARE for REQUEST 1741323542381; ignoring PREPARE
[2025-03-07 13:59:11,204] [INFO] [30145] Received COMMIT: id:1741323542381, from:30051, delay:0.0002s, distance:255.84m (Euclidean)
[2025-03-07 13:59:11,242] [INFO] [30145] Received PREPARE: id:1741323542381, from:30102, delay:0.0000s, distance:188.53m (Euclidean)
[2025-03-07 13:59:11,242] [INFO] [30145] Missing PRE-PREPARE for REQUEST 1741323542381; ignoring PREPARE
[2025-03-07 13:59:11,242] [INFO] [30145] Received COMMIT: id:1741323542381, from:30102, delay:0.0000s, distance:188.53m (Euclidean)
[2025-03-07 13:59:11,258] [INFO] [30145] Received PREPARE: id:1741323542381, from:30095, delay:0.0000s, distance:89.43m (Euclidean)
[2025-03-07 13:59:11,258] [INFO] [30145] Missing PRE-PREPARE for REQUEST 1741323542381; ignoring PREPARE
[2025-03-07 13:59:11,258] [INFO] [30145] Received COMMIT: id:1741323542381, from:30095, delay:0.0000s, distance:89.43m (Euclidean)
[2025-03-07 13:59:11,368] [INFO] [30145] Received PREPARE: id:1741323542381, from:30007, delay:0.0001s, distance:232.14m (Euclidean)
[2025-03-07 13:59:11,368] [INFO] [30145] Missing PRE-PREPARE for REQUEST 1741323542381; ignoring PREPARE
[2025-03-07 13:59:11,368] [INFO] [30145] Received COMMIT: id:1741323542381, from:30007, delay:0.0001s, distance:232.14m (Euclidean)
[2025-03-07 13:59:12,086] [INFO] [30145] Received PREPARE: id:1741323542381, from:30066, delay:0.0000s, distance:127.82m (Euclidean)
[2025-03-07 13:59:12,086] [INFO] [30145] Missing PRE-PREPARE for REQUEST 1741323542381; ignoring PREPARE
[2025-03-07 13:59:12,086] [INFO] [30145] Received COMMIT: id:1741323542381, from:30066, delay:0.0000s, distance:127.82m (Euclidean)
[2025-03-07 13:59:12,377] [INFO] [30145] Received PREPARE: id:1741323542381, from:30175, delay:0.0000s, distance:177.97m (Euclidean)
[2025-03-07 13:59:12,377] [INFO] [30145] Missing PRE-PREPARE for REQUEST 1741323542381; ignoring PREPARE
[2025-03-07 13:59:12,377] [INFO] [30145] Received COMMIT: id:1741323542381, from:30175, delay:0.0000s, distance:177.97m (Euclidean)
[2025-03-07 13:59:12,611] [INFO] [30145] Received PREPARE: id:1741323542381, from:30019, delay:0.0000s, distance:299.68m (Euclidean)
[2025-03-07 13:59:12,611] [INFO] [30145] Missing PRE-PREPARE for REQUEST 1741323542381; ignoring PREPARE
[2025-03-07 13:59:13,000] [INFO] [30145] Received PRE-PREPARE: id:1741323542381, from:Leader(30000), delay:0.0001s, distance:228.46m (Euclidean)
[2025-03-07 13:59:13,000] [INFO] [30145] Broadcasting PREPARE for REQUEST 1741323542381
[2025-03-07 13:59:13,005] [INFO] [30145] Not broadcasting to fault node: 30077
[2025-03-07 13:59:13,028] [INFO] [30145] Not broadcasting to fault node: 30184
[2025-03-07 13:59:13,116] [INFO] [30145] Received PREPARE: id:1741323542381, from:30011, delay:0.0000s, distance:141.60m (Euclidean)
[2025-03-07 13:59:13,116] [INFO] [30145] Broadcasting COMMIT for REQUEST 1741323542381
[2025-03-07 13:59:13,116] [INFO] [30145] Not broadcasting to fault node: 30077
[2025-03-07 13:59:13,146] [INFO] [30145] Not broadcasting to fault node: 30184
[2025-03-07 13:59:13,146] [INFO] [30145] Received COMMIT: id:1741323542381, from:30011, delay:0.0000s, distance:141.60m (Euclidean)
[2025-03-07 13:59:13,227] [INFO] [30145] Received PREPARE: id:1741323542381, from:30036, delay:0.0000s, distance:249.31m (Euclidean)
[2025-03-07 13:59:13,449] [INFO] [30145] Received COMMIT: id:1741323542381, from:30036, delay:0.0000s, distance:249.31m (Euclidean)
[2025-03-07 13:59:13,512] [INFO] [30145] Received COMMIT: id:1741323542381, from:30000, delay:0.0001s, distance:228.46m (Euclidean)
[2025-03-07 13:59:13,575] [INFO] [30145] Received PREPARE: id:1741323542381, from:30088, delay:0.0000s, distance:55.36m (Euclidean)
[2025-03-07 13:59:14,166] [INFO] [30145] Received PREPARE: id:1741323542381, from:30165, delay:0.0001s, distance:179.41m (Euclidean)
[2025-03-07 13:59:14,166] [INFO] [30145] Received COMMIT: id:1741323542381, from:30165, delay:0.0001s, distance:179.41m (Euclidean)
[2025-03-07 13:59:14,338] [INFO] [30145] Received COMMIT: id:1741323542381, from:30019, delay:0.0000s, distance:299.68m (Euclidean)
[2025-03-07 13:59:14,714] [INFO] [30145] Received PREPARE: id:1741323542381, from:30146, delay:0.0001s, distance:225.43m (Euclidean)
[2025-03-07 13:59:14,720] [INFO] [30145] Received COMMIT: id:1741323542381, from:30146, delay:0.0001s, distance:225.43m (Euclidean)
[2025-03-07 13:59:14,881] [INFO] [30145] Received PREPARE: id:1741323542381, from:30061, delay:0.0001s, distance:246.31m (Euclidean)
[2025-03-07 13:59:15,359] [INFO] [30145] Received PREPARE: id:1741323542381, from:30052, delay:0.0000s, distance:114.28m (Euclidean)
[2025-03-07 13:59:15,430] [INFO] [30145] Received PREPARE: id:1741323542381, from:30087, delay:0.0001s, distance:190.04m (Euclidean)
[2025-03-07 13:59:15,746] [INFO] [30145] Received PREPARE: id:1741323542381, from:30135, delay:0.0001s, distance:189.55m (Euclidean)
[2025-03-07 13:59:15,830] [INFO] [30145] Received COMMIT: id:1741323542381, from:30088, delay:0.0000s, distance:55.36m (Euclidean)
[2025-03-07 13:59:15,912] [INFO] [30145] Received COMMIT: id:1741323542381, from:30087, delay:0.0001s, distance:190.04m (Euclidean)
[2025-03-07 13:59:15,985] [INFO] [30145] Received COMMIT: id:1741323542381, from:30061, delay:0.0001s, distance:246.31m (Euclidean)
[2025-03-07 13:59:16,060] [INFO] [30145] Received COMMIT: id:1741323542381, from:30135, delay:0.0001s, distance:189.55m (Euclidean)
[2025-03-07 13:59:16,076] [INFO] [30145] Received PREPARE: id:1741323542381, from:30034, delay:0.0001s, distance:237.68m (Euclidean)
[2025-03-07 13:59:16,078] [INFO] [30145] Received COMMIT: id:1741323542381, from:30034, delay:0.0001s, distance:237.68m (Euclidean)
[2025-03-07 13:59:16,461] [INFO] [30145] Received PREPARE: id:1741323542381, from:30001, delay:0.0000s, distance:119.38m (Euclidean)
[2025-03-07 13:59:16,463] [INFO] [30145] Received COMMIT: id:1741323542381, from:30001, delay:0.0000s, distance:119.38m (Euclidean)
[2025-03-07 13:59:16,557] [INFO] [30145] Received PREPARE: id:1741323542381, from:30067, delay:0.0001s, distance:220.69m (Euclidean)
[2025-03-07 13:59:16,578] [INFO] [30145] Received COMMIT: id:1741323542381, from:30067, delay:0.0001s, distance:220.69m (Euclidean)
[2025-03-07 13:59:16,892] [INFO] [30145] Received PREPARE: id:1741323542381, from:30114, delay:0.0001s, distance:190.04m (Euclidean)
[2025-03-07 13:59:16,892] [INFO] [30145] Received COMMIT: id:1741323542381, from:30114, delay:0.0001s, distance:190.04m (Euclidean)
[2025-03-07 13:59:16,940] [INFO] [30145] Received PREPARE: id:1741323542381, from:30140, delay:0.0001s, distance:237.62m (Euclidean)
[2025-03-07 13:59:16,940] [INFO] [30145] Received COMMIT: id:1741323542381, from:30052, delay:0.0000s, distance:114.28m (Euclidean)
[2025-03-07 13:59:16,940] [INFO] [30145] Received COMMIT: id:1741323542381, from:30140, delay:0.0001s, distance:237.62m (Euclidean)
[2025-03-07 13:59:17,166] [INFO] [30145] Received PREPARE: id:1741323542381, from:30137, delay:0.0002s, distance:280.83m (Euclidean)
[2025-03-07 13:59:17,176] [INFO] [30145] Received COMMIT: id:1741323542381, from:30137, delay:0.0002s, distance:280.83m (Euclidean)
[2025-03-07 13:59:17,190] [INFO] [30145] Received PREPARE: id:1741323542381, from:30073, delay:0.0000s, distance:53.29m (Euclidean)
[2025-03-07 13:59:17,190] [INFO] [30145] Received COMMIT: id:1741323542381, from:30073, delay:0.0000s, distance:53.29m (Euclidean)
[2025-03-07 13:59:17,397] [INFO] [30145] Received PREPARE: id:1741323542381, from:30194, delay:0.0002s, distance:286.01m (Euclidean)
[2025-03-07 13:59:17,397] [INFO] [30145] Received COMMIT: id:1741323542381, from:30194, delay:0.0002s, distance:286.01m (Euclidean)
[2025-03-07 13:59:17,430] [INFO] [30145] Received PREPARE: id:1741323542381, from:30131, delay:0.0000s, distance:84.35m (Euclidean)
[2025-03-07 13:59:17,430] [INFO] [30145] Received COMMIT: id:1741323542381, from:30131, delay:0.0000s, distance:84.35m (Euclidean)
[2025-03-07 13:59:17,880] [INFO] [30145] Received PREPARE: id:1741323542381, from:30138, delay:0.0000s, distance:106.23m (Euclidean)
[2025-03-07 13:59:18,003] [INFO] [30145] Received PREPARE: id:1741323542381, from:30188, delay:0.0001s, distance:172.92m (Euclidean)
[2025-03-07 13:59:18,008] [INFO] [30145] Received COMMIT: id:1741323542381, from:30188, delay:0.0001s, distance:172.92m (Euclidean)
[2025-03-07 13:59:18,091] [INFO] [30145] Received PREPARE: id:1741323542381, from:30016, delay:0.0002s, distance:267.68m (Euclidean)
[2025-03-07 13:59:18,091] [INFO] [30145] Received COMMIT: id:1741323542381, from:30016, delay:0.0002s, distance:267.68m (Euclidean)
[2025-03-07 13:59:18,454] [INFO] [30145] Received PREPARE: id:1741323542381, from:30058, delay:0.0002s, distance:269.70m (Euclidean)
[2025-03-07 13:59:18,454] [INFO] [30145] Received COMMIT: id:1741323542381, from:30058, delay:0.0002s, distance:269.70m (Euclidean)
[2025-03-07 13:59:18,791] [INFO] [30145] Received PREPARE: id:1741323542381, from:30006, delay:0.0000s, distance:106.02m (Euclidean)
[2025-03-07 13:59:18,791] [INFO] [30145] Received COMMIT: id:1741323542381, from:30006, delay:0.0000s, distance:106.02m (Euclidean)
[2025-03-07 13:59:18,847] [INFO] [30145] Received PREPARE: id:1741323542381, from:30032, delay:0.0001s, distance:226.30m (Euclidean)
[2025-03-07 13:59:18,847] [INFO] [30145] Received COMMIT: id:1741323542381, from:30032, delay:0.0001s, distance:226.30m (Euclidean)
[2025-03-07 13:59:19,046] [INFO] [30145] Received PREPARE: id:1741323542381, from:30017, delay:0.0001s, distance:194.88m (Euclidean)
[2025-03-07 13:59:19,066] [INFO] [30145] Received PREPARE: id:1741323542381, from:30125, delay:0.0002s, distance:274.11m (Euclidean)
[2025-03-07 13:59:19,066] [INFO] [30145] Received COMMIT: id:1741323542381, from:30125, delay:0.0002s, distance:274.11m (Euclidean)
[2025-03-07 13:59:19,344] [INFO] [30145] Received PREPARE: id:1741323542381, from:30014, delay:0.0000s, distance:82.51m (Euclidean)
[2025-03-07 13:59:19,347] [INFO] [30145] Received COMMIT: id:1741323542381, from:30014, delay:0.0000s, distance:82.51m (Euclidean)
[2025-03-07 13:59:20,004] [INFO] [30145] Received PREPARE: id:1741323542381, from:30159, delay:0.0002s, distance:298.77m (Euclidean)
[2025-03-07 13:59:20,004] [INFO] [30145] Received PREPARE: id:1741323542381, from:30187, delay:0.0001s, distance:198.01m (Euclidean)
[2025-03-07 13:59:20,023] [INFO] [30145] Received COMMIT: id:1741323542381, from:30159, delay:0.0002s, distance:298.77m (Euclidean)
[2025-03-07 13:59:20,101] [INFO] [30145] Received PREPARE: id:1741323542381, from:30075, delay:0.0000s, distance:58.79m (Euclidean)
[2025-03-07 13:59:20,101] [INFO] [30145] Received COMMIT: id:1741323542381, from:30075, delay:0.0000s, distance:58.79m (Euclidean)
[2025-03-07 13:59:20,157] [INFO] [30145] Received PREPARE: id:1741323542381, from:30033, delay:0.0002s, distance:270.93m (Euclidean)
[2025-03-07 13:59:20,157] [INFO] [30145] Received COMMIT: id:1741323542381, from:30033, delay:0.0002s, distance:270.93m (Euclidean)
[2025-03-07 13:59:20,221] [INFO] [30145] Received PREPARE: id:1741323542381, from:30038, delay:0.0001s, distance:247.57m (Euclidean)
[2025-03-07 13:59:20,221] [INFO] [30145] Received COMMIT: id:1741323542381, from:30038, delay:0.0001s, distance:247.57m (Euclidean)
[2025-03-07 13:59:20,831] [INFO] [30145] Received COMMIT: id:1741323542381, from:30138, delay:0.0000s, distance:106.23m (Euclidean)
[2025-03-07 13:59:21,071] [INFO] [30145] Received PREPARE: id:1741323542381, from:30166, delay:0.0001s, distance:172.73m (Euclidean)
[2025-03-07 13:59:21,072] [INFO] [30145] Received COMMIT: id:1741323542381, from:30166, delay:0.0001s, distance:172.73m (Euclidean)
[2025-03-07 13:59:21,374] [INFO] [30145] Received PREPARE: id:1741323542381, from:30143, delay:0.0001s, distance:191.31m (Euclidean)
[2025-03-07 13:59:21,393] [INFO] [30145] Received COMMIT: id:1741323542381, from:30143, delay:0.0001s, distance:191.31m (Euclidean)
[2025-03-07 13:59:21,627] [INFO] [30145] Received PREPARE: id:1741323542381, from:30031, delay:0.0002s, distance:286.05m (Euclidean)
[2025-03-07 13:59:21,627] [INFO] [30145] Received COMMIT: id:1741323542381, from:30031, delay:0.0002s, distance:286.05m (Euclidean)
[2025-03-07 13:59:21,665] [INFO] [30145] Received PREPARE: id:1741323542381, from:30079, delay:0.0000s, distance:124.25m (Euclidean)
[2025-03-07 13:59:21,667] [INFO] [30145] Received COMMIT: id:1741323542381, from:30079, delay:0.0000s, distance:124.25m (Euclidean)
[2025-03-07 13:59:21,838] [INFO] [30145] Received COMMIT: id:1741323542381, from:30187, delay:0.0001s, distance:198.01m (Euclidean)
[2025-03-07 13:59:22,235] [INFO] [30145] Received COMMIT: id:1741323542381, from:30017, delay:0.0001s, distance:194.88m (Euclidean)
[2025-03-07 13:59:22,533] [INFO] [30145] Received PREPARE: id:1741323542381, from:30151, delay:0.0000s, distance:134.71m (Euclidean)
[2025-03-07 13:59:22,533] [INFO] [30145] Received COMMIT: id:1741323542381, from:30151, delay:0.0000s, distance:134.71m (Euclidean)
[2025-03-07 13:59:22,657] [INFO] [30145] Received PREPARE: id:1741323542381, from:30071, delay:0.0002s, distance:273.94m (Euclidean)
[2025-03-07 13:59:22,671] [INFO] [30145] Received COMMIT: id:1741323542381, from:30071, delay:0.0002s, distance:273.94m (Euclidean)
[2025-03-07 13:59:22,718] [INFO] [30145] Received PREPARE: id:1741323542381, from:30142, delay:0.0000s, distance:127.21m (Euclidean)
[2025-03-07 13:59:22,755] [INFO] [30145] Received COMMIT: id:1741323542381, from:30142, delay:0.0000s, distance:127.21m (Euclidean)
[2025-03-07 13:59:22,857] [INFO] [30145] Received PREPARE: id:1741323542381, from:30132, delay:0.0001s, distance:227.54m (Euclidean)
[2025-03-07 13:59:22,859] [INFO] [30145] Received COMMIT: id:1741323542381, from:30132, delay:0.0001s, distance:227.54m (Euclidean)
[2025-03-07 13:59:22,907] [INFO] [30145] Received PREPARE: id:1741323542381, from:30156, delay:0.0002s, distance:253.38m (Euclidean)
[2025-03-07 13:59:22,907] [INFO] [30145] Received COMMIT: id:1741323542381, from:30156, delay:0.0002s, distance:253.38m (Euclidean)
[2025-03-07 13:59:23,002] [INFO] [30145] Received PREPARE: id:1741323542381, from:30091, delay:0.0001s, distance:177.00m (Euclidean)
[2025-03-07 13:59:23,002] [INFO] [30145] Received COMMIT: id:1741323542381, from:30091, delay:0.0001s, distance:177.00m (Euclidean)
[2025-03-07 13:59:23,457] [INFO] [30145] Received PREPARE: id:1741323542381, from:30105, delay:0.0001s, distance:246.86m (Euclidean)
[2025-03-07 13:59:23,457] [INFO] [30145] Received COMMIT: id:1741323542381, from:30105, delay:0.0001s, distance:246.86m (Euclidean)
[2025-03-07 13:59:23,840] [INFO] [30145] Received PREPARE: id:1741323542381, from:30022, delay:0.0002s, distance:261.08m (Euclidean)
[2025-03-07 13:59:23,840] [INFO] [30145] Received COMMIT: id:1741323542381, from:30022, delay:0.0002s, distance:261.08m (Euclidean)
[2025-03-07 13:59:24,102] [INFO] [30145] Received PREPARE: id:1741323542381, from:30173, delay:0.0001s, distance:209.75m (Euclidean)
[2025-03-07 13:59:24,128] [INFO] [30145] Received COMMIT: id:1741323542381, from:30173, delay:0.0001s, distance:209.75m (Euclidean)
[2025-03-07 13:59:24,363] [INFO] [30145] Received PREPARE: id:1741323542381, from:30008, delay:0.0001s, distance:215.45m (Euclidean)
[2025-03-07 13:59:24,363] [INFO] [30145] Received COMMIT: id:1741323542381, from:30008, delay:0.0001s, distance:215.45m (Euclidean)
[2025-03-07 13:59:24,630] [INFO] [30145] Received PREPARE: id:1741323542381, from:30193, delay:0.0001s, distance:213.32m (Euclidean)
[2025-03-07 13:59:24,636] [INFO] [30145] Received COMMIT: id:1741323542381, from:30193, delay:0.0001s, distance:213.32m (Euclidean)
[2025-03-07 13:59:25,004] [INFO] [30145] Received PREPARE: id:1741323542381, from:30068, delay:0.0002s, distance:274.28m (Euclidean)
[2025-03-07 13:59:25,004] [INFO] [30145] Received COMMIT: id:1741323542381, from:30068, delay:0.0002s, distance:274.28m (Euclidean)
[2025-03-07 13:59:25,185] [INFO] [30145] Received PREPARE: id:1741323542381, from:30104, delay:0.0002s, distance:269.37m (Euclidean)
[2025-03-07 13:59:25,186] [INFO] [30145] Received COMMIT: id:1741323542381, from:30104, delay:0.0002s, distance:269.37m (Euclidean)
[2025-03-07 13:59:25,290] [INFO] [30145] Received PREPARE: id:1741323542381, from:30172, delay:0.0000s, distance:68.57m (Euclidean)
[2025-03-07 13:59:25,472] [INFO] [30145] Received PREPARE: id:1741323542381, from:30186, delay:0.0001s, distance:252.07m (Euclidean)
[2025-03-07 13:59:25,472] [INFO] [30145] Received COMMIT: id:1741323542381, from:30186, delay:0.0001s, distance:252.07m (Euclidean)
[2025-03-07 13:59:25,604] [INFO] [30145] Received PREPARE: id:1741323542381, from:30122, delay:0.0001s, distance:167.18m (Euclidean)
[2025-03-07 13:59:25,604] [INFO] [30145] Received COMMIT: id:1741323542381, from:30122, delay:0.0001s, distance:167.18m (Euclidean)
[2025-03-07 13:59:25,798] [INFO] [30145] Received PREPARE: id:1741323542381, from:30153, delay:0.0002s, distance:284.22m (Euclidean)
[2025-03-07 13:59:25,798] [INFO] [30145] Received COMMIT: id:1741323542381, from:30153, delay:0.0002s, distance:284.22m (Euclidean)
[2025-03-07 13:59:25,910] [INFO] [30145] Received PREPARE: id:1741323542381, from:30084, delay:0.0001s, distance:172.39m (Euclidean)
[2025-03-07 13:59:25,911] [INFO] [30145] Received COMMIT: id:1741323542381, from:30084, delay:0.0001s, distance:172.39m (Euclidean)
[2025-03-07 13:59:25,911] [INFO] [30145] Received PREPARE: id:1741323542381, from:30094, delay:0.0000s, distance:107.33m (Euclidean)
[2025-03-07 13:59:25,928] [INFO] [30145] Received COMMIT: id:1741323542381, from:30094, delay:0.0000s, distance:107.33m (Euclidean)
[2025-03-07 13:59:26,025] [INFO] [30145] Received PREPARE: id:1741323542381, from:30042, delay:0.0000s, distance:156.57m (Euclidean)
[2025-03-07 13:59:26,025] [INFO] [30145] Received COMMIT: id:1741323542381, from:30042, delay:0.0000s, distance:156.57m (Euclidean)
[2025-03-07 13:59:26,327] [INFO] [30145] Received PREPARE: id:1741323542381, from:30039, delay:0.0001s, distance:197.04m (Euclidean)
[2025-03-07 13:59:26,328] [INFO] [30145] Received COMMIT: id:1741323542381, from:30039, delay:0.0001s, distance:197.04m (Euclidean)
[2025-03-07 13:59:26,546] [INFO] [30145] Received PREPARE: id:1741323542381, from:30162, delay:0.0001s, distance:152.90m (Euclidean)
[2025-03-07 13:59:26,546] [INFO] [30145] Received COMMIT: id:1741323542381, from:30162, delay:0.0001s, distance:152.90m (Euclidean)
[2025-03-07 13:59:27,224] [INFO] [30145] Received PREPARE: id:1741323542381, from:30072, delay:0.0000s, distance:65.35m (Euclidean)
[2025-03-07 13:59:27,225] [INFO] [30145] Received COMMIT: id:1741323542381, from:30072, delay:0.0000s, distance:65.35m (Euclidean)
[2025-03-07 13:59:27,447] [INFO] [30145] Received PREPARE: id:1741323542381, from:30047, delay:0.0000s, distance:121.29m (Euclidean)
[2025-03-07 13:59:27,456] [INFO] [30145] Received COMMIT: id:1741323542381, from:30047, delay:0.0000s, distance:121.29m (Euclidean)
[2025-03-07 13:59:27,468] [INFO] [30145] Received PREPARE: id:1741323542381, from:30012, delay:0.0000s, distance:29.56m (Euclidean)
[2025-03-07 13:59:27,469] [INFO] [30145] Received COMMIT: id:1741323542381, from:30012, delay:0.0000s, distance:29.56m (Euclidean)
[2025-03-07 13:59:27,526] [INFO] [30145] Received PREPARE: id:1741323542381, from:30139, delay:0.0001s, distance:183.06m (Euclidean)
[2025-03-07 13:59:27,548] [INFO] [30145] Received COMMIT: id:1741323542381, from:30139, delay:0.0001s, distance:183.06m (Euclidean)
[2025-03-07 13:59:27,750] [INFO] [30145] Received PREPARE: id:1741323542381, from:30152, delay:0.0001s, distance:184.22m (Euclidean)
[2025-03-07 13:59:27,751] [INFO] [30145] Received COMMIT: id:1741323542381, from:30152, delay:0.0001s, distance:184.22m (Euclidean)
[2025-03-07 13:59:27,884] [INFO] [30145] Received PREPARE: id:1741323542381, from:30148, delay:0.0001s, distance:240.13m (Euclidean)
[2025-03-07 13:59:27,884] [INFO] [30145] Received COMMIT: id:1741323542381, from:30148, delay:0.0001s, distance:240.13m (Euclidean)
[2025-03-07 13:59:28,174] [INFO] [30145] Received PREPARE: id:1741323542381, from:30185, delay:0.0001s, distance:213.60m (Euclidean)
[2025-03-07 13:59:28,186] [INFO] [30145] Received COMMIT: id:1741323542381, from:30185, delay:0.0001s, distance:213.60m (Euclidean)
[2025-03-07 13:59:28,606] [INFO] [30145] Received PREPARE: id:1741323542381, from:30192, delay:0.0002s, distance:265.23m (Euclidean)
[2025-03-07 13:59:28,626] [INFO] [30145] Received COMMIT: id:1741323542381, from:30192, delay:0.0002s, distance:265.23m (Euclidean)
[2025-03-07 13:59:28,660] [INFO] [30145] Received COMMIT: id:1741323542381, from:30172, delay:0.0000s, distance:68.57m (Euclidean)
[2025-03-07 13:59:28,747] [INFO] [30145] Received PREPARE: id:1741323542381, from:30044, delay:0.0001s, distance:245.67m (Euclidean)
[2025-03-07 13:59:28,773] [INFO] [30145] Received COMMIT: id:1741323542381, from:30044, delay:0.0001s, distance:245.67m (Euclidean)
[2025-03-07 13:59:28,817] [INFO] [30145] Received PREPARE: id:1741323542381, from:30018, delay:0.0000s, distance:137.78m (Euclidean)
[2025-03-07 13:59:28,830] [INFO] [30145] Received COMMIT: id:1741323542381, from:30018, delay:0.0000s, distance:137.78m (Euclidean)
[2025-03-07 13:59:38,188] [INFO] [30145] Received PREPARE: id:1741323542381, from:30082, delay:0.0001s, distance:204.44m (Euclidean)
[2025-03-07 13:59:38,204] [INFO] [30145] Received COMMIT: id:1741323542381, from:30082, delay:0.0001s, distance:204.44m (Euclidean)
[2025-03-07 13:59:38,340] [INFO] [30145] Received PREPARE: id:1741323542381, from:30078, delay:0.0000s, distance:108.73m (Euclidean)
[2025-03-07 13:59:38,396] [INFO] [30145] Received PREPARE: id:1741323542381, from:30183, delay:0.0000s, distance:147.84m (Euclidean)
[2025-03-07 13:59:38,460] [INFO] [30145] Received COMMIT: id:1741323542381, from:30078, delay:0.0000s, distance:108.73m (Euclidean)
[2025-03-07 13:59:38,543] [INFO] [30145] Received PREPARE: id:1741323542381, from:30164, delay:0.0001s, distance:169.78m (Euclidean)
[2025-03-07 13:59:38,714] [INFO] [30145] Received COMMIT: id:1741323542381, from:30164, delay:0.0001s, distance:169.78m (Euclidean)
[2025-03-07 13:59:38,836] [INFO] [30145] Received PREPARE: id:1741323542381, from:30163, delay:0.0002s, distance:253.32m (Euclidean)
[2025-03-07 13:59:38,845] [INFO] [30145] Received COMMIT: id:1741323542381, from:30163, delay:0.0002s, distance:253.32m (Euclidean)
