[2025-03-12 16:07:41,211] [INFO] Starting node at localhost:30005 | index=  6 | f=1, k=4 | Role: Replica
[2025-03-12 16:07:41,221] [ERROR] Unexpected error in main loop:
Traceback (most recent call last):
  File "pbft.py", line 472, in main
    runner = await serve_app(app, node_addr['host'], node_addr['port'], logger)
  File "pbft.py", line 420, in serve_app
    await site.start()
  File "D:\anaconda\envs\PBFT\lib\site-packages\aiohttp\web_runner.py", line 128, in start
    reuse_port=self._reuse_port,
  File "D:\anaconda\envs\PBFT\lib\asyncio\base_events.py", line 1386, in create_server
    server._start_serving()
  File "D:\anaconda\envs\PBFT\lib\asyncio\base_events.py", line 276, in _start_serving
    sock.listen(self._backlog)
OSError: [WinError 10014] 호출에 대한 포인터 인수를 사용하려는 동안 시스템에서 잘못된 포인터 주소를 감지했습니다
[2025-03-12 16:07:41,223] [ERROR] Error during cleanup.
Traceback (most recent call last):
  File "pbft.py", line 485, in main
    await runner.cleanup()
UnboundLocalError: local variable 'runner' referenced before assignment
